return {
{["x"] = 0, ["meta"] = { ["fields"] = {}, ["inventory"] = {} }, ["param2"] = 0, ["y"] = 0, ["param1"] = 0, ["z"] = 0, ["name"] = "lottother:dirt" },
{["x"] = 0, ["meta"] = { ["fields"] = {}, ["inventory"] = {} }, ["param2"] = 0, ["y"] = 0, ["param1"] = 13, ["z"] = 1, ["name"] = "lottother:dirt" },
{["x"] = 0, ["meta"] = { ["fields"] = {}, ["inventory"] = {} }, ["param2"] = 0, ["y"] = 0, ["param1"] = 13, ["z"] = 2, ["name"] = "lottother:dirt" },
{["x"] = 0, ["meta"] = { ["fields"] = {}, ["inventory"] = {} }, ["param2"] = 0, ["y"] = 0, ["param1"] = 13, ["z"] = 3, ["name"] = "lottother:dirt" },
{["x"] = 0, ["meta"] = { ["fields"] = {}, ["inventory"] = {} }, ["param2"] = 0, ["y"] = 0, ["param1"] = 13, ["z"] = 4, ["name"] = "lottother:dirt" },
{["x"] = 0, ["meta"] = { ["fields"] = {}, ["inventory"] = {} }, ["param2"] = 0, ["y"] = 0, ["param1"] = 13, ["z"] = 5, ["name"] = "lottother:dirt" },
{["x"] = 0, ["meta"] = { ["fields"] = {}, ["inventory"] = {} }, ["param2"] = 0, ["y"] = 0, ["param1"] = 13, ["z"] = 6, ["name"] = "lottother:dirt" },
{["x"] = 0, ["meta"] = { ["fields"] = {}, ["inventory"] = {} }, ["param2"] = 0, ["y"] = 0, ["param1"] = 13, ["z"] = 7, ["name"] = "lottother:dirt" },
{["x"] = 0, ["meta"] = { ["fields"] = {}, ["inventory"] = {} }, ["param2"] = 0, ["y"] = 0, ["param1"] = 13, ["z"] = 8, ["name"] = "lottother:dirt" },
{["x"] = 0, ["meta"] = { ["fields"] = {}, ["inventory"] = {} }, ["param2"] = 0, ["y"] = 0, ["param1"] = 0, ["z"] = 9, ["name"] = "lottother:dirt" },
{["x"] = 0, ["meta"] = { ["fields"] = {}, ["inventory"] = {} }, ["param2"] = 0, ["y"] = 0, ["param1"] = 13, ["z"] = 10, ["name"] = "lottother:dirt" },
{["x"] = 0, ["meta"] = { ["fields"] = {}, ["inventory"] = {} }, ["param2"] = 0, ["y"] = 0, ["param1"] = 13, ["z"] = 11, ["name"] = "lottother:dirt" },
{["x"] = 0, ["meta"] = { ["fields"] = {}, ["inventory"] = {} }, ["param2"] = 0, ["y"] = 0, ["param1"] = 13, ["z"] = 12, ["name"] = "lottother:dirt" },
{["x"] = 0, ["meta"] = { ["fields"] = {}, ["inventory"] = {} }, ["param2"] = 0, ["y"] = 0, ["param1"] = 13, ["z"] = 13, ["name"] = "lottother:dirt" },
{["x"] = 0, ["meta"] = { ["fields"] = {}, ["inventory"] = {} }, ["param2"] = 0, ["y"] = 0, ["param1"] = 13, ["z"] = 14, ["name"] = "lottother:dirt" },
{["x"] = 0, ["meta"] = { ["fields"] = {}, ["inventory"] = {} }, ["param2"] = 0, ["y"] = 0, ["param1"] = 13, ["z"] = 15, ["name"] = "lottother:dirt" },
{["x"] = 0, ["meta"] = { ["fields"] = {}, ["inventory"] = {} }, ["param2"] = 0, ["y"] = 0, ["param1"] = 13, ["z"] = 16, ["name"] = "lottother:dirt" },
{["x"] = 0, ["meta"] = { ["fields"] = {}, ["inventory"] = {} }, ["param2"] = 0, ["y"] = 0, ["param1"] = 13, ["z"] = 17, ["name"] = "lottother:dirt" },
{["x"] = 0, ["meta"] = { ["fields"] = {}, ["inventory"] = {} }, ["param2"] = 0, ["y"] = 0, ["param1"] = 13, ["z"] = 18, ["name"] = "lottother:dirt" },
{["x"] = 0, ["meta"] = { ["fields"] = {}, ["inventory"] = {} }, ["param2"] = 0, ["y"] = 1, ["param1"] = 0, ["z"] = 0, ["name"] = "lord_ground:dirt_gondor" },
{["x"] = 0, ["meta"] = { ["fields"] = {}, ["inventory"] = {} }, ["param2"] = 0, ["y"] = 1, ["param1"] = 0, ["z"] = 1, ["name"] = "lord_ground:dirt_gondor" },
{["x"] = 0, ["meta"] = { ["fields"] = {}, ["inventory"] = {} }, ["param2"] = 0, ["y"] = 1, ["param1"] = 0, ["z"] = 2, ["name"] = "lord_ground:dirt_gondor" },
{["x"] = 0, ["meta"] = { ["fields"] = {}, ["inventory"] = {} }, ["param2"] = 0, ["y"] = 1, ["param1"] = 0, ["z"] = 3, ["name"] = "lord_ground:dirt_gondor" },
{["x"] = 0, ["meta"] = { ["fields"] = {}, ["inventory"] = {} }, ["param2"] = 0, ["y"] = 1, ["param1"] = 0, ["z"] = 4, ["name"] = "lord_ground:dirt_gondor" },
{["x"] = 0, ["meta"] = { ["fields"] = {}, ["inventory"] = {} }, ["param2"] = 0, ["y"] = 1, ["param1"] = 0, ["z"] = 5, ["name"] = "lord_ground:dirt_gondor" },
{["x"] = 0, ["meta"] = { ["fields"] = {}, ["inventory"] = {} }, ["param2"] = 0, ["y"] = 1, ["param1"] = 0, ["z"] = 6, ["name"] = "lord_ground:dirt_gondor" },
{["x"] = 0, ["meta"] = { ["fields"] = {}, ["inventory"] = {} }, ["param2"] = 0, ["y"] = 1, ["param1"] = 0, ["z"] = 7, ["name"] = "lord_ground:dirt_gondor" },
{["x"] = 0, ["meta"] = { ["fields"] = {}, ["inventory"] = {} }, ["param2"] = 0, ["y"] = 1, ["param1"] = 0, ["z"] = 8, ["name"] = "lord_ground:dirt_gondor" },
{["x"] = 0, ["meta"] = { ["fields"] = {}, ["inventory"] = {} }, ["param2"] = 0, ["y"] = 1, ["param1"] = 0, ["z"] = 9, ["name"] = "lord_ground:dirt_gondor" },
{["x"] = 0, ["meta"] = { ["fields"] = {}, ["inventory"] = {} }, ["param2"] = 0, ["y"] = 1, ["param1"] = 0, ["z"] = 10, ["name"] = "lord_ground:dirt_gondor" },
{["x"] = 0, ["meta"] = { ["fields"] = {}, ["inventory"] = {} }, ["param2"] = 0, ["y"] = 1, ["param1"] = 0, ["z"] = 11, ["name"] = "lord_ground:dirt_gondor" },
{["x"] = 0, ["meta"] = { ["fields"] = {}, ["inventory"] = {} }, ["param2"] = 0, ["y"] = 1, ["param1"] = 0, ["z"] = 12, ["name"] = "lord_ground:dirt_gondor" },
{["x"] = 0, ["meta"] = { ["fields"] = {}, ["inventory"] = {} }, ["param2"] = 0, ["y"] = 1, ["param1"] = 0, ["z"] = 13, ["name"] = "lord_ground:dirt_gondor" },
{["x"] = 0, ["meta"] = { ["fields"] = {}, ["inventory"] = {} }, ["param2"] = 0, ["y"] = 1, ["param1"] = 0, ["z"] = 14, ["name"] = "lord_ground:dirt_gondor" },
{["x"] = 0, ["meta"] = { ["fields"] = {}, ["inventory"] = {} }, ["param2"] = 0, ["y"] = 1, ["param1"] = 0, ["z"] = 15, ["name"] = "lord_ground:dirt_gondor" },
{["x"] = 0, ["meta"] = { ["fields"] = {}, ["inventory"] = {} }, ["param2"] = 0, ["y"] = 1, ["param1"] = 0, ["z"] = 16, ["name"] = "lord_ground:dirt_gondor" },
{["x"] = 0, ["meta"] = { ["fields"] = {}, ["inventory"] = {} }, ["param2"] = 0, ["y"] = 1, ["param1"] = 0, ["z"] = 17, ["name"] = "lord_ground:dirt_gondor" },
{["x"] = 0, ["meta"] = { ["fields"] = {}, ["inventory"] = {} }, ["param2"] = 0, ["y"] = 1, ["param1"] = 0, ["z"] = 18, ["name"] = "lord_ground:dirt_gondor" },
{["x"] = 1, ["meta"] = { ["fields"] = {}, ["inventory"] = {} }, ["param2"] = 0, ["y"] = 0, ["param1"] = 13, ["z"] = 0, ["name"] = "lottother:dirt" },
{["x"] = 1, ["meta"] = { ["fields"] = {}, ["inventory"] = {} }, ["param2"] = 0, ["y"] = 0, ["param1"] = 12, ["z"] = 1, ["name"] = "lottother:dirt" },
{["x"] = 1, ["meta"] = { ["fields"] = {}, ["inventory"] = {} }, ["param2"] = 0, ["y"] = 0, ["param1"] = 12, ["z"] = 2, ["name"] = "lottother:dirt" },
{["x"] = 1, ["meta"] = { ["fields"] = {}, ["inventory"] = {} }, ["param2"] = 0, ["y"] = 0, ["param1"] = 12, ["z"] = 3, ["name"] = "lottother:dirt" },
{["x"] = 1, ["meta"] = { ["fields"] = {}, ["inventory"] = {} }, ["param2"] = 0, ["y"] = 0, ["param1"] = 12, ["z"] = 4, ["name"] = "lottother:dirt" },
{["x"] = 1, ["meta"] = { ["fields"] = {}, ["inventory"] = {} }, ["param2"] = 0, ["y"] = 0, ["param1"] = 12, ["z"] = 5, ["name"] = "lottother:dirt" },
{["x"] = 1, ["meta"] = { ["fields"] = {}, ["inventory"] = {} }, ["param2"] = 0, ["y"] = 0, ["param1"] = 12, ["z"] = 6, ["name"] = "lottother:dirt" },
{["x"] = 1, ["meta"] = { ["fields"] = {}, ["inventory"] = {} }, ["param2"] = 0, ["y"] = 0, ["param1"] = 12, ["z"] = 7, ["name"] = "lottother:dirt" },
{["x"] = 1, ["meta"] = { ["fields"] = {}, ["inventory"] = {} }, ["param2"] = 0, ["y"] = 0, ["param1"] = 13, ["z"] = 8, ["name"] = "lottother:dirt" },
{["x"] = 1, ["meta"] = { ["fields"] = {}, ["inventory"] = {} }, ["param2"] = 0, ["y"] = 0, ["param1"] = 0, ["z"] = 9, ["name"] = "lottother:dirt" },
{["x"] = 1, ["meta"] = { ["fields"] = {}, ["inventory"] = {} }, ["param2"] = 0, ["y"] = 0, ["param1"] = 13, ["z"] = 10, ["name"] = "lottother:dirt" },
{["x"] = 1, ["meta"] = { ["fields"] = {}, ["inventory"] = {} }, ["param2"] = 0, ["y"] = 0, ["param1"] = 12, ["z"] = 11, ["name"] = "lottother:dirt" },
{["x"] = 1, ["meta"] = { ["fields"] = {}, ["inventory"] = {} }, ["param2"] = 0, ["y"] = 0, ["param1"] = 12, ["z"] = 12, ["name"] = "lottother:dirt" },
{["x"] = 1, ["meta"] = { ["fields"] = {}, ["inventory"] = {} }, ["param2"] = 0, ["y"] = 0, ["param1"] = 12, ["z"] = 13, ["name"] = "lottother:dirt" },
{["x"] = 1, ["meta"] = { ["fields"] = {}, ["inventory"] = {} }, ["param2"] = 0, ["y"] = 0, ["param1"] = 12, ["z"] = 14, ["name"] = "lottother:dirt" },
{["x"] = 1, ["meta"] = { ["fields"] = {}, ["inventory"] = {} }, ["param2"] = 0, ["y"] = 0, ["param1"] = 12, ["z"] = 15, ["name"] = "lottother:dirt" },
{["x"] = 1, ["meta"] = { ["fields"] = {}, ["inventory"] = {} }, ["param2"] = 0, ["y"] = 0, ["param1"] = 12, ["z"] = 16, ["name"] = "lottother:dirt" },
{["x"] = 1, ["meta"] = { ["fields"] = {}, ["inventory"] = {} }, ["param2"] = 0, ["y"] = 0, ["param1"] = 12, ["z"] = 17, ["name"] = "lottother:dirt" },
{["x"] = 1, ["meta"] = { ["fields"] = {}, ["inventory"] = {} }, ["param2"] = 0, ["y"] = 0, ["param1"] = 13, ["z"] = 18, ["name"] = "lottother:dirt" },
{["x"] = 1, ["meta"] = { ["fields"] = {}, ["inventory"] = {} }, ["param2"] = 0, ["y"] = 1, ["param1"] = 0, ["z"] = 0, ["name"] = "lord_ground:dirt_gondor" },
{["x"] = 1, ["meta"] = { ["fields"] = {}, ["inventory"] = {} }, ["param2"] = 0, ["y"] = 1, ["param1"] = 13, ["z"] = 1, ["name"] = "lottother:dirt" },
{["x"] = 1, ["meta"] = { ["fields"] = {}, ["inventory"] = {} }, ["param2"] = 0, ["y"] = 1, ["param1"] = 13, ["z"] = 2, ["name"] = "lottother:dirt" },
{["x"] = 1, ["meta"] = { ["fields"] = {}, ["inventory"] = {} }, ["param2"] = 0, ["y"] = 1, ["param1"] = 13, ["z"] = 3, ["name"] = "lottother:dirt" },
{["x"] = 1, ["meta"] = { ["fields"] = {}, ["inventory"] = {} }, ["param2"] = 0, ["y"] = 1, ["param1"] = 13, ["z"] = 4, ["name"] = "lottother:dirt" },
{["x"] = 1, ["meta"] = { ["fields"] = {}, ["inventory"] = {} }, ["param2"] = 0, ["y"] = 1, ["param1"] = 13, ["z"] = 5, ["name"] = "lottother:dirt" },
{["x"] = 1, ["meta"] = { ["fields"] = {}, ["inventory"] = {} }, ["param2"] = 0, ["y"] = 1, ["param1"] = 13, ["z"] = 6, ["name"] = "lottother:dirt" },
{["x"] = 1, ["meta"] = { ["fields"] = {}, ["inventory"] = {} }, ["param2"] = 0, ["y"] = 1, ["param1"] = 13, ["z"] = 7, ["name"] = "lottother:dirt" },
{["x"] = 1, ["meta"] = { ["fields"] = {}, ["inventory"] = {} }, ["param2"] = 0, ["y"] = 1, ["param1"] = 0, ["z"] = 8, ["name"] = "lord_ground:dirt_gondor" },
{["x"] = 1, ["meta"] = { ["fields"] = {}, ["inventory"] = {} }, ["param2"] = 0, ["y"] = 1, ["param1"] = 0, ["z"] = 9, ["name"] = "lord_ground:dirt_gondor" },
{["x"] = 1, ["meta"] = { ["fields"] = {}, ["inventory"] = {} }, ["param2"] = 0, ["y"] = 1, ["param1"] = 0, ["z"] = 10, ["name"] = "lord_ground:dirt_gondor" },
{["x"] = 1, ["meta"] = { ["fields"] = {}, ["inventory"] = {} }, ["param2"] = 0, ["y"] = 1, ["param1"] = 13, ["z"] = 11, ["name"] = "lottother:dirt" },
{["x"] = 1, ["meta"] = { ["fields"] = {}, ["inventory"] = {} }, ["param2"] = 0, ["y"] = 1, ["param1"] = 13, ["z"] = 12, ["name"] = "lottother:dirt" },
{["x"] = 1, ["meta"] = { ["fields"] = {}, ["inventory"] = {} }, ["param2"] = 0, ["y"] = 1, ["param1"] = 13, ["z"] = 13, ["name"] = "lottother:dirt" },
{["x"] = 1, ["meta"] = { ["fields"] = {}, ["inventory"] = {} }, ["param2"] = 0, ["y"] = 1, ["param1"] = 13, ["z"] = 14, ["name"] = "lottother:dirt" },
{["x"] = 1, ["meta"] = { ["fields"] = {}, ["inventory"] = {} }, ["param2"] = 0, ["y"] = 1, ["param1"] = 13, ["z"] = 15, ["name"] = "lottother:dirt" },
{["x"] = 1, ["meta"] = { ["fields"] = {}, ["inventory"] = {} }, ["param2"] = 0, ["y"] = 1, ["param1"] = 0, ["z"] = 16, ["name"] = "lottother:dirt" },
{["x"] = 1, ["meta"] = { ["fields"] = {}, ["inventory"] = {} }, ["param2"] = 0, ["y"] = 1, ["param1"] = 0, ["z"] = 17, ["name"] = "lottother:dirt" },
{["x"] = 1, ["meta"] = { ["fields"] = {}, ["inventory"] = {} }, ["param2"] = 0, ["y"] = 1, ["param1"] = 0, ["z"] = 18, ["name"] = "lord_ground:dirt_gondor" },
{["x"] = 1, ["meta"] = { ["fields"] = {}, ["inventory"] = {} }, ["param2"] = 0, ["y"] = 2, ["param1"] = 0, ["z"] = 1, ["name"] = "lord_ground:dirt_gondor" },
{["x"] = 1, ["meta"] = { ["fields"] = {}, ["inventory"] = {} }, ["param2"] = 0, ["y"] = 2, ["param1"] = 0, ["z"] = 2, ["name"] = "lord_ground:dirt_gondor" },
{["x"] = 1, ["meta"] = { ["fields"] = {}, ["inventory"] = {} }, ["param2"] = 0, ["y"] = 2, ["param1"] = 0, ["z"] = 3, ["name"] = "lord_ground:dirt_gondor" },
{["x"] = 1, ["meta"] = { ["fields"] = {}, ["inventory"] = {} }, ["param2"] = 0, ["y"] = 2, ["param1"] = 0, ["z"] = 4, ["name"] = "lord_ground:dirt_gondor" },
{["x"] = 1, ["meta"] = { ["fields"] = {}, ["inventory"] = {} }, ["param2"] = 0, ["y"] = 2, ["param1"] = 0, ["z"] = 5, ["name"] = "lord_ground:dirt_gondor" },
{["x"] = 1, ["meta"] = { ["fields"] = {}, ["inventory"] = {} }, ["param2"] = 0, ["y"] = 2, ["param1"] = 0, ["z"] = 6, ["name"] = "lord_ground:dirt_gondor" },
{["x"] = 1, ["meta"] = { ["fields"] = {}, ["inventory"] = {} }, ["param2"] = 0, ["y"] = 2, ["param1"] = 0, ["z"] = 7, ["name"] = "lord_ground:dirt_gondor" },
{["x"] = 1, ["meta"] = { ["fields"] = {}, ["inventory"] = {} }, ["param2"] = 0, ["y"] = 2, ["param1"] = 0, ["z"] = 11, ["name"] = "lord_ground:dirt_gondor" },
{["x"] = 1, ["meta"] = { ["fields"] = {}, ["inventory"] = {} }, ["param2"] = 0, ["y"] = 2, ["param1"] = 0, ["z"] = 12, ["name"] = "lord_ground:dirt_gondor" },
{["x"] = 1, ["meta"] = { ["fields"] = {}, ["inventory"] = {} }, ["param2"] = 0, ["y"] = 2, ["param1"] = 0, ["z"] = 13, ["name"] = "lord_ground:dirt_gondor" },
{["x"] = 1, ["meta"] = { ["fields"] = {}, ["inventory"] = {} }, ["param2"] = 0, ["y"] = 2, ["param1"] = 0, ["z"] = 14, ["name"] = "lord_ground:dirt_gondor" },
{["x"] = 1, ["meta"] = { ["fields"] = {}, ["inventory"] = {} }, ["param2"] = 0, ["y"] = 2, ["param1"] = 0, ["z"] = 15, ["name"] = "lord_ground:dirt_gondor" },
{["x"] = 1, ["meta"] = { ["fields"] = {}, ["inventory"] = {} }, ["param2"] = 0, ["y"] = 2, ["param1"] = 0, ["z"] = 16, ["name"] = "lord_ground:dirt_gondor" },
{["x"] = 1, ["meta"] = { ["fields"] = {}, ["inventory"] = {} }, ["param2"] = 0, ["y"] = 2, ["param1"] = 0, ["z"] = 17, ["name"] = "lord_ground:dirt_gondor" },
{["x"] = 2, ["meta"] = { ["fields"] = {}, ["inventory"] = {} }, ["param2"] = 0, ["y"] = 0, ["param1"] = 13, ["z"] = 0, ["name"] = "lottother:dirt" },
{["x"] = 2, ["meta"] = { ["fields"] = {}, ["inventory"] = {} }, ["param2"] = 0, ["y"] = 0, ["param1"] = 12, ["z"] = 1, ["name"] = "lottother:dirt" },
{["x"] = 2, ["meta"] = { ["fields"] = {}, ["inventory"] = {} }, ["param2"] = 0, ["y"] = 0, ["param1"] = 11, ["z"] = 2, ["name"] = "lottother:dirt" },
{["x"] = 2, ["meta"] = { ["fields"] = {}, ["inventory"] = {} }, ["param2"] = 0, ["y"] = 0, ["param1"] = 11, ["z"] = 3, ["name"] = "lottother:dirt" },
{["x"] = 2, ["meta"] = { ["fields"] = {}, ["inventory"] = {} }, ["param2"] = 0, ["y"] = 0, ["param1"] = 11, ["z"] = 4, ["name"] = "lottother:dirt" },
{["x"] = 2, ["meta"] = { ["fields"] = {}, ["inventory"] = {} }, ["param2"] = 0, ["y"] = 0, ["param1"] = 11, ["z"] = 5, ["name"] = "lottother:dirt" },
{["x"] = 2, ["meta"] = { ["fields"] = {}, ["inventory"] = {} }, ["param2"] = 0, ["y"] = 0, ["param1"] = 11, ["z"] = 6, ["name"] = "lottother:dirt" },
{["x"] = 2, ["meta"] = { ["fields"] = {}, ["inventory"] = {} }, ["param2"] = 0, ["y"] = 0, ["param1"] = 11, ["z"] = 7, ["name"] = "lottother:dirt" },
{["x"] = 2, ["meta"] = { ["fields"] = {}, ["inventory"] = {} }, ["param2"] = 0, ["y"] = 0, ["param1"] = 12, ["z"] = 8, ["name"] = "lottother:dirt" },
{["x"] = 2, ["meta"] = { ["fields"] = {}, ["inventory"] = {} }, ["param2"] = 0, ["y"] = 0, ["param1"] = 13, ["z"] = 9, ["name"] = "lottother:dirt" },
{["x"] = 2, ["meta"] = { ["fields"] = {}, ["inventory"] = {} }, ["param2"] = 0, ["y"] = 0, ["param1"] = 12, ["z"] = 10, ["name"] = "lottother:dirt" },
{["x"] = 2, ["meta"] = { ["fields"] = {}, ["inventory"] = {} }, ["param2"] = 0, ["y"] = 0, ["param1"] = 11, ["z"] = 11, ["name"] = "lottother:dirt" },
{["x"] = 2, ["meta"] = { ["fields"] = {}, ["inventory"] = {} }, ["param2"] = 0, ["y"] = 0, ["param1"] = 11, ["z"] = 12, ["name"] = "lottother:dirt" },
{["x"] = 2, ["meta"] = { ["fields"] = {}, ["inventory"] = {} }, ["param2"] = 0, ["y"] = 0, ["param1"] = 11, ["z"] = 13, ["name"] = "lottother:dirt" },
{["x"] = 2, ["meta"] = { ["fields"] = {}, ["inventory"] = {} }, ["param2"] = 0, ["y"] = 0, ["param1"] = 11, ["z"] = 14, ["name"] = "lottother:dirt" },
{["x"] = 2, ["meta"] = { ["fields"] = {}, ["inventory"] = {} }, ["param2"] = 0, ["y"] = 0, ["param1"] = 11, ["z"] = 15, ["name"] = "lottother:dirt" },
{["x"] = 2, ["meta"] = { ["fields"] = {}, ["inventory"] = {} }, ["param2"] = 0, ["y"] = 0, ["param1"] = 11, ["z"] = 16, ["name"] = "lottother:dirt" },
{["x"] = 2, ["meta"] = { ["fields"] = {}, ["inventory"] = {} }, ["param2"] = 0, ["y"] = 0, ["param1"] = 12, ["z"] = 17, ["name"] = "lottother:dirt" },
{["x"] = 2, ["meta"] = { ["fields"] = {}, ["inventory"] = {} }, ["param2"] = 0, ["y"] = 0, ["param1"] = 13, ["z"] = 18, ["name"] = "lottother:dirt" },
{["x"] = 2, ["meta"] = { ["fields"] = {}, ["inventory"] = {} }, ["param2"] = 0, ["y"] = 1, ["param1"] = 0, ["z"] = 0, ["name"] = "lord_ground:dirt_gondor" },
{["x"] = 2, ["meta"] = { ["fields"] = {}, ["inventory"] = {} }, ["param2"] = 0, ["y"] = 1, ["param1"] = 13, ["z"] = 1, ["name"] = "lottother:dirt" },
{["x"] = 2, ["meta"] = { ["fields"] = {}, ["inventory"] = {} }, ["param2"] = 0, ["y"] = 1, ["param1"] = 12, ["z"] = 2, ["name"] = "lottother:dirt" },
{["x"] = 2, ["meta"] = { ["fields"] = {}, ["inventory"] = {} }, ["param2"] = 0, ["y"] = 1, ["param1"] = 12, ["z"] = 3, ["name"] = "lottother:dirt" },
{["x"] = 2, ["meta"] = { ["fields"] = {}, ["inventory"] = {} }, ["param2"] = 0, ["y"] = 1, ["param1"] = 12, ["z"] = 4, ["name"] = "lottother:dirt" },
{["x"] = 2, ["meta"] = { ["fields"] = {}, ["inventory"] = {} }, ["param2"] = 0, ["y"] = 1, ["param1"] = 12, ["z"] = 5, ["name"] = "lottother:dirt" },
{["x"] = 2, ["meta"] = { ["fields"] = {}, ["inventory"] = {} }, ["param2"] = 0, ["y"] = 1, ["param1"] = 12, ["z"] = 6, ["name"] = "lottother:dirt" },
{["x"] = 2, ["meta"] = { ["fields"] = {}, ["inventory"] = {} }, ["param2"] = 0, ["y"] = 1, ["param1"] = 13, ["z"] = 7, ["name"] = "lottother:dirt" },
{["x"] = 2, ["meta"] = { ["fields"] = {}, ["inventory"] = {} }, ["param2"] = 0, ["y"] = 1, ["param1"] = 0, ["z"] = 8, ["name"] = "lord_ground:dirt_gondor" },
{["x"] = 2, ["meta"] = { ["fields"] = {}, ["inventory"] = {} }, ["param2"] = 0, ["y"] = 1, ["param1"] = 0, ["z"] = 9, ["name"] = "lord_ground:dirt_gondor" },
{["x"] = 2, ["meta"] = { ["fields"] = {}, ["inventory"] = {} }, ["param2"] = 0, ["y"] = 1, ["param1"] = 0, ["z"] = 10, ["name"] = "lord_ground:dirt_gondor" },
{["x"] = 2, ["meta"] = { ["fields"] = {}, ["inventory"] = {} }, ["param2"] = 0, ["y"] = 1, ["param1"] = 13, ["z"] = 11, ["name"] = "lottother:dirt" },
{["x"] = 2, ["meta"] = { ["fields"] = {}, ["inventory"] = {} }, ["param2"] = 0, ["y"] = 1, ["param1"] = 12, ["z"] = 12, ["name"] = "lottother:dirt" },
{["x"] = 2, ["meta"] = { ["fields"] = {}, ["inventory"] = {} }, ["param2"] = 0, ["y"] = 1, ["param1"] = 12, ["z"] = 13, ["name"] = "lottother:dirt" },
{["x"] = 2, ["meta"] = { ["fields"] = {}, ["inventory"] = {} }, ["param2"] = 0, ["y"] = 1, ["param1"] = 12, ["z"] = 14, ["name"] = "lottother:dirt" },
{["x"] = 2, ["meta"] = { ["fields"] = {}, ["inventory"] = {} }, ["param2"] = 0, ["y"] = 1, ["param1"] = 12, ["z"] = 15, ["name"] = "lottother:dirt" },
{["x"] = 2, ["meta"] = { ["fields"] = {}, ["inventory"] = {} }, ["param2"] = 0, ["y"] = 1, ["param1"] = 0, ["z"] = 16, ["name"] = "lottother:dirt" },
{["x"] = 2, ["meta"] = { ["fields"] = {}, ["inventory"] = {} }, ["param2"] = 0, ["y"] = 1, ["param1"] = 0, ["z"] = 17, ["name"] = "lottother:dirt" },
{["x"] = 2, ["meta"] = { ["fields"] = {}, ["inventory"] = {} }, ["param2"] = 0, ["y"] = 1, ["param1"] = 0, ["z"] = 18, ["name"] = "lord_ground:dirt_gondor" },
{["x"] = 2, ["meta"] = { ["fields"] = {}, ["inventory"] = {} }, ["param2"] = 0, ["y"] = 2, ["param1"] = 0, ["z"] = 1, ["name"] = "lord_ground:dirt_gondor" },
{["x"] = 2, ["meta"] = { ["fields"] = {}, ["inventory"] = {} }, ["param2"] = 0, ["y"] = 2, ["param1"] = 0, ["z"] = 2, ["name"] = "lottother:dirt" },
{["x"] = 2, ["meta"] = { ["fields"] = {}, ["inventory"] = {} }, ["param2"] = 0, ["y"] = 2, ["param1"] = 0, ["z"] = 3, ["name"] = "lottother:dirt" },
{["x"] = 2, ["meta"] = { ["fields"] = {}, ["inventory"] = {} }, ["param2"] = 0, ["y"] = 2, ["param1"] = 0, ["z"] = 4, ["name"] = "lottother:dirt" },
{["x"] = 2, ["meta"] = { ["fields"] = {}, ["inventory"] = {} }, ["param2"] = 0, ["y"] = 2, ["param1"] = 0, ["z"] = 5, ["name"] = "lottother:dirt" },
{["x"] = 2, ["meta"] = { ["fields"] = {}, ["inventory"] = {} }, ["param2"] = 0, ["y"] = 2, ["param1"] = 0, ["z"] = 6, ["name"] = "lottother:dirt" },
{["x"] = 2, ["meta"] = { ["fields"] = {}, ["inventory"] = {} }, ["param2"] = 0, ["y"] = 2, ["param1"] = 0, ["z"] = 7, ["name"] = "lord_ground:dirt_gondor" },
{["x"] = 2, ["meta"] = { ["fields"] = {}, ["inventory"] = {} }, ["param2"] = 0, ["y"] = 2, ["param1"] = 0, ["z"] = 11, ["name"] = "lord_ground:dirt_gondor" },
{["x"] = 2, ["meta"] = { ["fields"] = {}, ["inventory"] = {} }, ["param2"] = 0, ["y"] = 2, ["param1"] = 0, ["z"] = 12, ["name"] = "lottother:dirt" },
{["x"] = 2, ["meta"] = { ["fields"] = {}, ["inventory"] = {} }, ["param2"] = 0, ["y"] = 2, ["param1"] = 0, ["z"] = 13, ["name"] = "lottother:dirt" },
{["x"] = 2, ["meta"] = { ["fields"] = {}, ["inventory"] = {} }, ["param2"] = 0, ["y"] = 2, ["param1"] = 0, ["z"] = 14, ["name"] = "lottother:dirt" },
{["x"] = 2, ["meta"] = { ["fields"] = {}, ["inventory"] = {} }, ["param2"] = 0, ["y"] = 2, ["param1"] = 0, ["z"] = 15, ["name"] = "lottother:dirt" },
{["x"] = 2, ["meta"] = { ["fields"] = {}, ["inventory"] = {} }, ["param2"] = 0, ["y"] = 2, ["param1"] = 0, ["z"] = 16, ["name"] = "lottother:dirt" },
{["x"] = 2, ["meta"] = { ["fields"] = {}, ["inventory"] = {} }, ["param2"] = 0, ["y"] = 2, ["param1"] = 0, ["z"] = 17, ["name"] = "lord_ground:dirt_gondor" },
{["x"] = 2, ["meta"] = { ["fields"] = {}, ["inventory"] = {} }, ["param2"] = 0, ["y"] = 3, ["param1"] = 0, ["z"] = 2, ["name"] = "lottblocks:marble_brick" },
{["x"] = 2, ["meta"] = { ["fields"] = {}, ["inventory"] = {} }, ["param2"] = 0, ["y"] = 3, ["param1"] = 0, ["z"] = 3, ["name"] = "lottblocks:marble_brick" },
{["x"] = 2, ["meta"] = { ["fields"] = {}, ["inventory"] = {} }, ["param2"] = 0, ["y"] = 3, ["param1"] = 0, ["z"] = 4, ["name"] = "lottblocks:marble_brick" },
{["x"] = 2, ["meta"] = { ["fields"] = {}, ["inventory"] = {} }, ["param2"] = 0, ["y"] = 3, ["param1"] = 0, ["z"] = 5, ["name"] = "lottblocks:marble_brick" },
{["x"] = 2, ["meta"] = { ["fields"] = {}, ["inventory"] = {} }, ["param2"] = 0, ["y"] = 3, ["param1"] = 0, ["z"] = 6, ["name"] = "lottblocks:marble_brick" },
{["x"] = 2, ["meta"] = { ["fields"] = {}, ["inventory"] = {} }, ["param2"] = 0, ["y"] = 3, ["param1"] = 0, ["z"] = 12, ["name"] = "lottblocks:marble_brick" },
{["x"] = 2, ["meta"] = { ["fields"] = {}, ["inventory"] = {} }, ["param2"] = 0, ["y"] = 3, ["param1"] = 0, ["z"] = 13, ["name"] = "lottblocks:marble_brick" },
{["x"] = 2, ["meta"] = { ["fields"] = {}, ["inventory"] = {} }, ["param2"] = 0, ["y"] = 3, ["param1"] = 0, ["z"] = 14, ["name"] = "lottblocks:marble_brick" },
{["x"] = 2, ["meta"] = { ["fields"] = {}, ["inventory"] = {} }, ["param2"] = 0, ["y"] = 3, ["param1"] = 0, ["z"] = 15, ["name"] = "lottblocks:marble_brick" },
{["x"] = 2, ["meta"] = { ["fields"] = {}, ["inventory"] = {} }, ["param2"] = 0, ["y"] = 3, ["param1"] = 0, ["z"] = 16, ["name"] = "lottblocks:marble_brick" },
{["x"] = 2, ["meta"] = { ["fields"] = {}, ["inventory"] = {} }, ["param2"] = 0, ["y"] = 4, ["param1"] = 0, ["z"] = 2, ["name"] = "lottblocks:marble_brick" },
{["x"] = 2, ["meta"] = { ["fields"] = {}, ["inventory"] = {} }, ["param2"] = 0, ["y"] = 4, ["param1"] = 0, ["z"] = 3, ["name"] = "lottblocks:marble_brick" },
{["x"] = 2, ["meta"] = { ["fields"] = {}, ["inventory"] = {} }, ["param2"] = 0, ["y"] = 4, ["param1"] = 0, ["z"] = 4, ["name"] = "lottblocks:marble_brick" },
{["x"] = 2, ["meta"] = { ["fields"] = {}, ["inventory"] = {} }, ["param2"] = 0, ["y"] = 4, ["param1"] = 0, ["z"] = 5, ["name"] = "lottblocks:marble_brick" },
{["x"] = 2, ["meta"] = { ["fields"] = {}, ["inventory"] = {} }, ["param2"] = 0, ["y"] = 4, ["param1"] = 0, ["z"] = 6, ["name"] = "lottblocks:marble_brick" },
{["x"] = 2, ["meta"] = { ["fields"] = {}, ["inventory"] = {} }, ["param2"] = 0, ["y"] = 4, ["param1"] = 0, ["z"] = 12, ["name"] = "lottblocks:marble_brick" },
{["x"] = 2, ["meta"] = { ["fields"] = {}, ["inventory"] = {} }, ["param2"] = 0, ["y"] = 4, ["param1"] = 0, ["z"] = 13, ["name"] = "lottblocks:marble_brick" },
{["x"] = 2, ["meta"] = { ["fields"] = {}, ["inventory"] = {} }, ["param2"] = 0, ["y"] = 4, ["param1"] = 0, ["z"] = 14, ["name"] = "lottblocks:marble_brick" },
{["x"] = 2, ["meta"] = { ["fields"] = {}, ["inventory"] = {} }, ["param2"] = 0, ["y"] = 4, ["param1"] = 0, ["z"] = 15, ["name"] = "lottblocks:marble_brick" },
{["x"] = 2, ["meta"] = { ["fields"] = {}, ["inventory"] = {} }, ["param2"] = 0, ["y"] = 4, ["param1"] = 0, ["z"] = 16, ["name"] = "lottblocks:marble_brick" },
{["x"] = 2, ["meta"] = { ["fields"] = {}, ["inventory"] = {} }, ["param2"] = 0, ["y"] = 5, ["param1"] = 0, ["z"] = 2, ["name"] = "lottblocks:marble_brick" },
{["x"] = 2, ["meta"] = { ["fields"] = {}, ["inventory"] = {} }, ["param2"] = 0, ["y"] = 5, ["param1"] = 0, ["z"] = 3, ["name"] = "lottblocks:marble_brick" },
{["x"] = 2, ["meta"] = { ["fields"] = {}, ["inventory"] = {} }, ["param2"] = 0, ["y"] = 5, ["param1"] = 0, ["z"] = 4, ["name"] = "lottblocks:marble_brick" },
{["x"] = 2, ["meta"] = { ["fields"] = {}, ["inventory"] = {} }, ["param2"] = 0, ["y"] = 5, ["param1"] = 0, ["z"] = 5, ["name"] = "lottblocks:marble_brick" },
{["x"] = 2, ["meta"] = { ["fields"] = {}, ["inventory"] = {} }, ["param2"] = 0, ["y"] = 5, ["param1"] = 0, ["z"] = 6, ["name"] = "lottblocks:marble_brick" },
{["x"] = 2, ["meta"] = { ["fields"] = {}, ["inventory"] = {} }, ["param2"] = 0, ["y"] = 5, ["param1"] = 0, ["z"] = 12, ["name"] = "lottblocks:marble_brick" },
{["x"] = 2, ["meta"] = { ["fields"] = {}, ["inventory"] = {} }, ["param2"] = 0, ["y"] = 5, ["param1"] = 0, ["z"] = 13, ["name"] = "lottblocks:marble_brick" },
{["x"] = 2, ["meta"] = { ["fields"] = {}, ["inventory"] = {} }, ["param2"] = 0, ["y"] = 5, ["param1"] = 0, ["z"] = 14, ["name"] = "lottblocks:marble_brick" },
{["x"] = 2, ["meta"] = { ["fields"] = {}, ["inventory"] = {} }, ["param2"] = 0, ["y"] = 5, ["param1"] = 0, ["z"] = 15, ["name"] = "lottblocks:marble_brick" },
{["x"] = 2, ["meta"] = { ["fields"] = {}, ["inventory"] = {} }, ["param2"] = 0, ["y"] = 5, ["param1"] = 0, ["z"] = 16, ["name"] = "lottblocks:marble_brick" },
{["x"] = 2, ["meta"] = { ["fields"] = {}, ["inventory"] = {} }, ["param2"] = 0, ["y"] = 6, ["param1"] = 0, ["z"] = 2, ["name"] = "lottblocks:marble_brick" },
{["x"] = 2, ["meta"] = { ["fields"] = {}, ["inventory"] = {} }, ["param2"] = 0, ["y"] = 6, ["param1"] = 0, ["z"] = 3, ["name"] = "lottblocks:marble_brick" },
{["x"] = 2, ["meta"] = { ["fields"] = {}, ["inventory"] = {} }, ["param2"] = 0, ["y"] = 6, ["param1"] = 0, ["z"] = 4, ["name"] = "lottblocks:marble_brick" },
{["x"] = 2, ["meta"] = { ["fields"] = {}, ["inventory"] = {} }, ["param2"] = 0, ["y"] = 6, ["param1"] = 0, ["z"] = 5, ["name"] = "lottblocks:marble_brick" },
{["x"] = 2, ["meta"] = { ["fields"] = {}, ["inventory"] = {} }, ["param2"] = 0, ["y"] = 6, ["param1"] = 0, ["z"] = 6, ["name"] = "lottblocks:marble_brick" },
{["x"] = 2, ["meta"] = { ["fields"] = {}, ["inventory"] = {} }, ["param2"] = 0, ["y"] = 6, ["param1"] = 0, ["z"] = 12, ["name"] = "lottblocks:marble_brick" },
{["x"] = 2, ["meta"] = { ["fields"] = {}, ["inventory"] = {} }, ["param2"] = 0, ["y"] = 6, ["param1"] = 0, ["z"] = 13, ["name"] = "lottblocks:marble_brick" },
{["x"] = 2, ["meta"] = { ["fields"] = {}, ["inventory"] = {} }, ["param2"] = 0, ["y"] = 6, ["param1"] = 0, ["z"] = 14, ["name"] = "lottblocks:marble_brick" },
{["x"] = 2, ["meta"] = { ["fields"] = {}, ["inventory"] = {} }, ["param2"] = 0, ["y"] = 6, ["param1"] = 0, ["z"] = 15, ["name"] = "lottblocks:marble_brick" },
{["x"] = 2, ["meta"] = { ["fields"] = {}, ["inventory"] = {} }, ["param2"] = 0, ["y"] = 6, ["param1"] = 0, ["z"] = 16, ["name"] = "lottblocks:marble_brick" },
{["x"] = 2, ["meta"] = { ["fields"] = {}, ["inventory"] = {} }, ["param2"] = 0, ["y"] = 7, ["param1"] = 0, ["z"] = 2, ["name"] = "lottblocks:marble_brick" },
{["x"] = 2, ["meta"] = { ["fields"] = {}, ["inventory"] = {} }, ["param2"] = 0, ["y"] = 7, ["param1"] = 0, ["z"] = 3, ["name"] = "lottblocks:marble_brick" },
{["x"] = 2, ["meta"] = { ["fields"] = {}, ["inventory"] = {} }, ["param2"] = 0, ["y"] = 7, ["param1"] = 0, ["z"] = 4, ["name"] = "lottblocks:marble_brick" },
{["x"] = 2, ["meta"] = { ["fields"] = {}, ["inventory"] = {} }, ["param2"] = 0, ["y"] = 7, ["param1"] = 0, ["z"] = 5, ["name"] = "lottblocks:marble_brick" },
{["x"] = 2, ["meta"] = { ["fields"] = {}, ["inventory"] = {} }, ["param2"] = 0, ["y"] = 7, ["param1"] = 0, ["z"] = 6, ["name"] = "lottblocks:marble_brick" },
{["x"] = 2, ["meta"] = { ["fields"] = {}, ["inventory"] = {} }, ["param2"] = 0, ["y"] = 7, ["param1"] = 0, ["z"] = 12, ["name"] = "lottblocks:marble_brick" },
{["x"] = 2, ["meta"] = { ["fields"] = {}, ["inventory"] = {} }, ["param2"] = 0, ["y"] = 7, ["param1"] = 0, ["z"] = 13, ["name"] = "lottblocks:marble_brick" },
{["x"] = 2, ["meta"] = { ["fields"] = {}, ["inventory"] = {} }, ["param2"] = 0, ["y"] = 7, ["param1"] = 0, ["z"] = 14, ["name"] = "lottblocks:marble_brick" },
{["x"] = 2, ["meta"] = { ["fields"] = {}, ["inventory"] = {} }, ["param2"] = 0, ["y"] = 7, ["param1"] = 0, ["z"] = 15, ["name"] = "lottblocks:marble_brick" },
{["x"] = 2, ["meta"] = { ["fields"] = {}, ["inventory"] = {} }, ["param2"] = 0, ["y"] = 7, ["param1"] = 0, ["z"] = 16, ["name"] = "lottblocks:marble_brick" },
{["x"] = 2, ["meta"] = { ["fields"] = {}, ["inventory"] = {} }, ["param2"] = 0, ["y"] = 8, ["param1"] = 0, ["z"] = 2, ["name"] = "lottblocks:marble_brick" },
{["x"] = 2, ["meta"] = { ["fields"] = {}, ["inventory"] = {} }, ["param2"] = 0, ["y"] = 8, ["param1"] = 0, ["z"] = 3, ["name"] = "lottblocks:marble_brick" },
{["x"] = 2, ["meta"] = { ["fields"] = {}, ["inventory"] = {} }, ["param2"] = 0, ["y"] = 8, ["param1"] = 0, ["z"] = 4, ["name"] = "lottblocks:marble_brick" },
{["x"] = 2, ["meta"] = { ["fields"] = {}, ["inventory"] = {} }, ["param2"] = 0, ["y"] = 8, ["param1"] = 0, ["z"] = 5, ["name"] = "lottblocks:marble_brick" },
{["x"] = 2, ["meta"] = { ["fields"] = {}, ["inventory"] = {} }, ["param2"] = 0, ["y"] = 8, ["param1"] = 0, ["z"] = 6, ["name"] = "lottblocks:marble_brick" },
{["x"] = 2, ["meta"] = { ["fields"] = {}, ["inventory"] = {} }, ["param2"] = 0, ["y"] = 8, ["param1"] = 0, ["z"] = 12, ["name"] = "lottblocks:marble_brick" },
{["x"] = 2, ["meta"] = { ["fields"] = {}, ["inventory"] = {} }, ["param2"] = 0, ["y"] = 8, ["param1"] = 0, ["z"] = 13, ["name"] = "lottblocks:marble_brick" },
{["x"] = 2, ["meta"] = { ["fields"] = {}, ["inventory"] = {} }, ["param2"] = 0, ["y"] = 8, ["param1"] = 0, ["z"] = 14, ["name"] = "lottblocks:marble_brick" },
{["x"] = 2, ["meta"] = { ["fields"] = {}, ["inventory"] = {} }, ["param2"] = 0, ["y"] = 8, ["param1"] = 0, ["z"] = 15, ["name"] = "lottblocks:marble_brick" },
{["x"] = 2, ["meta"] = { ["fields"] = {}, ["inventory"] = {} }, ["param2"] = 0, ["y"] = 8, ["param1"] = 0, ["z"] = 16, ["name"] = "lottblocks:marble_brick" },
{["x"] = 2, ["meta"] = { ["fields"] = {}, ["inventory"] = {} }, ["param2"] = 0, ["y"] = 9, ["param1"] = 0, ["z"] = 2, ["name"] = "lottblocks:marble_brick" },
{["x"] = 2, ["meta"] = { ["fields"] = {}, ["inventory"] = {} }, ["param2"] = 0, ["y"] = 9, ["param1"] = 0, ["z"] = 3, ["name"] = "lottblocks:marble_brick" },
{["x"] = 2, ["meta"] = { ["fields"] = {}, ["inventory"] = {} }, ["param2"] = 0, ["y"] = 9, ["param1"] = 0, ["z"] = 4, ["name"] = "lottblocks:marble_brick" },
{["x"] = 2, ["meta"] = { ["fields"] = {}, ["inventory"] = {} }, ["param2"] = 0, ["y"] = 9, ["param1"] = 0, ["z"] = 5, ["name"] = "lottblocks:marble_brick" },
{["x"] = 2, ["meta"] = { ["fields"] = {}, ["inventory"] = {} }, ["param2"] = 0, ["y"] = 9, ["param1"] = 0, ["z"] = 6, ["name"] = "lottblocks:marble_brick" },
{["x"] = 2, ["meta"] = { ["fields"] = {}, ["inventory"] = {} }, ["param2"] = 0, ["y"] = 9, ["param1"] = 0, ["z"] = 12, ["name"] = "lottblocks:marble_brick" },
{["x"] = 2, ["meta"] = { ["fields"] = {}, ["inventory"] = {} }, ["param2"] = 0, ["y"] = 9, ["param1"] = 0, ["z"] = 13, ["name"] = "lottblocks:marble_brick" },
{["x"] = 2, ["meta"] = { ["fields"] = {}, ["inventory"] = {} }, ["param2"] = 0, ["y"] = 9, ["param1"] = 0, ["z"] = 14, ["name"] = "lottblocks:marble_brick" },
{["x"] = 2, ["meta"] = { ["fields"] = {}, ["inventory"] = {} }, ["param2"] = 0, ["y"] = 9, ["param1"] = 0, ["z"] = 15, ["name"] = "lottblocks:marble_brick" },
{["x"] = 2, ["meta"] = { ["fields"] = {}, ["inventory"] = {} }, ["param2"] = 0, ["y"] = 9, ["param1"] = 0, ["z"] = 16, ["name"] = "lottblocks:marble_brick" },
{["x"] = 2, ["meta"] = { ["fields"] = {}, ["inventory"] = {} }, ["param2"] = 0, ["y"] = 10, ["param1"] = 0, ["z"] = 2, ["name"] = "lottblocks:marble_brick" },
{["x"] = 2, ["meta"] = { ["fields"] = {}, ["inventory"] = {} }, ["param2"] = 0, ["y"] = 10, ["param1"] = 0, ["z"] = 3, ["name"] = "lottblocks:marble_brick" },
{["x"] = 2, ["meta"] = { ["fields"] = {}, ["inventory"] = {} }, ["param2"] = 0, ["y"] = 10, ["param1"] = 0, ["z"] = 4, ["name"] = "lottblocks:marble_brick" },
{["x"] = 2, ["meta"] = { ["fields"] = {}, ["inventory"] = {} }, ["param2"] = 0, ["y"] = 10, ["param1"] = 0, ["z"] = 5, ["name"] = "lottblocks:marble_brick" },
{["x"] = 2, ["meta"] = { ["fields"] = {}, ["inventory"] = {} }, ["param2"] = 0, ["y"] = 10, ["param1"] = 0, ["z"] = 6, ["name"] = "lottblocks:marble_brick" },
{["x"] = 2, ["meta"] = { ["fields"] = {}, ["inventory"] = {} }, ["param2"] = 0, ["y"] = 10, ["param1"] = 0, ["z"] = 12, ["name"] = "lottblocks:marble_brick" },
{["x"] = 2, ["meta"] = { ["fields"] = {}, ["inventory"] = {} }, ["param2"] = 0, ["y"] = 10, ["param1"] = 0, ["z"] = 13, ["name"] = "lottblocks:marble_brick" },
{["x"] = 2, ["meta"] = { ["fields"] = {}, ["inventory"] = {} }, ["param2"] = 0, ["y"] = 10, ["param1"] = 0, ["z"] = 14, ["name"] = "lottblocks:marble_brick" },
{["x"] = 2, ["meta"] = { ["fields"] = {}, ["inventory"] = {} }, ["param2"] = 0, ["y"] = 10, ["param1"] = 0, ["z"] = 15, ["name"] = "lottblocks:marble_brick" },
{["x"] = 2, ["meta"] = { ["fields"] = {}, ["inventory"] = {} }, ["param2"] = 0, ["y"] = 10, ["param1"] = 0, ["z"] = 16, ["name"] = "lottblocks:marble_brick" },
{["x"] = 2, ["meta"] = { ["fields"] = {}, ["inventory"] = {} }, ["param2"] = 0, ["y"] = 11, ["param1"] = 0, ["z"] = 2, ["name"] = "lottblocks:marble_brick" },
{["x"] = 2, ["meta"] = { ["fields"] = {}, ["inventory"] = {} }, ["param2"] = 0, ["y"] = 11, ["param1"] = 0, ["z"] = 3, ["name"] = "lottblocks:marble_brick" },
{["x"] = 2, ["meta"] = { ["fields"] = {}, ["inventory"] = {} }, ["param2"] = 0, ["y"] = 11, ["param1"] = 0, ["z"] = 4, ["name"] = "lottblocks:marble_brick" },
{["x"] = 2, ["meta"] = { ["fields"] = {}, ["inventory"] = {} }, ["param2"] = 0, ["y"] = 11, ["param1"] = 0, ["z"] = 5, ["name"] = "lottblocks:marble_brick" },
{["x"] = 2, ["meta"] = { ["fields"] = {}, ["inventory"] = {} }, ["param2"] = 0, ["y"] = 11, ["param1"] = 0, ["z"] = 6, ["name"] = "lottblocks:marble_brick" },
{["x"] = 2, ["meta"] = { ["fields"] = {}, ["inventory"] = {} }, ["param2"] = 0, ["y"] = 11, ["param1"] = 0, ["z"] = 12, ["name"] = "lottblocks:marble_brick" },
{["x"] = 2, ["meta"] = { ["fields"] = {}, ["inventory"] = {} }, ["param2"] = 0, ["y"] = 11, ["param1"] = 0, ["z"] = 13, ["name"] = "lottblocks:marble_brick" },
{["x"] = 2, ["meta"] = { ["fields"] = {}, ["inventory"] = {} }, ["param2"] = 0, ["y"] = 11, ["param1"] = 0, ["z"] = 14, ["name"] = "lottblocks:marble_brick" },
{["x"] = 2, ["meta"] = { ["fields"] = {}, ["inventory"] = {} }, ["param2"] = 0, ["y"] = 11, ["param1"] = 0, ["z"] = 15, ["name"] = "lottblocks:marble_brick" },
{["x"] = 2, ["meta"] = { ["fields"] = {}, ["inventory"] = {} }, ["param2"] = 0, ["y"] = 11, ["param1"] = 0, ["z"] = 16, ["name"] = "lottblocks:marble_brick" },
{["x"] = 2, ["meta"] = { ["fields"] = {}, ["inventory"] = {} }, ["param2"] = 0, ["y"] = 12, ["param1"] = 0, ["z"] = 2, ["name"] = "lottblocks:marble_brick" },
{["x"] = 2, ["meta"] = { ["fields"] = {}, ["inventory"] = {} }, ["param2"] = 0, ["y"] = 12, ["param1"] = 0, ["z"] = 3, ["name"] = "lottblocks:marble_brick" },
{["x"] = 2, ["meta"] = { ["fields"] = {}, ["inventory"] = {} }, ["param2"] = 0, ["y"] = 12, ["param1"] = 0, ["z"] = 4, ["name"] = "lottblocks:marble_brick" },
{["x"] = 2, ["meta"] = { ["fields"] = {}, ["inventory"] = {} }, ["param2"] = 0, ["y"] = 12, ["param1"] = 0, ["z"] = 5, ["name"] = "lottblocks:marble_brick" },
{["x"] = 2, ["meta"] = { ["fields"] = {}, ["inventory"] = {} }, ["param2"] = 0, ["y"] = 12, ["param1"] = 0, ["z"] = 6, ["name"] = "lottblocks:marble_brick" },
{["x"] = 2, ["meta"] = { ["fields"] = {}, ["inventory"] = {} }, ["param2"] = 0, ["y"] = 12, ["param1"] = 0, ["z"] = 12, ["name"] = "lottblocks:marble_brick" },
{["x"] = 2, ["meta"] = { ["fields"] = {}, ["inventory"] = {} }, ["param2"] = 0, ["y"] = 12, ["param1"] = 0, ["z"] = 13, ["name"] = "lottblocks:marble_brick" },
{["x"] = 2, ["meta"] = { ["fields"] = {}, ["inventory"] = {} }, ["param2"] = 0, ["y"] = 12, ["param1"] = 0, ["z"] = 14, ["name"] = "lottblocks:marble_brick" },
{["x"] = 2, ["meta"] = { ["fields"] = {}, ["inventory"] = {} }, ["param2"] = 0, ["y"] = 12, ["param1"] = 0, ["z"] = 15, ["name"] = "lottblocks:marble_brick" },
{["x"] = 2, ["meta"] = { ["fields"] = {}, ["inventory"] = {} }, ["param2"] = 0, ["y"] = 12, ["param1"] = 0, ["z"] = 16, ["name"] = "lottblocks:marble_brick" },
{["x"] = 2, ["meta"] = { ["fields"] = {}, ["inventory"] = {} }, ["param2"] = 0, ["y"] = 13, ["param1"] = 0, ["z"] = 2, ["name"] = "lottblocks:marble_brick" },
{["x"] = 2, ["meta"] = { ["fields"] = {}, ["inventory"] = {} }, ["param2"] = 0, ["y"] = 13, ["param1"] = 0, ["z"] = 3, ["name"] = "lottblocks:marble_brick" },
{["x"] = 2, ["meta"] = { ["fields"] = {}, ["inventory"] = {} }, ["param2"] = 0, ["y"] = 13, ["param1"] = 0, ["z"] = 4, ["name"] = "lottblocks:marble_brick" },
{["x"] = 2, ["meta"] = { ["fields"] = {}, ["inventory"] = {} }, ["param2"] = 0, ["y"] = 13, ["param1"] = 0, ["z"] = 5, ["name"] = "lottblocks:marble_brick" },
{["x"] = 2, ["meta"] = { ["fields"] = {}, ["inventory"] = {} }, ["param2"] = 0, ["y"] = 13, ["param1"] = 0, ["z"] = 6, ["name"] = "lottblocks:marble_brick" },
{["x"] = 2, ["meta"] = { ["fields"] = {}, ["inventory"] = {} }, ["param2"] = 0, ["y"] = 13, ["param1"] = 0, ["z"] = 12, ["name"] = "lottblocks:marble_brick" },
{["x"] = 2, ["meta"] = { ["fields"] = {}, ["inventory"] = {} }, ["param2"] = 0, ["y"] = 13, ["param1"] = 0, ["z"] = 13, ["name"] = "lottblocks:marble_brick" },
{["x"] = 2, ["meta"] = { ["fields"] = {}, ["inventory"] = {} }, ["param2"] = 0, ["y"] = 13, ["param1"] = 0, ["z"] = 14, ["name"] = "lottblocks:marble_brick" },
{["x"] = 2, ["meta"] = { ["fields"] = {}, ["inventory"] = {} }, ["param2"] = 0, ["y"] = 13, ["param1"] = 0, ["z"] = 15, ["name"] = "lottblocks:marble_brick" },
{["x"] = 2, ["meta"] = { ["fields"] = {}, ["inventory"] = {} }, ["param2"] = 0, ["y"] = 13, ["param1"] = 0, ["z"] = 16, ["name"] = "lottblocks:marble_brick" },
{["x"] = 2, ["meta"] = { ["fields"] = {}, ["inventory"] = {} }, ["param2"] = 0, ["y"] = 14, ["param1"] = 0, ["z"] = 2, ["name"] = "lottblocks:marble_brick" },
{["x"] = 2, ["meta"] = { ["fields"] = {}, ["inventory"] = {} }, ["param2"] = 0, ["y"] = 14, ["param1"] = 0, ["z"] = 3, ["name"] = "lottblocks:marble_brick" },
{["x"] = 2, ["meta"] = { ["fields"] = {}, ["inventory"] = {} }, ["param2"] = 0, ["y"] = 14, ["param1"] = 0, ["z"] = 4, ["name"] = "lottblocks:marble_brick" },
{["x"] = 2, ["meta"] = { ["fields"] = {}, ["inventory"] = {} }, ["param2"] = 0, ["y"] = 14, ["param1"] = 0, ["z"] = 5, ["name"] = "lottblocks:marble_brick" },
{["x"] = 2, ["meta"] = { ["fields"] = {}, ["inventory"] = {} }, ["param2"] = 0, ["y"] = 14, ["param1"] = 0, ["z"] = 6, ["name"] = "lottblocks:marble_brick" },
{["x"] = 2, ["meta"] = { ["fields"] = {}, ["inventory"] = {} }, ["param2"] = 0, ["y"] = 14, ["param1"] = 0, ["z"] = 12, ["name"] = "lottblocks:marble_brick" },
{["x"] = 2, ["meta"] = { ["fields"] = {}, ["inventory"] = {} }, ["param2"] = 0, ["y"] = 14, ["param1"] = 0, ["z"] = 13, ["name"] = "lottblocks:marble_brick" },
{["x"] = 2, ["meta"] = { ["fields"] = {}, ["inventory"] = {} }, ["param2"] = 0, ["y"] = 14, ["param1"] = 0, ["z"] = 14, ["name"] = "lottblocks:marble_brick" },
{["x"] = 2, ["meta"] = { ["fields"] = {}, ["inventory"] = {} }, ["param2"] = 0, ["y"] = 14, ["param1"] = 0, ["z"] = 15, ["name"] = "lottblocks:marble_brick" },
{["x"] = 2, ["meta"] = { ["fields"] = {}, ["inventory"] = {} }, ["param2"] = 0, ["y"] = 14, ["param1"] = 0, ["z"] = 16, ["name"] = "lottblocks:marble_brick" },
{["x"] = 2, ["meta"] = { ["fields"] = {}, ["inventory"] = {} }, ["param2"] = 0, ["y"] = 15, ["param1"] = 0, ["z"] = 3, ["name"] = "lottblocks:marble_brick" },
{["x"] = 2, ["meta"] = { ["fields"] = {}, ["inventory"] = {} }, ["param2"] = 0, ["y"] = 15, ["param1"] = 0, ["z"] = 4, ["name"] = "lottblocks:marble_brick" },
{["x"] = 2, ["meta"] = { ["fields"] = {}, ["inventory"] = {} }, ["param2"] = 0, ["y"] = 15, ["param1"] = 0, ["z"] = 5, ["name"] = "lottblocks:marble_brick" },
{["x"] = 2, ["meta"] = { ["fields"] = {}, ["inventory"] = {} }, ["param2"] = 0, ["y"] = 15, ["param1"] = 0, ["z"] = 13, ["name"] = "lottblocks:marble_brick" },
{["x"] = 2, ["meta"] = { ["fields"] = {}, ["inventory"] = {} }, ["param2"] = 0, ["y"] = 15, ["param1"] = 0, ["z"] = 14, ["name"] = "lottblocks:marble_brick" },
{["x"] = 2, ["meta"] = { ["fields"] = {}, ["inventory"] = {} }, ["param2"] = 0, ["y"] = 15, ["param1"] = 0, ["z"] = 15, ["name"] = "lottblocks:marble_brick" },
{["x"] = 2, ["meta"] = { ["fields"] = {}, ["inventory"] = {} }, ["param2"] = 0, ["y"] = 16, ["param1"] = 0, ["z"] = 3, ["name"] = "lottblocks:marble_brick" },
{["x"] = 2, ["meta"] = { ["fields"] = {}, ["inventory"] = {} }, ["param2"] = 0, ["y"] = 16, ["param1"] = 141, ["z"] = 4, ["name"] = "lottother:air" },
{["x"] = 2, ["meta"] = { ["fields"] = {}, ["inventory"] = {} }, ["param2"] = 0, ["y"] = 16, ["param1"] = 0, ["z"] = 5, ["name"] = "lottblocks:marble_brick" },
{["x"] = 2, ["meta"] = { ["fields"] = {}, ["inventory"] = {} }, ["param2"] = 0, ["y"] = 16, ["param1"] = 0, ["z"] = 13, ["name"] = "lottblocks:marble_brick" },
{["x"] = 2, ["meta"] = { ["fields"] = {}, ["inventory"] = {} }, ["param2"] = 0, ["y"] = 16, ["param1"] = 141, ["z"] = 14, ["name"] = "lottother:air" },
{["x"] = 2, ["meta"] = { ["fields"] = {}, ["inventory"] = {} }, ["param2"] = 0, ["y"] = 16, ["param1"] = 0, ["z"] = 15, ["name"] = "lottblocks:marble_brick" },
{["x"] = 2, ["meta"] = { ["fields"] = {}, ["inventory"] = {} }, ["param2"] = 0, ["y"] = 17, ["param1"] = 0, ["z"] = 3, ["name"] = "lottblocks:marble_brick" },
{["x"] = 2, ["meta"] = { ["fields"] = {}, ["inventory"] = {} }, ["param2"] = 0, ["y"] = 17, ["param1"] = 157, ["z"] = 4, ["name"] = "lottother:air" },
{["x"] = 2, ["meta"] = { ["fields"] = {}, ["inventory"] = {} }, ["param2"] = 0, ["y"] = 17, ["param1"] = 0, ["z"] = 5, ["name"] = "lottblocks:marble_brick" },
{["x"] = 2, ["meta"] = { ["fields"] = {}, ["inventory"] = {} }, ["param2"] = 0, ["y"] = 17, ["param1"] = 0, ["z"] = 13, ["name"] = "lottblocks:marble_brick" },
{["x"] = 2, ["meta"] = { ["fields"] = {}, ["inventory"] = {} }, ["param2"] = 0, ["y"] = 17, ["param1"] = 157, ["z"] = 14, ["name"] = "lottother:air" },
{["x"] = 2, ["meta"] = { ["fields"] = {}, ["inventory"] = {} }, ["param2"] = 0, ["y"] = 17, ["param1"] = 0, ["z"] = 15, ["name"] = "lottblocks:marble_brick" },
{["x"] = 2, ["meta"] = { ["fields"] = {}, ["inventory"] = {} }, ["param2"] = 0, ["y"] = 18, ["param1"] = 0, ["z"] = 3, ["name"] = "lottblocks:marble_brick" },
{["x"] = 2, ["meta"] = { ["fields"] = {}, ["inventory"] = {} }, ["param2"] = 0, ["y"] = 18, ["param1"] = 0, ["z"] = 4, ["name"] = "lottblocks:marble_brick" },
{["x"] = 2, ["meta"] = { ["fields"] = {}, ["inventory"] = {} }, ["param2"] = 0, ["y"] = 18, ["param1"] = 0, ["z"] = 5, ["name"] = "lottblocks:marble_brick" },
{["x"] = 2, ["meta"] = { ["fields"] = {}, ["inventory"] = {} }, ["param2"] = 0, ["y"] = 18, ["param1"] = 0, ["z"] = 13, ["name"] = "lottblocks:marble_brick" },
{["x"] = 2, ["meta"] = { ["fields"] = {}, ["inventory"] = {} }, ["param2"] = 0, ["y"] = 18, ["param1"] = 0, ["z"] = 14, ["name"] = "lottblocks:marble_brick" },
{["x"] = 2, ["meta"] = { ["fields"] = {}, ["inventory"] = {} }, ["param2"] = 0, ["y"] = 18, ["param1"] = 0, ["z"] = 15, ["name"] = "lottblocks:marble_brick" },
{["x"] = 2, ["meta"] = { ["fields"] = {}, ["inventory"] = {} }, ["param2"] = 0, ["y"] = 19, ["param1"] = 0, ["z"] = 3, ["name"] = "lottblocks:marble_brick" },
{["x"] = 2, ["meta"] = { ["fields"] = {}, ["inventory"] = {} }, ["param2"] = 0, ["y"] = 19, ["param1"] = 0, ["z"] = 4, ["name"] = "lottblocks:marble_brick" },
{["x"] = 2, ["meta"] = { ["fields"] = {}, ["inventory"] = {} }, ["param2"] = 0, ["y"] = 19, ["param1"] = 0, ["z"] = 5, ["name"] = "lottblocks:marble_brick" },
{["x"] = 2, ["meta"] = { ["fields"] = {}, ["inventory"] = {} }, ["param2"] = 0, ["y"] = 19, ["param1"] = 0, ["z"] = 13, ["name"] = "lottblocks:marble_brick" },
{["x"] = 2, ["meta"] = { ["fields"] = {}, ["inventory"] = {} }, ["param2"] = 0, ["y"] = 19, ["param1"] = 0, ["z"] = 14, ["name"] = "lottblocks:marble_brick" },
{["x"] = 2, ["meta"] = { ["fields"] = {}, ["inventory"] = {} }, ["param2"] = 0, ["y"] = 19, ["param1"] = 0, ["z"] = 15, ["name"] = "lottblocks:marble_brick" },
{["x"] = 3, ["meta"] = { ["fields"] = {}, ["inventory"] = {} }, ["param2"] = 0, ["y"] = 0, ["param1"] = 13, ["z"] = 0, ["name"] = "lottother:dirt" },
{["x"] = 3, ["meta"] = { ["fields"] = {}, ["inventory"] = {} }, ["param2"] = 0, ["y"] = 0, ["param1"] = 12, ["z"] = 1, ["name"] = "lottother:dirt" },
{["x"] = 3, ["meta"] = { ["fields"] = {}, ["inventory"] = {} }, ["param2"] = 0, ["y"] = 0, ["param1"] = 11, ["z"] = 2, ["name"] = "lottother:dirt" },
{["x"] = 3, ["meta"] = { ["fields"] = {}, ["inventory"] = {} }, ["param2"] = 0, ["y"] = 0, ["param1"] = 10, ["z"] = 3, ["name"] = "lottother:dirt" },
{["x"] = 3, ["meta"] = { ["fields"] = {}, ["inventory"] = {} }, ["param2"] = 0, ["y"] = 0, ["param1"] = 10, ["z"] = 4, ["name"] = "lottother:dirt" },
{["x"] = 3, ["meta"] = { ["fields"] = {}, ["inventory"] = {} }, ["param2"] = 0, ["y"] = 0, ["param1"] = 10, ["z"] = 5, ["name"] = "lottother:dirt" },
{["x"] = 3, ["meta"] = { ["fields"] = {}, ["inventory"] = {} }, ["param2"] = 0, ["y"] = 0, ["param1"] = 10, ["z"] = 6, ["name"] = "lottother:dirt" },
{["x"] = 3, ["meta"] = { ["fields"] = {}, ["inventory"] = {} }, ["param2"] = 0, ["y"] = 0, ["param1"] = 10, ["z"] = 7, ["name"] = "lottother:dirt" },
{["x"] = 3, ["meta"] = { ["fields"] = {}, ["inventory"] = {} }, ["param2"] = 0, ["y"] = 0, ["param1"] = 11, ["z"] = 8, ["name"] = "lottother:dirt" },
{["x"] = 3, ["meta"] = { ["fields"] = {}, ["inventory"] = {} }, ["param2"] = 0, ["y"] = 0, ["param1"] = 12, ["z"] = 9, ["name"] = "lottother:dirt" },
{["x"] = 3, ["meta"] = { ["fields"] = {}, ["inventory"] = {} }, ["param2"] = 0, ["y"] = 0, ["param1"] = 11, ["z"] = 10, ["name"] = "lottother:dirt" },
{["x"] = 3, ["meta"] = { ["fields"] = {}, ["inventory"] = {} }, ["param2"] = 0, ["y"] = 0, ["param1"] = 10, ["z"] = 11, ["name"] = "lottother:dirt" },
{["x"] = 3, ["meta"] = { ["fields"] = {}, ["inventory"] = {} }, ["param2"] = 0, ["y"] = 0, ["param1"] = 10, ["z"] = 12, ["name"] = "lottother:dirt" },
{["x"] = 3, ["meta"] = { ["fields"] = {}, ["inventory"] = {} }, ["param2"] = 0, ["y"] = 0, ["param1"] = 10, ["z"] = 13, ["name"] = "lottother:dirt" },
{["x"] = 3, ["meta"] = { ["fields"] = {}, ["inventory"] = {} }, ["param2"] = 0, ["y"] = 0, ["param1"] = 10, ["z"] = 14, ["name"] = "lottother:dirt" },
{["x"] = 3, ["meta"] = { ["fields"] = {}, ["inventory"] = {} }, ["param2"] = 0, ["y"] = 0, ["param1"] = 10, ["z"] = 15, ["name"] = "lottother:dirt" },
{["x"] = 3, ["meta"] = { ["fields"] = {}, ["inventory"] = {} }, ["param2"] = 0, ["y"] = 0, ["param1"] = 11, ["z"] = 16, ["name"] = "lottother:dirt" },
{["x"] = 3, ["meta"] = { ["fields"] = {}, ["inventory"] = {} }, ["param2"] = 0, ["y"] = 0, ["param1"] = 12, ["z"] = 17, ["name"] = "lottother:dirt" },
{["x"] = 3, ["meta"] = { ["fields"] = {}, ["inventory"] = {} }, ["param2"] = 0, ["y"] = 0, ["param1"] = 13, ["z"] = 18, ["name"] = "lottother:dirt" },
{["x"] = 3, ["meta"] = { ["fields"] = {}, ["inventory"] = {} }, ["param2"] = 0, ["y"] = 1, ["param1"] = 0, ["z"] = 0, ["name"] = "lord_ground:dirt_gondor" },
{["x"] = 3, ["meta"] = { ["fields"] = {}, ["inventory"] = {} }, ["param2"] = 0, ["y"] = 1, ["param1"] = 13, ["z"] = 1, ["name"] = "lottother:dirt" },
{["x"] = 3, ["meta"] = { ["fields"] = {}, ["inventory"] = {} }, ["param2"] = 0, ["y"] = 1, ["param1"] = 12, ["z"] = 2, ["name"] = "lottother:dirt" },
{["x"] = 3, ["meta"] = { ["fields"] = {}, ["inventory"] = {} }, ["param2"] = 0, ["y"] = 1, ["param1"] = 11, ["z"] = 3, ["name"] = "lottother:dirt" },
{["x"] = 3, ["meta"] = { ["fields"] = {}, ["inventory"] = {} }, ["param2"] = 0, ["y"] = 1, ["param1"] = 11, ["z"] = 4, ["name"] = "lottother:dirt" },
{["x"] = 3, ["meta"] = { ["fields"] = {}, ["inventory"] = {} }, ["param2"] = 0, ["y"] = 1, ["param1"] = 11, ["z"] = 5, ["name"] = "lottother:dirt" },
{["x"] = 3, ["meta"] = { ["fields"] = {}, ["inventory"] = {} }, ["param2"] = 0, ["y"] = 1, ["param1"] = 11, ["z"] = 6, ["name"] = "lottother:dirt" },
{["x"] = 3, ["meta"] = { ["fields"] = {}, ["inventory"] = {} }, ["param2"] = 0, ["y"] = 1, ["param1"] = 12, ["z"] = 7, ["name"] = "lottother:dirt" },
{["x"] = 3, ["meta"] = { ["fields"] = {}, ["inventory"] = {} }, ["param2"] = 0, ["y"] = 1, ["param1"] = 13, ["z"] = 8, ["name"] = "lottother:dirt" },
{["x"] = 3, ["meta"] = { ["fields"] = {}, ["inventory"] = {} }, ["param2"] = 0, ["y"] = 1, ["param1"] = 13, ["z"] = 9, ["name"] = "lottother:dirt" },
{["x"] = 3, ["meta"] = { ["fields"] = {}, ["inventory"] = {} }, ["param2"] = 0, ["y"] = 1, ["param1"] = 13, ["z"] = 10, ["name"] = "lottother:dirt" },
{["x"] = 3, ["meta"] = { ["fields"] = {}, ["inventory"] = {} }, ["param2"] = 0, ["y"] = 1, ["param1"] = 12, ["z"] = 11, ["name"] = "lottother:dirt" },
{["x"] = 3, ["meta"] = { ["fields"] = {}, ["inventory"] = {} }, ["param2"] = 0, ["y"] = 1, ["param1"] = 11, ["z"] = 12, ["name"] = "lottother:dirt" },
{["x"] = 3, ["meta"] = { ["fields"] = {}, ["inventory"] = {} }, ["param2"] = 0, ["y"] = 1, ["param1"] = 11, ["z"] = 13, ["name"] = "lottother:dirt" },
{["x"] = 3, ["meta"] = { ["fields"] = {}, ["inventory"] = {} }, ["param2"] = 0, ["y"] = 1, ["param1"] = 11, ["z"] = 14, ["name"] = "lottother:dirt" },
{["x"] = 3, ["meta"] = { ["fields"] = {}, ["inventory"] = {} }, ["param2"] = 0, ["y"] = 1, ["param1"] = 11, ["z"] = 15, ["name"] = "lottother:dirt" },
{["x"] = 3, ["meta"] = { ["fields"] = {}, ["inventory"] = {} }, ["param2"] = 0, ["y"] = 1, ["param1"] = 0, ["z"] = 16, ["name"] = "lottother:dirt" },
{["x"] = 3, ["meta"] = { ["fields"] = {}, ["inventory"] = {} }, ["param2"] = 0, ["y"] = 1, ["param1"] = 0, ["z"] = 17, ["name"] = "lottother:dirt" },
{["x"] = 3, ["meta"] = { ["fields"] = {}, ["inventory"] = {} }, ["param2"] = 0, ["y"] = 1, ["param1"] = 0, ["z"] = 18, ["name"] = "lord_ground:dirt_gondor" },
{["x"] = 3, ["meta"] = { ["fields"] = {}, ["inventory"] = {} }, ["param2"] = 0, ["y"] = 2, ["param1"] = 0, ["z"] = 1, ["name"] = "lord_ground:dirt_gondor" },
{["x"] = 3, ["meta"] = { ["fields"] = {}, ["inventory"] = {} }, ["param2"] = 0, ["y"] = 2, ["param1"] = 0, ["z"] = 2, ["name"] = "lottother:dirt" },
{["x"] = 3, ["meta"] = { ["fields"] = {}, ["inventory"] = {} }, ["param2"] = 0, ["y"] = 2, ["param1"] = 0, ["z"] = 3, ["name"] = "lottother:dirt" },
{["x"] = 3, ["meta"] = { ["fields"] = {}, ["inventory"] = {} }, ["param2"] = 0, ["y"] = 2, ["param1"] = 0, ["z"] = 4, ["name"] = "lottother:dirt" },
{["x"] = 3, ["meta"] = { ["fields"] = {}, ["inventory"] = {} }, ["param2"] = 0, ["y"] = 2, ["param1"] = 0, ["z"] = 5, ["name"] = "lottother:dirt" },
{["x"] = 3, ["meta"] = { ["fields"] = {}, ["inventory"] = {} }, ["param2"] = 0, ["y"] = 2, ["param1"] = 0, ["z"] = 6, ["name"] = "lottother:dirt" },
{["x"] = 3, ["meta"] = { ["fields"] = {}, ["inventory"] = {} }, ["param2"] = 0, ["y"] = 2, ["param1"] = 0, ["z"] = 7, ["name"] = "lord_ground:dirt_gondor" },
{["x"] = 3, ["meta"] = { ["fields"] = {}, ["inventory"] = {} }, ["param2"] = 0, ["y"] = 2, ["param1"] = 0, ["z"] = 8, ["name"] = "lord_ground:dirt_gondor" },
{["x"] = 3, ["meta"] = { ["fields"] = {}, ["inventory"] = {} }, ["param2"] = 0, ["y"] = 2, ["param1"] = 0, ["z"] = 9, ["name"] = "lord_ground:dirt_gondor" },
{["x"] = 3, ["meta"] = { ["fields"] = {}, ["inventory"] = {} }, ["param2"] = 0, ["y"] = 2, ["param1"] = 0, ["z"] = 10, ["name"] = "lord_ground:dirt_gondor" },
{["x"] = 3, ["meta"] = { ["fields"] = {}, ["inventory"] = {} }, ["param2"] = 0, ["y"] = 2, ["param1"] = 0, ["z"] = 11, ["name"] = "lord_ground:dirt_gondor" },
{["x"] = 3, ["meta"] = { ["fields"] = {}, ["inventory"] = {} }, ["param2"] = 0, ["y"] = 2, ["param1"] = 0, ["z"] = 12, ["name"] = "lottother:dirt" },
{["x"] = 3, ["meta"] = { ["fields"] = {}, ["inventory"] = {} }, ["param2"] = 0, ["y"] = 2, ["param1"] = 0, ["z"] = 13, ["name"] = "lottother:dirt" },
{["x"] = 3, ["meta"] = { ["fields"] = {}, ["inventory"] = {} }, ["param2"] = 0, ["y"] = 2, ["param1"] = 0, ["z"] = 14, ["name"] = "lottother:dirt" },
{["x"] = 3, ["meta"] = { ["fields"] = {}, ["inventory"] = {} }, ["param2"] = 0, ["y"] = 2, ["param1"] = 0, ["z"] = 15, ["name"] = "lottother:dirt" },
{["x"] = 3, ["meta"] = { ["fields"] = {}, ["inventory"] = {} }, ["param2"] = 0, ["y"] = 2, ["param1"] = 0, ["z"] = 16, ["name"] = "lottother:dirt" },
{["x"] = 3, ["meta"] = { ["fields"] = {}, ["inventory"] = {} }, ["param2"] = 0, ["y"] = 2, ["param1"] = 0, ["z"] = 17, ["name"] = "lord_ground:dirt_gondor" },
{["x"] = 3, ["meta"] = { ["fields"] = {}, ["inventory"] = {} }, ["param2"] = 0, ["y"] = 3, ["param1"] = 0, ["z"] = 2, ["name"] = "lottblocks:marble_brick" },
{["x"] = 3, ["meta"] = { ["fields"] = {}, ["inventory"] = {} }, ["param2"] = 0, ["y"] = 3, ["param1"] = 0, ["z"] = 3, ["name"] = "lottblocks:marble_brick" },
{["x"] = 3, ["meta"] = { ["fields"] = {}, ["inventory"] = {} }, ["param2"] = 0, ["y"] = 3, ["param1"] = 0, ["z"] = 4, ["name"] = "lottblocks:marble_brick" },
{["x"] = 3, ["meta"] = { ["fields"] = {}, ["inventory"] = {} }, ["param2"] = 0, ["y"] = 3, ["param1"] = 0, ["z"] = 5, ["name"] = "lottblocks:marble_brick" },
{["x"] = 3, ["meta"] = { ["fields"] = {}, ["inventory"] = {} }, ["param2"] = 0, ["y"] = 3, ["param1"] = 0, ["z"] = 6, ["name"] = "lottblocks:marble_brick" },
{["x"] = 3, ["meta"] = { ["fields"] = {}, ["inventory"] = {} }, ["param2"] = 0, ["y"] = 3, ["param1"] = 0, ["z"] = 12, ["name"] = "lottblocks:marble_brick" },
{["x"] = 3, ["meta"] = { ["fields"] = {}, ["inventory"] = {} }, ["param2"] = 0, ["y"] = 3, ["param1"] = 0, ["z"] = 13, ["name"] = "lottblocks:marble_brick" },
{["x"] = 3, ["meta"] = { ["fields"] = {}, ["inventory"] = {} }, ["param2"] = 0, ["y"] = 3, ["param1"] = 0, ["z"] = 14, ["name"] = "lottblocks:marble_brick" },
{["x"] = 3, ["meta"] = { ["fields"] = {}, ["inventory"] = {} }, ["param2"] = 0, ["y"] = 3, ["param1"] = 0, ["z"] = 15, ["name"] = "lottblocks:marble_brick" },
{["x"] = 3, ["meta"] = { ["fields"] = {}, ["inventory"] = {} }, ["param2"] = 0, ["y"] = 3, ["param1"] = 0, ["z"] = 16, ["name"] = "lottblocks:marble_brick" },
{["x"] = 3, ["meta"] = { ["fields"] = {}, ["inventory"] = {} }, ["param2"] = 0, ["y"] = 4, ["param1"] = 0, ["z"] = 2, ["name"] = "lottblocks:marble_brick" },
{["x"] = 3, ["meta"] = { ["fields"] = {}, ["inventory"] = {} }, ["param2"] = 0, ["y"] = 4, ["param1"] = 0, ["z"] = 3, ["name"] = "lottblocks:marble_brick" },
{["x"] = 3, ["meta"] = { ["fields"] = {}, ["inventory"] = {} }, ["param2"] = 0, ["y"] = 4, ["param1"] = 0, ["z"] = 4, ["name"] = "lottblocks:marble_brick" },
{["x"] = 3, ["meta"] = { ["fields"] = {}, ["inventory"] = {} }, ["param2"] = 0, ["y"] = 4, ["param1"] = 0, ["z"] = 5, ["name"] = "lottblocks:marble_brick" },
{["x"] = 3, ["meta"] = { ["fields"] = {}, ["inventory"] = {} }, ["param2"] = 0, ["y"] = 4, ["param1"] = 0, ["z"] = 6, ["name"] = "lottblocks:marble_brick" },
{["x"] = 3, ["meta"] = { ["fields"] = {}, ["inventory"] = {} }, ["param2"] = 0, ["y"] = 4, ["param1"] = 0, ["z"] = 12, ["name"] = "lottblocks:marble_brick" },
{["x"] = 3, ["meta"] = { ["fields"] = {}, ["inventory"] = {} }, ["param2"] = 0, ["y"] = 4, ["param1"] = 0, ["z"] = 13, ["name"] = "lottblocks:marble_brick" },
{["x"] = 3, ["meta"] = { ["fields"] = {}, ["inventory"] = {} }, ["param2"] = 0, ["y"] = 4, ["param1"] = 0, ["z"] = 14, ["name"] = "lottblocks:marble_brick" },
{["x"] = 3, ["meta"] = { ["fields"] = {}, ["inventory"] = {} }, ["param2"] = 0, ["y"] = 4, ["param1"] = 0, ["z"] = 15, ["name"] = "lottblocks:marble_brick" },
{["x"] = 3, ["meta"] = { ["fields"] = {}, ["inventory"] = {} }, ["param2"] = 0, ["y"] = 4, ["param1"] = 0, ["z"] = 16, ["name"] = "lottblocks:marble_brick" },
{["x"] = 3, ["meta"] = { ["fields"] = {}, ["inventory"] = {} }, ["param2"] = 0, ["y"] = 5, ["param1"] = 0, ["z"] = 2, ["name"] = "lottblocks:marble_brick" },
{["x"] = 3, ["meta"] = { ["fields"] = {}, ["inventory"] = {} }, ["param2"] = 0, ["y"] = 5, ["param1"] = 0, ["z"] = 3, ["name"] = "lottblocks:marble_brick" },
{["x"] = 3, ["meta"] = { ["fields"] = {}, ["inventory"] = {} }, ["param2"] = 2, ["y"] = 5, ["param1"] = 187, ["z"] = 4, ["name"] = "stairs:stair_marble_brick" },
{["x"] = 3, ["meta"] = { ["fields"] = {}, ["inventory"] = {} }, ["param2"] = 0, ["y"] = 5, ["param1"] = 170, ["z"] = 5, ["name"] = "lottother:air" },
{["x"] = 3, ["meta"] = { ["fields"] = {}, ["inventory"] = {} }, ["param2"] = 0, ["y"] = 5, ["param1"] = 0, ["z"] = 6, ["name"] = "lottblocks:marble_brick" },
{["x"] = 3, ["meta"] = { ["fields"] = {}, ["inventory"] = {} }, ["param2"] = 0, ["y"] = 5, ["param1"] = 0, ["z"] = 12, ["name"] = "lottblocks:marble_brick" },
{["x"] = 3, ["meta"] = { ["fields"] = {}, ["inventory"] = {} }, ["param2"] = 0, ["y"] = 5, ["param1"] = 153, ["z"] = 13, ["name"] = "lottother:air" },
{["x"] = 3, ["meta"] = { ["fields"] = {}, ["inventory"] = {} }, ["param2"] = 0, ["y"] = 5, ["param1"] = 170, ["z"] = 14, ["name"] = "stairs:stair_marble_brick" },
{["x"] = 3, ["meta"] = { ["fields"] = {}, ["inventory"] = {} }, ["param2"] = 0, ["y"] = 5, ["param1"] = 0, ["z"] = 15, ["name"] = "lottblocks:marble_brick" },
{["x"] = 3, ["meta"] = { ["fields"] = {}, ["inventory"] = {} }, ["param2"] = 0, ["y"] = 5, ["param1"] = 0, ["z"] = 16, ["name"] = "lottblocks:marble_brick" },
{["x"] = 3, ["meta"] = { ["fields"] = {}, ["inventory"] = {} }, ["param2"] = 0, ["y"] = 6, ["param1"] = 0, ["z"] = 2, ["name"] = "lottblocks:marble_brick" },
{["x"] = 3, ["meta"] = { ["fields"] = {}, ["inventory"] = {} }, ["param2"] = 0, ["y"] = 6, ["param1"] = 187, ["z"] = 3, ["name"] = "lottother:air" },
{["x"] = 3, ["meta"] = { ["fields"] = {}, ["inventory"] = {} }, ["param2"] = 0, ["y"] = 6, ["param1"] = 204, ["z"] = 4, ["name"] = "lottother:air" },
{["x"] = 3, ["meta"] = { ["fields"] = {}, ["inventory"] = {} }, ["param2"] = 0, ["y"] = 6, ["param1"] = 187, ["z"] = 5, ["name"] = "lottother:air" },
{["x"] = 3, ["meta"] = { ["fields"] = {}, ["inventory"] = {} }, ["param2"] = 0, ["y"] = 6, ["param1"] = 0, ["z"] = 6, ["name"] = "lottblocks:marble_brick" },
{["x"] = 3, ["meta"] = { ["fields"] = {}, ["inventory"] = {} }, ["param2"] = 0, ["y"] = 6, ["param1"] = 0, ["z"] = 12, ["name"] = "lottblocks:marble_brick" },
{["x"] = 3, ["meta"] = { ["fields"] = {}, ["inventory"] = {} }, ["param2"] = 0, ["y"] = 6, ["param1"] = 170, ["z"] = 13, ["name"] = "lottother:air" },
{["x"] = 3, ["meta"] = { ["fields"] = {}, ["inventory"] = {} }, ["param2"] = 0, ["y"] = 6, ["param1"] = 187, ["z"] = 14, ["name"] = "lottother:air" },
{["x"] = 3, ["meta"] = { ["fields"] = {}, ["inventory"] = {} }, ["param2"] = 0, ["y"] = 6, ["param1"] = 204, ["z"] = 15, ["name"] = "lottother:air" },
{["x"] = 3, ["meta"] = { ["fields"] = {}, ["inventory"] = {} }, ["param2"] = 0, ["y"] = 6, ["param1"] = 0, ["z"] = 16, ["name"] = "lottblocks:marble_brick" },
{["x"] = 3, ["meta"] = { ["fields"] = {}, ["inventory"] = {} }, ["param2"] = 0, ["y"] = 7, ["param1"] = 0, ["z"] = 2, ["name"] = "lottblocks:marble_brick" },
{["x"] = 3, ["meta"] = { ["fields"] = {}, ["inventory"] = {} }, ["param2"] = 0, ["y"] = 7, ["param1"] = 204, ["z"] = 3, ["name"] = "lottother:air" },
{["x"] = 3, ["meta"] = { ["fields"] = {}, ["inventory"] = {} }, ["param2"] = 3, ["y"] = 7, ["param1"] = 0, ["z"] = 4, ["name"] = "default:torch" },
{["x"] = 3, ["meta"] = { ["fields"] = {}, ["inventory"] = {} }, ["param2"] = 0, ["y"] = 7, ["param1"] = 204, ["z"] = 5, ["name"] = "lottother:air" },
{["x"] = 3, ["meta"] = { ["fields"] = {}, ["inventory"] = {} }, ["param2"] = 0, ["y"] = 7, ["param1"] = 0, ["z"] = 6, ["name"] = "lottblocks:marble_brick" },
{["x"] = 3, ["meta"] = { ["fields"] = {}, ["inventory"] = {} }, ["param2"] = 0, ["y"] = 7, ["param1"] = 0, ["z"] = 12, ["name"] = "lottblocks:marble_brick" },
{["x"] = 3, ["meta"] = { ["fields"] = {}, ["inventory"] = {} }, ["param2"] = 0, ["y"] = 7, ["param1"] = 187, ["z"] = 13, ["name"] = "lottother:air" },
{["x"] = 3, ["meta"] = { ["fields"] = {}, ["inventory"] = {} }, ["param2"] = 0, ["y"] = 7, ["param1"] = 204, ["z"] = 14, ["name"] = "lottother:air" },
{["x"] = 3, ["meta"] = { ["fields"] = {}, ["inventory"] = {} }, ["param2"] = 4, ["y"] = 7, ["param1"] = 0, ["z"] = 15, ["name"] = "default:torch" },
{["x"] = 3, ["meta"] = { ["fields"] = {}, ["inventory"] = {} }, ["param2"] = 0, ["y"] = 7, ["param1"] = 0, ["z"] = 16, ["name"] = "lottblocks:marble_brick" },
{["x"] = 3, ["meta"] = { ["fields"] = {}, ["inventory"] = {} }, ["param2"] = 0, ["y"] = 8, ["param1"] = 0, ["z"] = 2, ["name"] = "lottblocks:marble_brick" },
{["x"] = 3, ["meta"] = { ["fields"] = {}, ["inventory"] = {} }, ["param2"] = 0, ["y"] = 8, ["param1"] = 187, ["z"] = 3, ["name"] = "lottother:air" },
{["x"] = 3, ["meta"] = { ["fields"] = {}, ["inventory"] = {} }, ["param2"] = 0, ["y"] = 8, ["param1"] = 0, ["z"] = 4, ["name"] = "lottblocks:marble_brick" },
{["x"] = 3, ["meta"] = { ["fields"] = {}, ["inventory"] = {} }, ["param2"] = 3, ["y"] = 8, ["param1"] = 187, ["z"] = 5, ["name"] = "stairs:stair_marble_brick" },
{["x"] = 3, ["meta"] = { ["fields"] = {}, ["inventory"] = {} }, ["param2"] = 0, ["y"] = 8, ["param1"] = 0, ["z"] = 6, ["name"] = "lottblocks:marble_brick" },
{["x"] = 3, ["meta"] = { ["fields"] = {}, ["inventory"] = {} }, ["param2"] = 0, ["y"] = 8, ["param1"] = 0, ["z"] = 12, ["name"] = "lottblocks:marble_brick" },
{["x"] = 3, ["meta"] = { ["fields"] = {}, ["inventory"] = {} }, ["param2"] = 3, ["y"] = 8, ["param1"] = 187, ["z"] = 13, ["name"] = "stairs:stair_marble_brick" },
{["x"] = 3, ["meta"] = { ["fields"] = {}, ["inventory"] = {} }, ["param2"] = 0, ["y"] = 8, ["param1"] = 0, ["z"] = 14, ["name"] = "lottblocks:marble_brick" },
{["x"] = 3, ["meta"] = { ["fields"] = {}, ["inventory"] = {} }, ["param2"] = 0, ["y"] = 8, ["param1"] = 204, ["z"] = 15, ["name"] = "lottother:air" },
{["x"] = 3, ["meta"] = { ["fields"] = {}, ["inventory"] = {} }, ["param2"] = 0, ["y"] = 8, ["param1"] = 0, ["z"] = 16, ["name"] = "lottblocks:marble_brick" },
{["x"] = 3, ["meta"] = { ["fields"] = {}, ["inventory"] = {} }, ["param2"] = 0, ["y"] = 9, ["param1"] = 0, ["z"] = 2, ["name"] = "lottblocks:marble_brick" },
{["x"] = 3, ["meta"] = { ["fields"] = {}, ["inventory"] = {} }, ["param2"] = 0, ["y"] = 9, ["param1"] = 0, ["z"] = 3, ["name"] = "lottblocks:marble_brick" },
{["x"] = 3, ["meta"] = { ["fields"] = {}, ["inventory"] = {} }, ["param2"] = 2, ["y"] = 9, ["param1"] = 187, ["z"] = 4, ["name"] = "stairs:stair_marble_brick" },
{["x"] = 3, ["meta"] = { ["fields"] = {}, ["inventory"] = {} }, ["param2"] = 0, ["y"] = 9, ["param1"] = 170, ["z"] = 5, ["name"] = "lottother:air" },
{["x"] = 3, ["meta"] = { ["fields"] = {}, ["inventory"] = {} }, ["param2"] = 0, ["y"] = 9, ["param1"] = 0, ["z"] = 6, ["name"] = "lottblocks:marble_brick" },
{["x"] = 3, ["meta"] = { ["fields"] = {}, ["inventory"] = {} }, ["param2"] = 0, ["y"] = 9, ["param1"] = 0, ["z"] = 12, ["name"] = "lottblocks:marble_brick" },
{["x"] = 3, ["meta"] = { ["fields"] = {}, ["inventory"] = {} }, ["param2"] = 0, ["y"] = 9, ["param1"] = 204, ["z"] = 13, ["name"] = "lottother:air" },
{["x"] = 3, ["meta"] = { ["fields"] = {}, ["inventory"] = {} }, ["param2"] = 0, ["y"] = 9, ["param1"] = 187, ["z"] = 14, ["name"] = "stairs:stair_marble_brick" },
{["x"] = 3, ["meta"] = { ["fields"] = {}, ["inventory"] = {} }, ["param2"] = 0, ["y"] = 9, ["param1"] = 0, ["z"] = 15, ["name"] = "lottblocks:marble_brick" },
{["x"] = 3, ["meta"] = { ["fields"] = {}, ["inventory"] = {} }, ["param2"] = 0, ["y"] = 9, ["param1"] = 0, ["z"] = 16, ["name"] = "lottblocks:marble_brick" },
{["x"] = 3, ["meta"] = { ["fields"] = {}, ["inventory"] = {} }, ["param2"] = 0, ["y"] = 10, ["param1"] = 0, ["z"] = 2, ["name"] = "lottblocks:marble_brick" },
{["x"] = 3, ["meta"] = { ["fields"] = {}, ["inventory"] = {} }, ["param2"] = 0, ["y"] = 10, ["param1"] = 187, ["z"] = 3, ["name"] = "lottother:air" },
{["x"] = 3, ["meta"] = { ["fields"] = {}, ["inventory"] = {} }, ["param2"] = 0, ["y"] = 10, ["param1"] = 204, ["z"] = 4, ["name"] = "lottother:air" },
{["x"] = 3, ["meta"] = { ["fields"] = {}, ["inventory"] = {} }, ["param2"] = 0, ["y"] = 10, ["param1"] = 187, ["z"] = 5, ["name"] = "lottother:air" },
{["x"] = 3, ["meta"] = { ["fields"] = {}, ["inventory"] = {} }, ["param2"] = 0, ["y"] = 10, ["param1"] = 0, ["z"] = 6, ["name"] = "lottblocks:marble_brick" },
{["x"] = 3, ["meta"] = { ["fields"] = {}, ["inventory"] = {} }, ["param2"] = 0, ["y"] = 10, ["param1"] = 0, ["z"] = 12, ["name"] = "lottblocks:marble_brick" },
{["x"] = 3, ["meta"] = { ["fields"] = {}, ["inventory"] = {} }, ["param2"] = 3, ["y"] = 10, ["param1"] = 0, ["z"] = 13, ["name"] = "default:torch" },
{["x"] = 3, ["meta"] = { ["fields"] = {}, ["inventory"] = {} }, ["param2"] = 0, ["y"] = 10, ["param1"] = 204, ["z"] = 14, ["name"] = "lottother:air" },
{["x"] = 3, ["meta"] = { ["fields"] = {}, ["inventory"] = {} }, ["param2"] = 0, ["y"] = 10, ["param1"] = 187, ["z"] = 15, ["name"] = "lottother:air" },
{["x"] = 3, ["meta"] = { ["fields"] = {}, ["inventory"] = {} }, ["param2"] = 0, ["y"] = 10, ["param1"] = 0, ["z"] = 16, ["name"] = "lottblocks:marble_brick" },
{["x"] = 3, ["meta"] = { ["fields"] = {}, ["inventory"] = {} }, ["param2"] = 0, ["y"] = 11, ["param1"] = 0, ["z"] = 2, ["name"] = "lottblocks:marble_brick" },
{["x"] = 3, ["meta"] = { ["fields"] = {}, ["inventory"] = {} }, ["param2"] = 0, ["y"] = 11, ["param1"] = 204, ["z"] = 3, ["name"] = "lottother:air" },
{["x"] = 3, ["meta"] = { ["fields"] = {}, ["inventory"] = {} }, ["param2"] = 3, ["y"] = 11, ["param1"] = 0, ["z"] = 4, ["name"] = "default:torch" },
{["x"] = 3, ["meta"] = { ["fields"] = {}, ["inventory"] = {} }, ["param2"] = 0, ["y"] = 11, ["param1"] = 204, ["z"] = 5, ["name"] = "lottother:air" },
{["x"] = 3, ["meta"] = { ["fields"] = {}, ["inventory"] = {} }, ["param2"] = 0, ["y"] = 11, ["param1"] = 0, ["z"] = 6, ["name"] = "lottblocks:marble_brick" },
{["x"] = 3, ["meta"] = { ["fields"] = {}, ["inventory"] = {} }, ["param2"] = 0, ["y"] = 11, ["param1"] = 0, ["z"] = 12, ["name"] = "lottblocks:marble_brick" },
{["x"] = 3, ["meta"] = { ["fields"] = {}, ["inventory"] = {} }, ["param2"] = 0, ["y"] = 11, ["param1"] = 204, ["z"] = 13, ["name"] = "lottother:air" },
{["x"] = 3, ["meta"] = { ["fields"] = {}, ["inventory"] = {} }, ["param2"] = 0, ["y"] = 11, ["param1"] = 187, ["z"] = 14, ["name"] = "lottother:air" },
{["x"] = 3, ["meta"] = { ["fields"] = {}, ["inventory"] = {} }, ["param2"] = 0, ["y"] = 11, ["param1"] = 187, ["z"] = 15, ["name"] = "lottother:air" },
{["x"] = 3, ["meta"] = { ["fields"] = {}, ["inventory"] = {} }, ["param2"] = 0, ["y"] = 11, ["param1"] = 0, ["z"] = 16, ["name"] = "lottblocks:marble_brick" },
{["x"] = 3, ["meta"] = { ["fields"] = {}, ["inventory"] = {} }, ["param2"] = 0, ["y"] = 12, ["param1"] = 0, ["z"] = 2, ["name"] = "lottblocks:marble_brick" },
{["x"] = 3, ["meta"] = { ["fields"] = {}, ["inventory"] = {} }, ["param2"] = 0, ["y"] = 12, ["param1"] = 187, ["z"] = 3, ["name"] = "lottother:air" },
{["x"] = 3, ["meta"] = { ["fields"] = {}, ["inventory"] = {} }, ["param2"] = 0, ["y"] = 12, ["param1"] = 204, ["z"] = 4, ["name"] = "lottother:air" },
{["x"] = 3, ["meta"] = { ["fields"] = {}, ["inventory"] = {} }, ["param2"] = 0, ["y"] = 12, ["param1"] = 187, ["z"] = 5, ["name"] = "lottother:air" },
{["x"] = 3, ["meta"] = { ["fields"] = {}, ["inventory"] = {} }, ["param2"] = 0, ["y"] = 12, ["param1"] = 0, ["z"] = 6, ["name"] = "lottblocks:marble_brick" },
{["x"] = 3, ["meta"] = { ["fields"] = {}, ["inventory"] = {} }, ["param2"] = 0, ["y"] = 12, ["param1"] = 0, ["z"] = 12, ["name"] = "lottblocks:marble_brick" },
{["x"] = 3, ["meta"] = { ["fields"] = {}, ["inventory"] = {} }, ["param2"] = 0, ["y"] = 12, ["param1"] = 204, ["z"] = 13, ["name"] = "lottother:air" },
{["x"] = 3, ["meta"] = { ["fields"] = {}, ["inventory"] = {} }, ["param2"] = 0, ["y"] = 12, ["param1"] = 187, ["z"] = 14, ["name"] = "lottother:air" },
{["x"] = 3, ["meta"] = { ["fields"] = {}, ["inventory"] = {} }, ["param2"] = 0, ["y"] = 12, ["param1"] = 204, ["z"] = 15, ["name"] = "lottother:air" },
{["x"] = 3, ["meta"] = { ["fields"] = {}, ["inventory"] = {} }, ["param2"] = 0, ["y"] = 12, ["param1"] = 0, ["z"] = 16, ["name"] = "lottblocks:marble_brick" },
{["x"] = 3, ["meta"] = { ["fields"] = {}, ["inventory"] = {} }, ["param2"] = 0, ["y"] = 13, ["param1"] = 0, ["z"] = 2, ["name"] = "lottblocks:marble_brick" },
{["x"] = 3, ["meta"] = { ["fields"] = {}, ["inventory"] = {} }, ["param2"] = 0, ["y"] = 13, ["param1"] = 170, ["z"] = 3, ["name"] = "lottother:air" },
{["x"] = 3, ["meta"] = { ["fields"] = {}, ["inventory"] = {} }, ["param2"] = 0, ["y"] = 13, ["param1"] = 187, ["z"] = 4, ["name"] = "lottother:air" },
{["x"] = 3, ["meta"] = { ["fields"] = {}, ["inventory"] = {} }, ["param2"] = 0, ["y"] = 13, ["param1"] = 170, ["z"] = 5, ["name"] = "lottother:air" },
{["x"] = 3, ["meta"] = { ["fields"] = {}, ["inventory"] = {} }, ["param2"] = 0, ["y"] = 13, ["param1"] = 0, ["z"] = 6, ["name"] = "lottblocks:marble_brick" },
{["x"] = 3, ["meta"] = { ["fields"] = {}, ["inventory"] = {} }, ["param2"] = 0, ["y"] = 13, ["param1"] = 0, ["z"] = 12, ["name"] = "lottblocks:marble_brick" },
{["x"] = 3, ["meta"] = { ["fields"] = {}, ["inventory"] = {} }, ["param2"] = 3, ["y"] = 13, ["param1"] = 0, ["z"] = 13, ["name"] = "default:torch" },
{["x"] = 3, ["meta"] = { ["fields"] = {}, ["inventory"] = {} }, ["param2"] = 0, ["y"] = 13, ["param1"] = 204, ["z"] = 14, ["name"] = "lottother:air" },
{["x"] = 3, ["meta"] = { ["fields"] = {}, ["inventory"] = {} }, ["param2"] = 3, ["y"] = 13, ["param1"] = 0, ["z"] = 15, ["name"] = "default:torch" },
{["x"] = 3, ["meta"] = { ["fields"] = {}, ["inventory"] = {} }, ["param2"] = 0, ["y"] = 13, ["param1"] = 0, ["z"] = 16, ["name"] = "lottblocks:marble_brick" },
{["x"] = 3, ["meta"] = { ["fields"] = {}, ["inventory"] = {} }, ["param2"] = 0, ["y"] = 14, ["param1"] = 0, ["z"] = 2, ["name"] = "lottblocks:marble_brick" },
{["x"] = 3, ["meta"] = { ["fields"] = {}, ["inventory"] = {} }, ["param2"] = 0, ["y"] = 14, ["param1"] = 0, ["z"] = 3, ["name"] = "lottblocks:marble_brick" },
{["x"] = 3, ["meta"] = { ["fields"] = {}, ["inventory"] = {} }, ["param2"] = 0, ["y"] = 14, ["param1"] = 0, ["z"] = 4, ["name"] = "lottblocks:marble_brick" },
{["x"] = 3, ["meta"] = { ["fields"] = {}, ["inventory"] = {} }, ["param2"] = 0, ["y"] = 14, ["param1"] = 0, ["z"] = 5, ["name"] = "lottblocks:marble_brick" },
{["x"] = 3, ["meta"] = { ["fields"] = {}, ["inventory"] = {} }, ["param2"] = 0, ["y"] = 14, ["param1"] = 0, ["z"] = 6, ["name"] = "lottblocks:marble_brick" },
{["x"] = 3, ["meta"] = { ["fields"] = {}, ["inventory"] = {} }, ["param2"] = 0, ["y"] = 14, ["param1"] = 0, ["z"] = 12, ["name"] = "lottblocks:marble_brick" },
{["x"] = 3, ["meta"] = { ["fields"] = {}, ["inventory"] = {} }, ["param2"] = 0, ["y"] = 14, ["param1"] = 0, ["z"] = 13, ["name"] = "lottblocks:marble_brick" },
{["x"] = 3, ["meta"] = { ["fields"] = {}, ["inventory"] = {} }, ["param2"] = 0, ["y"] = 14, ["param1"] = 0, ["z"] = 14, ["name"] = "lottblocks:marble_brick" },
{["x"] = 3, ["meta"] = { ["fields"] = {}, ["inventory"] = {} }, ["param2"] = 0, ["y"] = 14, ["param1"] = 0, ["z"] = 15, ["name"] = "lottblocks:marble_brick" },
{["x"] = 3, ["meta"] = { ["fields"] = {}, ["inventory"] = {} }, ["param2"] = 0, ["y"] = 14, ["param1"] = 0, ["z"] = 16, ["name"] = "lottblocks:marble_brick" },
{["x"] = 3, ["meta"] = { ["fields"] = {}, ["inventory"] = {} }, ["param2"] = 0, ["y"] = 15, ["param1"] = 0, ["z"] = 2, ["name"] = "lottblocks:marble_brick" },
{["x"] = 3, ["meta"] = { ["fields"] = {}, ["inventory"] = {} }, ["param2"] = 0, ["y"] = 15, ["param1"] = 154, ["z"] = 3, ["name"] = "lottother:air" },
{["x"] = 3, ["meta"] = { ["fields"] = {}, ["inventory"] = {} }, ["param2"] = 0, ["y"] = 15, ["param1"] = 139, ["z"] = 4, ["name"] = "lottother:air" },
{["x"] = 3, ["meta"] = { ["fields"] = {}, ["inventory"] = {} }, ["param2"] = 0, ["y"] = 15, ["param1"] = 0, ["z"] = 5, ["name"] = "lottmapgen:gondor_chest_spawner" },
{["x"] = 3, ["meta"] = { ["fields"] = {}, ["inventory"] = {} }, ["param2"] = 0, ["y"] = 15, ["param1"] = 0, ["z"] = 6, ["name"] = "lottblocks:marble_brick" },
{["x"] = 3, ["meta"] = { ["fields"] = {}, ["inventory"] = {} }, ["param2"] = 0, ["y"] = 15, ["param1"] = 0, ["z"] = 12, ["name"] = "lottblocks:marble_brick" },
{["x"] = 3, ["meta"] = { ["fields"] = {}, ["inventory"] = {} }, ["param2"] = 0, ["y"] = 15, ["param1"] = 0, ["z"] = 13, ["name"] = "lottmapgen:gondor_chest_spawner" },
{["x"] = 3, ["meta"] = { ["fields"] = {}, ["inventory"] = {} }, ["param2"] = 0, ["y"] = 15, ["param1"] = 139, ["z"] = 14, ["name"] = "lottother:air" },
{["x"] = 3, ["meta"] = { ["fields"] = {}, ["inventory"] = {} }, ["param2"] = 0, ["y"] = 15, ["param1"] = 154, ["z"] = 15, ["name"] = "lottother:air" },
{["x"] = 3, ["meta"] = { ["fields"] = {}, ["inventory"] = {} }, ["param2"] = 0, ["y"] = 15, ["param1"] = 0, ["z"] = 16, ["name"] = "lottblocks:marble_brick" },
{["x"] = 3, ["meta"] = { ["fields"] = {}, ["inventory"] = {} }, ["param2"] = 0, ["y"] = 16, ["param1"] = 0, ["z"] = 2, ["name"] = "lottblocks:marble_brick" },
{["x"] = 3, ["meta"] = { ["fields"] = {}, ["inventory"] = {} }, ["param2"] = 0, ["y"] = 16, ["param1"] = 171, ["z"] = 3, ["name"] = "lottother:air" },
{["x"] = 3, ["meta"] = { ["fields"] = {}, ["inventory"] = {} }, ["param2"] = 0, ["y"] = 16, ["param1"] = 156, ["z"] = 4, ["name"] = "lottother:air" },
{["x"] = 3, ["meta"] = { ["fields"] = {}, ["inventory"] = {} }, ["param2"] = 0, ["y"] = 16, ["param1"] = 171, ["z"] = 5, ["name"] = "lottother:air" },
{["x"] = 3, ["meta"] = { ["fields"] = {}, ["inventory"] = {} }, ["param2"] = 0, ["y"] = 16, ["param1"] = 0, ["z"] = 6, ["name"] = "lottblocks:marble_brick" },
{["x"] = 3, ["meta"] = { ["fields"] = {}, ["inventory"] = {} }, ["param2"] = 0, ["y"] = 16, ["param1"] = 0, ["z"] = 12, ["name"] = "lottblocks:marble_brick" },
{["x"] = 3, ["meta"] = { ["fields"] = {}, ["inventory"] = {} }, ["param2"] = 0, ["y"] = 16, ["param1"] = 171, ["z"] = 13, ["name"] = "lottother:air" },
{["x"] = 3, ["meta"] = { ["fields"] = {}, ["inventory"] = {} }, ["param2"] = 0, ["y"] = 16, ["param1"] = 156, ["z"] = 14, ["name"] = "lottother:air" },
{["x"] = 3, ["meta"] = { ["fields"] = {}, ["inventory"] = {} }, ["param2"] = 0, ["y"] = 16, ["param1"] = 171, ["z"] = 15, ["name"] = "lottother:air" },
{["x"] = 3, ["meta"] = { ["fields"] = {}, ["inventory"] = {} }, ["param2"] = 0, ["y"] = 16, ["param1"] = 0, ["z"] = 16, ["name"] = "lottblocks:marble_brick" },
{["x"] = 3, ["meta"] = { ["fields"] = {}, ["inventory"] = {} }, ["param2"] = 0, ["y"] = 17, ["param1"] = 0, ["z"] = 2, ["name"] = "lottblocks:marble_brick" },
{["x"] = 3, ["meta"] = { ["fields"] = {}, ["inventory"] = {} }, ["param2"] = 0, ["y"] = 17, ["param1"] = 187, ["z"] = 3, ["name"] = "lottother:air" },
{["x"] = 3, ["meta"] = { ["fields"] = {}, ["inventory"] = {} }, ["param2"] = 0, ["y"] = 17, ["param1"] = 172, ["z"] = 4, ["name"] = "lottother:air" },
{["x"] = 3, ["meta"] = { ["fields"] = {}, ["inventory"] = {} }, ["param2"] = 0, ["y"] = 17, ["param1"] = 187, ["z"] = 5, ["name"] = "lottother:air" },
{["x"] = 3, ["meta"] = { ["fields"] = {}, ["inventory"] = {} }, ["param2"] = 0, ["y"] = 17, ["param1"] = 0, ["z"] = 6, ["name"] = "lottblocks:marble_brick" },
{["x"] = 3, ["meta"] = { ["fields"] = {}, ["inventory"] = {} }, ["param2"] = 0, ["y"] = 17, ["param1"] = 0, ["z"] = 12, ["name"] = "lottblocks:marble_brick" },
{["x"] = 3, ["meta"] = { ["fields"] = {}, ["inventory"] = {} }, ["param2"] = 0, ["y"] = 17, ["param1"] = 187, ["z"] = 13, ["name"] = "lottother:air" },
{["x"] = 3, ["meta"] = { ["fields"] = {}, ["inventory"] = {} }, ["param2"] = 0, ["y"] = 17, ["param1"] = 172, ["z"] = 14, ["name"] = "lottother:air" },
{["x"] = 3, ["meta"] = { ["fields"] = {}, ["inventory"] = {} }, ["param2"] = 0, ["y"] = 17, ["param1"] = 187, ["z"] = 15, ["name"] = "lottother:air" },
{["x"] = 3, ["meta"] = { ["fields"] = {}, ["inventory"] = {} }, ["param2"] = 0, ["y"] = 17, ["param1"] = 0, ["z"] = 16, ["name"] = "lottblocks:marble_brick" },
{["x"] = 3, ["meta"] = { ["fields"] = {}, ["inventory"] = {} }, ["param2"] = 0, ["y"] = 18, ["param1"] = 0, ["z"] = 2, ["name"] = "lottblocks:marble_brick" },
{["x"] = 3, ["meta"] = { ["fields"] = {}, ["inventory"] = {} }, ["param2"] = 0, ["y"] = 18, ["param1"] = 204, ["z"] = 3, ["name"] = "lottother:air" },
{["x"] = 3, ["meta"] = { ["fields"] = {}, ["inventory"] = {} }, ["param2"] = 0, ["y"] = 18, ["param1"] = 187, ["z"] = 4, ["name"] = "lottother:air" },
{["x"] = 3, ["meta"] = { ["fields"] = {}, ["inventory"] = {} }, ["param2"] = 0, ["y"] = 18, ["param1"] = 204, ["z"] = 5, ["name"] = "lottother:air" },
{["x"] = 3, ["meta"] = { ["fields"] = {}, ["inventory"] = {} }, ["param2"] = 0, ["y"] = 18, ["param1"] = 0, ["z"] = 6, ["name"] = "lottblocks:marble_brick" },
{["x"] = 3, ["meta"] = { ["fields"] = {}, ["inventory"] = {} }, ["param2"] = 0, ["y"] = 18, ["param1"] = 0, ["z"] = 12, ["name"] = "lottblocks:marble_brick" },
{["x"] = 3, ["meta"] = { ["fields"] = {}, ["inventory"] = {} }, ["param2"] = 0, ["y"] = 18, ["param1"] = 204, ["z"] = 13, ["name"] = "lottother:air" },
{["x"] = 3, ["meta"] = { ["fields"] = {}, ["inventory"] = {} }, ["param2"] = 0, ["y"] = 18, ["param1"] = 187, ["z"] = 14, ["name"] = "lottother:air" },
{["x"] = 3, ["meta"] = { ["fields"] = {}, ["inventory"] = {} }, ["param2"] = 0, ["y"] = 18, ["param1"] = 204, ["z"] = 15, ["name"] = "lottother:air" },
{["x"] = 3, ["meta"] = { ["fields"] = {}, ["inventory"] = {} }, ["param2"] = 0, ["y"] = 18, ["param1"] = 0, ["z"] = 16, ["name"] = "lottblocks:marble_brick" },
{["x"] = 3, ["meta"] = { ["fields"] = {}, ["inventory"] = {} }, ["param2"] = 0, ["y"] = 19, ["param1"] = 0, ["z"] = 2, ["name"] = "lottblocks:marble_brick" },
{["x"] = 3, ["meta"] = { ["fields"] = {}, ["inventory"] = {} }, ["param2"] = 3, ["y"] = 19, ["param1"] = 0, ["z"] = 3, ["name"] = "default:torch" },
{["x"] = 3, ["meta"] = { ["fields"] = {}, ["inventory"] = {} }, ["param2"] = 0, ["y"] = 19, ["param1"] = 204, ["z"] = 4, ["name"] = "lottother:air" },
{["x"] = 3, ["meta"] = { ["fields"] = {}, ["inventory"] = {} }, ["param2"] = 4, ["y"] = 19, ["param1"] = 0, ["z"] = 5, ["name"] = "default:torch" },
{["x"] = 3, ["meta"] = { ["fields"] = {}, ["inventory"] = {} }, ["param2"] = 0, ["y"] = 19, ["param1"] = 0, ["z"] = 6, ["name"] = "lottblocks:marble_brick" },
{["x"] = 3, ["meta"] = { ["fields"] = {}, ["inventory"] = {} }, ["param2"] = 0, ["y"] = 19, ["param1"] = 0, ["z"] = 12, ["name"] = "lottblocks:marble_brick" },
{["x"] = 3, ["meta"] = { ["fields"] = {}, ["inventory"] = {} }, ["param2"] = 3, ["y"] = 19, ["param1"] = 0, ["z"] = 13, ["name"] = "default:torch" },
{["x"] = 3, ["meta"] = { ["fields"] = {}, ["inventory"] = {} }, ["param2"] = 0, ["y"] = 19, ["param1"] = 204, ["z"] = 14, ["name"] = "lottother:air" },
{["x"] = 3, ["meta"] = { ["fields"] = {}, ["inventory"] = {} }, ["param2"] = 4, ["y"] = 19, ["param1"] = 0, ["z"] = 15, ["name"] = "default:torch" },
{["x"] = 3, ["meta"] = { ["fields"] = {}, ["inventory"] = {} }, ["param2"] = 0, ["y"] = 19, ["param1"] = 0, ["z"] = 16, ["name"] = "lottblocks:marble_brick" },
{["x"] = 3, ["meta"] = { ["fields"] = {}, ["inventory"] = {} }, ["param2"] = 0, ["y"] = 20, ["param1"] = 0, ["z"] = 3, ["name"] = "lottblocks:marble_brick" },
{["x"] = 3, ["meta"] = { ["fields"] = {}, ["inventory"] = {} }, ["param2"] = 0, ["y"] = 20, ["param1"] = 0, ["z"] = 4, ["name"] = "lottblocks:marble_brick" },
{["x"] = 3, ["meta"] = { ["fields"] = {}, ["inventory"] = {} }, ["param2"] = 0, ["y"] = 20, ["param1"] = 0, ["z"] = 5, ["name"] = "lottblocks:marble_brick" },
{["x"] = 3, ["meta"] = { ["fields"] = {}, ["inventory"] = {} }, ["param2"] = 0, ["y"] = 20, ["param1"] = 0, ["z"] = 13, ["name"] = "lottblocks:marble_brick" },
{["x"] = 3, ["meta"] = { ["fields"] = {}, ["inventory"] = {} }, ["param2"] = 0, ["y"] = 20, ["param1"] = 0, ["z"] = 14, ["name"] = "lottblocks:marble_brick" },
{["x"] = 3, ["meta"] = { ["fields"] = {}, ["inventory"] = {} }, ["param2"] = 0, ["y"] = 20, ["param1"] = 0, ["z"] = 15, ["name"] = "lottblocks:marble_brick" },
{["x"] = 3, ["meta"] = { ["fields"] = {}, ["inventory"] = {} }, ["param2"] = 0, ["y"] = 21, ["param1"] = 0, ["z"] = 4, ["name"] = "lottblocks:marble_brick" },
{["x"] = 3, ["meta"] = { ["fields"] = {}, ["inventory"] = {} }, ["param2"] = 0, ["y"] = 21, ["param1"] = 0, ["z"] = 14, ["name"] = "lottblocks:marble_brick" },
{["x"] = 4, ["meta"] = { ["fields"] = {}, ["inventory"] = {} }, ["param2"] = 0, ["y"] = 0, ["param1"] = 13, ["z"] = 0, ["name"] = "lottother:dirt" },
{["x"] = 4, ["meta"] = { ["fields"] = {}, ["inventory"] = {} }, ["param2"] = 0, ["y"] = 0, ["param1"] = 12, ["z"] = 1, ["name"] = "lottother:dirt" },
{["x"] = 4, ["meta"] = { ["fields"] = {}, ["inventory"] = {} }, ["param2"] = 0, ["y"] = 0, ["param1"] = 11, ["z"] = 2, ["name"] = "lottother:dirt" },
{["x"] = 4, ["meta"] = { ["fields"] = {}, ["inventory"] = {} }, ["param2"] = 0, ["y"] = 0, ["param1"] = 10, ["z"] = 3, ["name"] = "lottother:dirt" },
{["x"] = 4, ["meta"] = { ["fields"] = {}, ["inventory"] = {} }, ["param2"] = 0, ["y"] = 0, ["param1"] = 9, ["z"] = 4, ["name"] = "lottother:dirt" },
{["x"] = 4, ["meta"] = { ["fields"] = {}, ["inventory"] = {} }, ["param2"] = 0, ["y"] = 0, ["param1"] = 9, ["z"] = 5, ["name"] = "lottother:dirt" },
{["x"] = 4, ["meta"] = { ["fields"] = {}, ["inventory"] = {} }, ["param2"] = 0, ["y"] = 0, ["param1"] = 9, ["z"] = 6, ["name"] = "lottother:dirt" },
{["x"] = 4, ["meta"] = { ["fields"] = {}, ["inventory"] = {} }, ["param2"] = 0, ["y"] = 0, ["param1"] = 9, ["z"] = 7, ["name"] = "lottother:dirt" },
{["x"] = 4, ["meta"] = { ["fields"] = {}, ["inventory"] = {} }, ["param2"] = 0, ["y"] = 0, ["param1"] = 10, ["z"] = 8, ["name"] = "lottother:dirt" },
{["x"] = 4, ["meta"] = { ["fields"] = {}, ["inventory"] = {} }, ["param2"] = 0, ["y"] = 0, ["param1"] = 11, ["z"] = 9, ["name"] = "lottother:dirt" },
{["x"] = 4, ["meta"] = { ["fields"] = {}, ["inventory"] = {} }, ["param2"] = 0, ["y"] = 0, ["param1"] = 10, ["z"] = 10, ["name"] = "lottother:dirt" },
{["x"] = 4, ["meta"] = { ["fields"] = {}, ["inventory"] = {} }, ["param2"] = 0, ["y"] = 0, ["param1"] = 9, ["z"] = 11, ["name"] = "lottother:dirt" },
{["x"] = 4, ["meta"] = { ["fields"] = {}, ["inventory"] = {} }, ["param2"] = 0, ["y"] = 0, ["param1"] = 9, ["z"] = 12, ["name"] = "lottother:dirt" },
{["x"] = 4, ["meta"] = { ["fields"] = {}, ["inventory"] = {} }, ["param2"] = 0, ["y"] = 0, ["param1"] = 9, ["z"] = 13, ["name"] = "lottother:dirt" },
{["x"] = 4, ["meta"] = { ["fields"] = {}, ["inventory"] = {} }, ["param2"] = 0, ["y"] = 0, ["param1"] = 9, ["z"] = 14, ["name"] = "lottother:dirt" },
{["x"] = 4, ["meta"] = { ["fields"] = {}, ["inventory"] = {} }, ["param2"] = 0, ["y"] = 0, ["param1"] = 10, ["z"] = 15, ["name"] = "lottother:dirt" },
{["x"] = 4, ["meta"] = { ["fields"] = {}, ["inventory"] = {} }, ["param2"] = 0, ["y"] = 0, ["param1"] = 11, ["z"] = 16, ["name"] = "lottother:dirt" },
{["x"] = 4, ["meta"] = { ["fields"] = {}, ["inventory"] = {} }, ["param2"] = 0, ["y"] = 0, ["param1"] = 12, ["z"] = 17, ["name"] = "lottother:dirt" },
{["x"] = 4, ["meta"] = { ["fields"] = {}, ["inventory"] = {} }, ["param2"] = 0, ["y"] = 0, ["param1"] = 13, ["z"] = 18, ["name"] = "lottother:dirt" },
{["x"] = 4, ["meta"] = { ["fields"] = {}, ["inventory"] = {} }, ["param2"] = 0, ["y"] = 1, ["param1"] = 0, ["z"] = 0, ["name"] = "lord_ground:dirt_gondor" },
{["x"] = 4, ["meta"] = { ["fields"] = {}, ["inventory"] = {} }, ["param2"] = 0, ["y"] = 1, ["param1"] = 13, ["z"] = 1, ["name"] = "lottother:dirt" },
{["x"] = 4, ["meta"] = { ["fields"] = {}, ["inventory"] = {} }, ["param2"] = 0, ["y"] = 1, ["param1"] = 12, ["z"] = 2, ["name"] = "lottother:dirt" },
{["x"] = 4, ["meta"] = { ["fields"] = {}, ["inventory"] = {} }, ["param2"] = 0, ["y"] = 1, ["param1"] = 11, ["z"] = 3, ["name"] = "lottother:dirt" },
{["x"] = 4, ["meta"] = { ["fields"] = {}, ["inventory"] = {} }, ["param2"] = 0, ["y"] = 1, ["param1"] = 10, ["z"] = 4, ["name"] = "lottother:dirt" },
{["x"] = 4, ["meta"] = { ["fields"] = {}, ["inventory"] = {} }, ["param2"] = 0, ["y"] = 1, ["param1"] = 10, ["z"] = 5, ["name"] = "lottother:dirt" },
{["x"] = 4, ["meta"] = { ["fields"] = {}, ["inventory"] = {} }, ["param2"] = 0, ["y"] = 1, ["param1"] = 10, ["z"] = 6, ["name"] = "lottother:dirt" },
{["x"] = 4, ["meta"] = { ["fields"] = {}, ["inventory"] = {} }, ["param2"] = 0, ["y"] = 1, ["param1"] = 11, ["z"] = 7, ["name"] = "lottother:dirt" },
{["x"] = 4, ["meta"] = { ["fields"] = {}, ["inventory"] = {} }, ["param2"] = 0, ["y"] = 1, ["param1"] = 12, ["z"] = 8, ["name"] = "lottother:dirt" },
{["x"] = 4, ["meta"] = { ["fields"] = {}, ["inventory"] = {} }, ["param2"] = 0, ["y"] = 1, ["param1"] = 12, ["z"] = 9, ["name"] = "lottother:dirt" },
{["x"] = 4, ["meta"] = { ["fields"] = {}, ["inventory"] = {} }, ["param2"] = 0, ["y"] = 1, ["param1"] = 12, ["z"] = 10, ["name"] = "lottother:dirt" },
{["x"] = 4, ["meta"] = { ["fields"] = {}, ["inventory"] = {} }, ["param2"] = 0, ["y"] = 1, ["param1"] = 11, ["z"] = 11, ["name"] = "lottother:dirt" },
{["x"] = 4, ["meta"] = { ["fields"] = {}, ["inventory"] = {} }, ["param2"] = 0, ["y"] = 1, ["param1"] = 10, ["z"] = 12, ["name"] = "lottother:dirt" },
{["x"] = 4, ["meta"] = { ["fields"] = {}, ["inventory"] = {} }, ["param2"] = 0, ["y"] = 1, ["param1"] = 10, ["z"] = 13, ["name"] = "lottother:dirt" },
{["x"] = 4, ["meta"] = { ["fields"] = {}, ["inventory"] = {} }, ["param2"] = 0, ["y"] = 1, ["param1"] = 10, ["z"] = 14, ["name"] = "lottother:dirt" },
{["x"] = 4, ["meta"] = { ["fields"] = {}, ["inventory"] = {} }, ["param2"] = 0, ["y"] = 1, ["param1"] = 11, ["z"] = 15, ["name"] = "lottother:dirt" },
{["x"] = 4, ["meta"] = { ["fields"] = {}, ["inventory"] = {} }, ["param2"] = 0, ["y"] = 1, ["param1"] = 12, ["z"] = 16, ["name"] = "lottother:dirt" },
{["x"] = 4, ["meta"] = { ["fields"] = {}, ["inventory"] = {} }, ["param2"] = 0, ["y"] = 1, ["param1"] = 13, ["z"] = 17, ["name"] = "lottother:dirt" },
{["x"] = 4, ["meta"] = { ["fields"] = {}, ["inventory"] = {} }, ["param2"] = 0, ["y"] = 1, ["param1"] = 0, ["z"] = 18, ["name"] = "lord_ground:dirt_gondor" },
{["x"] = 4, ["meta"] = { ["fields"] = {}, ["inventory"] = {} }, ["param2"] = 0, ["y"] = 2, ["param1"] = 0, ["z"] = 1, ["name"] = "lord_ground:dirt_gondor" },
{["x"] = 4, ["meta"] = { ["fields"] = {}, ["inventory"] = {} }, ["param2"] = 0, ["y"] = 2, ["param1"] = 0, ["z"] = 2, ["name"] = "lottother:dirt" },
{["x"] = 4, ["meta"] = { ["fields"] = {}, ["inventory"] = {} }, ["param2"] = 0, ["y"] = 2, ["param1"] = 0, ["z"] = 3, ["name"] = "lottother:dirt" },
{["x"] = 4, ["meta"] = { ["fields"] = {}, ["inventory"] = {} }, ["param2"] = 0, ["y"] = 2, ["param1"] = 0, ["z"] = 4, ["name"] = "lottother:dirt" },
{["x"] = 4, ["meta"] = { ["fields"] = {}, ["inventory"] = {} }, ["param2"] = 0, ["y"] = 2, ["param1"] = 0, ["z"] = 5, ["name"] = "lottother:dirt" },
{["x"] = 4, ["meta"] = { ["fields"] = {}, ["inventory"] = {} }, ["param2"] = 0, ["y"] = 2, ["param1"] = 0, ["z"] = 6, ["name"] = "lottother:dirt" },
{["x"] = 4, ["meta"] = { ["fields"] = {}, ["inventory"] = {} }, ["param2"] = 0, ["y"] = 2, ["param1"] = 0, ["z"] = 7, ["name"] = "lottother:dirt" },
{["x"] = 4, ["meta"] = { ["fields"] = {}, ["inventory"] = {} }, ["param2"] = 0, ["y"] = 2, ["param1"] = 0, ["z"] = 8, ["name"] = "lottother:dirt" },
{["x"] = 4, ["meta"] = { ["fields"] = {}, ["inventory"] = {} }, ["param2"] = 0, ["y"] = 2, ["param1"] = 0, ["z"] = 9, ["name"] = "lottother:dirt" },
{["x"] = 4, ["meta"] = { ["fields"] = {}, ["inventory"] = {} }, ["param2"] = 0, ["y"] = 2, ["param1"] = 0, ["z"] = 10, ["name"] = "lottother:dirt" },
{["x"] = 4, ["meta"] = { ["fields"] = {}, ["inventory"] = {} }, ["param2"] = 0, ["y"] = 2, ["param1"] = 0, ["z"] = 11, ["name"] = "lottother:dirt" },
{["x"] = 4, ["meta"] = { ["fields"] = {}, ["inventory"] = {} }, ["param2"] = 0, ["y"] = 2, ["param1"] = 0, ["z"] = 12, ["name"] = "lottother:dirt" },
{["x"] = 4, ["meta"] = { ["fields"] = {}, ["inventory"] = {} }, ["param2"] = 0, ["y"] = 2, ["param1"] = 0, ["z"] = 13, ["name"] = "lottother:dirt" },
{["x"] = 4, ["meta"] = { ["fields"] = {}, ["inventory"] = {} }, ["param2"] = 0, ["y"] = 2, ["param1"] = 0, ["z"] = 14, ["name"] = "lottother:dirt" },
{["x"] = 4, ["meta"] = { ["fields"] = {}, ["inventory"] = {} }, ["param2"] = 0, ["y"] = 2, ["param1"] = 0, ["z"] = 15, ["name"] = "lottother:dirt" },
{["x"] = 4, ["meta"] = { ["fields"] = {}, ["inventory"] = {} }, ["param2"] = 0, ["y"] = 2, ["param1"] = 0, ["z"] = 16, ["name"] = "lottother:dirt" },
{["x"] = 4, ["meta"] = { ["fields"] = {}, ["inventory"] = {} }, ["param2"] = 0, ["y"] = 2, ["param1"] = 0, ["z"] = 17, ["name"] = "lord_ground:dirt_gondor" },
{["x"] = 4, ["meta"] = { ["fields"] = {}, ["inventory"] = {} }, ["param2"] = 0, ["y"] = 3, ["param1"] = 0, ["z"] = 2, ["name"] = "lottblocks:marble_brick" },
{["x"] = 4, ["meta"] = { ["fields"] = {}, ["inventory"] = {} }, ["param2"] = 0, ["y"] = 3, ["param1"] = 0, ["z"] = 3, ["name"] = "lottblocks:marble_brick" },
{["x"] = 4, ["meta"] = { ["fields"] = {}, ["inventory"] = {} }, ["param2"] = 0, ["y"] = 3, ["param1"] = 0, ["z"] = 4, ["name"] = "lottblocks:marble_brick" },
{["x"] = 4, ["meta"] = { ["fields"] = {}, ["inventory"] = {} }, ["param2"] = 0, ["y"] = 3, ["param1"] = 0, ["z"] = 5, ["name"] = "lottblocks:marble_brick" },
{["x"] = 4, ["meta"] = { ["fields"] = {}, ["inventory"] = {} }, ["param2"] = 0, ["y"] = 3, ["param1"] = 0, ["z"] = 6, ["name"] = "lottblocks:marble_brick" },
{["x"] = 4, ["meta"] = { ["fields"] = {}, ["inventory"] = {} }, ["param2"] = 0, ["y"] = 3, ["param1"] = 0, ["z"] = 7, ["name"] = "lottblocks:marble_brick" },
{["x"] = 4, ["meta"] = { ["fields"] = {}, ["inventory"] = {} }, ["param2"] = 0, ["y"] = 3, ["param1"] = 0, ["z"] = 8, ["name"] = "lottblocks:marble_brick" },
{["x"] = 4, ["meta"] = { ["fields"] = {}, ["inventory"] = {} }, ["param2"] = 0, ["y"] = 3, ["param1"] = 0, ["z"] = 9, ["name"] = "lottblocks:marble_brick" },
{["x"] = 4, ["meta"] = { ["fields"] = {}, ["inventory"] = {} }, ["param2"] = 0, ["y"] = 3, ["param1"] = 0, ["z"] = 10, ["name"] = "lottblocks:marble_brick" },
{["x"] = 4, ["meta"] = { ["fields"] = {}, ["inventory"] = {} }, ["param2"] = 0, ["y"] = 3, ["param1"] = 0, ["z"] = 11, ["name"] = "lottblocks:marble_brick" },
{["x"] = 4, ["meta"] = { ["fields"] = {}, ["inventory"] = {} }, ["param2"] = 0, ["y"] = 3, ["param1"] = 0, ["z"] = 12, ["name"] = "lottblocks:marble_brick" },
{["x"] = 4, ["meta"] = { ["fields"] = {}, ["inventory"] = {} }, ["param2"] = 0, ["y"] = 3, ["param1"] = 0, ["z"] = 13, ["name"] = "lottblocks:marble_brick" },
{["x"] = 4, ["meta"] = { ["fields"] = {}, ["inventory"] = {} }, ["param2"] = 0, ["y"] = 3, ["param1"] = 0, ["z"] = 14, ["name"] = "lottblocks:marble_brick" },
{["x"] = 4, ["meta"] = { ["fields"] = {}, ["inventory"] = {} }, ["param2"] = 0, ["y"] = 3, ["param1"] = 0, ["z"] = 15, ["name"] = "lottblocks:marble_brick" },
{["x"] = 4, ["meta"] = { ["fields"] = {}, ["inventory"] = {} }, ["param2"] = 0, ["y"] = 3, ["param1"] = 0, ["z"] = 16, ["name"] = "lottblocks:marble_brick" },
{["x"] = 4, ["meta"] = { ["fields"] = {}, ["inventory"] = {} }, ["param2"] = 0, ["y"] = 4, ["param1"] = 0, ["z"] = 2, ["name"] = "lottblocks:marble_brick" },
{["x"] = 4, ["meta"] = { ["fields"] = {}, ["inventory"] = {} }, ["param2"] = 0, ["y"] = 4, ["param1"] = 0, ["z"] = 3, ["name"] = "lottblocks:marble_brick" },
{["x"] = 4, ["meta"] = { ["fields"] = {}, ["inventory"] = {} }, ["param2"] = 0, ["y"] = 4, ["param1"] = 153, ["z"] = 4, ["name"] = "lottother:air" },
{["x"] = 4, ["meta"] = { ["fields"] = {}, ["inventory"] = {} }, ["param2"] = 3, ["y"] = 4, ["param1"] = 137, ["z"] = 5, ["name"] = "stairs:stair_marble_brick" },
{["x"] = 4, ["meta"] = { ["fields"] = {}, ["inventory"] = {} }, ["param2"] = 0, ["y"] = 4, ["param1"] = 0, ["z"] = 6, ["name"] = "lottblocks:marble_brick" },
{["x"] = 4, ["meta"] = { ["fields"] = {}, ["inventory"] = {} }, ["param2"] = 0, ["y"] = 4, ["param1"] = 0, ["z"] = 7, ["name"] = "lottblocks:marble_brick" },
{["x"] = 4, ["meta"] = { ["fields"] = {}, ["inventory"] = {} }, ["param2"] = 0, ["y"] = 4, ["param1"] = 29, ["z"] = 8, ["name"] = "lottother:air" },
{["x"] = 4, ["meta"] = { ["fields"] = {}, ["inventory"] = {} }, ["param2"] = 0, ["y"] = 4, ["param1"] = 45, ["z"] = 9, ["name"] = "lottother:air" },
{["x"] = 4, ["meta"] = { ["fields"] = {}, ["inventory"] = {} }, ["param2"] = 0, ["y"] = 4, ["param1"] = 61, ["z"] = 10, ["name"] = "lottother:air" },
{["x"] = 4, ["meta"] = { ["fields"] = {}, ["inventory"] = {} }, ["param2"] = 0, ["y"] = 4, ["param1"] = 0, ["z"] = 11, ["name"] = "lottblocks:marble_brick" },
{["x"] = 4, ["meta"] = { ["fields"] = {}, ["inventory"] = {} }, ["param2"] = 0, ["y"] = 4, ["param1"] = 0, ["z"] = 12, ["name"] = "lottblocks:marble_brick" },
{["x"] = 4, ["meta"] = { ["fields"] = {}, ["inventory"] = {} }, ["param2"] = 3, ["y"] = 4, ["param1"] = 121, ["z"] = 13, ["name"] = "stairs:stair_marble_brick" },
{["x"] = 4, ["meta"] = { ["fields"] = {}, ["inventory"] = {} }, ["param2"] = 0, ["y"] = 4, ["param1"] = 136, ["z"] = 14, ["name"] = "lottother:air" },
{["x"] = 4, ["meta"] = { ["fields"] = {}, ["inventory"] = {} }, ["param2"] = 0, ["y"] = 4, ["param1"] = 0, ["z"] = 15, ["name"] = "lottblocks:marble_brick" },
{["x"] = 4, ["meta"] = { ["fields"] = {}, ["inventory"] = {} }, ["param2"] = 0, ["y"] = 4, ["param1"] = 0, ["z"] = 16, ["name"] = "lottblocks:marble_brick" },
{["x"] = 4, ["meta"] = { ["fields"] = {}, ["inventory"] = {} }, ["param2"] = 0, ["y"] = 5, ["param1"] = 0, ["z"] = 2, ["name"] = "lottblocks:marble_brick" },
{["x"] = 4, ["meta"] = { ["fields"] = {}, ["inventory"] = {} }, ["param2"] = 0, ["y"] = 5, ["param1"] = 0, ["z"] = 3, ["name"] = "lottblocks:marble_brick" },
{["x"] = 4, ["meta"] = { ["fields"] = {}, ["inventory"] = {} }, ["param2"] = 0, ["y"] = 5, ["param1"] = 170, ["z"] = 4, ["name"] = "lottother:air" },
{["x"] = 4, ["meta"] = { ["fields"] = {}, ["inventory"] = {} }, ["param2"] = 0, ["y"] = 5, ["param1"] = 153, ["z"] = 5, ["name"] = "lottother:air" },
{["x"] = 4, ["meta"] = { ["fields"] = {}, ["inventory"] = {} }, ["param2"] = 0, ["y"] = 5, ["param1"] = 0, ["z"] = 6, ["name"] = "lottblocks:marble_brick" },
{["x"] = 4, ["meta"] = { ["fields"] = {}, ["inventory"] = {} }, ["param2"] = 0, ["y"] = 5, ["param1"] = 0, ["z"] = 7, ["name"] = "lottblocks:marble_brick" },
{["x"] = 4, ["meta"] = { ["fields"] = {}, ["inventory"] = {} }, ["param2"] = 0, ["y"] = 5, ["param1"] = 45, ["z"] = 8, ["name"] = "lottother:air" },
{["x"] = 4, ["meta"] = { ["fields"] = {}, ["inventory"] = {} }, ["param2"] = 0, ["y"] = 5, ["param1"] = 61, ["z"] = 9, ["name"] = "lottother:air" },
{["x"] = 4, ["meta"] = { ["fields"] = {}, ["inventory"] = {} }, ["param2"] = 0, ["y"] = 5, ["param1"] = 77, ["z"] = 10, ["name"] = "lottother:air" },
{["x"] = 4, ["meta"] = { ["fields"] = {}, ["inventory"] = {} }, ["param2"] = 0, ["y"] = 5, ["param1"] = 0, ["z"] = 11, ["name"] = "lottblocks:marble_brick" },
{["x"] = 4, ["meta"] = { ["fields"] = {}, ["inventory"] = {} }, ["param2"] = 0, ["y"] = 5, ["param1"] = 0, ["z"] = 12, ["name"] = "lottblocks:marble_brick" },
{["x"] = 4, ["meta"] = { ["fields"] = {}, ["inventory"] = {} }, ["param2"] = 0, ["y"] = 5, ["param1"] = 137, ["z"] = 13, ["name"] = "lottother:air" },
{["x"] = 4, ["meta"] = { ["fields"] = {}, ["inventory"] = {} }, ["param2"] = 0, ["y"] = 5, ["param1"] = 153, ["z"] = 14, ["name"] = "lottother:air" },
{["x"] = 4, ["meta"] = { ["fields"] = {}, ["inventory"] = {} }, ["param2"] = 0, ["y"] = 5, ["param1"] = 0, ["z"] = 15, ["name"] = "lottblocks:marble_brick" },
{["x"] = 4, ["meta"] = { ["fields"] = {}, ["inventory"] = {} }, ["param2"] = 0, ["y"] = 5, ["param1"] = 0, ["z"] = 16, ["name"] = "lottblocks:marble_brick" },
{["x"] = 4, ["meta"] = { ["fields"] = {}, ["inventory"] = {} }, ["param2"] = 0, ["y"] = 6, ["param1"] = 0, ["z"] = 2, ["name"] = "lottblocks:marble_brick" },
{["x"] = 4, ["meta"] = { ["fields"] = {}, ["inventory"] = {} }, ["param2"] = 1, ["y"] = 6, ["param1"] = 170, ["z"] = 3, ["name"] = "stairs:stair_marble_brick" },
{["x"] = 4, ["meta"] = { ["fields"] = {}, ["inventory"] = {} }, ["param2"] = 0, ["y"] = 6, ["param1"] = 187, ["z"] = 4, ["name"] = "lottother:air" },
{["x"] = 4, ["meta"] = { ["fields"] = {}, ["inventory"] = {} }, ["param2"] = 0, ["y"] = 6, ["param1"] = 170, ["z"] = 5, ["name"] = "lottother:air" },
{["x"] = 4, ["meta"] = { ["fields"] = {}, ["inventory"] = {} }, ["param2"] = 0, ["y"] = 6, ["param1"] = 0, ["z"] = 6, ["name"] = "lottblocks:marble_brick" },
{["x"] = 4, ["meta"] = { ["fields"] = {}, ["inventory"] = {} }, ["param2"] = 0, ["y"] = 6, ["param1"] = 0, ["z"] = 7, ["name"] = "lottblocks:marble_brick" },
{["x"] = 4, ["meta"] = { ["fields"] = {}, ["inventory"] = {} }, ["param2"] = 0, ["y"] = 6, ["param1"] = 61, ["z"] = 8, ["name"] = "lottother:air" },
{["x"] = 4, ["meta"] = { ["fields"] = {}, ["inventory"] = {} }, ["param2"] = 0, ["y"] = 6, ["param1"] = 45, ["z"] = 9, ["name"] = "lottother:air" },
{["x"] = 4, ["meta"] = { ["fields"] = {}, ["inventory"] = {} }, ["param2"] = 0, ["y"] = 6, ["param1"] = 61, ["z"] = 10, ["name"] = "lottother:air" },
{["x"] = 4, ["meta"] = { ["fields"] = {}, ["inventory"] = {} }, ["param2"] = 0, ["y"] = 6, ["param1"] = 0, ["z"] = 11, ["name"] = "lottblocks:marble_brick" },
{["x"] = 4, ["meta"] = { ["fields"] = {}, ["inventory"] = {} }, ["param2"] = 0, ["y"] = 6, ["param1"] = 0, ["z"] = 12, ["name"] = "lottblocks:marble_brick" },
{["x"] = 4, ["meta"] = { ["fields"] = {}, ["inventory"] = {} }, ["param2"] = 0, ["y"] = 6, ["param1"] = 153, ["z"] = 13, ["name"] = "lottother:air" },
{["x"] = 4, ["meta"] = { ["fields"] = {}, ["inventory"] = {} }, ["param2"] = 0, ["y"] = 6, ["param1"] = 170, ["z"] = 14, ["name"] = "lottother:air" },
{["x"] = 4, ["meta"] = { ["fields"] = {}, ["inventory"] = {} }, ["param2"] = 1, ["y"] = 6, ["param1"] = 187, ["z"] = 15, ["name"] = "stairs:stair_marble_brick" },
{["x"] = 4, ["meta"] = { ["fields"] = {}, ["inventory"] = {} }, ["param2"] = 0, ["y"] = 6, ["param1"] = 0, ["z"] = 16, ["name"] = "lottblocks:marble_brick" },
{["x"] = 4, ["meta"] = { ["fields"] = {}, ["inventory"] = {} }, ["param2"] = 0, ["y"] = 7, ["param1"] = 0, ["z"] = 2, ["name"] = "lottblocks:marble_brick" },
{["x"] = 4, ["meta"] = { ["fields"] = {}, ["inventory"] = {} }, ["param2"] = 0, ["y"] = 7, ["param1"] = 187, ["z"] = 3, ["name"] = "lottother:air" },
{["x"] = 4, ["meta"] = { ["fields"] = {}, ["inventory"] = {} }, ["param2"] = 0, ["y"] = 7, ["param1"] = 204, ["z"] = 4, ["name"] = "lottother:air" },
{["x"] = 4, ["meta"] = { ["fields"] = {}, ["inventory"] = {} }, ["param2"] = 0, ["y"] = 7, ["param1"] = 0, ["z"] = 5, ["name"] = "lottblocks:marble_brick" },
