return {
{["x"] = 0, ["meta"] = { ["fields"] = {}, ["inventory"] = {} }, ["param2"] = 0, ["y"] = 0, ["param1"] = 13, ["z"] = 2, ["name"] = "lottother:dirt" },
{["x"] = 0, ["meta"] = { ["fields"] = {}, ["inventory"] = {} }, ["param2"] = 0, ["y"] = 0, ["param1"] = 13, ["z"] = 3, ["name"] = "lottother:dirt" },
{["x"] = 0, ["meta"] = { ["fields"] = {}, ["inventory"] = {} }, ["param2"] = 0, ["y"] = 0, ["param1"] = 13, ["z"] = 4, ["name"] = "lottother:dirt" },
{["x"] = 0, ["meta"] = { ["fields"] = {}, ["inventory"] = {} }, ["param2"] = 0, ["y"] = 0, ["param1"] = 13, ["z"] = 5, ["name"] = "lottother:dirt" },
{["x"] = 0, ["meta"] = { ["fields"] = {}, ["inventory"] = {} }, ["param2"] = 0, ["y"] = 0, ["param1"] = 13, ["z"] = 6, ["name"] = "lottother:dirt" },
{["x"] = 0, ["meta"] = { ["fields"] = {}, ["inventory"] = {} }, ["param2"] = 0, ["y"] = 0, ["param1"] = 13, ["z"] = 7, ["name"] = "lottother:dirt" },
{["x"] = 0, ["meta"] = { ["fields"] = {}, ["inventory"] = {} }, ["param2"] = 0, ["y"] = 0, ["param1"] = 13, ["z"] = 8, ["name"] = "lottother:dirt" },
{["x"] = 0, ["meta"] = { ["fields"] = {}, ["inventory"] = {} }, ["param2"] = 0, ["y"] = 0, ["param1"] = 13, ["z"] = 9, ["name"] = "lottother:dirt" },
{["x"] = 0, ["meta"] = { ["fields"] = {}, ["inventory"] = {} }, ["param2"] = 0, ["y"] = 0, ["param1"] = 13, ["z"] = 10, ["name"] = "lottother:dirt" },
{["x"] = 0, ["meta"] = { ["fields"] = {}, ["inventory"] = {} }, ["param2"] = 0, ["y"] = 0, ["param1"] = 13, ["z"] = 11, ["name"] = "lottother:dirt" },
{["x"] = 0, ["meta"] = { ["fields"] = {}, ["inventory"] = {} }, ["param2"] = 0, ["y"] = 0, ["param1"] = 13, ["z"] = 12, ["name"] = "lottother:dirt" },
{["x"] = 0, ["meta"] = { ["fields"] = {}, ["inventory"] = {} }, ["param2"] = 0, ["y"] = 0, ["param1"] = 13, ["z"] = 13, ["name"] = "lottother:dirt" },
{["x"] = 0, ["meta"] = { ["fields"] = {}, ["inventory"] = {} }, ["param2"] = 0, ["y"] = 0, ["param1"] = 13, ["z"] = 14, ["name"] = "lottother:dirt" },
{["x"] = 0, ["meta"] = { ["fields"] = {}, ["inventory"] = {} }, ["param2"] = 0, ["y"] = 0, ["param1"] = 13, ["z"] = 15, ["name"] = "lottother:dirt" },
{["x"] = 0, ["meta"] = { ["fields"] = {}, ["inventory"] = {} }, ["param2"] = 0, ["y"] = 0, ["param1"] = 13, ["z"] = 16, ["name"] = "lottother:dirt" },
{["x"] = 0, ["meta"] = { ["fields"] = {}, ["inventory"] = {} }, ["param2"] = 0, ["y"] = 0, ["param1"] = 13, ["z"] = 17, ["name"] = "lottother:dirt" },
{["x"] = 0, ["meta"] = { ["fields"] = {}, ["inventory"] = {} }, ["param2"] = 0, ["y"] = 0, ["param1"] = 13, ["z"] = 18, ["name"] = "lottother:dirt" },
{["x"] = 0, ["meta"] = { ["fields"] = {}, ["inventory"] = {} }, ["param2"] = 0, ["y"] = 0, ["param1"] = 13, ["z"] = 19, ["name"] = "lottother:dirt" },
{["x"] = 0, ["meta"] = { ["fields"] = {}, ["inventory"] = {} }, ["param2"] = 0, ["y"] = 0, ["param1"] = 13, ["z"] = 20, ["name"] = "lottother:dirt" },
{["x"] = 0, ["meta"] = { ["fields"] = {}, ["inventory"] = {} }, ["param2"] = 0, ["y"] = 0, ["param1"] = 13, ["z"] = 21, ["name"] = "lottother:dirt" },
{["x"] = 0, ["meta"] = { ["fields"] = {}, ["inventory"] = {} }, ["param2"] = 0, ["y"] = 0, ["param1"] = 15, ["z"] = 22, ["name"] = "lottother:dirt" },
{["x"] = 0, ["meta"] = { ["fields"] = {}, ["inventory"] = {} }, ["param2"] = 0, ["y"] = 1, ["param1"] = 0, ["z"] = 2, ["name"] = "lord_ground:dirt_shire" },
{["x"] = 0, ["meta"] = { ["fields"] = {}, ["inventory"] = {} }, ["param2"] = 0, ["y"] = 1, ["param1"] = 0, ["z"] = 3, ["name"] = "lord_ground:dirt_shire" },
{["x"] = 0, ["meta"] = { ["fields"] = {}, ["inventory"] = {} }, ["param2"] = 0, ["y"] = 1, ["param1"] = 0, ["z"] = 4, ["name"] = "lord_ground:dirt_shire" },
{["x"] = 0, ["meta"] = { ["fields"] = {}, ["inventory"] = {} }, ["param2"] = 0, ["y"] = 1, ["param1"] = 0, ["z"] = 5, ["name"] = "lord_ground:dirt_shire" },
{["x"] = 0, ["meta"] = { ["fields"] = {}, ["inventory"] = {} }, ["param2"] = 0, ["y"] = 1, ["param1"] = 0, ["z"] = 6, ["name"] = "lord_ground:dirt_shire" },
{["x"] = 0, ["meta"] = { ["fields"] = {}, ["inventory"] = {} }, ["param2"] = 0, ["y"] = 1, ["param1"] = 0, ["z"] = 7, ["name"] = "lord_ground:dirt_shire" },
{["x"] = 0, ["meta"] = { ["fields"] = {}, ["inventory"] = {} }, ["param2"] = 0, ["y"] = 1, ["param1"] = 0, ["z"] = 8, ["name"] = "lord_ground:dirt_shire" },
{["x"] = 0, ["meta"] = { ["fields"] = {}, ["inventory"] = {} }, ["param2"] = 0, ["y"] = 1, ["param1"] = 0, ["z"] = 9, ["name"] = "lord_ground:dirt_shire" },
{["x"] = 0, ["meta"] = { ["fields"] = {}, ["inventory"] = {} }, ["param2"] = 0, ["y"] = 1, ["param1"] = 0, ["z"] = 10, ["name"] = "lord_ground:dirt_shire" },
{["x"] = 0, ["meta"] = { ["fields"] = {}, ["inventory"] = {} }, ["param2"] = 0, ["y"] = 1, ["param1"] = 0, ["z"] = 11, ["name"] = "lord_ground:dirt_shire" },
{["x"] = 0, ["meta"] = { ["fields"] = {}, ["inventory"] = {} }, ["param2"] = 0, ["y"] = 1, ["param1"] = 0, ["z"] = 12, ["name"] = "lord_ground:dirt_shire" },
{["x"] = 0, ["meta"] = { ["fields"] = {}, ["inventory"] = {} }, ["param2"] = 0, ["y"] = 1, ["param1"] = 0, ["z"] = 13, ["name"] = "lord_ground:dirt_shire" },
{["x"] = 0, ["meta"] = { ["fields"] = {}, ["inventory"] = {} }, ["param2"] = 0, ["y"] = 1, ["param1"] = 0, ["z"] = 14, ["name"] = "lord_ground:dirt_shire" },
{["x"] = 0, ["meta"] = { ["fields"] = {}, ["inventory"] = {} }, ["param2"] = 0, ["y"] = 1, ["param1"] = 0, ["z"] = 15, ["name"] = "lord_ground:dirt_shire" },
{["x"] = 0, ["meta"] = { ["fields"] = {}, ["inventory"] = {} }, ["param2"] = 0, ["y"] = 1, ["param1"] = 0, ["z"] = 16, ["name"] = "lord_ground:dirt_shire" },
{["x"] = 0, ["meta"] = { ["fields"] = {}, ["inventory"] = {} }, ["param2"] = 0, ["y"] = 1, ["param1"] = 0, ["z"] = 17, ["name"] = "lord_ground:dirt_shire" },
{["x"] = 0, ["meta"] = { ["fields"] = {}, ["inventory"] = {} }, ["param2"] = 0, ["y"] = 1, ["param1"] = 0, ["z"] = 18, ["name"] = "lord_ground:dirt_shire" },
{["x"] = 0, ["meta"] = { ["fields"] = {}, ["inventory"] = {} }, ["param2"] = 0, ["y"] = 1, ["param1"] = 0, ["z"] = 19, ["name"] = "lord_ground:dirt_shire" },
{["x"] = 0, ["meta"] = { ["fields"] = {}, ["inventory"] = {} }, ["param2"] = 0, ["y"] = 1, ["param1"] = 0, ["z"] = 20, ["name"] = "lord_ground:dirt_shire" },
{["x"] = 0, ["meta"] = { ["fields"] = {}, ["inventory"] = {} }, ["param2"] = 0, ["y"] = 1, ["param1"] = 0, ["z"] = 21, ["name"] = "lord_ground:dirt_shire" },
{["x"] = 1, ["meta"] = { ["fields"] = {}, ["inventory"] = {} }, ["param2"] = 0, ["y"] = 0, ["param1"] = 13, ["z"] = 1, ["name"] = "lottother:dirt" },
{["x"] = 1, ["meta"] = { ["fields"] = {}, ["inventory"] = {} }, ["param2"] = 0, ["y"] = 0, ["param1"] = 12, ["z"] = 2, ["name"] = "lottother:dirt" },
{["x"] = 1, ["meta"] = { ["fields"] = {}, ["inventory"] = {} }, ["param2"] = 0, ["y"] = 0, ["param1"] = 12, ["z"] = 3, ["name"] = "lottother:dirt" },
{["x"] = 1, ["meta"] = { ["fields"] = {}, ["inventory"] = {} }, ["param2"] = 0, ["y"] = 0, ["param1"] = 12, ["z"] = 4, ["name"] = "lottother:dirt" },
{["x"] = 1, ["meta"] = { ["fields"] = {}, ["inventory"] = {} }, ["param2"] = 0, ["y"] = 0, ["param1"] = 12, ["z"] = 5, ["name"] = "lottother:dirt" },
{["x"] = 1, ["meta"] = { ["fields"] = {}, ["inventory"] = {} }, ["param2"] = 0, ["y"] = 0, ["param1"] = 12, ["z"] = 6, ["name"] = "lottother:dirt" },
{["x"] = 1, ["meta"] = { ["fields"] = {}, ["inventory"] = {} }, ["param2"] = 0, ["y"] = 0, ["param1"] = 12, ["z"] = 7, ["name"] = "lottother:dirt" },
{["x"] = 1, ["meta"] = { ["fields"] = {}, ["inventory"] = {} }, ["param2"] = 0, ["y"] = 0, ["param1"] = 12, ["z"] = 8, ["name"] = "lottother:dirt" },
{["x"] = 1, ["meta"] = { ["fields"] = {}, ["inventory"] = {} }, ["param2"] = 0, ["y"] = 0, ["param1"] = 12, ["z"] = 9, ["name"] = "lottother:dirt" },
{["x"] = 1, ["meta"] = { ["fields"] = {}, ["inventory"] = {} }, ["param2"] = 0, ["y"] = 0, ["param1"] = 12, ["z"] = 10, ["name"] = "lottother:dirt" },
{["x"] = 1, ["meta"] = { ["fields"] = {}, ["inventory"] = {} }, ["param2"] = 0, ["y"] = 0, ["param1"] = 12, ["z"] = 11, ["name"] = "lottother:dirt" },
{["x"] = 1, ["meta"] = { ["fields"] = {}, ["inventory"] = {} }, ["param2"] = 0, ["y"] = 0, ["param1"] = 12, ["z"] = 12, ["name"] = "lottother:dirt" },
{["x"] = 1, ["meta"] = { ["fields"] = {}, ["inventory"] = {} }, ["param2"] = 0, ["y"] = 0, ["param1"] = 12, ["z"] = 13, ["name"] = "lottother:dirt" },
{["x"] = 1, ["meta"] = { ["fields"] = {}, ["inventory"] = {} }, ["param2"] = 0, ["y"] = 0, ["param1"] = 12, ["z"] = 14, ["name"] = "lottother:dirt" },
{["x"] = 1, ["meta"] = { ["fields"] = {}, ["inventory"] = {} }, ["param2"] = 0, ["y"] = 0, ["param1"] = 12, ["z"] = 15, ["name"] = "lottother:dirt" },
{["x"] = 1, ["meta"] = { ["fields"] = {}, ["inventory"] = {} }, ["param2"] = 0, ["y"] = 0, ["param1"] = 12, ["z"] = 16, ["name"] = "lottother:dirt" },
{["x"] = 1, ["meta"] = { ["fields"] = {}, ["inventory"] = {} }, ["param2"] = 0, ["y"] = 0, ["param1"] = 12, ["z"] = 17, ["name"] = "lottother:dirt" },
{["x"] = 1, ["meta"] = { ["fields"] = {}, ["inventory"] = {} }, ["param2"] = 0, ["y"] = 0, ["param1"] = 12, ["z"] = 18, ["name"] = "lottother:dirt" },
{["x"] = 1, ["meta"] = { ["fields"] = {}, ["inventory"] = {} }, ["param2"] = 0, ["y"] = 0, ["param1"] = 12, ["z"] = 19, ["name"] = "lottother:dirt" },
{["x"] = 1, ["meta"] = { ["fields"] = {}, ["inventory"] = {} }, ["param2"] = 0, ["y"] = 0, ["param1"] = 12, ["z"] = 20, ["name"] = "lottother:dirt" },
{["x"] = 1, ["meta"] = { ["fields"] = {}, ["inventory"] = {} }, ["param2"] = 0, ["y"] = 0, ["param1"] = 12, ["z"] = 21, ["name"] = "lottother:dirt" },
{["x"] = 1, ["meta"] = { ["fields"] = {}, ["inventory"] = {} }, ["param2"] = 0, ["y"] = 0, ["param1"] = 13, ["z"] = 22, ["name"] = "lottother:dirt" },
{["x"] = 1, ["meta"] = { ["fields"] = {}, ["inventory"] = {} }, ["param2"] = 0, ["y"] = 1, ["param1"] = 0, ["z"] = 1, ["name"] = "lord_ground:dirt_shire" },
{["x"] = 1, ["meta"] = { ["fields"] = {}, ["inventory"] = {} }, ["param2"] = 0, ["y"] = 1, ["param1"] = 0, ["z"] = 2, ["name"] = "lord_ground:dirt_shire" },
{["x"] = 1, ["meta"] = { ["fields"] = {}, ["inventory"] = {} }, ["param2"] = 0, ["y"] = 1, ["param1"] = 13, ["z"] = 3, ["name"] = "lottother:dirt" },
{["x"] = 1, ["meta"] = { ["fields"] = {}, ["inventory"] = {} }, ["param2"] = 0, ["y"] = 1, ["param1"] = 13, ["z"] = 4, ["name"] = "lottother:dirt" },
{["x"] = 1, ["meta"] = { ["fields"] = {}, ["inventory"] = {} }, ["param2"] = 0, ["y"] = 1, ["param1"] = 13, ["z"] = 5, ["name"] = "lottother:dirt" },
{["x"] = 1, ["meta"] = { ["fields"] = {}, ["inventory"] = {} }, ["param2"] = 0, ["y"] = 1, ["param1"] = 13, ["z"] = 6, ["name"] = "lottother:dirt" },
{["x"] = 1, ["meta"] = { ["fields"] = {}, ["inventory"] = {} }, ["param2"] = 0, ["y"] = 1, ["param1"] = 13, ["z"] = 7, ["name"] = "lottother:dirt" },
{["x"] = 1, ["meta"] = { ["fields"] = {}, ["inventory"] = {} }, ["param2"] = 0, ["y"] = 1, ["param1"] = 13, ["z"] = 8, ["name"] = "lottother:dirt" },
{["x"] = 1, ["meta"] = { ["fields"] = {}, ["inventory"] = {} }, ["param2"] = 0, ["y"] = 1, ["param1"] = 0, ["z"] = 9, ["name"] = "lord_ground:dirt_shire" },
{["x"] = 1, ["meta"] = { ["fields"] = {}, ["inventory"] = {} }, ["param2"] = 0, ["y"] = 1, ["param1"] = 0, ["z"] = 10, ["name"] = "lord_ground:dirt_shire" },
{["x"] = 1, ["meta"] = { ["fields"] = {}, ["inventory"] = {} }, ["param2"] = 0, ["y"] = 1, ["param1"] = 13, ["z"] = 11, ["name"] = "lottother:dirt" },
{["x"] = 1, ["meta"] = { ["fields"] = {}, ["inventory"] = {} }, ["param2"] = 0, ["y"] = 1, ["param1"] = 13, ["z"] = 12, ["name"] = "lottother:dirt" },
{["x"] = 1, ["meta"] = { ["fields"] = {}, ["inventory"] = {} }, ["param2"] = 0, ["y"] = 1, ["param1"] = 13, ["z"] = 13, ["name"] = "lottother:dirt" },
{["x"] = 1, ["meta"] = { ["fields"] = {}, ["inventory"] = {} }, ["param2"] = 0, ["y"] = 1, ["param1"] = 13, ["z"] = 14, ["name"] = "lottother:dirt" },
{["x"] = 1, ["meta"] = { ["fields"] = {}, ["inventory"] = {} }, ["param2"] = 0, ["y"] = 1, ["param1"] = 13, ["z"] = 15, ["name"] = "lottother:dirt" },
{["x"] = 1, ["meta"] = { ["fields"] = {}, ["inventory"] = {} }, ["param2"] = 0, ["y"] = 1, ["param1"] = 13, ["z"] = 16, ["name"] = "lottother:dirt" },
{["x"] = 1, ["meta"] = { ["fields"] = {}, ["inventory"] = {} }, ["param2"] = 0, ["y"] = 1, ["param1"] = 29, ["z"] = 17, ["name"] = "lottother:dirt" },
{["x"] = 1, ["meta"] = { ["fields"] = {}, ["inventory"] = {} }, ["param2"] = 0, ["y"] = 1, ["param1"] = 13, ["z"] = 18, ["name"] = "lottother:dirt" },
{["x"] = 1, ["meta"] = { ["fields"] = {}, ["inventory"] = {} }, ["param2"] = 0, ["y"] = 1, ["param1"] = 13, ["z"] = 19, ["name"] = "lottother:dirt" },
{["x"] = 1, ["meta"] = { ["fields"] = {}, ["inventory"] = {} }, ["param2"] = 0, ["y"] = 1, ["param1"] = 13, ["z"] = 20, ["name"] = "lottother:dirt" },
{["x"] = 1, ["meta"] = { ["fields"] = {}, ["inventory"] = {} }, ["param2"] = 0, ["y"] = 1, ["param1"] = 0, ["z"] = 21, ["name"] = "lord_ground:dirt_shire" },
{["x"] = 1, ["meta"] = { ["fields"] = {}, ["inventory"] = {} }, ["param2"] = 0, ["y"] = 1, ["param1"] = 0, ["z"] = 22, ["name"] = "lord_ground:dirt_shire" },
{["x"] = 1, ["meta"] = { ["fields"] = {}, ["inventory"] = {} }, ["param2"] = 0, ["y"] = 2, ["param1"] = 0, ["z"] = 3, ["name"] = "lord_ground:dirt_shire" },
{["x"] = 1, ["meta"] = { ["fields"] = {}, ["inventory"] = {} }, ["param2"] = 0, ["y"] = 2, ["param1"] = 0, ["z"] = 4, ["name"] = "lord_ground:dirt_shire" },
{["x"] = 1, ["meta"] = { ["fields"] = {}, ["inventory"] = {} }, ["param2"] = 0, ["y"] = 2, ["param1"] = 0, ["z"] = 5, ["name"] = "lord_ground:dirt_shire" },
{["x"] = 1, ["meta"] = { ["fields"] = {}, ["inventory"] = {} }, ["param2"] = 0, ["y"] = 2, ["param1"] = 0, ["z"] = 6, ["name"] = "lord_ground:dirt_shire" },
{["x"] = 1, ["meta"] = { ["fields"] = {}, ["inventory"] = {} }, ["param2"] = 0, ["y"] = 2, ["param1"] = 0, ["z"] = 7, ["name"] = "lord_ground:dirt_shire" },
{["x"] = 1, ["meta"] = { ["fields"] = {}, ["inventory"] = {} }, ["param2"] = 0, ["y"] = 2, ["param1"] = 0, ["z"] = 8, ["name"] = "lord_ground:dirt_shire" },
{["x"] = 1, ["meta"] = { ["fields"] = {}, ["inventory"] = {} }, ["param2"] = 0, ["y"] = 2, ["param1"] = 0, ["z"] = 11, ["name"] = "lord_ground:dirt_shire" },
{["x"] = 1, ["meta"] = { ["fields"] = {}, ["inventory"] = {} }, ["param2"] = 0, ["y"] = 2, ["param1"] = 0, ["z"] = 12, ["name"] = "lord_ground:dirt_shire" },
{["x"] = 1, ["meta"] = { ["fields"] = {}, ["inventory"] = {} }, ["param2"] = 0, ["y"] = 2, ["param1"] = 0, ["z"] = 13, ["name"] = "lord_ground:dirt_shire" },
{["x"] = 1, ["meta"] = { ["fields"] = {}, ["inventory"] = {} }, ["param2"] = 0, ["y"] = 2, ["param1"] = 0, ["z"] = 14, ["name"] = "lord_ground:dirt_shire" },
{["x"] = 1, ["meta"] = { ["fields"] = {}, ["inventory"] = {} }, ["param2"] = 0, ["y"] = 2, ["param1"] = 0, ["z"] = 15, ["name"] = "lord_ground:dirt_shire" },
{["x"] = 1, ["meta"] = { ["fields"] = {}, ["inventory"] = {} }, ["param2"] = 0, ["y"] = 2, ["param1"] = 0, ["z"] = 16, ["name"] = "lord_ground:dirt_shire" },
{["x"] = 1, ["meta"] = { ["fields"] = {}, ["inventory"] = {} }, ["param2"] = 0, ["y"] = 2, ["param1"] = 0, ["z"] = 17, ["name"] = "lord_ground:dirt_shire" },
{["x"] = 1, ["meta"] = { ["fields"] = {}, ["inventory"] = {} }, ["param2"] = 0, ["y"] = 2, ["param1"] = 0, ["z"] = 18, ["name"] = "lord_ground:dirt_shire" },
{["x"] = 1, ["meta"] = { ["fields"] = {}, ["inventory"] = {} }, ["param2"] = 0, ["y"] = 2, ["param1"] = 0, ["z"] = 19, ["name"] = "lord_ground:dirt_shire" },
{["x"] = 1, ["meta"] = { ["fields"] = {}, ["inventory"] = {} }, ["param2"] = 0, ["y"] = 2, ["param1"] = 0, ["z"] = 20, ["name"] = "lord_ground:dirt_shire" },
{["x"] = 2, ["meta"] = { ["fields"] = {}, ["inventory"] = {} }, ["param2"] = 0, ["y"] = 0, ["param1"] = 13, ["z"] = 1, ["name"] = "lottother:dirt" },
{["x"] = 2, ["meta"] = { ["fields"] = {}, ["inventory"] = {} }, ["param2"] = 0, ["y"] = 0, ["param1"] = 12, ["z"] = 2, ["name"] = "lottother:dirt" },
{["x"] = 2, ["meta"] = { ["fields"] = {}, ["inventory"] = {} }, ["param2"] = 0, ["y"] = 0, ["param1"] = 11, ["z"] = 3, ["name"] = "lottother:dirt" },
{["x"] = 2, ["meta"] = { ["fields"] = {}, ["inventory"] = {} }, ["param2"] = 0, ["y"] = 0, ["param1"] = 11, ["z"] = 4, ["name"] = "lottother:dirt" },
{["x"] = 2, ["meta"] = { ["fields"] = {}, ["inventory"] = {} }, ["param2"] = 0, ["y"] = 0, ["param1"] = 11, ["z"] = 5, ["name"] = "lottother:dirt" },
{["x"] = 2, ["meta"] = { ["fields"] = {}, ["inventory"] = {} }, ["param2"] = 0, ["y"] = 0, ["param1"] = 11, ["z"] = 6, ["name"] = "lottother:dirt" },
{["x"] = 2, ["meta"] = { ["fields"] = {}, ["inventory"] = {} }, ["param2"] = 0, ["y"] = 0, ["param1"] = 11, ["z"] = 7, ["name"] = "lottother:dirt" },
{["x"] = 2, ["meta"] = { ["fields"] = {}, ["inventory"] = {} }, ["param2"] = 0, ["y"] = 0, ["param1"] = 11, ["z"] = 8, ["name"] = "lottother:dirt" },
{["x"] = 2, ["meta"] = { ["fields"] = {}, ["inventory"] = {} }, ["param2"] = 0, ["y"] = 0, ["param1"] = 11, ["z"] = 9, ["name"] = "lottother:dirt" },
{["x"] = 2, ["meta"] = { ["fields"] = {}, ["inventory"] = {} }, ["param2"] = 0, ["y"] = 0, ["param1"] = 11, ["z"] = 10, ["name"] = "lottother:dirt" },
{["x"] = 2, ["meta"] = { ["fields"] = {}, ["inventory"] = {} }, ["param2"] = 0, ["y"] = 0, ["param1"] = 11, ["z"] = 11, ["name"] = "lottother:dirt" },
{["x"] = 2, ["meta"] = { ["fields"] = {}, ["inventory"] = {} }, ["param2"] = 0, ["y"] = 0, ["param1"] = 11, ["z"] = 12, ["name"] = "lottother:dirt" },
{["x"] = 2, ["meta"] = { ["fields"] = {}, ["inventory"] = {} }, ["param2"] = 0, ["y"] = 0, ["param1"] = 11, ["z"] = 13, ["name"] = "lottother:dirt" },
{["x"] = 2, ["meta"] = { ["fields"] = {}, ["inventory"] = {} }, ["param2"] = 0, ["y"] = 0, ["param1"] = 11, ["z"] = 14, ["name"] = "lottother:dirt" },
{["x"] = 2, ["meta"] = { ["fields"] = {}, ["inventory"] = {} }, ["param2"] = 0, ["y"] = 0, ["param1"] = 11, ["z"] = 15, ["name"] = "lottother:dirt" },
{["x"] = 2, ["meta"] = { ["fields"] = {}, ["inventory"] = {} }, ["param2"] = 0, ["y"] = 0, ["param1"] = 11, ["z"] = 16, ["name"] = "lottother:dirt" },
{["x"] = 2, ["meta"] = { ["fields"] = {}, ["inventory"] = {} }, ["param2"] = 0, ["y"] = 0, ["param1"] = 11, ["z"] = 17, ["name"] = "lottother:dirt" },
{["x"] = 2, ["meta"] = { ["fields"] = {}, ["inventory"] = {} }, ["param2"] = 0, ["y"] = 0, ["param1"] = 11, ["z"] = 18, ["name"] = "lottother:dirt" },
{["x"] = 2, ["meta"] = { ["fields"] = {}, ["inventory"] = {} }, ["param2"] = 0, ["y"] = 0, ["param1"] = 11, ["z"] = 19, ["name"] = "lottother:dirt" },
{["x"] = 2, ["meta"] = { ["fields"] = {}, ["inventory"] = {} }, ["param2"] = 0, ["y"] = 0, ["param1"] = 11, ["z"] = 20, ["name"] = "lottother:dirt" },
{["x"] = 2, ["meta"] = { ["fields"] = {}, ["inventory"] = {} }, ["param2"] = 0, ["y"] = 0, ["param1"] = 12, ["z"] = 21, ["name"] = "lottother:dirt" },
{["x"] = 2, ["meta"] = { ["fields"] = {}, ["inventory"] = {} }, ["param2"] = 0, ["y"] = 0, ["param1"] = 13, ["z"] = 22, ["name"] = "lottother:dirt" },
{["x"] = 2, ["meta"] = { ["fields"] = {}, ["inventory"] = {} }, ["param2"] = 0, ["y"] = 1, ["param1"] = 0, ["z"] = 1, ["name"] = "lord_ground:dirt_shire" },
{["x"] = 2, ["meta"] = { ["fields"] = {}, ["inventory"] = {} }, ["param2"] = 0, ["y"] = 1, ["param1"] = 13, ["z"] = 2, ["name"] = "lottother:dirt" },
{["x"] = 2, ["meta"] = { ["fields"] = {}, ["inventory"] = {} }, ["param2"] = 0, ["y"] = 1, ["param1"] = 12, ["z"] = 3, ["name"] = "lottother:dirt" },
{["x"] = 2, ["meta"] = { ["fields"] = {}, ["inventory"] = {} }, ["param2"] = 0, ["y"] = 1, ["param1"] = 12, ["z"] = 4, ["name"] = "lottother:dirt" },
{["x"] = 2, ["meta"] = { ["fields"] = {}, ["inventory"] = {} }, ["param2"] = 0, ["y"] = 1, ["param1"] = 12, ["z"] = 5, ["name"] = "lottother:dirt" },
{["x"] = 2, ["meta"] = { ["fields"] = {}, ["inventory"] = {} }, ["param2"] = 0, ["y"] = 1, ["param1"] = 12, ["z"] = 6, ["name"] = "lottother:dirt" },
{["x"] = 2, ["meta"] = { ["fields"] = {}, ["inventory"] = {} }, ["param2"] = 0, ["y"] = 1, ["param1"] = 12, ["z"] = 7, ["name"] = "lottother:dirt" },
{["x"] = 2, ["meta"] = { ["fields"] = {}, ["inventory"] = {} }, ["param2"] = 0, ["y"] = 1, ["param1"] = 12, ["z"] = 8, ["name"] = "lottother:dirt" },
{["x"] = 2, ["meta"] = { ["fields"] = {}, ["inventory"] = {} }, ["param2"] = 0, ["y"] = 1, ["param1"] = 13, ["z"] = 9, ["name"] = "lottother:dirt" },
{["x"] = 2, ["meta"] = { ["fields"] = {}, ["inventory"] = {} }, ["param2"] = 0, ["y"] = 1, ["param1"] = 13, ["z"] = 10, ["name"] = "lottother:dirt" },
{["x"] = 2, ["meta"] = { ["fields"] = {}, ["inventory"] = {} }, ["param2"] = 0, ["y"] = 1, ["param1"] = 12, ["z"] = 11, ["name"] = "lottother:dirt" },
{["x"] = 2, ["meta"] = { ["fields"] = {}, ["inventory"] = {} }, ["param2"] = 0, ["y"] = 1, ["param1"] = 12, ["z"] = 12, ["name"] = "lottother:dirt" },
{["x"] = 2, ["meta"] = { ["fields"] = {}, ["inventory"] = {} }, ["param2"] = 0, ["y"] = 1, ["param1"] = 12, ["z"] = 13, ["name"] = "lottother:dirt" },
{["x"] = 2, ["meta"] = { ["fields"] = {}, ["inventory"] = {} }, ["param2"] = 0, ["y"] = 1, ["param1"] = 12, ["z"] = 14, ["name"] = "lottother:dirt" },
{["x"] = 2, ["meta"] = { ["fields"] = {}, ["inventory"] = {} }, ["param2"] = 0, ["y"] = 1, ["param1"] = 12, ["z"] = 15, ["name"] = "lottother:dirt" },
{["x"] = 2, ["meta"] = { ["fields"] = {}, ["inventory"] = {} }, ["param2"] = 0, ["y"] = 1, ["param1"] = 12, ["z"] = 16, ["name"] = "lottother:dirt" },
{["x"] = 2, ["meta"] = { ["fields"] = {}, ["inventory"] = {} }, ["param2"] = 0, ["y"] = 1, ["param1"] = 12, ["z"] = 17, ["name"] = "lottother:dirt" },
{["x"] = 2, ["meta"] = { ["fields"] = {}, ["inventory"] = {} }, ["param2"] = 0, ["y"] = 1, ["param1"] = 12, ["z"] = 18, ["name"] = "lottother:dirt" },
{["x"] = 2, ["meta"] = { ["fields"] = {}, ["inventory"] = {} }, ["param2"] = 0, ["y"] = 1, ["param1"] = 12, ["z"] = 19, ["name"] = "lottother:dirt" },
{["x"] = 2, ["meta"] = { ["fields"] = {}, ["inventory"] = {} }, ["param2"] = 0, ["y"] = 1, ["param1"] = 12, ["z"] = 20, ["name"] = "lottother:dirt" },
{["x"] = 2, ["meta"] = { ["fields"] = {}, ["inventory"] = {} }, ["param2"] = 0, ["y"] = 1, ["param1"] = 13, ["z"] = 21, ["name"] = "lottother:dirt" },
{["x"] = 2, ["meta"] = { ["fields"] = {}, ["inventory"] = {} }, ["param2"] = 0, ["y"] = 1, ["param1"] = 0, ["z"] = 22, ["name"] = "lord_ground:dirt_shire" },
{["x"] = 2, ["meta"] = { ["fields"] = {}, ["inventory"] = {} }, ["param2"] = 0, ["y"] = 2, ["param1"] = 0, ["z"] = 2, ["name"] = "lord_ground:dirt_shire" },
{["x"] = 2, ["meta"] = { ["fields"] = {}, ["inventory"] = {} }, ["param2"] = 0, ["y"] = 2, ["param1"] = 0, ["z"] = 3, ["name"] = "lord_ground:dirt_shire" },
{["x"] = 2, ["meta"] = { ["fields"] = {}, ["inventory"] = {} }, ["param2"] = 0, ["y"] = 2, ["param1"] = 13, ["z"] = 4, ["name"] = "lottother:dirt" },
{["x"] = 2, ["meta"] = { ["fields"] = {}, ["inventory"] = {} }, ["param2"] = 0, ["y"] = 2, ["param1"] = 29, ["z"] = 5, ["name"] = "lottother:dirt" },
{["x"] = 2, ["meta"] = { ["fields"] = {}, ["inventory"] = {} }, ["param2"] = 0, ["y"] = 2, ["param1"] = 45, ["z"] = 6, ["name"] = "lottother:dirt" },
{["x"] = 2, ["meta"] = { ["fields"] = {}, ["inventory"] = {} }, ["param2"] = 0, ["y"] = 2, ["param1"] = 61, ["z"] = 7, ["name"] = "lottother:dirt" },
{["x"] = 2, ["meta"] = { ["fields"] = {}, ["inventory"] = {} }, ["param2"] = 0, ["y"] = 2, ["param1"] = 0, ["z"] = 8, ["name"] = "lord_ground:dirt_shire" },
{["x"] = 2, ["meta"] = { ["fields"] = {}, ["inventory"] = {} }, ["param2"] = 0, ["y"] = 2, ["param1"] = 0, ["z"] = 9, ["name"] = "lord_ground:dirt_shire" },
{["x"] = 2, ["meta"] = { ["fields"] = {}, ["inventory"] = {} }, ["param2"] = 0, ["y"] = 2, ["param1"] = 0, ["z"] = 10, ["name"] = "lord_ground:dirt_shire" },
{["x"] = 2, ["meta"] = { ["fields"] = {}, ["inventory"] = {} }, ["param2"] = 0, ["y"] = 2, ["param1"] = 0, ["z"] = 11, ["name"] = "lord_ground:dirt_shire" },
{["x"] = 2, ["meta"] = { ["fields"] = {}, ["inventory"] = {} }, ["param2"] = 0, ["y"] = 2, ["param1"] = 61, ["z"] = 12, ["name"] = "lottother:dirt" },
{["x"] = 2, ["meta"] = { ["fields"] = {}, ["inventory"] = {} }, ["param2"] = 0, ["y"] = 2, ["param1"] = 45, ["z"] = 13, ["name"] = "lottother:dirt" },
{["x"] = 2, ["meta"] = { ["fields"] = {}, ["inventory"] = {} }, ["param2"] = 0, ["y"] = 2, ["param1"] = 45, ["z"] = 14, ["name"] = "lottother:dirt" },
{["x"] = 2, ["meta"] = { ["fields"] = {}, ["inventory"] = {} }, ["param2"] = 0, ["y"] = 2, ["param1"] = 61, ["z"] = 15, ["name"] = "lottother:dirt" },
{["x"] = 2, ["meta"] = { ["fields"] = {}, ["inventory"] = {} }, ["param2"] = 0, ["y"] = 2, ["param1"] = 0, ["z"] = 16, ["name"] = "lord_ground:dirt_shire" },
{["x"] = 2, ["meta"] = { ["fields"] = {}, ["inventory"] = {} }, ["param2"] = 0, ["y"] = 2, ["param1"] = 0, ["z"] = 17, ["name"] = "lord_ground:dirt_shire" },
{["x"] = 2, ["meta"] = { ["fields"] = {}, ["inventory"] = {} }, ["param2"] = 0, ["y"] = 2, ["param1"] = 77, ["z"] = 18, ["name"] = "lottother:dirt" },
{["x"] = 2, ["meta"] = { ["fields"] = {}, ["inventory"] = {} }, ["param2"] = 0, ["y"] = 2, ["param1"] = 61, ["z"] = 19, ["name"] = "lottother:dirt" },
{["x"] = 2, ["meta"] = { ["fields"] = {}, ["inventory"] = {} }, ["param2"] = 0, ["y"] = 2, ["param1"] = 0, ["z"] = 20, ["name"] = "lord_ground:dirt_shire" },
{["x"] = 2, ["meta"] = { ["fields"] = {}, ["inventory"] = {} }, ["param2"] = 0, ["y"] = 2, ["param1"] = 0, ["z"] = 21, ["name"] = "lord_ground:dirt_shire" },
{["x"] = 2, ["meta"] = { ["fields"] = {}, ["inventory"] = {} }, ["param2"] = 0, ["y"] = 3, ["param1"] = 0, ["z"] = 4, ["name"] = "default:dirt" },
{["x"] = 2, ["meta"] = { ["fields"] = {}, ["inventory"] = {} }, ["param2"] = 0, ["y"] = 3, ["param1"] = 0, ["z"] = 5, ["name"] = "default:dirt" },
{["x"] = 2, ["meta"] = { ["fields"] = {}, ["inventory"] = {} }, ["param2"] = 0, ["y"] = 3, ["param1"] = 0, ["z"] = 6, ["name"] = "default:dirt" },
{["x"] = 2, ["meta"] = { ["fields"] = {}, ["inventory"] = {} }, ["param2"] = 0, ["y"] = 3, ["param1"] = 0, ["z"] = 7, ["name"] = "default:dirt" },
{["x"] = 2, ["meta"] = { ["fields"] = {}, ["inventory"] = {} }, ["param2"] = 0, ["y"] = 3, ["param1"] = 0, ["z"] = 12, ["name"] = "default:dirt" },
{["x"] = 2, ["meta"] = { ["fields"] = {}, ["inventory"] = {} }, ["param2"] = 0, ["y"] = 3, ["param1"] = 0, ["z"] = 13, ["name"] = "default:dirt" },
{["x"] = 2, ["meta"] = { ["fields"] = {}, ["inventory"] = {} }, ["param2"] = 0, ["y"] = 3, ["param1"] = 0, ["z"] = 14, ["name"] = "default:dirt" },
{["x"] = 2, ["meta"] = { ["fields"] = {}, ["inventory"] = {} }, ["param2"] = 0, ["y"] = 3, ["param1"] = 0, ["z"] = 15, ["name"] = "default:dirt" },
{["x"] = 2, ["meta"] = { ["fields"] = {}, ["inventory"] = {} }, ["param2"] = 0, ["y"] = 3, ["param1"] = 0, ["z"] = 18, ["name"] = "default:dirt" },
{["x"] = 2, ["meta"] = { ["fields"] = {}, ["inventory"] = {} }, ["param2"] = 0, ["y"] = 3, ["param1"] = 0, ["z"] = 19, ["name"] = "default:dirt" },
{["x"] = 2, ["meta"] = { ["fields"] = {}, ["inventory"] = {} }, ["param2"] = 0, ["y"] = 4, ["param1"] = 0, ["z"] = 4, ["name"] = "default:dirt" },
{["x"] = 2, ["meta"] = { ["fields"] = {}, ["inventory"] = {} }, ["param2"] = 0, ["y"] = 4, ["param1"] = 0, ["z"] = 5, ["name"] = "default:dirt" },
{["x"] = 2, ["meta"] = { ["fields"] = {}, ["inventory"] = {} }, ["param2"] = 0, ["y"] = 4, ["param1"] = 0, ["z"] = 6, ["name"] = "default:dirt" },
{["x"] = 2, ["meta"] = { ["fields"] = {}, ["inventory"] = {} }, ["param2"] = 0, ["y"] = 4, ["param1"] = 0, ["z"] = 7, ["name"] = "default:dirt" },
{["x"] = 2, ["meta"] = { ["fields"] = {}, ["inventory"] = {} }, ["param2"] = 0, ["y"] = 4, ["param1"] = 0, ["z"] = 12, ["name"] = "default:dirt" },
{["x"] = 2, ["meta"] = { ["fields"] = {}, ["inventory"] = {} }, ["param2"] = 0, ["y"] = 4, ["param1"] = 0, ["z"] = 13, ["name"] = "default:dirt" },
{["x"] = 2, ["meta"] = { ["fields"] = {}, ["inventory"] = {} }, ["param2"] = 0, ["y"] = 4, ["param1"] = 0, ["z"] = 14, ["name"] = "default:dirt" },
{["x"] = 2, ["meta"] = { ["fields"] = {}, ["inventory"] = {} }, ["param2"] = 0, ["y"] = 4, ["param1"] = 0, ["z"] = 15, ["name"] = "default:dirt" },
{["x"] = 2, ["meta"] = { ["fields"] = {}, ["inventory"] = {} }, ["param2"] = 0, ["y"] = 4, ["param1"] = 0, ["z"] = 18, ["name"] = "default:dirt" },
{["x"] = 2, ["meta"] = { ["fields"] = {}, ["inventory"] = {} }, ["param2"] = 0, ["y"] = 4, ["param1"] = 0, ["z"] = 19, ["name"] = "default:dirt" },
{["x"] = 2, ["meta"] = { ["fields"] = {}, ["inventory"] = {} }, ["param2"] = 0, ["y"] = 5, ["param1"] = 0, ["z"] = 4, ["name"] = "lord_ground:dirt_shire" },
{["x"] = 2, ["meta"] = { ["fields"] = {}, ["inventory"] = {} }, ["param2"] = 0, ["y"] = 5, ["param1"] = 0, ["z"] = 5, ["name"] = "lord_ground:dirt_shire" },
{["x"] = 2, ["meta"] = { ["fields"] = {}, ["inventory"] = {} }, ["param2"] = 0, ["y"] = 5, ["param1"] = 0, ["z"] = 6, ["name"] = "lord_ground:dirt_shire" },
{["x"] = 2, ["meta"] = { ["fields"] = {}, ["inventory"] = {} }, ["param2"] = 0, ["y"] = 5, ["param1"] = 0, ["z"] = 7, ["name"] = "lord_ground:dirt_shire" },
{["x"] = 2, ["meta"] = { ["fields"] = {}, ["inventory"] = {} }, ["param2"] = 0, ["y"] = 5, ["param1"] = 0, ["z"] = 12, ["name"] = "lord_ground:dirt_shire" },
{["x"] = 2, ["meta"] = { ["fields"] = {}, ["inventory"] = {} }, ["param2"] = 0, ["y"] = 5, ["param1"] = 0, ["z"] = 13, ["name"] = "lord_ground:dirt_shire" },
{["x"] = 2, ["meta"] = { ["fields"] = {}, ["inventory"] = {} }, ["param2"] = 0, ["y"] = 5, ["param1"] = 0, ["z"] = 14, ["name"] = "lord_ground:dirt_shire" },
{["x"] = 2, ["meta"] = { ["fields"] = {}, ["inventory"] = {} }, ["param2"] = 0, ["y"] = 5, ["param1"] = 0, ["z"] = 15, ["name"] = "lord_ground:dirt_shire" },
{["x"] = 2, ["meta"] = { ["fields"] = {}, ["inventory"] = {} }, ["param2"] = 0, ["y"] = 5, ["param1"] = 0, ["z"] = 18, ["name"] = "lord_ground:dirt_shire" },
{["x"] = 2, ["meta"] = { ["fields"] = {}, ["inventory"] = {} }, ["param2"] = 0, ["y"] = 5, ["param1"] = 0, ["z"] = 19, ["name"] = "lord_ground:dirt_shire" },
{["x"] = 2, ["meta"] = { ["fields"] = {}, ["inventory"] = {} }, ["param2"] = 0, ["y"] = 6, ["param1"] = 95, ["z"] = 5, ["name"] = "flowers:rose" },
{["x"] = 2, ["meta"] = { ["fields"] = {}, ["inventory"] = {} }, ["param2"] = 0, ["y"] = 6, ["param1"] = 111, ["z"] = 6, ["name"] = "flowers:viola" },
{["x"] = 2, ["meta"] = { ["fields"] = {}, ["inventory"] = {} }, ["param2"] = 0, ["y"] = 6, ["param1"] = 125, ["z"] = 7, ["name"] = "default:grass_5" },
{["x"] = 2, ["meta"] = { ["fields"] = {}, ["inventory"] = {} }, ["param2"] = 0, ["y"] = 6, ["param1"] = 127, ["z"] = 12, ["name"] = "flowers:rose" },
{["x"] = 2, ["meta"] = { ["fields"] = {}, ["inventory"] = {} }, ["param2"] = 0, ["y"] = 6, ["param1"] = 111, ["z"] = 13, ["name"] = "flowers:dandelion_white" },
{["x"] = 2, ["meta"] = { ["fields"] = {}, ["inventory"] = {} }, ["param2"] = 0, ["y"] = 6, ["param1"] = 109, ["z"] = 14, ["name"] = "default:grass_5" },
{["x"] = 2, ["meta"] = { ["fields"] = {}, ["inventory"] = {} }, ["param2"] = 0, ["y"] = 6, ["param1"] = 125, ["z"] = 19, ["name"] = "default:grass_5" },
{["x"] = 3, ["meta"] = { ["fields"] = {}, ["inventory"] = {} }, ["param2"] = 0, ["y"] = 0, ["param1"] = 13, ["z"] = 1, ["name"] = "lottother:dirt" },
{["x"] = 3, ["meta"] = { ["fields"] = {}, ["inventory"] = {} }, ["param2"] = 0, ["y"] = 0, ["param1"] = 12, ["z"] = 2, ["name"] = "lottother:dirt" },
{["x"] = 3, ["meta"] = { ["fields"] = {}, ["inventory"] = {} }, ["param2"] = 0, ["y"] = 0, ["param1"] = 11, ["z"] = 3, ["name"] = "lottother:dirt" },
{["x"] = 3, ["meta"] = { ["fields"] = {}, ["inventory"] = {} }, ["param2"] = 0, ["y"] = 0, ["param1"] = 10, ["z"] = 4, ["name"] = "lottother:dirt" },
{["x"] = 3, ["meta"] = { ["fields"] = {}, ["inventory"] = {} }, ["param2"] = 0, ["y"] = 0, ["param1"] = 10, ["z"] = 5, ["name"] = "lottother:dirt" },
{["x"] = 3, ["meta"] = { ["fields"] = {}, ["inventory"] = {} }, ["param2"] = 0, ["y"] = 0, ["param1"] = 10, ["z"] = 6, ["name"] = "lottother:dirt" },
{["x"] = 3, ["meta"] = { ["fields"] = {}, ["inventory"] = {} }, ["param2"] = 0, ["y"] = 0, ["param1"] = 10, ["z"] = 7, ["name"] = "lottother:dirt" },
{["x"] = 3, ["meta"] = { ["fields"] = {}, ["inventory"] = {} }, ["param2"] = 0, ["y"] = 0, ["param1"] = 10, ["z"] = 8, ["name"] = "lottother:dirt" },
{["x"] = 3, ["meta"] = { ["fields"] = {}, ["inventory"] = {} }, ["param2"] = 0, ["y"] = 0, ["param1"] = 10, ["z"] = 9, ["name"] = "lottother:dirt" },
{["x"] = 3, ["meta"] = { ["fields"] = {}, ["inventory"] = {} }, ["param2"] = 0, ["y"] = 0, ["param1"] = 10, ["z"] = 10, ["name"] = "lottother:dirt" },
{["x"] = 3, ["meta"] = { ["fields"] = {}, ["inventory"] = {} }, ["param2"] = 0, ["y"] = 0, ["param1"] = 10, ["z"] = 11, ["name"] = "lottother:dirt" },
{["x"] = 3, ["meta"] = { ["fields"] = {}, ["inventory"] = {} }, ["param2"] = 0, ["y"] = 0, ["param1"] = 10, ["z"] = 12, ["name"] = "lottother:dirt" },
{["x"] = 3, ["meta"] = { ["fields"] = {}, ["inventory"] = {} }, ["param2"] = 0, ["y"] = 0, ["param1"] = 10, ["z"] = 13, ["name"] = "lottother:dirt" },
{["x"] = 3, ["meta"] = { ["fields"] = {}, ["inventory"] = {} }, ["param2"] = 0, ["y"] = 0, ["param1"] = 10, ["z"] = 14, ["name"] = "lottother:dirt" },
{["x"] = 3, ["meta"] = { ["fields"] = {}, ["inventory"] = {} }, ["param2"] = 0, ["y"] = 0, ["param1"] = 10, ["z"] = 15, ["name"] = "lottother:dirt" },
{["x"] = 3, ["meta"] = { ["fields"] = {}, ["inventory"] = {} }, ["param2"] = 0, ["y"] = 0, ["param1"] = 10, ["z"] = 16, ["name"] = "lottother:dirt" },
{["x"] = 3, ["meta"] = { ["fields"] = {}, ["inventory"] = {} }, ["param2"] = 0, ["y"] = 0, ["param1"] = 10, ["z"] = 17, ["name"] = "lottother:dirt" },
{["x"] = 3, ["meta"] = { ["fields"] = {}, ["inventory"] = {} }, ["param2"] = 0, ["y"] = 0, ["param1"] = 10, ["z"] = 18, ["name"] = "lottother:dirt" },
{["x"] = 3, ["meta"] = { ["fields"] = {}, ["inventory"] = {} }, ["param2"] = 0, ["y"] = 0, ["param1"] = 10, ["z"] = 19, ["name"] = "lottother:dirt" },
{["x"] = 3, ["meta"] = { ["fields"] = {}, ["inventory"] = {} }, ["param2"] = 0, ["y"] = 0, ["param1"] = 11, ["z"] = 20, ["name"] = "lottother:dirt" },
{["x"] = 3, ["meta"] = { ["fields"] = {}, ["inventory"] = {} }, ["param2"] = 0, ["y"] = 0, ["param1"] = 12, ["z"] = 21, ["name"] = "lottother:dirt" },
{["x"] = 3, ["meta"] = { ["fields"] = {}, ["inventory"] = {} }, ["param2"] = 0, ["y"] = 0, ["param1"] = 13, ["z"] = 22, ["name"] = "lottother:dirt" },
{["x"] = 3, ["meta"] = { ["fields"] = {}, ["inventory"] = {} }, ["param2"] = 0, ["y"] = 1, ["param1"] = 0, ["z"] = 1, ["name"] = "lord_ground:dirt_shire" },
{["x"] = 3, ["meta"] = { ["fields"] = {}, ["inventory"] = {} }, ["param2"] = 0, ["y"] = 1, ["param1"] = 13, ["z"] = 2, ["name"] = "lottother:dirt" },
{["x"] = 3, ["meta"] = { ["fields"] = {}, ["inventory"] = {} }, ["param2"] = 0, ["y"] = 1, ["param1"] = 12, ["z"] = 3, ["name"] = "lottother:dirt" },
{["x"] = 3, ["meta"] = { ["fields"] = {}, ["inventory"] = {} }, ["param2"] = 0, ["y"] = 1, ["param1"] = 11, ["z"] = 4, ["name"] = "lottother:dirt" },
{["x"] = 3, ["meta"] = { ["fields"] = {}, ["inventory"] = {} }, ["param2"] = 0, ["y"] = 1, ["param1"] = 11, ["z"] = 5, ["name"] = "lottother:dirt" },
{["x"] = 3, ["meta"] = { ["fields"] = {}, ["inventory"] = {} }, ["param2"] = 0, ["y"] = 1, ["param1"] = 11, ["z"] = 6, ["name"] = "lottother:dirt" },
{["x"] = 3, ["meta"] = { ["fields"] = {}, ["inventory"] = {} }, ["param2"] = 0, ["y"] = 1, ["param1"] = 11, ["z"] = 7, ["name"] = "lottother:dirt" },
{["x"] = 3, ["meta"] = { ["fields"] = {}, ["inventory"] = {} }, ["param2"] = 0, ["y"] = 1, ["param1"] = 11, ["z"] = 8, ["name"] = "lottother:dirt" },
{["x"] = 3, ["meta"] = { ["fields"] = {}, ["inventory"] = {} }, ["param2"] = 0, ["y"] = 1, ["param1"] = 12, ["z"] = 9, ["name"] = "lottother:dirt" },
{["x"] = 3, ["meta"] = { ["fields"] = {}, ["inventory"] = {} }, ["param2"] = 0, ["y"] = 1, ["param1"] = 12, ["z"] = 10, ["name"] = "lottother:dirt" },
{["x"] = 3, ["meta"] = { ["fields"] = {}, ["inventory"] = {} }, ["param2"] = 0, ["y"] = 1, ["param1"] = 11, ["z"] = 11, ["name"] = "lottother:dirt" },
{["x"] = 3, ["meta"] = { ["fields"] = {}, ["inventory"] = {} }, ["param2"] = 0, ["y"] = 1, ["param1"] = 11, ["z"] = 12, ["name"] = "lottother:dirt" },
{["x"] = 3, ["meta"] = { ["fields"] = {}, ["inventory"] = {} }, ["param2"] = 0, ["y"] = 1, ["param1"] = 11, ["z"] = 13, ["name"] = "lottother:dirt" },
{["x"] = 3, ["meta"] = { ["fields"] = {}, ["inventory"] = {} }, ["param2"] = 0, ["y"] = 1, ["param1"] = 11, ["z"] = 14, ["name"] = "lottother:dirt" },
{["x"] = 3, ["meta"] = { ["fields"] = {}, ["inventory"] = {} }, ["param2"] = 0, ["y"] = 1, ["param1"] = 11, ["z"] = 15, ["name"] = "lottother:dirt" },
{["x"] = 3, ["meta"] = { ["fields"] = {}, ["inventory"] = {} }, ["param2"] = 0, ["y"] = 1, ["param1"] = 11, ["z"] = 16, ["name"] = "lottother:dirt" },
{["x"] = 3, ["meta"] = { ["fields"] = {}, ["inventory"] = {} }, ["param2"] = 0, ["y"] = 1, ["param1"] = 11, ["z"] = 17, ["name"] = "lottother:dirt" },
{["x"] = 3, ["meta"] = { ["fields"] = {}, ["inventory"] = {} }, ["param2"] = 0, ["y"] = 1, ["param1"] = 11, ["z"] = 18, ["name"] = "lottother:dirt" },
{["x"] = 3, ["meta"] = { ["fields"] = {}, ["inventory"] = {} }, ["param2"] = 0, ["y"] = 1, ["param1"] = 11, ["z"] = 19, ["name"] = "lottother:dirt" },
{["x"] = 3, ["meta"] = { ["fields"] = {}, ["inventory"] = {} }, ["param2"] = 0, ["y"] = 1, ["param1"] = 12, ["z"] = 20, ["name"] = "lottother:dirt" },
{["x"] = 3, ["meta"] = { ["fields"] = {}, ["inventory"] = {} }, ["param2"] = 0, ["y"] = 1, ["param1"] = 13, ["z"] = 21, ["name"] = "lottother:dirt" },
{["x"] = 3, ["meta"] = { ["fields"] = {}, ["inventory"] = {} }, ["param2"] = 0, ["y"] = 1, ["param1"] = 0, ["z"] = 22, ["name"] = "lord_ground:dirt_shire" },
{["x"] = 3, ["meta"] = { ["fields"] = {}, ["inventory"] = {} }, ["param2"] = 0, ["y"] = 2, ["param1"] = 0, ["z"] = 2, ["name"] = "lord_ground:dirt_shire" },
{["x"] = 3, ["meta"] = { ["fields"] = {}, ["inventory"] = {} }, ["param2"] = 0, ["y"] = 2, ["param1"] = 13, ["z"] = 3, ["name"] = "lottother:dirt" },
{["x"] = 3, ["meta"] = { ["fields"] = {}, ["inventory"] = {} }, ["param2"] = 0, ["y"] = 2, ["param1"] = 12, ["z"] = 4, ["name"] = "lottother:dirt" },
{["x"] = 3, ["meta"] = { ["fields"] = {}, ["inventory"] = {} }, ["param2"] = 0, ["y"] = 2, ["param1"] = 12, ["z"] = 5, ["name"] = "lottother:dirt" },
{["x"] = 3, ["meta"] = { ["fields"] = {}, ["inventory"] = {} }, ["param2"] = 0, ["y"] = 2, ["param1"] = 28, ["z"] = 6, ["name"] = "lottother:dirt" },
{["x"] = 3, ["meta"] = { ["fields"] = {}, ["inventory"] = {} }, ["param2"] = 0, ["y"] = 2, ["param1"] = 44, ["z"] = 7, ["name"] = "lottother:dirt" },
{["x"] = 3, ["meta"] = { ["fields"] = {}, ["inventory"] = {} }, ["param2"] = 0, ["y"] = 2, ["param1"] = 61, ["z"] = 8, ["name"] = "lottother:dirt" },
{["x"] = 3, ["meta"] = { ["fields"] = {}, ["inventory"] = {} }, ["param2"] = 0, ["y"] = 2, ["param1"] = 45, ["z"] = 9, ["name"] = "lottother:dirt" },
{["x"] = 3, ["meta"] = { ["fields"] = {}, ["inventory"] = {} }, ["param2"] = 0, ["y"] = 2, ["param1"] = 45, ["z"] = 10, ["name"] = "lottother:dirt" },
{["x"] = 3, ["meta"] = { ["fields"] = {}, ["inventory"] = {} }, ["param2"] = 0, ["y"] = 2, ["param1"] = 61, ["z"] = 11, ["name"] = "lottother:dirt" },
{["x"] = 3, ["meta"] = { ["fields"] = {}, ["inventory"] = {} }, ["param2"] = 0, ["y"] = 2, ["param1"] = 44, ["z"] = 12, ["name"] = "lottother:dirt" },
{["x"] = 3, ["meta"] = { ["fields"] = {}, ["inventory"] = {} }, ["param2"] = 0, ["y"] = 2, ["param1"] = 28, ["z"] = 13, ["name"] = "lottother:dirt" },
{["x"] = 3, ["meta"] = { ["fields"] = {}, ["inventory"] = {} }, ["param2"] = 0, ["y"] = 2, ["param1"] = 28, ["z"] = 14, ["name"] = "lottother:dirt" },
{["x"] = 3, ["meta"] = { ["fields"] = {}, ["inventory"] = {} }, ["param2"] = 0, ["y"] = 2, ["param1"] = 44, ["z"] = 15, ["name"] = "lottother:dirt" },
{["x"] = 3, ["meta"] = { ["fields"] = {}, ["inventory"] = {} }, ["param2"] = 0, ["y"] = 2, ["param1"] = 61, ["z"] = 16, ["name"] = "lottother:dirt" },
{["x"] = 3, ["meta"] = { ["fields"] = {}, ["inventory"] = {} }, ["param2"] = 0, ["y"] = 2, ["param1"] = 77, ["z"] = 17, ["name"] = "lottother:dirt" },
{["x"] = 3, ["meta"] = { ["fields"] = {}, ["inventory"] = {} }, ["param2"] = 0, ["y"] = 2, ["param1"] = 60, ["z"] = 18, ["name"] = "lottother:dirt" },
{["x"] = 3, ["meta"] = { ["fields"] = {}, ["inventory"] = {} }, ["param2"] = 0, ["y"] = 2, ["param1"] = 44, ["z"] = 19, ["name"] = "lottother:dirt" },
{["x"] = 3, ["meta"] = { ["fields"] = {}, ["inventory"] = {} }, ["param2"] = 0, ["y"] = 2, ["param1"] = 29, ["z"] = 20, ["name"] = "lottother:dirt" },
{["x"] = 3, ["meta"] = { ["fields"] = {}, ["inventory"] = {} }, ["param2"] = 0, ["y"] = 2, ["param1"] = 0, ["z"] = 21, ["name"] = "lord_ground:dirt_shire" },
{["x"] = 3, ["meta"] = { ["fields"] = {}, ["inventory"] = {} }, ["param2"] = 0, ["y"] = 3, ["param1"] = 0, ["z"] = 3, ["name"] = "default:dirt" },
{["x"] = 3, ["meta"] = { ["fields"] = {}, ["inventory"] = {} }, ["param2"] = 0, ["y"] = 3, ["param1"] = 0, ["z"] = 4, ["name"] = "default:dirt" },
{["x"] = 3, ["meta"] = { ["fields"] = {}, ["inventory"] = {} }, ["param2"] = 0, ["y"] = 3, ["param1"] = 0, ["z"] = 5, ["name"] = "default:dirt" },
{["x"] = 3, ["meta"] = { ["fields"] = {}, ["inventory"] = {} }, ["param2"] = 0, ["y"] = 3, ["param1"] = 0, ["z"] = 6, ["name"] = "default:dirt" },
{["x"] = 3, ["meta"] = { ["fields"] = {}, ["inventory"] = {} }, ["param2"] = 0, ["y"] = 3, ["param1"] = 0, ["z"] = 7, ["name"] = "default:dirt" },
{["x"] = 3, ["meta"] = { ["fields"] = {}, ["inventory"] = {} }, ["param2"] = 0, ["y"] = 3, ["param1"] = 0, ["z"] = 8, ["name"] = "default:dirt" },
{["x"] = 3, ["meta"] = { ["fields"] = {}, ["inventory"] = {} }, ["param2"] = 0, ["y"] = 3, ["param1"] = 0, ["z"] = 9, ["name"] = "default:dirt" },
{["x"] = 3, ["meta"] = { ["fields"] = {}, ["inventory"] = {} }, ["param2"] = 0, ["y"] = 3, ["param1"] = 0, ["z"] = 10, ["name"] = "default:dirt" },
{["x"] = 3, ["meta"] = { ["fields"] = {}, ["inventory"] = {} }, ["param2"] = 0, ["y"] = 3, ["param1"] = 0, ["z"] = 11, ["name"] = "default:dirt" },
{["x"] = 3, ["meta"] = { ["fields"] = {}, ["inventory"] = {} }, ["param2"] = 0, ["y"] = 3, ["param1"] = 0, ["z"] = 12, ["name"] = "default:dirt" },
{["x"] = 3, ["meta"] = { ["fields"] = {}, ["inventory"] = {} }, ["param2"] = 0, ["y"] = 3, ["param1"] = 0, ["z"] = 13, ["name"] = "default:dirt" },
{["x"] = 3, ["meta"] = { ["fields"] = {}, ["inventory"] = {} }, ["param2"] = 0, ["y"] = 3, ["param1"] = 0, ["z"] = 14, ["name"] = "default:dirt" },
{["x"] = 3, ["meta"] = { ["fields"] = {}, ["inventory"] = {} }, ["param2"] = 0, ["y"] = 3, ["param1"] = 0, ["z"] = 15, ["name"] = "default:dirt" },
{["x"] = 3, ["meta"] = { ["fields"] = {}, ["inventory"] = {} }, ["param2"] = 0, ["y"] = 3, ["param1"] = 0, ["z"] = 16, ["name"] = "default:dirt" },
{["x"] = 3, ["meta"] = { ["fields"] = {}, ["inventory"] = {} }, ["param2"] = 0, ["y"] = 3, ["param1"] = 0, ["z"] = 17, ["name"] = "default:dirt" },
{["x"] = 3, ["meta"] = { ["fields"] = {}, ["inventory"] = {} }, ["param2"] = 0, ["y"] = 3, ["param1"] = 0, ["z"] = 18, ["name"] = "default:dirt" },
{["x"] = 3, ["meta"] = { ["fields"] = {}, ["inventory"] = {} }, ["param2"] = 0, ["y"] = 3, ["param1"] = 0, ["z"] = 19, ["name"] = "default:dirt" },
{["x"] = 3, ["meta"] = { ["fields"] = {}, ["inventory"] = {} }, ["param2"] = 0, ["y"] = 3, ["param1"] = 0, ["z"] = 20, ["name"] = "default:dirt" },
{["x"] = 3, ["meta"] = { ["fields"] = {}, ["inventory"] = {} }, ["param2"] = 0, ["y"] = 4, ["param1"] = 0, ["z"] = 3, ["name"] = "default:dirt" },
{["x"] = 3, ["meta"] = { ["fields"] = {}, ["inventory"] = {} }, ["param2"] = 0, ["y"] = 4, ["param1"] = 0, ["z"] = 4, ["name"] = "default:dirt" },
{["x"] = 3, ["meta"] = { ["fields"] = {}, ["inventory"] = {} }, ["param2"] = 0, ["y"] = 4, ["param1"] = 0, ["z"] = 5, ["name"] = "default:dirt" },
{["x"] = 3, ["meta"] = { ["fields"] = {}, ["inventory"] = {} }, ["param2"] = 0, ["y"] = 4, ["param1"] = 0, ["z"] = 6, ["name"] = "default:dirt" },
{["x"] = 3, ["meta"] = { ["fields"] = {}, ["inventory"] = {} }, ["param2"] = 0, ["y"] = 4, ["param1"] = 0, ["z"] = 7, ["name"] = "default:dirt" },
{["x"] = 3, ["meta"] = { ["fields"] = {}, ["inventory"] = {} }, ["param2"] = 0, ["y"] = 4, ["param1"] = 0, ["z"] = 8, ["name"] = "lord_ground:dirt_shire" },
{["x"] = 3, ["meta"] = { ["fields"] = {}, ["inventory"] = {} }, ["param2"] = 0, ["y"] = 4, ["param1"] = 0, ["z"] = 9, ["name"] = "default:dirt" },
{["x"] = 3, ["meta"] = { ["fields"] = {}, ["inventory"] = {} }, ["param2"] = 0, ["y"] = 4, ["param1"] = 0, ["z"] = 10, ["name"] = "default:dirt" },
{["x"] = 3, ["meta"] = { ["fields"] = {}, ["inventory"] = {} }, ["param2"] = 0, ["y"] = 4, ["param1"] = 0, ["z"] = 11, ["name"] = "lord_ground:dirt_shire" },
{["x"] = 3, ["meta"] = { ["fields"] = {}, ["inventory"] = {} }, ["param2"] = 0, ["y"] = 4, ["param1"] = 0, ["z"] = 12, ["name"] = "default:dirt" },
{["x"] = 3, ["meta"] = { ["fields"] = {}, ["inventory"] = {} }, ["param2"] = 0, ["y"] = 4, ["param1"] = 0, ["z"] = 13, ["name"] = "default:dirt" },
{["x"] = 3, ["meta"] = { ["fields"] = {}, ["inventory"] = {} }, ["param2"] = 0, ["y"] = 4, ["param1"] = 0, ["z"] = 14, ["name"] = "default:dirt" },
{["x"] = 3, ["meta"] = { ["fields"] = {}, ["inventory"] = {} }, ["param2"] = 0, ["y"] = 4, ["param1"] = 0, ["z"] = 15, ["name"] = "default:dirt" },
{["x"] = 3, ["meta"] = { ["fields"] = {}, ["inventory"] = {} }, ["param2"] = 0, ["y"] = 4, ["param1"] = 0, ["z"] = 16, ["name"] = "lord_ground:dirt_shire" },
{["x"] = 3, ["meta"] = { ["fields"] = {}, ["inventory"] = {} }, ["param2"] = 0, ["y"] = 4, ["param1"] = 0, ["z"] = 17, ["name"] = "lord_ground:dirt_shire" },
{["x"] = 3, ["meta"] = { ["fields"] = {}, ["inventory"] = {} }, ["param2"] = 0, ["y"] = 4, ["param1"] = 0, ["z"] = 18, ["name"] = "default:dirt" },
{["x"] = 3, ["meta"] = { ["fields"] = {}, ["inventory"] = {} }, ["param2"] = 0, ["y"] = 4, ["param1"] = 0, ["z"] = 19, ["name"] = "default:dirt" },
{["x"] = 3, ["meta"] = { ["fields"] = {}, ["inventory"] = {} }, ["param2"] = 0, ["y"] = 4, ["param1"] = 0, ["z"] = 20, ["name"] = "default:dirt" },
{["x"] = 3, ["meta"] = { ["fields"] = {}, ["inventory"] = {} }, ["param2"] = 0, ["y"] = 5, ["param1"] = 0, ["z"] = 3, ["name"] = "lord_ground:dirt_shire" },
{["x"] = 3, ["meta"] = { ["fields"] = {}, ["inventory"] = {} }, ["param2"] = 0, ["y"] = 5, ["param1"] = 0, ["z"] = 4, ["name"] = "default:dirt" },
{["x"] = 3, ["meta"] = { ["fields"] = {}, ["inventory"] = {} }, ["param2"] = 0, ["y"] = 5, ["param1"] = 0, ["z"] = 5, ["name"] = "default:dirt" },
{["x"] = 3, ["meta"] = { ["fields"] = {}, ["inventory"] = {} }, ["param2"] = 0, ["y"] = 5, ["param1"] = 0, ["z"] = 6, ["name"] = "default:dirt" },
{["x"] = 3, ["meta"] = { ["fields"] = {}, ["inventory"] = {} }, ["param2"] = 0, ["y"] = 5, ["param1"] = 0, ["z"] = 7, ["name"] = "default:dirt" },
{["x"] = 3, ["meta"] = { ["fields"] = {}, ["inventory"] = {} }, ["param2"] = 0, ["y"] = 5, ["param1"] = 141, ["z"] = 8, ["name"] = "flowers:rose" },
{["x"] = 3, ["meta"] = { ["fields"] = {}, ["inventory"] = {} }, ["param2"] = 0, ["y"] = 5, ["param1"] = 0, ["z"] = 9, ["name"] = "default:brick" },
{["x"] = 3, ["meta"] = { ["fields"] = {}, ["inventory"] = {} }, ["param2"] = 0, ["y"] = 5, ["param1"] = 0, ["z"] = 10, ["name"] = "default:brick" },
{["x"] = 3, ["meta"] = { ["fields"] = {}, ["inventory"] = {} }, ["param2"] = 0, ["y"] = 5, ["param1"] = 141, ["z"] = 11, ["name"] = "default:grass_5" },
{["x"] = 3, ["meta"] = { ["fields"] = {}, ["inventory"] = {} }, ["param2"] = 0, ["y"] = 5, ["param1"] = 0, ["z"] = 12, ["name"] = "default:dirt" },
{["x"] = 3, ["meta"] = { ["fields"] = {}, ["inventory"] = {} }, ["param2"] = 0, ["y"] = 5, ["param1"] = 0, ["z"] = 13, ["name"] = "default:dirt" },
{["x"] = 3, ["meta"] = { ["fields"] = {}, ["inventory"] = {} }, ["param2"] = 0, ["y"] = 5, ["param1"] = 0, ["z"] = 14, ["name"] = "default:dirt" },
{["x"] = 3, ["meta"] = { ["fields"] = {}, ["inventory"] = {} }, ["param2"] = 0, ["y"] = 5, ["param1"] = 0, ["z"] = 15, ["name"] = "default:dirt" },
{["x"] = 3, ["meta"] = { ["fields"] = {}, ["inventory"] = {} }, ["param2"] = 0, ["y"] = 5, ["param1"] = 0, ["z"] = 18, ["name"] = "default:dirt" },
{["x"] = 3, ["meta"] = { ["fields"] = {}, ["inventory"] = {} }, ["param2"] = 0, ["y"] = 5, ["param1"] = 0, ["z"] = 19, ["name"] = "default:dirt" },
{["x"] = 3, ["meta"] = { ["fields"] = {}, ["inventory"] = {} }, ["param2"] = 0, ["y"] = 5, ["param1"] = 0, ["z"] = 20, ["name"] = "lord_ground:dirt_shire" },
{["x"] = 3, ["meta"] = { ["fields"] = {}, ["inventory"] = {} }, ["param2"] = 0, ["y"] = 6, ["param1"] = 45, ["z"] = 3, ["name"] = "default:grass_5" },
{["x"] = 3, ["meta"] = { ["fields"] = {}, ["inventory"] = {} }, ["param2"] = 0, ["y"] = 6, ["param1"] = 0, ["z"] = 4, ["name"] = "lord_ground:dirt_shire" },
{["x"] = 3, ["meta"] = { ["fields"] = {}, ["inventory"] = {} }, ["param2"] = 0, ["y"] = 6, ["param1"] = 0, ["z"] = 5, ["name"] = "lord_ground:dirt_shire" },
{["x"] = 3, ["meta"] = { ["fields"] = {}, ["inventory"] = {} }, ["param2"] = 0, ["y"] = 6, ["param1"] = 0, ["z"] = 6, ["name"] = "lord_ground:dirt_shire" },
{["x"] = 3, ["meta"] = { ["fields"] = {}, ["inventory"] = {} }, ["param2"] = 0, ["y"] = 6, ["param1"] = 0, ["z"] = 7, ["name"] = "default:brick" },
{["x"] = 3, ["meta"] = { ["fields"] = {}, ["inventory"] = {} }, ["param2"] = 0, ["y"] = 6, ["param1"] = 0, ["z"] = 9, ["name"] = "default:brick" },
{["x"] = 3, ["meta"] = { ["fields"] = {}, ["inventory"] = {} }, ["param2"] = 0, ["y"] = 6, ["param1"] = 0, ["z"] = 10, ["name"] = "default:brick" },
{["x"] = 3, ["meta"] = { ["fields"] = {}, ["inventory"] = {} }, ["param2"] = 0, ["y"] = 6, ["param1"] = 0, ["z"] = 12, ["name"] = "default:brick" },
{["x"] = 3, ["meta"] = { ["fields"] = {}, ["inventory"] = {} }, ["param2"] = 0, ["y"] = 6, ["param1"] = 0, ["z"] = 13, ["name"] = "lord_ground:dirt_shire" },
{["x"] = 3, ["meta"] = { ["fields"] = {}, ["inventory"] = {} }, ["param2"] = 0, ["y"] = 6, ["param1"] = 0, ["z"] = 14, ["name"] = "lord_ground:dirt_shire" },
{["x"] = 3, ["meta"] = { ["fields"] = {}, ["inventory"] = {} }, ["param2"] = 0, ["y"] = 6, ["param1"] = 0, ["z"] = 15, ["name"] = "default:brick" },
{["x"] = 3, ["meta"] = { ["fields"] = {}, ["inventory"] = {} }, ["param2"] = 0, ["y"] = 6, ["param1"] = 0, ["z"] = 18, ["name"] = "default:brick" },
{["x"] = 3, ["meta"] = { ["fields"] = {}, ["inventory"] = {} }, ["param2"] = 0, ["y"] = 6, ["param1"] = 0, ["z"] = 19, ["name"] = "lord_ground:dirt_shire" },
{["x"] = 3, ["meta"] = { ["fields"] = {}, ["inventory"] = {} }, ["param2"] = 0, ["y"] = 7, ["param1"] = 47, ["z"] = 4, ["name"] = "flowers:geranium" },
{["x"] = 3, ["meta"] = { ["fields"] = {}, ["inventory"] = {} }, ["param2"] = 0, ["y"] = 7, ["param1"] = 79, ["z"] = 6, ["name"] = "flowers:tulip" },
{["x"] = 3, ["meta"] = { ["fields"] = {}, ["inventory"] = {} }, ["param2"] = 0, ["y"] = 7, ["param1"] = 0, ["z"] = 7, ["name"] = "default:brick" },
{["x"] = 3, ["meta"] = { ["fields"] = {}, ["inventory"] = {} }, ["param2"] = 0, ["y"] = 7, ["param1"] = 0, ["z"] = 8, ["name"] = "default:brick" },
{["x"] = 3, ["meta"] = { ["fields"] = {}, ["inventory"] = {} }, ["param2"] = 0, ["y"] = 7, ["param1"] = 0, ["z"] = 9, ["name"] = "default:brick" },
{["x"] = 3, ["meta"] = { ["fields"] = {}, ["inventory"] = {} }, ["param2"] = 0, ["y"] = 7, ["param1"] = 0, ["z"] = 10, ["name"] = "default:brick" },
{["x"] = 3, ["meta"] = { ["fields"] = {}, ["inventory"] = {} }, ["param2"] = 0, ["y"] = 7, ["param1"] = 0, ["z"] = 11, ["name"] = "default:brick" },
{["x"] = 3, ["meta"] = { ["fields"] = {}, ["inventory"] = {} }, ["param2"] = 0, ["y"] = 7, ["param1"] = 0, ["z"] = 12, ["name"] = "default:brick" },
{["x"] = 3, ["meta"] = { ["fields"] = {}, ["inventory"] = {} }, ["param2"] = 0, ["y"] = 7, ["param1"] = 79, ["z"] = 13, ["name"] = "flowers:viola" },
{["x"] = 3, ["meta"] = { ["fields"] = {}, ["inventory"] = {} }, ["param2"] = 0, ["y"] = 7, ["param1"] = 77, ["z"] = 14, ["name"] = "default:grass_5" },
{["x"] = 3, ["meta"] = { ["fields"] = {}, ["inventory"] = {} }, ["param2"] = 0, ["y"] = 7, ["param1"] = 0, ["z"] = 15, ["name"] = "default:brick" },
{["x"] = 3, ["meta"] = { ["fields"] = {}, ["inventory"] = {} }, ["param2"] = 0, ["y"] = 7, ["param1"] = 0, ["z"] = 16, ["name"] = "default:brick" },
{["x"] = 3, ["meta"] = { ["fields"] = {}, ["inventory"] = {} }, ["param2"] = 0, ["y"] = 7, ["param1"] = 0, ["z"] = 17, ["name"] = "default:brick" },
{["x"] = 3, ["meta"] = { ["fields"] = {}, ["inventory"] = {} }, ["param2"] = 0, ["y"] = 7, ["param1"] = 0, ["z"] = 18, ["name"] = "default:brick" },
{["x"] = 3, ["meta"] = { ["fields"] = {}, ["inventory"] = {} }, ["param2"] = 0, ["y"] = 7, ["param1"] = 95, ["z"] = 19, ["name"] = "flowers:tulip" },
{["x"] = 4, ["meta"] = { ["fields"] = {}, ["inventory"] = {} }, ["param2"] = 0, ["y"] = 0, ["param1"] = 13, ["z"] = 1, ["name"] = "lottother:dirt" },
{["x"] = 4, ["meta"] = { ["fields"] = {}, ["inventory"] = {} }, ["param2"] = 0, ["y"] = 0, ["param1"] = 12, ["z"] = 2, ["name"] = "lottother:dirt" },
{["x"] = 4, ["meta"] = { ["fields"] = {}, ["inventory"] = {} }, ["param2"] = 0, ["y"] = 0, ["param1"] = 11, ["z"] = 3, ["name"] = "lottother:dirt" },
{["x"] = 4, ["meta"] = { ["fields"] = {}, ["inventory"] = {} }, ["param2"] = 0, ["y"] = 0, ["param1"] = 10, ["z"] = 4, ["name"] = "lottother:dirt" },
{["x"] = 4, ["meta"] = { ["fields"] = {}, ["inventory"] = {} }, ["param2"] = 0, ["y"] = 0, ["param1"] = 9, ["z"] = 5, ["name"] = "lottother:dirt" },
{["x"] = 4, ["meta"] = { ["fields"] = {}, ["inventory"] = {} }, ["param2"] = 0, ["y"] = 0, ["param1"] = 9, ["z"] = 6, ["name"] = "lottother:dirt" },
{["x"] = 4, ["meta"] = { ["fields"] = {}, ["inventory"] = {} }, ["param2"] = 0, ["y"] = 0, ["param1"] = 9, ["z"] = 7, ["name"] = "lottother:dirt" },
{["x"] = 4, ["meta"] = { ["fields"] = {}, ["inventory"] = {} }, ["param2"] = 0, ["y"] = 0, ["param1"] = 9, ["z"] = 8, ["name"] = "lottother:dirt" },
{["x"] = 4, ["meta"] = { ["fields"] = {}, ["inventory"] = {} }, ["param2"] = 0, ["y"] = 0, ["param1"] = 9, ["z"] = 9, ["name"] = "lottother:dirt" },
{["x"] = 4, ["meta"] = { ["fields"] = {}, ["inventory"] = {} }, ["param2"] = 0, ["y"] = 0, ["param1"] = 9, ["z"] = 10, ["name"] = "lottother:dirt" },
{["x"] = 4, ["meta"] = { ["fields"] = {}, ["inventory"] = {} }, ["param2"] = 0, ["y"] = 0, ["param1"] = 9, ["z"] = 11, ["name"] = "lottother:dirt" },
{["x"] = 4, ["meta"] = { ["fields"] = {}, ["inventory"] = {} }, ["param2"] = 0, ["y"] = 0, ["param1"] = 9, ["z"] = 12, ["name"] = "lottother:dirt" },
{["x"] = 4, ["meta"] = { ["fields"] = {}, ["inventory"] = {} }, ["param2"] = 0, ["y"] = 0, ["param1"] = 9, ["z"] = 13, ["name"] = "lottother:dirt" },
{["x"] = 4, ["meta"] = { ["fields"] = {}, ["inventory"] = {} }, ["param2"] = 0, ["y"] = 0, ["param1"] = 9, ["z"] = 14, ["name"] = "lottother:dirt" },
{["x"] = 4, ["meta"] = { ["fields"] = {}, ["inventory"] = {} }, ["param2"] = 0, ["y"] = 0, ["param1"] = 9, ["z"] = 15, ["name"] = "lottother:dirt" },
{["x"] = 4, ["meta"] = { ["fields"] = {}, ["inventory"] = {} }, ["param2"] = 0, ["y"] = 0, ["param1"] = 9, ["z"] = 16, ["name"] = "lottother:dirt" },
{["x"] = 4, ["meta"] = { ["fields"] = {}, ["inventory"] = {} }, ["param2"] = 0, ["y"] = 0, ["param1"] = 9, ["z"] = 17, ["name"] = "lottother:dirt" },
{["x"] = 4, ["meta"] = { ["fields"] = {}, ["inventory"] = {} }, ["param2"] = 0, ["y"] = 0, ["param1"] = 9, ["z"] = 18, ["name"] = "lottother:dirt" },
{["x"] = 4, ["meta"] = { ["fields"] = {}, ["inventory"] = {} }, ["param2"] = 0, ["y"] = 0, ["param1"] = 10, ["z"] = 19, ["name"] = "lottother:dirt" },
{["x"] = 4, ["meta"] = { ["fields"] = {}, ["inventory"] = {} }, ["param2"] = 0, ["y"] = 0, ["param1"] = 11, ["z"] = 20, ["name"] = "lottother:dirt" },
{["x"] = 4, ["meta"] = { ["fields"] = {}, ["inventory"] = {} }, ["param2"] = 0, ["y"] = 0, ["param1"] = 12, ["z"] = 21, ["name"] = "lottother:dirt" },
{["x"] = 4, ["meta"] = { ["fields"] = {}, ["inventory"] = {} }, ["param2"] = 0, ["y"] = 0, ["param1"] = 13, ["z"] = 22, ["name"] = "lottother:dirt" },
{["x"] = 4, ["meta"] = { ["fields"] = {}, ["inventory"] = {} }, ["param2"] = 0, ["y"] = 1, ["param1"] = 0, ["z"] = 1, ["name"] = "lord_ground:dirt_shire" },
{["x"] = 4, ["meta"] = { ["fields"] = {}, ["inventory"] = {} }, ["param2"] = 0, ["y"] = 1, ["param1"] = 13, ["z"] = 2, ["name"] = "lottother:dirt" },
{["x"] = 4, ["meta"] = { ["fields"] = {}, ["inventory"] = {} }, ["param2"] = 0, ["y"] = 1, ["param1"] = 12, ["z"] = 3, ["name"] = "lottother:dirt" },
{["x"] = 4, ["meta"] = { ["fields"] = {}, ["inventory"] = {} }, ["param2"] = 0, ["y"] = 1, ["param1"] = 11, ["z"] = 4, ["name"] = "lottother:dirt" },
{["x"] = 4, ["meta"] = { ["fields"] = {}, ["inventory"] = {} }, ["param2"] = 0, ["y"] = 1, ["param1"] = 10, ["z"] = 5, ["name"] = "lottother:dirt" },
{["x"] = 4, ["meta"] = { ["fields"] = {}, ["inventory"] = {} }, ["param2"] = 0, ["y"] = 1, ["param1"] = 10, ["z"] = 6, ["name"] = "lottother:dirt" },
{["x"] = 4, ["meta"] = { ["fields"] = {}, ["inventory"] = {} }, ["param2"] = 0, ["y"] = 1, ["param1"] = 10, ["z"] = 7, ["name"] = "lottother:dirt" },
{["x"] = 4, ["meta"] = { ["fields"] = {}, ["inventory"] = {} }, ["param2"] = 0, ["y"] = 1, ["param1"] = 10, ["z"] = 8, ["name"] = "lottother:dirt" },
{["x"] = 4, ["meta"] = { ["fields"] = {}, ["inventory"] = {} }, ["param2"] = 0, ["y"] = 1, ["param1"] = 11, ["z"] = 9, ["name"] = "lottother:dirt" },
{["x"] = 4, ["meta"] = { ["fields"] = {}, ["inventory"] = {} }, ["param2"] = 0, ["y"] = 1, ["param1"] = 11, ["z"] = 10, ["name"] = "lottother:dirt" },
{["x"] = 4, ["meta"] = { ["fields"] = {}, ["inventory"] = {} }, ["param2"] = 0, ["y"] = 1, ["param1"] = 10, ["z"] = 11, ["name"] = "lottother:dirt" },
{["x"] = 4, ["meta"] = { ["fields"] = {}, ["inventory"] = {} }, ["param2"] = 0, ["y"] = 1, ["param1"] = 10, ["z"] = 12, ["name"] = "lottother:dirt" },
{["x"] = 4, ["meta"] = { ["fields"] = {}, ["inventory"] = {} }, ["param2"] = 0, ["y"] = 1, ["param1"] = 10, ["z"] = 13, ["name"] = "lottother:dirt" },
{["x"] = 4, ["meta"] = { ["fields"] = {}, ["inventory"] = {} }, ["param2"] = 0, ["y"] = 1, ["param1"] = 10, ["z"] = 14, ["name"] = "lottother:dirt" },
{["x"] = 4, ["meta"] = { ["fields"] = {}, ["inventory"] = {} }, ["param2"] = 0, ["y"] = 1, ["param1"] = 10, ["z"] = 15, ["name"] = "lottother:dirt" },
{["x"] = 4, ["meta"] = { ["fields"] = {}, ["inventory"] = {} }, ["param2"] = 0, ["y"] = 1, ["param1"] = 10, ["z"] = 16, ["name"] = "lottother:dirt" },
{["x"] = 4, ["meta"] = { ["fields"] = {}, ["inventory"] = {} }, ["param2"] = 0, ["y"] = 1, ["param1"] = 10, ["z"] = 17, ["name"] = "lottother:dirt" },
{["x"] = 4, ["meta"] = { ["fields"] = {}, ["inventory"] = {} }, ["param2"] = 0, ["y"] = 1, ["param1"] = 10, ["z"] = 18, ["name"] = "lottother:dirt" },
{["x"] = 4, ["meta"] = { ["fields"] = {}, ["inventory"] = {} }, ["param2"] = 0, ["y"] = 1, ["param1"] = 11, ["z"] = 19, ["name"] = "lottother:dirt" },
{["x"] = 4, ["meta"] = { ["fields"] = {}, ["inventory"] = {} }, ["param2"] = 0, ["y"] = 1, ["param1"] = 12, ["z"] = 20, ["name"] = "lottother:dirt" },
{["x"] = 4, ["meta"] = { ["fields"] = {}, ["inventory"] = {} }, ["param2"] = 0, ["y"] = 1, ["param1"] = 13, ["z"] = 21, ["name"] = "lottother:dirt" },
{["x"] = 4, ["meta"] = { ["fields"] = {}, ["inventory"] = {} }, ["param2"] = 0, ["y"] = 1, ["param1"] = 0, ["z"] = 22, ["name"] = "lord_ground:dirt_shire" },
{["x"] = 4, ["meta"] = { ["fields"] = {}, ["inventory"] = {} }, ["param2"] = 0, ["y"] = 2, ["param1"] = 0, ["z"] = 2, ["name"] = "lord_ground:dirt_shire" },
{["x"] = 4, ["meta"] = { ["fields"] = {}, ["inventory"] = {} }, ["param2"] = 0, ["y"] = 2, ["param1"] = 13, ["z"] = 3, ["name"] = "lottother:dirt" },
{["x"] = 4, ["meta"] = { ["fields"] = {}, ["inventory"] = {} }, ["param2"] = 0, ["y"] = 2, ["param1"] = 12, ["z"] = 4, ["name"] = "lottother:dirt" },
{["x"] = 4, ["meta"] = { ["fields"] = {}, ["inventory"] = {} }, ["param2"] = 0, ["y"] = 2, ["param1"] = 11, ["z"] = 5, ["name"] = "lottother:dirt" },
{["x"] = 4, ["meta"] = { ["fields"] = {}, ["inventory"] = {} }, ["param2"] = 0, ["y"] = 2, ["param1"] = 11, ["z"] = 6, ["name"] = "lottother:dirt" },
{["x"] = 4, ["meta"] = { ["fields"] = {}, ["inventory"] = {} }, ["param2"] = 0, ["y"] = 2, ["param1"] = 27, ["z"] = 7, ["name"] = "lottother:dirt" },
{["x"] = 4, ["meta"] = { ["fields"] = {}, ["inventory"] = {} }, ["param2"] = 0, ["y"] = 2, ["param1"] = 44, ["z"] = 8, ["name"] = "lottother:dirt" },
{["x"] = 4, ["meta"] = { ["fields"] = {}, ["inventory"] = {} }, ["param2"] = 0, ["y"] = 2, ["param1"] = 28, ["z"] = 9, ["name"] = "lottother:dirt" },
{["x"] = 4, ["meta"] = { ["fields"] = {}, ["inventory"] = {} }, ["param2"] = 0, ["y"] = 2, ["param1"] = 28, ["z"] = 10, ["name"] = "lottother:dirt" },
{["x"] = 4, ["meta"] = { ["fields"] = {}, ["inventory"] = {} }, ["param2"] = 0, ["y"] = 2, ["param1"] = 44, ["z"] = 11, ["name"] = "lottother:dirt" },
{["x"] = 4, ["meta"] = { ["fields"] = {}, ["inventory"] = {} }, ["param2"] = 0, ["y"] = 2, ["param1"] = 27, ["z"] = 12, ["name"] = "lottother:dirt" },
{["x"] = 4, ["meta"] = { ["fields"] = {}, ["inventory"] = {} }, ["param2"] = 0, ["y"] = 2, ["param1"] = 11, ["z"] = 13, ["name"] = "lottother:dirt" },
{["x"] = 4, ["meta"] = { ["fields"] = {}, ["inventory"] = {} }, ["param2"] = 0, ["y"] = 2, ["param1"] = 11, ["z"] = 14, ["name"] = "lottother:dirt" },
{["x"] = 4, ["meta"] = { ["fields"] = {}, ["inventory"] = {} }, ["param2"] = 0, ["y"] = 2, ["param1"] = 27, ["z"] = 15, ["name"] = "lottother:dirt" },
{["x"] = 4, ["meta"] = { ["fields"] = {}, ["inventory"] = {} }, ["param2"] = 0, ["y"] = 2, ["param1"] = 44, ["z"] = 16, ["name"] = "lottother:dirt" },
{["x"] = 4, ["meta"] = { ["fields"] = {}, ["inventory"] = {} }, ["param2"] = 0, ["y"] = 2, ["param1"] = 60, ["z"] = 17, ["name"] = "lottother:dirt" },
{["x"] = 4, ["meta"] = { ["fields"] = {}, ["inventory"] = {} }, ["param2"] = 0, ["y"] = 2, ["param1"] = 43, ["z"] = 18, ["name"] = "lottother:dirt" },
{["x"] = 4, ["meta"] = { ["fields"] = {}, ["inventory"] = {} }, ["param2"] = 0, ["y"] = 2, ["param1"] = 28, ["z"] = 19, ["name"] = "lottother:dirt" },
{["x"] = 4, ["meta"] = { ["fields"] = {}, ["inventory"] = {} }, ["param2"] = 0, ["y"] = 2, ["param1"] = 45, ["z"] = 20, ["name"] = "lottother:dirt" },
{["x"] = 4, ["meta"] = { ["fields"] = {}, ["inventory"] = {} }, ["param2"] = 0, ["y"] = 2, ["param1"] = 0, ["z"] = 21, ["name"] = "lord_ground:dirt_shire" },
{["x"] = 4, ["meta"] = { ["fields"] = {}, ["inventory"] = {} }, ["param2"] = 0, ["y"] = 3, ["param1"] = 0, ["z"] = 3, ["name"] = "default:dirt" },
{["x"] = 4, ["meta"] = { ["fields"] = {}, ["inventory"] = {} }, ["param2"] = 0, ["y"] = 3, ["param1"] = 0, ["z"] = 4, ["name"] = "default:dirt" },
{["x"] = 4, ["meta"] = { ["fields"] = {}, ["inventory"] = {} }, ["param2"] = 0, ["y"] = 3, ["param1"] = 0, ["z"] = 5, ["name"] = "default:dirt" },
{["x"] = 4, ["meta"] = { ["fields"] = {}, ["inventory"] = {} }, ["param2"] = 0, ["y"] = 3, ["param1"] = 0, ["z"] = 6, ["name"] = "default:dirt" },
{["x"] = 4, ["meta"] = { ["fields"] = {}, ["inventory"] = {} }, ["param2"] = 0, ["y"] = 3, ["param1"] = 0, ["z"] = 7, ["name"] = "default:dirt" },
{["x"] = 4, ["meta"] = { ["fields"] = {}, ["inventory"] = {} }, ["param2"] = 0, ["y"] = 3, ["param1"] = 0, ["z"] = 8, ["name"] = "default:dirt" },
{["x"] = 4, ["meta"] = { ["fields"] = {}, ["inventory"] = {} }, ["param2"] = 0, ["y"] = 3, ["param1"] = 0, ["z"] = 9, ["name"] = "default:dirt" },
{["x"] = 4, ["meta"] = { ["fields"] = {}, ["inventory"] = {} }, ["param2"] = 0, ["y"] = 3, ["param1"] = 0, ["z"] = 10, ["name"] = "default:dirt" },
{["x"] = 4, ["meta"] = { ["fields"] = {}, ["inventory"] = {} }, ["param2"] = 0, ["y"] = 3, ["param1"] = 0, ["z"] = 11, ["name"] = "default:dirt" },
{["x"] = 4, ["meta"] = { ["fields"] = {}, ["inventory"] = {} }, ["param2"] = 0, ["y"] = 3, ["param1"] = 0, ["z"] = 12, ["name"] = "default:dirt" },
{["x"] = 4, ["meta"] = { ["fields"] = {}, ["inventory"] = {} }, ["param2"] = 0, ["y"] = 3, ["param1"] = 0, ["z"] = 13, ["name"] = "default:dirt" },
{["x"] = 4, ["meta"] = { ["fields"] = {}, ["inventory"] = {} }, ["param2"] = 0, ["y"] = 3, ["param1"] = 0, ["z"] = 14, ["name"] = "default:dirt" },
{["x"] = 4, ["meta"] = { ["fields"] = {}, ["inventory"] = {} }, ["param2"] = 0, ["y"] = 3, ["param1"] = 0, ["z"] = 15, ["name"] = "default:dirt" },
{["x"] = 4, ["meta"] = { ["fields"] = {}, ["inventory"] = {} }, ["param2"] = 0, ["y"] = 3, ["param1"] = 0, ["z"] = 16, ["name"] = "default:dirt" },
{["x"] = 4, ["meta"] = { ["fields"] = {}, ["inventory"] = {} }, ["param2"] = 0, ["y"] = 3, ["param1"] = 0, ["z"] = 17, ["name"] = "default:dirt" },
{["x"] = 4, ["meta"] = { ["fields"] = {}, ["inventory"] = {} }, ["param2"] = 0, ["y"] = 3, ["param1"] = 0, ["z"] = 18, ["name"] = "default:dirt" },
{["x"] = 4, ["meta"] = { ["fields"] = {}, ["inventory"] = {} }, ["param2"] = 0, ["y"] = 3, ["param1"] = 0, ["z"] = 19, ["name"] = "default:dirt" },
{["x"] = 4, ["meta"] = { ["fields"] = {}, ["inventory"] = {} }, ["param2"] = 0, ["y"] = 3, ["param1"] = 0, ["z"] = 20, ["name"] = "default:dirt" },
{["x"] = 4, ["meta"] = { ["fields"] = {}, ["inventory"] = {} }, ["param2"] = 0, ["y"] = 4, ["param1"] = 0, ["z"] = 3, ["name"] = "default:dirt" },
{["x"] = 4, ["meta"] = { ["fields"] = {}, ["inventory"] = {} }, ["param2"] = 0, ["y"] = 4, ["param1"] = 0, ["z"] = 4, ["name"] = "default:dirt" },
{["x"] = 4, ["meta"] = { ["fields"] = {}, ["inventory"] = {} }, ["param2"] = 0, ["y"] = 4, ["param1"] = 0, ["z"] = 5, ["name"] = "default:junglewood" },
{["x"] = 4, ["meta"] = { ["fields"] = {}, ["inventory"] = {} }, ["param2"] = 0, ["y"] = 4, ["param1"] = 0, ["z"] = 6, ["name"] = "default:junglewood" },
{["x"] = 4, ["meta"] = { ["fields"] = {}, ["inventory"] = {} }, ["param2"] = 0, ["y"] = 4, ["param1"] = 0, ["z"] = 7, ["name"] = "default:junglewood" },
{["x"] = 4, ["meta"] = { ["fields"] = {}, ["inventory"] = {} }, ["param2"] = 0, ["y"] = 4, ["param1"] = 0, ["z"] = 8, ["name"] = "default:junglewood" },
{["x"] = 4, ["meta"] = { ["fields"] = {}, ["inventory"] = {} }, ["param2"] = 0, ["y"] = 4, ["param1"] = 0, ["z"] = 9, ["name"] = "default:junglewood" },
{["x"] = 4, ["meta"] = { ["fields"] = {}, ["inventory"] = {} }, ["param2"] = 0, ["y"] = 4, ["param1"] = 0, ["z"] = 10, ["name"] = "default:junglewood" },
{["x"] = 4, ["meta"] = { ["fields"] = {}, ["inventory"] = {} }, ["param2"] = 0, ["y"] = 4, ["param1"] = 0, ["z"] = 11, ["name"] = "default:junglewood" },
{["x"] = 4, ["meta"] = { ["fields"] = {}, ["inventory"] = {} }, ["param2"] = 0, ["y"] = 4, ["param1"] = 0, ["z"] = 12, ["name"] = "default:junglewood" },
{["x"] = 4, ["meta"] = { ["fields"] = {}, ["inventory"] = {} }, ["param2"] = 0, ["y"] = 4, ["param1"] = 0, ["z"] = 13, ["name"] = "default:junglewood" },
{["x"] = 4, ["meta"] = { ["fields"] = {}, ["inventory"] = {} }, ["param2"] = 0, ["y"] = 4, ["param1"] = 0, ["z"] = 14, ["name"] = "default:sandstone" },
{["x"] = 4, ["meta"] = { ["fields"] = {}, ["inventory"] = {} }, ["param2"] = 0, ["y"] = 4, ["param1"] = 0, ["z"] = 15, ["name"] = "default:sandstone" },
{["x"] = 4, ["meta"] = { ["fields"] = {}, ["inventory"] = {} }, ["param2"] = 0, ["y"] = 4, ["param1"] = 0, ["z"] = 16, ["name"] = "default:sandstone" },
{["x"] = 4, ["meta"] = { ["fields"] = {}, ["inventory"] = {} }, ["param2"] = 0, ["y"] = 4, ["param1"] = 0, ["z"] = 17, ["name"] = "default:sandstone" },
{["x"] = 4, ["meta"] = { ["fields"] = {}, ["inventory"] = {} }, ["param2"] = 0, ["y"] = 4, ["param1"] = 0, ["z"] = 18, ["name"] = "default:sandstone" },
{["x"] = 4, ["meta"] = { ["fields"] = {}, ["inventory"] = {} }, ["param2"] = 0, ["y"] = 4, ["param1"] = 0, ["z"] = 19, ["name"] = "default:dirt" },
{["x"] = 4, ["meta"] = { ["fields"] = {}, ["inventory"] = {} }, ["param2"] = 0, ["y"] = 4, ["param1"] = 0, ["z"] = 20, ["name"] = "default:dirt" },
{["x"] = 4, ["meta"] = { ["fields"] = {}, ["inventory"] = {} }, ["param2"] = 0, ["y"] = 5, ["param1"] = 0, ["z"] = 3, ["name"] = "lord_ground:dirt_shire" },
{["x"] = 4, ["meta"] = { ["fields"] = {}, ["inventory"] = {} }, ["param2"] = 0, ["y"] = 5, ["param1"] = 0, ["z"] = 4, ["name"] = "default:dirt" },
{["x"] = 4, ["meta"] = { ["fields"] = {}, ["inventory"] = {} }, ["param2"] = 0, ["y"] = 5, ["param1"] = 0, ["z"] = 5, ["name"] = "default:junglewood" },
{["x"] = 4, ["meta"] = { ["fields"] = {}, ["inventory"] = {} }, ["param2"] = 0, ["y"] = 5, ["param1"] = 0, ["z"] = 6, ["name"] = "default:junglewood" },
{["x"] = 4, ["meta"] = { ["fields"] = {}, ["inventory"] = {} }, ["param2"] = 0, ["y"] = 5, ["param1"] = 0, ["z"] = 7, ["name"] = "default:junglewood" },
{["x"] = 4, ["meta"] = { ["fields"] = {}, ["inventory"] = {} }, ["param2"] = 0, ["y"] = 5, ["param1"] = 156, ["z"] = 8, ["name"] = "default:glass" },
{["x"] = 4, ["meta"] = { ["fields"] = {}, ["inventory"] = {} }, ["param2"] = 0, ["y"] = 5, ["param1"] = 0, ["z"] = 9, ["name"] = "default:junglewood" },
{["x"] = 4, ["meta"] = { ["fields"] = {}, ["inventory"] = {} }, ["param2"] = 0, ["y"] = 5, ["param1"] = 0, ["z"] = 10, ["name"] = "default:junglewood" },
{["x"] = 4, ["meta"] = { ["fields"] = {}, ["inventory"] = {} }, ["param2"] = 0, ["y"] = 5, ["param1"] = 156, ["z"] = 11, ["name"] = "default:glass" },
{["x"] = 4, ["meta"] = { ["fields"] = {}, ["inventory"] = {} }, ["param2"] = 0, ["y"] = 5, ["param1"] = 0, ["z"] = 12, ["name"] = "default:junglewood" },
{["x"] = 4, ["meta"] = { ["fields"] = {}, ["inventory"] = {} }, ["param2"] = 0, ["y"] = 5, ["param1"] = 0, ["z"] = 13, ["name"] = "default:junglewood" },
{["x"] = 4, ["meta"] = { ["fields"] = {}, ["inventory"] = {} }, ["param2"] = 0, ["y"] = 5, ["param1"] = 0, ["z"] = 14, ["name"] = "default:sandstone" },
{["x"] = 4, ["meta"] = { ["fields"] = {}, ["inventory"] = {} }, ["param2"] = 0, ["y"] = 5, ["param1"] = 0, ["z"] = 15, ["name"] = "default:sandstone" },
{["x"] = 4, ["meta"] = { ["fields"] = {}, ["inventory"] = {} }, ["param2"] = 0, ["y"] = 5, ["param1"] = 156, ["z"] = 16, ["name"] = "default:glass" },
{["x"] = 4, ["meta"] = { ["fields"] = {}, ["inventory"] = {} }, ["param2"] = 0, ["y"] = 5, ["param1"] = 172, ["z"] = 17, ["name"] = "default:glass" },
{["x"] = 4, ["meta"] = { ["fields"] = {}, ["inventory"] = {} }, ["param2"] = 0, ["y"] = 5, ["param1"] = 0, ["z"] = 18, ["name"] = "default:sandstone" },
{["x"] = 4, ["meta"] = { ["fields"] = {}, ["inventory"] = {} }, ["param2"] = 0, ["y"] = 5, ["param1"] = 0, ["z"] = 19, ["name"] = "default:dirt" },
{["x"] = 4, ["meta"] = { ["fields"] = {}, ["inventory"] = {} }, ["param2"] = 0, ["y"] = 5, ["param1"] = 0, ["z"] = 20, ["name"] = "lord_ground:dirt_shire" },
{["x"] = 4, ["meta"] = { ["fields"] = {}, ["inventory"] = {} }, ["param2"] = 0, ["y"] = 6, ["param1"] = 0, ["z"] = 4, ["name"] = "lord_ground:dirt_shire" },
{["x"] = 4, ["meta"] = { ["fields"] = {}, ["inventory"] = {} }, ["param2"] = 0, ["y"] = 6, ["param1"] = 0, ["z"] = 5, ["name"] = "default:junglewood" },
{["x"] = 4, ["meta"] = { ["fields"] = {}, ["inventory"] = {} }, ["param2"] = 0, ["y"] = 6, ["param1"] = 0, ["z"] = 6, ["name"] = "default:junglewood" },
{["x"] = 4, ["meta"] = { ["fields"] = {}, ["inventory"] = {} }, ["param2"] = 0, ["y"] = 6, ["param1"] = 0, ["z"] = 7, ["name"] = "default:junglewood" },
{["x"] = 4, ["meta"] = { ["fields"] = {}, ["inventory"] = {} }, ["param2"] = 0, ["y"] = 6, ["param1"] = 172, ["z"] = 8, ["name"] = "default:glass" },
{["x"] = 4, ["meta"] = { ["fields"] = {}, ["inventory"] = {} }, ["param2"] = 0, ["y"] = 6, ["param1"] = 0, ["z"] = 9, ["name"] = "default:junglewood" },
{["x"] = 4, ["meta"] = { ["fields"] = {}, ["inventory"] = {} }, ["param2"] = 0, ["y"] = 6, ["param1"] = 0, ["z"] = 10, ["name"] = "default:junglewood" },
{["x"] = 4, ["meta"] = { ["fields"] = {}, ["inventory"] = {} }, ["param2"] = 0, ["y"] = 6, ["param1"] = 172, ["z"] = 11, ["name"] = "default:glass" },
{["x"] = 4, ["meta"] = { ["fields"] = {}, ["inventory"] = {} }, ["param2"] = 0, ["y"] = 6, ["param1"] = 0, ["z"] = 12, ["name"] = "default:junglewood" },
{["x"] = 4, ["meta"] = { ["fields"] = {}, ["inventory"] = {} }, ["param2"] = 0, ["y"] = 6, ["param1"] = 0, ["z"] = 13, ["name"] = "default:junglewood" },
{["x"] = 4, ["meta"] = { ["fields"] = {}, ["inventory"] = {} }, ["param2"] = 0, ["y"] = 6, ["param1"] = 0, ["z"] = 14, ["name"] = "default:sandstone" },
{["x"] = 4, ["meta"] = { ["fields"] = {}, ["inventory"] = {} }, ["param2"] = 0, ["y"] = 6, ["param1"] = 0, ["z"] = 15, ["name"] = "default:sandstone" },
{["x"] = 4, ["meta"] = { ["fields"] = {}, ["inventory"] = {} }, ["param2"] = 0, ["y"] = 6, ["param1"] = 172, ["z"] = 16, ["name"] = "default:glass" },
{["x"] = 4, ["meta"] = { ["fields"] = {}, ["inventory"] = {} }, ["param2"] = 0, ["y"] = 6, ["param1"] = 188, ["z"] = 17, ["name"] = "default:glass" },
{["x"] = 4, ["meta"] = { ["fields"] = {}, ["inventory"] = {} }, ["param2"] = 0, ["y"] = 6, ["param1"] = 0, ["z"] = 18, ["name"] = "default:sandstone" },
{["x"] = 4, ["meta"] = { ["fields"] = {}, ["inventory"] = {} }, ["param2"] = 0, ["y"] = 6, ["param1"] = 0, ["z"] = 19, ["name"] = "default:brick" },
{["x"] = 4, ["meta"] = { ["fields"] = {}, ["inventory"] = {} }, ["param2"] = 0, ["y"] = 7, ["param1"] = 0, ["z"] = 5, ["name"] = "default:dirt" },
{["x"] = 4, ["meta"] = { ["fields"] = {}, ["inventory"] = {} }, ["param2"] = 0, ["y"] = 7, ["param1"] = 0, ["z"] = 6, ["name"] = "default:dirt" },
{["x"] = 4, ["meta"] = { ["fields"] = {}, ["inventory"] = {} }, ["param2"] = 0, ["y"] = 7, ["param1"] = 0, ["z"] = 7, ["name"] = "default:dirt" },
{["x"] = 4, ["meta"] = { ["fields"] = {}, ["inventory"] = {} }, ["param2"] = 0, ["y"] = 7, ["param1"] = 0, ["z"] = 8, ["name"] = "lord_ground:dirt_shire" },
{["x"] = 4, ["meta"] = { ["fields"] = {}, ["inventory"] = {} }, ["param2"] = 0, ["y"] = 7, ["param1"] = 0, ["z"] = 9, ["name"] = "lord_ground:dirt_shire" },
{["x"] = 4, ["meta"] = { ["fields"] = {}, ["inventory"] = {} }, ["param2"] = 0, ["y"] = 7, ["param1"] = 0, ["z"] = 10, ["name"] = "lord_ground:dirt_shire" },
{["x"] = 4, ["meta"] = { ["fields"] = {}, ["inventory"] = {} }, ["param2"] = 0, ["y"] = 7, ["param1"] = 0, ["z"] = 11, ["name"] = "lord_ground:dirt_shire" },
{["x"] = 4, ["meta"] = { ["fields"] = {}, ["inventory"] = {} }, ["param2"] = 0, ["y"] = 7, ["param1"] = 0, ["z"] = 12, ["name"] = "lord_ground:dirt_shire" },
{["x"] = 4, ["meta"] = { ["fields"] = {}, ["inventory"] = {} }, ["param2"] = 0, ["y"] = 7, ["param1"] = 0, ["z"] = 13, ["name"] = "lord_ground:dirt_shire" },
{["x"] = 4, ["meta"] = { ["fields"] = {}, ["inventory"] = {} }, ["param2"] = 0, ["y"] = 7, ["param1"] = 0, ["z"] = 14, ["name"] = "lord_ground:dirt_shire" },
{["x"] = 4, ["meta"] = { ["fields"] = {}, ["inventory"] = {} }, ["param2"] = 0, ["y"] = 7, ["param1"] = 0, ["z"] = 15, ["name"] = "lord_ground:dirt_shire" },
{["x"] = 4, ["meta"] = { ["fields"] = {}, ["inventory"] = {} }, ["param2"] = 0, ["y"] = 7, ["param1"] = 0, ["z"] = 16, ["name"] = "lord_ground:dirt_shire" },
{["x"] = 4, ["meta"] = { ["fields"] = {}, ["inventory"] = {} }, ["param2"] = 0, ["y"] = 7, ["param1"] = 0, ["z"] = 17, ["name"] = "lord_ground:dirt_shire" },
{["x"] = 4, ["meta"] = { ["fields"] = {}, ["inventory"] = {} }, ["param2"] = 0, ["y"] = 7, ["param1"] = 0, ["z"] = 18, ["name"] = "lord_ground:dirt_shire" },
{["x"] = 4, ["meta"] = { ["fields"] = {}, ["inventory"] = {} }, ["param2"] = 0, ["y"] = 7, ["param1"] = 0, ["z"] = 19, ["name"] = "default:brick" },
{["x"] = 4, ["meta"] = { ["fields"] = {}, ["inventory"] = {} }, ["param2"] = 0, ["y"] = 8, ["param1"] = 0, ["z"] = 5, ["name"] = "lord_ground:dirt_shire" },
{["x"] = 4, ["meta"] = { ["fields"] = {}, ["inventory"] = {} }, ["param2"] = 0, ["y"] = 8, ["param1"] = 0, ["z"] = 6, ["name"] = "lord_ground:dirt_shire" },
{["x"] = 4, ["meta"] = { ["fields"] = {}, ["inventory"] = {} }, ["param2"] = 0, ["y"] = 8, ["param1"] = 0, ["z"] = 7, ["name"] = "lord_ground:dirt_shire" },
{["x"] = 4, ["meta"] = { ["fields"] = {}, ["inventory"] = {} }, ["param2"] = 0, ["y"] = 8, ["param1"] = 63, ["z"] = 10, ["name"] = "flowers:tulip" },
{["x"] = 4, ["meta"] = { ["fields"] = {}, ["inventory"] = {} }, ["param2"] = 0, ["y"] = 8, ["param1"] = 77, ["z"] = 11, ["name"] = "default:grass_5" },
{["x"] = 4, ["meta"] = { ["fields"] = {}, ["inventory"] = {} }, ["param2"] = 0, ["y"] = 8, ["param1"] = 47, ["z"] = 13, ["name"] = "flowers:tulip" },
{["x"] = 4, ["meta"] = { ["fields"] = {}, ["inventory"] = {} }, ["param2"] = 0, ["y"] = 8, ["param1"] = 45, ["z"] = 14, ["name"] = "default:grass_5" },
{["x"] = 4, ["meta"] = { ["fields"] = {}, ["inventory"] = {} }, ["param2"] = 0, ["y"] = 8, ["param1"] = 95, ["z"] = 17, ["name"] = "flowers:rose" },
{["x"] = 4, ["meta"] = { ["fields"] = {}, ["inventory"] = {} }, ["param2"] = 0, ["y"] = 9, ["param1"] = 31, ["z"] = 6, ["name"] = "flowers:rose" },
{["x"] = 5, ["meta"] = { ["fields"] = {}, ["inventory"] = {} }, ["param2"] = 0, ["y"] = 0, ["param1"] = 13, ["z"] = 1, ["name"] = "lottother:dirt" },
{["x"] = 5, ["meta"] = { ["fields"] = {}, ["inventory"] = {} }, ["param2"] = 0, ["y"] = 0, ["param1"] = 12, ["z"] = 2, ["name"] = "lottother:dirt" },
{["x"] = 5, ["meta"] = { ["fields"] = {}, ["inventory"] = {} }, ["param2"] = 0, ["y"] = 0, ["param1"] = 11, ["z"] = 3, ["name"] = "lottother:dirt" },
{["x"] = 5, ["meta"] = { ["fields"] = {}, ["inventory"] = {} }, ["param2"] = 0, ["y"] = 0, ["param1"] = 10, ["z"] = 4, ["name"] = "lottother:dirt" },
{["x"] = 5, ["meta"] = { ["fields"] = {}, ["inventory"] = {} }, ["param2"] = 0, ["y"] = 0, ["param1"] = 9, ["z"] = 5, ["name"] = "lottother:dirt" },
{["x"] = 5, ["meta"] = { ["fields"] = {}, ["inventory"] = {} }, ["param2"] = 0, ["y"] = 0, ["param1"] = 8, ["z"] = 6, ["name"] = "lottother:dirt" },
{["x"] = 5, ["meta"] = { ["fields"] = {}, ["inventory"] = {} }, ["param2"] = 0, ["y"] = 0, ["param1"] = 8, ["z"] = 7, ["name"] = "lottother:dirt" },
{["x"] = 5, ["meta"] = { ["fields"] = {}, ["inventory"] = {} }, ["param2"] = 0, ["y"] = 0, ["param1"] = 8, ["z"] = 8, ["name"] = "lottother:dirt" },
{["x"] = 5, ["meta"] = { ["fields"] = {}, ["inventory"] = {} }, ["param2"] = 0, ["y"] = 0, ["param1"] = 8, ["z"] = 9, ["name"] = "lottother:dirt" },
{["x"] = 5, ["meta"] = { ["fields"] = {}, ["inventory"] = {} }, ["param2"] = 0, ["y"] = 0, ["param1"] = 8, ["z"] = 10, ["name"] = "lottother:dirt" },
{["x"] = 5, ["meta"] = { ["fields"] = {}, ["inventory"] = {} }, ["param2"] = 0, ["y"] = 0, ["param1"] = 8, ["z"] = 11, ["name"] = "lottother:dirt" },
{["x"] = 5, ["meta"] = { ["fields"] = {}, ["inventory"] = {} }, ["param2"] = 0, ["y"] = 0, ["param1"] = 8, ["z"] = 12, ["name"] = "lottother:dirt" },
{["x"] = 5, ["meta"] = { ["fields"] = {}, ["inventory"] = {} }, ["param2"] = 0, ["y"] = 0, ["param1"] = 8, ["z"] = 13, ["name"] = "lottother:dirt" },
{["x"] = 5, ["meta"] = { ["fields"] = {}, ["inventory"] = {} }, ["param2"] = 0, ["y"] = 0, ["param1"] = 8, ["z"] = 14, ["name"] = "lottother:dirt" },
{["x"] = 5, ["meta"] = { ["fields"] = {}, ["inventory"] = {} }, ["param2"] = 0, ["y"] = 0, ["param1"] = 8, ["z"] = 15, ["name"] = "lottother:dirt" },
{["x"] = 5, ["meta"] = { ["fields"] = {}, ["inventory"] = {} }, ["param2"] = 0, ["y"] = 0, ["param1"] = 8, ["z"] = 16, ["name"] = "lottother:dirt" },
{["x"] = 5, ["meta"] = { ["fields"] = {}, ["inventory"] = {} }, ["param2"] = 0, ["y"] = 0, ["param1"] = 8, ["z"] = 17, ["name"] = "lottother:dirt" },
{["x"] = 5, ["meta"] = { ["fields"] = {}, ["inventory"] = {} }, ["param2"] = 0, ["y"] = 0, ["param1"] = 9, ["z"] = 18, ["name"] = "lottother:dirt" },
{["x"] = 5, ["meta"] = { ["fields"] = {}, ["inventory"] = {} }, ["param2"] = 0, ["y"] = 0, ["param1"] = 10, ["z"] = 19, ["name"] = "lottother:dirt" },
{["x"] = 5, ["meta"] = { ["fields"] = {}, ["inventory"] = {} }, ["param2"] = 0, ["y"] = 0, ["param1"] = 11, ["z"] = 20, ["name"] = "lottother:dirt" },
{["x"] = 5, ["meta"] = { ["fields"] = {}, ["inventory"] = {} }, ["param2"] = 0, ["y"] = 0, ["param1"] = 12, ["z"] = 21, ["name"] = "lottother:dirt" },
{["x"] = 5, ["meta"] = { ["fields"] = {}, ["inventory"] = {} }, ["param2"] = 0, ["y"] = 0, ["param1"] = 13, ["z"] = 22, ["name"] = "lottother:dirt" },
{["x"] = 5, ["meta"] = { ["fields"] = {}, ["inventory"] = {} }, ["param2"] = 0, ["y"] = 1, ["param1"] = 0, ["z"] = 1, ["name"] = "lord_ground:dirt_shire" },
{["x"] = 5, ["meta"] = { ["fields"] = {}, ["inventory"] = {} }, ["param2"] = 0, ["y"] = 1, ["param1"] = 0, ["z"] = 2, ["name"] = "lottother:dirt" },
{["x"] = 5, ["meta"] = { ["fields"] = {}, ["inventory"] = {} }, ["param2"] = 0, ["y"] = 1, ["param1"] = 12, ["z"] = 3, ["name"] = "lottother:dirt" },
{["x"] = 5, ["meta"] = { ["fields"] = {}, ["inventory"] = {} }, ["param2"] = 0, ["y"] = 1, ["param1"] = 11, ["z"] = 4, ["name"] = "lottother:dirt" },
{["x"] = 5, ["meta"] = { ["fields"] = {}, ["inventory"] = {} }, ["param2"] = 0, ["y"] = 1, ["param1"] = 10, ["z"] = 5, ["name"] = "lottother:dirt" },
{["x"] = 5, ["meta"] = { ["fields"] = {}, ["inventory"] = {} }, ["param2"] = 0, ["y"] = 1, ["param1"] = 9, ["z"] = 6, ["name"] = "lottother:dirt" },
{["x"] = 5, ["meta"] = { ["fields"] = {}, ["inventory"] = {} }, ["param2"] = 0, ["y"] = 1, ["param1"] = 9, ["z"] = 7, ["name"] = "lottother:dirt" },
{["x"] = 5, ["meta"] = { ["fields"] = {}, ["inventory"] = {} }, ["param2"] = 0, ["y"] = 1, ["param1"] = 9, ["z"] = 8, ["name"] = "lottother:dirt" },
{["x"] = 5, ["meta"] = { ["fields"] = {}, ["inventory"] = {} }, ["param2"] = 0, ["y"] = 1, ["param1"] = 10, ["z"] = 9, ["name"] = "lottother:dirt" },
{["x"] = 5, ["meta"] = { ["fields"] = {}, ["inventory"] = {} }, ["param2"] = 0, ["y"] = 1, ["param1"] = 10, ["z"] = 10, ["name"] = "lottother:dirt" },
{["x"] = 5, ["meta"] = { ["fields"] = {}, ["inventory"] = {} }, ["param2"] = 0, ["y"] = 1, ["param1"] = 9, ["z"] = 11, ["name"] = "lottother:dirt" },
{["x"] = 5, ["meta"] = { ["fields"] = {}, ["inventory"] = {} }, ["param2"] = 0, ["y"] = 1, ["param1"] = 9, ["z"] = 12, ["name"] = "lottother:dirt" },
{["x"] = 5, ["meta"] = { ["fields"] = {}, ["inventory"] = {} }, ["param2"] = 0, ["y"] = 1, ["param1"] = 9, ["z"] = 13, ["name"] = "lottother:dirt" },
{["x"] = 5, ["meta"] = { ["fields"] = {}, ["inventory"] = {} }, ["param2"] = 0, ["y"] = 1, ["param1"] = 9, ["z"] = 14, ["name"] = "lottother:dirt" },
{["x"] = 5, ["meta"] = { ["fields"] = {}, ["inventory"] = {} }, ["param2"] = 0, ["y"] = 1, ["param1"] = 9, ["z"] = 15, ["name"] = "lottother:dirt" },
{["x"] = 5, ["meta"] = { ["fields"] = {}, ["inventory"] = {} }, ["param2"] = 0, ["y"] = 1, ["param1"] = 9, ["z"] = 16, ["name"] = "lottother:dirt" },
{["x"] = 5, ["meta"] = { ["fields"] = {}, ["inventory"] = {} }, ["param2"] = 0, ["y"] = 1, ["param1"] = 9, ["z"] = 17, ["name"] = "lottother:dirt" },
{["x"] = 5, ["meta"] = { ["fields"] = {}, ["inventory"] = {} }, ["param2"] = 0, ["y"] = 1, ["param1"] = 10, ["z"] = 18, ["name"] = "lottother:dirt" },
{["x"] = 5, ["meta"] = { ["fields"] = {}, ["inventory"] = {} }, ["param2"] = 0, ["y"] = 1, ["param1"] = 11, ["z"] = 19, ["name"] = "lottother:dirt" },
{["x"] = 5, ["meta"] = { ["fields"] = {}, ["inventory"] = {} }, ["param2"] = 0, ["y"] = 1, ["param1"] = 12, ["z"] = 20, ["name"] = "lottother:dirt" },
{["x"] = 5, ["meta"] = { ["fields"] = {}, ["inventory"] = {} }, ["param2"] = 0, ["y"] = 1, ["param1"] = 29, ["z"] = 21, ["name"] = "lottother:dirt" },
{["x"] = 5, ["meta"] = { ["fields"] = {}, ["inventory"] = {} }, ["param2"] = 0, ["y"] = 1, ["param1"] = 0, ["z"] = 22, ["name"] = "lord_ground:dirt_shire" },
{["x"] = 5, ["meta"] = { ["fields"] = {}, ["inventory"] = {} }, ["param2"] = 0, ["y"] = 2, ["param1"] = 0, ["z"] = 2, ["name"] = "lord_ground:dirt_shire" },
{["x"] = 5, ["meta"] = { ["fields"] = {}, ["inventory"] = {} }, ["param2"] = 0, ["y"] = 2, ["param1"] = 13, ["z"] = 3, ["name"] = "lottother:dirt" },
{["x"] = 5, ["meta"] = { ["fields"] = {}, ["inventory"] = {} }, ["param2"] = 0, ["y"] = 2, ["param1"] = 12, ["z"] = 4, ["name"] = "lottother:dirt" },
{["x"] = 5, ["meta"] = { ["fields"] = {}, ["inventory"] = {} }, ["param2"] = 0, ["y"] = 2, ["param1"] = 11, ["z"] = 5, ["name"] = "lottother:dirt" },
{["x"] = 5, ["meta"] = { ["fields"] = {}, ["inventory"] = {} }, ["param2"] = 0, ["y"] = 2, ["param1"] = 10, ["z"] = 6, ["name"] = "lottother:dirt" },
{["x"] = 5, ["meta"] = { ["fields"] = {}, ["inventory"] = {} }, ["param2"] = 0, ["y"] = 2, ["param1"] = 10, ["z"] = 7, ["name"] = "lottother:dirt" },
{["x"] = 5, ["meta"] = { ["fields"] = {}, ["inventory"] = {} }, ["param2"] = 0, ["y"] = 2, ["param1"] = 27, ["z"] = 8, ["name"] = "lottother:dirt" },
{["x"] = 5, ["meta"] = { ["fields"] = {}, ["inventory"] = {} }, ["param2"] = 0, ["y"] = 2, ["param1"] = 11, ["z"] = 9, ["name"] = "lottother:dirt" },
{["x"] = 5, ["meta"] = { ["fields"] = {}, ["inventory"] = {} }, ["param2"] = 0, ["y"] = 2, ["param1"] = 11, ["z"] = 10, ["name"] = "lottother:dirt" },
{["x"] = 5, ["meta"] = { ["fields"] = {}, ["inventory"] = {} }, ["param2"] = 0, ["y"] = 2, ["param1"] = 27, ["z"] = 11, ["name"] = "lottother:dirt" },
{["x"] = 5, ["meta"] = { ["fields"] = {}, ["inventory"] = {} }, ["param2"] = 0, ["y"] = 2, ["param1"] = 10, ["z"] = 12, ["name"] = "lottother:dirt" },
{["x"] = 5, ["meta"] = { ["fields"] = {}, ["inventory"] = {} }, ["param2"] = 0, ["y"] = 2, ["param1"] = 10, ["z"] = 13, ["name"] = "lottother:dirt" },
{["x"] = 5, ["meta"] = { ["fields"] = {}, ["inventory"] = {} }, ["param2"] = 0, ["y"] = 2, ["param1"] = 10, ["z"] = 14, ["name"] = "lottother:dirt" },
{["x"] = 5, ["meta"] = { ["fields"] = {}, ["inventory"] = {} }, ["param2"] = 0, ["y"] = 2, ["param1"] = 10, ["z"] = 15, ["name"] = "lottother:dirt" },
{["x"] = 5, ["meta"] = { ["fields"] = {}, ["inventory"] = {} }, ["param2"] = 0, ["y"] = 2, ["param1"] = 27, ["z"] = 16, ["name"] = "lottother:dirt" },
{["x"] = 5, ["meta"] = { ["fields"] = {}, ["inventory"] = {} }, ["param2"] = 0, ["y"] = 2, ["param1"] = 43, ["z"] = 17, ["name"] = "lottother:dirt" },
{["x"] = 5, ["meta"] = { ["fields"] = {}, ["inventory"] = {} }, ["param2"] = 0, ["y"] = 2, ["param1"] = 27, ["z"] = 18, ["name"] = "lottother:dirt" },
{["x"] = 5, ["meta"] = { ["fields"] = {}, ["inventory"] = {} }, ["param2"] = 0, ["y"] = 2, ["param1"] = 44, ["z"] = 19, ["name"] = "lottother:dirt" },
{["x"] = 5, ["meta"] = { ["fields"] = {}, ["inventory"] = {} }, ["param2"] = 0, ["y"] = 2, ["param1"] = 61, ["z"] = 20, ["name"] = "lottother:dirt" },
{["x"] = 5, ["meta"] = { ["fields"] = {}, ["inventory"] = {} }, ["param2"] = 0, ["y"] = 2, ["param1"] = 0, ["z"] = 21, ["name"] = "lord_ground:dirt_shire" },
{["x"] = 5, ["meta"] = { ["fields"] = {}, ["inventory"] = {} }, ["param2"] = 0, ["y"] = 3, ["param1"] = 0, ["z"] = 3, ["name"] = "default:dirt" },
{["x"] = 5, ["meta"] = { ["fields"] = {}, ["inventory"] = {} }, ["param2"] = 0, ["y"] = 3, ["param1"] = 0, ["z"] = 4, ["name"] = "default:dirt" },
{["x"] = 5, ["meta"] = { ["fields"] = {}, ["inventory"] = {} }, ["param2"] = 0, ["y"] = 3, ["param1"] = 0, ["z"] = 5, ["name"] = "default:dirt" },
{["x"] = 5, ["meta"] = { ["fields"] = {}, ["inventory"] = {} }, ["param2"] = 0, ["y"] = 3, ["param1"] = 0, ["z"] = 6, ["name"] = "default:desert_stonebrick" },
{["x"] = 5, ["meta"] = { ["fields"] = {}, ["inventory"] = {} }, ["param2"] = 0, ["y"] = 3, ["param1"] = 0, ["z"] = 7, ["name"] = "wool:blue" },
{["x"] = 5, ["meta"] = { ["fields"] = {}, ["inventory"] = {} }, ["param2"] = 0, ["y"] = 3, ["param1"] = 0, ["z"] = 8, ["name"] = "wool:blue" },
{["x"] = 5, ["meta"] = { ["fields"] = {}, ["inventory"] = {} }, ["param2"] = 0, ["y"] = 3, ["param1"] = 0, ["z"] = 9, ["name"] = "wool:blue" },
{["x"] = 5, ["meta"] = { ["fields"] = {}, ["inventory"] = {} }, ["param2"] = 0, ["y"] = 3, ["param1"] = 0, ["z"] = 10, ["name"] = "wool:blue" },
{["x"] = 5, ["meta"] = { ["fields"] = {}, ["inventory"] = {} }, ["param2"] = 0, ["y"] = 3, ["param1"] = 0, ["z"] = 11, ["name"] = "wool:blue" },
{["x"] = 5, ["meta"] = { ["fields"] = {}, ["inventory"] = {} }, ["param2"] = 0, ["y"] = 3, ["param1"] = 0, ["z"] = 12, ["name"] = "wool:blue" },
{["x"] = 5, ["meta"] = { ["fields"] = {}, ["inventory"] = {} }, ["param2"] = 0, ["y"] = 3, ["param1"] = 0, ["z"] = 13, ["name"] = "default:dirt" },
{["x"] = 5, ["meta"] = { ["fields"] = {}, ["inventory"] = {} }, ["param2"] = 0, ["y"] = 3, ["param1"] = 0, ["z"] = 14, ["name"] = "default:dirt" },
{["x"] = 5, ["meta"] = { ["fields"] = {}, ["inventory"] = {} }, ["param2"] = 0, ["y"] = 3, ["param1"] = 0, ["z"] = 15, ["name"] = "wool:dark_green" },
{["x"] = 5, ["meta"] = { ["fields"] = {}, ["inventory"] = {} }, ["param2"] = 0, ["y"] = 3, ["param1"] = 0, ["z"] = 16, ["name"] = "wool:dark_green" },
{["x"] = 5, ["meta"] = { ["fields"] = {}, ["inventory"] = {} }, ["param2"] = 0, ["y"] = 3, ["param1"] = 0, ["z"] = 17, ["name"] = "wool:dark_green" },
{["x"] = 5, ["meta"] = { ["fields"] = {}, ["inventory"] = {} }, ["param2"] = 0, ["y"] = 3, ["param1"] = 0, ["z"] = 18, ["name"] = "default:dirt" },
{["x"] = 5, ["meta"] = { ["fields"] = {}, ["inventory"] = {} }, ["param2"] = 0, ["y"] = 3, ["param1"] = 0, ["z"] = 19, ["name"] = "default:dirt" },
{["x"] = 5, ["meta"] = { ["fields"] = {}, ["inventory"] = {} }, ["param2"] = 0, ["y"] = 3, ["param1"] = 0, ["z"] = 20, ["name"] = "default:dirt" },
{["x"] = 5, ["meta"] = { ["fields"] = {}, ["inventory"] = {} }, ["param2"] = 0, ["y"] = 4, ["param1"] = 0, ["z"] = 3, ["name"] = "default:dirt" },
{["x"] = 5, ["meta"] = { ["fields"] = {}, ["inventory"] = {} }, ["param2"] = 0, ["y"] = 4, ["param1"] = 0, ["z"] = 4, ["name"] = "default:dirt" },
{["x"] = 5, ["meta"] = { ["fields"] = {}, ["inventory"] = {} }, ["param2"] = 0, ["y"] = 4, ["param1"] = 0, ["z"] = 5, ["name"] = "default:desert_stonebrick" },
{["x"] = 5, ["meta"] = { ["fields"] = {}, ["inventory"] = {} }, ["param2"] = 0, ["y"] = 4, ["param1"] = 187, ["z"] = 6, ["name"] = "lottother:air" },
{["x"] = 5, ["meta"] = { ["fields"] = {}, ["inventory"] = {} }, ["param2"] = 0, ["y"] = 4, ["param1"] = 170, ["z"] = 7, ["name"] = "lottother:air" },
{["x"] = 5, ["meta"] = { ["fields"] = {}, ["inventory"] = {} }, ["param2"] = 0, ["y"] = 4, ["param1"] = 154, ["z"] = 8, ["name"] = "lottother:air" },
{["x"] = 5, ["meta"] = { ["fields"] = {}, ["inventory"] = {} }, ["param2"] = 0, ["y"] = 4, ["param1"] = 153, ["z"] = 9, ["name"] = "lottother:air" },
{["x"] = 5, ["meta"] = { ["fields"] = {}, ["inventory"] = {} }, ["param2"] = 0, ["y"] = 4, ["param1"] = 137, ["z"] = 10, ["name"] = "lottother:air" },
{["x"] = 5, ["meta"] = { ["fields"] = {}, ["inventory"] = {} }, ["param2"] = 0, ["y"] = 4, ["param1"] = 154, ["z"] = 11, ["name"] = "lottother:air" },
{["x"] = 5, ["meta"] = { ["fields"] = {}, ["inventory"] = {} }, ["param2"] = 0, ["y"] = 4, ["param1"] = 170, ["z"] = 12, ["name"] = "lottother:air" },
{["x"] = 5, ["meta"] = { ["fields"] = {}, ["inventory"] = {} }, ["param2"] = 0, ["y"] = 4, ["param1"] = 0, ["z"] = 13, ["name"] = "default:junglewood" },
{["x"] = 5, ["meta"] = { ["fields"] = {}, ["inventory"] = {} }, ["param2"] = 0, ["y"] = 4, ["param1"] = 0, ["z"] = 14, ["name"] = "default:sandstone" },
{["x"] = 5, ["meta"] = { ["fields"] = {}, ["inventory"] = {} }, ["param2"] = 3, ["y"] = 4, ["param1"] = 137, ["z"] = 15, ["name"] = "lottother:air" },
{["x"] = 5, ["meta"] = { ["fields"] = {}, ["inventory"] = {} }, ["param2"] = 0, ["y"] = 4, ["param1"] = 154, ["z"] = 16, ["name"] = "beds:bed_bottom" },
{["x"] = 5, ["meta"] = { ["fields"] = {}, ["inventory"] = {} }, ["param2"] = 0, ["y"] = 4, ["param1"] = 170, ["z"] = 17, ["name"] = "beds:bed_top" },
{["x"] = 5, ["meta"] = { ["fields"] = {}, ["inventory"] = {} }, ["param2"] = 0, ["y"] = 4, ["param1"] = 0, ["z"] = 18, ["name"] = "default:wood" },
{["x"] = 5, ["meta"] = { ["fields"] = {}, ["inventory"] = {} }, ["param2"] = 0, ["y"] = 4, ["param1"] = 0, ["z"] = 19, ["name"] = "default:dirt" },
{["x"] = 5, ["meta"] = { ["fields"] = {}, ["inventory"] = {} }, ["param2"] = 0, ["y"] = 4, ["param1"] = 0, ["z"] = 20, ["name"] = "default:dirt" },
{["x"] = 5, ["meta"] = { ["fields"] = {}, ["inventory"] = {} }, ["param2"] = 0, ["y"] = 5, ["param1"] = 0, ["z"] = 3, ["name"] = "lord_ground:dirt_shire" },
{["x"] = 5, ["meta"] = { ["fields"] = {}, ["inventory"] = {} }, ["param2"] = 0, ["y"] = 5, ["param1"] = 0, ["z"] = 4, ["name"] = "default:dirt" },
{["x"] = 5, ["meta"] = { ["fields"] = {}, ["inventory"] = {} }, ["param2"] = 0, ["y"] = 5, ["param1"] = 0, ["z"] = 5, ["name"] = "default:desert_stonebrick" },
{["x"] = 5, ["meta"] = { ["fields"] = {}, ["inventory"] = {} }, ["param2"] = 0, ["y"] = 5, ["param1"] = 204, ["z"] = 6, ["name"] = "lottother:air" },
{["x"] = 5, ["meta"] = { ["fields"] = {}, ["inventory"] = {} }, ["param2"] = 0, ["y"] = 5, ["param1"] = 187, ["z"] = 7, ["name"] = "lottother:air" },
{["x"] = 5, ["meta"] = { ["fields"] = {}, ["inventory"] = {} }, ["param2"] = 0, ["y"] = 5, ["param1"] = 171, ["z"] = 8, ["name"] = "lottother:air" },
{["x"] = 5, ["meta"] = { ["fields"] = {}, ["inventory"] = {} }, ["param2"] = 0, ["y"] = 5, ["param1"] = 170, ["z"] = 9, ["name"] = "lottother:air" },
{["x"] = 5, ["meta"] = { ["fields"] = {}, ["inventory"] = {} }, ["param2"] = 0, ["y"] = 5, ["param1"] = 154, ["z"] = 10, ["name"] = "lottother:air" },
{["x"] = 5, ["meta"] = { ["fields"] = {}, ["inventory"] = {} }, ["param2"] = 0, ["y"] = 5, ["param1"] = 171, ["z"] = 11, ["name"] = "lottother:air" },
{["x"] = 5, ["meta"] = { ["fields"] = {}, ["inventory"] = {} }, ["param2"] = 0, ["y"] = 5, ["param1"] = 187, ["z"] = 12, ["name"] = "lottother:air" },
{["x"] = 5, ["meta"] = { ["fields"] = {}, ["inventory"] = {} }, ["param2"] = 0, ["y"] = 5, ["param1"] = 0, ["z"] = 13, ["name"] = "default:junglewood" },
{["x"] = 5, ["meta"] = { ["fields"] = {}, ["inventory"] = {} }, ["param2"] = 0, ["y"] = 5, ["param1"] = 0, ["z"] = 14, ["name"] = "default:sandstone" },
{["x"] = 5, ["meta"] = { ["fields"] = {}, ["inventory"] = {} }, ["param2"] = 0, ["y"] = 5, ["param1"] = 154, ["z"] = 15, ["name"] = "lottother:air" },
{["x"] = 5, ["meta"] = { ["fields"] = {}, ["inventory"] = {} }, ["param2"] = 0, ["y"] = 5, ["param1"] = 171, ["z"] = 16, ["name"] = "lottother:air" },
{["x"] = 5, ["meta"] = { ["fields"] = {}, ["inventory"] = {} }, ["param2"] = 0, ["y"] = 5, ["param1"] = 187, ["z"] = 17, ["name"] = "lottother:air" },
{["x"] = 5, ["meta"] = { ["fields"] = {}, ["inventory"] = {} }, ["param2"] = 0, ["y"] = 5, ["param1"] = 0, ["z"] = 18, ["name"] = "default:wood" },
{["x"] = 5, ["meta"] = { ["fields"] = {}, ["inventory"] = {} }, ["param2"] = 0, ["y"] = 5, ["param1"] = 0, ["z"] = 19, ["name"] = "lord_ground:dirt_shire" },
{["x"] = 5, ["meta"] = { ["fields"] = {}, ["inventory"] = {} }, ["param2"] = 0, ["y"] = 5, ["param1"] = 0, ["z"] = 20, ["name"] = "lord_ground:dirt_shire" },
{["x"] = 5, ["meta"] = { ["fields"] = {}, ["inventory"] = {} }, ["param2"] = 0, ["y"] = 6, ["param1"] = 15, ["z"] = 3, ["name"] = "flowers:tulip" },
{["x"] = 5, ["meta"] = { ["fields"] = {}, ["inventory"] = {} }, ["param2"] = 0, ["y"] = 6, ["param1"] = 0, ["z"] = 4, ["name"] = "lord_ground:dirt_shire" },
{["x"] = 5, ["meta"] = { ["fields"] = {}, ["inventory"] = {} }, ["param2"] = 0, ["y"] = 6, ["param1"] = 0, ["z"] = 5, ["name"] = "default:desert_stonebrick" },
{["x"] = 5, ["meta"] = { ["fields"] = {}, ["inventory"] = {} }, ["param2"] = 5, ["y"] = 6, ["param1"] = 0, ["z"] = 6, ["name"] = "default:torch" },
{["x"] = 5, ["meta"] = { ["fields"] = {}, ["inventory"] = {} }, ["param2"] = 0, ["y"] = 6, ["param1"] = 204, ["z"] = 7, ["name"] = "lottother:air" },
{["x"] = 5, ["meta"] = { ["fields"] = {}, ["inventory"] = {} }, ["param2"] = 0, ["y"] = 6, ["param1"] = 187, ["z"] = 8, ["name"] = "lottother:air" },
{["x"] = 5, ["meta"] = { ["fields"] = {}, ["inventory"] = {} }, ["param2"] = 0, ["y"] = 6, ["param1"] = 187, ["z"] = 9, ["name"] = "lottother:air" },
{["x"] = 5, ["meta"] = { ["fields"] = {}, ["inventory"] = {} }, ["param2"] = 0, ["y"] = 6, ["param1"] = 170, ["z"] = 10, ["name"] = "lottother:air" },
{["x"] = 5, ["meta"] = { ["fields"] = {}, ["inventory"] = {} }, ["param2"] = 0, ["y"] = 6, ["param1"] = 187, ["z"] = 11, ["name"] = "lottother:air" },
{["x"] = 5, ["meta"] = { ["fields"] = {}, ["inventory"] = {} }, ["param2"] = 0, ["y"] = 6, ["param1"] = 204, ["z"] = 12, ["name"] = "lottother:air" },
{["x"] = 5, ["meta"] = { ["fields"] = {}, ["inventory"] = {} }, ["param2"] = 0, ["y"] = 6, ["param1"] = 0, ["z"] = 13, ["name"] = "default:junglewood" },
{["x"] = 5, ["meta"] = { ["fields"] = {}, ["inventory"] = {} }, ["param2"] = 0, ["y"] = 6, ["param1"] = 0, ["z"] = 14, ["name"] = "default:sandstone" },
{["x"] = 5, ["meta"] = { ["fields"] = {}, ["inventory"] = {} }, ["param2"] = 0, ["y"] = 6, ["param1"] = 170, ["z"] = 15, ["name"] = "lottother:air" },
{["x"] = 5, ["meta"] = { ["fields"] = {}, ["inventory"] = {} }, ["param2"] = 0, ["y"] = 6, ["param1"] = 187, ["z"] = 16, ["name"] = "lottother:air" },
{["x"] = 5, ["meta"] = { ["fields"] = {}, ["inventory"] = {} }, ["param2"] = 0, ["y"] = 6, ["param1"] = 204, ["z"] = 17, ["name"] = "lottother:air" },
{["x"] = 5, ["meta"] = { ["fields"] = {}, ["inventory"] = {} }, ["param2"] = 0, ["y"] = 6, ["param1"] = 188, ["z"] = 18, ["name"] = "default:glass" },
{["x"] = 5, ["meta"] = { ["fields"] = {}, ["inventory"] = {} }, ["param2"] = 0, ["y"] = 6, ["param1"] = 159, ["z"] = 20, ["name"] = "flowers:rose" },
{["x"] = 5, ["meta"] = { ["fields"] = {}, ["inventory"] = {} }, ["param2"] = 0, ["y"] = 7, ["param1"] = 15, ["z"] = 4, ["name"] = "flowers:tulip" },
{["x"] = 5, ["meta"] = { ["fields"] = {}, ["inventory"] = {} }, ["param2"] = 0, ["y"] = 7, ["param1"] = 0, ["z"] = 5, ["name"] = "default:dirt" },
{["x"] = 5, ["meta"] = { ["fields"] = {}, ["inventory"] = {} }, ["param2"] = 0, ["y"] = 7, ["param1"] = 0, ["z"] = 6, ["name"] = "default:brick" },
{["x"] = 5, ["meta"] = { ["fields"] = {}, ["inventory"] = {} }, ["param2"] = 0, ["y"] = 7, ["param1"] = 0, ["z"] = 7, ["name"] = "default:brick" },
{["x"] = 5, ["meta"] = { ["fields"] = {}, ["inventory"] = {} }, ["param2"] = 0, ["y"] = 7, ["param1"] = 0, ["z"] = 8, ["name"] = "default:brick" },
{["x"] = 5, ["meta"] = { ["fields"] = {}, ["inventory"] = {} }, ["param2"] = 0, ["y"] = 7, ["param1"] = 0, ["z"] = 9, ["name"] = "default:brick" },
{["x"] = 5, ["meta"] = { ["fields"] = {}, ["inventory"] = {} }, ["param2"] = 0, ["y"] = 7, ["param1"] = 0, ["z"] = 10, ["name"] = "default:brick" },
{["x"] = 5, ["meta"] = { ["fields"] = {}, ["inventory"] = {} }, ["param2"] = 0, ["y"] = 7, ["param1"] = 0, ["z"] = 11, ["name"] = "default:brick" },
{["x"] = 5, ["meta"] = { ["fields"] = {}, ["inventory"] = {} }, ["param2"] = 0, ["y"] = 7, ["param1"] = 0, ["z"] = 12, ["name"] = "default:brick" },
{["x"] = 5, ["meta"] = { ["fields"] = {}, ["inventory"] = {} }, ["param2"] = 0, ["y"] = 7, ["param1"] = 0, ["z"] = 13, ["name"] = "default:dirt" },
{["x"] = 5, ["meta"] = { ["fields"] = {}, ["inventory"] = {} }, ["param2"] = 0, ["y"] = 7, ["param1"] = 0, ["z"] = 14, ["name"] = "default:dirt" },
{["x"] = 5, ["meta"] = { ["fields"] = {}, ["inventory"] = {} }, ["param2"] = 0, ["y"] = 7, ["param1"] = 0, ["z"] = 15, ["name"] = "default:sandstonebrick" },
{["x"] = 5, ["meta"] = { ["fields"] = {}, ["inventory"] = {} }, ["param2"] = 0, ["y"] = 7, ["param1"] = 0, ["z"] = 16, ["name"] = "default:sandstonebrick" },
{["x"] = 5, ["meta"] = { ["fields"] = {}, ["inventory"] = {} }, ["param2"] = 0, ["y"] = 7, ["param1"] = 0, ["z"] = 17, ["name"] = "default:sandstonebrick" },
{["x"] = 5, ["meta"] = { ["fields"] = {}, ["inventory"] = {} }, ["param2"] = 0, ["y"] = 7, ["param1"] = 0, ["z"] = 18, ["name"] = "default:dirt" },
{["x"] = 5, ["meta"] = { ["fields"] = {}, ["inventory"] = {} }, ["param2"] = 0, ["y"] = 7, ["param1"] = 0, ["z"] = 19, ["name"] = "default:brick" },
{["x"] = 5, ["meta"] = { ["fields"] = {}, ["inventory"] = {} }, ["param2"] = 0, ["y"] = 8, ["param1"] = 0, ["z"] = 5, ["name"] = "lord_ground:dirt_shire" },
{["x"] = 5, ["meta"] = { ["fields"] = {}, ["inventory"] = {} }, ["param2"] = 0, ["y"] = 8, ["param1"] = 0, ["z"] = 6, ["name"] = "lord_ground:dirt_shire" },
{["x"] = 5, ["meta"] = { ["fields"] = {}, ["inventory"] = {} }, ["param2"] = 0, ["y"] = 8, ["param1"] = 0, ["z"] = 7, ["name"] = "lord_ground:dirt_shire" },
{["x"] = 5, ["meta"] = { ["fields"] = {}, ["inventory"] = {} }, ["param2"] = 0, ["y"] = 8, ["param1"] = 0, ["z"] = 8, ["name"] = "lord_ground:dirt_shire" },
{["x"] = 5, ["meta"] = { ["fields"] = {}, ["inventory"] = {} }, ["param2"] = 0, ["y"] = 8, ["param1"] = 0, ["z"] = 9, ["name"] = "lord_ground:dirt_shire" },
