5:return {
{["x"] = 0, ["meta"] = {["fields"] = {}, ["inventory"] = {}}, ["y"] = 49, ["param1"] = 13, ["z"] = 11, ["name"] = "lord_trees:mallorn_leaf"},
{["x"] = 0, ["meta"] = {["fields"] = {}, ["inventory"] = {}}, ["y"] = 51, ["param1"] = 13, ["z"] = 10, ["name"] = "lord_trees:mallorn_leaf"},
{["x"] = 0, ["meta"] = {["fields"] = {}, ["inventory"] = {}}, ["y"] = 51, ["param1"] = 13, ["z"] = 11, ["name"] = "lord_trees:mallorn_leaf"},
{["x"] = 1, ["meta"] = {["fields"] = {}, ["inventory"] = {}}, ["y"] = 49, ["param1"] = 12, ["z"] = 11, ["name"] = "lord_trees:mallorn_leaf"},
{["x"] = 1, ["meta"] = {["fields"] = {}, ["inventory"] = {}}, ["y"] = 50, ["param1"] = 13, ["z"] = 8, ["name"] = "lord_trees:mallorn_leaf"},
{["x"] = 1, ["meta"] = {["fields"] = {}, ["inventory"] = {}}, ["y"] = 50, ["param1"] = 12, ["z"] = 10, ["name"] = "lord_trees:mallorn_leaf"},
{["x"] = 1, ["meta"] = {["fields"] = {}, ["inventory"] = {}}, ["y"] = 50, ["param1"] = 12, ["z"] = 11, ["name"] = "lord_trees:mallorn_leaf"},
{["x"] = 1, ["meta"] = {["fields"] = {}, ["inventory"] = {}}, ["y"] = 51, ["param1"] = 13, ["z"] = 7, ["name"] = "lord_trees:mallorn_leaf"},
{["x"] = 1, ["meta"] = {["fields"] = {}, ["inventory"] = {}}, ["y"] = 51, ["param1"] = 13, ["z"] = 8, ["name"] = "lord_trees:mallorn_leaf"},
{["x"] = 1, ["meta"] = {["fields"] = {}, ["inventory"] = {}}, ["y"] = 51, ["param1"] = 13, ["z"] = 9, ["name"] = "lord_trees:mallorn_leaf"},
{["x"] = 1, ["meta"] = {["fields"] = {}, ["inventory"] = {}}, ["y"] = 51, ["param1"] = 13, ["z"] = 10, ["name"] = "lord_trees:mallorn_leaf"},
{["x"] = 1, ["meta"] = {["fields"] = {}, ["inventory"] = {}}, ["y"] = 51, ["param1"] = 12, ["z"] = 11, ["name"] = "lord_trees:mallorn_leaf"},
{["x"] = 1, ["meta"] = {["fields"] = {}, ["inventory"] = {}}, ["y"] = 51, ["param1"] = 13, ["z"] = 12, ["name"] = "lord_trees:mallorn_leaf"},
{["x"] = 1, ["meta"] = {["fields"] = {}, ["inventory"] = {}}, ["y"] = 52, ["param1"] = 13, ["z"] = 11, ["name"] = "lord_trees:mallorn_leaf"},
{["x"] = 2, ["meta"] = {["fields"] = {}, ["inventory"] = {}}, ["y"] = 49, ["param1"] = 12, ["z"] = 9, ["name"] = "lord_trees:mallorn_leaf"},
{["x"] = 2, ["meta"] = {["fields"] = {}, ["inventory"] = {}}, ["y"] = 49, ["param1"] = 11, ["z"] = 10, ["name"] = "lord_trees:mallorn_leaf"},
{["x"] = 2, ["meta"] = {["fields"] = {}, ["inventory"] = {}}, ["y"] = 49, ["param1"] = 11, ["z"] = 11, ["name"] = "lord_trees:mallorn_leaf"},
{["x"] = 2, ["meta"] = {["fields"] = {}, ["inventory"] = {}}, ["y"] = 50, ["param1"] = 13, ["z"] = 6, ["name"] = "lord_trees:mallorn_leaf"},
{["x"] = 2, ["meta"] = {["fields"] = {}, ["inventory"] = {}}, ["y"] = 50, ["param1"] = 12, ["z"] = 7, ["name"] = "lord_trees:mallorn_leaf"},
{["x"] = 2, ["meta"] = {["fields"] = {}, ["inventory"] = {}}, ["y"] = 50, ["param1"] = 12, ["z"] = 8, ["name"] = "lord_trees:mallorn_leaf"},
{["x"] = 2, ["meta"] = {["fields"] = {}, ["inventory"] = {}}, ["y"] = 50, ["param1"] = 12, ["z"] = 9, ["name"] = "lord_trees:mallorn_leaf"},
{["x"] = 2, ["meta"] = {["fields"] = {}, ["inventory"] = {}}, ["y"] = 50, ["param1"] = 11, ["z"] = 10, ["name"] = "lord_trees:mallorn_leaf"},
{["x"] = 2, ["meta"] = {["fields"] = {}, ["inventory"] = {}}, ["y"] = 50, ["param1"] = 11, ["z"] = 11, ["name"] = "lord_trees:mallorn_leaf"},
{["x"] = 2, ["meta"] = {["fields"] = {}, ["inventory"] = {}}, ["y"] = 50, ["param1"] = 12, ["z"] = 12, ["name"] = "lord_trees:mallorn_leaf"},
{["x"] = 2, ["meta"] = {["fields"] = {}, ["inventory"] = {}}, ["y"] = 51, ["param1"] = 13, ["z"] = 6, ["name"] = "lord_trees:mallorn_leaf"},
{["x"] = 2, ["meta"] = {["fields"] = {}, ["inventory"] = {}}, ["y"] = 51, ["param1"] = 12, ["z"] = 7, ["name"] = "lord_trees:mallorn_leaf"},
{["x"] = 2, ["meta"] = {["fields"] = {}, ["inventory"] = {}}, ["y"] = 51, ["param1"] = 13, ["z"] = 8, ["name"] = "lord_trees:mallorn_leaf"},
{["x"] = 2, ["meta"] = {["fields"] = {}, ["inventory"] = {}}, ["y"] = 51, ["param1"] = 12, ["z"] = 9, ["name"] = "lord_trees:mallorn_leaf"},
{["x"] = 2, ["meta"] = {["fields"] = {}, ["inventory"] = {}}, ["y"] = 51, ["param1"] = 12, ["z"] = 10, ["name"] = "lord_trees:mallorn_leaf"},
{["x"] = 2, ["meta"] = {["fields"] = {}, ["inventory"] = {}}, ["param2"] = 1, ["y"] = 51, ["z"] = 11, ["name"] = "lord_trees:mallorn_tree"},
{["x"] = 2, ["meta"] = {["fields"] = {}, ["inventory"] = {}}, ["y"] = 51, ["param1"] = 12, ["z"] = 12, ["name"] = "lord_trees:mallorn_leaf"},
{["x"] = 2, ["meta"] = {["fields"] = {}, ["inventory"] = {}}, ["y"] = 51, ["param1"] = 13, ["z"] = 13, ["name"] = "lord_trees:mallorn_leaf"},
{["x"] = 2, ["meta"] = {["fields"] = {}, ["inventory"] = {}}, ["y"] = 52, ["param1"] = 13, ["z"] = 9, ["name"] = "lord_trees:mallorn_leaf"},
{["x"] = 2, ["meta"] = {["fields"] = {}, ["inventory"] = {}}, ["y"] = 52, ["param1"] = 13, ["z"] = 10, ["name"] = "lord_trees:mallorn_leaf"},
{["x"] = 2, ["meta"] = {["fields"] = {}, ["inventory"] = {}}, ["y"] = 52, ["param1"] = 13, ["z"] = 11, ["name"] = "lord_trees:mallorn_leaf"},
{["x"] = 2, ["meta"] = {["fields"] = {}, ["inventory"] = {}}, ["y"] = 52, ["param1"] = 13, ["z"] = 12, ["name"] = "lord_trees:mallorn_leaf"},
{["x"] = 2, ["meta"] = {["fields"] = {}, ["inventory"] = {}}, ["y"] = 53, ["param1"] = 13, ["z"] = 4, ["name"] = "lord_trees:mallorn_leaf"},
{["x"] = 2, ["meta"] = {["fields"] = {}, ["inventory"] = {}}, ["y"] = 53, ["param1"] = 13, ["z"] = 5, ["name"] = "lord_trees:mallorn_leaf"},
{["x"] = 2, ["meta"] = {["fields"] = {}, ["inventory"] = {}}, ["y"] = 53, ["param1"] = 13, ["z"] = 6, ["name"] = "lord_trees:mallorn_leaf"},
{["x"] = 2, ["meta"] = {["fields"] = {}, ["inventory"] = {}}, ["y"] = 53, ["param1"] = 13, ["z"] = 7, ["name"] = "lord_trees:mallorn_leaf"},
{["x"] = 2, ["meta"] = {["fields"] = {}, ["inventory"] = {}}, ["y"] = 53, ["param1"] = 13, ["z"] = 10, ["name"] = "lord_trees:mallorn_leaf"},
{["x"] = 3, ["meta"] = {["fields"] = {}, ["inventory"] = {}}, ["y"] = 12, ["param1"] = 123, ["z"] = 12, ["name"] = "lord_trees:mallorn_leaf"},
{["x"] = 3, ["meta"] = {["fields"] = {}, ["inventory"] = {}}, ["y"] = 13, ["param1"] = 122, ["z"] = 11, ["name"] = "lord_trees:mallorn_leaf"},
{["x"] = 3, ["meta"] = {["fields"] = {}, ["inventory"] = {}}, ["y"] = 13, ["param1"] = 139, ["z"] = 12, ["name"] = "lord_trees:mallorn_leaf"},
{["x"] = 3, ["meta"] = {["fields"] = {}, ["inventory"] = {}}, ["y"] = 25, ["param1"] = 75, ["z"] = 8, ["name"] = "lord_trees:mallorn_leaf"},
{["x"] = 3, ["meta"] = {["fields"] = {}, ["inventory"] = {}}, ["y"] = 25, ["param1"] = 106, ["z"] = 11, ["name"] = "lord_trees:mallorn_leaf"},
{["x"] = 3, ["meta"] = {["fields"] = {}, ["inventory"] = {}}, ["y"] = 25, ["param1"] = 91, ["z"] = 12, ["name"] = "lord_trees:mallorn_leaf"},
{["x"] = 3, ["meta"] = {["fields"] = {}, ["inventory"] = {}}, ["y"] = 26, ["param1"] = 92, ["z"] = 6, ["name"] = "lord_trees:mallorn_leaf"},
{["x"] = 3, ["meta"] = {["fields"] = {}, ["inventory"] = {}}, ["y"] = 26, ["param1"] = 91, ["z"] = 8, ["name"] = "lord_trees:mallorn_leaf"},
{["x"] = 3, ["meta"] = {["fields"] = {}, ["inventory"] = {}}, ["y"] = 26, ["param1"] = 107, ["z"] = 9, ["name"] = "lord_trees:mallorn_leaf"},
{["x"] = 3, ["meta"] = {["fields"] = {}, ["inventory"] = {}}, ["y"] = 49, ["param1"] = 11, ["z"] = 7, ["name"] = "lord_trees:mallorn_leaf"},
{["x"] = 3, ["meta"] = {["fields"] = {}, ["inventory"] = {}}, ["y"] = 49, ["param1"] = 11, ["z"] = 8, ["name"] = "lord_trees:mallorn_leaf"},
{["x"] = 3, ["meta"] = {["fields"] = {}, ["inventory"] = {}}, ["y"] = 49, ["param1"] = 27, ["z"] = 9, ["name"] = "lord_trees:mallorn_leaf"},
{["x"] = 3, ["meta"] = {["fields"] = {}, ["inventory"] = {}}, ["y"] = 49, ["param1"] = 11, ["z"] = 10, ["name"] = "lord_trees:mallorn_leaf"},
{["x"] = 3, ["meta"] = {["fields"] = {}, ["inventory"] = {}}, ["y"] = 49, ["param1"] = 26, ["z"] = 11, ["name"] = "lord_trees:mallorn_leaf"},
{["x"] = 3, ["meta"] = {["fields"] = {}, ["inventory"] = {}}, ["y"] = 49, ["param1"] = 11, ["z"] = 12, ["name"] = "lord_trees:mallorn_leaf"},
{["x"] = 3, ["meta"] = {["fields"] = {}, ["inventory"] = {}}, ["y"] = 50, ["param1"] = 11, ["z"] = 8, ["name"] = "lord_trees:mallorn_leaf"},
{["x"] = 3, ["meta"] = {["fields"] = {}, ["inventory"] = {}}, ["y"] = 50, ["param1"] = 12, ["z"] = 10, ["name"] = "lord_trees:mallorn_leaf"},
{["x"] = 3, ["meta"] = {["fields"] = {}, ["inventory"] = {}}, ["y"] = 50, ["param1"] = 11, ["z"] = 11, ["name"] = "lord_trees:mallorn_leaf"},
{["x"] = 3, ["meta"] = {["fields"] = {}, ["inventory"] = {}}, ["y"] = 50, ["param1"] = 12, ["z"] = 12, ["name"] = "lord_trees:mallorn_leaf"},
{["x"] = 3, ["meta"] = {["fields"] = {}, ["inventory"] = {}}, ["y"] = 51, ["param1"] = 13, ["z"] = 5, ["name"] = "lord_trees:mallorn_leaf"},
{["x"] = 3, ["meta"] = {["fields"] = {}, ["inventory"] = {}}, ["y"] = 51, ["param1"] = 13, ["z"] = 6, ["name"] = "lord_trees:mallorn_leaf"},
{["x"] = 3, ["meta"] = {["fields"] = {}, ["inventory"] = {}}, ["y"] = 51, ["param1"] = 12, ["z"] = 7, ["name"] = "lord_trees:mallorn_leaf"},
{["x"] = 3, ["meta"] = {["fields"] = {}, ["inventory"] = {}}, ["param2"] = 3, ["y"] = 51, ["z"] = 8, ["name"] = "lord_trees:mallorn_tree"},
{["x"] = 3, ["meta"] = {["fields"] = {}, ["inventory"] = {}}, ["y"] = 51, ["param1"] = 13, ["z"] = 9, ["name"] = "lord_trees:mallorn_leaf"},
{["x"] = 3, ["meta"] = {["fields"] = {}, ["inventory"] = {}}, ["y"] = 51, ["param1"] = 13, ["z"] = 10, ["name"] = "lord_trees:mallorn_leaf"},
{["x"] = 3, ["meta"] = {["fields"] = {}, ["inventory"] = {}}, ["param2"] = 1, ["y"] = 51, ["z"] = 11, ["name"] = "lord_trees:mallorn_tree"},
{["x"] = 3, ["meta"] = {["fields"] = {}, ["inventory"] = {}}, ["y"] = 51, ["param1"] = 13, ["z"] = 12, ["name"] = "lord_trees:mallorn_leaf"},
{["x"] = 3, ["meta"] = {["fields"] = {}, ["inventory"] = {}}, ["y"] = 51, ["param1"] = 13, ["z"] = 13, ["name"] = "lord_trees:mallorn_leaf"},
{["x"] = 3, ["meta"] = {["fields"] = {}, ["inventory"] = {}}, ["y"] = 51, ["param1"] = 13, ["z"] = 14, ["name"] = "lord_trees:mallorn_leaf"},
{["x"] = 3, ["meta"] = {["fields"] = {}, ["inventory"] = {}}, ["y"] = 52, ["param1"] = 13, ["z"] = 3, ["name"] = "lord_trees:mallorn_leaf"},
{["x"] = 3, ["meta"] = {["fields"] = {}, ["inventory"] = {}}, ["y"] = 52, ["param1"] = 13, ["z"] = 4, ["name"] = "lord_trees:mallorn_leaf"},
{["x"] = 3, ["meta"] = {["fields"] = {}, ["inventory"] = {}}, ["y"] = 52, ["param1"] = 13, ["z"] = 8, ["name"] = "lord_trees:mallorn_leaf"},
{["x"] = 3, ["meta"] = {["fields"] = {}, ["inventory"] = {}}, ["y"] = 52, ["param1"] = 13, ["z"] = 11, ["name"] = "lord_trees:mallorn_leaf"},
{["x"] = 3, ["meta"] = {["fields"] = {}, ["inventory"] = {}}, ["y"] = 53, ["param1"] = 13, ["z"] = 7, ["name"] = "lord_trees:mallorn_leaf"},
{["x"] = 4, ["meta"] = {["fields"] = {}, ["inventory"] = {}}, ["y"] = 12, ["param1"] = 138, ["z"] = 12, ["name"] = "lord_trees:mallorn_leaf"},
{["x"] = 4, ["meta"] = {["fields"] = {}, ["inventory"] = {}}, ["y"] = 12, ["param1"] = 123, ["z"] = 13, ["name"] = "lord_trees:mallorn_leaf"},
{["x"] = 4, ["meta"] = {["fields"] = {}, ["inventory"] = {}}, ["y"] = 12, ["param1"] = 108, ["z"] = 14, ["name"] = "lord_trees:mallorn_leaf"},
{["x"] = 4, ["meta"] = {["fields"] = {}, ["inventory"] = {}}, ["y"] = 13, ["param1"] = 121, ["z"] = 10, ["name"] = "lord_trees:mallorn_leaf"},
{["x"] = 4, ["meta"] = {["fields"] = {}, ["inventory"] = {}}, ["y"] = 13, ["param1"] = 137, ["z"] = 11, ["name"] = "lord_trees:mallorn_leaf"},
{["x"] = 4, ["meta"] = {["fields"] = {}, ["inventory"] = {}}, ["y"] = 13, ["param1"] = 154, ["z"] = 12, ["name"] = "lord_trees:mallorn_leaf"},
{["x"] = 4, ["meta"] = {["fields"] = {}, ["inventory"] = {}}, ["y"] = 13, ["param1"] = 139, ["z"] = 13, ["name"] = "lord_trees:mallorn_leaf"},
{["x"] = 4, ["meta"] = {["fields"] = {}, ["inventory"] = {}}, ["y"] = 13, ["param1"] = 124, ["z"] = 14, ["name"] = "lord_trees:mallorn_leaf"},
{["x"] = 4, ["meta"] = {["fields"] = {}, ["inventory"] = {}}, ["y"] = 13, ["param1"] = 109, ["z"] = 15, ["name"] = "lord_trees:mallorn_leaf"},
{["x"] = 4, ["meta"] = {["fields"] = {}, ["inventory"] = {}}, ["y"] = 13, ["param1"] = 93, ["z"] = 16, ["name"] = "lord_trees:mallorn_leaf"},
{["x"] = 4, ["meta"] = {["fields"] = {}, ["inventory"] = {}}, ["y"] = 14, ["param1"] = 137, ["z"] = 10, ["name"] = "lord_trees:mallorn_leaf"},
{["x"] = 4, ["meta"] = {["fields"] = {}, ["inventory"] = {}}, ["y"] = 14, ["param1"] = 153, ["z"] = 11, ["name"] = "lord_trees:mallorn_leaf"},
{["x"] = 4, ["meta"] = {["fields"] = {}, ["inventory"] = {}}, ["y"] = 14, ["param1"] = 170, ["z"] = 12, ["name"] = "lord_trees:mallorn_leaf"},
{["x"] = 4, ["meta"] = {["fields"] = {}, ["inventory"] = {}}, ["y"] = 14, ["param1"] = 155, ["z"] = 13, ["name"] = "lord_trees:mallorn_leaf"},
{["x"] = 4, ["meta"] = {["fields"] = {}, ["inventory"] = {}}, ["y"] = 25, ["param1"] = 106, ["z"] = 7, ["name"] = "lord_trees:mallorn_leaf"},
{["x"] = 4, ["meta"] = {["fields"] = {}, ["inventory"] = {}}, ["y"] = 25, ["param1"] = 90, ["z"] = 8, ["name"] = "lord_trees:mallorn_leaf"},
{["x"] = 4, ["meta"] = {["fields"] = {}, ["inventory"] = {}}, ["y"] = 25, ["param1"] = 121, ["z"] = 11, ["name"] = "lord_trees:mallorn_leaf"},
{["x"] = 4, ["meta"] = {["fields"] = {}, ["inventory"] = {}}, ["y"] = 25, ["param1"] = 106, ["z"] = 12, ["name"] = "lord_trees:mallorn_leaf"},
{["x"] = 4, ["meta"] = {["fields"] = {}, ["inventory"] = {}}, ["y"] = 25, ["param1"] = 107, ["z"] = 13, ["name"] = "lord_trees:mallorn_leaf"},
{["x"] = 4, ["meta"] = {["fields"] = {}, ["inventory"] = {}}, ["y"] = 26, ["param1"] = 107, ["z"] = 6, ["name"] = "lord_trees:mallorn_leaf"},
{["x"] = 4, ["meta"] = {["fields"] = {}, ["inventory"] = {}}, ["y"] = 26, ["param1"] = 122, ["z"] = 7, ["name"] = "lord_trees:mallorn_leaf"},
{["x"] = 4, ["meta"] = {["fields"] = {}, ["inventory"] = {}}, ["y"] = 26, ["param1"] = 106, ["z"] = 8, ["name"] = "lord_trees:mallorn_leaf"},
{["x"] = 4, ["meta"] = {["fields"] = {}, ["inventory"] = {}}, ["y"] = 26, ["param1"] = 122, ["z"] = 9, ["name"] = "lord_trees:mallorn_leaf"},
{["x"] = 4, ["meta"] = {["fields"] = {}, ["inventory"] = {}}, ["y"] = 26, ["param1"] = 123, ["z"] = 13, ["name"] = "lord_trees:mallorn_leaf"},
{["x"] = 4, ["meta"] = {["fields"] = {}, ["inventory"] = {}}, ["y"] = 48, ["param1"] = 41, ["z"] = 10, ["name"] = "lord_trees:mallorn_leaf"},
{["x"] = 4, ["meta"] = {["fields"] = {}, ["inventory"] = {}}, ["y"] = 49, ["param1"] = 10, ["z"] = 7, ["name"] = "lord_trees:mallorn_leaf"},
{["x"] = 4, ["meta"] = {["fields"] = {}, ["inventory"] = {}}, ["y"] = 49, ["param1"] = 26, ["z"] = 10, ["name"] = "lord_trees:mallorn_leaf"},
{["x"] = 4, ["meta"] = {["fields"] = {}, ["inventory"] = {}}, ["y"] = 49, ["param1"] = 42, ["z"] = 11, ["name"] = "lord_trees:mallorn_leaf"},
{["x"] = 4, ["meta"] = {["fields"] = {}, ["inventory"] = {}}, ["y"] = 49, ["param1"] = 27, ["z"] = 12, ["name"] = "lord_trees:mallorn_leaf"},
{["x"] = 4, ["meta"] = {["fields"] = {}, ["inventory"] = {}}, ["y"] = 49, ["param1"] = 11, ["z"] = 13, ["name"] = "lord_trees:mallorn_leaf"},
{["x"] = 4, ["meta"] = {["fields"] = {}, ["inventory"] = {}}, ["y"] = 50, ["param1"] = 11, ["z"] = 6, ["name"] = "lord_trees:mallorn_leaf"},
{["x"] = 4, ["meta"] = {["fields"] = {}, ["inventory"] = {}}, ["y"] = 50, ["param1"] = 11, ["z"] = 7, ["name"] = "lord_trees:mallorn_leaf"},
{["x"] = 4, ["meta"] = {["fields"] = {}, ["inventory"] = {}}, ["y"] = 50, ["param1"] = 10, ["z"] = 8, ["name"] = "lord_trees:mallorn_leaf"},
{["x"] = 4, ["meta"] = {["fields"] = {}, ["inventory"] = {}}, ["y"] = 50, ["param1"] = 27, ["z"] = 9, ["name"] = "lord_trees:mallorn_leaf"},
{["x"] = 4, ["meta"] = {["fields"] = {}, ["inventory"] = {}}, ["y"] = 50, ["param1"] = 11, ["z"] = 10, ["name"] = "lord_trees:mallorn_leaf"},
{["x"] = 4, ["meta"] = {["fields"] = {}, ["inventory"] = {}}, ["y"] = 50, ["param1"] = 27, ["z"] = 11, ["name"] = "lord_trees:mallorn_leaf"},
{["x"] = 4, ["meta"] = {["fields"] = {}, ["inventory"] = {}}, ["y"] = 50, ["param1"] = 12, ["z"] = 13, ["name"] = "lord_trees:mallorn_leaf"},
{["x"] = 4, ["meta"] = {["fields"] = {}, ["inventory"] = {}}, ["y"] = 51, ["param1"] = 12, ["z"] = 4, ["name"] = "lord_trees:mallorn_leaf"},
{["x"] = 4, ["meta"] = {["fields"] = {}, ["inventory"] = {}}, ["y"] = 51, ["param1"] = 12, ["z"] = 5, ["name"] = "lord_trees:mallorn_leaf"},
{["x"] = 4, ["meta"] = {["fields"] = {}, ["inventory"] = {}}, ["y"] = 51, ["param1"] = 12, ["z"] = 6, ["name"] = "lord_trees:mallorn_leaf"},
{["x"] = 4, ["meta"] = {["fields"] = {}, ["inventory"] = {}}, ["y"] = 51, ["param1"] = 12, ["z"] = 7, ["name"] = "lord_trees:mallorn_leaf"},
{["x"] = 4, ["meta"] = {["fields"] = {}, ["inventory"] = {}}, ["param2"] = 3, ["y"] = 51, ["z"] = 8, ["name"] = "lord_trees:mallorn_tree"},
{["x"] = 4, ["meta"] = {["fields"] = {}, ["inventory"] = {}}, ["y"] = 51, ["param1"] = 12, ["z"] = 9, ["name"] = "lord_trees:mallorn_leaf"},
{["x"] = 4, ["meta"] = {["fields"] = {}, ["inventory"] = {}}, ["y"] = 51, ["param1"] = 12, ["z"] = 10, ["name"] = "lord_trees:mallorn_leaf"},
{["x"] = 4, ["meta"] = {["fields"] = {}, ["inventory"] = {}}, ["param2"] = 1, ["y"] = 51, ["z"] = 11, ["name"] = "lord_trees:mallorn_tree"},
{["x"] = 4, ["meta"] = {["fields"] = {}, ["inventory"] = {}}, ["y"] = 51, ["param1"] = 13, ["z"] = 12, ["name"] = "lord_trees:mallorn_leaf"},
{["x"] = 4, ["meta"] = {["fields"] = {}, ["inventory"] = {}}, ["y"] = 51, ["param1"] = 13, ["z"] = 13, ["name"] = "lord_trees:mallorn_leaf"},
{["x"] = 4, ["meta"] = {["fields"] = {}, ["inventory"] = {}}, ["y"] = 51, ["param1"] = 13, ["z"] = 14, ["name"] = "lord_trees:mallorn_leaf"},
{["x"] = 4, ["meta"] = {["fields"] = {}, ["inventory"] = {}}, ["y"] = 51, ["param1"] = 13, ["z"] = 15, ["name"] = "lord_trees:mallorn_leaf"},
{["x"] = 4, ["meta"] = {["fields"] = {}, ["inventory"] = {}}, ["y"] = 52, ["param1"] = 13, ["z"] = 3, ["name"] = "lord_trees:mallorn_leaf"},
{["x"] = 4, ["meta"] = {["fields"] = {}, ["inventory"] = {}}, ["y"] = 52, ["param1"] = 13, ["z"] = 4, ["name"] = "lord_trees:mallorn_leaf"},
{["x"] = 4, ["meta"] = {["fields"] = {}, ["inventory"] = {}}, ["y"] = 52, ["param1"] = 13, ["z"] = 5, ["name"] = "lord_trees:mallorn_leaf"},
{["x"] = 4, ["meta"] = {["fields"] = {}, ["inventory"] = {}}, ["y"] = 52, ["param1"] = 13, ["z"] = 6, ["name"] = "lord_trees:mallorn_leaf"},
{["x"] = 4, ["meta"] = {["fields"] = {}, ["inventory"] = {}}, ["y"] = 52, ["param1"] = 13, ["z"] = 7, ["name"] = "lord_trees:mallorn_leaf"},
{["x"] = 4, ["meta"] = {["fields"] = {}, ["inventory"] = {}}, ["y"] = 52, ["param1"] = 12, ["z"] = 8, ["name"] = "lord_trees:mallorn_leaf"},
{["x"] = 4, ["meta"] = {["fields"] = {}, ["inventory"] = {}}, ["y"] = 52, ["param1"] = 13, ["z"] = 9, ["name"] = "lord_trees:mallorn_leaf"},
{["x"] = 4, ["meta"] = {["fields"] = {}, ["inventory"] = {}}, ["y"] = 52, ["param1"] = 13, ["z"] = 10, ["name"] = "lord_trees:mallorn_leaf"},
{["x"] = 4, ["meta"] = {["fields"] = {}, ["inventory"] = {}}, ["y"] = 52, ["param1"] = 13, ["z"] = 11, ["name"] = "lord_trees:mallorn_leaf"},
{["x"] = 4, ["meta"] = {["fields"] = {}, ["inventory"] = {}}, ["y"] = 53, ["param1"] = 13, ["z"] = 5, ["name"] = "lord_trees:mallorn_leaf"},
{["x"] = 4, ["meta"] = {["fields"] = {}, ["inventory"] = {}}, ["y"] = 53, ["param1"] = 13, ["z"] = 7, ["name"] = "lord_trees:mallorn_leaf"},
{["x"] = 4, ["meta"] = {["fields"] = {}, ["inventory"] = {}}, ["y"] = 53, ["param1"] = 13, ["z"] = 8, ["name"] = "lord_trees:mallorn_leaf"},
{["x"] = 4, ["meta"] = {["fields"] = {}, ["inventory"] = {}}, ["y"] = 53, ["param1"] = 13, ["z"] = 11, ["name"] = "lord_trees:mallorn_leaf"},
{["x"] = 5, ["meta"] = {["fields"] = {}, ["inventory"] = {}}, ["y"] = 0, ["z"] = 5, ["name"] = "lottother:dirt"},
{["x"] = 5, ["meta"] = {["fields"] = {}, ["inventory"] = {}}, ["y"] = 0, ["z"] = 6, ["name"] = "lottother:dirt"},
{["x"] = 5, ["meta"] = {["fields"] = {}, ["inventory"] = {}}, ["y"] = 0, ["z"] = 7, ["name"] = "lottother:dirt"},
{["x"] = 5, ["meta"] = {["fields"] = {}, ["inventory"] = {}}, ["y"] = 0, ["z"] = 8, ["name"] = "lottother:dirt"},
{["x"] = 5, ["meta"] = {["fields"] = {}, ["inventory"] = {}}, ["y"] = 0, ["z"] = 9, ["name"] = "lottother:dirt"},
{["x"] = 5, ["meta"] = {["fields"] = {}, ["inventory"] = {}}, ["y"] = 0, ["z"] = 10, ["name"] = "lottother:dirt"},
{["x"] = 5, ["meta"] = {["fields"] = {}, ["inventory"] = {}}, ["y"] = 0, ["z"] = 11, ["name"] = "lottother:dirt"},
{["x"] = 5, ["meta"] = {["fields"] = {}, ["inventory"] = {}}, ["y"] = 0, ["z"] = 12, ["name"] = "lottother:dirt"},
{["x"] = 5, ["meta"] = {["fields"] = {}, ["inventory"] = {}}, ["y"] = 0, ["z"] = 13, ["name"] = "lottother:dirt"},
{["x"] = 5, ["meta"] = {["fields"] = {}, ["inventory"] = {}}, ["y"] = 0, ["z"] = 14, ["name"] = "lottother:dirt"},
{["x"] = 5, ["meta"] = {["fields"] = {}, ["inventory"] = {}}, ["y"] = 1, ["z"] = 5, ["name"] = "lord_ground:dirt_lorien"},
{["x"] = 5, ["meta"] = {["fields"] = {}, ["inventory"] = {}}, ["y"] = 1, ["z"] = 6, ["name"] = "lord_ground:dirt_lorien"},
{["x"] = 5, ["meta"] = {["fields"] = {}, ["inventory"] = {}}, ["y"] = 1, ["param1"] = 9, ["z"] = 7, ["name"] = "lord_ground:dirt_lorien"},
{["x"] = 5, ["meta"] = {["fields"] = {}, ["inventory"] = {}}, ["y"] = 1, ["param1"] = 10, ["z"] = 8, ["name"] = "lord_ground:dirt_lorien"},
{["x"] = 5, ["meta"] = {["fields"] = {}, ["inventory"] = {}}, ["y"] = 1, ["param1"] = 10, ["z"] = 9, ["name"] = "lord_ground:dirt_lorien"},
{["x"] = 5, ["meta"] = {["fields"] = {}, ["inventory"] = {}}, ["y"] = 1, ["param1"] = 9, ["z"] = 10, ["name"] = "lord_ground:dirt_lorien"},
{["x"] = 5, ["meta"] = {["fields"] = {}, ["inventory"] = {}}, ["y"] = 1, ["param1"] = 9, ["z"] = 11, ["name"] = "lord_ground:dirt_lorien"},
{["x"] = 5, ["meta"] = {["fields"] = {}, ["inventory"] = {}}, ["y"] = 1, ["param1"] = 10, ["z"] = 12, ["name"] = "lord_ground:dirt_lorien"},
{["x"] = 5, ["meta"] = {["fields"] = {}, ["inventory"] = {}}, ["y"] = 1, ["param1"] = 10, ["z"] = 13, ["name"] = "lord_ground:dirt_lorien"},
{["x"] = 5, ["meta"] = {["fields"] = {}, ["inventory"] = {}}, ["y"] = 1, ["param1"] = 11, ["z"] = 14, ["name"] = "lord_ground:dirt_lorien"},
{["x"] = 5, ["meta"] = {["fields"] = {}, ["inventory"] = {}}, ["y"] = 2, ["param1"] = 11, ["z"] = 5, ["name"] = "lottother:air"},
{["x"] = 5, ["meta"] = {["fields"] = {}, ["inventory"] = {}}, ["y"] = 2, ["param1"] = 10, ["z"] = 6, ["name"] = "lottother:air"},
{["x"] = 5, ["meta"] = {["fields"] = {}, ["inventory"] = {}}, ["y"] = 2, ["param1"] = 9, ["z"] = 7, ["name"] = "lottother:air"},
{["x"] = 5, ["meta"] = {["fields"] = {}, ["inventory"] = {}}, ["y"] = 2, ["param1"] = 9, ["z"] = 8, ["name"] = "lottother:air"},
{["x"] = 5, ["meta"] = {["fields"] = {}, ["inventory"] = {}}, ["y"] = 2, ["param1"] = 9, ["z"] = 9, ["name"] = "lottother:air"},
{["x"] = 5, ["meta"] = {["fields"] = {}, ["inventory"] = {}}, ["y"] = 2, ["param1"] = 8, ["z"] = 10, ["name"] = "lottother:air"},
{["x"] = 5, ["meta"] = {["fields"] = {}, ["inventory"] = {}}, ["y"] = 2, ["param1"] = 8, ["z"] = 11, ["name"] = "lottother:air"},
{["x"] = 5, ["meta"] = {["fields"] = {}, ["inventory"] = {}}, ["y"] = 2, ["param1"] = 9, ["z"] = 12, ["name"] = "lottother:air"},
{["x"] = 5, ["meta"] = {["fields"] = {}, ["inventory"] = {}}, ["y"] = 2, ["param1"] = 10, ["z"] = 13, ["name"] = "lottother:air"},
{["x"] = 5, ["meta"] = {["fields"] = {}, ["inventory"] = {}}, ["y"] = 2, ["param1"] = 11, ["z"] = 14, ["name"] = "lottother:air"},
{["x"] = 5, ["meta"] = {["fields"] = {}, ["inventory"] = {}}, ["y"] = 3, ["param1"] = 11, ["z"] = 5, ["name"] = "lottother:air"},
{["x"] = 5, ["meta"] = {["fields"] = {}, ["inventory"] = {}}, ["y"] = 3, ["param1"] = 10, ["z"] = 6, ["name"] = "lottother:air"},
{["x"] = 5, ["meta"] = {["fields"] = {}, ["inventory"] = {}}, ["y"] = 3, ["param1"] = 9, ["z"] = 7, ["name"] = "lottother:air"},
{["x"] = 5, ["meta"] = {["fields"] = {}, ["inventory"] = {}}, ["y"] = 3, ["param1"] = 9, ["z"] = 8, ["name"] = "lottother:air"},
{["x"] = 5, ["meta"] = {["fields"] = {}, ["inventory"] = {}}, ["y"] = 3, ["param1"] = 9, ["z"] = 9, ["name"] = "lottother:air"},
{["x"] = 5, ["meta"] = {["fields"] = {}, ["inventory"] = {}}, ["y"] = 3, ["param1"] = 8, ["z"] = 10, ["name"] = "lottother:air"},
{["x"] = 5, ["meta"] = {["fields"] = {}, ["inventory"] = {}}, ["y"] = 3, ["param1"] = 8, ["z"] = 11, ["name"] = "lottother:air"},
{["x"] = 5, ["meta"] = {["fields"] = {}, ["inventory"] = {}}, ["y"] = 3, ["param1"] = 9, ["z"] = 12, ["name"] = "lottother:air"},
{["x"] = 5, ["meta"] = {["fields"] = {}, ["inventory"] = {}}, ["y"] = 3, ["param1"] = 10, ["z"] = 13, ["name"] = "lottother:air"},
{["x"] = 5, ["meta"] = {["fields"] = {}, ["inventory"] = {}}, ["y"] = 3, ["param1"] = 11, ["z"] = 14, ["name"] = "lottother:air"},
{["x"] = 5, ["meta"] = {["fields"] = {}, ["inventory"] = {}}, ["y"] = 4, ["param1"] = 11, ["z"] = 5, ["name"] = "lottother:air"},
{["x"] = 5, ["meta"] = {["fields"] = {}, ["inventory"] = {}}, ["y"] = 4, ["param1"] = 10, ["z"] = 6, ["name"] = "lottother:air"},
{["x"] = 5, ["meta"] = {["fields"] = {}, ["inventory"] = {}}, ["y"] = 4, ["param1"] = 9, ["z"] = 7, ["name"] = "lottother:air"},
{["x"] = 5, ["meta"] = {["fields"] = {}, ["inventory"] = {}}, ["y"] = 4, ["param1"] = 9, ["z"] = 8, ["name"] = "lottother:air"},
{["x"] = 5, ["meta"] = {["fields"] = {}, ["inventory"] = {}}, ["y"] = 4, ["param1"] = 9, ["z"] = 9, ["name"] = "lottother:air"},
{["x"] = 5, ["meta"] = {["fields"] = {}, ["inventory"] = {}}, ["y"] = 4, ["param1"] = 8, ["z"] = 10, ["name"] = "lottother:air"},
{["x"] = 5, ["meta"] = {["fields"] = {}, ["inventory"] = {}}, ["y"] = 4, ["param1"] = 8, ["z"] = 11, ["name"] = "lottother:air"},
{["x"] = 5, ["meta"] = {["fields"] = {}, ["inventory"] = {}}, ["y"] = 4, ["param1"] = 9, ["z"] = 12, ["name"] = "lottother:air"},
{["x"] = 5, ["meta"] = {["fields"] = {}, ["inventory"] = {}}, ["y"] = 4, ["param1"] = 10, ["z"] = 13, ["name"] = "lottother:air"},
{["x"] = 5, ["meta"] = {["fields"] = {}, ["inventory"] = {}}, ["y"] = 4, ["param1"] = 11, ["z"] = 14, ["name"] = "lottother:air"},
{["x"] = 5, ["meta"] = {["fields"] = {}, ["inventory"] = {}}, ["y"] = 5, ["param1"] = 11, ["z"] = 5, ["name"] = "lottother:air"},
{["x"] = 5, ["meta"] = {["fields"] = {}, ["inventory"] = {}}, ["y"] = 5, ["param1"] = 10, ["z"] = 6, ["name"] = "lottother:air"},
{["x"] = 5, ["meta"] = {["fields"] = {}, ["inventory"] = {}}, ["y"] = 5, ["param1"] = 9, ["z"] = 7, ["name"] = "lottother:air"},
{["x"] = 5, ["meta"] = {["fields"] = {}, ["inventory"] = {}}, ["y"] = 5, ["param1"] = 9, ["z"] = 8, ["name"] = "lottother:air"},
{["x"] = 5, ["meta"] = {["fields"] = {}, ["inventory"] = {}}, ["y"] = 5, ["param1"] = 9, ["z"] = 9, ["name"] = "lottother:air"},
{["x"] = 5, ["meta"] = {["fields"] = {}, ["inventory"] = {}}, ["y"] = 5, ["param1"] = 8, ["z"] = 10, ["name"] = "lottother:air"},
{["x"] = 5, ["meta"] = {["fields"] = {}, ["inventory"] = {}}, ["y"] = 5, ["param1"] = 8, ["z"] = 11, ["name"] = "lottother:air"},
{["x"] = 5, ["meta"] = {["fields"] = {}, ["inventory"] = {}}, ["y"] = 5, ["param1"] = 9, ["z"] = 12, ["name"] = "lottother:air"},
{["x"] = 5, ["meta"] = {["fields"] = {}, ["inventory"] = {}}, ["y"] = 5, ["param1"] = 10, ["z"] = 13, ["name"] = "lottother:air"},
{["x"] = 5, ["meta"] = {["fields"] = {}, ["inventory"] = {}}, ["y"] = 5, ["param1"] = 11, ["z"] = 14, ["name"] = "lottother:air"},
{["x"] = 5, ["meta"] = {["fields"] = {}, ["inventory"] = {}}, ["y"] = 6, ["param1"] = 11, ["z"] = 5, ["name"] = "lottother:air"},
{["x"] = 5, ["meta"] = {["fields"] = {}, ["inventory"] = {}}, ["y"] = 6, ["param1"] = 10, ["z"] = 6, ["name"] = "lottother:air"},
{["x"] = 5, ["meta"] = {["fields"] = {}, ["inventory"] = {}}, ["y"] = 6, ["param1"] = 9, ["z"] = 7, ["name"] = "lottother:air"},
{["x"] = 5, ["meta"] = {["fields"] = {}, ["inventory"] = {}}, ["y"] = 6, ["param1"] = 9, ["z"] = 8, ["name"] = "lottother:air"},
{["x"] = 5, ["meta"] = {["fields"] = {}, ["inventory"] = {}}, ["y"] = 6, ["param1"] = 9, ["z"] = 9, ["name"] = "lottother:air"},
{["x"] = 5, ["meta"] = {["fields"] = {}, ["inventory"] = {}}, ["y"] = 6, ["param1"] = 24, ["z"] = 10, ["name"] = "lottother:air"},
{["x"] = 5, ["meta"] = {["fields"] = {}, ["inventory"] = {}}, ["y"] = 6, ["param1"] = 8, ["z"] = 11, ["name"] = "lottother:air"},
{["x"] = 5, ["meta"] = {["fields"] = {}, ["inventory"] = {}}, ["y"] = 6, ["param1"] = 25, ["z"] = 12, ["name"] = "lottother:air"},
{["x"] = 5, ["meta"] = {["fields"] = {}, ["inventory"] = {}}, ["y"] = 6, ["param1"] = 10, ["z"] = 13, ["name"] = "lottother:air"},
{["x"] = 5, ["meta"] = {["fields"] = {}, ["inventory"] = {}}, ["y"] = 6, ["param1"] = 27, ["z"] = 14, ["name"] = "lottother:air"},
{["x"] = 5, ["meta"] = {["fields"] = {}, ["inventory"] = {}}, ["y"] = 7, ["param1"] = 11, ["z"] = 5, ["name"] = "lottother:air"},
{["x"] = 5, ["meta"] = {["fields"] = {}, ["inventory"] = {}}, ["y"] = 7, ["param1"] = 10, ["z"] = 6, ["name"] = "lottother:air"},
{["x"] = 5, ["meta"] = {["fields"] = {}, ["inventory"] = {}}, ["y"] = 7, ["param1"] = 9, ["z"] = 7, ["name"] = "lottother:air"},
{["x"] = 5, ["meta"] = {["fields"] = {}, ["inventory"] = {}}, ["y"] = 7, ["param1"] = 9, ["z"] = 8, ["name"] = "lottother:air"},
{["x"] = 5, ["meta"] = {["fields"] = {}, ["inventory"] = {}}, ["y"] = 7, ["param1"] = 25, ["z"] = 9, ["name"] = "lottother:air"},
{["x"] = 5, ["meta"] = {["fields"] = {}, ["inventory"] = {}}, ["y"] = 7, ["param1"] = 40, ["z"] = 10, ["name"] = "lottother:air"},
{["x"] = 5, ["meta"] = {["fields"] = {}, ["inventory"] = {}}, ["y"] = 7, ["param1"] = 24, ["z"] = 11, ["name"] = "lottother:air"},
{["x"] = 5, ["meta"] = {["fields"] = {}, ["inventory"] = {}}, ["y"] = 7, ["param1"] = 41, ["z"] = 12, ["name"] = "lottother:air"},
{["x"] = 5, ["meta"] = {["fields"] = {}, ["inventory"] = {}}, ["y"] = 7, ["param1"] = 26, ["z"] = 13, ["name"] = "lottother:air"},
{["x"] = 5, ["meta"] = {["fields"] = {}, ["inventory"] = {}}, ["y"] = 7, ["param1"] = 43, ["z"] = 14, ["name"] = "lottother:air"},
{["x"] = 5, ["meta"] = {["fields"] = {}, ["inventory"] = {}}, ["y"] = 8, ["param1"] = 11, ["z"] = 5, ["name"] = "lottother:air"},
{["x"] = 5, ["meta"] = {["fields"] = {}, ["inventory"] = {}}, ["y"] = 8, ["param1"] = 10, ["z"] = 6, ["name"] = "lottother:air"},
{["x"] = 5, ["meta"] = {["fields"] = {}, ["inventory"] = {}}, ["y"] = 8, ["param1"] = 9, ["z"] = 7, ["name"] = "lottother:air"},
{["x"] = 5, ["meta"] = {["fields"] = {}, ["inventory"] = {}}, ["y"] = 8, ["param1"] = 25, ["z"] = 8, ["name"] = "lottother:air"},
{["x"] = 5, ["meta"] = {["fields"] = {}, ["inventory"] = {}}, ["y"] = 8, ["param1"] = 41, ["z"] = 9, ["name"] = "lottother:air"},
{["x"] = 5, ["meta"] = {["fields"] = {}, ["inventory"] = {}}, ["y"] = 8, ["param1"] = 56, ["z"] = 10, ["name"] = "lottother:air"},
{["x"] = 5, ["meta"] = {["fields"] = {}, ["inventory"] = {}}, ["y"] = 8, ["param1"] = 40, ["z"] = 11, ["name"] = "lottother:air"},
{["x"] = 5, ["meta"] = {["fields"] = {}, ["inventory"] = {}}, ["y"] = 8, ["param1"] = 57, ["z"] = 12, ["name"] = "lottother:air"},
{["x"] = 5, ["meta"] = {["fields"] = {}, ["inventory"] = {}}, ["y"] = 8, ["param1"] = 42, ["z"] = 13, ["name"] = "lottother:air"},
{["x"] = 5, ["meta"] = {["fields"] = {}, ["inventory"] = {}}, ["y"] = 8, ["param1"] = 59, ["z"] = 14, ["name"] = "lottother:air"},
{["x"] = 5, ["meta"] = {["fields"] = {}, ["inventory"] = {}}, ["y"] = 9, ["param1"] = 11, ["z"] = 5, ["name"] = "lottother:air"},
{["x"] = 5, ["meta"] = {["fields"] = {}, ["inventory"] = {}}, ["y"] = 9, ["param1"] = 10, ["z"] = 6, ["name"] = "lottother:air"},
{["x"] = 5, ["meta"] = {["fields"] = {}, ["inventory"] = {}}, ["y"] = 9, ["param1"] = 25, ["z"] = 7, ["name"] = "lottother:air"},
{["x"] = 5, ["meta"] = {["fields"] = {}, ["inventory"] = {}}, ["y"] = 9, ["param1"] = 41, ["z"] = 8, ["name"] = "lottother:air"},
{["x"] = 5, ["meta"] = {["fields"] = {}, ["inventory"] = {}}, ["y"] = 9, ["param1"] = 57, ["z"] = 9, ["name"] = "lottother:air"},
{["x"] = 5, ["meta"] = {["fields"] = {}, ["inventory"] = {}}, ["y"] = 9, ["param1"] = 72, ["z"] = 10, ["name"] = "lottother:air"},
{["x"] = 5, ["meta"] = {["fields"] = {}, ["inventory"] = {}}, ["y"] = 9, ["param1"] = 56, ["z"] = 11, ["name"] = "lottother:air"},
{["x"] = 5, ["meta"] = {["fields"] = {}, ["inventory"] = {}}, ["y"] = 9, ["param1"] = 73, ["z"] = 12, ["name"] = "lottother:air"},
{["x"] = 5, ["meta"] = {["fields"] = {}, ["inventory"] = {}}, ["y"] = 9, ["param1"] = 58, ["z"] = 13, ["name"] = "lottother:air"},
{["x"] = 5, ["meta"] = {["fields"] = {}, ["inventory"] = {}}, ["y"] = 9, ["param1"] = 75, ["z"] = 14, ["name"] = "lottother:air"},
{["x"] = 5, ["meta"] = {["fields"] = {}, ["inventory"] = {}}, ["y"] = 10, ["param1"] = 11, ["z"] = 5, ["name"] = "lottother:air"},
{["x"] = 5, ["meta"] = {["fields"] = {}, ["inventory"] = {}}, ["y"] = 10, ["param1"] = 26, ["z"] = 6, ["name"] = "lottother:air"},
{["x"] = 5, ["meta"] = {["fields"] = {}, ["inventory"] = {}}, ["y"] = 10, ["param1"] = 41, ["z"] = 7, ["name"] = "lottother:air"},
{["x"] = 5, ["meta"] = {["fields"] = {}, ["inventory"] = {}}, ["y"] = 10, ["param1"] = 57, ["z"] = 8, ["name"] = "lottother:air"},
{["x"] = 5, ["meta"] = {["fields"] = {}, ["inventory"] = {}}, ["y"] = 10, ["param1"] = 73, ["z"] = 9, ["name"] = "lottother:air"},
{["x"] = 5, ["meta"] = {["fields"] = {}, ["inventory"] = {}}, ["y"] = 10, ["param1"] = 88, ["z"] = 10, ["name"] = "lottother:air"},
{["x"] = 5, ["meta"] = {["fields"] = {}, ["inventory"] = {}}, ["y"] = 10, ["param1"] = 72, ["z"] = 11, ["name"] = "lottother:air"},
{["x"] = 5, ["meta"] = {["fields"] = {}, ["inventory"] = {}}, ["y"] = 10, ["param1"] = 89, ["z"] = 12, ["name"] = "lottother:air"},
{["x"] = 5, ["meta"] = {["fields"] = {}, ["inventory"] = {}}, ["y"] = 10, ["param1"] = 74, ["z"] = 13, ["name"] = "lottother:air"},
{["x"] = 5, ["meta"] = {["fields"] = {}, ["inventory"] = {}}, ["y"] = 10, ["param1"] = 91, ["z"] = 14, ["name"] = "lottother:air"},
{["x"] = 5, ["meta"] = {["fields"] = {}, ["inventory"] = {}}, ["y"] = 11, ["param1"] = 27, ["z"] = 5, ["name"] = "lottother:air"},
{["x"] = 5, ["meta"] = {["fields"] = {}, ["inventory"] = {}}, ["y"] = 11, ["param1"] = 42, ["z"] = 6, ["name"] = "lottother:air"},
{["x"] = 5, ["meta"] = {["fields"] = {}, ["inventory"] = {}}, ["y"] = 11, ["param1"] = 57, ["z"] = 7, ["name"] = "lottother:air"},
{["x"] = 5, ["meta"] = {["fields"] = {}, ["inventory"] = {}}, ["y"] = 11, ["param1"] = 73, ["z"] = 8, ["name"] = "lottother:air"},
{["x"] = 5, ["meta"] = {["fields"] = {}, ["inventory"] = {}}, ["y"] = 11, ["param1"] = 89, ["z"] = 9, ["name"] = "lottother:air"},
{["x"] = 5, ["meta"] = {["fields"] = {}, ["inventory"] = {}}, ["y"] = 11, ["param1"] = 104, ["z"] = 10, ["name"] = "lottother:air"},
{["x"] = 5, ["meta"] = {["fields"] = {}, ["inventory"] = {}}, ["y"] = 11, ["param1"] = 88, ["z"] = 11, ["name"] = "lottother:air"},
{["x"] = 5, ["meta"] = {["fields"] = {}, ["inventory"] = {}}, ["y"] = 11, ["param1"] = 105, ["z"] = 12, ["name"] = "lord_trees:mallorn_leaf"},
{["x"] = 5, ["meta"] = {["fields"] = {}, ["inventory"] = {}}, ["y"] = 11, ["param1"] = 90, ["z"] = 13, ["name"] = "lottother:air"},
{["x"] = 5, ["meta"] = {["fields"] = {}, ["inventory"] = {}}, ["y"] = 11, ["param1"] = 107, ["z"] = 14, ["name"] = "lottother:air"},
{["x"] = 5, ["meta"] = {["fields"] = {}, ["inventory"] = {}}, ["y"] = 11, ["param1"] = 92, ["z"] = 15, ["name"] = "lord_trees:mallorn_leaf"},
{["x"] = 5, ["meta"] = {["fields"] = {}, ["inventory"] = {}}, ["y"] = 12, ["param1"] = 43, ["z"] = 5, ["name"] = "lottother:air"},
{["x"] = 5, ["meta"] = {["fields"] = {}, ["inventory"] = {}}, ["y"] = 12, ["param1"] = 58, ["z"] = 6, ["name"] = "lottother:air"},
{["x"] = 5, ["meta"] = {["fields"] = {}, ["inventory"] = {}}, ["y"] = 12, ["param1"] = 73, ["z"] = 7, ["name"] = "lottother:air"},
{["x"] = 5, ["meta"] = {["fields"] = {}, ["inventory"] = {}}, ["y"] = 12, ["param1"] = 89, ["z"] = 8, ["name"] = "lottother:air"},
{["x"] = 5, ["meta"] = {["fields"] = {}, ["inventory"] = {}}, ["y"] = 12, ["param1"] = 105, ["z"] = 9, ["name"] = "lottother:air"},
{["x"] = 5, ["meta"] = {["fields"] = {}, ["inventory"] = {}}, ["y"] = 12, ["param1"] = 120, ["z"] = 10, ["name"] = "lottother:air"},
{["x"] = 5, ["meta"] = {["fields"] = {}, ["inventory"] = {}}, ["y"] = 12, ["param1"] = 104, ["z"] = 11, ["name"] = "lord_trees:mallorn_leaf"},
{["x"] = 5, ["meta"] = {["fields"] = {}, ["inventory"] = {}}, ["y"] = 12, ["param1"] = 121, ["z"] = 12, ["name"] = "lord_trees:mallorn_leaf"},
{["x"] = 5, ["meta"] = {["fields"] = {}, ["inventory"] = {}}, ["y"] = 12, ["param1"] = 106, ["z"] = 13, ["name"] = "lord_trees:mallorn_leaf"},
{["x"] = 5, ["meta"] = {["fields"] = {}, ["inventory"] = {}}, ["y"] = 12, ["param1"] = 123, ["z"] = 14, ["name"] = "lord_trees:mallorn_leaf"},
{["x"] = 5, ["meta"] = {["fields"] = {}, ["inventory"] = {}}, ["y"] = 12, ["param1"] = 108, ["z"] = 15, ["name"] = "lord_trees:mallorn_leaf"},
{["x"] = 5, ["meta"] = {["fields"] = {}, ["inventory"] = {}}, ["y"] = 12, ["param1"] = 93, ["z"] = 16, ["name"] = "lord_trees:mallorn_leaf"},
{["x"] = 5, ["meta"] = {["fields"] = {}, ["inventory"] = {}}, ["y"] = 13, ["param1"] = 59, ["z"] = 5, ["name"] = "lottother:air"},
{["x"] = 5, ["meta"] = {["fields"] = {}, ["inventory"] = {}}, ["y"] = 13, ["param1"] = 74, ["z"] = 6, ["name"] = "lottother:air"},
{["x"] = 5, ["meta"] = {["fields"] = {}, ["inventory"] = {}}, ["y"] = 13, ["param1"] = 89, ["z"] = 7, ["name"] = "lottother:air"},
{["x"] = 5, ["meta"] = {["fields"] = {}, ["inventory"] = {}}, ["y"] = 13, ["param1"] = 105, ["z"] = 8, ["name"] = "lottother:air"},
{["x"] = 5, ["meta"] = {["fields"] = {}, ["inventory"] = {}}, ["y"] = 13, ["param1"] = 121, ["z"] = 9, ["name"] = "lottother:air"},
{["x"] = 5, ["meta"] = {["fields"] = {}, ["inventory"] = {}}, ["y"] = 13, ["param1"] = 136, ["z"] = 10, ["name"] = "lord_trees:mallorn_leaf"},
{["x"] = 5, ["meta"] = {["fields"] = {}, ["inventory"] = {}}, ["param2"] = 1, ["y"] = 13, ["z"] = 11, ["name"] = "lord_trees:mallorn_tree"},
{["x"] = 5, ["meta"] = {["fields"] = {}, ["inventory"] = {}}, ["param2"] = 1, ["y"] = 13, ["z"] = 12, ["name"] = "lord_trees:mallorn_tree"},
{["x"] = 5, ["meta"] = {["fields"] = {}, ["inventory"] = {}}, ["param2"] = 1, ["y"] = 13, ["z"] = 13, ["name"] = "lord_trees:mallorn_tree"},
{["x"] = 5, ["meta"] = {["fields"] = {}, ["inventory"] = {}}, ["y"] = 13, ["param1"] = 139, ["z"] = 14, ["name"] = "lord_trees:mallorn_leaf"},
{["x"] = 5, ["meta"] = {["fields"] = {}, ["inventory"] = {}}, ["y"] = 14, ["param1"] = 75, ["z"] = 5, ["name"] = "lottother:air"},
{["x"] = 5, ["meta"] = {["fields"] = {}, ["inventory"] = {}}, ["y"] = 14, ["param1"] = 90, ["z"] = 6, ["name"] = "lottother:air"},
{["x"] = 5, ["meta"] = {["fields"] = {}, ["inventory"] = {}}, ["y"] = 14, ["param1"] = 105, ["z"] = 7, ["name"] = "lottother:air"},
{["x"] = 5, ["meta"] = {["fields"] = {}, ["inventory"] = {}}, ["y"] = 14, ["param1"] = 121, ["z"] = 8, ["name"] = "lottother:air"},
{["x"] = 5, ["meta"] = {["fields"] = {}, ["inventory"] = {}}, ["y"] = 14, ["param1"] = 137, ["z"] = 9, ["name"] = "lottother:air"},
{["x"] = 5, ["meta"] = {["fields"] = {}, ["inventory"] = {}}, ["y"] = 14, ["param1"] = 153, ["z"] = 10, ["name"] = "lord_trees:mallorn_leaf"},
{["x"] = 5, ["meta"] = {["fields"] = {}, ["inventory"] = {}}, ["y"] = 14, ["param1"] = 170, ["z"] = 11, ["name"] = "default:fence_wood"},
{["x"] = 5, ["meta"] = {["fields"] = {}, ["inventory"] = {}}, ["y"] = 14, ["param1"] = 187, ["z"] = 12, ["name"] = "lottother:air"},
{["x"] = 5, ["meta"] = {["fields"] = {}, ["inventory"] = {}}, ["y"] = 14, ["param1"] = 170, ["z"] = 13, ["name"] = "default:fence_wood"},
{["x"] = 5, ["meta"] = {["fields"] = {}, ["inventory"] = {}}, ["y"] = 14, ["param1"] = 155, ["z"] = 14, ["name"] = "lord_trees:mallorn_leaf"},
{["x"] = 5, ["meta"] = {["fields"] = {}, ["inventory"] = {}}, ["y"] = 15, ["param1"] = 91, ["z"] = 5, ["name"] = "lottother:air"},
{["x"] = 5, ["meta"] = {["fields"] = {}, ["inventory"] = {}}, ["y"] = 15, ["param1"] = 106, ["z"] = 6, ["name"] = "lottother:air"},
{["x"] = 5, ["meta"] = {["fields"] = {}, ["inventory"] = {}}, ["y"] = 15, ["param1"] = 121, ["z"] = 7, ["name"] = "lottother:air"},
{["x"] = 5, ["meta"] = {["fields"] = {}, ["inventory"] = {}}, ["y"] = 15, ["param1"] = 137, ["z"] = 8, ["name"] = "lottother:air"},
{["x"] = 5, ["meta"] = {["fields"] = {}, ["inventory"] = {}}, ["y"] = 15, ["param1"] = 153, ["z"] = 9, ["name"] = "lottother:air"},
{["x"] = 5, ["meta"] = {["fields"] = {}, ["inventory"] = {}}, ["y"] = 15, ["param1"] = 170, ["z"] = 10, ["name"] = "lottother:air"},
{["x"] = 5, ["meta"] = {["fields"] = {}, ["inventory"] = {}}, ["y"] = 15, ["param1"] = 187, ["z"] = 11, ["name"] = "default:fence_wood"},
{["x"] = 5, ["meta"] = {["fields"] = {}, ["inventory"] = {}}, ["y"] = 15, ["param1"] = 204, ["z"] = 12, ["name"] = "lottother:air"},
{["x"] = 5, ["meta"] = {["fields"] = {}, ["inventory"] = {}}, ["y"] = 15, ["param1"] = 187, ["z"] = 13, ["name"] = "default:fence_wood"},
{["x"] = 5, ["meta"] = {["fields"] = {}, ["inventory"] = {}}, ["y"] = 15, ["param1"] = 171, ["z"] = 14, ["name"] = "lottother:air"},
{["x"] = 5, ["meta"] = {["fields"] = {}, ["inventory"] = {}}, ["y"] = 16, ["param1"] = 107, ["z"] = 5, ["name"] = "lottother:air"},
{["x"] = 5, ["meta"] = {["fields"] = {}, ["inventory"] = {}}, ["y"] = 16, ["param1"] = 122, ["z"] = 6, ["name"] = "lottother:air"},
{["x"] = 5, ["meta"] = {["fields"] = {}, ["inventory"] = {}}, ["y"] = 16, ["param1"] = 137, ["z"] = 7, ["name"] = "lottother:air"},
{["x"] = 5, ["meta"] = {["fields"] = {}, ["inventory"] = {}}, ["y"] = 16, ["param1"] = 153, ["z"] = 8, ["name"] = "lottother:air"},
{["x"] = 5, ["meta"] = {["fields"] = {}, ["inventory"] = {}}, ["y"] = 16, ["param1"] = 170, ["z"] = 9, ["name"] = "lottother:air"},
{["x"] = 5, ["meta"] = {["fields"] = {}, ["inventory"] = {}}, ["y"] = 16, ["param1"] = 187, ["z"] = 10, ["name"] = "lottother:air"},
{["x"] = 5, ["meta"] = {["fields"] = {}, ["inventory"] = {}}, ["y"] = 16, ["param1"] = 204, ["z"] = 11, ["name"] = "default:fence_wood"},
{["x"] = 5, ["meta"] = {["fields"] = {}, ["inventory"] = {}}, ["y"] = 16, ["z"] = 12, ["name"] = "lottother:blue_torch"},
{["x"] = 5, ["meta"] = {["fields"] = {}, ["inventory"] = {}}, ["y"] = 16, ["param1"] = 204, ["z"] = 13, ["name"] = "default:fence_wood"},
{["x"] = 5, ["meta"] = {["fields"] = {}, ["inventory"] = {}}, ["y"] = 16, ["param1"] = 187, ["z"] = 14, ["name"] = "lottother:air"},
{["x"] = 5, ["meta"] = {["fields"] = {}, ["inventory"] = {}}, ["y"] = 17, ["param1"] = 91, ["z"] = 5, ["name"] = "lottother:air"},
{["x"] = 5, ["meta"] = {["fields"] = {}, ["inventory"] = {}}, ["y"] = 17, ["param1"] = 106, ["z"] = 6, ["name"] = "lottother:air"},
{["x"] = 5, ["meta"] = {["fields"] = {}, ["inventory"] = {}}, ["y"] = 17, ["param1"] = 121, ["z"] = 7, ["name"] = "lottother:air"},
{["x"] = 5, ["meta"] = {["fields"] = {}, ["inventory"] = {}}, ["y"] = 17, ["param1"] = 137, ["z"] = 8, ["name"] = "lottother:air"},
{["x"] = 5, ["meta"] = {["fields"] = {}, ["inventory"] = {}}, ["y"] = 17, ["param1"] = 153, ["z"] = 9, ["name"] = "lottother:air"},
{["x"] = 5, ["meta"] = {["fields"] = {}, ["inventory"] = {}}, ["y"] = 17, ["param1"] = 170, ["z"] = 10, ["name"] = "lottother:air"},
{["x"] = 5, ["meta"] = {["fields"] = {}, ["inventory"] = {}}, ["y"] = 17, ["z"] = 11, ["name"] = "lord_planks:mallorn"},
{["x"] = 5, ["meta"] = {["fields"] = {}, ["inventory"] = {}}, ["y"] = 17, ["z"] = 12, ["name"] = "lord_planks:mallorn"},
{["x"] = 5, ["meta"] = {["fields"] = {}, ["inventory"] = {}}, ["y"] = 17, ["z"] = 13, ["name"] = "lord_planks:mallorn"},
{["x"] = 5, ["meta"] = {["fields"] = {}, ["inventory"] = {}}, ["y"] = 17, ["param1"] = 171, ["z"] = 14, ["name"] = "lottother:air"},
{["x"] = 5, ["meta"] = {["fields"] = {}, ["inventory"] = {}}, ["y"] = 18, ["param1"] = 75, ["z"] = 5, ["name"] = "lottother:air"},
{["x"] = 5, ["meta"] = {["fields"] = {}, ["inventory"] = {}}, ["y"] = 18, ["param1"] = 90, ["z"] = 6, ["name"] = "lottother:air"},
{["x"] = 5, ["meta"] = {["fields"] = {}, ["inventory"] = {}}, ["y"] = 18, ["param1"] = 105, ["z"] = 7, ["name"] = "lottother:air"},
{["x"] = 5, ["meta"] = {["fields"] = {}, ["inventory"] = {}}, ["y"] = 18, ["param1"] = 121, ["z"] = 8, ["name"] = "lottother:air"},
{["x"] = 5, ["meta"] = {["fields"] = {}, ["inventory"] = {}}, ["y"] = 18, ["param1"] = 137, ["z"] = 9, ["name"] = "lottother:air"},
{["x"] = 5, ["meta"] = {["fields"] = {}, ["inventory"] = {}}, ["y"] = 18, ["param1"] = 153, ["z"] = 10, ["name"] = "lottother:air"},
{["x"] = 5, ["meta"] = {["fields"] = {}, ["inventory"] = {}}, ["y"] = 18, ["param1"] = 136, ["z"] = 11, ["name"] = "lottother:air"},
{["x"] = 5, ["meta"] = {["fields"] = {}, ["inventory"] = {}}, ["y"] = 18, ["param1"] = 153, ["z"] = 12, ["name"] = "lottother:air"},
{["x"] = 5, ["meta"] = {["fields"] = {}, ["inventory"] = {}}, ["y"] = 18, ["param1"] = 138, ["z"] = 13, ["name"] = "lottother:air"},
{["x"] = 5, ["meta"] = {["fields"] = {}, ["inventory"] = {}}, ["y"] = 18, ["param1"] = 155, ["z"] = 14, ["name"] = "lottother:air"},
{["x"] = 5, ["meta"] = {["fields"] = {}, ["inventory"] = {}}, ["y"] = 19, ["param1"] = 59, ["z"] = 5, ["name"] = "lottother:air"},
{["x"] = 5, ["meta"] = {["fields"] = {}, ["inventory"] = {}}, ["y"] = 19, ["param1"] = 74, ["z"] = 6, ["name"] = "lottother:air"},
{["x"] = 5, ["meta"] = {["fields"] = {}, ["inventory"] = {}}, ["y"] = 19, ["param1"] = 89, ["z"] = 7, ["name"] = "lottother:air"},
{["x"] = 5, ["meta"] = {["fields"] = {}, ["inventory"] = {}}, ["y"] = 19, ["param1"] = 105, ["z"] = 8, ["name"] = "lottother:air"},
{["x"] = 5, ["meta"] = {["fields"] = {}, ["inventory"] = {}}, ["y"] = 19, ["param1"] = 121, ["z"] = 9, ["name"] = "lottother:air"},
{["x"] = 5, ["meta"] = {["fields"] = {}, ["inventory"] = {}}, ["y"] = 19, ["param1"] = 136, ["z"] = 10, ["name"] = "lottother:air"},
{["x"] = 5, ["meta"] = {["fields"] = {}, ["inventory"] = {}}, ["y"] = 19, ["param1"] = 120, ["z"] = 11, ["name"] = "lottother:air"},
{["x"] = 5, ["meta"] = {["fields"] = {}, ["inventory"] = {}}, ["y"] = 19, ["param1"] = 137, ["z"] = 12, ["name"] = "lottother:air"},
{["x"] = 5, ["meta"] = {["fields"] = {}, ["inventory"] = {}}, ["y"] = 19, ["param1"] = 122, ["z"] = 13, ["name"] = "lottother:air"},
{["x"] = 5, ["meta"] = {["fields"] = {}, ["inventory"] = {}}, ["y"] = 19, ["param1"] = 139, ["z"] = 14, ["name"] = "lottother:air"},
{["x"] = 5, ["meta"] = {["fields"] = {}, ["inventory"] = {}}, ["y"] = 20, ["param1"] = 43, ["z"] = 5, ["name"] = "lottother:air"},
{["x"] = 5, ["meta"] = {["fields"] = {}, ["inventory"] = {}}, ["y"] = 20, ["param1"] = 58, ["z"] = 6, ["name"] = "lottother:air"},
{["x"] = 5, ["meta"] = {["fields"] = {}, ["inventory"] = {}}, ["y"] = 20, ["param1"] = 73, ["z"] = 7, ["name"] = "lottother:air"},
{["x"] = 5, ["meta"] = {["fields"] = {}, ["inventory"] = {}}, ["y"] = 20, ["param1"] = 89, ["z"] = 8, ["name"] = "lottother:air"},
{["x"] = 5, ["meta"] = {["fields"] = {}, ["inventory"] = {}}, ["y"] = 20, ["param1"] = 105, ["z"] = 9, ["name"] = "lottother:air"},
{["x"] = 5, ["meta"] = {["fields"] = {}, ["inventory"] = {}}, ["y"] = 20, ["param1"] = 120, ["z"] = 10, ["name"] = "lottother:air"},
{["x"] = 5, ["meta"] = {["fields"] = {}, ["inventory"] = {}}, ["y"] = 20, ["param1"] = 104, ["z"] = 11, ["name"] = "lottother:air"},
{["x"] = 5, ["meta"] = {["fields"] = {}, ["inventory"] = {}}, ["y"] = 20, ["param1"] = 121, ["z"] = 12, ["name"] = "lottother:air"},
{["x"] = 5, ["meta"] = {["fields"] = {}, ["inventory"] = {}}, ["y"] = 20, ["param1"] = 106, ["z"] = 13, ["name"] = "lottother:air"},
{["x"] = 5, ["meta"] = {["fields"] = {}, ["inventory"] = {}}, ["y"] = 20, ["param1"] = 123, ["z"] = 14, ["name"] = "lottother:air"},
{["x"] = 5, ["meta"] = {["fields"] = {}, ["inventory"] = {}}, ["y"] = 21, ["param1"] = 27, ["z"] = 5, ["name"] = "lottother:air"},
{["x"] = 5, ["meta"] = {["fields"] = {}, ["inventory"] = {}}, ["y"] = 21, ["param1"] = 42, ["z"] = 6, ["name"] = "lottother:air"},
{["x"] = 5, ["meta"] = {["fields"] = {}, ["inventory"] = {}}, ["y"] = 21, ["param1"] = 57, ["z"] = 7, ["name"] = "lottother:air"},
{["x"] = 5, ["meta"] = {["fields"] = {}, ["inventory"] = {}}, ["y"] = 21, ["param1"] = 73, ["z"] = 8, ["name"] = "lottother:air"},
{["x"] = 5, ["meta"] = {["fields"] = {}, ["inventory"] = {}}, ["y"] = 21, ["param1"] = 89, ["z"] = 9, ["name"] = "lottother:air"},
{["x"] = 5, ["meta"] = {["fields"] = {}, ["inventory"] = {}}, ["y"] = 21, ["param1"] = 104, ["z"] = 10, ["name"] = "lottother:air"},
{["x"] = 5, ["meta"] = {["fields"] = {}, ["inventory"] = {}}, ["y"] = 21, ["param1"] = 104, ["z"] = 11, ["name"] = "lottother:air"},
{["x"] = 5, ["meta"] = {["fields"] = {}, ["inventory"] = {}}, ["y"] = 21, ["param1"] = 105, ["z"] = 12, ["name"] = "lottother:air"},
{["x"] = 5, ["meta"] = {["fields"] = {}, ["inventory"] = {}}, ["y"] = 21, ["param1"] = 90, ["z"] = 13, ["name"] = "lottother:air"},
{["x"] = 5, ["meta"] = {["fields"] = {}, ["inventory"] = {}}, ["y"] = 21, ["param1"] = 107, ["z"] = 14, ["name"] = "lottother:air"},
{["x"] = 5, ["meta"] = {["fields"] = {}, ["inventory"] = {}}, ["y"] = 22, ["param1"] = 43, ["z"] = 5, ["name"] = "lottother:air"},
{["x"] = 5, ["meta"] = {["fields"] = {}, ["inventory"] = {}}, ["y"] = 22, ["param1"] = 58, ["z"] = 6, ["name"] = "lottother:air"},
{["x"] = 5, ["meta"] = {["fields"] = {}, ["inventory"] = {}}, ["y"] = 22, ["param1"] = 73, ["z"] = 7, ["name"] = "lottother:air"},
{["x"] = 5, ["meta"] = {["fields"] = {}, ["inventory"] = {}}, ["y"] = 22, ["param1"] = 73, ["z"] = 8, ["name"] = "lottother:air"},
{["x"] = 5, ["meta"] = {["fields"] = {}, ["inventory"] = {}}, ["y"] = 22, ["param1"] = 89, ["z"] = 9, ["name"] = "lottother:air"},
{["x"] = 5, ["meta"] = {["fields"] = {}, ["inventory"] = {}}, ["y"] = 22, ["param1"] = 104, ["z"] = 10, ["name"] = "lottother:air"},
{["x"] = 5, ["meta"] = {["fields"] = {}, ["inventory"] = {}}, ["y"] = 22, ["param1"] = 120, ["z"] = 11, ["name"] = "lottother:air"},
{["x"] = 5, ["meta"] = {["fields"] = {}, ["inventory"] = {}}, ["y"] = 22, ["param1"] = 105, ["z"] = 12, ["name"] = "lottother:air"},
{["x"] = 5, ["meta"] = {["fields"] = {}, ["inventory"] = {}}, ["y"] = 22, ["param1"] = 90, ["z"] = 13, ["name"] = "lottother:air"},
{["x"] = 5, ["meta"] = {["fields"] = {}, ["inventory"] = {}}, ["y"] = 22, ["param1"] = 91, ["z"] = 14, ["name"] = "lottother:air"},
{["x"] = 5, ["meta"] = {["fields"] = {}, ["inventory"] = {}}, ["y"] = 23, ["param1"] = 59, ["z"] = 5, ["name"] = "lottother:air"},
{["x"] = 5, ["meta"] = {["fields"] = {}, ["inventory"] = {}}, ["y"] = 23, ["param1"] = 74, ["z"] = 6, ["name"] = "lottother:air"},
{["x"] = 5, ["meta"] = {["fields"] = {}, ["inventory"] = {}}, ["y"] = 23, ["param1"] = 89, ["z"] = 7, ["name"] = "lottother:air"},
{["x"] = 5, ["meta"] = {["fields"] = {}, ["inventory"] = {}}, ["y"] = 23, ["param1"] = 89, ["z"] = 8, ["name"] = "lottother:air"},
{["x"] = 5, ["meta"] = {["fields"] = {}, ["inventory"] = {}}, ["y"] = 23, ["param1"] = 105, ["z"] = 9, ["name"] = "lottother:air"},
{["x"] = 5, ["meta"] = {["fields"] = {}, ["inventory"] = {}}, ["y"] = 23, ["param1"] = 120, ["z"] = 10, ["name"] = "lottother:air"},
{["x"] = 5, ["meta"] = {["fields"] = {}, ["inventory"] = {}}, ["y"] = 23, ["param1"] = 136, ["z"] = 11, ["name"] = "lottother:air"},
{["x"] = 5, ["meta"] = {["fields"] = {}, ["inventory"] = {}}, ["y"] = 23, ["param1"] = 121, ["z"] = 12, ["name"] = "lottother:air"},
{["x"] = 5, ["meta"] = {["fields"] = {}, ["inventory"] = {}}, ["y"] = 23, ["param1"] = 106, ["z"] = 13, ["name"] = "lottother:air"},
{["x"] = 5, ["meta"] = {["fields"] = {}, ["inventory"] = {}}, ["y"] = 23, ["param1"] = 91, ["z"] = 14, ["name"] = "lottother:air"},
{["x"] = 5, ["meta"] = {["fields"] = {}, ["inventory"] = {}}, ["y"] = 24, ["param1"] = 75, ["z"] = 5, ["name"] = "lottother:air"},
{["x"] = 5, ["meta"] = {["fields"] = {}, ["inventory"] = {}}, ["y"] = 24, ["param1"] = 90, ["z"] = 6, ["name"] = "lottother:air"},
{["x"] = 5, ["meta"] = {["fields"] = {}, ["inventory"] = {}}, ["y"] = 24, ["param1"] = 105, ["z"] = 7, ["name"] = "lord_trees:mallorn_leaf"},
{["x"] = 5, ["meta"] = {["fields"] = {}, ["inventory"] = {}}, ["y"] = 24, ["param1"] = 105, ["z"] = 8, ["name"] = "lord_trees:mallorn_leaf"},
{["x"] = 5, ["meta"] = {["fields"] = {}, ["inventory"] = {}}, ["y"] = 24, ["param1"] = 121, ["z"] = 9, ["name"] = "lord_trees:mallorn_leaf"},
{["x"] = 5, ["meta"] = {["fields"] = {}, ["inventory"] = {}}, ["y"] = 24, ["param1"] = 136, ["z"] = 10, ["name"] = "lord_trees:mallorn_leaf"},
{["x"] = 5, ["meta"] = {["fields"] = {}, ["inventory"] = {}}, ["y"] = 24, ["param1"] = 153, ["z"] = 11, ["name"] = "lord_trees:mallorn_leaf"},
{["x"] = 5, ["meta"] = {["fields"] = {}, ["inventory"] = {}}, ["y"] = 24, ["param1"] = 137, ["z"] = 12, ["name"] = "lord_trees:mallorn_leaf"},
{["x"] = 5, ["meta"] = {["fields"] = {}, ["inventory"] = {}}, ["y"] = 24, ["param1"] = 122, ["z"] = 13, ["name"] = "lord_trees:mallorn_leaf"},
{["x"] = 5, ["meta"] = {["fields"] = {}, ["inventory"] = {}}, ["y"] = 24, ["param1"] = 107, ["z"] = 14, ["name"] = "lord_trees:mallorn_leaf"},
{["x"] = 5, ["meta"] = {["fields"] = {}, ["inventory"] = {}}, ["y"] = 25, ["param1"] = 76, ["z"] = 4, ["name"] = "lord_trees:mallorn_leaf"},
{["x"] = 5, ["meta"] = {["fields"] = {}, ["inventory"] = {}}, ["y"] = 25, ["param1"] = 91, ["z"] = 5, ["name"] = "lord_trees:mallorn_leaf"},
{["x"] = 5, ["meta"] = {["fields"] = {}, ["inventory"] = {}}, ["y"] = 25, ["param1"] = 106, ["z"] = 6, ["name"] = "lottother:air"},
{["x"] = 5, ["meta"] = {["fields"] = {}, ["inventory"] = {}}, ["y"] = 25, ["param1"] = 121, ["z"] = 7, ["name"] = "lord_trees:mallorn_leaf"},
{["x"] = 5, ["meta"] = {["fields"] = {}, ["inventory"] = {}}, ["y"] = 25, ["param1"] = 105, ["z"] = 8, ["name"] = "lord_trees:mallorn_leaf"},
{["x"] = 5, ["meta"] = {["fields"] = {}, ["inventory"] = {}}, ["y"] = 25, ["param1"] = 121, ["z"] = 9, ["name"] = "lord_trees:mallorn_leaf"},
{["x"] = 5, ["meta"] = {["fields"] = {}, ["inventory"] = {}}, ["y"] = 25, ["param1"] = 136, ["z"] = 10, ["name"] = "lord_trees:mallorn_leaf"},
{["x"] = 5, ["meta"] = {["fields"] = {}, ["inventory"] = {}}, ["y"] = 25, ["param1"] = 136, ["z"] = 11, ["name"] = "lord_trees:mallorn_leaf"},
{["x"] = 5, ["meta"] = {["fields"] = {}, ["inventory"] = {}}, ["y"] = 25, ["param1"] = 121, ["z"] = 12, ["name"] = "lord_trees:mallorn_leaf"},
{["x"] = 5, ["meta"] = {["fields"] = {}, ["inventory"] = {}}, ["y"] = 25, ["param1"] = 122, ["z"] = 13, ["name"] = "lord_trees:mallorn_leaf"},
{["x"] = 5, ["meta"] = {["fields"] = {}, ["inventory"] = {}}, ["y"] = 25, ["param1"] = 107, ["z"] = 14, ["name"] = "lord_trees:mallorn_leaf"},
{["x"] = 5, ["meta"] = {["fields"] = {}, ["inventory"] = {}}, ["y"] = 26, ["param1"] = 107, ["z"] = 5, ["name"] = "lord_trees:mallorn_leaf"},
{["x"] = 5, ["meta"] = {["fields"] = {}, ["inventory"] = {}}, ["y"] = 26, ["param1"] = 122, ["z"] = 6, ["name"] = "lord_trees:mallorn_leaf"},
{["x"] = 5, ["meta"] = {["fields"] = {}, ["inventory"] = {}}, ["y"] = 26, ["param1"] = 137, ["z"] = 7, ["name"] = "lord_trees:mallorn_leaf"},
{["x"] = 5, ["meta"] = {["fields"] = {}, ["inventory"] = {}}, ["y"] = 26, ["param1"] = 121, ["z"] = 8, ["name"] = "lord_trees:mallorn_leaf"},
{["x"] = 5, ["meta"] = {["fields"] = {}, ["inventory"] = {}}, ["y"] = 26, ["param1"] = 137, ["z"] = 9, ["name"] = "lord_trees:mallorn_leaf"},
{["x"] = 5, ["meta"] = {["fields"] = {}, ["inventory"] = {}}, ["y"] = 26, ["param1"] = 153, ["z"] = 10, ["name"] = "lord_trees:mallorn_leaf"},
{["x"] = 5, ["meta"] = {["fields"] = {}, ["inventory"] = {}}, ["y"] = 26, ["param1"] = 153, ["z"] = 11, ["name"] = "lord_trees:mallorn_leaf"},
{["x"] = 5, ["meta"] = {["fields"] = {}, ["inventory"] = {}}, ["y"] = 26, ["param1"] = 137, ["z"] = 12, ["name"] = "lord_trees:mallorn_leaf"},
{["x"] = 5, ["meta"] = {["fields"] = {}, ["inventory"] = {}}, ["y"] = 26, ["param1"] = 138, ["z"] = 13, ["name"] = "lord_trees:mallorn_leaf"},
{["x"] = 5, ["meta"] = {["fields"] = {}, ["inventory"] = {}}, ["y"] = 26, ["param1"] = 123, ["z"] = 14, ["name"] = "lord_trees:mallorn_leaf"},
{["x"] = 5, ["meta"] = {["fields"] = {}, ["inventory"] = {}}, ["y"] = 26, ["param1"] = 108, ["z"] = 15, ["name"] = "lord_trees:mallorn_leaf"},
{["x"] = 5, ["meta"] = {["fields"] = {}, ["inventory"] = {}}, ["y"] = 27, ["param1"] = 123, ["z"] = 5, ["name"] = "lottother:air"},
{["x"] = 5, ["meta"] = {["fields"] = {}, ["inventory"] = {}}, ["y"] = 27, ["param1"] = 138, ["z"] = 6, ["name"] = "lottother:air"},
{["x"] = 5, ["meta"] = {["fields"] = {}, ["inventory"] = {}}, ["y"] = 27, ["param1"] = 153, ["z"] = 7, ["name"] = "lottother:air"},
{["x"] = 5, ["meta"] = {["fields"] = {}, ["inventory"] = {}}, ["y"] = 27, ["param1"] = 137, ["z"] = 8, ["name"] = "lottother:air"},
{["x"] = 5, ["meta"] = {["fields"] = {}, ["inventory"] = {}}, ["y"] = 27, ["param1"] = 153, ["z"] = 9, ["name"] = "lottother:air"},
{["x"] = 5, ["meta"] = {["fields"] = {}, ["inventory"] = {}}, ["y"] = 27, ["param1"] = 170, ["z"] = 10, ["name"] = "lottother:air"},
{["x"] = 5, ["meta"] = {["fields"] = {}, ["inventory"] = {}}, ["y"] = 27, ["param1"] = 153, ["z"] = 11, ["name"] = "lottother:air"},
{["x"] = 5, ["meta"] = {["fields"] = {}, ["inventory"] = {}}, ["y"] = 27, ["param1"] = 137, ["z"] = 12, ["name"] = "lottother:air"},
{["x"] = 5, ["meta"] = {["fields"] = {}, ["inventory"] = {}}, ["y"] = 27, ["param1"] = 154, ["z"] = 13, ["name"] = "lottother:air"},
{["x"] = 5, ["meta"] = {["fields"] = {}, ["inventory"] = {}}, ["y"] = 27, ["param1"] = 139, ["z"] = 14, ["name"] = "lottother:air"},
{["x"] = 5, ["meta"] = {["fields"] = {}, ["inventory"] = {}}, ["y"] = 28, ["param1"] = 139, ["z"] = 5, ["name"] = "lottother:air"},
{["x"] = 5, ["meta"] = {["fields"] = {}, ["inventory"] = {}}, ["y"] = 28, ["param1"] = 154, ["z"] = 6, ["name"] = "lottother:air"},
{["x"] = 5, ["meta"] = {["fields"] = {}, ["inventory"] = {}}, ["y"] = 28, ["param1"] = 170, ["z"] = 7, ["name"] = "lottother:air"},
{["x"] = 5, ["meta"] = {["fields"] = {}, ["inventory"] = {}}, ["y"] = 28, ["param1"] = 153, ["z"] = 8, ["name"] = "lottother:air"},
{["x"] = 5, ["meta"] = {["fields"] = {}, ["inventory"] = {}}, ["y"] = 28, ["param1"] = 170, ["z"] = 9, ["name"] = "lottother:air"},
{["x"] = 5, ["meta"] = {["fields"] = {}, ["inventory"] = {}}, ["y"] = 28, ["param1"] = 187, ["z"] = 10, ["name"] = "lottother:air"},
{["x"] = 5, ["meta"] = {["fields"] = {}, ["inventory"] = {}}, ["y"] = 28, ["param1"] = 170, ["z"] = 11, ["name"] = "lottother:air"},
{["x"] = 5, ["meta"] = {["fields"] = {}, ["inventory"] = {}}, ["y"] = 28, ["param1"] = 153, ["z"] = 12, ["name"] = "lottother:air"},
{["x"] = 5, ["meta"] = {["fields"] = {}, ["inventory"] = {}}, ["y"] = 28, ["param1"] = 170, ["z"] = 13, ["name"] = "lottother:air"},
{["x"] = 5, ["meta"] = {["fields"] = {}, ["inventory"] = {}}, ["y"] = 28, ["param1"] = 155, ["z"] = 14, ["name"] = "lottother:air"},
{["x"] = 5, ["meta"] = {["fields"] = {}, ["inventory"] = {}}, ["y"] = 29, ["param1"] = 155, ["z"] = 5, ["name"] = "lottother:air"},
{["x"] = 5, ["meta"] = {["fields"] = {}, ["inventory"] = {}}, ["y"] = 29, ["param1"] = 170, ["z"] = 6, ["name"] = "lottother:air"},
{["x"] = 5, ["meta"] = {["fields"] = {}, ["inventory"] = {}}, ["y"] = 29, ["param1"] = 187, ["z"] = 7, ["name"] = "lottother:air"},
{["x"] = 5, ["meta"] = {["fields"] = {}, ["inventory"] = {}}, ["y"] = 29, ["param1"] = 170, ["z"] = 8, ["name"] = "lottother:air"},
{["x"] = 5, ["meta"] = {["fields"] = {}, ["inventory"] = {}}, ["y"] = 29, ["param1"] = 187, ["z"] = 9, ["name"] = "lottother:air"},
{["x"] = 5, ["meta"] = {["fields"] = {}, ["inventory"] = {}}, ["y"] = 29, ["param1"] = 204, ["z"] = 10, ["name"] = "lottother:air"},
{["x"] = 5, ["meta"] = {["fields"] = {}, ["inventory"] = {}}, ["y"] = 29, ["param1"] = 187, ["z"] = 11, ["name"] = "lottother:air"},
{["x"] = 5, ["meta"] = {["fields"] = {}, ["inventory"] = {}}, ["y"] = 29, ["param1"] = 170, ["z"] = 12, ["name"] = "lottother:air"},
{["x"] = 5, ["meta"] = {["fields"] = {}, ["inventory"] = {}}, ["y"] = 29, ["param1"] = 187, ["z"] = 13, ["name"] = "lottother:air"},
{["x"] = 5, ["meta"] = {["fields"] = {}, ["inventory"] = {}}, ["y"] = 29, ["param1"] = 171, ["z"] = 14, ["name"] = "lottother:air"},
{["x"] = 5, ["meta"] = {["fields"] = {}, ["inventory"] = {}}, ["y"] = 30, ["param1"] = 139, ["z"] = 5, ["name"] = "lottother:air"},
{["x"] = 5, ["meta"] = {["fields"] = {}, ["inventory"] = {}}, ["y"] = 30, ["param1"] = 154, ["z"] = 6, ["name"] = "lottother:air"},
{["x"] = 5, ["meta"] = {["fields"] = {}, ["inventory"] = {}}, ["y"] = 30, ["param1"] = 170, ["z"] = 7, ["name"] = "lottother:air"},
{["x"] = 5, ["meta"] = {["fields"] = {}, ["inventory"] = {}}, ["y"] = 30, ["param1"] = 153, ["z"] = 8, ["name"] = "lottother:air"},
{["x"] = 5, ["meta"] = {["fields"] = {}, ["inventory"] = {}}, ["y"] = 30, ["param1"] = 170, ["z"] = 9, ["name"] = "lottother:air"},
{["x"] = 5, ["meta"] = {["fields"] = {}, ["inventory"] = {}}, ["y"] = 30, ["param1"] = 187, ["z"] = 10, ["name"] = "lottother:air"},
{["x"] = 5, ["meta"] = {["fields"] = {}, ["inventory"] = {}}, ["y"] = 30, ["param1"] = 170, ["z"] = 11, ["name"] = "lottother:air"},
{["x"] = 5, ["meta"] = {["fields"] = {}, ["inventory"] = {}}, ["y"] = 30, ["param1"] = 153, ["z"] = 12, ["name"] = "lottother:air"},
{["x"] = 5, ["meta"] = {["fields"] = {}, ["inventory"] = {}}, ["y"] = 30, ["param1"] = 170, ["z"] = 13, ["name"] = "lottother:air"},
{["x"] = 5, ["meta"] = {["fields"] = {}, ["inventory"] = {}}, ["y"] = 30, ["param1"] = 155, ["z"] = 14, ["name"] = "lottother:air"},
{["x"] = 5, ["meta"] = {["fields"] = {}, ["inventory"] = {}}, ["y"] = 31, ["param1"] = 123, ["z"] = 5, ["name"] = "lottother:air"},
{["x"] = 5, ["meta"] = {["fields"] = {}, ["inventory"] = {}}, ["y"] = 31, ["param1"] = 138, ["z"] = 6, ["name"] = "lottother:air"},
{["x"] = 5, ["meta"] = {["fields"] = {}, ["inventory"] = {}}, ["y"] = 31, ["param1"] = 153, ["z"] = 7, ["name"] = "lottother:air"},
{["x"] = 5, ["meta"] = {["fields"] = {}, ["inventory"] = {}}, ["y"] = 31, ["param1"] = 137, ["z"] = 8, ["name"] = "lottother:air"},
{["x"] = 5, ["meta"] = {["fields"] = {}, ["inventory"] = {}}, ["y"] = 31, ["param1"] = 153, ["z"] = 9, ["name"] = "lottother:air"},
{["x"] = 5, ["meta"] = {["fields"] = {}, ["inventory"] = {}}, ["y"] = 31, ["param1"] = 170, ["z"] = 10, ["name"] = "lottother:air"},
{["x"] = 5, ["meta"] = {["fields"] = {}, ["inventory"] = {}}, ["y"] = 31, ["param1"] = 153, ["z"] = 11, ["name"] = "lottother:air"},
{["x"] = 5, ["meta"] = {["fields"] = {}, ["inventory"] = {}}, ["y"] = 31, ["param1"] = 137, ["z"] = 12, ["name"] = "lottother:air"},
{["x"] = 5, ["meta"] = {["fields"] = {}, ["inventory"] = {}}, ["y"] = 31, ["param1"] = 154, ["z"] = 13, ["name"] = "lottother:air"},
{["x"] = 5, ["meta"] = {["fields"] = {}, ["inventory"] = {}}, ["y"] = 31, ["param1"] = 139, ["z"] = 14, ["name"] = "lottother:air"},
{["x"] = 5, ["meta"] = {["fields"] = {}, ["inventory"] = {}}, ["y"] = 32, ["param1"] = 107, ["z"] = 5, ["name"] = "lottother:air"},
{["x"] = 5, ["meta"] = {["fields"] = {}, ["inventory"] = {}}, ["y"] = 32, ["param1"] = 122, ["z"] = 6, ["name"] = "lottother:air"},
{["x"] = 5, ["meta"] = {["fields"] = {}, ["inventory"] = {}}, ["y"] = 32, ["param1"] = 137, ["z"] = 7, ["name"] = "lottother:air"},
{["x"] = 5, ["meta"] = {["fields"] = {}, ["inventory"] = {}}, ["y"] = 32, ["param1"] = 121, ["z"] = 8, ["name"] = "lottother:air"},
{["x"] = 5, ["meta"] = {["fields"] = {}, ["inventory"] = {}}, ["y"] = 32, ["param1"] = 137, ["z"] = 9, ["name"] = "lottother:air"},
{["x"] = 5, ["meta"] = {["fields"] = {}, ["inventory"] = {}}, ["y"] = 32, ["param1"] = 153, ["z"] = 10, ["name"] = "lottother:air"},
{["x"] = 5, ["meta"] = {["fields"] = {}, ["inventory"] = {}}, ["y"] = 32, ["param1"] = 136, ["z"] = 11, ["name"] = "lottother:air"},
{["x"] = 5, ["meta"] = {["fields"] = {}, ["inventory"] = {}}, ["y"] = 32, ["param1"] = 121, ["z"] = 12, ["name"] = "lottother:air"},
{["x"] = 5, ["meta"] = {["fields"] = {}, ["inventory"] = {}}, ["y"] = 32, ["param1"] = 138, ["z"] = 13, ["name"] = "lottother:air"},
{["x"] = 5, ["meta"] = {["fields"] = {}, ["inventory"] = {}}, ["y"] = 32, ["param1"] = 123, ["z"] = 14, ["name"] = "lottother:air"},
{["x"] = 5, ["meta"] = {["fields"] = {}, ["inventory"] = {}}, ["y"] = 33, ["param1"] = 91, ["z"] = 5, ["name"] = "lottother:air"},
{["x"] = 5, ["meta"] = {["fields"] = {}, ["inventory"] = {}}, ["y"] = 33, ["param1"] = 106, ["z"] = 6, ["name"] = "lottother:air"},
{["x"] = 5, ["meta"] = {["fields"] = {}, ["inventory"] = {}}, ["y"] = 33, ["param1"] = 121, ["z"] = 7, ["name"] = "lottother:air"},
{["x"] = 5, ["meta"] = {["fields"] = {}, ["inventory"] = {}}, ["y"] = 33, ["param1"] = 105, ["z"] = 8, ["name"] = "lottother:air"},
{["x"] = 5, ["meta"] = {["fields"] = {}, ["inventory"] = {}}, ["y"] = 33, ["param1"] = 121, ["z"] = 9, ["name"] = "lottother:air"},
{["x"] = 5, ["meta"] = {["fields"] = {}, ["inventory"] = {}}, ["y"] = 33, ["param1"] = 136, ["z"] = 10, ["name"] = "lottother:air"},
{["x"] = 5, ["meta"] = {["fields"] = {}, ["inventory"] = {}}, ["y"] = 33, ["param1"] = 120, ["z"] = 11, ["name"] = "lottother:air"},
{["x"] = 5, ["meta"] = {["fields"] = {}, ["inventory"] = {}}, ["y"] = 33, ["param1"] = 105, ["z"] = 12, ["name"] = "lottother:air"},
{["x"] = 5, ["meta"] = {["fields"] = {}, ["inventory"] = {}}, ["y"] = 33, ["param1"] = 122, ["z"] = 13, ["name"] = "lottother:air"},
{["x"] = 5, ["meta"] = {["fields"] = {}, ["inventory"] = {}}, ["y"] = 33, ["param1"] = 107, ["z"] = 14, ["name"] = "lottother:air"},
{["x"] = 5, ["meta"] = {["fields"] = {}, ["inventory"] = {}}, ["y"] = 34, ["param1"] = 75, ["z"] = 5, ["name"] = "lottother:air"},
{["x"] = 5, ["meta"] = {["fields"] = {}, ["inventory"] = {}}, ["y"] = 34, ["param1"] = 90, ["z"] = 6, ["name"] = "lottother:air"},
{["x"] = 5, ["meta"] = {["fields"] = {}, ["inventory"] = {}}, ["y"] = 34, ["param1"] = 105, ["z"] = 7, ["name"] = "lottother:air"},
{["x"] = 5, ["meta"] = {["fields"] = {}, ["inventory"] = {}}, ["y"] = 34, ["param1"] = 89, ["z"] = 8, ["name"] = "lottother:air"},
{["x"] = 5, ["meta"] = {["fields"] = {}, ["inventory"] = {}}, ["y"] = 34, ["param1"] = 105, ["z"] = 9, ["name"] = "lottother:air"},
{["x"] = 5, ["meta"] = {["fields"] = {}, ["inventory"] = {}}, ["y"] = 34, ["param1"] = 120, ["z"] = 10, ["name"] = "lottother:air"},
{["x"] = 5, ["meta"] = {["fields"] = {}, ["inventory"] = {}}, ["y"] = 34, ["param1"] = 104, ["z"] = 11, ["name"] = "lottother:air"},
{["x"] = 5, ["meta"] = {["fields"] = {}, ["inventory"] = {}}, ["y"] = 34, ["param1"] = 89, ["z"] = 12, ["name"] = "lottother:air"},
{["x"] = 5, ["meta"] = {["fields"] = {}, ["inventory"] = {}}, ["y"] = 34, ["param1"] = 106, ["z"] = 13, ["name"] = "lottother:air"},
{["x"] = 5, ["meta"] = {["fields"] = {}, ["inventory"] = {}}, ["y"] = 34, ["param1"] = 91, ["z"] = 14, ["name"] = "lottother:air"},
{["x"] = 5, ["meta"] = {["fields"] = {}, ["inventory"] = {}}, ["y"] = 35, ["param1"] = 59, ["z"] = 5, ["name"] = "lottother:air"},
{["x"] = 5, ["meta"] = {["fields"] = {}, ["inventory"] = {}}, ["y"] = 35, ["param1"] = 74, ["z"] = 6, ["name"] = "lottother:air"},
{["x"] = 5, ["meta"] = {["fields"] = {}, ["inventory"] = {}}, ["y"] = 35, ["param1"] = 89, ["z"] = 7, ["name"] = "lottother:air"},
{["x"] = 5, ["meta"] = {["fields"] = {}, ["inventory"] = {}}, ["y"] = 35, ["param1"] = 105, ["z"] = 8, ["name"] = "lottother:air"},
{["x"] = 5, ["meta"] = {["fields"] = {}, ["inventory"] = {}}, ["y"] = 35, ["param1"] = 121, ["z"] = 9, ["name"] = "lottother:air"},
{["x"] = 5, ["meta"] = {["fields"] = {}, ["inventory"] = {}}, ["y"] = 35, ["param1"] = 104, ["z"] = 10, ["name"] = "lottother:air"},
{["x"] = 5, ["meta"] = {["fields"] = {}, ["inventory"] = {}}, ["y"] = 35, ["param1"] = 120, ["z"] = 11, ["name"] = "lottother:air"},
{["x"] = 5, ["meta"] = {["fields"] = {}, ["inventory"] = {}}, ["y"] = 35, ["param1"] = 105, ["z"] = 12, ["name"] = "lottother:air"},
{["x"] = 5, ["meta"] = {["fields"] = {}, ["inventory"] = {}}, ["y"] = 35, ["param1"] = 90, ["z"] = 13, ["name"] = "lottother:air"},
{["x"] = 5, ["meta"] = {["fields"] = {}, ["inventory"] = {}}, ["y"] = 35, ["param1"] = 75, ["z"] = 14, ["name"] = "lottother:air"},
{["x"] = 5, ["meta"] = {["fields"] = {}, ["inventory"] = {}}, ["y"] = 36, ["param1"] = 75, ["z"] = 5, ["name"] = "lottother:air"},
{["x"] = 5, ["meta"] = {["fields"] = {}, ["inventory"] = {}}, ["y"] = 36, ["param1"] = 90, ["z"] = 6, ["name"] = "lottother:air"},
{["x"] = 5, ["meta"] = {["fields"] = {}, ["inventory"] = {}}, ["y"] = 36, ["param1"] = 105, ["z"] = 7, ["name"] = "lottother:air"},
{["x"] = 5, ["meta"] = {["fields"] = {}, ["inventory"] = {}}, ["y"] = 36, ["param1"] = 121, ["z"] = 8, ["name"] = "lottother:air"},
{["x"] = 5, ["meta"] = {["fields"] = {}, ["inventory"] = {}}, ["y"] = 36, ["param1"] = 137, ["z"] = 9, ["name"] = "lottother:air"},
{["x"] = 5, ["meta"] = {["fields"] = {}, ["inventory"] = {}}, ["y"] = 36, ["param1"] = 120, ["z"] = 10, ["name"] = "lottother:air"},
{["x"] = 5, ["meta"] = {["fields"] = {}, ["inventory"] = {}}, ["y"] = 36, ["param1"] = 136, ["z"] = 11, ["name"] = "lottother:air"},
{["x"] = 5, ["meta"] = {["fields"] = {}, ["inventory"] = {}}, ["y"] = 36, ["param1"] = 121, ["z"] = 12, ["name"] = "lottother:air"},
{["x"] = 5, ["meta"] = {["fields"] = {}, ["inventory"] = {}}, ["y"] = 36, ["param1"] = 106, ["z"] = 13, ["name"] = "lottother:air"},
{["x"] = 5, ["meta"] = {["fields"] = {}, ["inventory"] = {}}, ["y"] = 36, ["param1"] = 91, ["z"] = 14, ["name"] = "lottother:air"},
{["x"] = 5, ["meta"] = {["fields"] = {}, ["inventory"] = {}}, ["y"] = 37, ["param1"] = 91, ["z"] = 5, ["name"] = "lottother:air"},
{["x"] = 5, ["meta"] = {["fields"] = {}, ["inventory"] = {}}, ["y"] = 37, ["param1"] = 106, ["z"] = 6, ["name"] = "lottother:air"},
{["x"] = 5, ["meta"] = {["fields"] = {}, ["inventory"] = {}}, ["y"] = 37, ["param1"] = 121, ["z"] = 7, ["name"] = "lottother:air"},
{["x"] = 5, ["meta"] = {["fields"] = {}, ["inventory"] = {}}, ["y"] = 37, ["param1"] = 137, ["z"] = 8, ["name"] = "lottother:air"},
{["x"] = 5, ["meta"] = {["fields"] = {}, ["inventory"] = {}}, ["y"] = 37, ["param1"] = 153, ["z"] = 9, ["name"] = "lord_trees:mallorn_leaf"},
{["x"] = 5, ["meta"] = {["fields"] = {}, ["inventory"] = {}}, ["y"] = 37, ["param1"] = 136, ["z"] = 10, ["name"] = "lord_trees:mallorn_leaf"},
{["x"] = 5, ["meta"] = {["fields"] = {}, ["inventory"] = {}}, ["y"] = 37, ["param1"] = 153, ["z"] = 11, ["name"] = "lord_trees:mallorn_leaf"},
{["x"] = 5, ["meta"] = {["fields"] = {}, ["inventory"] = {}}, ["y"] = 37, ["param1"] = 137, ["z"] = 12, ["name"] = "lottother:air"},
{["x"] = 5, ["meta"] = {["fields"] = {}, ["inventory"] = {}}, ["y"] = 37, ["param1"] = 122, ["z"] = 13, ["name"] = "lottother:air"},
{["x"] = 5, ["meta"] = {["fields"] = {}, ["inventory"] = {}}, ["y"] = 37, ["param1"] = 107, ["z"] = 14, ["name"] = "lottother:air"},
{["x"] = 5, ["meta"] = {["fields"] = {}, ["inventory"] = {}}, ["y"] = 38, ["param1"] = 107, ["z"] = 5, ["name"] = "lottother:air"},
{["x"] = 5, ["meta"] = {["fields"] = {}, ["inventory"] = {}}, ["y"] = 38, ["param1"] = 122, ["z"] = 6, ["name"] = "lottother:air"},
{["x"] = 5, ["meta"] = {["fields"] = {}, ["inventory"] = {}}, ["y"] = 38, ["param1"] = 137, ["z"] = 7, ["name"] = "lottother:air"},
{["x"] = 5, ["meta"] = {["fields"] = {}, ["inventory"] = {}}, ["y"] = 38, ["param1"] = 153, ["z"] = 8, ["name"] = "lottother:air"},
{["x"] = 5, ["meta"] = {["fields"] = {}, ["inventory"] = {}}, ["y"] = 38, ["param1"] = 170, ["z"] = 9, ["name"] = "lord_trees:mallorn_leaf"},
{["x"] = 5, ["meta"] = {["fields"] = {}, ["inventory"] = {}}, ["y"] = 38, ["param1"] = 153, ["z"] = 10, ["name"] = "lord_trees:mallorn_leaf"},
{["x"] = 5, ["meta"] = {["fields"] = {}, ["inventory"] = {}}, ["y"] = 38, ["param1"] = 170, ["z"] = 11, ["name"] = "lord_trees:mallorn_leaf"},
{["x"] = 5, ["meta"] = {["fields"] = {}, ["inventory"] = {}}, ["y"] = 38, ["param1"] = 153, ["z"] = 12, ["name"] = "lottother:air"},
{["x"] = 5, ["meta"] = {["fields"] = {}, ["inventory"] = {}}, ["y"] = 38, ["param1"] = 138, ["z"] = 13, ["name"] = "lottother:air"},
{["x"] = 5, ["meta"] = {["fields"] = {}, ["inventory"] = {}}, ["y"] = 38, ["param1"] = 123, ["z"] = 14, ["name"] = "lottother:air"},
{["x"] = 5, ["meta"] = {["fields"] = {}, ["inventory"] = {}}, ["y"] = 39, ["param1"] = 123, ["z"] = 5, ["name"] = "lottother:air"},
{["x"] = 5, ["meta"] = {["fields"] = {}, ["inventory"] = {}}, ["y"] = 39, ["param1"] = 138, ["z"] = 6, ["name"] = "lottother:air"},
{["x"] = 5, ["meta"] = {["fields"] = {}, ["inventory"] = {}}, ["y"] = 39, ["param1"] = 153, ["z"] = 7, ["name"] = "lottother:air"},
{["x"] = 5, ["meta"] = {["fields"] = {}, ["inventory"] = {}}, ["y"] = 39, ["param1"] = 170, ["z"] = 8, ["name"] = "lottother:air"},
{["x"] = 5, ["meta"] = {["fields"] = {}, ["inventory"] = {}}, ["y"] = 39, ["param1"] = 187, ["z"] = 9, ["name"] = "lottother:air"},
{["x"] = 5, ["meta"] = {["fields"] = {}, ["inventory"] = {}}, ["y"] = 39, ["param1"] = 170, ["z"] = 10, ["name"] = "lottother:air"},
{["x"] = 5, ["meta"] = {["fields"] = {}, ["inventory"] = {}}, ["y"] = 39, ["param1"] = 187, ["z"] = 11, ["name"] = "lottother:air"},
{["x"] = 5, ["meta"] = {["fields"] = {}, ["inventory"] = {}}, ["y"] = 39, ["param1"] = 170, ["z"] = 12, ["name"] = "lottother:air"},
{["x"] = 5, ["meta"] = {["fields"] = {}, ["inventory"] = {}}, ["y"] = 39, ["param1"] = 154, ["z"] = 13, ["name"] = "lottother:air"},
{["x"] = 5, ["meta"] = {["fields"] = {}, ["inventory"] = {}}, ["y"] = 39, ["param1"] = 139, ["z"] = 14, ["name"] = "lottother:air"},
{["x"] = 5, ["meta"] = {["fields"] = {}, ["inventory"] = {}}, ["y"] = 40, ["param1"] = 139, ["z"] = 5, ["name"] = "lottother:air"},
{["x"] = 5, ["meta"] = {["fields"] = {}, ["inventory"] = {}}, ["y"] = 40, ["param1"] = 154, ["z"] = 6, ["name"] = "lottother:air"},
{["x"] = 5, ["meta"] = {["fields"] = {}, ["inventory"] = {}}, ["y"] = 40, ["param1"] = 170, ["z"] = 7, ["name"] = "lottother:air"},
{["x"] = 5, ["meta"] = {["fields"] = {}, ["inventory"] = {}}, ["y"] = 40, ["param1"] = 187, ["z"] = 8, ["name"] = "lottother:air"},
{["x"] = 5, ["meta"] = {["fields"] = {}, ["inventory"] = {}}, ["y"] = 40, ["param1"] = 204, ["z"] = 9, ["name"] = "lottother:air"},
{["x"] = 5, ["meta"] = {["fields"] = {}, ["inventory"] = {}}, ["y"] = 40, ["param1"] = 187, ["z"] = 10, ["name"] = "lottother:air"},
{["x"] = 5, ["meta"] = {["fields"] = {}, ["inventory"] = {}}, ["y"] = 40, ["param1"] = 204, ["z"] = 11, ["name"] = "lottother:air"},
{["x"] = 5, ["meta"] = {["fields"] = {}, ["inventory"] = {}}, ["y"] = 40, ["param1"] = 187, ["z"] = 12, ["name"] = "lottother:air"},
{["x"] = 5, ["meta"] = {["fields"] = {}, ["inventory"] = {}}, ["y"] = 40, ["param1"] = 170, ["z"] = 13, ["name"] = "lottother:air"},
{["x"] = 5, ["meta"] = {["fields"] = {}, ["inventory"] = {}}, ["y"] = 40, ["param1"] = 155, ["z"] = 14, ["name"] = "lottother:air"},
{["x"] = 5, ["meta"] = {["fields"] = {}, ["inventory"] = {}}, ["y"] = 41, ["param1"] = 123, ["z"] = 5, ["name"] = "lottother:air"},
{["x"] = 5, ["meta"] = {["fields"] = {}, ["inventory"] = {}}, ["y"] = 41, ["param1"] = 138, ["z"] = 6, ["name"] = "lottother:air"},
{["x"] = 5, ["meta"] = {["fields"] = {}, ["inventory"] = {}}, ["y"] = 41, ["param1"] = 153, ["z"] = 7, ["name"] = "lottother:air"},
{["x"] = 5, ["meta"] = {["fields"] = {}, ["inventory"] = {}}, ["y"] = 41, ["param1"] = 170, ["z"] = 8, ["name"] = "lottother:air"},
{["x"] = 5, ["meta"] = {["fields"] = {}, ["inventory"] = {}}, ["y"] = 41, ["param1"] = 187, ["z"] = 9, ["name"] = "lottother:air"},
{["x"] = 5, ["meta"] = {["fields"] = {}, ["inventory"] = {}}, ["y"] = 41, ["param1"] = 170, ["z"] = 10, ["name"] = "lottother:air"},
{["x"] = 5, ["meta"] = {["fields"] = {}, ["inventory"] = {}}, ["y"] = 41, ["param1"] = 187, ["z"] = 11, ["name"] = "lottother:air"},
{["x"] = 5, ["meta"] = {["fields"] = {}, ["inventory"] = {}}, ["y"] = 41, ["param1"] = 170, ["z"] = 12, ["name"] = "lottother:air"},
{["x"] = 5, ["meta"] = {["fields"] = {}, ["inventory"] = {}}, ["y"] = 41, ["param1"] = 154, ["z"] = 13, ["name"] = "lottother:air"},
{["x"] = 5, ["meta"] = {["fields"] = {}, ["inventory"] = {}}, ["y"] = 41, ["param1"] = 139, ["z"] = 14, ["name"] = "lottother:air"},
{["x"] = 5, ["meta"] = {["fields"] = {}, ["inventory"] = {}}, ["y"] = 42, ["param1"] = 107, ["z"] = 5, ["name"] = "lottother:air"},
{["x"] = 5, ["meta"] = {["fields"] = {}, ["inventory"] = {}}, ["y"] = 42, ["param1"] = 122, ["z"] = 6, ["name"] = "lottother:air"},
{["x"] = 5, ["meta"] = {["fields"] = {}, ["inventory"] = {}}, ["y"] = 42, ["param1"] = 137, ["z"] = 7, ["name"] = "lottother:air"},
{["x"] = 5, ["meta"] = {["fields"] = {}, ["inventory"] = {}}, ["y"] = 42, ["param1"] = 153, ["z"] = 8, ["name"] = "lottother:air"},
{["x"] = 5, ["meta"] = {["fields"] = {}, ["inventory"] = {}}, ["y"] = 42, ["param1"] = 170, ["z"] = 9, ["name"] = "lottother:air"},
{["x"] = 5, ["meta"] = {["fields"] = {}, ["inventory"] = {}}, ["y"] = 42, ["param1"] = 153, ["z"] = 10, ["name"] = "lottother:air"},
{["x"] = 5, ["meta"] = {["fields"] = {}, ["inventory"] = {}}, ["y"] = 42, ["param1"] = 170, ["z"] = 11, ["name"] = "lottother:air"},
{["x"] = 5, ["meta"] = {["fields"] = {}, ["inventory"] = {}}, ["y"] = 42, ["param1"] = 153, ["z"] = 12, ["name"] = "lottother:air"},
{["x"] = 5, ["meta"] = {["fields"] = {}, ["inventory"] = {}}, ["y"] = 42, ["param1"] = 138, ["z"] = 13, ["name"] = "lottother:air"},
{["x"] = 5, ["meta"] = {["fields"] = {}, ["inventory"] = {}}, ["y"] = 42, ["param1"] = 123, ["z"] = 14, ["name"] = "lottother:air"},
{["x"] = 5, ["meta"] = {["fields"] = {}, ["inventory"] = {}}, ["y"] = 43, ["param1"] = 91, ["z"] = 5, ["name"] = "lottother:air"},
{["x"] = 5, ["meta"] = {["fields"] = {}, ["inventory"] = {}}, ["y"] = 43, ["param1"] = 106, ["z"] = 6, ["name"] = "lottother:air"},
{["x"] = 5, ["meta"] = {["fields"] = {}, ["inventory"] = {}}, ["y"] = 43, ["param1"] = 121, ["z"] = 7, ["name"] = "lottother:air"},
{["x"] = 5, ["meta"] = {["fields"] = {}, ["inventory"] = {}}, ["y"] = 43, ["param1"] = 137, ["z"] = 8, ["name"] = "lottother:air"},
{["x"] = 5, ["meta"] = {["fields"] = {}, ["inventory"] = {}}, ["y"] = 43, ["param1"] = 153, ["z"] = 9, ["name"] = "lottother:air"},
{["x"] = 5, ["meta"] = {["fields"] = {}, ["inventory"] = {}}, ["y"] = 43, ["param1"] = 136, ["z"] = 10, ["name"] = "lottother:air"},
{["x"] = 5, ["meta"] = {["fields"] = {}, ["inventory"] = {}}, ["y"] = 43, ["param1"] = 153, ["z"] = 11, ["name"] = "lottother:air"},
{["x"] = 5, ["meta"] = {["fields"] = {}, ["inventory"] = {}}, ["y"] = 43, ["param1"] = 137, ["z"] = 12, ["name"] = "lottother:air"},
{["x"] = 5, ["meta"] = {["fields"] = {}, ["inventory"] = {}}, ["y"] = 43, ["param1"] = 122, ["z"] = 13, ["name"] = "lottother:air"},
{["x"] = 5, ["meta"] = {["fields"] = {}, ["inventory"] = {}}, ["y"] = 43, ["param1"] = 107, ["z"] = 14, ["name"] = "lottother:air"},
{["x"] = 5, ["meta"] = {["fields"] = {}, ["inventory"] = {}}, ["y"] = 44, ["param1"] = 75, ["z"] = 5, ["name"] = "lottother:air"},
{["x"] = 5, ["meta"] = {["fields"] = {}, ["inventory"] = {}}, ["y"] = 44, ["param1"] = 90, ["z"] = 6, ["name"] = "lottother:air"},
{["x"] = 5, ["meta"] = {["fields"] = {}, ["inventory"] = {}}, ["y"] = 44, ["param1"] = 105, ["z"] = 7, ["name"] = "lottother:air"},
{["x"] = 5, ["meta"] = {["fields"] = {}, ["inventory"] = {}}, ["y"] = 44, ["param1"] = 121, ["z"] = 8, ["name"] = "lottother:air"},
{["x"] = 5, ["meta"] = {["fields"] = {}, ["inventory"] = {}}, ["y"] = 44, ["param1"] = 137, ["z"] = 9, ["name"] = "lottother:air"},
{["x"] = 5, ["meta"] = {["fields"] = {}, ["inventory"] = {}}, ["y"] = 44, ["param1"] = 120, ["z"] = 10, ["name"] = "lottother:air"},
{["x"] = 5, ["meta"] = {["fields"] = {}, ["inventory"] = {}}, ["y"] = 44, ["param1"] = 136, ["z"] = 11, ["name"] = "lottother:air"},
{["x"] = 5, ["meta"] = {["fields"] = {}, ["inventory"] = {}}, ["y"] = 44, ["param1"] = 121, ["z"] = 12, ["name"] = "lottother:air"},
{["x"] = 5, ["meta"] = {["fields"] = {}, ["inventory"] = {}}, ["y"] = 44, ["param1"] = 106, ["z"] = 13, ["name"] = "lottother:air"},
{["x"] = 5, ["meta"] = {["fields"] = {}, ["inventory"] = {}}, ["y"] = 44, ["param1"] = 91, ["z"] = 14, ["name"] = "lottother:air"},
{["x"] = 5, ["meta"] = {["fields"] = {}, ["inventory"] = {}}, ["y"] = 45, ["param1"] = 59, ["z"] = 5, ["name"] = "lottother:air"},
{["x"] = 5, ["meta"] = {["fields"] = {}, ["inventory"] = {}}, ["y"] = 45, ["param1"] = 74, ["z"] = 6, ["name"] = "lottother:air"},
{["x"] = 5, ["meta"] = {["fields"] = {}, ["inventory"] = {}}, ["y"] = 45, ["param1"] = 89, ["z"] = 7, ["name"] = "lottother:air"},
{["x"] = 5, ["meta"] = {["fields"] = {}, ["inventory"] = {}}, ["y"] = 45, ["param1"] = 105, ["z"] = 8, ["name"] = "lottother:air"},
{["x"] = 5, ["meta"] = {["fields"] = {}, ["inventory"] = {}}, ["y"] = 45, ["param1"] = 121, ["z"] = 9, ["name"] = "lottother:air"},
{["x"] = 5, ["meta"] = {["fields"] = {}, ["inventory"] = {}}, ["y"] = 45, ["param1"] = 104, ["z"] = 10, ["name"] = "lottother:air"},
{["x"] = 5, ["meta"] = {["fields"] = {}, ["inventory"] = {}}, ["y"] = 45, ["param1"] = 120, ["z"] = 11, ["name"] = "lottother:air"},
{["x"] = 5, ["meta"] = {["fields"] = {}, ["inventory"] = {}}, ["y"] = 45, ["param1"] = 105, ["z"] = 12, ["name"] = "lottother:air"},
{["x"] = 5, ["meta"] = {["fields"] = {}, ["inventory"] = {}}, ["y"] = 45, ["param1"] = 90, ["z"] = 13, ["name"] = "lottother:air"},
{["x"] = 5, ["meta"] = {["fields"] = {}, ["inventory"] = {}}, ["y"] = 45, ["param1"] = 75, ["z"] = 14, ["name"] = "lottother:air"},
{["x"] = 5, ["meta"] = {["fields"] = {}, ["inventory"] = {}}, ["y"] = 46, ["param1"] = 43, ["z"] = 5, ["name"] = "lottother:air"},
{["x"] = 5, ["meta"] = {["fields"] = {}, ["inventory"] = {}}, ["y"] = 46, ["param1"] = 58, ["z"] = 6, ["name"] = "lottother:air"},
{["x"] = 5, ["meta"] = {["fields"] = {}, ["inventory"] = {}}, ["y"] = 46, ["param1"] = 73, ["z"] = 7, ["name"] = "lottother:air"},
{["x"] = 5, ["meta"] = {["fields"] = {}, ["inventory"] = {}}, ["y"] = 46, ["param1"] = 89, ["z"] = 8, ["name"] = "lottother:air"},
{["x"] = 5, ["meta"] = {["fields"] = {}, ["inventory"] = {}}, ["y"] = 46, ["param1"] = 105, ["z"] = 9, ["name"] = "lottother:air"},
{["x"] = 5, ["meta"] = {["fields"] = {}, ["inventory"] = {}}, ["y"] = 46, ["param1"] = 88, ["z"] = 10, ["name"] = "lottother:air"},
{["x"] = 5, ["meta"] = {["fields"] = {}, ["inventory"] = {}}, ["y"] = 46, ["param1"] = 104, ["z"] = 11, ["name"] = "lottother:air"},
{["x"] = 5, ["meta"] = {["fields"] = {}, ["inventory"] = {}}, ["y"] = 46, ["param1"] = 89, ["z"] = 12, ["name"] = "lottother:air"},
{["x"] = 5, ["meta"] = {["fields"] = {}, ["inventory"] = {}}, ["y"] = 46, ["param1"] = 74, ["z"] = 13, ["name"] = "lottother:air"},
{["x"] = 5, ["meta"] = {["fields"] = {}, ["inventory"] = {}}, ["y"] = 46, ["param1"] = 59, ["z"] = 14, ["name"] = "lottother:air"},
{["x"] = 5, ["meta"] = {["fields"] = {}, ["inventory"] = {}}, ["y"] = 47, ["param1"] = 27, ["z"] = 5, ["name"] = "lottother:air"},
{["x"] = 5, ["meta"] = {["fields"] = {}, ["inventory"] = {}}, ["y"] = 47, ["param1"] = 42, ["z"] = 6, ["name"] = "lottother:air"},
{["x"] = 5, ["meta"] = {["fields"] = {}, ["inventory"] = {}}, ["y"] = 47, ["param1"] = 57, ["z"] = 7, ["name"] = "lottother:air"},
{["x"] = 5, ["meta"] = {["fields"] = {}, ["inventory"] = {}}, ["y"] = 47, ["param1"] = 73, ["z"] = 8, ["name"] = "lottother:air"},
{["x"] = 5, ["meta"] = {["fields"] = {}, ["inventory"] = {}}, ["y"] = 47, ["param1"] = 89, ["z"] = 9, ["name"] = "lottother:air"},
{["x"] = 5, ["meta"] = {["fields"] = {}, ["inventory"] = {}}, ["y"] = 47, ["param1"] = 72, ["z"] = 10, ["name"] = "lottother:air"},
{["x"] = 5, ["meta"] = {["fields"] = {}, ["inventory"] = {}}, ["y"] = 47, ["param1"] = 88, ["z"] = 11, ["name"] = "lottother:air"},
{["x"] = 5, ["meta"] = {["fields"] = {}, ["inventory"] = {}}, ["y"] = 47, ["param1"] = 73, ["z"] = 12, ["name"] = "lottother:air"},
{["x"] = 5, ["meta"] = {["fields"] = {}, ["inventory"] = {}}, ["y"] = 47, ["param1"] = 58, ["z"] = 13, ["name"] = "lottother:air"},
{["x"] = 5, ["meta"] = {["fields"] = {}, ["inventory"] = {}}, ["y"] = 47, ["param1"] = 43, ["z"] = 14, ["name"] = "lottother:air"},
{["x"] = 5, ["meta"] = {["fields"] = {}, ["inventory"] = {}}, ["y"] = 48, ["param1"] = 12, ["z"] = 4, ["name"] = "lord_trees:mallorn_leaf"},
{["x"] = 5, ["meta"] = {["fields"] = {}, ["inventory"] = {}}, ["y"] = 48, ["param1"] = 11, ["z"] = 5, ["name"] = "lottother:air"},
{["x"] = 5, ["meta"] = {["fields"] = {}, ["inventory"] = {}}, ["y"] = 48, ["param1"] = 26, ["z"] = 6, ["name"] = "lottother:air"},
{["x"] = 5, ["meta"] = {["fields"] = {}, ["inventory"] = {}}, ["y"] = 48, ["param1"] = 41, ["z"] = 7, ["name"] = "lord_trees:mallorn_leaf"},
{["x"] = 5, ["meta"] = {["fields"] = {}, ["inventory"] = {}}, ["y"] = 48, ["param1"] = 57, ["z"] = 8, ["name"] = "lottother:air"},
{["x"] = 5, ["meta"] = {["fields"] = {}, ["inventory"] = {}}, ["y"] = 48, ["param1"] = 74, ["z"] = 9, ["name"] = "lord_trees:mallorn_leaf"},
{["x"] = 5, ["meta"] = {["fields"] = {}, ["inventory"] = {}}, ["y"] = 48, ["param1"] = 57, ["z"] = 10, ["name"] = "lottother:air"},
{["x"] = 5, ["meta"] = {["fields"] = {}, ["inventory"] = {}}, ["y"] = 48, ["param1"] = 72, ["z"] = 11, ["name"] = "lottother:air"},
{["x"] = 5, ["meta"] = {["fields"] = {}, ["inventory"] = {}}, ["y"] = 48, ["param1"] = 57, ["z"] = 12, ["name"] = "lord_trees:mallorn_leaf"},
{["x"] = 5, ["meta"] = {["fields"] = {}, ["inventory"] = {}}, ["y"] = 48, ["param1"] = 42, ["z"] = 13, ["name"] = "lottother:air"},
{["x"] = 5, ["meta"] = {["fields"] = {}, ["inventory"] = {}}, ["y"] = 48, ["param1"] = 27, ["z"] = 14, ["name"] = "lottother:air"},
{["x"] = 5, ["meta"] = {["fields"] = {}, ["inventory"] = {}}, ["y"] = 49, ["param1"] = 13, ["z"] = 3, ["name"] = "lord_trees:mallorn_leaf"},
{["x"] = 5, ["meta"] = {["fields"] = {}, ["inventory"] = {}}, ["y"] = 49, ["param1"] = 12, ["z"] = 4, ["name"] = "lord_trees:mallorn_leaf"},
{["x"] = 5, ["meta"] = {["fields"] = {}, ["inventory"] = {}}, ["y"] = 49, ["param1"] = 11, ["z"] = 5, ["name"] = "lottother:air"},
{["x"] = 5, ["meta"] = {["fields"] = {}, ["inventory"] = {}}, ["y"] = 49, ["param1"] = 10, ["z"] = 6, ["name"] = "lottother:air"},
{["x"] = 5, ["meta"] = {["fields"] = {}, ["inventory"] = {}}, ["y"] = 49, ["param1"] = 25, ["z"] = 7, ["name"] = "lottother:air"},
{["x"] = 5, ["meta"] = {["fields"] = {}, ["inventory"] = {}}, ["y"] = 49, ["param1"] = 42, ["z"] = 8, ["name"] = "lord_trees:mallorn_leaf"},
{["x"] = 5, ["meta"] = {["fields"] = {}, ["inventory"] = {}}, ["y"] = 49, ["param1"] = 59, ["z"] = 9, ["name"] = "lord_trees:mallorn_leaf"},
{["x"] = 5, ["meta"] = {["fields"] = {}, ["inventory"] = {}}, ["y"] = 49, ["param1"] = 42, ["z"] = 10, ["name"] = "lord_trees:mallorn_leaf"},
{["x"] = 5, ["meta"] = {["fields"] = {}, ["inventory"] = {}}, ["y"] = 49, ["param1"] = 57, ["z"] = 11, ["name"] = "lord_trees:mallorn_leaf"},
{["x"] = 5, ["meta"] = {["fields"] = {}, ["inventory"] = {}}, ["y"] = 49, ["param1"] = 42, ["z"] = 12, ["name"] = "lord_trees:mallorn_leaf"},
{["x"] = 5, ["meta"] = {["fields"] = {}, ["inventory"] = {}}, ["y"] = 49, ["param1"] = 26, ["z"] = 13, ["name"] = "lottother:air"},
{["x"] = 5, ["meta"] = {["fields"] = {}, ["inventory"] = {}}, ["y"] = 49, ["param1"] = 11, ["z"] = 14, ["name"] = "lottother:air"},
{["x"] = 5, ["meta"] = {["fields"] = {}, ["inventory"] = {}}, ["y"] = 50, ["param1"] = 12, ["z"] = 4, ["name"] = "lord_trees:mallorn_leaf"},
{["x"] = 5, ["meta"] = {["fields"] = {}, ["inventory"] = {}}, ["y"] = 50, ["param1"] = 12, ["z"] = 5, ["name"] = "lottother:air"},
{["x"] = 5, ["meta"] = {["fields"] = {}, ["inventory"] = {}}, ["y"] = 50, ["param1"] = 11, ["z"] = 6, ["name"] = "lord_trees:mallorn_leaf"},
{["x"] = 5, ["meta"] = {["fields"] = {}, ["inventory"] = {}}, ["y"] = 50, ["param1"] = 10, ["z"] = 7, ["name"] = "lord_trees:mallorn_leaf"},
{["x"] = 5, ["meta"] = {["fields"] = {}, ["inventory"] = {}}, ["y"] = 50, ["param1"] = 27, ["z"] = 8, ["name"] = "lord_trees:mallorn_leaf"},
{["x"] = 5, ["meta"] = {["fields"] = {}, ["inventory"] = {}}, ["y"] = 50, ["param1"] = 44, ["z"] = 9, ["name"] = "lord_trees:mallorn_leaf"},
{["x"] = 5, ["meta"] = {["fields"] = {}, ["inventory"] = {}}, ["y"] = 50, ["param1"] = 27, ["z"] = 10, ["name"] = "lord_trees:mallorn_leaf"},
{["x"] = 5, ["meta"] = {["fields"] = {}, ["inventory"] = {}}, ["y"] = 50, ["param1"] = 42, ["z"] = 11, ["name"] = "lord_trees:mallorn_leaf"},
{["x"] = 5, ["meta"] = {["fields"] = {}, ["inventory"] = {}}, ["y"] = 50, ["param1"] = 27, ["z"] = 12, ["name"] = "lord_trees:mallorn_leaf"},
{["x"] = 5, ["meta"] = {["fields"] = {}, ["inventory"] = {}}, ["y"] = 50, ["param1"] = 11, ["z"] = 13, ["name"] = "lottother:air"},
{["x"] = 5, ["meta"] = {["fields"] = {}, ["inventory"] = {}}, ["y"] = 50, ["param1"] = 11, ["z"] = 14, ["name"] = "lottother:air"},
{["x"] = 5, ["meta"] = {["fields"] = {}, ["inventory"] = {}}, ["y"] = 50, ["param1"] = 12, ["z"] = 15, ["name"] = "lord_trees:mallorn_leaf"},
{["x"] = 5, ["meta"] = {["fields"] = {}, ["inventory"] = {}}, ["y"] = 51, ["param1"] = 13, ["z"] = 3, ["name"] = "lord_trees:mallorn_leaf"},
{["x"] = 5, ["meta"] = {["fields"] = {}, ["inventory"] = {}}, ["y"] = 51, ["param1"] = 13, ["z"] = 4, ["name"] = "lord_trees:mallorn_leaf"},
{["x"] = 5, ["meta"] = {["fields"] = {}, ["inventory"] = {}}, ["y"] = 51, ["param1"] = 13, ["z"] = 5, ["name"] = "lord_trees:mallorn_leaf"},
{["x"] = 5, ["meta"] = {["fields"] = {}, ["inventory"] = {}}, ["param2"] = 1, ["y"] = 51, ["z"] = 6, ["name"] = "lord_trees:mallorn_tree"},
{["x"] = 5, ["meta"] = {["fields"] = {}, ["inventory"] = {}}, ["param2"] = 1, ["y"] = 51, ["z"] = 7, ["name"] = "lord_trees:mallorn_tree"},
{["x"] = 5, ["meta"] = {["fields"] = {}, ["inventory"] = {}}, ["param2"] = 3, ["y"] = 51, ["z"] = 8, ["name"] = "lord_trees:mallorn_tree"},
{["x"] = 5, ["meta"] = {["fields"] = {}, ["inventory"] = {}}, ["y"] = 51, ["param1"] = 29, ["z"] = 9, ["name"] = "lord_trees:mallorn_leaf"},
{["x"] = 5, ["meta"] = {["fields"] = {}, ["inventory"] = {}}, ["y"] = 51, ["param1"] = 12, ["z"] = 10, ["name"] = "lord_trees:mallorn_leaf"},
{["x"] = 5, ["meta"] = {["fields"] = {}, ["inventory"] = {}}, ["param2"] = 3, ["y"] = 51, ["z"] = 11, ["name"] = "lord_trees:mallorn_tree"},
{["x"] = 5, ["meta"] = {["fields"] = {}, ["inventory"] = {}}, ["y"] = 51, ["param1"] = 12, ["z"] = 12, ["name"] = "lord_trees:mallorn_leaf"},
{["x"] = 5, ["meta"] = {["fields"] = {}, ["inventory"] = {}}, ["y"] = 51, ["param1"] = 12, ["z"] = 13, ["name"] = "lord_trees:mallorn_leaf"},
{["x"] = 5, ["meta"] = {["fields"] = {}, ["inventory"] = {}}, ["y"] = 51, ["param1"] = 12, ["z"] = 14, ["name"] = "lord_trees:mallorn_leaf"},
{["x"] = 5, ["meta"] = {["fields"] = {}, ["inventory"] = {}}, ["y"] = 51, ["param1"] = 12, ["z"] = 15, ["name"] = "lord_trees:mallorn_leaf"},
{["x"] = 5, ["meta"] = {["fields"] = {}, ["inventory"] = {}}, ["y"] = 51, ["param1"] = 13, ["z"] = 16, ["name"] = "lord_trees:mallorn_leaf"},
{["x"] = 5, ["meta"] = {["fields"] = {}, ["inventory"] = {}}, ["y"] = 52, ["param1"] = 13, ["z"] = 3, ["name"] = "lord_trees:mallorn_leaf"},
{["x"] = 5, ["meta"] = {["fields"] = {}, ["inventory"] = {}}, ["y"] = 52, ["param1"] = 13, ["z"] = 6, ["name"] = "lord_trees:mallorn_leaf"},
{["x"] = 5, ["meta"] = {["fields"] = {}, ["inventory"] = {}}, ["y"] = 52, ["param1"] = 13, ["z"] = 8, ["name"] = "lord_trees:mallorn_leaf"},
{["x"] = 5, ["meta"] = {["fields"] = {}, ["inventory"] = {}}, ["y"] = 52, ["param1"] = 13, ["z"] = 10, ["name"] = "lord_trees:mallorn_leaf"},
{["x"] = 5, ["meta"] = {["fields"] = {}, ["inventory"] = {}}, ["y"] = 52, ["param1"] = 12, ["z"] = 11, ["name"] = "lord_trees:mallorn_leaf"},
{["x"] = 5, ["meta"] = {["fields"] = {}, ["inventory"] = {}}, ["y"] = 52, ["param1"] = 13, ["z"] = 12, ["name"] = "lord_trees:mallorn_leaf"},
{["x"] = 5, ["meta"] = {["fields"] = {}, ["inventory"] = {}}, ["y"] = 52, ["param1"] = 13, ["z"] = 13, ["name"] = "lord_trees:mallorn_leaf"},
{["x"] = 5, ["meta"] = {["fields"] = {}, ["inventory"] = {}}, ["y"] = 52, ["param1"] = 13, ["z"] = 14, ["name"] = "lord_trees:mallorn_leaf"},
{["x"] = 5, ["meta"] = {["fields"] = {}, ["inventory"] = {}}, ["y"] = 52, ["param1"] = 13, ["z"] = 15, ["name"] = "lord_trees:mallorn_leaf"},
{["x"] = 5, ["meta"] = {["fields"] = {}, ["inventory"] = {}}, ["y"] = 53, ["param1"] = 13, ["z"] = 8, ["name"] = "lord_trees:mallorn_leaf"},
{["x"] = 5, ["meta"] = {["fields"] = {}, ["inventory"] = {}}, ["y"] = 53, ["param1"] = 13, ["z"] = 10, ["name"] = "lord_trees:mallorn_leaf"},
{["x"] = 5, ["meta"] = {["fields"] = {}, ["inventory"] = {}}, ["y"] = 53, ["param1"] = 13, ["z"] = 11, ["name"] = "lord_trees:mallorn_leaf"},
{["x"] = 6, ["meta"] = {["fields"] = {}, ["inventory"] = {}}, ["y"] = 0, ["z"] = 5, ["name"] = "lottother:dirt"},
{["x"] = 6, ["meta"] = {["fields"] = {}, ["inventory"] = {}}, ["y"] = 0, ["z"] = 6, ["name"] = "lottother:dirt"},
{["x"] = 6, ["meta"] = {["fields"] = {}, ["inventory"] = {}}, ["y"] = 0, ["z"] = 7, ["name"] = "lottother:dirt"},
{["x"] = 6, ["meta"] = {["fields"] = {}, ["inventory"] = {}}, ["y"] = 0, ["z"] = 8, ["name"] = "lottother:dirt"},
{["x"] = 6, ["meta"] = {["fields"] = {}, ["inventory"] = {}}, ["y"] = 0, ["z"] = 9, ["name"] = "lottother:dirt"},
{["x"] = 6, ["meta"] = {["fields"] = {}, ["inventory"] = {}}, ["y"] = 0, ["z"] = 10, ["name"] = "lottother:dirt"},
{["x"] = 6, ["meta"] = {["fields"] = {}, ["inventory"] = {}}, ["y"] = 0, ["z"] = 11, ["name"] = "lottother:dirt"},
{["x"] = 6, ["meta"] = {["fields"] = {}, ["inventory"] = {}}, ["y"] = 0, ["z"] = 12, ["name"] = "lottother:dirt"},
{["x"] = 6, ["meta"] = {["fields"] = {}, ["inventory"] = {}}, ["y"] = 0, ["z"] = 13, ["name"] = "lottother:dirt"},
{["x"] = 6, ["meta"] = {["fields"] = {}, ["inventory"] = {}}, ["y"] = 0, ["z"] = 14, ["name"] = "lottother:dirt"},
{["x"] = 6, ["meta"] = {["fields"] = {}, ["inventory"] = {}}, ["y"] = 1, ["param1"] = 10, ["z"] = 5, ["name"] = "lord_ground:dirt_lorien"},
{["x"] = 6, ["meta"] = {["fields"] = {}, ["inventory"] = {}}, ["y"] = 1, ["z"] = 6, ["name"] = "lord_ground:dirt_lorien"},
{["x"] = 6, ["meta"] = {["fields"] = {}, ["inventory"] = {}}, ["y"] = 1, ["param1"] = 8, ["z"] = 7, ["name"] = "lord_ground:dirt_lorien"},
{["x"] = 6, ["meta"] = {["fields"] = {}, ["inventory"] = {}}, ["y"] = 1, ["param1"] = 9, ["z"] = 8, ["name"] = "lord_ground:dirt_lorien"},
{["x"] = 6, ["meta"] = {["fields"] = {}, ["inventory"] = {}}, ["y"] = 1, ["z"] = 9, ["name"] = "lord_ground:dirt_lorien"},
{["x"] = 6, ["meta"] = {["fields"] = {}, ["inventory"] = {}}, ["y"] = 1, ["z"] = 10, ["name"] = "default:dirt"},
{["x"] = 6, ["meta"] = {["fields"] = {}, ["inventory"] = {}}, ["y"] = 1, ["z"] = 11, ["name"] = "default:dirt"},
{["x"] = 6, ["meta"] = {["fields"] = {}, ["inventory"] = {}}, ["y"] = 1, ["z"] = 12, ["name"] = "default:dirt"},
{["x"] = 6, ["meta"] = {["fields"] = {}, ["inventory"] = {}}, ["y"] = 1, ["z"] = 13, ["name"] = "default:dirt"},
{["x"] = 6, ["meta"] = {["fields"] = {}, ["inventory"] = {}}, ["y"] = 1, ["param1"] = 10, ["z"] = 14, ["name"] = "lord_ground:dirt_lorien"},
{["x"] = 6, ["meta"] = {["fields"] = {}, ["inventory"] = {}}, ["y"] = 2, ["param1"] = 10, ["z"] = 5, ["name"] = "lottother:air"},
{["x"] = 6, ["meta"] = {["fields"] = {}, ["inventory"] = {}}, ["y"] = 2, ["param1"] = 9, ["z"] = 6, ["name"] = "lottother:air"},
{["x"] = 6, ["meta"] = {["fields"] = {}, ["inventory"] = {}}, ["y"] = 2, ["param1"] = 8, ["z"] = 7, ["name"] = "lottother:air"},
{["x"] = 6, ["meta"] = {["fields"] = {}, ["inventory"] = {}}, ["y"] = 2, ["param1"] = 8, ["z"] = 8, ["name"] = "lottother:air"},
{["x"] = 6, ["meta"] = {["fields"] = {}, ["inventory"] = {}}, ["y"] = 2, ["param1"] = 8, ["z"] = 9, ["name"] = "lottother:air"},
{["x"] = 6, ["meta"] = {["fields"] = {}, ["inventory"] = {}}, ["param2"] = 1, ["y"] = 2, ["z"] = 10, ["name"] = "lord_trees:mallorn_tree"},
{["x"] = 6, ["meta"] = {["fields"] = {}, ["inventory"] = {}}, ["param2"] = 1, ["y"] = 2, ["z"] = 11, ["name"] = "lord_trees:mallorn_tree"},
{["x"] = 6, ["meta"] = {["fields"] = {}, ["inventory"] = {}}, ["param2"] = 2, ["y"] = 2, ["z"] = 12, ["name"] = "lord_trees:mallorn_tree"},
{["x"] = 6, ["meta"] = {["fields"] = {}, ["inventory"] = {}}, ["param2"] = 3, ["y"] = 2, ["z"] = 13, ["name"] = "lord_trees:mallorn_tree"},
{["x"] = 6, ["meta"] = {["fields"] = {}, ["inventory"] = {}}, ["y"] = 2, ["param1"] = 10, ["z"] = 14, ["name"] = "lottother:air"},
{["x"] = 6, ["meta"] = {["fields"] = {}, ["inventory"] = {}}, ["y"] = 3, ["param1"] = 10, ["z"] = 5, ["name"] = "lottother:air"},
{["x"] = 6, ["meta"] = {["fields"] = {}, ["inventory"] = {}}, ["y"] = 3, ["param1"] = 9, ["z"] = 6, ["name"] = "lottother:air"},
{["x"] = 6, ["meta"] = {["fields"] = {}, ["inventory"] = {}}, ["y"] = 3, ["param1"] = 8, ["z"] = 7, ["name"] = "lottother:air"},
{["x"] = 6, ["meta"] = {["fields"] = {}, ["inventory"] = {}}, ["y"] = 3, ["param1"] = 8, ["z"] = 8, ["name"] = "lottother:air"},
{["x"] = 6, ["meta"] = {["fields"] = {}, ["inventory"] = {}}, ["y"] = 3, ["param1"] = 8, ["z"] = 9, ["name"] = "lottother:air"},
{["x"] = 6, ["meta"] = {["fields"] = {}, ["inventory"] = {}}, ["param2"] = 1, ["y"] = 3, ["z"] = 10, ["name"] = "lord_trees:mallorn_tree"},
{["x"] = 6, ["meta"] = {["fields"] = {}, ["inventory"] = {}}, ["param2"] = 2, ["y"] = 3, ["z"] = 11, ["name"] = "lord_trees:mallorn_tree"},
{["x"] = 6, ["meta"] = {["fields"] = {}, ["inventory"] = {}}, ["param2"] = 2, ["y"] = 3, ["z"] = 12, ["name"] = "lord_trees:mallorn_tree"},
{["x"] = 6, ["meta"] = {["fields"] = {}, ["inventory"] = {}}, ["y"] = 3, ["param1"] = 9, ["z"] = 13, ["name"] = "lottother:air"},
{["x"] = 6, ["meta"] = {["fields"] = {}, ["inventory"] = {}}, ["y"] = 3, ["param1"] = 10, ["z"] = 14, ["name"] = "lottother:air"},
{["x"] = 6, ["meta"] = {["fields"] = {}, ["inventory"] = {}}, ["y"] = 4, ["param1"] = 10, ["z"] = 5, ["name"] = "lottother:air"},
{["x"] = 6, ["meta"] = {["fields"] = {}, ["inventory"] = {}}, ["y"] = 4, ["param1"] = 9, ["z"] = 6, ["name"] = "lottother:air"},
{["x"] = 6, ["meta"] = {["fields"] = {}, ["inventory"] = {}}, ["y"] = 4, ["param1"] = 8, ["z"] = 7, ["name"] = "lottother:air"},
{["x"] = 6, ["meta"] = {["fields"] = {}, ["inventory"] = {}}, ["y"] = 4, ["param1"] = 8, ["z"] = 8, ["name"] = "lottother:air"},
{["x"] = 6, ["meta"] = {["fields"] = {}, ["inventory"] = {}}, ["y"] = 4, ["param1"] = 8, ["z"] = 9, ["name"] = "lottother:air"},
{["x"] = 6, ["meta"] = {["fields"] = {}, ["inventory"] = {}}, ["param2"] = 1, ["y"] = 4, ["z"] = 10, ["name"] = "lord_trees:mallorn_tree"},
{["x"] = 6, ["meta"] = {["fields"] = {}, ["inventory"] = {}}, ["param2"] = 2, ["y"] = 4, ["z"] = 11, ["name"] = "lord_trees:mallorn_tree"},
{["x"] = 6, ["meta"] = {["fields"] = {}, ["inventory"] = {}}, ["param2"] = 2, ["y"] = 4, ["z"] = 12, ["name"] = "lord_trees:mallorn_tree"},
{["x"] = 6, ["meta"] = {["fields"] = {}, ["inventory"] = {}}, ["y"] = 4, ["param1"] = 9, ["z"] = 13, ["name"] = "lottother:air"},
{["x"] = 6, ["meta"] = {["fields"] = {}, ["inventory"] = {}}, ["y"] = 4, ["param1"] = 10, ["z"] = 14, ["name"] = "lottother:air"},
{["x"] = 6, ["meta"] = {["fields"] = {}, ["inventory"] = {}}, ["y"] = 5, ["param1"] = 10, ["z"] = 5, ["name"] = "lottother:air"},
{["x"] = 6, ["meta"] = {["fields"] = {}, ["inventory"] = {}}, ["y"] = 5, ["param1"] = 9, ["z"] = 6, ["name"] = "lottother:air"},
{["x"] = 6, ["meta"] = {["fields"] = {}, ["inventory"] = {}}, ["y"] = 5, ["param1"] = 8, ["z"] = 7, ["name"] = "lottother:air"},
{["x"] = 6, ["meta"] = {["fields"] = {}, ["inventory"] = {}}, ["y"] = 5, ["param1"] = 8, ["z"] = 8, ["name"] = "lottother:air"},
{["x"] = 6, ["meta"] = {["fields"] = {}, ["inventory"] = {}}, ["y"] = 5, ["param1"] = 8, ["z"] = 9, ["name"] = "lottother:air"},
{["x"] = 6, ["meta"] = {["fields"] = {}, ["inventory"] = {}}, ["param2"] = 1, ["y"] = 5, ["z"] = 10, ["name"] = "lord_trees:mallorn_tree"},
{["x"] = 6, ["meta"] = {["fields"] = {}, ["inventory"] = {}}, ["param2"] = 2, ["y"] = 5, ["z"] = 11, ["name"] = "lord_trees:mallorn_tree"},
{["x"] = 6, ["meta"] = {["fields"] = {}, ["inventory"] = {}}, ["param2"] = 2, ["y"] = 5, ["z"] = 12, ["name"] = "lord_trees:mallorn_tree"},
{["x"] = 6, ["meta"] = {["fields"] = {}, ["inventory"] = {}}, ["y"] = 5, ["param1"] = 9, ["z"] = 13, ["name"] = "lottother:air"},
{["x"] = 6, ["meta"] = {["fields"] = {}, ["inventory"] = {}}, ["y"] = 5, ["param1"] = 10, ["z"] = 14, ["name"] = "lottother:air"},
