return {
{["x"] = 0, ["meta"] = { ["fields"] = {}, ["inventory"] = {} }, ["param2"] = 0, ["y"] = 53, ["param1"] = 29, ["z"] = 8, ["name"] = "lord_trees:mallorn_leaf" },
{["x"] = 0, ["meta"] = { ["fields"] = {}, ["inventory"] = {} }, ["param2"] = 0, ["y"] = 53, ["param1"] = 29, ["z"] = 9, ["name"] = "lord_trees:mallorn_leaf" },
{["x"] = 0, ["meta"] = { ["fields"] = {}, ["inventory"] = {} }, ["param2"] = 0, ["y"] = 53, ["param1"] = 13, ["z"] = 10, ["name"] = "lord_trees:mallorn_leaf" },
{["x"] = 1, ["meta"] = { ["fields"] = {}, ["inventory"] = {} }, ["param2"] = 0, ["y"] = 53, ["param1"] = 45, ["z"] = 8, ["name"] = "lord_trees:mallorn_leaf" },
{["x"] = 1, ["meta"] = { ["fields"] = {}, ["inventory"] = {} }, ["param2"] = 0, ["y"] = 53, ["param1"] = 45, ["z"] = 9, ["name"] = "lord_trees:mallorn_leaf" },
{["x"] = 1, ["meta"] = { ["fields"] = {}, ["inventory"] = {} }, ["param2"] = 0, ["y"] = 53, ["param1"] = 28, ["z"] = 10, ["name"] = "lord_trees:mallorn_leaf" },
{["x"] = 1, ["meta"] = { ["fields"] = {}, ["inventory"] = {} }, ["param2"] = 0, ["y"] = 53, ["param1"] = 13, ["z"] = 11, ["name"] = "lord_trees:mallorn_leaf" },
{["x"] = 1, ["meta"] = { ["fields"] = {}, ["inventory"] = {} }, ["param2"] = 0, ["y"] = 53, ["param1"] = 13, ["z"] = 12, ["name"] = "lord_trees:mallorn_leaf" },
{["x"] = 1, ["meta"] = { ["fields"] = {}, ["inventory"] = {} }, ["param2"] = 0, ["y"] = 53, ["param1"] = 13, ["z"] = 13, ["name"] = "lord_trees:mallorn_leaf" },
{["x"] = 1, ["meta"] = { ["fields"] = {}, ["inventory"] = {} }, ["param2"] = 0, ["y"] = 54, ["param1"] = 13, ["z"] = 10, ["name"] = "lord_trees:mallorn_leaf" },
{["x"] = 2, ["meta"] = { ["fields"] = {}, ["inventory"] = {} }, ["param2"] = 0, ["y"] = 0, ["param1"] = 13, ["z"] = 5, ["name"] = "lottother:dirt" },
{["x"] = 2, ["meta"] = { ["fields"] = {}, ["inventory"] = {} }, ["param2"] = 0, ["y"] = 0, ["param1"] = 13, ["z"] = 6, ["name"] = "lottother:dirt" },
{["x"] = 2, ["meta"] = { ["fields"] = {}, ["inventory"] = {} }, ["param2"] = 0, ["y"] = 0, ["param1"] = 13, ["z"] = 7, ["name"] = "lottother:dirt" },
{["x"] = 2, ["meta"] = { ["fields"] = {}, ["inventory"] = {} }, ["param2"] = 0, ["y"] = 0, ["param1"] = 12, ["z"] = 8, ["name"] = "lottother:dirt" },
{["x"] = 2, ["meta"] = { ["fields"] = {}, ["inventory"] = {} }, ["param2"] = 0, ["y"] = 0, ["param1"] = 11, ["z"] = 9, ["name"] = "lottother:dirt" },
{["x"] = 2, ["meta"] = { ["fields"] = {}, ["inventory"] = {} }, ["param2"] = 0, ["y"] = 0, ["param1"] = 11, ["z"] = 10, ["name"] = "lottother:dirt" },
{["x"] = 2, ["meta"] = { ["fields"] = {}, ["inventory"] = {} }, ["param2"] = 0, ["y"] = 0, ["param1"] = 12, ["z"] = 11, ["name"] = "lottother:dirt" },
{["x"] = 2, ["meta"] = { ["fields"] = {}, ["inventory"] = {} }, ["param2"] = 0, ["y"] = 0, ["param1"] = 12, ["z"] = 12, ["name"] = "lottother:dirt" },
{["x"] = 2, ["meta"] = { ["fields"] = {}, ["inventory"] = {} }, ["param2"] = 0, ["y"] = 1, ["param1"] = 0, ["z"] = 5, ["name"] = "lottmapgen:lorien_grass" },
{["x"] = 2, ["meta"] = { ["fields"] = {}, ["inventory"] = {} }, ["param2"] = 0, ["y"] = 1, ["param1"] = 0, ["z"] = 6, ["name"] = "lottmapgen:lorien_grass" },
{["x"] = 2, ["meta"] = { ["fields"] = {}, ["inventory"] = {} }, ["param2"] = 0, ["y"] = 1, ["param1"] = 0, ["z"] = 7, ["name"] = "lottmapgen:lorien_grass" },
{["x"] = 2, ["meta"] = { ["fields"] = {}, ["inventory"] = {} }, ["param2"] = 0, ["y"] = 1, ["param1"] = 0, ["z"] = 8, ["name"] = "lottmapgen:lorien_grass" },
{["x"] = 2, ["meta"] = { ["fields"] = {}, ["inventory"] = {} }, ["param2"] = 0, ["y"] = 1, ["param1"] = 0, ["z"] = 9, ["name"] = "lottmapgen:lorien_grass" },
{["x"] = 2, ["meta"] = { ["fields"] = {}, ["inventory"] = {} }, ["param2"] = 0, ["y"] = 1, ["param1"] = 0, ["z"] = 10, ["name"] = "lottmapgen:lorien_grass" },
{["x"] = 2, ["meta"] = { ["fields"] = {}, ["inventory"] = {} }, ["param2"] = 0, ["y"] = 1, ["param1"] = 0, ["z"] = 11, ["name"] = "lottmapgen:lorien_grass" },
{["x"] = 2, ["meta"] = { ["fields"] = {}, ["inventory"] = {} }, ["param2"] = 0, ["y"] = 1, ["param1"] = 0, ["z"] = 12, ["name"] = "lottmapgen:lorien_grass" },
{["x"] = 2, ["meta"] = { ["fields"] = {}, ["inventory"] = {} }, ["param2"] = 0, ["y"] = 53, ["param1"] = 13, ["z"] = 5, ["name"] = "lord_trees:mallorn_leaf" },
{["x"] = 2, ["meta"] = { ["fields"] = {}, ["inventory"] = {} }, ["param2"] = 0, ["y"] = 53, ["param1"] = 29, ["z"] = 6, ["name"] = "lord_trees:mallorn_leaf" },
{["x"] = 2, ["meta"] = { ["fields"] = {}, ["inventory"] = {} }, ["param2"] = 0, ["y"] = 53, ["param1"] = 45, ["z"] = 7, ["name"] = "lord_trees:mallorn_leaf" },
{["x"] = 2, ["meta"] = { ["fields"] = {}, ["inventory"] = {} }, ["param2"] = 0, ["y"] = 53, ["param1"] = 61, ["z"] = 8, ["name"] = "lord_trees:mallorn_leaf" },
{["x"] = 2, ["meta"] = { ["fields"] = {}, ["inventory"] = {} }, ["param2"] = 0, ["y"] = 53, ["param1"] = 0, ["z"] = 9, ["name"] = "lord_trees:mallorn_tree" },
{["x"] = 2, ["meta"] = { ["fields"] = {}, ["inventory"] = {} }, ["param2"] = 0, ["y"] = 53, ["param1"] = 44, ["z"] = 10, ["name"] = "lord_trees:mallorn_leaf" },
{["x"] = 2, ["meta"] = { ["fields"] = {}, ["inventory"] = {} }, ["param2"] = 0, ["y"] = 53, ["param1"] = 29, ["z"] = 11, ["name"] = "lord_trees:mallorn_leaf" },
{["x"] = 2, ["meta"] = { ["fields"] = {}, ["inventory"] = {} }, ["param2"] = 0, ["y"] = 53, ["param1"] = 13, ["z"] = 12, ["name"] = "lord_trees:mallorn_leaf" },
{["x"] = 2, ["meta"] = { ["fields"] = {}, ["inventory"] = {} }, ["param2"] = 0, ["y"] = 53, ["param1"] = 13, ["z"] = 13, ["name"] = "lord_trees:mallorn_leaf" },
{["x"] = 2, ["meta"] = { ["fields"] = {}, ["inventory"] = {} }, ["param2"] = 0, ["y"] = 54, ["param1"] = 13, ["z"] = 6, ["name"] = "lord_trees:mallorn_leaf" },
{["x"] = 2, ["meta"] = { ["fields"] = {}, ["inventory"] = {} }, ["param2"] = 0, ["y"] = 54, ["param1"] = 45, ["z"] = 9, ["name"] = "lord_trees:mallorn_leaf" },
{["x"] = 2, ["meta"] = { ["fields"] = {}, ["inventory"] = {} }, ["param2"] = 0, ["y"] = 54, ["param1"] = 29, ["z"] = 10, ["name"] = "lord_trees:mallorn_leaf" },
{["x"] = 2, ["meta"] = { ["fields"] = {}, ["inventory"] = {} }, ["param2"] = 0, ["y"] = 54, ["param1"] = 13, ["z"] = 13, ["name"] = "lord_trees:mallorn_leaf" },
{["x"] = 3, ["meta"] = { ["fields"] = {}, ["inventory"] = {} }, ["param2"] = 0, ["y"] = 0, ["param1"] = 12, ["z"] = 5, ["name"] = "lottother:dirt" },
{["x"] = 3, ["meta"] = { ["fields"] = {}, ["inventory"] = {} }, ["param2"] = 0, ["y"] = 0, ["param1"] = 12, ["z"] = 6, ["name"] = "lottother:dirt" },
{["x"] = 3, ["meta"] = { ["fields"] = {}, ["inventory"] = {} }, ["param2"] = 0, ["y"] = 0, ["param1"] = 12, ["z"] = 7, ["name"] = "lottother:dirt" },
{["x"] = 3, ["meta"] = { ["fields"] = {}, ["inventory"] = {} }, ["param2"] = 0, ["y"] = 0, ["param1"] = 11, ["z"] = 8, ["name"] = "lottother:dirt" },
{["x"] = 3, ["meta"] = { ["fields"] = {}, ["inventory"] = {} }, ["param2"] = 0, ["y"] = 0, ["param1"] = 10, ["z"] = 9, ["name"] = "lottother:dirt" },
{["x"] = 3, ["meta"] = { ["fields"] = {}, ["inventory"] = {} }, ["param2"] = 0, ["y"] = 0, ["param1"] = 10, ["z"] = 10, ["name"] = "lottother:dirt" },
{["x"] = 3, ["meta"] = { ["fields"] = {}, ["inventory"] = {} }, ["param2"] = 0, ["y"] = 0, ["param1"] = 11, ["z"] = 11, ["name"] = "lottother:dirt" },
{["x"] = 3, ["meta"] = { ["fields"] = {}, ["inventory"] = {} }, ["param2"] = 0, ["y"] = 0, ["param1"] = 11, ["z"] = 12, ["name"] = "lottother:dirt" },
{["x"] = 3, ["meta"] = { ["fields"] = {}, ["inventory"] = {} }, ["param2"] = 0, ["y"] = 0, ["param1"] = 12, ["z"] = 13, ["name"] = "lottother:dirt" },
{["x"] = 3, ["meta"] = { ["fields"] = {}, ["inventory"] = {} }, ["param2"] = 0, ["y"] = 1, ["param1"] = 0, ["z"] = 5, ["name"] = "lottmapgen:lorien_grass" },
{["x"] = 3, ["meta"] = { ["fields"] = {}, ["inventory"] = {} }, ["param2"] = 0, ["y"] = 1, ["param1"] = 0, ["z"] = 6, ["name"] = "lottother:dirt" },
{["x"] = 3, ["meta"] = { ["fields"] = {}, ["inventory"] = {} }, ["param2"] = 0, ["y"] = 1, ["param1"] = 0, ["z"] = 7, ["name"] = "lottother:dirt" },
{["x"] = 3, ["meta"] = { ["fields"] = {}, ["inventory"] = {} }, ["param2"] = 0, ["y"] = 1, ["param1"] = 0, ["z"] = 8, ["name"] = "lottother:dirt" },
{["x"] = 3, ["meta"] = { ["fields"] = {}, ["inventory"] = {} }, ["param2"] = 0, ["y"] = 1, ["param1"] = 0, ["z"] = 9, ["name"] = "lottother:dirt" },
{["x"] = 3, ["meta"] = { ["fields"] = {}, ["inventory"] = {} }, ["param2"] = 0, ["y"] = 1, ["param1"] = 0, ["z"] = 10, ["name"] = "lottother:dirt" },
{["x"] = 3, ["meta"] = { ["fields"] = {}, ["inventory"] = {} }, ["param2"] = 0, ["y"] = 1, ["param1"] = 0, ["z"] = 11, ["name"] = "lottmapgen:lorien_grass" },
{["x"] = 3, ["meta"] = { ["fields"] = {}, ["inventory"] = {} }, ["param2"] = 0, ["y"] = 1, ["param1"] = 0, ["z"] = 12, ["name"] = "lottmapgen:lorien_grass" },
{["x"] = 3, ["meta"] = { ["fields"] = {}, ["inventory"] = {} }, ["param2"] = 0, ["y"] = 1, ["param1"] = 0, ["z"] = 13, ["name"] = "lottmapgen:lorien_grass" },
{["x"] = 3, ["meta"] = { ["fields"] = {}, ["inventory"] = {} }, ["param2"] = 0, ["y"] = 2, ["param1"] = 0, ["z"] = 6, ["name"] = "lottmapgen:lorien_grass" },
{["x"] = 3, ["meta"] = { ["fields"] = {}, ["inventory"] = {} }, ["param2"] = 0, ["y"] = 2, ["param1"] = 0, ["z"] = 7, ["name"] = "lottmapgen:lorien_grass" },
{["x"] = 3, ["meta"] = { ["fields"] = {}, ["inventory"] = {} }, ["param2"] = 0, ["y"] = 2, ["param1"] = 0, ["z"] = 8, ["name"] = "lottmapgen:lorien_grass" },
{["x"] = 3, ["meta"] = { ["fields"] = {}, ["inventory"] = {} }, ["param2"] = 0, ["y"] = 2, ["param1"] = 0, ["z"] = 9, ["name"] = "lottmapgen:lorien_grass" },
{["x"] = 3, ["meta"] = { ["fields"] = {}, ["inventory"] = {} }, ["param2"] = 0, ["y"] = 2, ["param1"] = 0, ["z"] = 10, ["name"] = "lottmapgen:lorien_grass" },
{["x"] = 3, ["meta"] = { ["fields"] = {}, ["inventory"] = {} }, ["param2"] = 0, ["y"] = 3, ["param1"] = 12, ["z"] = 7, ["name"] = "lottother:air" },
{["x"] = 3, ["meta"] = { ["fields"] = {}, ["inventory"] = {} }, ["param2"] = 0, ["y"] = 3, ["param1"] = 11, ["z"] = 8, ["name"] = "lottother:air" },
{["x"] = 3, ["meta"] = { ["fields"] = {}, ["inventory"] = {} }, ["param2"] = 0, ["y"] = 3, ["param1"] = 10, ["z"] = 9, ["name"] = "lottother:air" },
{["x"] = 3, ["meta"] = { ["fields"] = {}, ["inventory"] = {} }, ["param2"] = 0, ["y"] = 4, ["param1"] = 12, ["z"] = 7, ["name"] = "lottother:air" },
{["x"] = 3, ["meta"] = { ["fields"] = {}, ["inventory"] = {} }, ["param2"] = 0, ["y"] = 4, ["param1"] = 11, ["z"] = 8, ["name"] = "lottother:air" },
{["x"] = 3, ["meta"] = { ["fields"] = {}, ["inventory"] = {} }, ["param2"] = 0, ["y"] = 4, ["param1"] = 10, ["z"] = 9, ["name"] = "lottother:air" },
{["x"] = 3, ["meta"] = { ["fields"] = {}, ["inventory"] = {} }, ["param2"] = 0, ["y"] = 5, ["param1"] = 12, ["z"] = 7, ["name"] = "lottother:air" },
{["x"] = 3, ["meta"] = { ["fields"] = {}, ["inventory"] = {} }, ["param2"] = 0, ["y"] = 5, ["param1"] = 11, ["z"] = 8, ["name"] = "lottother:air" },
{["x"] = 3, ["meta"] = { ["fields"] = {}, ["inventory"] = {} }, ["param2"] = 0, ["y"] = 5, ["param1"] = 10, ["z"] = 9, ["name"] = "lottother:air" },
{["x"] = 3, ["meta"] = { ["fields"] = {}, ["inventory"] = {} }, ["param2"] = 0, ["y"] = 6, ["param1"] = 11, ["z"] = 8, ["name"] = "lottother:air" },
{["x"] = 3, ["meta"] = { ["fields"] = {}, ["inventory"] = {} }, ["param2"] = 0, ["y"] = 25, ["param1"] = 0, ["z"] = 6, ["name"] = "lord_planks:mallorn" },
{["x"] = 3, ["meta"] = { ["fields"] = {}, ["inventory"] = {} }, ["param2"] = 0, ["y"] = 25, ["param1"] = 0, ["z"] = 7, ["name"] = "lord_planks:mallorn" },
{["x"] = 3, ["meta"] = { ["fields"] = {}, ["inventory"] = {} }, ["param2"] = 0, ["y"] = 26, ["param1"] = 204, ["z"] = 6, ["name"] = "default:fence_wood" },
{["x"] = 3, ["meta"] = { ["fields"] = {}, ["inventory"] = {} }, ["param2"] = 0, ["y"] = 26, ["param1"] = 188, ["z"] = 7, ["name"] = "default:fence_wood" },
{["x"] = 3, ["meta"] = { ["fields"] = {}, ["inventory"] = {} }, ["param2"] = 1, ["y"] = 27, ["param1"] = 0, ["z"] = 6, ["name"] = "lottother:blue_torch" },
{["x"] = 3, ["meta"] = { ["fields"] = {}, ["inventory"] = {} }, ["param2"] = 0, ["y"] = 27, ["param1"] = 204, ["z"] = 7, ["name"] = "lottother:air" },
{["x"] = 3, ["meta"] = { ["fields"] = {}, ["inventory"] = {} }, ["param2"] = 0, ["y"] = 28, ["param1"] = 204, ["z"] = 6, ["name"] = "lottother:air" },
{["x"] = 3, ["meta"] = { ["fields"] = {}, ["inventory"] = {} }, ["param2"] = 0, ["y"] = 28, ["param1"] = 188, ["z"] = 7, ["name"] = "lottother:air" },
{["x"] = 3, ["meta"] = { ["fields"] = {}, ["inventory"] = {} }, ["param2"] = 0, ["y"] = 29, ["param1"] = 0, ["z"] = 6, ["name"] = "lord_planks:mallorn" },
{["x"] = 3, ["meta"] = { ["fields"] = {}, ["inventory"] = {} }, ["param2"] = 0, ["y"] = 29, ["param1"] = 0, ["z"] = 7, ["name"] = "lord_planks:mallorn" },
{["x"] = 3, ["meta"] = { ["fields"] = {}, ["inventory"] = {} }, ["param2"] = 0, ["y"] = 50, ["param1"] = 0, ["z"] = 8, ["name"] = "lord_planks:mallorn" },
{["x"] = 3, ["meta"] = { ["fields"] = {}, ["inventory"] = {} }, ["param2"] = 0, ["y"] = 50, ["param1"] = 0, ["z"] = 9, ["name"] = "lord_planks:mallorn" },
{["x"] = 3, ["meta"] = { ["fields"] = {}, ["inventory"] = {} }, ["param2"] = 0, ["y"] = 52, ["param1"] = 60, ["z"] = 6, ["name"] = "lord_trees:mallorn_leaf" },
{["x"] = 3, ["meta"] = { ["fields"] = {}, ["inventory"] = {} }, ["param2"] = 0, ["y"] = 52, ["param1"] = 76, ["z"] = 7, ["name"] = "lord_trees:mallorn_leaf" },
{["x"] = 3, ["meta"] = { ["fields"] = {}, ["inventory"] = {} }, ["param2"] = 0, ["y"] = 52, ["param1"] = 91, ["z"] = 8, ["name"] = "lord_trees:mallorn_leaf" },
{["x"] = 3, ["meta"] = { ["fields"] = {}, ["inventory"] = {} }, ["param2"] = 0, ["y"] = 52, ["param1"] = 90, ["z"] = 9, ["name"] = "lord_trees:mallorn_leaf" },
{["x"] = 3, ["meta"] = { ["fields"] = {}, ["inventory"] = {} }, ["param2"] = 0, ["y"] = 52, ["param1"] = 75, ["z"] = 10, ["name"] = "lord_trees:mallorn_leaf" },
{["x"] = 3, ["meta"] = { ["fields"] = {}, ["inventory"] = {} }, ["param2"] = 0, ["y"] = 52, ["param1"] = 59, ["z"] = 11, ["name"] = "lord_trees:mallorn_leaf" },
{["x"] = 3, ["meta"] = { ["fields"] = {}, ["inventory"] = {} }, ["param2"] = 0, ["y"] = 52, ["param1"] = 43, ["z"] = 12, ["name"] = "lord_trees:mallorn_leaf" },
{["x"] = 3, ["meta"] = { ["fields"] = {}, ["inventory"] = {} }, ["param2"] = 0, ["y"] = 52, ["param1"] = 28, ["z"] = 13, ["name"] = "lord_trees:mallorn_leaf" },
{["x"] = 3, ["meta"] = { ["fields"] = {}, ["inventory"] = {} }, ["param2"] = 0, ["y"] = 53, ["param1"] = 13, ["z"] = 4, ["name"] = "lord_trees:mallorn_leaf" },
{["x"] = 3, ["meta"] = { ["fields"] = {}, ["inventory"] = {} }, ["param2"] = 0, ["y"] = 53, ["param1"] = 0, ["z"] = 5, ["name"] = "lord_trees:mallorn_tree" },
{["x"] = 3, ["meta"] = { ["fields"] = {}, ["inventory"] = {} }, ["param2"] = 0, ["y"] = 53, ["param1"] = 45, ["z"] = 6, ["name"] = "lord_trees:mallorn_leaf" },
{["x"] = 3, ["meta"] = { ["fields"] = {}, ["inventory"] = {} }, ["param2"] = 0, ["y"] = 53, ["param1"] = 61, ["z"] = 7, ["name"] = "lord_trees:mallorn_leaf" },
{["x"] = 3, ["meta"] = { ["fields"] = {}, ["inventory"] = {} }, ["param2"] = 0, ["y"] = 53, ["param1"] = 76, ["z"] = 8, ["name"] = "lord_trees:mallorn_leaf" },
{["x"] = 3, ["meta"] = { ["fields"] = {}, ["inventory"] = {} }, ["param2"] = 0, ["y"] = 53, ["param1"] = 0, ["z"] = 9, ["name"] = "lord_trees:mallorn_tree" },
{["x"] = 3, ["meta"] = { ["fields"] = {}, ["inventory"] = {} }, ["param2"] = 0, ["y"] = 53, ["param1"] = 60, ["z"] = 10, ["name"] = "lord_trees:mallorn_leaf" },
{["x"] = 3, ["meta"] = { ["fields"] = {}, ["inventory"] = {} }, ["param2"] = 0, ["y"] = 53, ["param1"] = 44, ["z"] = 11, ["name"] = "lord_trees:mallorn_leaf" },
{["x"] = 3, ["meta"] = { ["fields"] = {}, ["inventory"] = {} }, ["param2"] = 0, ["y"] = 53, ["param1"] = 0, ["z"] = 12, ["name"] = "lord_trees:mallorn_tree" },
{["x"] = 3, ["meta"] = { ["fields"] = {}, ["inventory"] = {} }, ["param2"] = 0, ["y"] = 53, ["param1"] = 13, ["z"] = 13, ["name"] = "lord_trees:mallorn_leaf" },
{["x"] = 3, ["meta"] = { ["fields"] = {}, ["inventory"] = {} }, ["param2"] = 0, ["y"] = 53, ["param1"] = 13, ["z"] = 14, ["name"] = "lord_trees:mallorn_leaf" },
{["x"] = 3, ["meta"] = { ["fields"] = {}, ["inventory"] = {} }, ["param2"] = 0, ["y"] = 54, ["param1"] = 13, ["z"] = 5, ["name"] = "lord_trees:mallorn_leaf" },
{["x"] = 3, ["meta"] = { ["fields"] = {}, ["inventory"] = {} }, ["param2"] = 0, ["y"] = 54, ["param1"] = 61, ["z"] = 8, ["name"] = "lord_trees:mallorn_leaf" },
{["x"] = 3, ["meta"] = { ["fields"] = {}, ["inventory"] = {} }, ["param2"] = 0, ["y"] = 54, ["param1"] = 61, ["z"] = 9, ["name"] = "lord_trees:mallorn_leaf" },
{["x"] = 3, ["meta"] = { ["fields"] = {}, ["inventory"] = {} }, ["param2"] = 0, ["y"] = 54, ["param1"] = 45, ["z"] = 10, ["name"] = "lord_trees:mallorn_leaf" },
{["x"] = 3, ["meta"] = { ["fields"] = {}, ["inventory"] = {} }, ["param2"] = 0, ["y"] = 54, ["param1"] = 29, ["z"] = 11, ["name"] = "lord_trees:mallorn_leaf" },
{["x"] = 3, ["meta"] = { ["fields"] = {}, ["inventory"] = {} }, ["param2"] = 0, ["y"] = 54, ["param1"] = 13, ["z"] = 12, ["name"] = "lord_trees:mallorn_leaf" },
{["x"] = 3, ["meta"] = { ["fields"] = {}, ["inventory"] = {} }, ["param2"] = 0, ["y"] = 55, ["param1"] = 13, ["z"] = 12, ["name"] = "lord_trees:mallorn_leaf" },
{["x"] = 4, ["meta"] = { ["fields"] = {}, ["inventory"] = {} }, ["param2"] = 0, ["y"] = 0, ["param1"] = 12, ["z"] = 4, ["name"] = "lottother:dirt" },
{["x"] = 4, ["meta"] = { ["fields"] = {}, ["inventory"] = {} }, ["param2"] = 0, ["y"] = 0, ["param1"] = 11, ["z"] = 5, ["name"] = "lottother:dirt" },
{["x"] = 4, ["meta"] = { ["fields"] = {}, ["inventory"] = {} }, ["param2"] = 0, ["y"] = 0, ["param1"] = 11, ["z"] = 6, ["name"] = "lottother:dirt" },
{["x"] = 4, ["meta"] = { ["fields"] = {}, ["inventory"] = {} }, ["param2"] = 0, ["y"] = 0, ["param1"] = 11, ["z"] = 7, ["name"] = "lottother:dirt" },
{["x"] = 4, ["meta"] = { ["fields"] = {}, ["inventory"] = {} }, ["param2"] = 0, ["y"] = 0, ["param1"] = 10, ["z"] = 8, ["name"] = "lottother:dirt" },
{["x"] = 4, ["meta"] = { ["fields"] = {}, ["inventory"] = {} }, ["param2"] = 0, ["y"] = 0, ["param1"] = 9, ["z"] = 9, ["name"] = "lottother:dirt" },
{["x"] = 4, ["meta"] = { ["fields"] = {}, ["inventory"] = {} }, ["param2"] = 0, ["y"] = 0, ["param1"] = 9, ["z"] = 10, ["name"] = "lottother:dirt" },
{["x"] = 4, ["meta"] = { ["fields"] = {}, ["inventory"] = {} }, ["param2"] = 0, ["y"] = 0, ["param1"] = 10, ["z"] = 11, ["name"] = "lottother:dirt" },
{["x"] = 4, ["meta"] = { ["fields"] = {}, ["inventory"] = {} }, ["param2"] = 0, ["y"] = 0, ["param1"] = 10, ["z"] = 12, ["name"] = "lottother:dirt" },
{["x"] = 4, ["meta"] = { ["fields"] = {}, ["inventory"] = {} }, ["param2"] = 0, ["y"] = 0, ["param1"] = 11, ["z"] = 13, ["name"] = "lottother:dirt" },
{["x"] = 4, ["meta"] = { ["fields"] = {}, ["inventory"] = {} }, ["param2"] = 0, ["y"] = 1, ["param1"] = 0, ["z"] = 4, ["name"] = "lottmapgen:lorien_grass" },
{["x"] = 4, ["meta"] = { ["fields"] = {}, ["inventory"] = {} }, ["param2"] = 0, ["y"] = 1, ["param1"] = 0, ["z"] = 5, ["name"] = "lottmapgen:lorien_grass" },
{["x"] = 4, ["meta"] = { ["fields"] = {}, ["inventory"] = {} }, ["param2"] = 0, ["y"] = 1, ["param1"] = 0, ["z"] = 6, ["name"] = "lottother:dirt" },
{["x"] = 4, ["meta"] = { ["fields"] = {}, ["inventory"] = {} }, ["param2"] = 0, ["y"] = 1, ["param1"] = 0, ["z"] = 7, ["name"] = "lottother:dirt" },
{["x"] = 4, ["meta"] = { ["fields"] = {}, ["inventory"] = {} }, ["param2"] = 0, ["y"] = 1, ["param1"] = 0, ["z"] = 8, ["name"] = "lottother:dirt" },
{["x"] = 4, ["meta"] = { ["fields"] = {}, ["inventory"] = {} }, ["param2"] = 0, ["y"] = 1, ["param1"] = 0, ["z"] = 9, ["name"] = "lottother:dirt" },
{["x"] = 4, ["meta"] = { ["fields"] = {}, ["inventory"] = {} }, ["param2"] = 0, ["y"] = 1, ["param1"] = 0, ["z"] = 10, ["name"] = "lottother:dirt" },
{["x"] = 4, ["meta"] = { ["fields"] = {}, ["inventory"] = {} }, ["param2"] = 0, ["y"] = 1, ["param1"] = 0, ["z"] = 11, ["name"] = "lottother:dirt" },
{["x"] = 4, ["meta"] = { ["fields"] = {}, ["inventory"] = {} }, ["param2"] = 0, ["y"] = 1, ["param1"] = 0, ["z"] = 12, ["name"] = "lottother:dirt" },
{["x"] = 4, ["meta"] = { ["fields"] = {}, ["inventory"] = {} }, ["param2"] = 0, ["y"] = 1, ["param1"] = 0, ["z"] = 13, ["name"] = "lottmapgen:lorien_grass" },
{["x"] = 4, ["meta"] = { ["fields"] = {}, ["inventory"] = {} }, ["param2"] = 0, ["y"] = 2, ["param1"] = 0, ["z"] = 6, ["name"] = "lottmapgen:lorien_grass" },
{["x"] = 4, ["meta"] = { ["fields"] = {}, ["inventory"] = {} }, ["param2"] = 0, ["y"] = 2, ["param1"] = 0, ["z"] = 7, ["name"] = "lottother:dirt" },
{["x"] = 4, ["meta"] = { ["fields"] = {}, ["inventory"] = {} }, ["param2"] = 0, ["y"] = 2, ["param1"] = 0, ["z"] = 8, ["name"] = "lottother:dirt" },
{["x"] = 4, ["meta"] = { ["fields"] = {}, ["inventory"] = {} }, ["param2"] = 0, ["y"] = 2, ["param1"] = 0, ["z"] = 9, ["name"] = "lottother:dirt" },
{["x"] = 4, ["meta"] = { ["fields"] = {}, ["inventory"] = {} }, ["param2"] = 0, ["y"] = 2, ["param1"] = 0, ["z"] = 10, ["name"] = "lottmapgen:lorien_grass" },
{["x"] = 4, ["meta"] = { ["fields"] = {}, ["inventory"] = {} }, ["param2"] = 0, ["y"] = 2, ["param1"] = 0, ["z"] = 11, ["name"] = "lottmapgen:lorien_grass" },
{["x"] = 4, ["meta"] = { ["fields"] = {}, ["inventory"] = {} }, ["param2"] = 0, ["y"] = 2, ["param1"] = 0, ["z"] = 12, ["name"] = "lottmapgen:lorien_grass" },
{["x"] = 4, ["meta"] = { ["fields"] = {}, ["inventory"] = {} }, ["param2"] = 1, ["y"] = 3, ["param1"] = 0, ["z"] = 7, ["name"] = "lord_trees:mallorn_tree" },
{["x"] = 4, ["meta"] = { ["fields"] = {}, ["inventory"] = {} }, ["param2"] = 1, ["y"] = 3, ["param1"] = 0, ["z"] = 8, ["name"] = "lord_trees:mallorn_tree" },
{["x"] = 4, ["meta"] = { ["fields"] = {}, ["inventory"] = {} }, ["param2"] = 1, ["y"] = 3, ["param1"] = 0, ["z"] = 9, ["name"] = "lord_trees:mallorn_tree" },
{["x"] = 4, ["meta"] = { ["fields"] = {}, ["inventory"] = {} }, ["param2"] = 0, ["y"] = 4, ["param1"] = 11, ["z"] = 7, ["name"] = "lottother:air" },
{["x"] = 4, ["meta"] = { ["fields"] = {}, ["inventory"] = {} }, ["param2"] = 2, ["y"] = 4, ["param1"] = 10, ["z"] = 8, ["name"] = "default:ladder" },
{["x"] = 4, ["meta"] = { ["fields"] = {}, ["inventory"] = {} }, ["param2"] = 0, ["y"] = 4, ["param1"] = 9, ["z"] = 9, ["name"] = "lottother:air" },
{["x"] = 4, ["meta"] = { ["fields"] = {}, ["inventory"] = {} }, ["param2"] = 0, ["y"] = 5, ["param1"] = 11, ["z"] = 7, ["name"] = "lottother:air" },
{["x"] = 4, ["meta"] = { ["fields"] = {}, ["inventory"] = {} }, ["param2"] = 2, ["y"] = 5, ["param1"] = 10, ["z"] = 8, ["name"] = "default:ladder" },
{["x"] = 4, ["meta"] = { ["fields"] = {}, ["inventory"] = {} }, ["param2"] = 0, ["y"] = 5, ["param1"] = 9, ["z"] = 9, ["name"] = "lottother:air" },
{["x"] = 4, ["meta"] = { ["fields"] = {}, ["inventory"] = {} }, ["param2"] = 0, ["y"] = 6, ["param1"] = 11, ["z"] = 7, ["name"] = "lottother:air" },
{["x"] = 4, ["meta"] = { ["fields"] = {}, ["inventory"] = {} }, ["param2"] = 0, ["y"] = 6, ["param1"] = 10, ["z"] = 8, ["name"] = "lottother:air" },
{["x"] = 4, ["meta"] = { ["fields"] = {}, ["inventory"] = {} }, ["param2"] = 0, ["y"] = 6, ["param1"] = 9, ["z"] = 9, ["name"] = "lottother:air" },
{["x"] = 4, ["meta"] = { ["fields"] = {}, ["inventory"] = {} }, ["param2"] = 0, ["y"] = 7, ["param1"] = 11, ["z"] = 7, ["name"] = "lottother:air" },
{["x"] = 4, ["meta"] = { ["fields"] = {}, ["inventory"] = {} }, ["param2"] = 0, ["y"] = 7, ["param1"] = 10, ["z"] = 8, ["name"] = "lottother:air" },
{["x"] = 4, ["meta"] = { ["fields"] = {}, ["inventory"] = {} }, ["param2"] = 0, ["y"] = 7, ["param1"] = 9, ["z"] = 9, ["name"] = "lottother:air" },
{["x"] = 4, ["meta"] = { ["fields"] = {}, ["inventory"] = {} }, ["param2"] = 0, ["y"] = 8, ["param1"] = 11, ["z"] = 7, ["name"] = "lottother:air" },
{["x"] = 4, ["meta"] = { ["fields"] = {}, ["inventory"] = {} }, ["param2"] = 0, ["y"] = 8, ["param1"] = 10, ["z"] = 8, ["name"] = "lottother:air" },
{["x"] = 4, ["meta"] = { ["fields"] = {}, ["inventory"] = {} }, ["param2"] = 0, ["y"] = 8, ["param1"] = 9, ["z"] = 9, ["name"] = "lottother:air" },
{["x"] = 4, ["meta"] = { ["fields"] = {}, ["inventory"] = {} }, ["param2"] = 0, ["y"] = 9, ["param1"] = 11, ["z"] = 7, ["name"] = "lottother:air" },
{["x"] = 4, ["meta"] = { ["fields"] = {}, ["inventory"] = {} }, ["param2"] = 0, ["y"] = 9, ["param1"] = 10, ["z"] = 8, ["name"] = "lottother:air" },
{["x"] = 4, ["meta"] = { ["fields"] = {}, ["inventory"] = {} }, ["param2"] = 0, ["y"] = 9, ["param1"] = 9, ["z"] = 9, ["name"] = "lottother:air" },
{["x"] = 4, ["meta"] = { ["fields"] = {}, ["inventory"] = {} }, ["param2"] = 0, ["y"] = 24, ["param1"] = 0, ["z"] = 6, ["name"] = "lord_planks:mallorn" },
{["x"] = 4, ["meta"] = { ["fields"] = {}, ["inventory"] = {} }, ["param2"] = 0, ["y"] = 24, ["param1"] = 0, ["z"] = 7, ["name"] = "lord_planks:mallorn" },
{["x"] = 4, ["meta"] = { ["fields"] = {}, ["inventory"] = {} }, ["param2"] = 0, ["y"] = 25, ["param1"] = 0, ["z"] = 5, ["name"] = "lord_planks:mallorn" },
{["x"] = 4, ["meta"] = { ["fields"] = {}, ["inventory"] = {} }, ["param2"] = 0, ["y"] = 25, ["param1"] = 0, ["z"] = 6, ["name"] = "lord_planks:mallorn" },
{["x"] = 4, ["meta"] = { ["fields"] = {}, ["inventory"] = {} }, ["param2"] = 0, ["y"] = 25, ["param1"] = 0, ["z"] = 7, ["name"] = "lord_planks:mallorn" },
{["x"] = 4, ["meta"] = { ["fields"] = {}, ["inventory"] = {} }, ["param2"] = 0, ["y"] = 25, ["param1"] = 0, ["z"] = 8, ["name"] = "lord_planks:mallorn" },
{["x"] = 4, ["meta"] = { ["fields"] = {}, ["inventory"] = {} }, ["param2"] = 0, ["y"] = 26, ["param1"] = 171, ["z"] = 5, ["name"] = "default:fence_wood" },
{["x"] = 4, ["meta"] = { ["fields"] = {}, ["inventory"] = {} }, ["param2"] = 0, ["y"] = 26, ["param1"] = 187, ["z"] = 6, ["name"] = "lottother:air" },
{["x"] = 4, ["meta"] = { ["fields"] = {}, ["inventory"] = {} }, ["param2"] = 0, ["y"] = 26, ["param1"] = 171, ["z"] = 7, ["name"] = "lottother:air" },
{["x"] = 4, ["meta"] = { ["fields"] = {}, ["inventory"] = {} }, ["param2"] = 0, ["y"] = 26, ["param1"] = 170, ["z"] = 8, ["name"] = "default:fence_wood" },
{["x"] = 4, ["meta"] = { ["fields"] = {}, ["inventory"] = {} }, ["param2"] = 0, ["y"] = 27, ["param1"] = 187, ["z"] = 5, ["name"] = "default:fence_wood" },
{["x"] = 4, ["meta"] = { ["fields"] = {}, ["inventory"] = {} }, ["param2"] = 0, ["y"] = 27, ["param1"] = 204, ["z"] = 6, ["name"] = "lottother:air" },
{["x"] = 4, ["meta"] = { ["fields"] = {}, ["inventory"] = {} }, ["param2"] = 0, ["y"] = 27, ["param1"] = 187, ["z"] = 7, ["name"] = "lottother:air" },
{["x"] = 4, ["meta"] = { ["fields"] = {}, ["inventory"] = {} }, ["param2"] = 0, ["y"] = 27, ["param1"] = 187, ["z"] = 8, ["name"] = "default:fence_wood" },
{["x"] = 4, ["meta"] = { ["fields"] = {}, ["inventory"] = {} }, ["param2"] = 0, ["y"] = 28, ["param1"] = 171, ["z"] = 5, ["name"] = "default:fence_wood" },
{["x"] = 4, ["meta"] = { ["fields"] = {}, ["inventory"] = {} }, ["param2"] = 0, ["y"] = 28, ["param1"] = 187, ["z"] = 6, ["name"] = "lottother:air" },
{["x"] = 4, ["meta"] = { ["fields"] = {}, ["inventory"] = {} }, ["param2"] = 0, ["y"] = 28, ["param1"] = 171, ["z"] = 7, ["name"] = "lottother:air" },
{["x"] = 4, ["meta"] = { ["fields"] = {}, ["inventory"] = {} }, ["param2"] = 0, ["y"] = 28, ["param1"] = 170, ["z"] = 8, ["name"] = "default:fence_wood" },
{["x"] = 4, ["meta"] = { ["fields"] = {}, ["inventory"] = {} }, ["param2"] = 0, ["y"] = 29, ["param1"] = 0, ["z"] = 5, ["name"] = "lord_planks:mallorn" },
{["x"] = 4, ["meta"] = { ["fields"] = {}, ["inventory"] = {} }, ["param2"] = 0, ["y"] = 29, ["param1"] = 0, ["z"] = 6, ["name"] = "lord_planks:mallorn" },
{["x"] = 4, ["meta"] = { ["fields"] = {}, ["inventory"] = {} }, ["param2"] = 0, ["y"] = 29, ["param1"] = 0, ["z"] = 7, ["name"] = "lord_planks:mallorn" },
{["x"] = 4, ["meta"] = { ["fields"] = {}, ["inventory"] = {} }, ["param2"] = 0, ["y"] = 29, ["param1"] = 0, ["z"] = 8, ["name"] = "lord_planks:mallorn" },
{["x"] = 4, ["meta"] = { ["fields"] = {}, ["inventory"] = {} }, ["param2"] = 0, ["y"] = 30, ["param1"] = 0, ["z"] = 6, ["name"] = "lord_planks:mallorn" },
{["x"] = 4, ["meta"] = { ["fields"] = {}, ["inventory"] = {} }, ["param2"] = 0, ["y"] = 30, ["param1"] = 0, ["z"] = 7, ["name"] = "lord_planks:mallorn" },
{["x"] = 4, ["meta"] = { ["fields"] = {}, ["inventory"] = {} }, ["param2"] = 0, ["y"] = 49, ["param1"] = 0, ["z"] = 7, ["name"] = "lord_planks:mallorn" },
{["x"] = 4, ["meta"] = { ["fields"] = {}, ["inventory"] = {} }, ["param2"] = 0, ["y"] = 49, ["param1"] = 0, ["z"] = 10, ["name"] = "lord_planks:mallorn" },
{["x"] = 4, ["meta"] = { ["fields"] = {}, ["inventory"] = {} }, ["param2"] = 0, ["y"] = 50, ["param1"] = 0, ["z"] = 8, ["name"] = "lord_planks:mallorn" },
{["x"] = 4, ["meta"] = { ["fields"] = {}, ["inventory"] = {} }, ["param2"] = 0, ["y"] = 50, ["param1"] = 0, ["z"] = 9, ["name"] = "lord_planks:mallorn" },
{["x"] = 4, ["meta"] = { ["fields"] = {}, ["inventory"] = {} }, ["param2"] = 0, ["y"] = 52, ["param1"] = 76, ["z"] = 6, ["name"] = "lord_trees:mallorn_leaf" },
{["x"] = 4, ["meta"] = { ["fields"] = {}, ["inventory"] = {} }, ["param2"] = 0, ["y"] = 52, ["param1"] = 91, ["z"] = 7, ["name"] = "lord_trees:mallorn_leaf" },
{["x"] = 4, ["meta"] = { ["fields"] = {}, ["inventory"] = {} }, ["param2"] = 0, ["y"] = 52, ["param1"] = 0, ["z"] = 8, ["name"] = "lord_trees:mallorn_tree" },
{["x"] = 4, ["meta"] = { ["fields"] = {}, ["inventory"] = {} }, ["param2"] = 0, ["y"] = 52, ["param1"] = 107, ["z"] = 9, ["name"] = "lord_trees:mallorn_leaf" },
{["x"] = 4, ["meta"] = { ["fields"] = {}, ["inventory"] = {} }, ["param2"] = 0, ["y"] = 52, ["param1"] = 91, ["z"] = 10, ["name"] = "lord_trees:mallorn_leaf" },
{["x"] = 4, ["meta"] = { ["fields"] = {}, ["inventory"] = {} }, ["param2"] = 0, ["y"] = 52, ["param1"] = 74, ["z"] = 11, ["name"] = "lord_trees:mallorn_leaf" },
{["x"] = 4, ["meta"] = { ["fields"] = {}, ["inventory"] = {} }, ["param2"] = 0, ["y"] = 52, ["param1"] = 59, ["z"] = 12, ["name"] = "lord_trees:mallorn_leaf" },
{["x"] = 4, ["meta"] = { ["fields"] = {}, ["inventory"] = {} }, ["param2"] = 0, ["y"] = 53, ["param1"] = 13, ["z"] = 3, ["name"] = "lord_trees:mallorn_leaf" },
{["x"] = 4, ["meta"] = { ["fields"] = {}, ["inventory"] = {} }, ["param2"] = 0, ["y"] = 53, ["param1"] = 28, ["z"] = 4, ["name"] = "lord_trees:mallorn_leaf" },
{["x"] = 4, ["meta"] = { ["fields"] = {}, ["inventory"] = {} }, ["param2"] = 0, ["y"] = 53, ["param1"] = 45, ["z"] = 5, ["name"] = "lord_trees:mallorn_leaf" },
{["x"] = 4, ["meta"] = { ["fields"] = {}, ["inventory"] = {} }, ["param2"] = 0, ["y"] = 53, ["param1"] = 61, ["z"] = 6, ["name"] = "lord_trees:mallorn_leaf" },
{["x"] = 4, ["meta"] = { ["fields"] = {}, ["inventory"] = {} }, ["param2"] = 0, ["y"] = 53, ["param1"] = 0, ["z"] = 7, ["name"] = "lord_trees:mallorn_tree" },
{["x"] = 4, ["meta"] = { ["fields"] = {}, ["inventory"] = {} }, ["param2"] = 0, ["y"] = 53, ["param1"] = 92, ["z"] = 8, ["name"] = "lord_trees:mallorn_leaf" },
{["x"] = 4, ["meta"] = { ["fields"] = {}, ["inventory"] = {} }, ["param2"] = 0, ["y"] = 53, ["param1"] = 92, ["z"] = 9, ["name"] = "lord_trees:mallorn_leaf" },
{["x"] = 4, ["meta"] = { ["fields"] = {}, ["inventory"] = {} }, ["param2"] = 0, ["y"] = 53, ["param1"] = 76, ["z"] = 10, ["name"] = "lord_trees:mallorn_leaf" },
{["x"] = 4, ["meta"] = { ["fields"] = {}, ["inventory"] = {} }, ["param2"] = 0, ["y"] = 53, ["param1"] = 59, ["z"] = 11, ["name"] = "lord_trees:mallorn_leaf" },
{["x"] = 4, ["meta"] = { ["fields"] = {}, ["inventory"] = {} }, ["param2"] = 0, ["y"] = 53, ["param1"] = 44, ["z"] = 12, ["name"] = "lord_trees:mallorn_leaf" },
{["x"] = 4, ["meta"] = { ["fields"] = {}, ["inventory"] = {} }, ["param2"] = 0, ["y"] = 53, ["param1"] = 28, ["z"] = 13, ["name"] = "lord_trees:mallorn_leaf" },
{["x"] = 4, ["meta"] = { ["fields"] = {}, ["inventory"] = {} }, ["param2"] = 0, ["y"] = 53, ["param1"] = 12, ["z"] = 14, ["name"] = "lord_trees:mallorn_leaf" },
{["x"] = 4, ["meta"] = { ["fields"] = {}, ["inventory"] = {} }, ["param2"] = 0, ["y"] = 53, ["param1"] = 13, ["z"] = 15, ["name"] = "lord_trees:mallorn_leaf" },
{["x"] = 4, ["meta"] = { ["fields"] = {}, ["inventory"] = {} }, ["param2"] = 0, ["y"] = 53, ["param1"] = 13, ["z"] = 16, ["name"] = "lord_trees:mallorn_leaf" },
{["x"] = 4, ["meta"] = { ["fields"] = {}, ["inventory"] = {} }, ["param2"] = 0, ["y"] = 54, ["param1"] = 13, ["z"] = 4, ["name"] = "lord_trees:mallorn_leaf" },
{["x"] = 4, ["meta"] = { ["fields"] = {}, ["inventory"] = {} }, ["param2"] = 0, ["y"] = 54, ["param1"] = 61, ["z"] = 7, ["name"] = "lord_trees:mallorn_leaf" },
{["x"] = 4, ["meta"] = { ["fields"] = {}, ["inventory"] = {} }, ["param2"] = 0, ["y"] = 54, ["param1"] = 77, ["z"] = 8, ["name"] = "lord_trees:mallorn_leaf" },
{["x"] = 4, ["meta"] = { ["fields"] = {}, ["inventory"] = {} }, ["param2"] = 0, ["y"] = 54, ["param1"] = 77, ["z"] = 9, ["name"] = "lord_trees:mallorn_leaf" },
{["x"] = 4, ["meta"] = { ["fields"] = {}, ["inventory"] = {} }, ["param2"] = 0, ["y"] = 54, ["param1"] = 61, ["z"] = 10, ["name"] = "lord_trees:mallorn_leaf" },
{["x"] = 4, ["meta"] = { ["fields"] = {}, ["inventory"] = {} }, ["param2"] = 0, ["y"] = 54, ["param1"] = 0, ["z"] = 11, ["name"] = "lord_trees:mallorn_tree" },
{["x"] = 4, ["meta"] = { ["fields"] = {}, ["inventory"] = {} }, ["param2"] = 0, ["y"] = 54, ["param1"] = 29, ["z"] = 12, ["name"] = "lord_trees:mallorn_leaf" },
{["x"] = 4, ["meta"] = { ["fields"] = {}, ["inventory"] = {} }, ["param2"] = 0, ["y"] = 54, ["param1"] = 13, ["z"] = 13, ["name"] = "lord_trees:mallorn_leaf" },
{["x"] = 4, ["meta"] = { ["fields"] = {}, ["inventory"] = {} }, ["param2"] = 0, ["y"] = 54, ["param1"] = 13, ["z"] = 14, ["name"] = "lord_trees:mallorn_leaf" },
{["x"] = 4, ["meta"] = { ["fields"] = {}, ["inventory"] = {} }, ["param2"] = 0, ["y"] = 55, ["param1"] = 29, ["z"] = 11, ["name"] = "lord_trees:mallorn_leaf" },
{["x"] = 5, ["meta"] = { ["fields"] = {}, ["inventory"] = {} }, ["param2"] = 0, ["y"] = 0, ["param1"] = 12, ["z"] = 3, ["name"] = "lottother:dirt" },
{["x"] = 5, ["meta"] = { ["fields"] = {}, ["inventory"] = {} }, ["param2"] = 0, ["y"] = 0, ["param1"] = 11, ["z"] = 4, ["name"] = "lottother:dirt" },
{["x"] = 5, ["meta"] = { ["fields"] = {}, ["inventory"] = {} }, ["param2"] = 0, ["y"] = 0, ["param1"] = 10, ["z"] = 5, ["name"] = "lottother:dirt" },
{["x"] = 5, ["meta"] = { ["fields"] = {}, ["inventory"] = {} }, ["param2"] = 0, ["y"] = 0, ["param1"] = 10, ["z"] = 6, ["name"] = "lottother:dirt" },
{["x"] = 5, ["meta"] = { ["fields"] = {}, ["inventory"] = {} }, ["param2"] = 0, ["y"] = 0, ["param1"] = 10, ["z"] = 7, ["name"] = "lottother:dirt" },
{["x"] = 5, ["meta"] = { ["fields"] = {}, ["inventory"] = {} }, ["param2"] = 0, ["y"] = 0, ["param1"] = 9, ["z"] = 8, ["name"] = "lottother:dirt" },
{["x"] = 5, ["meta"] = { ["fields"] = {}, ["inventory"] = {} }, ["param2"] = 0, ["y"] = 0, ["param1"] = 8, ["z"] = 9, ["name"] = "lottother:dirt" },
{["x"] = 5, ["meta"] = { ["fields"] = {}, ["inventory"] = {} }, ["param2"] = 0, ["y"] = 0, ["param1"] = 8, ["z"] = 10, ["name"] = "lottother:dirt" },
{["x"] = 5, ["meta"] = { ["fields"] = {}, ["inventory"] = {} }, ["param2"] = 0, ["y"] = 0, ["param1"] = 9, ["z"] = 11, ["name"] = "lottother:dirt" },
{["x"] = 5, ["meta"] = { ["fields"] = {}, ["inventory"] = {} }, ["param2"] = 0, ["y"] = 0, ["param1"] = 9, ["z"] = 12, ["name"] = "lottother:dirt" },
{["x"] = 5, ["meta"] = { ["fields"] = {}, ["inventory"] = {} }, ["param2"] = 0, ["y"] = 0, ["param1"] = 10, ["z"] = 13, ["name"] = "lottother:dirt" },
{["x"] = 5, ["meta"] = { ["fields"] = {}, ["inventory"] = {} }, ["param2"] = 0, ["y"] = 0, ["param1"] = 11, ["z"] = 14, ["name"] = "lottother:dirt" },
{["x"] = 5, ["meta"] = { ["fields"] = {}, ["inventory"] = {} }, ["param2"] = 0, ["y"] = 1, ["param1"] = 0, ["z"] = 3, ["name"] = "lottmapgen:lorien_grass" },
{["x"] = 5, ["meta"] = { ["fields"] = {}, ["inventory"] = {} }, ["param2"] = 0, ["y"] = 1, ["param1"] = 0, ["z"] = 4, ["name"] = "lottmapgen:lorien_grass" },
{["x"] = 5, ["meta"] = { ["fields"] = {}, ["inventory"] = {} }, ["param2"] = 0, ["y"] = 1, ["param1"] = 0, ["z"] = 5, ["name"] = "lottother:dirt" },
{["x"] = 5, ["meta"] = { ["fields"] = {}, ["inventory"] = {} }, ["param2"] = 0, ["y"] = 1, ["param1"] = 0, ["z"] = 6, ["name"] = "lottother:dirt" },
{["x"] = 5, ["meta"] = { ["fields"] = {}, ["inventory"] = {} }, ["param2"] = 0, ["y"] = 1, ["param1"] = 0, ["z"] = 7, ["name"] = "lottother:dirt" },
{["x"] = 5, ["meta"] = { ["fields"] = {}, ["inventory"] = {} }, ["param2"] = 0, ["y"] = 1, ["param1"] = 0, ["z"] = 8, ["name"] = "lottother:dirt" },
{["x"] = 5, ["meta"] = { ["fields"] = {}, ["inventory"] = {} }, ["param2"] = 0, ["y"] = 1, ["param1"] = 0, ["z"] = 9, ["name"] = "lottother:dirt" },
{["x"] = 5, ["meta"] = { ["fields"] = {}, ["inventory"] = {} }, ["param2"] = 0, ["y"] = 1, ["param1"] = 0, ["z"] = 10, ["name"] = "lottother:dirt" },
{["x"] = 5, ["meta"] = { ["fields"] = {}, ["inventory"] = {} }, ["param2"] = 0, ["y"] = 1, ["param1"] = 0, ["z"] = 11, ["name"] = "lottother:dirt" },
{["x"] = 5, ["meta"] = { ["fields"] = {}, ["inventory"] = {} }, ["param2"] = 0, ["y"] = 1, ["param1"] = 0, ["z"] = 12, ["name"] = "lottother:dirt" },
{["x"] = 5, ["meta"] = { ["fields"] = {}, ["inventory"] = {} }, ["param2"] = 0, ["y"] = 1, ["param1"] = 0, ["z"] = 13, ["name"] = "lottmapgen:lorien_grass" },
{["x"] = 5, ["meta"] = { ["fields"] = {}, ["inventory"] = {} }, ["param2"] = 0, ["y"] = 1, ["param1"] = 0, ["z"] = 14, ["name"] = "lottmapgen:lorien_grass" },
{["x"] = 5, ["meta"] = { ["fields"] = {}, ["inventory"] = {} }, ["param2"] = 0, ["y"] = 2, ["param1"] = 0, ["z"] = 5, ["name"] = "lottmapgen:lorien_grass" },
{["x"] = 5, ["meta"] = { ["fields"] = {}, ["inventory"] = {} }, ["param2"] = 0, ["y"] = 2, ["param1"] = 0, ["z"] = 6, ["name"] = "lottmapgen:lorien_grass" },
{["x"] = 5, ["meta"] = { ["fields"] = {}, ["inventory"] = {} }, ["param2"] = 0, ["y"] = 2, ["param1"] = 0, ["z"] = 7, ["name"] = "lottother:dirt" },
{["x"] = 5, ["meta"] = { ["fields"] = {}, ["inventory"] = {} }, ["param2"] = 0, ["y"] = 2, ["param1"] = 0, ["z"] = 8, ["name"] = "lottother:dirt" },
{["x"] = 5, ["meta"] = { ["fields"] = {}, ["inventory"] = {} }, ["param2"] = 0, ["y"] = 2, ["param1"] = 0, ["z"] = 9, ["name"] = "lottother:dirt" },
{["x"] = 5, ["meta"] = { ["fields"] = {}, ["inventory"] = {} }, ["param2"] = 0, ["y"] = 2, ["param1"] = 0, ["z"] = 10, ["name"] = "lottother:dirt" },
{["x"] = 5, ["meta"] = { ["fields"] = {}, ["inventory"] = {} }, ["param2"] = 0, ["y"] = 2, ["param1"] = 0, ["z"] = 11, ["name"] = "lottother:dirt" },
{["x"] = 5, ["meta"] = { ["fields"] = {}, ["inventory"] = {} }, ["param2"] = 0, ["y"] = 2, ["param1"] = 0, ["z"] = 12, ["name"] = "lottmapgen:lorien_grass" },
{["x"] = 5, ["meta"] = { ["fields"] = {}, ["inventory"] = {} }, ["param2"] = 1, ["y"] = 3, ["param1"] = 0, ["z"] = 7, ["name"] = "lord_trees:mallorn_tree" },
{["x"] = 5, ["meta"] = { ["fields"] = {}, ["inventory"] = {} }, ["param2"] = 1, ["y"] = 3, ["param1"] = 0, ["z"] = 8, ["name"] = "lord_trees:mallorn_tree" },
{["x"] = 5, ["meta"] = { ["fields"] = {}, ["inventory"] = {} }, ["param2"] = 1, ["y"] = 3, ["param1"] = 0, ["z"] = 9, ["name"] = "lord_trees:mallorn_tree" },
{["x"] = 5, ["meta"] = { ["fields"] = {}, ["inventory"] = {} }, ["param2"] = 1, ["y"] = 3, ["param1"] = 0, ["z"] = 10, ["name"] = "lord_trees:mallorn_tree" },
{["x"] = 5, ["meta"] = { ["fields"] = {}, ["inventory"] = {} }, ["param2"] = 1, ["y"] = 3, ["param1"] = 0, ["z"] = 11, ["name"] = "lord_trees:mallorn_tree" },
{["x"] = 5, ["meta"] = { ["fields"] = {}, ["inventory"] = {} }, ["param2"] = 0, ["y"] = 4, ["param1"] = 10, ["z"] = 7, ["name"] = "lottother:air" },
{["x"] = 5, ["meta"] = { ["fields"] = {}, ["inventory"] = {} }, ["param2"] = 1, ["y"] = 4, ["param1"] = 0, ["z"] = 8, ["name"] = "lord_trees:mallorn_tree" },
{["x"] = 5, ["meta"] = { ["fields"] = {}, ["inventory"] = {} }, ["param2"] = 1, ["y"] = 4, ["param1"] = 0, ["z"] = 9, ["name"] = "lord_trees:mallorn_tree" },
{["x"] = 5, ["meta"] = { ["fields"] = {}, ["inventory"] = {} }, ["param2"] = 1, ["y"] = 4, ["param1"] = 0, ["z"] = 10, ["name"] = "lord_trees:mallorn_tree" },
{["x"] = 5, ["meta"] = { ["fields"] = {}, ["inventory"] = {} }, ["param2"] = 1, ["y"] = 4, ["param1"] = 0, ["z"] = 11, ["name"] = "lord_trees:mallorn_tree" },
{["x"] = 5, ["meta"] = { ["fields"] = {}, ["inventory"] = {} }, ["param2"] = 0, ["y"] = 5, ["param1"] = 10, ["z"] = 7, ["name"] = "lottother:air" },
{["x"] = 5, ["meta"] = { ["fields"] = {}, ["inventory"] = {} }, ["param2"] = 1, ["y"] = 5, ["param1"] = 0, ["z"] = 8, ["name"] = "lord_trees:mallorn_tree" },
{["x"] = 5, ["meta"] = { ["fields"] = {}, ["inventory"] = {} }, ["param2"] = 1, ["y"] = 5, ["param1"] = 0, ["z"] = 9, ["name"] = "lord_trees:mallorn_tree" },
{["x"] = 5, ["meta"] = { ["fields"] = {}, ["inventory"] = {} }, ["param2"] = 1, ["y"] = 5, ["param1"] = 0, ["z"] = 10, ["name"] = "lord_trees:mallorn_tree" },
{["x"] = 5, ["meta"] = { ["fields"] = {}, ["inventory"] = {} }, ["param2"] = 0, ["y"] = 6, ["param1"] = 10, ["z"] = 7, ["name"] = "lottother:air" },
{["x"] = 5, ["meta"] = { ["fields"] = {}, ["inventory"] = {} }, ["param2"] = 2, ["y"] = 6, ["param1"] = 9, ["z"] = 8, ["name"] = "default:ladder" },
{["x"] = 5, ["meta"] = { ["fields"] = {}, ["inventory"] = {} }, ["param2"] = 1, ["y"] = 6, ["param1"] = 0, ["z"] = 9, ["name"] = "lord_trees:mallorn_tree" },
{["x"] = 5, ["meta"] = { ["fields"] = {}, ["inventory"] = {} }, ["param2"] = 0, ["y"] = 7, ["param1"] = 10, ["z"] = 7, ["name"] = "lottother:air" },
{["x"] = 5, ["meta"] = { ["fields"] = {}, ["inventory"] = {} }, ["param2"] = 2, ["y"] = 7, ["param1"] = 9, ["z"] = 8, ["name"] = "default:ladder" },
{["x"] = 5, ["meta"] = { ["fields"] = {}, ["inventory"] = {} }, ["param2"] = 1, ["y"] = 7, ["param1"] = 0, ["z"] = 9, ["name"] = "lord_trees:mallorn_tree" },
{["x"] = 5, ["meta"] = { ["fields"] = {}, ["inventory"] = {} }, ["param2"] = 0, ["y"] = 8, ["param1"] = 10, ["z"] = 7, ["name"] = "lottother:air" },
{["x"] = 5, ["meta"] = { ["fields"] = {}, ["inventory"] = {} }, ["param2"] = 2, ["y"] = 8, ["param1"] = 9, ["z"] = 8, ["name"] = "default:ladder" },
{["x"] = 5, ["meta"] = { ["fields"] = {}, ["inventory"] = {} }, ["param2"] = 1, ["y"] = 8, ["param1"] = 0, ["z"] = 9, ["name"] = "lord_trees:mallorn_tree" },
{["x"] = 5, ["meta"] = { ["fields"] = {}, ["inventory"] = {} }, ["param2"] = 0, ["y"] = 9, ["param1"] = 10, ["z"] = 7, ["name"] = "lottother:air" },
{["x"] = 5, ["meta"] = { ["fields"] = {}, ["inventory"] = {} }, ["param2"] = 0, ["y"] = 9, ["param1"] = 9, ["z"] = 8, ["name"] = "lottother:air" },
{["x"] = 5, ["meta"] = { ["fields"] = {}, ["inventory"] = {} }, ["param2"] = 0, ["y"] = 9, ["param1"] = 8, ["z"] = 9, ["name"] = "lottother:air" },
{["x"] = 5, ["meta"] = { ["fields"] = {}, ["inventory"] = {} }, ["param2"] = 0, ["y"] = 10, ["param1"] = 10, ["z"] = 7, ["name"] = "lottother:air" },
{["x"] = 5, ["meta"] = { ["fields"] = {}, ["inventory"] = {} }, ["param2"] = 0, ["y"] = 10, ["param1"] = 9, ["z"] = 8, ["name"] = "lottother:air" },
{["x"] = 5, ["meta"] = { ["fields"] = {}, ["inventory"] = {} }, ["param2"] = 0, ["y"] = 10, ["param1"] = 8, ["z"] = 9, ["name"] = "lottother:air" },
{["x"] = 5, ["meta"] = { ["fields"] = {}, ["inventory"] = {} }, ["param2"] = 0, ["y"] = 11, ["param1"] = 10, ["z"] = 7, ["name"] = "lottother:air" },
{["x"] = 5, ["meta"] = { ["fields"] = {}, ["inventory"] = {} }, ["param2"] = 0, ["y"] = 11, ["param1"] = 9, ["z"] = 8, ["name"] = "lottother:air" },
{["x"] = 5, ["meta"] = { ["fields"] = {}, ["inventory"] = {} }, ["param2"] = 0, ["y"] = 11, ["param1"] = 8, ["z"] = 9, ["name"] = "lottother:air" },
{["x"] = 5, ["meta"] = { ["fields"] = {}, ["inventory"] = {} }, ["param2"] = 0, ["y"] = 12, ["param1"] = 10, ["z"] = 7, ["name"] = "lottother:air" },
{["x"] = 5, ["meta"] = { ["fields"] = {}, ["inventory"] = {} }, ["param2"] = 0, ["y"] = 12, ["param1"] = 9, ["z"] = 8, ["name"] = "lottother:air" },
{["x"] = 5, ["meta"] = { ["fields"] = {}, ["inventory"] = {} }, ["param2"] = 0, ["y"] = 12, ["param1"] = 8, ["z"] = 9, ["name"] = "lottother:air" },
{["x"] = 5, ["meta"] = { ["fields"] = {}, ["inventory"] = {} }, ["param2"] = 0, ["y"] = 13, ["param1"] = 10, ["z"] = 7, ["name"] = "lottother:air" },
{["x"] = 5, ["meta"] = { ["fields"] = {}, ["inventory"] = {} }, ["param2"] = 0, ["y"] = 13, ["param1"] = 9, ["z"] = 8, ["name"] = "lottother:air" },
{["x"] = 5, ["meta"] = { ["fields"] = {}, ["inventory"] = {} }, ["param2"] = 0, ["y"] = 13, ["param1"] = 24, ["z"] = 9, ["name"] = "lottother:air" },
{["x"] = 5, ["meta"] = { ["fields"] = {}, ["inventory"] = {} }, ["param2"] = 0, ["y"] = 14, ["param1"] = 10, ["z"] = 7, ["name"] = "lottother:air" },
{["x"] = 5, ["meta"] = { ["fields"] = {}, ["inventory"] = {} }, ["param2"] = 0, ["y"] = 14, ["param1"] = 25, ["z"] = 8, ["name"] = "lottother:air" },
{["x"] = 5, ["meta"] = { ["fields"] = {}, ["inventory"] = {} }, ["param2"] = 0, ["y"] = 14, ["param1"] = 40, ["z"] = 9, ["name"] = "lottother:air" },
{["x"] = 5, ["meta"] = { ["fields"] = {}, ["inventory"] = {} }, ["param2"] = 0, ["y"] = 15, ["param1"] = 26, ["z"] = 7, ["name"] = "lottother:air" },
{["x"] = 5, ["meta"] = { ["fields"] = {}, ["inventory"] = {} }, ["param2"] = 0, ["y"] = 15, ["param1"] = 41, ["z"] = 8, ["name"] = "lottother:air" },
{["x"] = 5, ["meta"] = { ["fields"] = {}, ["inventory"] = {} }, ["param2"] = 0, ["y"] = 15, ["param1"] = 56, ["z"] = 9, ["name"] = "lottother:air" },
{["x"] = 5, ["meta"] = { ["fields"] = {}, ["inventory"] = {} }, ["param2"] = 0, ["y"] = 16, ["param1"] = 42, ["z"] = 7, ["name"] = "lottother:air" },
{["x"] = 5, ["meta"] = { ["fields"] = {}, ["inventory"] = {} }, ["param2"] = 0, ["y"] = 16, ["param1"] = 57, ["z"] = 8, ["name"] = "lottother:air" },
{["x"] = 5, ["meta"] = { ["fields"] = {}, ["inventory"] = {} }, ["param2"] = 0, ["y"] = 16, ["param1"] = 72, ["z"] = 9, ["name"] = "lottother:air" },
{["x"] = 5, ["meta"] = { ["fields"] = {}, ["inventory"] = {} }, ["param2"] = 0, ["y"] = 17, ["param1"] = 58, ["z"] = 7, ["name"] = "lottother:air" },
{["x"] = 5, ["meta"] = { ["fields"] = {}, ["inventory"] = {} }, ["param2"] = 0, ["y"] = 17, ["param1"] = 73, ["z"] = 8, ["name"] = "lottother:air" },
{["x"] = 5, ["meta"] = { ["fields"] = {}, ["inventory"] = {} }, ["param2"] = 0, ["y"] = 17, ["param1"] = 88, ["z"] = 9, ["name"] = "lottother:air" },
{["x"] = 5, ["meta"] = { ["fields"] = {}, ["inventory"] = {} }, ["param2"] = 0, ["y"] = 18, ["param1"] = 74, ["z"] = 7, ["name"] = "lottother:air" },
{["x"] = 5, ["meta"] = { ["fields"] = {}, ["inventory"] = {} }, ["param2"] = 0, ["y"] = 18, ["param1"] = 89, ["z"] = 8, ["name"] = "lottother:air" },
{["x"] = 5, ["meta"] = { ["fields"] = {}, ["inventory"] = {} }, ["param2"] = 0, ["y"] = 18, ["param1"] = 104, ["z"] = 9, ["name"] = "lottother:air" },
{["x"] = 5, ["meta"] = { ["fields"] = {}, ["inventory"] = {} }, ["param2"] = 0, ["y"] = 19, ["param1"] = 90, ["z"] = 7, ["name"] = "lottother:air" },
{["x"] = 5, ["meta"] = { ["fields"] = {}, ["inventory"] = {} }, ["param2"] = 0, ["y"] = 19, ["param1"] = 105, ["z"] = 8, ["name"] = "lottother:air" },
{["x"] = 5, ["meta"] = { ["fields"] = {}, ["inventory"] = {} }, ["param2"] = 0, ["y"] = 19, ["param1"] = 120, ["z"] = 9, ["name"] = "lottother:air" },
{["x"] = 5, ["meta"] = { ["fields"] = {}, ["inventory"] = {} }, ["param2"] = 0, ["y"] = 20, ["param1"] = 106, ["z"] = 7, ["name"] = "lottother:air" },
{["x"] = 5, ["meta"] = { ["fields"] = {}, ["inventory"] = {} }, ["param2"] = 0, ["y"] = 20, ["param1"] = 121, ["z"] = 8, ["name"] = "lottother:air" },
{["x"] = 5, ["meta"] = { ["fields"] = {}, ["inventory"] = {} }, ["param2"] = 0, ["y"] = 20, ["param1"] = 136, ["z"] = 9, ["name"] = "lottother:air" },
{["x"] = 5, ["meta"] = { ["fields"] = {}, ["inventory"] = {} }, ["param2"] = 0, ["y"] = 21, ["param1"] = 122, ["z"] = 7, ["name"] = "lottother:air" },
{["x"] = 5, ["meta"] = { ["fields"] = {}, ["inventory"] = {} }, ["param2"] = 0, ["y"] = 21, ["param1"] = 137, ["z"] = 8, ["name"] = "lottother:air" },
{["x"] = 5, ["meta"] = { ["fields"] = {}, ["inventory"] = {} }, ["param2"] = 0, ["y"] = 21, ["param1"] = 153, ["z"] = 9, ["name"] = "lottother:air" },
{["x"] = 5, ["meta"] = { ["fields"] = {}, ["inventory"] = {} }, ["param2"] = 0, ["y"] = 22, ["param1"] = 138, ["z"] = 7, ["name"] = "lottother:air" },
{["x"] = 5, ["meta"] = { ["fields"] = {}, ["inventory"] = {} }, ["param2"] = 0, ["y"] = 22, ["param1"] = 153, ["z"] = 8, ["name"] = "lottother:air" },
{["x"] = 5, ["meta"] = { ["fields"] = {}, ["inventory"] = {} }, ["param2"] = 0, ["y"] = 22, ["param1"] = 170, ["z"] = 9, ["name"] = "lottother:air" },
{["x"] = 5, ["meta"] = { ["fields"] = {}, ["inventory"] = {} }, ["param2"] = 0, ["y"] = 23, ["param1"] = 154, ["z"] = 7, ["name"] = "lottother:air" },
{["x"] = 5, ["meta"] = { ["fields"] = {}, ["inventory"] = {} }, ["param2"] = 0, ["y"] = 23, ["param1"] = 170, ["z"] = 8, ["name"] = "lottother:air" },
{["x"] = 5, ["meta"] = { ["fields"] = {}, ["inventory"] = {} }, ["param2"] = 0, ["y"] = 23, ["param1"] = 187, ["z"] = 9, ["name"] = "lottother:air" },
{["x"] = 5, ["meta"] = { ["fields"] = {}, ["inventory"] = {} }, ["param2"] = 0, ["y"] = 24, ["param1"] = 0, ["z"] = 5, ["name"] = "lord_planks:mallorn" },
{["x"] = 5, ["meta"] = { ["fields"] = {}, ["inventory"] = {} }, ["param2"] = 0, ["y"] = 24, ["param1"] = 0, ["z"] = 6, ["name"] = "lord_planks:mallorn" },
{["x"] = 5, ["meta"] = { ["fields"] = {}, ["inventory"] = {} }, ["param2"] = 0, ["y"] = 24, ["param1"] = 0, ["z"] = 7, ["name"] = "lord_planks:mallorn" },
{["x"] = 5, ["meta"] = { ["fields"] = {}, ["inventory"] = {} }, ["param2"] = 0, ["y"] = 24, ["param1"] = 0, ["z"] = 8, ["name"] = "lord_planks:mallorn" },
{["x"] = 5, ["meta"] = { ["fields"] = {}, ["inventory"] = {} }, ["param2"] = 0, ["y"] = 25, ["param1"] = 0, ["z"] = 4, ["name"] = "lord_planks:mallorn" },
{["x"] = 5, ["meta"] = { ["fields"] = {}, ["inventory"] = {} }, ["param2"] = 0, ["y"] = 25, ["param1"] = 0, ["z"] = 5, ["name"] = "lord_planks:mallorn" },
{["x"] = 5, ["meta"] = { ["fields"] = {}, ["inventory"] = {} }, ["param2"] = 0, ["y"] = 25, ["param1"] = 0, ["z"] = 6, ["name"] = "lord_planks:mallorn" },
{["x"] = 5, ["meta"] = { ["fields"] = {}, ["inventory"] = {} }, ["param2"] = 0, ["y"] = 25, ["param1"] = 0, ["z"] = 7, ["name"] = "lord_planks:mallorn" },
{["x"] = 5, ["meta"] = { ["fields"] = {}, ["inventory"] = {} }, ["param2"] = 0, ["y"] = 25, ["param1"] = 0, ["z"] = 8, ["name"] = "lord_planks:mallorn" },
{["x"] = 5, ["meta"] = { ["fields"] = {}, ["inventory"] = {} }, ["param2"] = 0, ["y"] = 25, ["param1"] = 0, ["z"] = 9, ["name"] = "lord_planks:mallorn" },
{["x"] = 5, ["meta"] = { ["fields"] = {}, ["inventory"] = {} }, ["param2"] = 0, ["y"] = 26, ["param1"] = 187, ["z"] = 4, ["name"] = "default:fence_wood" },
{["x"] = 5, ["meta"] = { ["fields"] = {}, ["inventory"] = {} }, ["param2"] = 0, ["y"] = 26, ["param1"] = 170, ["z"] = 5, ["name"] = "lottother:air" },
{["x"] = 5, ["meta"] = { ["fields"] = {}, ["inventory"] = {} }, ["param2"] = 0, ["y"] = 26, ["param1"] = 170, ["z"] = 6, ["name"] = "lottother:elfms_off" },
{["x"] = 5, ["meta"] = { ["fields"] = {}, ["inventory"] = {} }, ["param2"] = 0, ["y"] = 26, ["param1"] = 170, ["z"] = 7, ["name"] = "lottother:air" },
{["x"] = 5, ["meta"] = { ["fields"] = {}, ["inventory"] = {} }, ["param2"] = 0, ["y"] = 26, ["param1"] = 187, ["z"] = 8, ["name"] = "lottother:air" },
{["x"] = 5, ["meta"] = { ["fields"] = {}, ["inventory"] = {} }, ["param2"] = 0, ["y"] = 26, ["param1"] = 204, ["z"] = 9, ["name"] = "default:fence_wood" },
{["x"] = 5, ["meta"] = { ["fields"] = {}, ["inventory"] = {} }, ["param2"] = 0, ["y"] = 27, ["param1"] = 204, ["z"] = 4, ["name"] = "lottother:air" },
{["x"] = 5, ["meta"] = { ["fields"] = {}, ["inventory"] = {} }, ["param2"] = 0, ["y"] = 27, ["param1"] = 187, ["z"] = 5, ["name"] = "lottother:air" },
{["x"] = 5, ["meta"] = { ["fields"] = {}, ["inventory"] = {} }, ["param2"] = 0, ["y"] = 27, ["param1"] = 187, ["z"] = 6, ["name"] = "lottother:air" },
{["x"] = 5, ["meta"] = { ["fields"] = {}, ["inventory"] = {} }, ["param2"] = 0, ["y"] = 27, ["param1"] = 187, ["z"] = 7, ["name"] = "lottother:air" },
{["x"] = 5, ["meta"] = { ["fields"] = {}, ["inventory"] = {} }, ["param2"] = 0, ["y"] = 27, ["param1"] = 204, ["z"] = 8, ["name"] = "lottother:air" },
{["x"] = 5, ["meta"] = { ["fields"] = {}, ["inventory"] = {} }, ["param2"] = 1, ["y"] = 27, ["param1"] = 0, ["z"] = 9, ["name"] = "lottother:blue_torch" },
{["x"] = 5, ["meta"] = { ["fields"] = {}, ["inventory"] = {} }, ["param2"] = 0, ["y"] = 28, ["param1"] = 187, ["z"] = 4, ["name"] = "lottother:air" },
{["x"] = 5, ["meta"] = { ["fields"] = {}, ["inventory"] = {} }, ["param2"] = 0, ["y"] = 28, ["param1"] = 170, ["z"] = 5, ["name"] = "lottother:air" },
{["x"] = 5, ["meta"] = { ["fields"] = {}, ["inventory"] = {} }, ["param2"] = 0, ["y"] = 28, ["param1"] = 170, ["z"] = 6, ["name"] = "lottother:air" },
{["x"] = 5, ["meta"] = { ["fields"] = {}, ["inventory"] = {} }, ["param2"] = 0, ["y"] = 28, ["param1"] = 170, ["z"] = 7, ["name"] = "lottother:air" },
{["x"] = 5, ["meta"] = { ["fields"] = {}, ["inventory"] = {} }, ["param2"] = 0, ["y"] = 28, ["param1"] = 187, ["z"] = 8, ["name"] = "lottother:air" },
{["x"] = 5, ["meta"] = { ["fields"] = {}, ["inventory"] = {} }, ["param2"] = 0, ["y"] = 28, ["param1"] = 204, ["z"] = 9, ["name"] = "lottother:air" },
{["x"] = 5, ["meta"] = { ["fields"] = {}, ["inventory"] = {} }, ["param2"] = 0, ["y"] = 29, ["param1"] = 0, ["z"] = 4, ["name"] = "lord_planks:mallorn" },
{["x"] = 5, ["meta"] = { ["fields"] = {}, ["inventory"] = {} }, ["param2"] = 0, ["y"] = 29, ["param1"] = 0, ["z"] = 5, ["name"] = "lord_planks:mallorn" },
{["x"] = 5, ["meta"] = { ["fields"] = {}, ["inventory"] = {} }, ["param2"] = 0, ["y"] = 29, ["param1"] = 153, ["z"] = 6, ["name"] = "lottother:air" },
{["x"] = 5, ["meta"] = { ["fields"] = {}, ["inventory"] = {} }, ["param2"] = 0, ["y"] = 29, ["param1"] = 153, ["z"] = 7, ["name"] = "lottother:air" },
{["x"] = 5, ["meta"] = { ["fields"] = {}, ["inventory"] = {} }, ["param2"] = 0, ["y"] = 29, ["param1"] = 0, ["z"] = 8, ["name"] = "lord_planks:mallorn" },
{["x"] = 5, ["meta"] = { ["fields"] = {}, ["inventory"] = {} }, ["param2"] = 0, ["y"] = 29, ["param1"] = 0, ["z"] = 9, ["name"] = "lord_planks:mallorn" },
{["x"] = 5, ["meta"] = { ["fields"] = {}, ["inventory"] = {} }, ["param2"] = 0, ["y"] = 30, ["param1"] = 0, ["z"] = 5, ["name"] = "lord_planks:mallorn" },
{["x"] = 5, ["meta"] = { ["fields"] = {}, ["inventory"] = {} }, ["param2"] = 0, ["y"] = 30, ["param1"] = 0, ["z"] = 6, ["name"] = "lord_planks:mallorn" },
{["x"] = 5, ["meta"] = { ["fields"] = {}, ["inventory"] = {} }, ["param2"] = 0, ["y"] = 30, ["param1"] = 0, ["z"] = 7, ["name"] = "lord_planks:mallorn" },
{["x"] = 5, ["meta"] = { ["fields"] = {}, ["inventory"] = {} }, ["param2"] = 0, ["y"] = 30, ["param1"] = 0, ["z"] = 8, ["name"] = "lord_planks:mallorn" },
{["x"] = 5, ["meta"] = { ["fields"] = {}, ["inventory"] = {} }, ["param2"] = 0, ["y"] = 31, ["param1"] = 0, ["z"] = 6, ["name"] = "lord_planks:mallorn" },
{["x"] = 5, ["meta"] = { ["fields"] = {}, ["inventory"] = {} }, ["param2"] = 0, ["y"] = 31, ["param1"] = 0, ["z"] = 7, ["name"] = "lord_planks:mallorn" },
{["x"] = 5, ["meta"] = { ["fields"] = {}, ["inventory"] = {} }, ["param2"] = 0, ["y"] = 39, ["param1"] = 0, ["z"] = 8, ["name"] = "lord_planks:mallorn" },
{["x"] = 5, ["meta"] = { ["fields"] = {}, ["inventory"] = {} }, ["param2"] = 0, ["y"] = 39, ["param1"] = 0, ["z"] = 9, ["name"] = "lord_planks:mallorn" },
{["x"] = 5, ["meta"] = { ["fields"] = {}, ["inventory"] = {} }, ["param2"] = 0, ["y"] = 40, ["param1"] = 0, ["z"] = 7, ["name"] = "lord_planks:mallorn" },
{["x"] = 5, ["meta"] = { ["fields"] = {}, ["inventory"] = {} }, ["param2"] = 0, ["y"] = 40, ["param1"] = 0, ["z"] = 8, ["name"] = "lord_planks:mallorn" },
{["x"] = 5, ["meta"] = { ["fields"] = {}, ["inventory"] = {} }, ["param2"] = 0, ["y"] = 40, ["param1"] = 0, ["z"] = 9, ["name"] = "lord_planks:mallorn" },
{["x"] = 5, ["meta"] = { ["fields"] = {}, ["inventory"] = {} }, ["param2"] = 0, ["y"] = 40, ["param1"] = 0, ["z"] = 10, ["name"] = "lord_planks:mallorn" },
{["x"] = 5, ["meta"] = { ["fields"] = {}, ["inventory"] = {} }, ["param2"] = 0, ["y"] = 41, ["param1"] = 170, ["z"] = 7, ["name"] = "default:fence_wood" },
{["x"] = 5, ["meta"] = { ["fields"] = {}, ["inventory"] = {} }, ["param2"] = 0, ["y"] = 41, ["param1"] = 153, ["z"] = 8, ["name"] = "default:fence_wood" },
{["x"] = 5, ["meta"] = { ["fields"] = {}, ["inventory"] = {} }, ["param2"] = 0, ["y"] = 41, ["param1"] = 153, ["z"] = 9, ["name"] = "default:fence_wood" },
{["x"] = 5, ["meta"] = { ["fields"] = {}, ["inventory"] = {} }, ["param2"] = 0, ["y"] = 41, ["param1"] = 170, ["z"] = 10, ["name"] = "default:fence_wood" },
{["x"] = 5, ["meta"] = { ["fields"] = {}, ["inventory"] = {} }, ["param2"] = 0, ["y"] = 42, ["param1"] = 187, ["z"] = 7, ["name"] = "default:fence_wood" },
{["x"] = 5, ["meta"] = { ["fields"] = {}, ["inventory"] = {} }, ["param2"] = 0, ["y"] = 42, ["param1"] = 170, ["z"] = 8, ["name"] = "lottother:air" },
{["x"] = 5, ["meta"] = { ["fields"] = {}, ["inventory"] = {} }, ["param2"] = 0, ["y"] = 42, ["param1"] = 170, ["z"] = 9, ["name"] = "lottother:air" },
{["x"] = 5, ["meta"] = { ["fields"] = {}, ["inventory"] = {} }, ["param2"] = 0, ["y"] = 42, ["param1"] = 187, ["z"] = 10, ["name"] = "default:fence_wood" },
{["x"] = 5, ["meta"] = { ["fields"] = {}, ["inventory"] = {} }, ["param2"] = 0, ["y"] = 43, ["param1"] = 170, ["z"] = 7, ["name"] = "default:fence_wood" },
{["x"] = 5, ["meta"] = { ["fields"] = {}, ["inventory"] = {} }, ["param2"] = 0, ["y"] = 43, ["param1"] = 153, ["z"] = 8, ["name"] = "lottother:air" },
{["x"] = 5, ["meta"] = { ["fields"] = {}, ["inventory"] = {} }, ["param2"] = 0, ["y"] = 43, ["param1"] = 153, ["z"] = 9, ["name"] = "lottother:air" },
{["x"] = 5, ["meta"] = { ["fields"] = {}, ["inventory"] = {} }, ["param2"] = 0, ["y"] = 43, ["param1"] = 170, ["z"] = 10, ["name"] = "default:fence_wood" },
{["x"] = 5, ["meta"] = { ["fields"] = {}, ["inventory"] = {} }, ["param2"] = 0, ["y"] = 44, ["param1"] = 154, ["z"] = 7, ["name"] = "default:fence_wood" },
{["x"] = 5, ["meta"] = { ["fields"] = {}, ["inventory"] = {} }, ["param2"] = 0, ["y"] = 44, ["param1"] = 0, ["z"] = 8, ["name"] = "lord_planks:mallorn" },
{["x"] = 5, ["meta"] = { ["fields"] = {}, ["inventory"] = {} }, ["param2"] = 0, ["y"] = 44, ["param1"] = 0, ["z"] = 9, ["name"] = "lord_planks:mallorn" },
{["x"] = 5, ["meta"] = { ["fields"] = {}, ["inventory"] = {} }, ["param2"] = 0, ["y"] = 44, ["param1"] = 153, ["z"] = 10, ["name"] = "default:fence_wood" },
{["x"] = 5, ["meta"] = { ["fields"] = {}, ["inventory"] = {} }, ["param2"] = 0, ["y"] = 45, ["param1"] = 0, ["z"] = 7, ["name"] = "lord_planks:mallorn" },
{["x"] = 5, ["meta"] = { ["fields"] = {}, ["inventory"] = {} }, ["param2"] = 0, ["y"] = 45, ["param1"] = 0, ["z"] = 8, ["name"] = "lord_planks:mallorn" },
{["x"] = 5, ["meta"] = { ["fields"] = {}, ["inventory"] = {} }, ["param2"] = 0, ["y"] = 45, ["param1"] = 0, ["z"] = 9, ["name"] = "lord_planks:mallorn" },
{["x"] = 5, ["meta"] = { ["fields"] = {}, ["inventory"] = {} }, ["param2"] = 0, ["y"] = 45, ["param1"] = 0, ["z"] = 10, ["name"] = "lord_planks:mallorn" },
{["x"] = 5, ["meta"] = { ["fields"] = {}, ["inventory"] = {} }, ["param2"] = 0, ["y"] = 46, ["param1"] = 0, ["z"] = 7, ["name"] = "lord_planks:mallorn" },
{["x"] = 5, ["meta"] = { ["fields"] = {}, ["inventory"] = {} }, ["param2"] = 0, ["y"] = 46, ["param1"] = 187, ["z"] = 8, ["name"] = "lottother:air" },
{["x"] = 5, ["meta"] = { ["fields"] = {}, ["inventory"] = {} }, ["param2"] = 0, ["y"] = 46, ["param1"] = 187, ["z"] = 9, ["name"] = "lottother:air" },
{["x"] = 5, ["meta"] = { ["fields"] = {}, ["inventory"] = {} }, ["param2"] = 0, ["y"] = 46, ["param1"] = 0, ["z"] = 10, ["name"] = "lord_planks:mallorn" },
{["x"] = 5, ["meta"] = { ["fields"] = {}, ["inventory"] = {} }, ["param2"] = 0, ["y"] = 47, ["param1"] = 0, ["z"] = 7, ["name"] = "lord_planks:mallorn" },
{["x"] = 5, ["meta"] = { ["fields"] = {}, ["inventory"] = {} }, ["param2"] = 0, ["y"] = 47, ["param1"] = 170, ["z"] = 8, ["name"] = "lottother:air" },
{["x"] = 5, ["meta"] = { ["fields"] = {}, ["inventory"] = {} }, ["param2"] = 0, ["y"] = 47, ["param1"] = 170, ["z"] = 9, ["name"] = "lottother:air" },
{["x"] = 5, ["meta"] = { ["fields"] = {}, ["inventory"] = {} }, ["param2"] = 0, ["y"] = 47, ["param1"] = 0, ["z"] = 10, ["name"] = "lord_planks:mallorn" },
{["x"] = 5, ["meta"] = { ["fields"] = {}, ["inventory"] = {} }, ["param2"] = 0, ["y"] = 48, ["param1"] = 0, ["z"] = 6, ["name"] = "lord_planks:mallorn" },
{["x"] = 5, ["meta"] = { ["fields"] = {}, ["inventory"] = {} }, ["param2"] = 0, ["y"] = 48, ["param1"] = 0, ["z"] = 7, ["name"] = "lord_planks:mallorn" },
{["x"] = 5, ["meta"] = { ["fields"] = {}, ["inventory"] = {} }, ["param2"] = 0, ["y"] = 48, ["param1"] = 187, ["z"] = 8, ["name"] = "lottother:air" },
{["x"] = 5, ["meta"] = { ["fields"] = {}, ["inventory"] = {} }, ["param2"] = 0, ["y"] = 48, ["param1"] = 187, ["z"] = 9, ["name"] = "lottother:air" },
{["x"] = 5, ["meta"] = { ["fields"] = {}, ["inventory"] = {} }, ["param2"] = 0, ["y"] = 48, ["param1"] = 0, ["z"] = 10, ["name"] = "lord_planks:mallorn" },
{["x"] = 5, ["meta"] = { ["fields"] = {}, ["inventory"] = {} }, ["param2"] = 0, ["y"] = 48, ["param1"] = 0, ["z"] = 11, ["name"] = "lord_planks:mallorn" },
{["x"] = 5, ["meta"] = { ["fields"] = {}, ["inventory"] = {} }, ["param2"] = 0, ["y"] = 49, ["param1"] = 0, ["z"] = 7, ["name"] = "lord_planks:mallorn" },
{["x"] = 5, ["meta"] = { ["fields"] = {}, ["inventory"] = {} }, ["param2"] = 0, ["y"] = 49, ["param1"] = 0, ["z"] = 8, ["name"] = "lord_planks:mallorn" },
{["x"] = 5, ["meta"] = { ["fields"] = {}, ["inventory"] = {} }, ["param2"] = 0, ["y"] = 49, ["param1"] = 0, ["z"] = 9, ["name"] = "lord_planks:mallorn" },
{["x"] = 5, ["meta"] = { ["fields"] = {}, ["inventory"] = {} }, ["param2"] = 0, ["y"] = 49, ["param1"] = 0, ["z"] = 10, ["name"] = "lord_planks:mallorn" },
{["x"] = 5, ["meta"] = { ["fields"] = {}, ["inventory"] = {} }, ["param2"] = 0, ["y"] = 50, ["param1"] = 0, ["z"] = 8, ["name"] = "lord_planks:mallorn" },
{["x"] = 5, ["meta"] = { ["fields"] = {}, ["inventory"] = {} }, ["param2"] = 0, ["y"] = 50, ["param1"] = 0, ["z"] = 9, ["name"] = "lord_planks:mallorn" },
{["x"] = 5, ["meta"] = { ["fields"] = {}, ["inventory"] = {} }, ["param2"] = 0, ["y"] = 52, ["param1"] = 107, ["z"] = 7, ["name"] = "lord_trees:mallorn_leaf" },
{["x"] = 5, ["meta"] = { ["fields"] = {}, ["inventory"] = {} }, ["param2"] = 0, ["y"] = 52, ["param1"] = 123, ["z"] = 8, ["name"] = "lord_trees:mallorn_leaf" },
{["x"] = 5, ["meta"] = { ["fields"] = {}, ["inventory"] = {} }, ["param2"] = 0, ["y"] = 52, ["param1"] = 122, ["z"] = 9, ["name"] = "lord_trees:mallorn_leaf" },
{["x"] = 5, ["meta"] = { ["fields"] = {}, ["inventory"] = {} }, ["param2"] = 0, ["y"] = 52, ["param1"] = 106, ["z"] = 10, ["name"] = "lord_trees:mallorn_leaf" },
{["x"] = 5, ["meta"] = { ["fields"] = {}, ["inventory"] = {} }, ["param2"] = 0, ["y"] = 52, ["param1"] = 0, ["z"] = 11, ["name"] = "lord_trees:mallorn_tree" },
{["x"] = 5, ["meta"] = { ["fields"] = {}, ["inventory"] = {} }, ["param2"] = 0, ["y"] = 52, ["param1"] = 75, ["z"] = 12, ["name"] = "lord_trees:mallorn_leaf" },
{["x"] = 5, ["meta"] = { ["fields"] = {}, ["inventory"] = {} }, ["param2"] = 0, ["y"] = 53, ["param1"] = 13, ["z"] = 2, ["name"] = "lord_trees:mallorn_leaf" },
{["x"] = 5, ["meta"] = { ["fields"] = {}, ["inventory"] = {} }, ["param2"] = 0, ["y"] = 53, ["param1"] = 29, ["z"] = 3, ["name"] = "lord_trees:mallorn_leaf" },
{["x"] = 5, ["meta"] = { ["fields"] = {}, ["inventory"] = {} }, ["param2"] = 0, ["y"] = 53, ["param1"] = 45, ["z"] = 4, ["name"] = "lord_trees:mallorn_leaf" },
{["x"] = 5, ["meta"] = { ["fields"] = {}, ["inventory"] = {} }, ["param2"] = 0, ["y"] = 53, ["param1"] = 60, ["z"] = 5, ["name"] = "lord_trees:mallorn_leaf" },
{["x"] = 5, ["meta"] = { ["fields"] = {}, ["inventory"] = {} }, ["param2"] = 0, ["y"] = 53, ["param1"] = 76, ["z"] = 6, ["name"] = "lord_trees:mallorn_leaf" },
{["x"] = 5, ["meta"] = { ["fields"] = {}, ["inventory"] = {} }, ["param2"] = 0, ["y"] = 53, ["param1"] = 92, ["z"] = 7, ["name"] = "lord_trees:mallorn_leaf" },
{["x"] = 5, ["meta"] = { ["fields"] = {}, ["inventory"] = {} }, ["param2"] = 0, ["y"] = 53, ["param1"] = 108, ["z"] = 8, ["name"] = "lord_trees:mallorn_leaf" },
{["x"] = 5, ["meta"] = { ["fields"] = {}, ["inventory"] = {} }, ["param2"] = 0, ["y"] = 53, ["param1"] = 107, ["z"] = 9, ["name"] = "lord_trees:mallorn_leaf" },
{["x"] = 5, ["meta"] = { ["fields"] = {}, ["inventory"] = {} }, ["param2"] = 0, ["y"] = 53, ["param1"] = 91, ["z"] = 10, ["name"] = "lord_trees:mallorn_leaf" },
{["x"] = 5, ["meta"] = { ["fields"] = {}, ["inventory"] = {} }, ["param2"] = 0, ["y"] = 53, ["param1"] = 76, ["z"] = 11, ["name"] = "lord_trees:mallorn_leaf" },
{["x"] = 5, ["meta"] = { ["fields"] = {}, ["inventory"] = {} }, ["param2"] = 0, ["y"] = 53, ["param1"] = 60, ["z"] = 12, ["name"] = "lord_trees:mallorn_leaf" },
{["x"] = 5, ["meta"] = { ["fields"] = {}, ["inventory"] = {} }, ["param2"] = 0, ["y"] = 53, ["param1"] = 44, ["z"] = 13, ["name"] = "lord_trees:mallorn_leaf" },
{["x"] = 5, ["meta"] = { ["fields"] = {}, ["inventory"] = {} }, ["param2"] = 0, ["y"] = 53, ["param1"] = 29, ["z"] = 14, ["name"] = "lord_trees:mallorn_leaf" },
{["x"] = 5, ["meta"] = { ["fields"] = {}, ["inventory"] = {} }, ["param2"] = 0, ["y"] = 53, ["param1"] = 13, ["z"] = 15, ["name"] = "lord_trees:mallorn_leaf" },
{["x"] = 5, ["meta"] = { ["fields"] = {}, ["inventory"] = {} }, ["param2"] = 0, ["y"] = 53, ["param1"] = 13, ["z"] = 16, ["name"] = "lord_trees:mallorn_leaf" },
{["x"] = 5, ["meta"] = { ["fields"] = {}, ["inventory"] = {} }, ["param2"] = 0, ["y"] = 54, ["param1"] = 45, ["z"] = 5, ["name"] = "lord_trees:mallorn_leaf" },
{["x"] = 5, ["meta"] = { ["fields"] = {}, ["inventory"] = {} }, ["param2"] = 0, ["y"] = 54, ["param1"] = 61, ["z"] = 6, ["name"] = "lord_trees:mallorn_leaf" },
{["x"] = 5, ["meta"] = { ["fields"] = {}, ["inventory"] = {} }, ["param2"] = 0, ["y"] = 54, ["param1"] = 77, ["z"] = 7, ["name"] = "lord_trees:mallorn_leaf" },
{["x"] = 5, ["meta"] = { ["fields"] = {}, ["inventory"] = {} }, ["param2"] = 0, ["y"] = 54, ["param1"] = 93, ["z"] = 8, ["name"] = "lord_trees:mallorn_leaf" },
{["x"] = 5, ["meta"] = { ["fields"] = {}, ["inventory"] = {} }, ["param2"] = 0, ["y"] = 54, ["param1"] = 92, ["z"] = 9, ["name"] = "lord_trees:mallorn_leaf" },
{["x"] = 5, ["meta"] = { ["fields"] = {}, ["inventory"] = {} }, ["param2"] = 0, ["y"] = 54, ["param1"] = 76, ["z"] = 10, ["name"] = "lord_trees:mallorn_leaf" },
{["x"] = 5, ["meta"] = { ["fields"] = {}, ["inventory"] = {} }, ["param2"] = 0, ["y"] = 54, ["param1"] = 61, ["z"] = 11, ["name"] = "lord_trees:mallorn_leaf" },
{["x"] = 5, ["meta"] = { ["fields"] = {}, ["inventory"] = {} }, ["param2"] = 0, ["y"] = 54, ["param1"] = 45, ["z"] = 12, ["name"] = "lord_trees:mallorn_leaf" },
{["x"] = 5, ["meta"] = { ["fields"] = {}, ["inventory"] = {} }, ["param2"] = 0, ["y"] = 54, ["param1"] = 29, ["z"] = 13, ["name"] = "lord_trees:mallorn_leaf" },
{["x"] = 5, ["meta"] = { ["fields"] = {}, ["inventory"] = {} }, ["param2"] = 0, ["y"] = 54, ["param1"] = 13, ["z"] = 16, ["name"] = "lord_trees:mallorn_leaf" },
{["x"] = 5, ["meta"] = { ["fields"] = {}, ["inventory"] = {} }, ["param2"] = 0, ["y"] = 55, ["param1"] = 77, ["z"] = 9, ["name"] = "lord_trees:mallorn_leaf" },
{["x"] = 5, ["meta"] = { ["fields"] = {}, ["inventory"] = {} }, ["param2"] = 0, ["y"] = 55, ["param1"] = 61, ["z"] = 10, ["name"] = "lord_trees:mallorn_leaf" },
{["x"] = 6, ["meta"] = { ["fields"] = {}, ["inventory"] = {} }, ["param2"] = 0, ["y"] = 0, ["param1"] = 11, ["z"] = 3, ["name"] = "lottother:dirt" },
{["x"] = 6, ["meta"] = { ["fields"] = {}, ["inventory"] = {} }, ["param2"] = 0, ["y"] = 0, ["param1"] = 10, ["z"] = 4, ["name"] = "lottother:dirt" },
{["x"] = 6, ["meta"] = { ["fields"] = {}, ["inventory"] = {} }, ["param2"] = 0, ["y"] = 0, ["param1"] = 9, ["z"] = 5, ["name"] = "lottother:dirt" },
{["x"] = 6, ["meta"] = { ["fields"] = {}, ["inventory"] = {} }, ["param2"] = 0, ["y"] = 0, ["param1"] = 9, ["z"] = 6, ["name"] = "lottother:dirt" },
{["x"] = 6, ["meta"] = { ["fields"] = {}, ["inventory"] = {} }, ["param2"] = 0, ["y"] = 0, ["param1"] = 9, ["z"] = 7, ["name"] = "lottother:dirt" },
{["x"] = 6, ["meta"] = { ["fields"] = {}, ["inventory"] = {} }, ["param2"] = 0, ["y"] = 0, ["param1"] = 8, ["z"] = 8, ["name"] = "lottother:dirt" },
{["x"] = 6, ["meta"] = { ["fields"] = {}, ["inventory"] = {} }, ["param2"] = 0, ["y"] = 0, ["param1"] = 7, ["z"] = 9, ["name"] = "lottother:dirt" },
{["x"] = 6, ["meta"] = { ["fields"] = {}, ["inventory"] = {} }, ["param2"] = 0, ["y"] = 0, ["param1"] = 7, ["z"] = 10, ["name"] = "lottother:dirt" },
{["x"] = 6, ["meta"] = { ["fields"] = {}, ["inventory"] = {} }, ["param2"] = 0, ["y"] = 0, ["param1"] = 8, ["z"] = 11, ["name"] = "lottother:dirt" },
{["x"] = 6, ["meta"] = { ["fields"] = {}, ["inventory"] = {} }, ["param2"] = 0, ["y"] = 0, ["param1"] = 9, ["z"] = 12, ["name"] = "lottother:dirt" },
{["x"] = 6, ["meta"] = { ["fields"] = {}, ["inventory"] = {} }, ["param2"] = 0, ["y"] = 0, ["param1"] = 10, ["z"] = 13, ["name"] = "lottother:dirt" },
{["x"] = 6, ["meta"] = { ["fields"] = {}, ["inventory"] = {} }, ["param2"] = 0, ["y"] = 0, ["param1"] = 11, ["z"] = 14, ["name"] = "lottother:dirt" },
{["x"] = 6, ["meta"] = { ["fields"] = {}, ["inventory"] = {} }, ["param2"] = 0, ["y"] = 1, ["param1"] = 0, ["z"] = 3, ["name"] = "lottmapgen:lorien_grass" },
{["x"] = 6, ["meta"] = { ["fields"] = {}, ["inventory"] = {} }, ["param2"] = 0, ["y"] = 1, ["param1"] = 0, ["z"] = 4, ["name"] = "lottother:dirt" },
{["x"] = 6, ["meta"] = { ["fields"] = {}, ["inventory"] = {} }, ["param2"] = 0, ["y"] = 1, ["param1"] = 0, ["z"] = 5, ["name"] = "lottother:dirt" },
{["x"] = 6, ["meta"] = { ["fields"] = {}, ["inventory"] = {} }, ["param2"] = 0, ["y"] = 1, ["param1"] = 0, ["z"] = 6, ["name"] = "lottother:dirt" },
{["x"] = 6, ["meta"] = { ["fields"] = {}, ["inventory"] = {} }, ["param2"] = 0, ["y"] = 1, ["param1"] = 0, ["z"] = 7, ["name"] = "lottother:dirt" },
{["x"] = 6, ["meta"] = { ["fields"] = {}, ["inventory"] = {} }, ["param2"] = 0, ["y"] = 1, ["param1"] = 0, ["z"] = 8, ["name"] = "lottother:dirt" },
{["x"] = 6, ["meta"] = { ["fields"] = {}, ["inventory"] = {} }, ["param2"] = 0, ["y"] = 1, ["param1"] = 0, ["z"] = 9, ["name"] = "lottother:dirt" },
{["x"] = 6, ["meta"] = { ["fields"] = {}, ["inventory"] = {} }, ["param2"] = 0, ["y"] = 1, ["param1"] = 0, ["z"] = 10, ["name"] = "lottother:dirt" },
{["x"] = 6, ["meta"] = { ["fields"] = {}, ["inventory"] = {} }, ["param2"] = 0, ["y"] = 1, ["param1"] = 0, ["z"] = 11, ["name"] = "lottother:dirt" },
{["x"] = 6, ["meta"] = { ["fields"] = {}, ["inventory"] = {} }, ["param2"] = 0, ["y"] = 1, ["param1"] = 0, ["z"] = 12, ["name"] = "lottother:dirt" },
{["x"] = 6, ["meta"] = { ["fields"] = {}, ["inventory"] = {} }, ["param2"] = 0, ["y"] = 1, ["param1"] = 0, ["z"] = 13, ["name"] = "lottother:dirt" },
{["x"] = 6, ["meta"] = { ["fields"] = {}, ["inventory"] = {} }, ["param2"] = 0, ["y"] = 1, ["param1"] = 0, ["z"] = 14, ["name"] = "lottmapgen:lorien_grass" },
{["x"] = 6, ["meta"] = { ["fields"] = {}, ["inventory"] = {} }, ["param2"] = 0, ["y"] = 2, ["param1"] = 0, ["z"] = 4, ["name"] = "lottmapgen:lorien_grass" },
{["x"] = 6, ["meta"] = { ["fields"] = {}, ["inventory"] = {} }, ["param2"] = 0, ["y"] = 2, ["param1"] = 0, ["z"] = 5, ["name"] = "lottmapgen:lorien_grass" },
{["x"] = 6, ["meta"] = { ["fields"] = {}, ["inventory"] = {} }, ["param2"] = 0, ["y"] = 2, ["param1"] = 0, ["z"] = 6, ["name"] = "lottother:dirt" },
{["x"] = 6, ["meta"] = { ["fields"] = {}, ["inventory"] = {} }, ["param2"] = 0, ["y"] = 2, ["param1"] = 0, ["z"] = 7, ["name"] = "lottother:dirt" },
{["x"] = 6, ["meta"] = { ["fields"] = {}, ["inventory"] = {} }, ["param2"] = 0, ["y"] = 2, ["param1"] = 0, ["z"] = 8, ["name"] = "lottother:dirt" },
{["x"] = 6, ["meta"] = { ["fields"] = {}, ["inventory"] = {} }, ["param2"] = 0, ["y"] = 2, ["param1"] = 0, ["z"] = 9, ["name"] = "lottother:dirt" },
{["x"] = 6, ["meta"] = { ["fields"] = {}, ["inventory"] = {} }, ["param2"] = 0, ["y"] = 2, ["param1"] = 0, ["z"] = 10, ["name"] = "lottother:dirt" },
{["x"] = 6, ["meta"] = { ["fields"] = {}, ["inventory"] = {} }, ["param2"] = 0, ["y"] = 2, ["param1"] = 0, ["z"] = 11, ["name"] = "lottother:dirt" },
{["x"] = 6, ["meta"] = { ["fields"] = {}, ["inventory"] = {} }, ["param2"] = 0, ["y"] = 2, ["param1"] = 0, ["z"] = 12, ["name"] = "lottmapgen:lorien_grass" },
{["x"] = 6, ["meta"] = { ["fields"] = {}, ["inventory"] = {} }, ["param2"] = 0, ["y"] = 2, ["param1"] = 0, ["z"] = 13, ["name"] = "lottmapgen:lorien_grass" },
{["x"] = 6, ["meta"] = { ["fields"] = {}, ["inventory"] = {} }, ["param2"] = 1, ["y"] = 3, ["param1"] = 0, ["z"] = 6, ["name"] = "lord_trees:mallorn_tree" },
{["x"] = 6, ["meta"] = { ["fields"] = {}, ["inventory"] = {} }, ["param2"] = 0, ["y"] = 3, ["param1"] = 0, ["z"] = 7, ["name"] = "lord_trees:mallorn_tree" },
{["x"] = 6, ["meta"] = { ["fields"] = {}, ["inventory"] = {} }, ["param2"] = 0, ["y"] = 3, ["param1"] = 0, ["z"] = 8, ["name"] = "lord_trees:mallorn_tree" },
{["x"] = 6, ["meta"] = { ["fields"] = {}, ["inventory"] = {} }, ["param2"] = 0, ["y"] = 3, ["param1"] = 0, ["z"] = 9, ["name"] = "lord_trees:mallorn_tree" },
{["x"] = 6, ["meta"] = { ["fields"] = {}, ["inventory"] = {} }, ["param2"] = 1, ["y"] = 3, ["param1"] = 0, ["z"] = 10, ["name"] = "lord_trees:mallorn_tree" },
{["x"] = 6, ["meta"] = { ["fields"] = {}, ["inventory"] = {} }, ["param2"] = 1, ["y"] = 3, ["param1"] = 0, ["z"] = 11, ["name"] = "lord_trees:mallorn_tree" },
{["x"] = 6, ["meta"] = { ["fields"] = {}, ["inventory"] = {} }, ["param2"] = 1, ["y"] = 4, ["param1"] = 0, ["z"] = 6, ["name"] = "lord_trees:mallorn_tree" },
{["x"] = 6, ["meta"] = { ["fields"] = {}, ["inventory"] = {} }, ["param2"] = 1, ["y"] = 4, ["param1"] = 0, ["z"] = 7, ["name"] = "lord_trees:mallorn_tree" },
{["x"] = 6, ["meta"] = { ["fields"] = {}, ["inventory"] = {} }, ["param2"] = 0, ["y"] = 4, ["param1"] = 0, ["z"] = 8, ["name"] = "lord_trees:mallorn_tree" },
{["x"] = 6, ["meta"] = { ["fields"] = {}, ["inventory"] = {} }, ["param2"] = 0, ["y"] = 4, ["param1"] = 0, ["z"] = 9, ["name"] = "lord_trees:mallorn_tree" },
{["x"] = 6, ["meta"] = { ["fields"] = {}, ["inventory"] = {} }, ["param2"] = 1, ["y"] = 4, ["param1"] = 0, ["z"] = 11, ["name"] = "lord_trees:mallorn_tree" },
{["x"] = 6, ["meta"] = { ["fields"] = {}, ["inventory"] = {} }, ["param2"] = 1, ["y"] = 5, ["param1"] = 0, ["z"] = 7, ["name"] = "lord_trees:mallorn_tree" },
{["x"] = 6, ["meta"] = { ["fields"] = {}, ["inventory"] = {} }, ["param2"] = 0, ["y"] = 5, ["param1"] = 0, ["z"] = 8, ["name"] = "lord_trees:mallorn_tree" },
{["x"] = 6, ["meta"] = { ["fields"] = {}, ["inventory"] = {} }, ["param2"] = 0, ["y"] = 5, ["param1"] = 0, ["z"] = 9, ["name"] = "lord_trees:mallorn_tree" },
{["x"] = 6, ["meta"] = { ["fields"] = {}, ["inventory"] = {} }, ["param2"] = 18, ["y"] = 5, ["param1"] = 0, ["z"] = 10, ["name"] = "lord_trees:mallorn_tree" },
{["x"] = 6, ["meta"] = { ["fields"] = {}, ["inventory"] = {} }, ["param2"] = 1, ["y"] = 5, ["param1"] = 0, ["z"] = 11, ["name"] = "lord_trees:mallorn_tree" },
{["x"] = 6, ["meta"] = { ["fields"] = {}, ["inventory"] = {} }, ["param2"] = 1, ["y"] = 6, ["param1"] = 0, ["z"] = 7, ["name"] = "lord_trees:mallorn_tree" },
{["x"] = 6, ["meta"] = { ["fields"] = {}, ["inventory"] = {} }, ["param2"] = 1, ["y"] = 6, ["param1"] = 0, ["z"] = 8, ["name"] = "lord_trees:mallorn_tree" },
{["x"] = 6, ["meta"] = { ["fields"] = {}, ["inventory"] = {} }, ["param2"] = 0, ["y"] = 6, ["param1"] = 0, ["z"] = 9, ["name"] = "lord_trees:mallorn_tree" },
{["x"] = 6, ["meta"] = { ["fields"] = {}, ["inventory"] = {} }, ["param2"] = 1, ["y"] = 6, ["param1"] = 0, ["z"] = 10, ["name"] = "lord_trees:mallorn_tree" },
{["x"] = 6, ["meta"] = { ["fields"] = {}, ["inventory"] = {} }, ["param2"] = 1, ["y"] = 6, ["param1"] = 0, ["z"] = 11, ["name"] = "lord_trees:mallorn_tree" },
{["x"] = 6, ["meta"] = { ["fields"] = {}, ["inventory"] = {} }, ["param2"] = 0, ["y"] = 7, ["param1"] = 9, ["z"] = 7, ["name"] = "lottother:air" },
{["x"] = 6, ["meta"] = { ["fields"] = {}, ["inventory"] = {} }, ["param2"] = 1, ["y"] = 7, ["param1"] = 0, ["z"] = 8, ["name"] = "lord_trees:mallorn_tree" },
{["x"] = 6, ["meta"] = { ["fields"] = {}, ["inventory"] = {} }, ["param2"] = 1, ["y"] = 7, ["param1"] = 0, ["z"] = 9, ["name"] = "lord_trees:mallorn_tree" },
{["x"] = 6, ["meta"] = { ["fields"] = {}, ["inventory"] = {} }, ["param2"] = 1, ["y"] = 7, ["param1"] = 0, ["z"] = 10, ["name"] = "lord_trees:mallorn_tree" },
{["x"] = 6, ["meta"] = { ["fields"] = {}, ["inventory"] = {} }, ["param2"] = 1, ["y"] = 7, ["param1"] = 0, ["z"] = 11, ["name"] = "lord_trees:mallorn_tree" },
{["x"] = 6, ["meta"] = { ["fields"] = {}, ["inventory"] = {} }, ["param2"] = 0, ["y"] = 8, ["param1"] = 9, ["z"] = 7, ["name"] = "lottother:air" },
{["x"] = 6, ["meta"] = { ["fields"] = {}, ["inventory"] = {} }, ["param2"] = 1, ["y"] = 8, ["param1"] = 0, ["z"] = 8, ["name"] = "lord_trees:mallorn_tree" },
{["x"] = 6, ["meta"] = { ["fields"] = {}, ["inventory"] = {} }, ["param2"] = 1, ["y"] = 8, ["param1"] = 0, ["z"] = 9, ["name"] = "lord_trees:mallorn_tree" },
{["x"] = 6, ["meta"] = { ["fields"] = {}, ["inventory"] = {} }, ["param2"] = 1, ["y"] = 8, ["param1"] = 0, ["z"] = 11, ["name"] = "lord_trees:mallorn_tree" },
{["x"] = 6, ["meta"] = { ["fields"] = {}, ["inventory"] = {} }, ["param2"] = 0, ["y"] = 9, ["param1"] = 9, ["z"] = 7, ["name"] = "lottother:air" },
{["x"] = 6, ["meta"] = { ["fields"] = {}, ["inventory"] = {} }, ["param2"] = 2, ["y"] = 9, ["param1"] = 8, ["z"] = 8, ["name"] = "default:ladder" },
{["x"] = 6, ["meta"] = { ["fields"] = {}, ["inventory"] = {} }, ["param2"] = 1, ["y"] = 9, ["param1"] = 0, ["z"] = 9, ["name"] = "lord_trees:mallorn_tree" },
{["x"] = 6, ["meta"] = { ["fields"] = {}, ["inventory"] = {} }, ["param2"] = 1, ["y"] = 9, ["param1"] = 0, ["z"] = 11, ["name"] = "lord_trees:mallorn_tree" },
{["x"] = 6, ["meta"] = { ["fields"] = {}, ["inventory"] = {} }, ["param2"] = 0, ["y"] = 10, ["param1"] = 9, ["z"] = 7, ["name"] = "lottother:air" },
{["x"] = 6, ["meta"] = { ["fields"] = {}, ["inventory"] = {} }, ["param2"] = 2, ["y"] = 10, ["param1"] = 8, ["z"] = 8, ["name"] = "default:ladder" },
{["x"] = 6, ["meta"] = { ["fields"] = {}, ["inventory"] = {} }, ["param2"] = 0, ["y"] = 10, ["param1"] = 7, ["z"] = 9, ["name"] = "lottother:air" },
{["x"] = 6, ["meta"] = { ["fields"] = {}, ["inventory"] = {} }, ["param2"] = 0, ["y"] = 11, ["param1"] = 9, ["z"] = 7, ["name"] = "lottother:air" },
{["x"] = 6, ["meta"] = { ["fields"] = {}, ["inventory"] = {} }, ["param2"] = 2, ["y"] = 11, ["param1"] = 8, ["z"] = 8, ["name"] = "default:ladder" },
{["x"] = 6, ["meta"] = { ["fields"] = {}, ["inventory"] = {} }, ["param2"] = 0, ["y"] = 11, ["param1"] = 7, ["z"] = 9, ["name"] = "lottother:air" },
{["x"] = 6, ["meta"] = { ["fields"] = {}, ["inventory"] = {} }, ["param2"] = 0, ["y"] = 12, ["param1"] = 9, ["z"] = 7, ["name"] = "lottother:air" },
{["x"] = 6, ["meta"] = { ["fields"] = {}, ["inventory"] = {} }, ["param2"] = 2, ["y"] = 12, ["param1"] = 8, ["z"] = 8, ["name"] = "default:ladder" },
{["x"] = 6, ["meta"] = { ["fields"] = {}, ["inventory"] = {} }, ["param2"] = 0, ["y"] = 12, ["param1"] = 23, ["z"] = 9, ["name"] = "lottother:air" },
{["x"] = 6, ["meta"] = { ["fields"] = {}, ["inventory"] = {} }, ["param2"] = 0, ["y"] = 13, ["param1"] = 9, ["z"] = 7, ["name"] = "lottother:air" },
{["x"] = 6, ["meta"] = { ["fields"] = {}, ["inventory"] = {} }, ["param2"] = 2, ["y"] = 13, ["param1"] = 24, ["z"] = 8, ["name"] = "default:ladder" },
{["x"] = 6, ["meta"] = { ["fields"] = {}, ["inventory"] = {} }, ["param2"] = 0, ["y"] = 13, ["param1"] = 39, ["z"] = 9, ["name"] = "lottother:air" },
{["x"] = 6, ["meta"] = { ["fields"] = {}, ["inventory"] = {} }, ["param2"] = 0, ["y"] = 14, ["param1"] = 25, ["z"] = 7, ["name"] = "lottother:air" },
{["x"] = 6, ["meta"] = { ["fields"] = {}, ["inventory"] = {} }, ["param2"] = 2, ["y"] = 14, ["param1"] = 40, ["z"] = 8, ["name"] = "default:ladder" },
{["x"] = 6, ["meta"] = { ["fields"] = {}, ["inventory"] = {} }, ["param2"] = 0, ["y"] = 14, ["param1"] = 55, ["z"] = 9, ["name"] = "lottother:air" },
{["x"] = 6, ["meta"] = { ["fields"] = {}, ["inventory"] = {} }, ["param2"] = 0, ["y"] = 15, ["param1"] = 41, ["z"] = 7, ["name"] = "lottother:air" },
{["x"] = 6, ["meta"] = { ["fields"] = {}, ["inventory"] = {} }, ["param2"] = 2, ["y"] = 15, ["param1"] = 56, ["z"] = 8, ["name"] = "default:ladder" },
{["x"] = 6, ["meta"] = { ["fields"] = {}, ["inventory"] = {} }, ["param2"] = 0, ["y"] = 15, ["param1"] = 71, ["z"] = 9, ["name"] = "lottother:air" },
{["x"] = 6, ["meta"] = { ["fields"] = {}, ["inventory"] = {} }, ["param2"] = 0, ["y"] = 16, ["param1"] = 57, ["z"] = 7, ["name"] = "lottother:air" },
{["x"] = 6, ["meta"] = { ["fields"] = {}, ["inventory"] = {} }, ["param2"] = 2, ["y"] = 16, ["param1"] = 72, ["z"] = 8, ["name"] = "default:ladder" },
{["x"] = 6, ["meta"] = { ["fields"] = {}, ["inventory"] = {} }, ["param2"] = 0, ["y"] = 16, ["param1"] = 87, ["z"] = 9, ["name"] = "lottother:air" },
{["x"] = 6, ["meta"] = { ["fields"] = {}, ["inventory"] = {} }, ["param2"] = 0, ["y"] = 17, ["param1"] = 73, ["z"] = 7, ["name"] = "lottother:air" },
{["x"] = 6, ["meta"] = { ["fields"] = {}, ["inventory"] = {} }, ["param2"] = 2, ["y"] = 17, ["param1"] = 88, ["z"] = 8, ["name"] = "default:ladder" },
{["x"] = 6, ["meta"] = { ["fields"] = {}, ["inventory"] = {} }, ["param2"] = 0, ["y"] = 17, ["param1"] = 103, ["z"] = 9, ["name"] = "lottother:air" },
{["x"] = 6, ["meta"] = { ["fields"] = {}, ["inventory"] = {} }, ["param2"] = 0, ["y"] = 18, ["param1"] = 89, ["z"] = 7, ["name"] = "lottother:air" },
{["x"] = 6, ["meta"] = { ["fields"] = {}, ["inventory"] = {} }, ["param2"] = 2, ["y"] = 18, ["param1"] = 104, ["z"] = 8, ["name"] = "default:ladder" },
{["x"] = 6, ["meta"] = { ["fields"] = {}, ["inventory"] = {} }, ["param2"] = 0, ["y"] = 18, ["param1"] = 119, ["z"] = 9, ["name"] = "lottother:air" },
{["x"] = 6, ["meta"] = { ["fields"] = {}, ["inventory"] = {} }, ["param2"] = 0, ["y"] = 19, ["param1"] = 105, ["z"] = 7, ["name"] = "lottother:air" },
{["x"] = 6, ["meta"] = { ["fields"] = {}, ["inventory"] = {} }, ["param2"] = 2, ["y"] = 19, ["param1"] = 120, ["z"] = 8, ["name"] = "default:ladder" },
{["x"] = 6, ["meta"] = { ["fields"] = {}, ["inventory"] = {} }, ["param2"] = 0, ["y"] = 19, ["param1"] = 136, ["z"] = 9, ["name"] = "lottother:air" },
{["x"] = 6, ["meta"] = { ["fields"] = {}, ["inventory"] = {} }, ["param2"] = 0, ["y"] = 20, ["param1"] = 121, ["z"] = 7, ["name"] = "lottother:air" },
{["x"] = 6, ["meta"] = { ["fields"] = {}, ["inventory"] = {} }, ["param2"] = 2, ["y"] = 20, ["param1"] = 136, ["z"] = 8, ["name"] = "default:ladder" },
{["x"] = 6, ["meta"] = { ["fields"] = {}, ["inventory"] = {} }, ["param2"] = 0, ["y"] = 20, ["param1"] = 153, ["z"] = 9, ["name"] = "lottother:air" },
{["x"] = 6, ["meta"] = { ["fields"] = {}, ["inventory"] = {} }, ["param2"] = 0, ["y"] = 21, ["param1"] = 137, ["z"] = 7, ["name"] = "lottother:air" },
{["x"] = 6, ["meta"] = { ["fields"] = {}, ["inventory"] = {} }, ["param2"] = 2, ["y"] = 21, ["param1"] = 153, ["z"] = 8, ["name"] = "default:ladder" },
{["x"] = 6, ["meta"] = { ["fields"] = {}, ["inventory"] = {} }, ["param2"] = 0, ["y"] = 21, ["param1"] = 170, ["z"] = 9, ["name"] = "lottother:air" },
{["x"] = 6, ["meta"] = { ["fields"] = {}, ["inventory"] = {} }, ["param2"] = 0, ["y"] = 22, ["param1"] = 153, ["z"] = 7, ["name"] = "lottother:air" },
{["x"] = 6, ["meta"] = { ["fields"] = {}, ["inventory"] = {} }, ["param2"] = 2, ["y"] = 22, ["param1"] = 170, ["z"] = 8, ["name"] = "default:ladder" },
{["x"] = 6, ["meta"] = { ["fields"] = {}, ["inventory"] = {} }, ["param2"] = 0, ["y"] = 22, ["param1"] = 187, ["z"] = 9, ["name"] = "lottother:air" },
{["x"] = 6, ["meta"] = { ["fields"] = {}, ["inventory"] = {} }, ["param2"] = 0, ["y"] = 23, ["param1"] = 170, ["z"] = 7, ["name"] = "lottother:air" },
{["x"] = 6, ["meta"] = { ["fields"] = {}, ["inventory"] = {} }, ["param2"] = 0, ["y"] = 23, ["param1"] = 187, ["z"] = 8, ["name"] = "lottother:air" },
{["x"] = 6, ["meta"] = { ["fields"] = {}, ["inventory"] = {} }, ["param2"] = 0, ["y"] = 23, ["param1"] = 204, ["z"] = 9, ["name"] = "lottother:air" },
{["x"] = 6, ["meta"] = { ["fields"] = {}, ["inventory"] = {} }, ["param2"] = 0, ["y"] = 24, ["param1"] = 0, ["z"] = 5, ["name"] = "lord_planks:mallorn" },
{["x"] = 6, ["meta"] = { ["fields"] = {}, ["inventory"] = {} }, ["param2"] = 0, ["y"] = 24, ["param1"] = 0, ["z"] = 6, ["name"] = "lord_planks:mallorn" },
{["x"] = 6, ["meta"] = { ["fields"] = {}, ["inventory"] = {} }, ["param2"] = 0, ["y"] = 24, ["param1"] = 0, ["z"] = 7, ["name"] = "lord_planks:mallorn" },
{["x"] = 6, ["meta"] = { ["fields"] = {}, ["inventory"] = {} }, ["param2"] = 0, ["y"] = 24, ["param1"] = 204, ["z"] = 8, ["name"] = "lottother:air" },
{["x"] = 6, ["meta"] = { ["fields"] = {}, ["inventory"] = {} }, ["param2"] = 2, ["y"] = 24, ["param1"] = 0, ["z"] = 9, ["name"] = "lottother:blue_torch" },
{["x"] = 6, ["meta"] = { ["fields"] = {}, ["inventory"] = {} }, ["param2"] = 0, ["y"] = 25, ["param1"] = 0, ["z"] = 4, ["name"] = "lord_planks:mallorn" },
{["x"] = 6, ["meta"] = { ["fields"] = {}, ["inventory"] = {} }, ["param2"] = 0, ["y"] = 25, ["param1"] = 0, ["z"] = 5, ["name"] = "lord_planks:mallorn" },
{["x"] = 6, ["meta"] = { ["fields"] = {}, ["inventory"] = {} }, ["param2"] = 0, ["y"] = 25, ["param1"] = 0, ["z"] = 6, ["name"] = "lord_planks:mallorn" },
{["x"] = 6, ["meta"] = { ["fields"] = {}, ["inventory"] = {} }, ["param2"] = 0, ["y"] = 25, ["param1"] = 0, ["z"] = 7, ["name"] = "lord_planks:mallorn" },
{["x"] = 6, ["meta"] = { ["fields"] = {}, ["inventory"] = {} }, ["param2"] = 0, ["y"] = 25, ["param1"] = 0, ["z"] = 8, ["name"] = "lord_planks:mallorn" },
{["x"] = 6, ["meta"] = { ["fields"] = {}, ["inventory"] = {} }, ["param2"] = 0, ["y"] = 25, ["param1"] = 0, ["z"] = 9, ["name"] = "lord_planks:mallorn" },
{["x"] = 6, ["meta"] = { ["fields"] = {}, ["inventory"] = {} }, ["param2"] = 0, ["y"] = 26, ["param1"] = 204, ["z"] = 4, ["name"] = "default:fence_wood" },
{["x"] = 6, ["meta"] = { ["fields"] = {}, ["inventory"] = {} }, ["param2"] = 0, ["y"] = 26, ["param1"] = 187, ["z"] = 5, ["name"] = "lottother:air" },
{["x"] = 6, ["meta"] = { ["fields"] = {}, ["inventory"] = {} }, ["param2"] = 0, ["y"] = 26, ["param1"] = 170, ["z"] = 6, ["name"] = "lottother:air" },
{["x"] = 6, ["meta"] = { ["fields"] = {}, ["inventory"] = {} }, ["param2"] = 0, ["y"] = 26, ["param1"] = 170, ["z"] = 7, ["name"] = "lottother:air" },
{["x"] = 6, ["meta"] = { ["fields"] = {}, ["inventory"] = {} }, ["param2"] = 0, ["y"] = 26, ["param1"] = 170, ["z"] = 8, ["name"] = "lottother:air" },
{["x"] = 6, ["meta"] = { ["fields"] = {}, ["inventory"] = {} }, ["param2"] = 0, ["y"] = 26, ["param1"] = 187, ["z"] = 9, ["name"] = "default:fence_wood" },
{["x"] = 6, ["meta"] = { ["fields"] = {}, ["inventory"] = {} }, ["param2"] = 1, ["y"] = 27, ["param1"] = 0, ["z"] = 4, ["name"] = "lottother:blue_torch" },
{["x"] = 6, ["meta"] = { ["fields"] = {}, ["inventory"] = {} }, ["param2"] = 0, ["y"] = 27, ["param1"] = 204, ["z"] = 5, ["name"] = "lottother:air" },
{["x"] = 6, ["meta"] = { ["fields"] = {}, ["inventory"] = {} }, ["param2"] = 0, ["y"] = 27, ["param1"] = 187, ["z"] = 6, ["name"] = "lottother:air" },
{["x"] = 6, ["meta"] = { ["fields"] = {}, ["inventory"] = {} }, ["param2"] = 0, ["y"] = 27, ["param1"] = 187, ["z"] = 7, ["name"] = "lottother:air" },
{["x"] = 6, ["meta"] = { ["fields"] = {}, ["inventory"] = {} }, ["param2"] = 0, ["y"] = 27, ["param1"] = 187, ["z"] = 8, ["name"] = "lottother:air" },
{["x"] = 6, ["meta"] = { ["fields"] = {}, ["inventory"] = {} }, ["param2"] = 0, ["y"] = 27, ["param1"] = 204, ["z"] = 9, ["name"] = "lottother:air" },
{["x"] = 6, ["meta"] = { ["fields"] = {}, ["inventory"] = {} }, ["param2"] = 0, ["y"] = 28, ["param1"] = 204, ["z"] = 4, ["name"] = "lottother:air" },
{["x"] = 6, ["meta"] = { ["fields"] = {}, ["inventory"] = {} }, ["param2"] = 0, ["y"] = 28, ["param1"] = 187, ["z"] = 5, ["name"] = "lottother:air" },
{["x"] = 6, ["meta"] = { ["fields"] = {}, ["inventory"] = {} }, ["param2"] = 0, ["y"] = 28, ["param1"] = 170, ["z"] = 6, ["name"] = "lottother:air" },
{["x"] = 6, ["meta"] = { ["fields"] = {}, ["inventory"] = {} }, ["param2"] = 0, ["y"] = 28, ["param1"] = 170, ["z"] = 7, ["name"] = "lottother:air" },
{["x"] = 6, ["meta"] = { ["fields"] = {}, ["inventory"] = {} }, ["param2"] = 0, ["y"] = 28, ["param1"] = 170, ["z"] = 8, ["name"] = "lottother:air" },
{["x"] = 6, ["meta"] = { ["fields"] = {}, ["inventory"] = {} }, ["param2"] = 0, ["y"] = 28, ["param1"] = 187, ["z"] = 9, ["name"] = "lottother:air" },
{["x"] = 6, ["meta"] = { ["fields"] = {}, ["inventory"] = {} }, ["param2"] = 0, ["y"] = 29, ["param1"] = 0, ["z"] = 4, ["name"] = "lord_planks:mallorn" },
{["x"] = 6, ["meta"] = { ["fields"] = {}, ["inventory"] = {} }, ["param2"] = 0, ["y"] = 29, ["param1"] = 0, ["z"] = 5, ["name"] = "lord_planks:mallorn" },
{["x"] = 6, ["meta"] = { ["fields"] = {}, ["inventory"] = {} }, ["param2"] = 0, ["y"] = 29, ["param1"] = 153, ["z"] = 6, ["name"] = "lottother:air" },
{["x"] = 6, ["meta"] = { ["fields"] = {}, ["inventory"] = {} }, ["param2"] = 0, ["y"] = 29, ["param1"] = 153, ["z"] = 7, ["name"] = "lottother:air" },
{["x"] = 6, ["meta"] = { ["fields"] = {}, ["inventory"] = {} }, ["param2"] = 0, ["y"] = 29, ["param1"] = 0, ["z"] = 8, ["name"] = "lord_planks:mallorn" },
{["x"] = 6, ["meta"] = { ["fields"] = {}, ["inventory"] = {} }, ["param2"] = 0, ["y"] = 29, ["param1"] = 0, ["z"] = 9, ["name"] = "lord_planks:mallorn" },
{["x"] = 6, ["meta"] = { ["fields"] = {}, ["inventory"] = {} }, ["param2"] = 0, ["y"] = 30, ["param1"] = 0, ["z"] = 5, ["name"] = "lord_planks:mallorn" },
{["x"] = 6, ["meta"] = { ["fields"] = {}, ["inventory"] = {} }, ["param2"] = 0, ["y"] = 30, ["param1"] = 0, ["z"] = 6, ["name"] = "lord_planks:mallorn" },
{["x"] = 6, ["meta"] = { ["fields"] = {}, ["inventory"] = {} }, ["param2"] = 0, ["y"] = 30, ["param1"] = 0, ["z"] = 7, ["name"] = "lord_planks:mallorn" },
{["x"] = 6, ["meta"] = { ["fields"] = {}, ["inventory"] = {} }, ["param2"] = 0, ["y"] = 30, ["param1"] = 0, ["z"] = 8, ["name"] = "lord_planks:mallorn" },
{["x"] = 6, ["meta"] = { ["fields"] = {}, ["inventory"] = {} }, ["param2"] = 0, ["y"] = 30, ["param1"] = 119, ["z"] = 9, ["name"] = "lottother:air" },
{["x"] = 6, ["meta"] = { ["fields"] = {}, ["inventory"] = {} }, ["param2"] = 0, ["y"] = 31, ["param1"] = 0, ["z"] = 6, ["name"] = "lord_planks:mallorn" },
{["x"] = 6, ["meta"] = { ["fields"] = {}, ["inventory"] = {} }, ["param2"] = 0, ["y"] = 31, ["param1"] = 0, ["z"] = 7, ["name"] = "lord_planks:mallorn" },
{["x"] = 6, ["meta"] = { ["fields"] = {}, ["inventory"] = {} }, ["param2"] = 0, ["y"] = 31, ["param1"] = 104, ["z"] = 8, ["name"] = "lottother:air" },
{["x"] = 6, ["meta"] = { ["fields"] = {}, ["inventory"] = {} }, ["param2"] = 0, ["y"] = 31, ["param1"] = 103, ["z"] = 9, ["name"] = "lottother:air" },
{["x"] = 6, ["meta"] = { ["fields"] = {}, ["inventory"] = {} }, ["param2"] = 0, ["y"] = 32, ["param1"] = 105, ["z"] = 7, ["name"] = "lottother:air" },
{["x"] = 6, ["meta"] = { ["fields"] = {}, ["inventory"] = {} }, ["param2"] = 0, ["y"] = 32, ["param1"] = 88, ["z"] = 8, ["name"] = "lottother:air" },
{["x"] = 6, ["meta"] = { ["fields"] = {}, ["inventory"] = {} }, ["param2"] = 0, ["y"] = 32, ["param1"] = 87, ["z"] = 9, ["name"] = "lottother:air" },
{["x"] = 6, ["meta"] = { ["fields"] = {}, ["inventory"] = {} }, ["param2"] = 0, ["y"] = 33, ["param1"] = 121, ["z"] = 7, ["name"] = "lottother:air" },
{["x"] = 6, ["meta"] = { ["fields"] = {}, ["inventory"] = {} }, ["param2"] = 0, ["y"] = 33, ["param1"] = 104, ["z"] = 8, ["name"] = "lottother:air" },
{["x"] = 6, ["meta"] = { ["fields"] = {}, ["inventory"] = {} }, ["param2"] = 0, ["y"] = 33, ["param1"] = 103, ["z"] = 9, ["name"] = "lottother:air" },
{["x"] = 6, ["meta"] = { ["fields"] = {}, ["inventory"] = {} }, ["param2"] = 0, ["y"] = 34, ["param1"] = 137, ["z"] = 7, ["name"] = "lottother:air" },
{["x"] = 6, ["meta"] = { ["fields"] = {}, ["inventory"] = {} }, ["param2"] = 0, ["y"] = 34, ["param1"] = 120, ["z"] = 8, ["name"] = "lottother:air" },
{["x"] = 6, ["meta"] = { ["fields"] = {}, ["inventory"] = {} }, ["param2"] = 0, ["y"] = 34, ["param1"] = 119, ["z"] = 9, ["name"] = "lottother:air" },
{["x"] = 6, ["meta"] = { ["fields"] = {}, ["inventory"] = {} }, ["param2"] = 0, ["y"] = 35, ["param1"] = 153, ["z"] = 7, ["name"] = "lottother:air" },
{["x"] = 6, ["meta"] = { ["fields"] = {}, ["inventory"] = {} }, ["param2"] = 0, ["y"] = 35, ["param1"] = 136, ["z"] = 8, ["name"] = "lottother:air" },
{["x"] = 6, ["meta"] = { ["fields"] = {}, ["inventory"] = {} }, ["param2"] = 0, ["y"] = 35, ["param1"] = 136, ["z"] = 9, ["name"] = "lottother:air" },
{["x"] = 6, ["meta"] = { ["fields"] = {}, ["inventory"] = {} }, ["param2"] = 0, ["y"] = 36, ["param1"] = 170, ["z"] = 7, ["name"] = "lottother:air" },
{["x"] = 6, ["meta"] = { ["fields"] = {}, ["inventory"] = {} }, ["param2"] = 0, ["y"] = 36, ["param1"] = 153, ["z"] = 8, ["name"] = "lottother:air" },
{["x"] = 6, ["meta"] = { ["fields"] = {}, ["inventory"] = {} }, ["param2"] = 0, ["y"] = 36, ["param1"] = 153, ["z"] = 9, ["name"] = "lottother:air" },
{["x"] = 6, ["meta"] = { ["fields"] = {}, ["inventory"] = {} }, ["param2"] = 0, ["y"] = 37, ["param1"] = 187, ["z"] = 7, ["name"] = "lottother:air" },
{["x"] = 6, ["meta"] = { ["fields"] = {}, ["inventory"] = {} }, ["param2"] = 0, ["y"] = 37, ["param1"] = 170, ["z"] = 8, ["name"] = "lottother:air" },
{["x"] = 6, ["meta"] = { ["fields"] = {}, ["inventory"] = {} }, ["param2"] = 0, ["y"] = 37, ["param1"] = 170, ["z"] = 9, ["name"] = "lottother:air" },
{["x"] = 6, ["meta"] = { ["fields"] = {}, ["inventory"] = {} }, ["param2"] = 0, ["y"] = 38, ["param1"] = 204, ["z"] = 7, ["name"] = "lottother:air" },
{["x"] = 6, ["meta"] = { ["fields"] = {}, ["inventory"] = {} }, ["param2"] = 0, ["y"] = 38, ["param1"] = 0, ["z"] = 8, ["name"] = "lord_planks:mallorn" },
{["x"] = 6, ["meta"] = { ["fields"] = {}, ["inventory"] = {} }, ["param2"] = 0, ["y"] = 38, ["param1"] = 0, ["z"] = 9, ["name"] = "lord_planks:mallorn" },
{["x"] = 6, ["meta"] = { ["fields"] = {}, ["inventory"] = {} }, ["param2"] = 0, ["y"] = 39, ["param1"] = 187, ["z"] = 7, ["name"] = "lottother:air" },
{["x"] = 6, ["meta"] = { ["fields"] = {}, ["inventory"] = {} }, ["param2"] = 0, ["y"] = 39, ["param1"] = 170, ["z"] = 8, ["name"] = "default:fence_wood" },
{["x"] = 6, ["meta"] = { ["fields"] = {}, ["inventory"] = {} }, ["param2"] = 0, ["y"] = 39, ["param1"] = 170, ["z"] = 9, ["name"] = "default:fence_wood" },
{["x"] = 6, ["meta"] = { ["fields"] = {}, ["inventory"] = {} }, ["param2"] = 0, ["y"] = 40, ["param1"] = 0, ["z"] = 6, ["name"] = "lord_planks:mallorn" },
{["x"] = 6, ["meta"] = { ["fields"] = {}, ["inventory"] = {} }, ["param2"] = 0, ["y"] = 40, ["param1"] = 0, ["z"] = 7, ["name"] = "lord_planks:mallorn" },
{["x"] = 6, ["meta"] = { ["fields"] = {}, ["inventory"] = {} }, ["param2"] = 0, ["y"] = 40, ["param1"] = 0, ["z"] = 8, ["name"] = "lord_planks:mallorn" },
{["x"] = 6, ["meta"] = { ["fields"] = {}, ["inventory"] = {} }, ["param2"] = 0, ["y"] = 40, ["param1"] = 0, ["z"] = 9, ["name"] = "lord_planks:mallorn" },
{["x"] = 6, ["meta"] = { ["fields"] = {}, ["inventory"] = {} }, ["param2"] = 0, ["y"] = 40, ["param1"] = 0, ["z"] = 10, ["name"] = "lord_planks:mallorn" },
{["x"] = 6, ["meta"] = { ["fields"] = {}, ["inventory"] = {} }, ["param2"] = 0, ["y"] = 40, ["param1"] = 0, ["z"] = 11, ["name"] = "lord_planks:mallorn" },
{["x"] = 6, ["meta"] = { ["fields"] = {}, ["inventory"] = {} }, ["param2"] = 0, ["y"] = 41, ["param1"] = 204, ["z"] = 6, ["name"] = "default:fence_wood" },
{["x"] = 6, ["meta"] = { ["fields"] = {}, ["inventory"] = {} }, ["param2"] = 0, ["y"] = 41, ["param1"] = 187, ["z"] = 7, ["name"] = "lottother:air" },
{["x"] = 6, ["meta"] = { ["fields"] = {}, ["inventory"] = {} }, ["param2"] = 0, ["y"] = 41, ["param1"] = 170, ["z"] = 8, ["name"] = "lottother:air" },
{["x"] = 6, ["meta"] = { ["fields"] = {}, ["inventory"] = {} }, ["param2"] = 0, ["y"] = 41, ["param1"] = 170, ["z"] = 9, ["name"] = "lottother:air" },
{["x"] = 6, ["meta"] = { ["fields"] = {}, ["inventory"] = {} }, ["param2"] = 0, ["y"] = 41, ["param1"] = 187, ["z"] = 10, ["name"] = "lottother:air" },
{["x"] = 6, ["meta"] = { ["fields"] = {}, ["inventory"] = {} }, ["param2"] = 0, ["y"] = 41, ["param1"] = 204, ["z"] = 11, ["name"] = "default:fence_wood" },
{["x"] = 6, ["meta"] = { ["fields"] = {}, ["inventory"] = {} }, ["param2"] = 1, ["y"] = 42, ["param1"] = 0, ["z"] = 6, ["name"] = "lottother:blue_torch" },
{["x"] = 6, ["meta"] = { ["fields"] = {}, ["inventory"] = {} }, ["param2"] = 0, ["y"] = 42, ["param1"] = 204, ["z"] = 7, ["name"] = "lottother:air" },
{["x"] = 6, ["meta"] = { ["fields"] = {}, ["inventory"] = {} }, ["param2"] = 0, ["y"] = 42, ["param1"] = 187, ["z"] = 8, ["name"] = "lottother:air" },
{["x"] = 6, ["meta"] = { ["fields"] = {}, ["inventory"] = {} }, ["param2"] = 0, ["y"] = 42, ["param1"] = 187, ["z"] = 9, ["name"] = "lottother:air" },
{["x"] = 6, ["meta"] = { ["fields"] = {}, ["inventory"] = {} }, ["param2"] = 0, ["y"] = 42, ["param1"] = 204, ["z"] = 10, ["name"] = "lottother:air" },
{["x"] = 6, ["meta"] = { ["fields"] = {}, ["inventory"] = {} }, ["param2"] = 1, ["y"] = 42, ["param1"] = 0, ["z"] = 11, ["name"] = "lottother:blue_torch" },
{["x"] = 6, ["meta"] = { ["fields"] = {}, ["inventory"] = {} }, ["param2"] = 0, ["y"] = 43, ["param1"] = 204, ["z"] = 6, ["name"] = "lottother:air" },
{["x"] = 6, ["meta"] = { ["fields"] = {}, ["inventory"] = {} }, ["param2"] = 0, ["y"] = 43, ["param1"] = 187, ["z"] = 7, ["name"] = "lottother:air" },
{["x"] = 6, ["meta"] = { ["fields"] = {}, ["inventory"] = {} }, ["param2"] = 0, ["y"] = 43, ["param1"] = 170, ["z"] = 8, ["name"] = "lottother:air" },
{["x"] = 6, ["meta"] = { ["fields"] = {}, ["inventory"] = {} }, ["param2"] = 0, ["y"] = 43, ["param1"] = 170, ["z"] = 9, ["name"] = "lottother:air" },
{["x"] = 6, ["meta"] = { ["fields"] = {}, ["inventory"] = {} }, ["param2"] = 0, ["y"] = 43, ["param1"] = 187, ["z"] = 10, ["name"] = "lottother:air" },
{["x"] = 6, ["meta"] = { ["fields"] = {}, ["inventory"] = {} }, ["param2"] = 0, ["y"] = 43, ["param1"] = 204, ["z"] = 11, ["name"] = "lottother:air" },
{["x"] = 6, ["meta"] = { ["fields"] = {}, ["inventory"] = {} }, ["param2"] = 0, ["y"] = 44, ["param1"] = 187, ["z"] = 6, ["name"] = "lottother:air" },
{["x"] = 6, ["meta"] = { ["fields"] = {}, ["inventory"] = {} }, ["param2"] = 0, ["y"] = 44, ["param1"] = 170, ["z"] = 7, ["name"] = "lottother:air" },
{["x"] = 6, ["meta"] = { ["fields"] = {}, ["inventory"] = {} }, ["param2"] = 0, ["y"] = 44, ["param1"] = 170, ["z"] = 8, ["name"] = "lottother:air" },
{["x"] = 6, ["meta"] = { ["fields"] = {}, ["inventory"] = {} }, ["param2"] = 0, ["y"] = 44, ["param1"] = 170, ["z"] = 9, ["name"] = "lottother:air" },
{["x"] = 6, ["meta"] = { ["fields"] = {}, ["inventory"] = {} }, ["param2"] = 0, ["y"] = 44, ["param1"] = 170, ["z"] = 10, ["name"] = "lottother:air" },
{["x"] = 6, ["meta"] = { ["fields"] = {}, ["inventory"] = {} }, ["param2"] = 0, ["y"] = 44, ["param1"] = 187, ["z"] = 11, ["name"] = "lottother:air" },
{["x"] = 6, ["meta"] = { ["fields"] = {}, ["inventory"] = {} }, ["param2"] = 0, ["y"] = 45, ["param1"] = 0, ["z"] = 6, ["name"] = "lord_planks:mallorn" },
{["x"] = 6, ["meta"] = { ["fields"] = {}, ["inventory"] = {} }, ["param2"] = 0, ["y"] = 45, ["param1"] = 0, ["z"] = 7, ["name"] = "lord_planks:mallorn" },
{["x"] = 6, ["meta"] = { ["fields"] = {}, ["inventory"] = {} }, ["param2"] = 0, ["y"] = 45, ["param1"] = 187, ["z"] = 8, ["name"] = "lottother:air" },
{["x"] = 6, ["meta"] = { ["fields"] = {}, ["inventory"] = {} }, ["param2"] = 0, ["y"] = 45, ["param1"] = 187, ["z"] = 9, ["name"] = "lottother:air" },
