return {
{["x"] = 0, ["meta"] = { ["fields"] = {}, ["inventory"] = {} }, ["param2"] = 0, ["y"] = 0, ["param1"] = 0, ["z"] = 5, ["name"] = "lottother:dirt" },
{["x"] = 0, ["meta"] = { ["fields"] = {}, ["inventory"] = {} }, ["param2"] = 0, ["y"] = 0, ["param1"] = 0, ["z"] = 6, ["name"] = "lottother:dirt" },
{["x"] = 0, ["meta"] = { ["fields"] = {}, ["inventory"] = {} }, ["param2"] = 0, ["y"] = 0, ["param1"] = 0, ["z"] = 7, ["name"] = "lottother:dirt" },
{["x"] = 0, ["meta"] = { ["fields"] = {}, ["inventory"] = {} }, ["param2"] = 0, ["y"] = 0, ["param1"] = 0, ["z"] = 8, ["name"] = "lottother:dirt" },
{["x"] = 0, ["meta"] = { ["fields"] = {}, ["inventory"] = {} }, ["param2"] = 0, ["y"] = 0, ["param1"] = 0, ["z"] = 9, ["name"] = "lottother:dirt" },
{["x"] = 0, ["meta"] = { ["fields"] = {}, ["inventory"] = {} }, ["param2"] = 0, ["y"] = 1, ["param1"] = 0, ["z"] = 5, ["name"] = "lord_ground:dirt_mirkwood" },
{["x"] = 0, ["meta"] = { ["fields"] = {}, ["inventory"] = {} }, ["param2"] = 0, ["y"] = 1, ["param1"] = 0, ["z"] = 6, ["name"] = "lord_ground:dirt_mirkwood" },
{["x"] = 0, ["meta"] = { ["fields"] = {}, ["inventory"] = {} }, ["param2"] = 0, ["y"] = 1, ["param1"] = 0, ["z"] = 7, ["name"] = "lord_ground:dirt_mirkwood" },
{["x"] = 0, ["meta"] = { ["fields"] = {}, ["inventory"] = {} }, ["param2"] = 0, ["y"] = 1, ["param1"] = 0, ["z"] = 8, ["name"] = "lord_ground:dirt_mirkwood" },
{["x"] = 0, ["meta"] = { ["fields"] = {}, ["inventory"] = {} }, ["param2"] = 0, ["y"] = 1, ["param1"] = 0, ["z"] = 9, ["name"] = "lord_ground:dirt_mirkwood" },
{["x"] = 0, ["meta"] = { ["fields"] = {}, ["inventory"] = {} }, ["param2"] = 0, ["y"] = 22, ["param1"] = 13, ["z"] = 5, ["name"] = "lord_trees:mirk_leaf" },
{["x"] = 0, ["meta"] = { ["fields"] = {}, ["inventory"] = {} }, ["param2"] = 0, ["y"] = 22, ["param1"] = 13, ["z"] = 6, ["name"] = "lord_trees:mirk_leaf" },
{["x"] = 0, ["meta"] = { ["fields"] = {}, ["inventory"] = {} }, ["param2"] = 0, ["y"] = 22, ["param1"] = 13, ["z"] = 7, ["name"] = "lord_trees:mirk_leaf" },
{["x"] = 0, ["meta"] = { ["fields"] = {}, ["inventory"] = {} }, ["param2"] = 0, ["y"] = 22, ["param1"] = 13, ["z"] = 8, ["name"] = "lord_trees:mirk_leaf" },
{["x"] = 0, ["meta"] = { ["fields"] = {}, ["inventory"] = {} }, ["param2"] = 0, ["y"] = 23, ["param1"] = 13, ["z"] = 8, ["name"] = "lord_trees:mirk_leaf" },
{["x"] = 0, ["meta"] = { ["fields"] = {}, ["inventory"] = {} }, ["param2"] = 0, ["y"] = 25, ["param1"] = 13, ["z"] = 6, ["name"] = "lord_trees:mirk_leaf" },
{["x"] = 0, ["meta"] = { ["fields"] = {}, ["inventory"] = {} }, ["param2"] = 0, ["y"] = 25, ["param1"] = 13, ["z"] = 7, ["name"] = "lord_trees:mirk_leaf" },
{["x"] = 0, ["meta"] = { ["fields"] = {}, ["inventory"] = {} }, ["param2"] = 0, ["y"] = 25, ["param1"] = 13, ["z"] = 8, ["name"] = "lord_trees:mirk_leaf" },
{["x"] = 0, ["meta"] = { ["fields"] = {}, ["inventory"] = {} }, ["param2"] = 0, ["y"] = 25, ["param1"] = 13, ["z"] = 9, ["name"] = "lord_trees:mirk_leaf" },
{["x"] = 0, ["meta"] = { ["fields"] = {}, ["inventory"] = {} }, ["param2"] = 0, ["y"] = 25, ["param1"] = 13, ["z"] = 10, ["name"] = "lord_trees:mirk_leaf" },
{["x"] = 0, ["meta"] = { ["fields"] = {}, ["inventory"] = {} }, ["param2"] = 0, ["y"] = 26, ["param1"] = 13, ["z"] = 10, ["name"] = "lord_trees:mirk_leaf" },
{["x"] = 1, ["meta"] = { ["fields"] = {}, ["inventory"] = {} }, ["param2"] = 0, ["y"] = 0, ["param1"] = 0, ["z"] = 1, ["name"] = "lottother:dirt" },
{["x"] = 1, ["meta"] = { ["fields"] = {}, ["inventory"] = {} }, ["param2"] = 0, ["y"] = 0, ["param1"] = 0, ["z"] = 2, ["name"] = "lottother:dirt" },
{["x"] = 1, ["meta"] = { ["fields"] = {}, ["inventory"] = {} }, ["param2"] = 0, ["y"] = 0, ["param1"] = 0, ["z"] = 3, ["name"] = "lottother:dirt" },
{["x"] = 1, ["meta"] = { ["fields"] = {}, ["inventory"] = {} }, ["param2"] = 0, ["y"] = 0, ["param1"] = 0, ["z"] = 4, ["name"] = "lottother:dirt" },
{["x"] = 1, ["meta"] = { ["fields"] = {}, ["inventory"] = {} }, ["param2"] = 0, ["y"] = 0, ["param1"] = 0, ["z"] = 5, ["name"] = "lottother:dirt" },
{["x"] = 1, ["meta"] = { ["fields"] = {}, ["inventory"] = {} }, ["param2"] = 0, ["y"] = 0, ["param1"] = 0, ["z"] = 6, ["name"] = "lottother:dirt" },
{["x"] = 1, ["meta"] = { ["fields"] = {}, ["inventory"] = {} }, ["param2"] = 0, ["y"] = 0, ["param1"] = 0, ["z"] = 7, ["name"] = "lottother:dirt" },
{["x"] = 1, ["meta"] = { ["fields"] = {}, ["inventory"] = {} }, ["param2"] = 0, ["y"] = 0, ["param1"] = 0, ["z"] = 8, ["name"] = "lottother:dirt" },
{["x"] = 1, ["meta"] = { ["fields"] = {}, ["inventory"] = {} }, ["param2"] = 0, ["y"] = 0, ["param1"] = 0, ["z"] = 9, ["name"] = "lottother:dirt" },
{["x"] = 1, ["meta"] = { ["fields"] = {}, ["inventory"] = {} }, ["param2"] = 0, ["y"] = 0, ["param1"] = 0, ["z"] = 10, ["name"] = "lottother:dirt" },
{["x"] = 1, ["meta"] = { ["fields"] = {}, ["inventory"] = {} }, ["param2"] = 0, ["y"] = 0, ["param1"] = 0, ["z"] = 11, ["name"] = "lottother:dirt" },
{["x"] = 1, ["meta"] = { ["fields"] = {}, ["inventory"] = {} }, ["param2"] = 0, ["y"] = 0, ["param1"] = 0, ["z"] = 12, ["name"] = "lottother:dirt" },
{["x"] = 1, ["meta"] = { ["fields"] = {}, ["inventory"] = {} }, ["param2"] = 0, ["y"] = 1, ["param1"] = 0, ["z"] = 1, ["name"] = "lord_ground:dirt_mirkwood" },
{["x"] = 1, ["meta"] = { ["fields"] = {}, ["inventory"] = {} }, ["param2"] = 0, ["y"] = 1, ["param1"] = 0, ["z"] = 2, ["name"] = "lord_ground:dirt_mirkwood" },
{["x"] = 1, ["meta"] = { ["fields"] = {}, ["inventory"] = {} }, ["param2"] = 0, ["y"] = 1, ["param1"] = 0, ["z"] = 3, ["name"] = "lord_ground:dirt_mirkwood" },
{["x"] = 1, ["meta"] = { ["fields"] = {}, ["inventory"] = {} }, ["param2"] = 0, ["y"] = 1, ["param1"] = 0, ["z"] = 4, ["name"] = "lord_ground:dirt_mirkwood" },
{["x"] = 1, ["meta"] = { ["fields"] = {}, ["inventory"] = {} }, ["param2"] = 0, ["y"] = 1, ["param1"] = 0, ["z"] = 5, ["name"] = "lord_ground:dirt_mirkwood" },
{["x"] = 1, ["meta"] = { ["fields"] = {}, ["inventory"] = {} }, ["param2"] = 0, ["y"] = 1, ["param1"] = 0, ["z"] = 6, ["name"] = "lottother:dirt" },
{["x"] = 1, ["meta"] = { ["fields"] = {}, ["inventory"] = {} }, ["param2"] = 0, ["y"] = 1, ["param1"] = 0, ["z"] = 7, ["name"] = "lottother:dirt" },
{["x"] = 1, ["meta"] = { ["fields"] = {}, ["inventory"] = {} }, ["param2"] = 0, ["y"] = 1, ["param1"] = 0, ["z"] = 8, ["name"] = "lottother:dirt" },
{["x"] = 1, ["meta"] = { ["fields"] = {}, ["inventory"] = {} }, ["param2"] = 0, ["y"] = 1, ["param1"] = 0, ["z"] = 9, ["name"] = "lord_ground:dirt_mirkwood" },
{["x"] = 1, ["meta"] = { ["fields"] = {}, ["inventory"] = {} }, ["param2"] = 0, ["y"] = 1, ["param1"] = 0, ["z"] = 10, ["name"] = "lord_ground:dirt_mirkwood" },
{["x"] = 1, ["meta"] = { ["fields"] = {}, ["inventory"] = {} }, ["param2"] = 0, ["y"] = 1, ["param1"] = 0, ["z"] = 11, ["name"] = "lord_ground:dirt_mirkwood" },
{["x"] = 1, ["meta"] = { ["fields"] = {}, ["inventory"] = {} }, ["param2"] = 0, ["y"] = 1, ["param1"] = 0, ["z"] = 12, ["name"] = "lord_ground:dirt_mirkwood" },
{["x"] = 1, ["meta"] = { ["fields"] = {}, ["inventory"] = {} }, ["param2"] = 0, ["y"] = 2, ["param1"] = 0, ["z"] = 6, ["name"] = "lord_ground:dirt_mirkwood" },
{["x"] = 1, ["meta"] = { ["fields"] = {}, ["inventory"] = {} }, ["param2"] = 0, ["y"] = 2, ["param1"] = 0, ["z"] = 7, ["name"] = "lord_ground:dirt_mirkwood" },
{["x"] = 1, ["meta"] = { ["fields"] = {}, ["inventory"] = {} }, ["param2"] = 0, ["y"] = 2, ["param1"] = 0, ["z"] = 8, ["name"] = "lord_ground:dirt_mirkwood" },
{["x"] = 1, ["meta"] = { ["fields"] = {}, ["inventory"] = {} }, ["param2"] = 0, ["y"] = 16, ["param1"] = 13, ["z"] = 5, ["name"] = "lord_trees:mirk_leaf" },
{["x"] = 1, ["meta"] = { ["fields"] = {}, ["inventory"] = {} }, ["param2"] = 0, ["y"] = 16, ["param1"] = 12, ["z"] = 6, ["name"] = "lord_trees:mirk_leaf" },
{["x"] = 1, ["meta"] = { ["fields"] = {}, ["inventory"] = {} }, ["param2"] = 0, ["y"] = 16, ["param1"] = 28, ["z"] = 7, ["name"] = "lord_trees:mirk_leaf" },
{["x"] = 1, ["meta"] = { ["fields"] = {}, ["inventory"] = {} }, ["param2"] = 0, ["y"] = 16, ["param1"] = 44, ["z"] = 8, ["name"] = "lord_trees:mirk_leaf" },
{["x"] = 1, ["meta"] = { ["fields"] = {}, ["inventory"] = {} }, ["param2"] = 0, ["y"] = 17, ["param1"] = 28, ["z"] = 8, ["name"] = "lord_trees:mirk_leaf" },
{["x"] = 1, ["meta"] = { ["fields"] = {}, ["inventory"] = {} }, ["param2"] = 0, ["y"] = 22, ["param1"] = 13, ["z"] = 5, ["name"] = "lord_trees:mirk_leaf" },
{["x"] = 1, ["meta"] = { ["fields"] = {}, ["inventory"] = {} }, ["param2"] = 0, ["y"] = 22, ["param1"] = 12, ["z"] = 6, ["name"] = "lord_trees:mirk_leaf" },
{["x"] = 1, ["meta"] = { ["fields"] = {}, ["inventory"] = {} }, ["param2"] = 0, ["y"] = 22, ["param1"] = 0, ["z"] = 7, ["name"] = "default:tree" },
{["x"] = 1, ["meta"] = { ["fields"] = {}, ["inventory"] = {} }, ["param2"] = 0, ["y"] = 22, ["param1"] = 12, ["z"] = 8, ["name"] = "lord_trees:mirk_leaf" },
{["x"] = 1, ["meta"] = { ["fields"] = {}, ["inventory"] = {} }, ["param2"] = 0, ["y"] = 22, ["param1"] = 12, ["z"] = 9, ["name"] = "lord_trees:mirk_leaf" },
{["x"] = 1, ["meta"] = { ["fields"] = {}, ["inventory"] = {} }, ["param2"] = 0, ["y"] = 22, ["param1"] = 12, ["z"] = 10, ["name"] = "lord_trees:mirk_leaf" },
{["x"] = 1, ["meta"] = { ["fields"] = {}, ["inventory"] = {} }, ["param2"] = 0, ["y"] = 22, ["param1"] = 13, ["z"] = 11, ["name"] = "lord_trees:mirk_leaf" },
{["x"] = 1, ["meta"] = { ["fields"] = {}, ["inventory"] = {} }, ["param2"] = 0, ["y"] = 22, ["param1"] = 13, ["z"] = 12, ["name"] = "lord_trees:mirk_leaf" },
{["x"] = 1, ["meta"] = { ["fields"] = {}, ["inventory"] = {} }, ["param2"] = 0, ["y"] = 23, ["param1"] = 12, ["z"] = 7, ["name"] = "lord_trees:mirk_leaf" },
{["x"] = 1, ["meta"] = { ["fields"] = {}, ["inventory"] = {} }, ["param2"] = 0, ["y"] = 23, ["param1"] = 12, ["z"] = 8, ["name"] = "lord_trees:mirk_leaf" },
{["x"] = 1, ["meta"] = { ["fields"] = {}, ["inventory"] = {} }, ["param2"] = 0, ["y"] = 23, ["param1"] = 13, ["z"] = 11, ["name"] = "lord_trees:mirk_leaf" },
{["x"] = 1, ["meta"] = { ["fields"] = {}, ["inventory"] = {} }, ["param2"] = 0, ["y"] = 23, ["param1"] = 13, ["z"] = 12, ["name"] = "lord_trees:mirk_leaf" },
{["x"] = 1, ["meta"] = { ["fields"] = {}, ["inventory"] = {} }, ["param2"] = 0, ["y"] = 25, ["param1"] = 13, ["z"] = 6, ["name"] = "lord_trees:mirk_leaf" },
{["x"] = 1, ["meta"] = { ["fields"] = {}, ["inventory"] = {} }, ["param2"] = 0, ["y"] = 25, ["param1"] = 13, ["z"] = 7, ["name"] = "lord_trees:mirk_leaf" },
{["x"] = 1, ["meta"] = { ["fields"] = {}, ["inventory"] = {} }, ["param2"] = 0, ["y"] = 25, ["param1"] = 13, ["z"] = 8, ["name"] = "lord_trees:mirk_leaf" },
{["x"] = 1, ["meta"] = { ["fields"] = {}, ["inventory"] = {} }, ["param2"] = 0, ["y"] = 25, ["param1"] = 12, ["z"] = 9, ["name"] = "lord_trees:mirk_leaf" },
{["x"] = 1, ["meta"] = { ["fields"] = {}, ["inventory"] = {} }, ["param2"] = 0, ["y"] = 25, ["param1"] = 13, ["z"] = 10, ["name"] = "lord_trees:mirk_leaf" },
{["x"] = 1, ["meta"] = { ["fields"] = {}, ["inventory"] = {} }, ["param2"] = 0, ["y"] = 26, ["param1"] = 13, ["z"] = 9, ["name"] = "lord_trees:mirk_leaf" },
{["x"] = 1, ["meta"] = { ["fields"] = {}, ["inventory"] = {} }, ["param2"] = 0, ["y"] = 26, ["param1"] = 13, ["z"] = 10, ["name"] = "lord_trees:mirk_leaf" },
{["x"] = 2, ["meta"] = { ["fields"] = {}, ["inventory"] = {} }, ["param2"] = 0, ["y"] = 0, ["param1"] = 0, ["z"] = 0, ["name"] = "lottother:dirt" },
{["x"] = 2, ["meta"] = { ["fields"] = {}, ["inventory"] = {} }, ["param2"] = 0, ["y"] = 0, ["param1"] = 0, ["z"] = 1, ["name"] = "lottother:dirt" },
{["x"] = 2, ["meta"] = { ["fields"] = {}, ["inventory"] = {} }, ["param2"] = 0, ["y"] = 0, ["param1"] = 13, ["z"] = 2, ["name"] = "lottother:dirt" },
{["x"] = 2, ["meta"] = { ["fields"] = {}, ["inventory"] = {} }, ["param2"] = 0, ["y"] = 0, ["param1"] = 13, ["z"] = 3, ["name"] = "lottother:dirt" },
{["x"] = 2, ["meta"] = { ["fields"] = {}, ["inventory"] = {} }, ["param2"] = 0, ["y"] = 0, ["param1"] = 13, ["z"] = 4, ["name"] = "lottother:dirt" },
{["x"] = 2, ["meta"] = { ["fields"] = {}, ["inventory"] = {} }, ["param2"] = 0, ["y"] = 0, ["param1"] = 12, ["z"] = 5, ["name"] = "lottother:dirt" },
{["x"] = 2, ["meta"] = { ["fields"] = {}, ["inventory"] = {} }, ["param2"] = 0, ["y"] = 0, ["param1"] = 11, ["z"] = 6, ["name"] = "lottother:dirt" },
{["x"] = 2, ["meta"] = { ["fields"] = {}, ["inventory"] = {} }, ["param2"] = 0, ["y"] = 0, ["param1"] = 11, ["z"] = 7, ["name"] = "lottother:dirt" },
{["x"] = 2, ["meta"] = { ["fields"] = {}, ["inventory"] = {} }, ["param2"] = 0, ["y"] = 0, ["param1"] = 11, ["z"] = 8, ["name"] = "lottother:dirt" },
{["x"] = 2, ["meta"] = { ["fields"] = {}, ["inventory"] = {} }, ["param2"] = 0, ["y"] = 0, ["param1"] = 11, ["z"] = 9, ["name"] = "lottother:dirt" },
{["x"] = 2, ["meta"] = { ["fields"] = {}, ["inventory"] = {} }, ["param2"] = 0, ["y"] = 0, ["param1"] = 11, ["z"] = 10, ["name"] = "lottother:dirt" },
{["x"] = 2, ["meta"] = { ["fields"] = {}, ["inventory"] = {} }, ["param2"] = 0, ["y"] = 0, ["param1"] = 12, ["z"] = 11, ["name"] = "lottother:dirt" },
{["x"] = 2, ["meta"] = { ["fields"] = {}, ["inventory"] = {} }, ["param2"] = 0, ["y"] = 0, ["param1"] = 0, ["z"] = 12, ["name"] = "lottother:dirt" },
{["x"] = 2, ["meta"] = { ["fields"] = {}, ["inventory"] = {} }, ["param2"] = 0, ["y"] = 1, ["param1"] = 0, ["z"] = 0, ["name"] = "lord_ground:dirt_mirkwood" },
{["x"] = 2, ["meta"] = { ["fields"] = {}, ["inventory"] = {} }, ["param2"] = 0, ["y"] = 1, ["param1"] = 0, ["z"] = 1, ["name"] = "lord_ground:dirt_mirkwood" },
{["x"] = 2, ["meta"] = { ["fields"] = {}, ["inventory"] = {} }, ["param2"] = 0, ["y"] = 1, ["param1"] = 29, ["z"] = 2, ["name"] = "lottother:dirt" },
{["x"] = 2, ["meta"] = { ["fields"] = {}, ["inventory"] = {} }, ["param2"] = 0, ["y"] = 1, ["param1"] = 13, ["z"] = 3, ["name"] = "lottother:dirt" },
{["x"] = 2, ["meta"] = { ["fields"] = {}, ["inventory"] = {} }, ["param2"] = 0, ["y"] = 1, ["param1"] = 13, ["z"] = 4, ["name"] = "lottother:dirt" },
{["x"] = 2, ["meta"] = { ["fields"] = {}, ["inventory"] = {} }, ["param2"] = 0, ["y"] = 1, ["param1"] = 12, ["z"] = 5, ["name"] = "lottother:dirt" },
{["x"] = 2, ["meta"] = { ["fields"] = {}, ["inventory"] = {} }, ["param2"] = 0, ["y"] = 1, ["param1"] = 11, ["z"] = 6, ["name"] = "lottother:dirt" },
{["x"] = 2, ["meta"] = { ["fields"] = {}, ["inventory"] = {} }, ["param2"] = 0, ["y"] = 1, ["param1"] = 11, ["z"] = 7, ["name"] = "lottother:dirt" },
{["x"] = 2, ["meta"] = { ["fields"] = {}, ["inventory"] = {} }, ["param2"] = 0, ["y"] = 1, ["param1"] = 11, ["z"] = 8, ["name"] = "lottother:dirt" },
{["x"] = 2, ["meta"] = { ["fields"] = {}, ["inventory"] = {} }, ["param2"] = 0, ["y"] = 1, ["param1"] = 11, ["z"] = 9, ["name"] = "lottother:dirt" },
{["x"] = 2, ["meta"] = { ["fields"] = {}, ["inventory"] = {} }, ["param2"] = 0, ["y"] = 1, ["param1"] = 11, ["z"] = 10, ["name"] = "lottother:dirt" },
{["x"] = 2, ["meta"] = { ["fields"] = {}, ["inventory"] = {} }, ["param2"] = 0, ["y"] = 1, ["param1"] = 12, ["z"] = 11, ["name"] = "lottother:dirt" },
{["x"] = 2, ["meta"] = { ["fields"] = {}, ["inventory"] = {} }, ["param2"] = 0, ["y"] = 1, ["param1"] = 0, ["z"] = 12, ["name"] = "lord_ground:dirt_mirkwood" },
{["x"] = 2, ["meta"] = { ["fields"] = {}, ["inventory"] = {} }, ["param2"] = 0, ["y"] = 2, ["param1"] = 0, ["z"] = 2, ["name"] = "lord_ground:dirt_mirkwood" },
{["x"] = 2, ["meta"] = { ["fields"] = {}, ["inventory"] = {} }, ["param2"] = 0, ["y"] = 2, ["param1"] = 0, ["z"] = 3, ["name"] = "lord_ground:dirt_mirkwood" },
{["x"] = 2, ["meta"] = { ["fields"] = {}, ["inventory"] = {} }, ["param2"] = 0, ["y"] = 2, ["param1"] = 0, ["z"] = 4, ["name"] = "lord_ground:dirt_mirkwood" },
{["x"] = 2, ["meta"] = { ["fields"] = {}, ["inventory"] = {} }, ["param2"] = 0, ["y"] = 2, ["param1"] = 0, ["z"] = 5, ["name"] = "lord_ground:dirt_mirkwood" },
{["x"] = 2, ["meta"] = { ["fields"] = {}, ["inventory"] = {} }, ["param2"] = 0, ["y"] = 2, ["param1"] = 0, ["z"] = 6, ["name"] = "lord_ground:dirt_mirkwood" },
{["x"] = 2, ["meta"] = { ["fields"] = {}, ["inventory"] = {} }, ["param2"] = 0, ["y"] = 2, ["param1"] = 11, ["z"] = 7, ["name"] = "lottother:dirt" },
{["x"] = 2, ["meta"] = { ["fields"] = {}, ["inventory"] = {} }, ["param2"] = 0, ["y"] = 2, ["param1"] = 0, ["z"] = 8, ["name"] = "lord_ground:dirt_mirkwood" },
{["x"] = 2, ["meta"] = { ["fields"] = {}, ["inventory"] = {} }, ["param2"] = 0, ["y"] = 2, ["param1"] = 0, ["z"] = 9, ["name"] = "lord_ground:dirt_mirkwood" },
{["x"] = 2, ["meta"] = { ["fields"] = {}, ["inventory"] = {} }, ["param2"] = 0, ["y"] = 2, ["param1"] = 0, ["z"] = 10, ["name"] = "lord_ground:dirt_mirkwood" },
{["x"] = 2, ["meta"] = { ["fields"] = {}, ["inventory"] = {} }, ["param2"] = 0, ["y"] = 2, ["param1"] = 0, ["z"] = 11, ["name"] = "lord_ground:dirt_mirkwood" },
{["x"] = 2, ["meta"] = { ["fields"] = {}, ["inventory"] = {} }, ["param2"] = 0, ["y"] = 3, ["param1"] = 0, ["z"] = 7, ["name"] = "default:tree" },
{["x"] = 2, ["meta"] = { ["fields"] = {}, ["inventory"] = {} }, ["param2"] = 0, ["y"] = 4, ["param1"] = 0, ["z"] = 7, ["name"] = "default:tree" },
{["x"] = 2, ["meta"] = { ["fields"] = {}, ["inventory"] = {} }, ["param2"] = 0, ["y"] = 5, ["param1"] = 0, ["z"] = 7, ["name"] = "default:tree" },
{["x"] = 2, ["meta"] = { ["fields"] = {}, ["inventory"] = {} }, ["param2"] = 0, ["y"] = 6, ["param1"] = 0, ["z"] = 7, ["name"] = "default:tree" },
{["x"] = 2, ["meta"] = { ["fields"] = {}, ["inventory"] = {} }, ["param2"] = 1, ["y"] = 7, ["param1"] = 45, ["z"] = 3, ["name"] = "stairs:stair_junglewood" },
{["x"] = 2, ["meta"] = { ["fields"] = {}, ["inventory"] = {} }, ["param2"] = 1, ["y"] = 7, ["param1"] = 29, ["z"] = 4, ["name"] = "stairs:stair_junglewood" },
{["x"] = 2, ["meta"] = { ["fields"] = {}, ["inventory"] = {} }, ["param2"] = 1, ["y"] = 7, ["param1"] = 12, ["z"] = 5, ["name"] = "stairs:stair_junglewood" },
{["x"] = 2, ["meta"] = { ["fields"] = {}, ["inventory"] = {} }, ["param2"] = 0, ["y"] = 7, ["param1"] = 0, ["z"] = 7, ["name"] = "default:tree" },
{["x"] = 2, ["meta"] = { ["fields"] = {}, ["inventory"] = {} }, ["param2"] = 0, ["y"] = 16, ["param1"] = 12, ["z"] = 5, ["name"] = "lord_trees:mirk_leaf" },
{["x"] = 2, ["meta"] = { ["fields"] = {}, ["inventory"] = {} }, ["param2"] = 0, ["y"] = 16, ["param1"] = 27, ["z"] = 6, ["name"] = "lord_trees:mirk_leaf" },
{["x"] = 2, ["meta"] = { ["fields"] = {}, ["inventory"] = {} }, ["param2"] = 0, ["y"] = 16, ["param1"] = 43, ["z"] = 7, ["name"] = "lord_trees:mirk_leaf" },
{["x"] = 2, ["meta"] = { ["fields"] = {}, ["inventory"] = {} }, ["param2"] = 0, ["y"] = 16, ["param1"] = 59, ["z"] = 8, ["name"] = "lord_trees:mirk_leaf" },
{["x"] = 2, ["meta"] = { ["fields"] = {}, ["inventory"] = {} }, ["param2"] = 0, ["y"] = 17, ["param1"] = 27, ["z"] = 7, ["name"] = "lord_trees:mirk_leaf" },
{["x"] = 2, ["meta"] = { ["fields"] = {}, ["inventory"] = {} }, ["param2"] = 0, ["y"] = 19, ["param1"] = 11, ["z"] = 6, ["name"] = "lord_trees:mirk_leaf" },
{["x"] = 2, ["meta"] = { ["fields"] = {}, ["inventory"] = {} }, ["param2"] = 0, ["y"] = 19, ["param1"] = 11, ["z"] = 7, ["name"] = "lord_trees:mirk_leaf" },
{["x"] = 2, ["meta"] = { ["fields"] = {}, ["inventory"] = {} }, ["param2"] = 0, ["y"] = 19, ["param1"] = 11, ["z"] = 8, ["name"] = "lord_trees:mirk_leaf" },
{["x"] = 2, ["meta"] = { ["fields"] = {}, ["inventory"] = {} }, ["param2"] = 0, ["y"] = 21, ["param1"] = 12, ["z"] = 5, ["name"] = "lord_trees:mirk_leaf" },
{["x"] = 2, ["meta"] = { ["fields"] = {}, ["inventory"] = {} }, ["param2"] = 0, ["y"] = 21, ["param1"] = 11, ["z"] = 6, ["name"] = "lord_trees:mirk_leaf" },
{["x"] = 2, ["meta"] = { ["fields"] = {}, ["inventory"] = {} }, ["param2"] = 0, ["y"] = 21, ["param1"] = 11, ["z"] = 7, ["name"] = "lord_trees:mirk_leaf" },
{["x"] = 2, ["meta"] = { ["fields"] = {}, ["inventory"] = {} }, ["param2"] = 0, ["y"] = 21, ["param1"] = 11, ["z"] = 8, ["name"] = "lord_trees:mirk_leaf" },
{["x"] = 2, ["meta"] = { ["fields"] = {}, ["inventory"] = {} }, ["param2"] = 0, ["y"] = 21, ["param1"] = 11, ["z"] = 9, ["name"] = "lord_trees:mirk_leaf" },
{["x"] = 2, ["meta"] = { ["fields"] = {}, ["inventory"] = {} }, ["param2"] = 0, ["y"] = 22, ["param1"] = 13, ["z"] = 2, ["name"] = "lord_trees:mirk_leaf" },
{["x"] = 2, ["meta"] = { ["fields"] = {}, ["inventory"] = {} }, ["param2"] = 0, ["y"] = 22, ["param1"] = 13, ["z"] = 3, ["name"] = "lord_trees:mirk_leaf" },
{["x"] = 2, ["meta"] = { ["fields"] = {}, ["inventory"] = {} }, ["param2"] = 0, ["y"] = 22, ["param1"] = 13, ["z"] = 4, ["name"] = "lord_trees:mirk_leaf" },
{["x"] = 2, ["meta"] = { ["fields"] = {}, ["inventory"] = {} }, ["param2"] = 0, ["y"] = 22, ["param1"] = 12, ["z"] = 5, ["name"] = "lord_trees:mirk_leaf" },
{["x"] = 2, ["meta"] = { ["fields"] = {}, ["inventory"] = {} }, ["param2"] = 0, ["y"] = 22, ["param1"] = 11, ["z"] = 6, ["name"] = "lord_trees:mirk_leaf" },
{["x"] = 2, ["meta"] = { ["fields"] = {}, ["inventory"] = {} }, ["param2"] = 0, ["y"] = 22, ["param1"] = 0, ["z"] = 7, ["name"] = "default:tree" },
{["x"] = 2, ["meta"] = { ["fields"] = {}, ["inventory"] = {} }, ["param2"] = 0, ["y"] = 22, ["param1"] = 11, ["z"] = 8, ["name"] = "lord_trees:mirk_leaf" },
{["x"] = 2, ["meta"] = { ["fields"] = {}, ["inventory"] = {} }, ["param2"] = 0, ["y"] = 22, ["param1"] = 11, ["z"] = 9, ["name"] = "lord_trees:mirk_leaf" },
{["x"] = 2, ["meta"] = { ["fields"] = {}, ["inventory"] = {} }, ["param2"] = 0, ["y"] = 22, ["param1"] = 0, ["z"] = 10, ["name"] = "default:tree" },
{["x"] = 2, ["meta"] = { ["fields"] = {}, ["inventory"] = {} }, ["param2"] = 0, ["y"] = 22, ["param1"] = 12, ["z"] = 11, ["name"] = "lord_trees:mirk_leaf" },
{["x"] = 2, ["meta"] = { ["fields"] = {}, ["inventory"] = {} }, ["param2"] = 0, ["y"] = 22, ["param1"] = 29, ["z"] = 12, ["name"] = "lord_trees:mirk_leaf" },
{["x"] = 2, ["meta"] = { ["fields"] = {}, ["inventory"] = {} }, ["param2"] = 0, ["y"] = 23, ["param1"] = 13, ["z"] = 5, ["name"] = "lord_trees:mirk_leaf" },
{["x"] = 2, ["meta"] = { ["fields"] = {}, ["inventory"] = {} }, ["param2"] = 0, ["y"] = 23, ["param1"] = 12, ["z"] = 6, ["name"] = "lord_trees:mirk_leaf" },
{["x"] = 2, ["meta"] = { ["fields"] = {}, ["inventory"] = {} }, ["param2"] = 0, ["y"] = 23, ["param1"] = 11, ["z"] = 7, ["name"] = "lord_trees:mirk_leaf" },
{["x"] = 2, ["meta"] = { ["fields"] = {}, ["inventory"] = {} }, ["param2"] = 0, ["y"] = 23, ["param1"] = 11, ["z"] = 8, ["name"] = "lord_trees:mirk_leaf" },
{["x"] = 2, ["meta"] = { ["fields"] = {}, ["inventory"] = {} }, ["param2"] = 0, ["y"] = 23, ["param1"] = 12, ["z"] = 10, ["name"] = "lord_trees:mirk_leaf" },
{["x"] = 2, ["meta"] = { ["fields"] = {}, ["inventory"] = {} }, ["param2"] = 0, ["y"] = 23, ["param1"] = 13, ["z"] = 11, ["name"] = "lord_trees:mirk_leaf" },
{["x"] = 2, ["meta"] = { ["fields"] = {}, ["inventory"] = {} }, ["param2"] = 0, ["y"] = 25, ["param1"] = 13, ["z"] = 3, ["name"] = "lord_trees:mirk_leaf" },
{["x"] = 2, ["meta"] = { ["fields"] = {}, ["inventory"] = {} }, ["param2"] = 0, ["y"] = 25, ["param1"] = 13, ["z"] = 4, ["name"] = "lord_trees:mirk_leaf" },
{["x"] = 2, ["meta"] = { ["fields"] = {}, ["inventory"] = {} }, ["param2"] = 0, ["y"] = 25, ["param1"] = 13, ["z"] = 5, ["name"] = "lord_trees:mirk_leaf" },
{["x"] = 2, ["meta"] = { ["fields"] = {}, ["inventory"] = {} }, ["param2"] = 0, ["y"] = 25, ["param1"] = 13, ["z"] = 6, ["name"] = "lord_trees:mirk_leaf" },
{["x"] = 2, ["meta"] = { ["fields"] = {}, ["inventory"] = {} }, ["param2"] = 0, ["y"] = 25, ["param1"] = 12, ["z"] = 7, ["name"] = "lord_trees:mirk_leaf" },
{["x"] = 2, ["meta"] = { ["fields"] = {}, ["inventory"] = {} }, ["param2"] = 0, ["y"] = 25, ["param1"] = 0, ["z"] = 8, ["name"] = "default:tree" },
{["x"] = 2, ["meta"] = { ["fields"] = {}, ["inventory"] = {} }, ["param2"] = 0, ["y"] = 25, ["param1"] = 12, ["z"] = 9, ["name"] = "lord_trees:mirk_leaf" },
{["x"] = 2, ["meta"] = { ["fields"] = {}, ["inventory"] = {} }, ["param2"] = 0, ["y"] = 25, ["param1"] = 12, ["z"] = 10, ["name"] = "lord_trees:mirk_leaf" },
{["x"] = 2, ["meta"] = { ["fields"] = {}, ["inventory"] = {} }, ["param2"] = 0, ["y"] = 25, ["param1"] = 13, ["z"] = 11, ["name"] = "lord_trees:mirk_leaf" },
{["x"] = 2, ["meta"] = { ["fields"] = {}, ["inventory"] = {} }, ["param2"] = 0, ["y"] = 26, ["param1"] = 13, ["z"] = 7, ["name"] = "lord_trees:mirk_leaf" },
{["x"] = 2, ["meta"] = { ["fields"] = {}, ["inventory"] = {} }, ["param2"] = 0, ["y"] = 26, ["param1"] = 13, ["z"] = 8, ["name"] = "lord_trees:mirk_leaf" },
{["x"] = 2, ["meta"] = { ["fields"] = {}, ["inventory"] = {} }, ["param2"] = 0, ["y"] = 26, ["param1"] = 13, ["z"] = 9, ["name"] = "lord_trees:mirk_leaf" },
{["x"] = 2, ["meta"] = { ["fields"] = {}, ["inventory"] = {} }, ["param2"] = 0, ["y"] = 26, ["param1"] = 13, ["z"] = 10, ["name"] = "lord_trees:mirk_leaf" },
{["x"] = 2, ["meta"] = { ["fields"] = {}, ["inventory"] = {} }, ["param2"] = 0, ["y"] = 26, ["param1"] = 13, ["z"] = 11, ["name"] = "lord_trees:mirk_leaf" },
{["x"] = 3, ["meta"] = { ["fields"] = {}, ["inventory"] = {} }, ["param2"] = 0, ["y"] = 0, ["param1"] = 0, ["z"] = 0, ["name"] = "lottother:dirt" },
{["x"] = 3, ["meta"] = { ["fields"] = {}, ["inventory"] = {} }, ["param2"] = 0, ["y"] = 0, ["param1"] = 15, ["z"] = 1, ["name"] = "lottother:dirt" },
{["x"] = 3, ["meta"] = { ["fields"] = {}, ["inventory"] = {} }, ["param2"] = 0, ["y"] = 0, ["param1"] = 29, ["z"] = 2, ["name"] = "lottother:dirt" },
{["x"] = 3, ["meta"] = { ["fields"] = {}, ["inventory"] = {} }, ["param2"] = 0, ["y"] = 0, ["param1"] = 12, ["z"] = 3, ["name"] = "lottother:dirt" },
{["x"] = 3, ["meta"] = { ["fields"] = {}, ["inventory"] = {} }, ["param2"] = 0, ["y"] = 0, ["param1"] = 12, ["z"] = 4, ["name"] = "lottother:dirt" },
{["x"] = 3, ["meta"] = { ["fields"] = {}, ["inventory"] = {} }, ["param2"] = 0, ["y"] = 0, ["param1"] = 11, ["z"] = 5, ["name"] = "lottother:dirt" },
{["x"] = 3, ["meta"] = { ["fields"] = {}, ["inventory"] = {} }, ["param2"] = 0, ["y"] = 0, ["param1"] = 10, ["z"] = 6, ["name"] = "lottother:dirt" },
{["x"] = 3, ["meta"] = { ["fields"] = {}, ["inventory"] = {} }, ["param2"] = 0, ["y"] = 0, ["param1"] = 10, ["z"] = 7, ["name"] = "lottother:dirt" },
{["x"] = 3, ["meta"] = { ["fields"] = {}, ["inventory"] = {} }, ["param2"] = 0, ["y"] = 0, ["param1"] = 10, ["z"] = 8, ["name"] = "lottother:dirt" },
{["x"] = 3, ["meta"] = { ["fields"] = {}, ["inventory"] = {} }, ["param2"] = 0, ["y"] = 0, ["param1"] = 10, ["z"] = 9, ["name"] = "lottother:dirt" },
{["x"] = 3, ["meta"] = { ["fields"] = {}, ["inventory"] = {} }, ["param2"] = 0, ["y"] = 0, ["param1"] = 11, ["z"] = 10, ["name"] = "lottother:dirt" },
{["x"] = 3, ["meta"] = { ["fields"] = {}, ["inventory"] = {} }, ["param2"] = 0, ["y"] = 0, ["param1"] = 12, ["z"] = 11, ["name"] = "lottother:dirt" },
{["x"] = 3, ["meta"] = { ["fields"] = {}, ["inventory"] = {} }, ["param2"] = 0, ["y"] = 0, ["param1"] = 0, ["z"] = 12, ["name"] = "lottother:dirt" },
{["x"] = 3, ["meta"] = { ["fields"] = {}, ["inventory"] = {} }, ["param2"] = 0, ["y"] = 0, ["param1"] = 0, ["z"] = 13, ["name"] = "lottother:dirt" },
{["x"] = 3, ["meta"] = { ["fields"] = {}, ["inventory"] = {} }, ["param2"] = 0, ["y"] = 1, ["param1"] = 0, ["z"] = 0, ["name"] = "lord_ground:dirt_mirkwood" },
{["x"] = 3, ["meta"] = { ["fields"] = {}, ["inventory"] = {} }, ["param2"] = 0, ["y"] = 1, ["param1"] = 31, ["z"] = 1, ["name"] = "lottother:dirt" },
{["x"] = 3, ["meta"] = { ["fields"] = {}, ["inventory"] = {} }, ["param2"] = 0, ["y"] = 1, ["param1"] = 45, ["z"] = 2, ["name"] = "lottother:dirt" },
{["x"] = 3, ["meta"] = { ["fields"] = {}, ["inventory"] = {} }, ["param2"] = 0, ["y"] = 1, ["param1"] = 28, ["z"] = 3, ["name"] = "lottother:dirt" },
{["x"] = 3, ["meta"] = { ["fields"] = {}, ["inventory"] = {} }, ["param2"] = 0, ["y"] = 1, ["param1"] = 12, ["z"] = 4, ["name"] = "lottother:dirt" },
{["x"] = 3, ["meta"] = { ["fields"] = {}, ["inventory"] = {} }, ["param2"] = 0, ["y"] = 1, ["param1"] = 11, ["z"] = 5, ["name"] = "lottother:dirt" },
{["x"] = 3, ["meta"] = { ["fields"] = {}, ["inventory"] = {} }, ["param2"] = 0, ["y"] = 1, ["param1"] = 10, ["z"] = 6, ["name"] = "lottother:dirt" },
{["x"] = 3, ["meta"] = { ["fields"] = {}, ["inventory"] = {} }, ["param2"] = 0, ["y"] = 1, ["param1"] = 10, ["z"] = 7, ["name"] = "lottother:dirt" },
{["x"] = 3, ["meta"] = { ["fields"] = {}, ["inventory"] = {} }, ["param2"] = 0, ["y"] = 1, ["param1"] = 10, ["z"] = 8, ["name"] = "lottother:dirt" },
{["x"] = 3, ["meta"] = { ["fields"] = {}, ["inventory"] = {} }, ["param2"] = 0, ["y"] = 1, ["param1"] = 10, ["z"] = 9, ["name"] = "lottother:dirt" },
{["x"] = 3, ["meta"] = { ["fields"] = {}, ["inventory"] = {} }, ["param2"] = 0, ["y"] = 1, ["param1"] = 11, ["z"] = 10, ["name"] = "lottother:dirt" },
{["x"] = 3, ["meta"] = { ["fields"] = {}, ["inventory"] = {} }, ["param2"] = 0, ["y"] = 1, ["param1"] = 12, ["z"] = 11, ["name"] = "lottother:dirt" },
{["x"] = 3, ["meta"] = { ["fields"] = {}, ["inventory"] = {} }, ["param2"] = 0, ["y"] = 1, ["param1"] = 0, ["z"] = 12, ["name"] = "lord_ground:dirt_mirkwood" },
{["x"] = 3, ["meta"] = { ["fields"] = {}, ["inventory"] = {} }, ["param2"] = 0, ["y"] = 1, ["param1"] = 0, ["z"] = 13, ["name"] = "lord_ground:dirt_mirkwood" },
{["x"] = 3, ["meta"] = { ["fields"] = {}, ["inventory"] = {} }, ["param2"] = 0, ["y"] = 2, ["param1"] = 0, ["z"] = 1, ["name"] = "lord_ground:dirt_mirkwood" },
{["x"] = 3, ["meta"] = { ["fields"] = {}, ["inventory"] = {} }, ["param2"] = 0, ["y"] = 2, ["param1"] = 0, ["z"] = 2, ["name"] = "lord_ground:dirt_mirkwood" },
{["x"] = 3, ["meta"] = { ["fields"] = {}, ["inventory"] = {} }, ["param2"] = 0, ["y"] = 2, ["param1"] = 44, ["z"] = 3, ["name"] = "lottother:dirt" },
{["x"] = 3, ["meta"] = { ["fields"] = {}, ["inventory"] = {} }, ["param2"] = 0, ["y"] = 2, ["param1"] = 28, ["z"] = 4, ["name"] = "lottother:dirt" },
{["x"] = 3, ["meta"] = { ["fields"] = {}, ["inventory"] = {} }, ["param2"] = 0, ["y"] = 2, ["param1"] = 11, ["z"] = 5, ["name"] = "lottother:dirt" },
{["x"] = 3, ["meta"] = { ["fields"] = {}, ["inventory"] = {} }, ["param2"] = 0, ["y"] = 2, ["param1"] = 10, ["z"] = 6, ["name"] = "lottother:dirt" },
{["x"] = 3, ["meta"] = { ["fields"] = {}, ["inventory"] = {} }, ["param2"] = 0, ["y"] = 2, ["param1"] = 10, ["z"] = 7, ["name"] = "lottother:dirt" },
{["x"] = 3, ["meta"] = { ["fields"] = {}, ["inventory"] = {} }, ["param2"] = 0, ["y"] = 2, ["param1"] = 0, ["z"] = 8, ["name"] = "lord_ground:dirt_mirkwood" },
{["x"] = 3, ["meta"] = { ["fields"] = {}, ["inventory"] = {} }, ["param2"] = 0, ["y"] = 2, ["param1"] = 0, ["z"] = 9, ["name"] = "lord_ground:dirt_mirkwood" },
{["x"] = 3, ["meta"] = { ["fields"] = {}, ["inventory"] = {} }, ["param2"] = 0, ["y"] = 2, ["param1"] = 11, ["z"] = 10, ["name"] = "lottother:dirt" },
{["x"] = 3, ["meta"] = { ["fields"] = {}, ["inventory"] = {} }, ["param2"] = 0, ["y"] = 2, ["param1"] = 0, ["z"] = 11, ["name"] = "lord_ground:dirt_mirkwood" },
{["x"] = 3, ["meta"] = { ["fields"] = {}, ["inventory"] = {} }, ["param2"] = 0, ["y"] = 3, ["param1"] = 0, ["z"] = 3, ["name"] = "default:junglewood" },
{["x"] = 3, ["meta"] = { ["fields"] = {}, ["inventory"] = {} }, ["param2"] = 0, ["y"] = 3, ["param1"] = 0, ["z"] = 4, ["name"] = "default:junglewood" },
{["x"] = 3, ["meta"] = { ["fields"] = {}, ["inventory"] = {} }, ["param2"] = 0, ["y"] = 3, ["param1"] = 0, ["z"] = 5, ["name"] = "default:tree" },
{["x"] = 3, ["meta"] = { ["fields"] = {}, ["inventory"] = {} }, ["param2"] = 0, ["y"] = 3, ["param1"] = 0, ["z"] = 6, ["name"] = "default:tree" },
{["x"] = 3, ["meta"] = { ["fields"] = {}, ["inventory"] = {} }, ["param2"] = 0, ["y"] = 3, ["param1"] = 0, ["z"] = 7, ["name"] = "default:tree" },
{["x"] = 3, ["meta"] = { ["fields"] = {}, ["inventory"] = {} }, ["param2"] = 0, ["y"] = 3, ["param1"] = 0, ["z"] = 10, ["name"] = "default:tree" },
{["x"] = 3, ["meta"] = { ["fields"] = {}, ["inventory"] = {} }, ["param2"] = 0, ["y"] = 4, ["param1"] = 76, ["z"] = 3, ["name"] = "default:fence_wood" },
{["x"] = 3, ["meta"] = { ["fields"] = {}, ["inventory"] = {} }, ["param2"] = 0, ["y"] = 4, ["param1"] = 0, ["z"] = 4, ["name"] = "default:junglewood" },
{["x"] = 3, ["meta"] = { ["fields"] = {}, ["inventory"] = {} }, ["param2"] = 0, ["y"] = 4, ["param1"] = 0, ["z"] = 5, ["name"] = "default:tree" },
{["x"] = 3, ["meta"] = { ["fields"] = {}, ["inventory"] = {} }, ["param2"] = 0, ["y"] = 4, ["param1"] = 0, ["z"] = 6, ["name"] = "default:tree" },
{["x"] = 3, ["meta"] = { ["fields"] = {}, ["inventory"] = {} }, ["param2"] = 0, ["y"] = 4, ["param1"] = 0, ["z"] = 7, ["name"] = "default:tree" },
{["x"] = 3, ["meta"] = { ["fields"] = {}, ["inventory"] = {} }, ["param2"] = 0, ["y"] = 4, ["param1"] = 0, ["z"] = 10, ["name"] = "default:tree" },
{["x"] = 3, ["meta"] = { ["fields"] = {}, ["inventory"] = {} }, ["param2"] = 0, ["y"] = 5, ["param1"] = 92, ["z"] = 3, ["name"] = "default:fence_wood" },
{["x"] = 3, ["meta"] = { ["fields"] = {}, ["inventory"] = {} }, ["param2"] = 0, ["y"] = 5, ["param1"] = 0, ["z"] = 4, ["name"] = "default:junglewood" },
{["x"] = 3, ["meta"] = { ["fields"] = {}, ["inventory"] = {} }, ["param2"] = 0, ["y"] = 5, ["param1"] = 0, ["z"] = 5, ["name"] = "default:tree" },
{["x"] = 3, ["meta"] = { ["fields"] = {}, ["inventory"] = {} }, ["param2"] = 0, ["y"] = 5, ["param1"] = 0, ["z"] = 6, ["name"] = "default:tree" },
{["x"] = 3, ["meta"] = { ["fields"] = {}, ["inventory"] = {} }, ["param2"] = 0, ["y"] = 5, ["param1"] = 0, ["z"] = 7, ["name"] = "default:tree" },
{["x"] = 3, ["meta"] = { ["fields"] = {}, ["inventory"] = {} }, ["param2"] = 0, ["y"] = 5, ["param1"] = 0, ["z"] = 10, ["name"] = "default:tree" },
{["x"] = 3, ["meta"] = { ["fields"] = {}, ["inventory"] = {} }, ["param2"] = 0, ["y"] = 6, ["param1"] = 76, ["z"] = 3, ["name"] = "default:fence_wood" },
{["x"] = 3, ["meta"] = { ["fields"] = {}, ["inventory"] = {} }, ["param2"] = 0, ["y"] = 6, ["param1"] = 0, ["z"] = 4, ["name"] = "default:junglewood" },
{["x"] = 3, ["meta"] = { ["fields"] = {}, ["inventory"] = {} }, ["param2"] = 0, ["y"] = 6, ["param1"] = 0, ["z"] = 5, ["name"] = "default:tree" },
{["x"] = 3, ["meta"] = { ["fields"] = {}, ["inventory"] = {} }, ["param2"] = 0, ["y"] = 6, ["param1"] = 0, ["z"] = 6, ["name"] = "default:tree" },
{["x"] = 3, ["meta"] = { ["fields"] = {}, ["inventory"] = {} }, ["param2"] = 0, ["y"] = 6, ["param1"] = 0, ["z"] = 7, ["name"] = "default:tree" },
{["x"] = 3, ["meta"] = { ["fields"] = {}, ["inventory"] = {} }, ["param2"] = 0, ["y"] = 6, ["param1"] = 0, ["z"] = 8, ["name"] = "default:tree" },
{["x"] = 3, ["meta"] = { ["fields"] = {}, ["inventory"] = {} }, ["param2"] = 0, ["y"] = 6, ["param1"] = 0, ["z"] = 10, ["name"] = "default:tree" },
{["x"] = 3, ["meta"] = { ["fields"] = {}, ["inventory"] = {} }, ["param2"] = 0, ["y"] = 7, ["param1"] = 77, ["z"] = 2, ["name"] = "stairs:stair_junglewood" },
{["x"] = 3, ["meta"] = { ["fields"] = {}, ["inventory"] = {} }, ["param2"] = 0, ["y"] = 7, ["param1"] = 0, ["z"] = 3, ["name"] = "default:junglewood" },
{["x"] = 3, ["meta"] = { ["fields"] = {}, ["inventory"] = {} }, ["param2"] = 0, ["y"] = 7, ["param1"] = 0, ["z"] = 4, ["name"] = "default:junglewood" },
{["x"] = 3, ["meta"] = { ["fields"] = {}, ["inventory"] = {} }, ["param2"] = 0, ["y"] = 7, ["param1"] = 0, ["z"] = 5, ["name"] = "default:tree" },
{["x"] = 3, ["meta"] = { ["fields"] = {}, ["inventory"] = {} }, ["param2"] = 0, ["y"] = 7, ["param1"] = 0, ["z"] = 6, ["name"] = "default:tree" },
{["x"] = 3, ["meta"] = { ["fields"] = {}, ["inventory"] = {} }, ["param2"] = 0, ["y"] = 7, ["param1"] = 0, ["z"] = 7, ["name"] = "default:tree" },
{["x"] = 3, ["meta"] = { ["fields"] = {}, ["inventory"] = {} }, ["param2"] = 0, ["y"] = 7, ["param1"] = 0, ["z"] = 8, ["name"] = "default:tree" },
{["x"] = 3, ["meta"] = { ["fields"] = {}, ["inventory"] = {} }, ["param2"] = 23, ["y"] = 7, ["param1"] = 0, ["z"] = 9, ["name"] = "default:tree" },
{["x"] = 3, ["meta"] = { ["fields"] = {}, ["inventory"] = {} }, ["param2"] = 0, ["y"] = 7, ["param1"] = 0, ["z"] = 10, ["name"] = "default:tree" },
{["x"] = 3, ["meta"] = { ["fields"] = {}, ["inventory"] = {} }, ["param2"] = 1, ["y"] = 8, ["param1"] = 28, ["z"] = 4, ["name"] = "stairs:stair_junglewood" },
{["x"] = 3, ["meta"] = { ["fields"] = {}, ["inventory"] = {} }, ["param2"] = 1, ["y"] = 8, ["param1"] = 11, ["z"] = 5, ["name"] = "stairs:stair_junglewood" },
{["x"] = 3, ["meta"] = { ["fields"] = {}, ["inventory"] = {} }, ["param2"] = 0, ["y"] = 8, ["param1"] = 0, ["z"] = 6, ["name"] = "default:tree" },
{["x"] = 3, ["meta"] = { ["fields"] = {}, ["inventory"] = {} }, ["param2"] = 0, ["y"] = 8, ["param1"] = 0, ["z"] = 7, ["name"] = "default:tree" },
{["x"] = 3, ["meta"] = { ["fields"] = {}, ["inventory"] = {} }, ["param2"] = 0, ["y"] = 8, ["param1"] = 0, ["z"] = 8, ["name"] = "default:tree" },
{["x"] = 3, ["meta"] = { ["fields"] = {}, ["inventory"] = {} }, ["param2"] = 0, ["y"] = 8, ["param1"] = 0, ["z"] = 9, ["name"] = "default:tree" },
{["x"] = 3, ["meta"] = { ["fields"] = {}, ["inventory"] = {} }, ["param2"] = 0, ["y"] = 9, ["param1"] = 0, ["z"] = 6, ["name"] = "default:tree" },
{["x"] = 3, ["meta"] = { ["fields"] = {}, ["inventory"] = {} }, ["param2"] = 3, ["y"] = 9, ["param1"] = 0, ["z"] = 7, ["name"] = "default:tree" },
{["x"] = 3, ["meta"] = { ["fields"] = {}, ["inventory"] = {} }, ["param2"] = 3, ["y"] = 9, ["param1"] = 0, ["z"] = 8, ["name"] = "default:tree" },
{["x"] = 3, ["meta"] = { ["fields"] = {}, ["inventory"] = {} }, ["param2"] = 3, ["y"] = 9, ["param1"] = 0, ["z"] = 9, ["name"] = "default:tree" },
{["x"] = 3, ["meta"] = { ["fields"] = {}, ["inventory"] = {} }, ["param2"] = 0, ["y"] = 10, ["param1"] = 0, ["z"] = 6, ["name"] = "default:tree" },
{["x"] = 3, ["meta"] = { ["fields"] = {}, ["inventory"] = {} }, ["param2"] = 3, ["y"] = 10, ["param1"] = 0, ["z"] = 7, ["name"] = "default:tree" },
{["x"] = 3, ["meta"] = { ["fields"] = {}, ["inventory"] = {} }, ["param2"] = 3, ["y"] = 10, ["param1"] = 0, ["z"] = 8, ["name"] = "default:tree" },
{["x"] = 3, ["meta"] = { ["fields"] = {}, ["inventory"] = {} }, ["param2"] = 3, ["y"] = 10, ["param1"] = 0, ["z"] = 9, ["name"] = "default:tree" },
{["x"] = 3, ["meta"] = { ["fields"] = {}, ["inventory"] = {} }, ["param2"] = 0, ["y"] = 11, ["param1"] = 0, ["z"] = 6, ["name"] = "default:tree" },
{["x"] = 3, ["meta"] = { ["fields"] = {}, ["inventory"] = {} }, ["param2"] = 0, ["y"] = 11, ["param1"] = 0, ["z"] = 7, ["name"] = "default:tree" },
{["x"] = 3, ["meta"] = { ["fields"] = {}, ["inventory"] = {} }, ["param2"] = 3, ["y"] = 11, ["param1"] = 0, ["z"] = 8, ["name"] = "default:tree" },
{["x"] = 3, ["meta"] = { ["fields"] = {}, ["inventory"] = {} }, ["param2"] = 0, ["y"] = 11, ["param1"] = 0, ["z"] = 9, ["name"] = "default:tree" },
{["x"] = 3, ["meta"] = { ["fields"] = {}, ["inventory"] = {} }, ["param2"] = 0, ["y"] = 12, ["param1"] = 0, ["z"] = 6, ["name"] = "default:tree" },
{["x"] = 3, ["meta"] = { ["fields"] = {}, ["inventory"] = {} }, ["param2"] = 0, ["y"] = 12, ["param1"] = 0, ["z"] = 7, ["name"] = "default:tree" },
{["x"] = 3, ["meta"] = { ["fields"] = {}, ["inventory"] = {} }, ["param2"] = 3, ["y"] = 12, ["param1"] = 0, ["z"] = 8, ["name"] = "default:tree" },
{["x"] = 3, ["meta"] = { ["fields"] = {}, ["inventory"] = {} }, ["param2"] = 0, ["y"] = 13, ["param1"] = 0, ["z"] = 6, ["name"] = "default:tree" },
{["x"] = 3, ["meta"] = { ["fields"] = {}, ["inventory"] = {} }, ["param2"] = 0, ["y"] = 13, ["param1"] = 0, ["z"] = 7, ["name"] = "default:tree" },
{["x"] = 3, ["meta"] = { ["fields"] = {}, ["inventory"] = {} }, ["param2"] = 0, ["y"] = 14, ["param1"] = 0, ["z"] = 6, ["name"] = "default:tree" },
{["x"] = 3, ["meta"] = { ["fields"] = {}, ["inventory"] = {} }, ["param2"] = 0, ["y"] = 14, ["param1"] = 0, ["z"] = 7, ["name"] = "default:tree" },
{["x"] = 3, ["meta"] = { ["fields"] = {}, ["inventory"] = {} }, ["param2"] = 0, ["y"] = 15, ["param1"] = 0, ["z"] = 6, ["name"] = "default:tree" },
{["x"] = 3, ["meta"] = { ["fields"] = {}, ["inventory"] = {} }, ["param2"] = 0, ["y"] = 15, ["param1"] = 0, ["z"] = 7, ["name"] = "default:tree" },
{["x"] = 3, ["meta"] = { ["fields"] = {}, ["inventory"] = {} }, ["param2"] = 0, ["y"] = 16, ["param1"] = 44, ["z"] = 4, ["name"] = "lord_trees:mirk_leaf" },
{["x"] = 3, ["meta"] = { ["fields"] = {}, ["inventory"] = {} }, ["param2"] = 0, ["y"] = 16, ["param1"] = 27, ["z"] = 5, ["name"] = "lord_trees:mirk_leaf" },
{["x"] = 3, ["meta"] = { ["fields"] = {}, ["inventory"] = {} }, ["param2"] = 0, ["y"] = 16, ["param1"] = 0, ["z"] = 6, ["name"] = "default:tree" },
{["x"] = 3, ["meta"] = { ["fields"] = {}, ["inventory"] = {} }, ["param2"] = 0, ["y"] = 16, ["param1"] = 0, ["z"] = 7, ["name"] = "default:tree" },
{["x"] = 3, ["meta"] = { ["fields"] = {}, ["inventory"] = {} }, ["param2"] = 0, ["y"] = 16, ["param1"] = 74, ["z"] = 8, ["name"] = "lord_trees:mirk_leaf" },
{["x"] = 3, ["meta"] = { ["fields"] = {}, ["inventory"] = {} }, ["param2"] = 0, ["y"] = 16, ["param1"] = 90, ["z"] = 9, ["name"] = "lord_trees:mirk_leaf" },
{["x"] = 3, ["meta"] = { ["fields"] = {}, ["inventory"] = {} }, ["param2"] = 0, ["y"] = 16, ["param1"] = 107, ["z"] = 10, ["name"] = "lord_trees:mirk_leaf" },
{["x"] = 3, ["meta"] = { ["fields"] = {}, ["inventory"] = {} }, ["param2"] = 0, ["y"] = 16, ["param1"] = 124, ["z"] = 11, ["name"] = "lord_trees:mirk_leaf" },
{["x"] = 3, ["meta"] = { ["fields"] = {}, ["inventory"] = {} }, ["param2"] = 0, ["y"] = 16, ["param1"] = 109, ["z"] = 12, ["name"] = "lord_trees:mirk_leaf" },
{["x"] = 3, ["meta"] = { ["fields"] = {}, ["inventory"] = {} }, ["param2"] = 0, ["y"] = 17, ["param1"] = 11, ["z"] = 5, ["name"] = "lord_trees:mirk_leaf" },
{["x"] = 3, ["meta"] = { ["fields"] = {}, ["inventory"] = {} }, ["param2"] = 0, ["y"] = 17, ["param1"] = 0, ["z"] = 6, ["name"] = "default:tree" },
{["x"] = 3, ["meta"] = { ["fields"] = {}, ["inventory"] = {} }, ["param2"] = 0, ["y"] = 17, ["param1"] = 0, ["z"] = 7, ["name"] = "default:tree" },
{["x"] = 3, ["meta"] = { ["fields"] = {}, ["inventory"] = {} }, ["param2"] = 0, ["y"] = 17, ["param1"] = 58, ["z"] = 8, ["name"] = "lord_trees:mirk_leaf" },
{["x"] = 3, ["meta"] = { ["fields"] = {}, ["inventory"] = {} }, ["param2"] = 0, ["y"] = 17, ["param1"] = 93, ["z"] = 12, ["name"] = "lord_trees:mirk_leaf" },
{["x"] = 3, ["meta"] = { ["fields"] = {}, ["inventory"] = {} }, ["param2"] = 0, ["y"] = 18, ["param1"] = 11, ["z"] = 5, ["name"] = "lord_trees:mirk_leaf" },
{["x"] = 3, ["meta"] = { ["fields"] = {}, ["inventory"] = {} }, ["param2"] = 0, ["y"] = 18, ["param1"] = 0, ["z"] = 6, ["name"] = "default:tree" },
{["x"] = 3, ["meta"] = { ["fields"] = {}, ["inventory"] = {} }, ["param2"] = 0, ["y"] = 18, ["param1"] = 0, ["z"] = 7, ["name"] = "default:tree" },
{["x"] = 3, ["meta"] = { ["fields"] = {}, ["inventory"] = {} }, ["param2"] = 0, ["y"] = 18, ["param1"] = 42, ["z"] = 8, ["name"] = "lord_trees:mirk_leaf" },
{["x"] = 3, ["meta"] = { ["fields"] = {}, ["inventory"] = {} }, ["param2"] = 0, ["y"] = 18, ["param1"] = 58, ["z"] = 9, ["name"] = "lord_trees:mirk_leaf" },
{["x"] = 3, ["meta"] = { ["fields"] = {}, ["inventory"] = {} }, ["param2"] = 0, ["y"] = 19, ["param1"] = 11, ["z"] = 5, ["name"] = "lord_trees:mirk_leaf" },
{["x"] = 3, ["meta"] = { ["fields"] = {}, ["inventory"] = {} }, ["param2"] = 0, ["y"] = 19, ["param1"] = 0, ["z"] = 6, ["name"] = "default:tree" },
{["x"] = 3, ["meta"] = { ["fields"] = {}, ["inventory"] = {} }, ["param2"] = 0, ["y"] = 19, ["param1"] = 0, ["z"] = 7, ["name"] = "default:tree" },
{["x"] = 3, ["meta"] = { ["fields"] = {}, ["inventory"] = {} }, ["param2"] = 0, ["y"] = 19, ["param1"] = 26, ["z"] = 8, ["name"] = "lord_trees:mirk_leaf" },
{["x"] = 3, ["meta"] = { ["fields"] = {}, ["inventory"] = {} }, ["param2"] = 0, ["y"] = 19, ["param1"] = 42, ["z"] = 9, ["name"] = "lord_trees:mirk_leaf" },
{["x"] = 3, ["meta"] = { ["fields"] = {}, ["inventory"] = {} }, ["param2"] = 0, ["y"] = 20, ["param1"] = 0, ["z"] = 6, ["name"] = "default:tree" },
{["x"] = 3, ["meta"] = { ["fields"] = {}, ["inventory"] = {} }, ["param2"] = 0, ["y"] = 20, ["param1"] = 0, ["z"] = 7, ["name"] = "default:tree" },
{["x"] = 3, ["meta"] = { ["fields"] = {}, ["inventory"] = {} }, ["param2"] = 0, ["y"] = 20, ["param1"] = 10, ["z"] = 8, ["name"] = "lord_trees:mirk_leaf" },
{["x"] = 3, ["meta"] = { ["fields"] = {}, ["inventory"] = {} }, ["param2"] = 0, ["y"] = 21, ["param1"] = 0, ["z"] = 6, ["name"] = "default:tree" },
{["x"] = 3, ["meta"] = { ["fields"] = {}, ["inventory"] = {} }, ["param2"] = 0, ["y"] = 21, ["param1"] = 0, ["z"] = 7, ["name"] = "default:tree" },
{["x"] = 3, ["meta"] = { ["fields"] = {}, ["inventory"] = {} }, ["param2"] = 0, ["y"] = 21, ["param1"] = 10, ["z"] = 8, ["name"] = "lord_trees:mirk_leaf" },
{["x"] = 3, ["meta"] = { ["fields"] = {}, ["inventory"] = {} }, ["param2"] = 0, ["y"] = 22, ["param1"] = 13, ["z"] = 3, ["name"] = "lord_trees:mirk_leaf" },
{["x"] = 3, ["meta"] = { ["fields"] = {}, ["inventory"] = {} }, ["param2"] = 0, ["y"] = 22, ["param1"] = 0, ["z"] = 4, ["name"] = "default:tree" },
{["x"] = 3, ["meta"] = { ["fields"] = {}, ["inventory"] = {} }, ["param2"] = 0, ["y"] = 22, ["param1"] = 0, ["z"] = 5, ["name"] = "default:tree" },
{["x"] = 3, ["meta"] = { ["fields"] = {}, ["inventory"] = {} }, ["param2"] = 0, ["y"] = 22, ["param1"] = 0, ["z"] = 6, ["name"] = "default:tree" },
{["x"] = 3, ["meta"] = { ["fields"] = {}, ["inventory"] = {} }, ["param2"] = 0, ["y"] = 22, ["param1"] = 0, ["z"] = 7, ["name"] = "default:tree" },
{["x"] = 3, ["meta"] = { ["fields"] = {}, ["inventory"] = {} }, ["param2"] = 0, ["y"] = 22, ["param1"] = 10, ["z"] = 8, ["name"] = "lord_trees:mirk_leaf" },
{["x"] = 3, ["meta"] = { ["fields"] = {}, ["inventory"] = {} }, ["param2"] = 0, ["y"] = 22, ["param1"] = 10, ["z"] = 9, ["name"] = "lord_trees:mirk_leaf" },
{["x"] = 3, ["meta"] = { ["fields"] = {}, ["inventory"] = {} }, ["param2"] = 0, ["y"] = 22, ["param1"] = 0, ["z"] = 10, ["name"] = "default:tree" },
{["x"] = 3, ["meta"] = { ["fields"] = {}, ["inventory"] = {} }, ["param2"] = 0, ["y"] = 22, ["param1"] = 28, ["z"] = 11, ["name"] = "lord_trees:mirk_leaf" },
{["x"] = 3, ["meta"] = { ["fields"] = {}, ["inventory"] = {} }, ["param2"] = 0, ["y"] = 22, ["param1"] = 45, ["z"] = 12, ["name"] = "lord_trees:mirk_leaf" },
{["x"] = 3, ["meta"] = { ["fields"] = {}, ["inventory"] = {} }, ["param2"] = 0, ["y"] = 23, ["param1"] = 12, ["z"] = 4, ["name"] = "lord_trees:mirk_leaf" },
{["x"] = 3, ["meta"] = { ["fields"] = {}, ["inventory"] = {} }, ["param2"] = 0, ["y"] = 23, ["param1"] = 12, ["z"] = 5, ["name"] = "lord_trees:mirk_leaf" },
{["x"] = 3, ["meta"] = { ["fields"] = {}, ["inventory"] = {} }, ["param2"] = 0, ["y"] = 23, ["param1"] = 11, ["z"] = 6, ["name"] = "lord_trees:mirk_leaf" },
{["x"] = 3, ["meta"] = { ["fields"] = {}, ["inventory"] = {} }, ["param2"] = 0, ["y"] = 23, ["param1"] = 10, ["z"] = 7, ["name"] = "lord_trees:mirk_leaf" },
{["x"] = 3, ["meta"] = { ["fields"] = {}, ["inventory"] = {} }, ["param2"] = 0, ["y"] = 23, ["param1"] = 10, ["z"] = 8, ["name"] = "lord_trees:mirk_leaf" },
{["x"] = 3, ["meta"] = { ["fields"] = {}, ["inventory"] = {} }, ["param2"] = 0, ["y"] = 23, ["param1"] = 10, ["z"] = 9, ["name"] = "lord_trees:mirk_leaf" },
{["x"] = 3, ["meta"] = { ["fields"] = {}, ["inventory"] = {} }, ["param2"] = 0, ["y"] = 23, ["param1"] = 11, ["z"] = 10, ["name"] = "lord_trees:mirk_leaf" },
{["x"] = 3, ["meta"] = { ["fields"] = {}, ["inventory"] = {} }, ["param2"] = 0, ["y"] = 23, ["param1"] = 12, ["z"] = 11, ["name"] = "lord_trees:mirk_leaf" },
{["x"] = 3, ["meta"] = { ["fields"] = {}, ["inventory"] = {} }, ["param2"] = 0, ["y"] = 23, ["param1"] = 29, ["z"] = 12, ["name"] = "lord_trees:mirk_leaf" },
{["x"] = 3, ["meta"] = { ["fields"] = {}, ["inventory"] = {} }, ["param2"] = 0, ["y"] = 24, ["param1"] = 12, ["z"] = 5, ["name"] = "lord_trees:mirk_leaf" },
{["x"] = 3, ["meta"] = { ["fields"] = {}, ["inventory"] = {} }, ["param2"] = 0, ["y"] = 24, ["param1"] = 11, ["z"] = 6, ["name"] = "lord_trees:mirk_leaf" },
{["x"] = 3, ["meta"] = { ["fields"] = {}, ["inventory"] = {} }, ["param2"] = 0, ["y"] = 24, ["param1"] = 11, ["z"] = 7, ["name"] = "lord_trees:mirk_leaf" },
{["x"] = 3, ["meta"] = { ["fields"] = {}, ["inventory"] = {} }, ["param2"] = 0, ["y"] = 24, ["param1"] = 10, ["z"] = 8, ["name"] = "lord_trees:mirk_leaf" },
{["x"] = 3, ["meta"] = { ["fields"] = {}, ["inventory"] = {} }, ["param2"] = 0, ["y"] = 25, ["param1"] = 13, ["z"] = 3, ["name"] = "lord_trees:mirk_leaf" },
{["x"] = 3, ["meta"] = { ["fields"] = {}, ["inventory"] = {} }, ["param2"] = 0, ["y"] = 25, ["param1"] = 13, ["z"] = 4, ["name"] = "lord_trees:mirk_leaf" },
{["x"] = 3, ["meta"] = { ["fields"] = {}, ["inventory"] = {} }, ["param2"] = 0, ["y"] = 25, ["param1"] = 13, ["z"] = 5, ["name"] = "lord_trees:mirk_leaf" },
{["x"] = 3, ["meta"] = { ["fields"] = {}, ["inventory"] = {} }, ["param2"] = 0, ["y"] = 25, ["param1"] = 12, ["z"] = 6, ["name"] = "lord_trees:mirk_leaf" },
{["x"] = 3, ["meta"] = { ["fields"] = {}, ["inventory"] = {} }, ["param2"] = 0, ["y"] = 25, ["param1"] = 12, ["z"] = 7, ["name"] = "lord_trees:mirk_leaf" },
{["x"] = 3, ["meta"] = { ["fields"] = {}, ["inventory"] = {} }, ["param2"] = 0, ["y"] = 25, ["param1"] = 0, ["z"] = 8, ["name"] = "default:tree" },
{["x"] = 3, ["meta"] = { ["fields"] = {}, ["inventory"] = {} }, ["param2"] = 0, ["y"] = 25, ["param1"] = 0, ["z"] = 9, ["name"] = "default:tree" },
{["x"] = 3, ["meta"] = { ["fields"] = {}, ["inventory"] = {} }, ["param2"] = 0, ["y"] = 25, ["param1"] = 12, ["z"] = 10, ["name"] = "lord_trees:mirk_leaf" },
{["x"] = 3, ["meta"] = { ["fields"] = {}, ["inventory"] = {} }, ["param2"] = 0, ["y"] = 25, ["param1"] = 13, ["z"] = 11, ["name"] = "lord_trees:mirk_leaf" },
{["x"] = 3, ["meta"] = { ["fields"] = {}, ["inventory"] = {} }, ["param2"] = 0, ["y"] = 26, ["param1"] = 13, ["z"] = 6, ["name"] = "lord_trees:mirk_leaf" },
{["x"] = 3, ["meta"] = { ["fields"] = {}, ["inventory"] = {} }, ["param2"] = 0, ["y"] = 26, ["param1"] = 13, ["z"] = 7, ["name"] = "lord_trees:mirk_leaf" },
{["x"] = 3, ["meta"] = { ["fields"] = {}, ["inventory"] = {} }, ["param2"] = 0, ["y"] = 26, ["param1"] = 13, ["z"] = 8, ["name"] = "lord_trees:mirk_leaf" },
{["x"] = 3, ["meta"] = { ["fields"] = {}, ["inventory"] = {} }, ["param2"] = 0, ["y"] = 26, ["param1"] = 13, ["z"] = 9, ["name"] = "lord_trees:mirk_leaf" },
{["x"] = 3, ["meta"] = { ["fields"] = {}, ["inventory"] = {} }, ["param2"] = 0, ["y"] = 26, ["param1"] = 13, ["z"] = 10, ["name"] = "lord_trees:mirk_leaf" },
{["x"] = 3, ["meta"] = { ["fields"] = {}, ["inventory"] = {} }, ["param2"] = 0, ["y"] = 26, ["param1"] = 13, ["z"] = 11, ["name"] = "lord_trees:mirk_leaf" },
{["x"] = 4, ["meta"] = { ["fields"] = {}, ["inventory"] = {} }, ["param2"] = 0, ["y"] = 0, ["param1"] = 0, ["z"] = 0, ["name"] = "lottother:dirt" },
{["x"] = 4, ["meta"] = { ["fields"] = {}, ["inventory"] = {} }, ["param2"] = 0, ["y"] = 0, ["param1"] = 31, ["z"] = 1, ["name"] = "lottother:dirt" },
{["x"] = 4, ["meta"] = { ["fields"] = {}, ["inventory"] = {} }, ["param2"] = 0, ["y"] = 0, ["param1"] = 13, ["z"] = 2, ["name"] = "lottother:dirt" },
{["x"] = 4, ["meta"] = { ["fields"] = {}, ["inventory"] = {} }, ["param2"] = 0, ["y"] = 0, ["param1"] = 12, ["z"] = 3, ["name"] = "lottother:dirt" },
{["x"] = 4, ["meta"] = { ["fields"] = {}, ["inventory"] = {} }, ["param2"] = 0, ["y"] = 0, ["param1"] = 11, ["z"] = 4, ["name"] = "lottother:dirt" },
{["x"] = 4, ["meta"] = { ["fields"] = {}, ["inventory"] = {} }, ["param2"] = 0, ["y"] = 0, ["param1"] = 10, ["z"] = 5, ["name"] = "lottother:dirt" },
{["x"] = 4, ["meta"] = { ["fields"] = {}, ["inventory"] = {} }, ["param2"] = 0, ["y"] = 0, ["param1"] = 9, ["z"] = 6, ["name"] = "lottother:dirt" },
{["x"] = 4, ["meta"] = { ["fields"] = {}, ["inventory"] = {} }, ["param2"] = 0, ["y"] = 0, ["param1"] = 9, ["z"] = 7, ["name"] = "lottother:dirt" },
{["x"] = 4, ["meta"] = { ["fields"] = {}, ["inventory"] = {} }, ["param2"] = 0, ["y"] = 0, ["param1"] = 9, ["z"] = 8, ["name"] = "lottother:dirt" },
{["x"] = 4, ["meta"] = { ["fields"] = {}, ["inventory"] = {} }, ["param2"] = 0, ["y"] = 0, ["param1"] = 9, ["z"] = 9, ["name"] = "lottother:dirt" },
{["x"] = 4, ["meta"] = { ["fields"] = {}, ["inventory"] = {} }, ["param2"] = 0, ["y"] = 0, ["param1"] = 10, ["z"] = 10, ["name"] = "lottother:dirt" },
{["x"] = 4, ["meta"] = { ["fields"] = {}, ["inventory"] = {} }, ["param2"] = 0, ["y"] = 0, ["param1"] = 11, ["z"] = 11, ["name"] = "lottother:dirt" },
{["x"] = 4, ["meta"] = { ["fields"] = {}, ["inventory"] = {} }, ["param2"] = 0, ["y"] = 0, ["param1"] = 12, ["z"] = 12, ["name"] = "lottother:dirt" },
{["x"] = 4, ["meta"] = { ["fields"] = {}, ["inventory"] = {} }, ["param2"] = 0, ["y"] = 0, ["param1"] = 0, ["z"] = 13, ["name"] = "lottother:dirt" },
{["x"] = 4, ["meta"] = { ["fields"] = {}, ["inventory"] = {} }, ["param2"] = 0, ["y"] = 1, ["param1"] = 0, ["z"] = 0, ["name"] = "lord_ground:dirt_mirkwood" },
{["x"] = 4, ["meta"] = { ["fields"] = {}, ["inventory"] = {} }, ["param2"] = 0, ["y"] = 1, ["param1"] = 47, ["z"] = 1, ["name"] = "lottother:dirt" },
{["x"] = 4, ["meta"] = { ["fields"] = {}, ["inventory"] = {} }, ["param2"] = 0, ["y"] = 1, ["param1"] = 29, ["z"] = 2, ["name"] = "lottother:dirt" },
{["x"] = 4, ["meta"] = { ["fields"] = {}, ["inventory"] = {} }, ["param2"] = 0, ["y"] = 1, ["param1"] = 12, ["z"] = 3, ["name"] = "lottother:dirt" },
{["x"] = 4, ["meta"] = { ["fields"] = {}, ["inventory"] = {} }, ["param2"] = 0, ["y"] = 1, ["param1"] = 11, ["z"] = 4, ["name"] = "lottother:dirt" },
{["x"] = 4, ["meta"] = { ["fields"] = {}, ["inventory"] = {} }, ["param2"] = 0, ["y"] = 1, ["param1"] = 10, ["z"] = 5, ["name"] = "lottother:dirt" },
{["x"] = 4, ["meta"] = { ["fields"] = {}, ["inventory"] = {} }, ["param2"] = 0, ["y"] = 1, ["param1"] = 9, ["z"] = 6, ["name"] = "lottother:dirt" },
{["x"] = 4, ["meta"] = { ["fields"] = {}, ["inventory"] = {} }, ["param2"] = 0, ["y"] = 1, ["param1"] = 9, ["z"] = 7, ["name"] = "lottother:dirt" },
{["x"] = 4, ["meta"] = { ["fields"] = {}, ["inventory"] = {} }, ["param2"] = 0, ["y"] = 1, ["param1"] = 9, ["z"] = 8, ["name"] = "lottother:dirt" },
{["x"] = 4, ["meta"] = { ["fields"] = {}, ["inventory"] = {} }, ["param2"] = 0, ["y"] = 1, ["param1"] = 9, ["z"] = 9, ["name"] = "lottother:dirt" },
{["x"] = 4, ["meta"] = { ["fields"] = {}, ["inventory"] = {} }, ["param2"] = 0, ["y"] = 1, ["param1"] = 10, ["z"] = 10, ["name"] = "lottother:dirt" },
{["x"] = 4, ["meta"] = { ["fields"] = {}, ["inventory"] = {} }, ["param2"] = 0, ["y"] = 1, ["param1"] = 11, ["z"] = 11, ["name"] = "lottother:dirt" },
{["x"] = 4, ["meta"] = { ["fields"] = {}, ["inventory"] = {} }, ["param2"] = 0, ["y"] = 1, ["param1"] = 12, ["z"] = 12, ["name"] = "lottother:dirt" },
{["x"] = 4, ["meta"] = { ["fields"] = {}, ["inventory"] = {} }, ["param2"] = 0, ["y"] = 1, ["param1"] = 0, ["z"] = 13, ["name"] = "lord_ground:dirt_mirkwood" },
{["x"] = 4, ["meta"] = { ["fields"] = {}, ["inventory"] = {} }, ["param2"] = 0, ["y"] = 2, ["param1"] = 0, ["z"] = 1, ["name"] = "lord_ground:dirt_mirkwood" },
{["x"] = 4, ["meta"] = { ["fields"] = {}, ["inventory"] = {} }, ["param2"] = 0, ["y"] = 2, ["param1"] = 45, ["z"] = 2, ["name"] = "lottother:dirt" },
{["x"] = 4, ["meta"] = { ["fields"] = {}, ["inventory"] = {} }, ["param2"] = 0, ["y"] = 2, ["param1"] = 28, ["z"] = 3, ["name"] = "lottother:dirt" },
{["x"] = 4, ["meta"] = { ["fields"] = {}, ["inventory"] = {} }, ["param2"] = 0, ["y"] = 2, ["param1"] = 11, ["z"] = 4, ["name"] = "lottother:dirt" },
{["x"] = 4, ["meta"] = { ["fields"] = {}, ["inventory"] = {} }, ["param2"] = 0, ["y"] = 2, ["param1"] = 10, ["z"] = 5, ["name"] = "lottother:dirt" },
{["x"] = 4, ["meta"] = { ["fields"] = {}, ["inventory"] = {} }, ["param2"] = 0, ["y"] = 2, ["param1"] = 9, ["z"] = 6, ["name"] = "lottother:dirt" },
{["x"] = 4, ["meta"] = { ["fields"] = {}, ["inventory"] = {} }, ["param2"] = 0, ["y"] = 2, ["param1"] = 9, ["z"] = 7, ["name"] = "lottother:dirt" },
{["x"] = 4, ["meta"] = { ["fields"] = {}, ["inventory"] = {} }, ["param2"] = 0, ["y"] = 2, ["param1"] = 9, ["z"] = 8, ["name"] = "lottother:dirt" },
{["x"] = 4, ["meta"] = { ["fields"] = {}, ["inventory"] = {} }, ["param2"] = 0, ["y"] = 2, ["param1"] = 9, ["z"] = 9, ["name"] = "lottother:dirt" },
{["x"] = 4, ["meta"] = { ["fields"] = {}, ["inventory"] = {} }, ["param2"] = 0, ["y"] = 2, ["param1"] = 10, ["z"] = 10, ["name"] = "lottother:dirt" },
{["x"] = 4, ["meta"] = { ["fields"] = {}, ["inventory"] = {} }, ["param2"] = 0, ["y"] = 2, ["param1"] = 0, ["z"] = 11, ["name"] = "lord_ground:dirt_mirkwood" },
{["x"] = 4, ["meta"] = { ["fields"] = {}, ["inventory"] = {} }, ["param2"] = 0, ["y"] = 2, ["param1"] = 0, ["z"] = 12, ["name"] = "lord_ground:dirt_mirkwood" },
{["x"] = 4, ["meta"] = { ["fields"] = {}, ["inventory"] = {} }, ["param2"] = 0, ["y"] = 3, ["param1"] = 0, ["z"] = 2, ["name"] = "default:junglewood" },
{["x"] = 4, ["meta"] = { ["fields"] = {}, ["inventory"] = {} }, ["param2"] = 0, ["y"] = 3, ["param1"] = 0, ["z"] = 3, ["name"] = "default:junglewood" },
{["x"] = 4, ["meta"] = { ["fields"] = {}, ["inventory"] = {} }, ["param2"] = 0, ["y"] = 3, ["param1"] = 0, ["z"] = 4, ["name"] = "default:junglewood" },
{["x"] = 4, ["meta"] = { ["fields"] = {}, ["inventory"] = {} }, ["param2"] = 0, ["y"] = 3, ["param1"] = 0, ["z"] = 5, ["name"] = "default:junglewood" },
{["x"] = 4, ["meta"] = { ["fields"] = {}, ["inventory"] = {} }, ["param2"] = 0, ["y"] = 3, ["param1"] = 0, ["z"] = 6, ["name"] = "default:tree" },
{["x"] = 4, ["meta"] = { ["fields"] = {}, ["inventory"] = {} }, ["param2"] = 0, ["y"] = 3, ["param1"] = 0, ["z"] = 7, ["name"] = "default:tree" },
{["x"] = 4, ["meta"] = { ["fields"] = {}, ["inventory"] = {} }, ["param2"] = 0, ["y"] = 3, ["param1"] = 0, ["z"] = 8, ["name"] = "default:tree" },
{["x"] = 4, ["meta"] = { ["fields"] = {}, ["inventory"] = {} }, ["param2"] = 0, ["y"] = 3, ["param1"] = 0, ["z"] = 9, ["name"] = "default:tree" },
{["x"] = 4, ["meta"] = { ["fields"] = {}, ["inventory"] = {} }, ["param2"] = 0, ["y"] = 3, ["param1"] = 0, ["z"] = 10, ["name"] = "default:tree" },
{["x"] = 4, ["meta"] = { ["fields"] = {}, ["inventory"] = {} }, ["param2"] = 0, ["y"] = 4, ["param1"] = 109, ["z"] = 2, ["name"] = "lottother:air" },
{["x"] = 4, ["meta"] = { ["fields"] = {}, ["inventory"] = {} }, ["param2"] = 0, ["y"] = 4, ["param1"] = 0, ["z"] = 3, ["name"] = "default:junglewood" },
{["x"] = 4, ["meta"] = { ["fields"] = {}, ["inventory"] = {} }, ["param2"] = 0, ["y"] = 4, ["param1"] = 137, ["z"] = 4, ["name"] = "lottother:air" },
{["x"] = 4, ["meta"] = { ["fields"] = {}, ["inventory"] = {} }, ["param2"] = 0, ["y"] = 4, ["param1"] = 0, ["z"] = 5, ["name"] = "lottmapgen:elfmirk_chest_spawner" },
{["x"] = 4, ["meta"] = { ["fields"] = {}, ["inventory"] = {} }, ["param2"] = 0, ["y"] = 4, ["param1"] = 0, ["z"] = 6, ["name"] = "default:tree" },
{["x"] = 4, ["meta"] = { ["fields"] = {}, ["inventory"] = {} }, ["param2"] = 0, ["y"] = 4, ["param1"] = 0, ["z"] = 7, ["name"] = "default:tree" },
{["x"] = 4, ["meta"] = { ["fields"] = {}, ["inventory"] = {} }, ["param2"] = 0, ["y"] = 4, ["param1"] = 0, ["z"] = 8, ["name"] = "default:tree" },
{["x"] = 4, ["meta"] = { ["fields"] = {}, ["inventory"] = {} }, ["param2"] = 0, ["y"] = 4, ["param1"] = 0, ["z"] = 9, ["name"] = "default:tree" },
{["x"] = 4, ["meta"] = { ["fields"] = {}, ["inventory"] = {} }, ["param2"] = 0, ["y"] = 4, ["param1"] = 0, ["z"] = 10, ["name"] = "default:tree" },
{["x"] = 4, ["meta"] = { ["fields"] = {}, ["inventory"] = {} }, ["param2"] = 0, ["y"] = 5, ["param1"] = 125, ["z"] = 2, ["name"] = "lottother:air" },
{["x"] = 4, ["meta"] = { ["fields"] = {}, ["inventory"] = {} }, ["param2"] = 0, ["y"] = 5, ["param1"] = 0, ["z"] = 3, ["name"] = "default:junglewood" },
{["x"] = 4, ["meta"] = { ["fields"] = {}, ["inventory"] = {} }, ["param2"] = 0, ["y"] = 5, ["param1"] = 153, ["z"] = 4, ["name"] = "lottother:air" },
{["x"] = 4, ["param2"] = 3, ["y"] = 5, ["param1"] = 0, ["z"] = 5, ["name"] = "default:furnace" },
{["x"] = 4, ["meta"] = { ["fields"] = {}, ["inventory"] = {} }, ["param2"] = 0, ["y"] = 5, ["param1"] = 0, ["z"] = 6, ["name"] = "default:tree" },
{["x"] = 4, ["meta"] = { ["fields"] = {}, ["inventory"] = {} }, ["param2"] = 0, ["y"] = 5, ["param1"] = 0, ["z"] = 7, ["name"] = "default:tree" },
{["x"] = 4, ["meta"] = { ["fields"] = {}, ["inventory"] = {} }, ["param2"] = 0, ["y"] = 5, ["param1"] = 0, ["z"] = 8, ["name"] = "default:tree" },
{["x"] = 4, ["meta"] = { ["fields"] = {}, ["inventory"] = {} }, ["param2"] = 0, ["y"] = 5, ["param1"] = 0, ["z"] = 9, ["name"] = "default:tree" },
{["x"] = 4, ["meta"] = { ["fields"] = {}, ["inventory"] = {} }, ["param2"] = 0, ["y"] = 5, ["param1"] = 0, ["z"] = 10, ["name"] = "default:tree" },
{["x"] = 4, ["meta"] = { ["fields"] = {}, ["inventory"] = {} }, ["param2"] = 0, ["y"] = 6, ["param1"] = 109, ["z"] = 2, ["name"] = "lottother:air" },
{["x"] = 4, ["meta"] = { ["fields"] = {}, ["inventory"] = {} }, ["param2"] = 0, ["y"] = 6, ["param1"] = 0, ["z"] = 3, ["name"] = "default:junglewood" },
{["x"] = 4, ["meta"] = { ["fields"] = {}, ["inventory"] = {} }, ["param2"] = 0, ["y"] = 6, ["param1"] = 170, ["z"] = 4, ["name"] = "lottother:air" },
{["x"] = 4, ["meta"] = { ["fields"] = {}, ["inventory"] = {} }, ["param2"] = 0, ["y"] = 6, ["param1"] = 187, ["z"] = 5, ["name"] = "lottother:air" },
{["x"] = 4, ["meta"] = { ["fields"] = {}, ["inventory"] = {} }, ["param2"] = 0, ["y"] = 6, ["param1"] = 0, ["z"] = 6, ["name"] = "default:tree" },
{["x"] = 4, ["meta"] = { ["fields"] = {}, ["inventory"] = {} }, ["param2"] = 0, ["y"] = 6, ["param1"] = 0, ["z"] = 7, ["name"] = "default:tree" },
{["x"] = 4, ["meta"] = { ["fields"] = {}, ["inventory"] = {} }, ["param2"] = 0, ["y"] = 6, ["param1"] = 0, ["z"] = 8, ["name"] = "default:tree" },
{["x"] = 4, ["meta"] = { ["fields"] = {}, ["inventory"] = {} }, ["param2"] = 0, ["y"] = 6, ["param1"] = 0, ["z"] = 9, ["name"] = "default:tree" },
{["x"] = 4, ["meta"] = { ["fields"] = {}, ["inventory"] = {} }, ["param2"] = 0, ["y"] = 6, ["param1"] = 0, ["z"] = 10, ["name"] = "default:tree" },
{["x"] = 4, ["meta"] = { ["fields"] = {}, ["inventory"] = {} }, ["param2"] = 0, ["y"] = 7, ["param1"] = 93, ["z"] = 2, ["name"] = "stairs:stair_junglewood" },
{["x"] = 4, ["meta"] = { ["fields"] = {}, ["inventory"] = {} }, ["param2"] = 0, ["y"] = 7, ["param1"] = 0, ["z"] = 3, ["name"] = "default:junglewood" },
{["x"] = 4, ["meta"] = { ["fields"] = {}, ["inventory"] = {} }, ["param2"] = 0, ["y"] = 7, ["param1"] = 0, ["z"] = 4, ["name"] = "default:junglewood" },
{["x"] = 4, ["meta"] = { ["fields"] = {}, ["inventory"] = {} }, ["param2"] = 0, ["y"] = 7, ["param1"] = 0, ["z"] = 5, ["name"] = "default:junglewood" },
{["x"] = 4, ["meta"] = { ["fields"] = {}, ["inventory"] = {} }, ["param2"] = 0, ["y"] = 7, ["param1"] = 0, ["z"] = 6, ["name"] = "default:tree" },
{["x"] = 4, ["meta"] = { ["fields"] = {}, ["inventory"] = {} }, ["param2"] = 0, ["y"] = 7, ["param1"] = 0, ["z"] = 7, ["name"] = "default:tree" },
{["x"] = 4, ["meta"] = { ["fields"] = {}, ["inventory"] = {} }, ["param2"] = 0, ["y"] = 7, ["param1"] = 0, ["z"] = 8, ["name"] = "default:tree" },
{["x"] = 4, ["meta"] = { ["fields"] = {}, ["inventory"] = {} }, ["param2"] = 0, ["y"] = 7, ["param1"] = 0, ["z"] = 9, ["name"] = "default:tree" },
{["x"] = 4, ["meta"] = { ["fields"] = {}, ["inventory"] = {} }, ["param2"] = 0, ["y"] = 7, ["param1"] = 0, ["z"] = 10, ["name"] = "default:tree" },
{["x"] = 4, ["meta"] = { ["fields"] = {}, ["inventory"] = {} }, ["param2"] = 0, ["y"] = 8, ["param1"] = 60, ["z"] = 3, ["name"] = "stairs:stair_junglewood" },
{["x"] = 4, ["meta"] = { ["fields"] = {}, ["inventory"] = {} }, ["param2"] = 0, ["y"] = 8, ["param1"] = 0, ["z"] = 4, ["name"] = "default:junglewood" },
{["x"] = 4, ["meta"] = { ["fields"] = {}, ["inventory"] = {} }, ["param2"] = 0, ["y"] = 8, ["param1"] = 0, ["z"] = 5, ["name"] = "default:junglewood" },
{["x"] = 4, ["meta"] = { ["fields"] = {}, ["inventory"] = {} }, ["param2"] = 0, ["y"] = 8, ["param1"] = 0, ["z"] = 6, ["name"] = "default:tree" },
{["x"] = 4, ["meta"] = { ["fields"] = {}, ["inventory"] = {} }, ["param2"] = 0, ["y"] = 8, ["param1"] = 0, ["z"] = 7, ["name"] = "default:tree" },
{["x"] = 4, ["meta"] = { ["fields"] = {}, ["inventory"] = {} }, ["param2"] = 0, ["y"] = 8, ["param1"] = 0, ["z"] = 8, ["name"] = "default:tree" },
{["x"] = 4, ["meta"] = { ["fields"] = {}, ["inventory"] = {} }, ["param2"] = 0, ["y"] = 8, ["param1"] = 0, ["z"] = 9, ["name"] = "default:tree" },
{["x"] = 4, ["meta"] = { ["fields"] = {}, ["inventory"] = {} }, ["param2"] = 0, ["y"] = 8, ["param1"] = 0, ["z"] = 10, ["name"] = "default:tree" },
{["x"] = 4, ["meta"] = { ["fields"] = {}, ["inventory"] = {} }, ["param2"] = 1, ["y"] = 9, ["param1"] = 10, ["z"] = 5, ["name"] = "stairs:stair_junglewood" },
{["x"] = 4, ["meta"] = { ["fields"] = {}, ["inventory"] = {} }, ["param2"] = 0, ["y"] = 9, ["param1"] = 0, ["z"] = 6, ["name"] = "default:tree" },
{["x"] = 4, ["meta"] = { ["fields"] = {}, ["inventory"] = {} }, ["param2"] = 3, ["y"] = 9, ["param1"] = 0, ["z"] = 7, ["name"] = "lottpotion:cauldron_full" },
{["x"] = 4, ["param2"] = 0, ["y"] = 9, ["param1"] = 187, ["z"] = 8, ["name"] = "lottpotion:potion_brewer" },
{["x"] = 4, ["meta"] = { ["fields"] = {}, ["inventory"] = {} }, ["param2"] = 0, ["y"] = 9, ["param1"] = 0, ["z"] = 9, ["name"] = "lottmapgen:elfmirk_chest_spawner" },
{["x"] = 4, ["meta"] = { ["fields"] = {}, ["inventory"] = {} }, ["param2"] = 0, ["y"] = 9, ["param1"] = 0, ["z"] = 10, ["name"] = "default:tree" },
{["x"] = 4, ["meta"] = { ["fields"] = {}, ["inventory"] = {} }, ["param2"] = 0, ["y"] = 10, ["param1"] = 0, ["z"] = 6, ["name"] = "default:tree" },
{["x"] = 4, ["meta"] = { ["fields"] = {}, ["inventory"] = {} }, ["param2"] = 5, ["y"] = 10, ["param1"] = 0, ["z"] = 7, ["name"] = "lottother:blue_torch" },
{["x"] = 4, ["meta"] = { ["fields"] = {}, ["inventory"] = {} }, ["param2"] = 0, ["y"] = 10, ["param1"] = 204, ["z"] = 8, ["name"] = "lottother:air" },
{["x"] = 4, ["meta"] = { ["fields"] = {}, ["inventory"] = {} }, ["param2"] = 0, ["y"] = 10, ["param1"] = 187, ["z"] = 9, ["name"] = "lottother:air" },
{["x"] = 4, ["meta"] = { ["fields"] = {}, ["inventory"] = {} }, ["param2"] = 0, ["y"] = 10, ["param1"] = 0, ["z"] = 10, ["name"] = "default:tree" },
{["x"] = 4, ["meta"] = { ["fields"] = {}, ["inventory"] = {} }, ["param2"] = 0, ["y"] = 11, ["param1"] = 0, ["z"] = 6, ["name"] = "default:tree" },
{["x"] = 4, ["meta"] = { ["fields"] = {}, ["inventory"] = {} }, ["param2"] = 0, ["y"] = 11, ["param1"] = 204, ["z"] = 7, ["name"] = "lottother:air" },
{["x"] = 4, ["meta"] = { ["fields"] = {}, ["inventory"] = {} }, ["param2"] = 0, ["y"] = 11, ["param1"] = 187, ["z"] = 8, ["name"] = "lottother:air" },
{["x"] = 4, ["meta"] = { ["fields"] = {}, ["inventory"] = {} }, ["param2"] = 0, ["y"] = 11, ["param1"] = 0, ["z"] = 9, ["name"] = "default:tree" },
{["x"] = 4, ["meta"] = { ["fields"] = {}, ["inventory"] = {} }, ["param2"] = 0, ["y"] = 11, ["param1"] = 0, ["z"] = 10, ["name"] = "default:tree" },
{["x"] = 4, ["meta"] = { ["fields"] = {}, ["inventory"] = {} }, ["param2"] = 0, ["y"] = 12, ["param1"] = 0, ["z"] = 6, ["name"] = "default:tree" },
{["x"] = 4, ["meta"] = { ["fields"] = {}, ["inventory"] = {} }, ["param2"] = 0, ["y"] = 12, ["param1"] = 0, ["z"] = 7, ["name"] = "default:tree" },
{["x"] = 4, ["meta"] = { ["fields"] = {}, ["inventory"] = {} }, ["param2"] = 0, ["y"] = 12, ["param1"] = 0, ["z"] = 8, ["name"] = "default:tree" },
{["x"] = 4, ["meta"] = { ["fields"] = {}, ["inventory"] = {} }, ["param2"] = 0, ["y"] = 12, ["param1"] = 0, ["z"] = 9, ["name"] = "default:tree" },
{["x"] = 4, ["meta"] = { ["fields"] = {}, ["inventory"] = {} }, ["param2"] = 0, ["y"] = 12, ["param1"] = 0, ["z"] = 10, ["name"] = "default:tree" },
{["x"] = 4, ["meta"] = { ["fields"] = {}, ["inventory"] = {} }, ["param2"] = 0, ["y"] = 13, ["param1"] = 0, ["z"] = 6, ["name"] = "default:tree" },
{["x"] = 4, ["meta"] = { ["fields"] = {}, ["inventory"] = {} }, ["param2"] = 0, ["y"] = 13, ["param1"] = 0, ["z"] = 7, ["name"] = "default:tree" },
{["x"] = 4, ["meta"] = { ["fields"] = {}, ["inventory"] = {} }, ["param2"] = 0, ["y"] = 13, ["param1"] = 0, ["z"] = 8, ["name"] = "default:tree" },
{["x"] = 4, ["meta"] = { ["fields"] = {}, ["inventory"] = {} }, ["param2"] = 0, ["y"] = 13, ["param1"] = 0, ["z"] = 9, ["name"] = "default:tree" },
{["x"] = 4, ["meta"] = { ["fields"] = {}, ["inventory"] = {} }, ["param2"] = 0, ["y"] = 13, ["param1"] = 0, ["z"] = 10, ["name"] = "default:tree" },
{["x"] = 4, ["meta"] = { ["fields"] = {}, ["inventory"] = {} }, ["param2"] = 0, ["y"] = 14, ["param1"] = 0, ["z"] = 6, ["name"] = "default:tree" },
{["x"] = 4, ["meta"] = { ["fields"] = {}, ["inventory"] = {} }, ["param2"] = 0, ["y"] = 14, ["param1"] = 0, ["z"] = 7, ["name"] = "default:tree" },
{["x"] = 4, ["meta"] = { ["fields"] = {}, ["inventory"] = {} }, ["param2"] = 0, ["y"] = 14, ["param1"] = 0, ["z"] = 8, ["name"] = "default:tree" },
{["x"] = 4, ["meta"] = { ["fields"] = {}, ["inventory"] = {} }, ["param2"] = 0, ["y"] = 14, ["param1"] = 0, ["z"] = 9, ["name"] = "default:tree" },
{["x"] = 4, ["meta"] = { ["fields"] = {}, ["inventory"] = {} }, ["param2"] = 0, ["y"] = 14, ["param1"] = 0, ["z"] = 10, ["name"] = "default:tree" },
{["x"] = 4, ["meta"] = { ["fields"] = {}, ["inventory"] = {} }, ["param2"] = 0, ["y"] = 15, ["param1"] = 0, ["z"] = 6, ["name"] = "default:tree" },
{["x"] = 4, ["meta"] = { ["fields"] = {}, ["inventory"] = {} }, ["param2"] = 0, ["y"] = 15, ["param1"] = 0, ["z"] = 7, ["name"] = "default:tree" },
{["x"] = 4, ["meta"] = { ["fields"] = {}, ["inventory"] = {} }, ["param2"] = 0, ["y"] = 15, ["param1"] = 0, ["z"] = 8, ["name"] = "default:tree" },
{["x"] = 4, ["meta"] = { ["fields"] = {}, ["inventory"] = {} }, ["param2"] = 0, ["y"] = 15, ["param1"] = 0, ["z"] = 9, ["name"] = "default:tree" },
{["x"] = 4, ["meta"] = { ["fields"] = {}, ["inventory"] = {} }, ["param2"] = 0, ["y"] = 15, ["param1"] = 0, ["z"] = 10, ["name"] = "default:tree" },
{["x"] = 4, ["meta"] = { ["fields"] = {}, ["inventory"] = {} }, ["param2"] = 0, ["y"] = 16, ["param1"] = 42, ["z"] = 5, ["name"] = "lord_trees:mirk_leaf" },
{["x"] = 4, ["meta"] = { ["fields"] = {}, ["inventory"] = {} }, ["param2"] = 0, ["y"] = 16, ["param1"] = 0, ["z"] = 6, ["name"] = "default:tree" },
{["x"] = 4, ["meta"] = { ["fields"] = {}, ["inventory"] = {} }, ["param2"] = 0, ["y"] = 16, ["param1"] = 0, ["z"] = 7, ["name"] = "default:tree" },
{["x"] = 4, ["meta"] = { ["fields"] = {}, ["inventory"] = {} }, ["param2"] = 0, ["y"] = 16, ["param1"] = 0, ["z"] = 8, ["name"] = "default:tree" },
{["x"] = 4, ["meta"] = { ["fields"] = {}, ["inventory"] = {} }, ["param2"] = 3, ["y"] = 16, ["param1"] = 0, ["z"] = 9, ["name"] = "default:tree" },
{["x"] = 4, ["meta"] = { ["fields"] = {}, ["inventory"] = {} }, ["param2"] = 0, ["y"] = 16, ["param1"] = 0, ["z"] = 10, ["name"] = "default:tree" },
{["x"] = 4, ["meta"] = { ["fields"] = {}, ["inventory"] = {} }, ["param2"] = 0, ["y"] = 16, ["param1"] = 139, ["z"] = 11, ["name"] = "lord_trees:mirk_leaf" },
{["x"] = 4, ["meta"] = { ["fields"] = {}, ["inventory"] = {} }, ["param2"] = 0, ["y"] = 16, ["param1"] = 124, ["z"] = 12, ["name"] = "lord_trees:mirk_leaf" },
{["x"] = 4, ["meta"] = { ["fields"] = {}, ["inventory"] = {} }, ["param2"] = 0, ["y"] = 17, ["param1"] = 43, ["z"] = 4, ["name"] = "lord_trees:mirk_leaf" },
{["x"] = 4, ["meta"] = { ["fields"] = {}, ["inventory"] = {} }, ["param2"] = 0, ["y"] = 17, ["param1"] = 26, ["z"] = 5, ["name"] = "lord_trees:mirk_leaf" },
{["x"] = 4, ["meta"] = { ["fields"] = {}, ["inventory"] = {} }, ["param2"] = 0, ["y"] = 17, ["param1"] = 0, ["z"] = 6, ["name"] = "default:tree" },
{["x"] = 4, ["meta"] = { ["fields"] = {}, ["inventory"] = {} }, ["param2"] = 0, ["y"] = 17, ["param1"] = 0, ["z"] = 7, ["name"] = "default:tree" },
{["x"] = 4, ["meta"] = { ["fields"] = {}, ["inventory"] = {} }, ["param2"] = 0, ["y"] = 17, ["param1"] = 0, ["z"] = 8, ["name"] = "default:tree" },
{["x"] = 4, ["meta"] = { ["fields"] = {}, ["inventory"] = {} }, ["param2"] = 3, ["y"] = 17, ["param1"] = 0, ["z"] = 9, ["name"] = "default:tree" },
{["x"] = 4, ["meta"] = { ["fields"] = {}, ["inventory"] = {} }, ["param2"] = 0, ["y"] = 17, ["param1"] = 0, ["z"] = 10, ["name"] = "default:tree" },
{["x"] = 4, ["meta"] = { ["fields"] = {}, ["inventory"] = {} }, ["param2"] = 0, ["y"] = 17, ["param1"] = 123, ["z"] = 11, ["name"] = "lord_trees:mirk_leaf" },
{["x"] = 4, ["meta"] = { ["fields"] = {}, ["inventory"] = {} }, ["param2"] = 0, ["y"] = 18, ["param1"] = 0, ["z"] = 6, ["name"] = "default:tree" },
{["x"] = 4, ["meta"] = { ["fields"] = {}, ["inventory"] = {} }, ["param2"] = 0, ["y"] = 18, ["param1"] = 0, ["z"] = 7, ["name"] = "default:tree" },
{["x"] = 4, ["meta"] = { ["fields"] = {}, ["inventory"] = {} }, ["param2"] = 0, ["y"] = 18, ["param1"] = 0, ["z"] = 8, ["name"] = "default:tree" },
{["x"] = 4, ["meta"] = { ["fields"] = {}, ["inventory"] = {} }, ["param2"] = 0, ["y"] = 18, ["param1"] = 0, ["z"] = 9, ["name"] = "default:tree" },
{["x"] = 4, ["meta"] = { ["fields"] = {}, ["inventory"] = {} }, ["param2"] = 0, ["y"] = 18, ["param1"] = 0, ["z"] = 10, ["name"] = "default:tree" },
{["x"] = 4, ["meta"] = { ["fields"] = {}, ["inventory"] = {} }, ["param2"] = 0, ["y"] = 19, ["param1"] = 10, ["z"] = 5, ["name"] = "lord_trees:mirk_leaf" },
{["x"] = 4, ["meta"] = { ["fields"] = {}, ["inventory"] = {} }, ["param2"] = 0, ["y"] = 19, ["param1"] = 0, ["z"] = 6, ["name"] = "default:tree" },
{["x"] = 4, ["meta"] = { ["fields"] = {}, ["inventory"] = {} }, ["param2"] = 0, ["y"] = 19, ["param1"] = 0, ["z"] = 7, ["name"] = "default:tree" },
{["x"] = 4, ["meta"] = { ["fields"] = {}, ["inventory"] = {} }, ["param2"] = 0, ["y"] = 19, ["param1"] = 0, ["z"] = 8, ["name"] = "default:tree" },
{["x"] = 4, ["meta"] = { ["fields"] = {}, ["inventory"] = {} }, ["param2"] = 0, ["y"] = 19, ["param1"] = 0, ["z"] = 9, ["name"] = "default:tree" },
{["x"] = 4, ["meta"] = { ["fields"] = {}, ["inventory"] = {} }, ["param2"] = 0, ["y"] = 19, ["param1"] = 0, ["z"] = 10, ["name"] = "default:tree" },
{["x"] = 4, ["meta"] = { ["fields"] = {}, ["inventory"] = {} }, ["param2"] = 0, ["y"] = 20, ["param1"] = 10, ["z"] = 5, ["name"] = "lord_trees:mirk_leaf" },
{["x"] = 4, ["meta"] = { ["fields"] = {}, ["inventory"] = {} }, ["param2"] = 0, ["y"] = 20, ["param1"] = 0, ["z"] = 6, ["name"] = "default:tree" },
{["x"] = 4, ["meta"] = { ["fields"] = {}, ["inventory"] = {} }, ["param2"] = 0, ["y"] = 20, ["param1"] = 0, ["z"] = 7, ["name"] = "default:tree" },
{["x"] = 4, ["meta"] = { ["fields"] = {}, ["inventory"] = {} }, ["param2"] = 0, ["y"] = 20, ["param1"] = 0, ["z"] = 8, ["name"] = "default:tree" },
{["x"] = 4, ["meta"] = { ["fields"] = {}, ["inventory"] = {} }, ["param2"] = 0, ["y"] = 20, ["param1"] = 0, ["z"] = 9, ["name"] = "default:tree" },
{["x"] = 4, ["meta"] = { ["fields"] = {}, ["inventory"] = {} }, ["param2"] = 0, ["y"] = 20, ["param1"] = 0, ["z"] = 10, ["name"] = "default:tree" },
{["x"] = 4, ["meta"] = { ["fields"] = {}, ["inventory"] = {} }, ["param2"] = 0, ["y"] = 20, ["param1"] = 75, ["z"] = 11, ["name"] = "lord_trees:mirk_leaf" },
{["x"] = 4, ["meta"] = { ["fields"] = {}, ["inventory"] = {} }, ["param2"] = 0, ["y"] = 21, ["param1"] = 11, ["z"] = 4, ["name"] = "lord_trees:mirk_leaf" },
{["x"] = 4, ["meta"] = { ["fields"] = {}, ["inventory"] = {} }, ["param2"] = 0, ["y"] = 21, ["param1"] = 10, ["z"] = 5, ["name"] = "lord_trees:mirk_leaf" },
{["x"] = 4, ["meta"] = { ["fields"] = {}, ["inventory"] = {} }, ["param2"] = 0, ["y"] = 21, ["param1"] = 0, ["z"] = 6, ["name"] = "default:tree" },
{["x"] = 4, ["meta"] = { ["fields"] = {}, ["inventory"] = {} }, ["param2"] = 0, ["y"] = 21, ["param1"] = 0, ["z"] = 7, ["name"] = "default:tree" },
{["x"] = 4, ["meta"] = { ["fields"] = {}, ["inventory"] = {} }, ["param2"] = 0, ["y"] = 21, ["param1"] = 0, ["z"] = 8, ["name"] = "default:tree" },
{["x"] = 4, ["meta"] = { ["fields"] = {}, ["inventory"] = {} }, ["param2"] = 0, ["y"] = 21, ["param1"] = 0, ["z"] = 9, ["name"] = "default:tree" },
{["x"] = 4, ["meta"] = { ["fields"] = {}, ["inventory"] = {} }, ["param2"] = 0, ["y"] = 21, ["param1"] = 0, ["z"] = 10, ["name"] = "default:tree" },
{["x"] = 4, ["meta"] = { ["fields"] = {}, ["inventory"] = {} }, ["param2"] = 0, ["y"] = 21, ["param1"] = 59, ["z"] = 11, ["name"] = "lord_trees:mirk_leaf" },
{["x"] = 4, ["meta"] = { ["fields"] = {}, ["inventory"] = {} }, ["param2"] = 0, ["y"] = 21, ["param1"] = 76, ["z"] = 12, ["name"] = "lord_trees:mirk_leaf" },
{["x"] = 4, ["meta"] = { ["fields"] = {}, ["inventory"] = {} }, ["param2"] = 0, ["y"] = 22, ["param1"] = 13, ["z"] = 2, ["name"] = "lord_trees:mirk_leaf" },
{["x"] = 4, ["meta"] = { ["fields"] = {}, ["inventory"] = {} }, ["param2"] = 0, ["y"] = 22, ["param1"] = 12, ["z"] = 3, ["name"] = "lord_trees:mirk_leaf" },
{["x"] = 4, ["meta"] = { ["fields"] = {}, ["inventory"] = {} }, ["param2"] = 0, ["y"] = 22, ["param1"] = 11, ["z"] = 4, ["name"] = "lord_trees:mirk_leaf" },
{["x"] = 4, ["meta"] = { ["fields"] = {}, ["inventory"] = {} }, ["param2"] = 0, ["y"] = 22, ["param1"] = 10, ["z"] = 5, ["name"] = "lord_trees:mirk_leaf" },
{["x"] = 4, ["meta"] = { ["fields"] = {}, ["inventory"] = {} }, ["param2"] = 0, ["y"] = 22, ["param1"] = 0, ["z"] = 6, ["name"] = "default:tree" },
{["x"] = 4, ["meta"] = { ["fields"] = {}, ["inventory"] = {} }, ["param2"] = 0, ["y"] = 22, ["param1"] = 0, ["z"] = 7, ["name"] = "default:tree" },
{["x"] = 4, ["meta"] = { ["fields"] = {}, ["inventory"] = {} }, ["param2"] = 0, ["y"] = 22, ["param1"] = 0, ["z"] = 8, ["name"] = "default:tree" },
{["x"] = 4, ["meta"] = { ["fields"] = {}, ["inventory"] = {} }, ["param2"] = 0, ["y"] = 22, ["param1"] = 0, ["z"] = 9, ["name"] = "default:tree" },
{["x"] = 4, ["meta"] = { ["fields"] = {}, ["inventory"] = {} }, ["param2"] = 0, ["y"] = 22, ["param1"] = 0, ["z"] = 10, ["name"] = "default:tree" },
{["x"] = 4, ["meta"] = { ["fields"] = {}, ["inventory"] = {} }, ["param2"] = 0, ["y"] = 22, ["param1"] = 0, ["z"] = 11, ["name"] = "default:tree" },
{["x"] = 4, ["meta"] = { ["fields"] = {}, ["inventory"] = {} }, ["param2"] = 0, ["y"] = 22, ["param1"] = 60, ["z"] = 12, ["name"] = "lord_trees:mirk_leaf" },
{["x"] = 4, ["meta"] = { ["fields"] = {}, ["inventory"] = {} }, ["param2"] = 0, ["y"] = 22, ["param1"] = 77, ["z"] = 13, ["name"] = "lord_trees:mirk_leaf" },
{["x"] = 4, ["meta"] = { ["fields"] = {}, ["inventory"] = {} }, ["param2"] = 0, ["y"] = 22, ["param1"] = 61, ["z"] = 14, ["name"] = "lord_trees:mirk_leaf" },
{["x"] = 4, ["meta"] = { ["fields"] = {}, ["inventory"] = {} }, ["param2"] = 0, ["y"] = 23, ["param1"] = 13, ["z"] = 3, ["name"] = "lord_trees:mirk_leaf" },
{["x"] = 4, ["meta"] = { ["fields"] = {}, ["inventory"] = {} }, ["param2"] = 0, ["y"] = 23, ["param1"] = 12, ["z"] = 4, ["name"] = "lord_trees:mirk_leaf" },
{["x"] = 4, ["meta"] = { ["fields"] = {}, ["inventory"] = {} }, ["param2"] = 0, ["y"] = 23, ["param1"] = 11, ["z"] = 5, ["name"] = "lord_trees:mirk_leaf" },
{["x"] = 4, ["meta"] = { ["fields"] = {}, ["inventory"] = {} }, ["param2"] = 0, ["y"] = 23, ["param1"] = 10, ["z"] = 6, ["name"] = "lord_trees:mirk_leaf" },
{["x"] = 4, ["meta"] = { ["fields"] = {}, ["inventory"] = {} }, ["param2"] = 0, ["y"] = 23, ["param1"] = 0, ["z"] = 7, ["name"] = "default:tree" },
{["x"] = 4, ["meta"] = { ["fields"] = {}, ["inventory"] = {} }, ["param2"] = 0, ["y"] = 23, ["param1"] = 0, ["z"] = 8, ["name"] = "default:tree" },
{["x"] = 4, ["meta"] = { ["fields"] = {}, ["inventory"] = {} }, ["param2"] = 0, ["y"] = 23, ["param1"] = 9, ["z"] = 9, ["name"] = "lord_trees:mirk_leaf" },
{["x"] = 4, ["meta"] = { ["fields"] = {}, ["inventory"] = {} }, ["param2"] = 0, ["y"] = 23, ["param1"] = 10, ["z"] = 10, ["name"] = "lord_trees:mirk_leaf" },
{["x"] = 4, ["meta"] = { ["fields"] = {}, ["inventory"] = {} }, ["param2"] = 0, ["y"] = 23, ["param1"] = 27, ["z"] = 11, ["name"] = "lord_trees:mirk_leaf" },
{["x"] = 4, ["meta"] = { ["fields"] = {}, ["inventory"] = {} }, ["param2"] = 0, ["y"] = 23, ["param1"] = 44, ["z"] = 12, ["name"] = "lord_trees:mirk_leaf" },
{["x"] = 4, ["meta"] = { ["fields"] = {}, ["inventory"] = {} }, ["param2"] = 0, ["y"] = 23, ["param1"] = 61, ["z"] = 13, ["name"] = "lord_trees:mirk_leaf" },
{["x"] = 4, ["meta"] = { ["fields"] = {}, ["inventory"] = {} }, ["param2"] = 0, ["y"] = 24, ["param1"] = 12, ["z"] = 5, ["name"] = "lord_trees:mirk_leaf" },
{["x"] = 4, ["meta"] = { ["fields"] = {}, ["inventory"] = {} }, ["param2"] = 0, ["y"] = 24, ["param1"] = 11, ["z"] = 6, ["name"] = "lord_trees:mirk_leaf" },
{["x"] = 4, ["meta"] = { ["fields"] = {}, ["inventory"] = {} }, ["param2"] = 0, ["y"] = 24, ["param1"] = 0, ["z"] = 7, ["name"] = "default:tree" },
{["x"] = 4, ["meta"] = { ["fields"] = {}, ["inventory"] = {} }, ["param2"] = 0, ["y"] = 24, ["param1"] = 0, ["z"] = 8, ["name"] = "default:tree" },
{["x"] = 4, ["meta"] = { ["fields"] = {}, ["inventory"] = {} }, ["param2"] = 0, ["y"] = 25, ["param1"] = 13, ["z"] = 4, ["name"] = "lord_trees:mirk_leaf" },
{["x"] = 4, ["meta"] = { ["fields"] = {}, ["inventory"] = {} }, ["param2"] = 0, ["y"] = 25, ["param1"] = 0, ["z"] = 5, ["name"] = "default:tree" },
{["x"] = 4, ["meta"] = { ["fields"] = {}, ["inventory"] = {} }, ["param2"] = 0, ["y"] = 25, ["param1"] = 0, ["z"] = 6, ["name"] = "default:tree" },
{["x"] = 4, ["meta"] = { ["fields"] = {}, ["inventory"] = {} }, ["param2"] = 0, ["y"] = 25, ["param1"] = 0, ["z"] = 7, ["name"] = "default:tree" },
{["x"] = 4, ["meta"] = { ["fields"] = {}, ["inventory"] = {} }, ["param2"] = 0, ["y"] = 25, ["param1"] = 0, ["z"] = 8, ["name"] = "default:tree" },
{["x"] = 4, ["meta"] = { ["fields"] = {}, ["inventory"] = {} }, ["param2"] = 0, ["y"] = 25, ["param1"] = 0, ["z"] = 9, ["name"] = "default:tree" },
{["x"] = 4, ["meta"] = { ["fields"] = {}, ["inventory"] = {} }, ["param2"] = 0, ["y"] = 25, ["param1"] = 12, ["z"] = 10, ["name"] = "lord_trees:mirk_leaf" },
{["x"] = 4, ["meta"] = { ["fields"] = {}, ["inventory"] = {} }, ["param2"] = 0, ["y"] = 25, ["param1"] = 12, ["z"] = 11, ["name"] = "lord_trees:mirk_leaf" },
{["x"] = 4, ["meta"] = { ["fields"] = {}, ["inventory"] = {} }, ["param2"] = 0, ["y"] = 25, ["param1"] = 13, ["z"] = 12, ["name"] = "lord_trees:mirk_leaf" },
{["x"] = 4, ["meta"] = { ["fields"] = {}, ["inventory"] = {} }, ["param2"] = 0, ["y"] = 26, ["param1"] = 13, ["z"] = 5, ["name"] = "lord_trees:mirk_leaf" },
{["x"] = 4, ["meta"] = { ["fields"] = {}, ["inventory"] = {} }, ["param2"] = 0, ["y"] = 26, ["param1"] = 13, ["z"] = 6, ["name"] = "lord_trees:mirk_leaf" },
{["x"] = 4, ["meta"] = { ["fields"] = {}, ["inventory"] = {} }, ["param2"] = 0, ["y"] = 26, ["param1"] = 13, ["z"] = 7, ["name"] = "lord_trees:mirk_leaf" },
{["x"] = 4, ["meta"] = { ["fields"] = {}, ["inventory"] = {} }, ["param2"] = 0, ["y"] = 26, ["param1"] = 13, ["z"] = 8, ["name"] = "lord_trees:mirk_leaf" },
{["x"] = 4, ["meta"] = { ["fields"] = {}, ["inventory"] = {} }, ["param2"] = 0, ["y"] = 26, ["param1"] = 13, ["z"] = 9, ["name"] = "lord_trees:mirk_leaf" },
{["x"] = 4, ["meta"] = { ["fields"] = {}, ["inventory"] = {} }, ["param2"] = 0, ["y"] = 26, ["param1"] = 13, ["z"] = 10, ["name"] = "lord_trees:mirk_leaf" },
{["x"] = 4, ["meta"] = { ["fields"] = {}, ["inventory"] = {} }, ["param2"] = 0, ["y"] = 26, ["param1"] = 13, ["z"] = 11, ["name"] = "lord_trees:mirk_leaf" },
{["x"] = 5, ["meta"] = { ["fields"] = {}, ["inventory"] = {} }, ["param2"] = 0, ["y"] = 0, ["param1"] = 0, ["z"] = 0, ["name"] = "lottother:dirt" },
{["x"] = 5, ["meta"] = { ["fields"] = {}, ["inventory"] = {} }, ["param2"] = 0, ["y"] = 0, ["param1"] = 45, ["z"] = 1, ["name"] = "lottother:dirt" },
{["x"] = 5, ["meta"] = { ["fields"] = {}, ["inventory"] = {} }, ["param2"] = 0, ["y"] = 0, ["param1"] = 28, ["z"] = 2, ["name"] = "lottother:dirt" },
{["x"] = 5, ["meta"] = { ["fields"] = {}, ["inventory"] = {} }, ["param2"] = 0, ["y"] = 0, ["param1"] = 11, ["z"] = 3, ["name"] = "lottother:dirt" },
{["x"] = 5, ["meta"] = { ["fields"] = {}, ["inventory"] = {} }, ["param2"] = 0, ["y"] = 0, ["param1"] = 10, ["z"] = 4, ["name"] = "lottother:dirt" },
{["x"] = 5, ["meta"] = { ["fields"] = {}, ["inventory"] = {} }, ["param2"] = 0, ["y"] = 0, ["param1"] = 9, ["z"] = 5, ["name"] = "lottother:dirt" },
{["x"] = 5, ["meta"] = { ["fields"] = {}, ["inventory"] = {} }, ["param2"] = 0, ["y"] = 0, ["param1"] = 8, ["z"] = 6, ["name"] = "lottother:dirt" },
{["x"] = 5, ["meta"] = { ["fields"] = {}, ["inventory"] = {} }, ["param2"] = 0, ["y"] = 0, ["param1"] = 8, ["z"] = 7, ["name"] = "lottother:dirt" },
{["x"] = 5, ["meta"] = { ["fields"] = {}, ["inventory"] = {} }, ["param2"] = 0, ["y"] = 0, ["param1"] = 8, ["z"] = 8, ["name"] = "lottother:dirt" },
{["x"] = 5, ["meta"] = { ["fields"] = {}, ["inventory"] = {} }, ["param2"] = 0, ["y"] = 0, ["param1"] = 9, ["z"] = 9, ["name"] = "lottother:dirt" },
{["x"] = 5, ["meta"] = { ["fields"] = {}, ["inventory"] = {} }, ["param2"] = 0, ["y"] = 0, ["param1"] = 10, ["z"] = 10, ["name"] = "lottother:dirt" },
{["x"] = 5, ["meta"] = { ["fields"] = {}, ["inventory"] = {} }, ["param2"] = 0, ["y"] = 0, ["param1"] = 11, ["z"] = 11, ["name"] = "lottother:dirt" },
{["x"] = 5, ["meta"] = { ["fields"] = {}, ["inventory"] = {} }, ["param2"] = 0, ["y"] = 0, ["param1"] = 12, ["z"] = 12, ["name"] = "lottother:dirt" },
{["x"] = 5, ["meta"] = { ["fields"] = {}, ["inventory"] = {} }, ["param2"] = 0, ["y"] = 0, ["param1"] = 0, ["z"] = 13, ["name"] = "lottother:dirt" },
{["x"] = 5, ["meta"] = { ["fields"] = {}, ["inventory"] = {} }, ["param2"] = 0, ["y"] = 0, ["param1"] = 0, ["z"] = 14, ["name"] = "lottother:dirt" },
{["x"] = 5, ["meta"] = { ["fields"] = {}, ["inventory"] = {} }, ["param2"] = 0, ["y"] = 1, ["param1"] = 0, ["z"] = 0, ["name"] = "lord_ground:dirt_mirkwood" },
{["x"] = 5, ["meta"] = { ["fields"] = {}, ["inventory"] = {} }, ["param2"] = 0, ["y"] = 1, ["param1"] = 61, ["z"] = 1, ["name"] = "lottother:dirt" },
{["x"] = 5, ["meta"] = { ["fields"] = {}, ["inventory"] = {} }, ["param2"] = 0, ["y"] = 1, ["param1"] = 44, ["z"] = 2, ["name"] = "lottother:dirt" },
{["x"] = 5, ["meta"] = { ["fields"] = {}, ["inventory"] = {} }, ["param2"] = 0, ["y"] = 1, ["param1"] = 27, ["z"] = 3, ["name"] = "lottother:dirt" },
{["x"] = 5, ["meta"] = { ["fields"] = {}, ["inventory"] = {} }, ["param2"] = 0, ["y"] = 1, ["param1"] = 10, ["z"] = 4, ["name"] = "lottother:dirt" },
{["x"] = 5, ["meta"] = { ["fields"] = {}, ["inventory"] = {} }, ["param2"] = 0, ["y"] = 1, ["param1"] = 9, ["z"] = 5, ["name"] = "lottother:dirt" },
{["x"] = 5, ["meta"] = { ["fields"] = {}, ["inventory"] = {} }, ["param2"] = 0, ["y"] = 1, ["param1"] = 8, ["z"] = 6, ["name"] = "lottother:dirt" },
{["x"] = 5, ["meta"] = { ["fields"] = {}, ["inventory"] = {} }, ["param2"] = 0, ["y"] = 1, ["param1"] = 8, ["z"] = 7, ["name"] = "lottother:dirt" },
{["x"] = 5, ["meta"] = { ["fields"] = {}, ["inventory"] = {} }, ["param2"] = 0, ["y"] = 1, ["param1"] = 8, ["z"] = 8, ["name"] = "lottother:dirt" },
{["x"] = 5, ["meta"] = { ["fields"] = {}, ["inventory"] = {} }, ["param2"] = 0, ["y"] = 1, ["param1"] = 9, ["z"] = 9, ["name"] = "lottother:dirt" },
{["x"] = 5, ["meta"] = { ["fields"] = {}, ["inventory"] = {} }, ["param2"] = 0, ["y"] = 1, ["param1"] = 10, ["z"] = 10, ["name"] = "lottother:dirt" },
{["x"] = 5, ["meta"] = { ["fields"] = {}, ["inventory"] = {} }, ["param2"] = 0, ["y"] = 1, ["param1"] = 11, ["z"] = 11, ["name"] = "lottother:dirt" },
{["x"] = 5, ["meta"] = { ["fields"] = {}, ["inventory"] = {} }, ["param2"] = 0, ["y"] = 1, ["param1"] = 12, ["z"] = 12, ["name"] = "lottother:dirt" },
{["x"] = 5, ["meta"] = { ["fields"] = {}, ["inventory"] = {} }, ["param2"] = 0, ["y"] = 1, ["param1"] = 0, ["z"] = 13, ["name"] = "lord_ground:dirt_mirkwood" },
{["x"] = 5, ["meta"] = { ["fields"] = {}, ["inventory"] = {} }, ["param2"] = 0, ["y"] = 1, ["param1"] = 0, ["z"] = 14, ["name"] = "lord_ground:dirt_mirkwood" },
{["x"] = 5, ["meta"] = { ["fields"] = {}, ["inventory"] = {} }, ["param2"] = 0, ["y"] = 2, ["param1"] = 0, ["z"] = 1, ["name"] = "lord_ground:dirt_mirkwood" },
{["x"] = 5, ["meta"] = { ["fields"] = {}, ["inventory"] = {} }, ["param2"] = 0, ["y"] = 2, ["param1"] = 60, ["z"] = 2, ["name"] = "lottother:dirt" },
{["x"] = 5, ["meta"] = { ["fields"] = {}, ["inventory"] = {} }, ["param2"] = 0, ["y"] = 2, ["param1"] = 43, ["z"] = 3, ["name"] = "lottother:dirt" },
{["x"] = 5, ["meta"] = { ["fields"] = {}, ["inventory"] = {} }, ["param2"] = 0, ["y"] = 2, ["param1"] = 26, ["z"] = 4, ["name"] = "lottother:dirt" },
{["x"] = 5, ["meta"] = { ["fields"] = {}, ["inventory"] = {} }, ["param2"] = 0, ["y"] = 2, ["param1"] = 9, ["z"] = 5, ["name"] = "lottother:dirt" },
{["x"] = 5, ["meta"] = { ["fields"] = {}, ["inventory"] = {} }, ["param2"] = 0, ["y"] = 2, ["param1"] = 8, ["z"] = 6, ["name"] = "lottother:dirt" },
{["x"] = 5, ["meta"] = { ["fields"] = {}, ["inventory"] = {} }, ["param2"] = 0, ["y"] = 2, ["param1"] = 8, ["z"] = 7, ["name"] = "lottother:dirt" },
{["x"] = 5, ["meta"] = { ["fields"] = {}, ["inventory"] = {} }, ["param2"] = 0, ["y"] = 2, ["param1"] = 8, ["z"] = 8, ["name"] = "lottother:dirt" },
{["x"] = 5, ["meta"] = { ["fields"] = {}, ["inventory"] = {} }, ["param2"] = 0, ["y"] = 2, ["param1"] = 9, ["z"] = 9, ["name"] = "lottother:dirt" },
{["x"] = 5, ["meta"] = { ["fields"] = {}, ["inventory"] = {} }, ["param2"] = 0, ["y"] = 2, ["param1"] = 10, ["z"] = 10, ["name"] = "lottother:dirt" },
{["x"] = 5, ["meta"] = { ["fields"] = {}, ["inventory"] = {} }, ["param2"] = 0, ["y"] = 2, ["param1"] = 11, ["z"] = 11, ["name"] = "lottother:dirt" },
{["x"] = 5, ["meta"] = { ["fields"] = {}, ["inventory"] = {} }, ["param2"] = 0, ["y"] = 2, ["param1"] = 0, ["z"] = 12, ["name"] = "lord_ground:dirt_mirkwood" },
{["x"] = 5, ["meta"] = { ["fields"] = {}, ["inventory"] = {} }, ["param2"] = 0, ["y"] = 3, ["param1"] = 0, ["z"] = 2, ["name"] = "default:junglewood" },
{["x"] = 5, ["meta"] = { ["fields"] = {}, ["inventory"] = {} }, ["param2"] = 0, ["y"] = 3, ["param1"] = 0, ["z"] = 3, ["name"] = "default:junglewood" },
{["x"] = 5, ["meta"] = { ["fields"] = {}, ["inventory"] = {} }, ["param2"] = 0, ["y"] = 3, ["param1"] = 0, ["z"] = 4, ["name"] = "default:junglewood" },
{["x"] = 5, ["meta"] = { ["fields"] = {}, ["inventory"] = {} }, ["param2"] = 0, ["y"] = 3, ["param1"] = 0, ["z"] = 5, ["name"] = "default:junglewood" },
{["x"] = 5, ["meta"] = { ["fields"] = {}, ["inventory"] = {} }, ["param2"] = 0, ["y"] = 3, ["param1"] = 0, ["z"] = 6, ["name"] = "default:tree" },
{["x"] = 5, ["meta"] = { ["fields"] = {}, ["inventory"] = {} }, ["param2"] = 23, ["y"] = 3, ["param1"] = 0, ["z"] = 7, ["name"] = "default:tree" },
{["x"] = 5, ["meta"] = { ["fields"] = {}, ["inventory"] = {} }, ["param2"] = 0, ["y"] = 3, ["param1"] = 0, ["z"] = 8, ["name"] = "default:tree" },
{["x"] = 5, ["meta"] = { ["fields"] = {}, ["inventory"] = {} }, ["param2"] = 0, ["y"] = 3, ["param1"] = 0, ["z"] = 9, ["name"] = "default:tree" },
{["x"] = 5, ["meta"] = { ["fields"] = {}, ["inventory"] = {} }, ["param2"] = 0, ["y"] = 3, ["param1"] = 0, ["z"] = 10, ["name"] = "default:tree" },
{["x"] = 5, ["meta"] = { ["fields"] = {}, ["inventory"] = {} }, ["param2"] = 0, ["y"] = 3, ["param1"] = 0, ["z"] = 11, ["name"] = "default:tree" },
{["x"] = 5, ["meta"] = { ["fields"] = {}, ["inventory"] = {} }, ["param2"] = 0, ["y"] = 4, ["param1"] = 124, ["z"] = 2, ["name"] = "lottother:air" },
{["x"] = 5, ["meta"] = { ["fields"] = {}, ["inventory"] = {} }, ["param2"] = 0, ["y"] = 4, ["param1"] = 139, ["z"] = 3, ["name"] = "doors:door_wood_a" },
{["x"] = 5, ["meta"] = { ["fields"] = {}, ["inventory"] = {} }, ["param2"] = 0, ["y"] = 4, ["param1"] = 154, ["z"] = 4, ["name"] = "lottother:elfms_off" },
{["x"] = 5, ["meta"] = { ["fields"] = {}, ["inventory"] = {} }, ["param2"] = 0, ["y"] = 4, ["param1"] = 170, ["z"] = 5, ["name"] = "lottother:air" },
{["x"] = 5, ["meta"] = { ["fields"] = {}, ["inventory"] = {} }, ["param2"] = 0, ["y"] = 4, ["param1"] = 0, ["z"] = 6, ["name"] = "default:tree" },
{["x"] = 5, ["meta"] = { ["fields"] = {}, ["inventory"] = {} }, ["param2"] = 23, ["y"] = 4, ["param1"] = 0, ["z"] = 7, ["name"] = "default:tree" },
{["x"] = 5, ["meta"] = { ["fields"] = {}, ["inventory"] = {} }, ["param2"] = 3, ["y"] = 4, ["param1"] = 153, ["z"] = 8, ["name"] = "stairs:stair_junglewood" },
{["x"] = 5, ["meta"] = { ["fields"] = {}, ["inventory"] = {} }, ["param2"] = 0, ["y"] = 4, ["param1"] = 0, ["z"] = 9, ["name"] = "default:tree" },
{["x"] = 5, ["meta"] = { ["fields"] = {}, ["inventory"] = {} }, ["param2"] = 0, ["y"] = 4, ["param1"] = 0, ["z"] = 10, ["name"] = "default:tree" },
{["x"] = 5, ["meta"] = { ["fields"] = {}, ["inventory"] = {} }, ["param2"] = 0, ["y"] = 4, ["param1"] = 0, ["z"] = 11, ["name"] = "default:tree" },
{["x"] = 5, ["meta"] = { ["fields"] = {}, ["inventory"] = {} }, ["param2"] = 0, ["y"] = 5, ["param1"] = 140, ["z"] = 2, ["name"] = "lottother:air" },
{["x"] = 5, ["meta"] = { ["fields"] = {}, ["inventory"] = {} }, ["param2"] = 0, ["y"] = 5, ["param1"] = 155, ["z"] = 3, ["name"] = "doors:hidden" },
{["x"] = 5, ["meta"] = { ["fields"] = {}, ["inventory"] = {} }, ["param2"] = 0, ["y"] = 5, ["param1"] = 170, ["z"] = 4, ["name"] = "lottother:air" },
{["x"] = 5, ["meta"] = { ["fields"] = {}, ["inventory"] = {} }, ["param2"] = 0, ["y"] = 5, ["param1"] = 187, ["z"] = 5, ["name"] = "lottother:air" },
{["x"] = 5, ["meta"] = { ["fields"] = {}, ["inventory"] = {} }, ["param2"] = 0, ["y"] = 5, ["param1"] = 0, ["z"] = 6, ["name"] = "default:tree" },
{["x"] = 5, ["meta"] = { ["fields"] = {}, ["inventory"] = {} }, ["param2"] = 23, ["y"] = 5, ["param1"] = 0, ["z"] = 7, ["name"] = "default:tree" },
{["x"] = 5, ["meta"] = { ["fields"] = {}, ["inventory"] = {} }, ["param2"] = 0, ["y"] = 5, ["param1"] = 170, ["z"] = 8, ["name"] = "lottother:air" },
{["x"] = 5, ["meta"] = { ["fields"] = {}, ["inventory"] = {} }, ["param2"] = 0, ["y"] = 5, ["param1"] = 187, ["z"] = 9, ["name"] = "stairs:stair_junglewood" },
{["x"] = 5, ["meta"] = { ["fields"] = {}, ["inventory"] = {} }, ["param2"] = 0, ["y"] = 5, ["param1"] = 0, ["z"] = 10, ["name"] = "default:tree" },
{["x"] = 5, ["meta"] = { ["fields"] = {}, ["inventory"] = {} }, ["param2"] = 0, ["y"] = 5, ["param1"] = 0, ["z"] = 11, ["name"] = "default:tree" },
{["x"] = 5, ["meta"] = { ["fields"] = {}, ["inventory"] = {} }, ["param2"] = 0, ["y"] = 6, ["param1"] = 124, ["z"] = 2, ["name"] = "lottother:air" },
{["x"] = 5, ["meta"] = { ["fields"] = {}, ["inventory"] = {} }, ["param2"] = 0, ["y"] = 6, ["param1"] = 0, ["z"] = 3, ["name"] = "default:junglewood" },
{["x"] = 5, ["meta"] = { ["fields"] = {}, ["inventory"] = {} }, ["param2"] = 0, ["y"] = 6, ["param1"] = 187, ["z"] = 4, ["name"] = "lottother:air" },
{["x"] = 5, ["meta"] = { ["fields"] = {}, ["inventory"] = {} }, ["param2"] = 0, ["y"] = 6, ["param1"] = 204, ["z"] = 5, ["name"] = "lottother:air" },
{["x"] = 5, ["meta"] = { ["fields"] = {}, ["inventory"] = {} }, ["param2"] = 0, ["y"] = 6, ["param1"] = 0, ["z"] = 6, ["name"] = "default:tree" },
{["x"] = 5, ["meta"] = { ["fields"] = {}, ["inventory"] = {} }, ["param2"] = 0, ["y"] = 6, ["param1"] = 0, ["z"] = 7, ["name"] = "default:tree" },
{["x"] = 5, ["meta"] = { ["fields"] = {}, ["inventory"] = {} }, ["param2"] = 0, ["y"] = 6, ["param1"] = 187, ["z"] = 8, ["name"] = "lottother:air" },
{["x"] = 5, ["meta"] = { ["fields"] = {}, ["inventory"] = {} }, ["param2"] = 0, ["y"] = 6, ["param1"] = 204, ["z"] = 9, ["name"] = "lottother:air" },
{["x"] = 5, ["meta"] = { ["fields"] = {}, ["inventory"] = {} }, ["param2"] = 0, ["y"] = 6, ["param1"] = 0, ["z"] = 10, ["name"] = "default:tree" },
{["x"] = 5, ["meta"] = { ["fields"] = {}, ["inventory"] = {} }, ["param2"] = 0, ["y"] = 6, ["param1"] = 0, ["z"] = 11, ["name"] = "default:tree" },
{["x"] = 5, ["meta"] = { ["fields"] = {}, ["inventory"] = {} }, ["param2"] = 0, ["y"] = 7, ["param1"] = 108, ["z"] = 2, ["name"] = "stairs:stair_junglewood" },
{["x"] = 5, ["meta"] = { ["fields"] = {}, ["inventory"] = {} }, ["param2"] = 0, ["y"] = 7, ["param1"] = 0, ["z"] = 3, ["name"] = "default:junglewood" },
{["x"] = 5, ["meta"] = { ["fields"] = {}, ["inventory"] = {} }, ["param2"] = 0, ["y"] = 7, ["param1"] = 0, ["z"] = 4, ["name"] = "default:junglewood" },
{["x"] = 5, ["meta"] = { ["fields"] = {}, ["inventory"] = {} }, ["param2"] = 0, ["y"] = 7, ["param1"] = 0, ["z"] = 5, ["name"] = "default:junglewood" },
{["x"] = 5, ["meta"] = { ["fields"] = {}, ["inventory"] = {} }, ["param2"] = 0, ["y"] = 7, ["param1"] = 0, ["z"] = 6, ["name"] = "default:tree" },
{["x"] = 5, ["meta"] = { ["fields"] = {}, ["inventory"] = {} }, ["param2"] = 0, ["y"] = 7, ["param1"] = 0, ["z"] = 7, ["name"] = "default:tree" },
{["x"] = 5, ["meta"] = { ["fields"] = {}, ["inventory"] = {} }, ["param2"] = 0, ["y"] = 7, ["param1"] = 204, ["z"] = 8, ["name"] = "lottother:air" },
{["x"] = 5, ["meta"] = { ["fields"] = {}, ["inventory"] = {} }, ["param2"] = 3, ["y"] = 7, ["param1"] = 0, ["z"] = 9, ["name"] = "lottother:blue_torch" },
{["x"] = 5, ["meta"] = { ["fields"] = {}, ["inventory"] = {} }, ["param2"] = 0, ["y"] = 7, ["param1"] = 0, ["z"] = 10, ["name"] = "default:tree" },
{["x"] = 5, ["meta"] = { ["fields"] = {}, ["inventory"] = {} }, ["param2"] = 0, ["y"] = 7, ["param1"] = 0, ["z"] = 11, ["name"] = "default:tree" },
{["x"] = 5, ["meta"] = { ["fields"] = {}, ["inventory"] = {} }, ["param2"] = 0, ["y"] = 8, ["param1"] = 75, ["z"] = 3, ["name"] = "stairs:stair_junglewood" },
{["x"] = 5, ["meta"] = { ["fields"] = {}, ["inventory"] = {} }, ["param2"] = 0, ["y"] = 8, ["param1"] = 0, ["z"] = 4, ["name"] = "default:junglewood" },
{["x"] = 5, ["meta"] = { ["fields"] = {}, ["inventory"] = {} }, ["param2"] = 0, ["y"] = 8, ["param1"] = 0, ["z"] = 5, ["name"] = "default:junglewood" },
{["x"] = 5, ["meta"] = { ["fields"] = {}, ["inventory"] = {} }, ["param2"] = 2, ["y"] = 8, ["param1"] = 0, ["z"] = 6, ["name"] = "default:tree" },
{["x"] = 5, ["meta"] = { ["fields"] = {}, ["inventory"] = {} }, ["param2"] = 0, ["y"] = 8, ["param1"] = 0, ["z"] = 7, ["name"] = "default:tree" },
{["x"] = 5, ["meta"] = { ["fields"] = {}, ["inventory"] = {} }, ["param2"] = 3, ["y"] = 8, ["param1"] = 187, ["z"] = 8, ["name"] = "stairs:stair_junglewood" },
{["x"] = 5, ["meta"] = { ["fields"] = {}, ["inventory"] = {} }, ["param2"] = 0, ["y"] = 8, ["param1"] = 204, ["z"] = 9, ["name"] = "lottother:air" },
{["x"] = 5, ["meta"] = { ["fields"] = {}, ["inventory"] = {} }, ["param2"] = 0, ["y"] = 8, ["param1"] = 0, ["z"] = 10, ["name"] = "default:tree" },
{["x"] = 5, ["meta"] = { ["fields"] = {}, ["inventory"] = {} }, ["param2"] = 0, ["y"] = 9, ["param1"] = 42, ["z"] = 4, ["name"] = "stairs:stair_junglewood" },
{["x"] = 5, ["meta"] = { ["fields"] = {}, ["inventory"] = {} }, ["param2"] = 2, ["y"] = 9, ["param1"] = 0, ["z"] = 6, ["name"] = "default:tree" },
{["x"] = 5, ["meta"] = { ["fields"] = {}, ["inventory"] = {} }, ["param2"] = 0, ["y"] = 9, ["param1"] = 187, ["z"] = 7, ["name"] = "lottother:air" },
{["x"] = 5, ["meta"] = { ["fields"] = {}, ["inventory"] = {} }, ["param2"] = 0, ["y"] = 9, ["param1"] = 170, ["z"] = 8, ["name"] = "lottother:elfms_off" },
{["x"] = 5, ["meta"] = { ["fields"] = {}, ["inventory"] = {} }, ["param2"] = 0, ["y"] = 9, ["param1"] = 187, ["z"] = 9, ["name"] = "lottother:air" },
{["x"] = 5, ["meta"] = { ["fields"] = {}, ["inventory"] = {} }, ["param2"] = 0, ["y"] = 9, ["param1"] = 0, ["z"] = 10, ["name"] = "default:tree" },
{["x"] = 5, ["meta"] = { ["fields"] = {}, ["inventory"] = {} }, ["param2"] = 2, ["y"] = 10, ["param1"] = 0, ["z"] = 6, ["name"] = "default:tree" },
{["x"] = 5, ["meta"] = { ["fields"] = {}, ["inventory"] = {} }, ["param2"] = 0, ["y"] = 10, ["param1"] = 204, ["z"] = 7, ["name"] = "lottother:air" },
{["x"] = 5, ["meta"] = { ["fields"] = {}, ["inventory"] = {} }, ["param2"] = 0, ["y"] = 10, ["param1"] = 187, ["z"] = 8, ["name"] = "lottother:air" },
{["x"] = 5, ["meta"] = { ["fields"] = {}, ["inventory"] = {} }, ["param2"] = 0, ["y"] = 10, ["param1"] = 170, ["z"] = 9, ["name"] = "lottother:air" },
{["x"] = 5, ["meta"] = { ["fields"] = {}, ["inventory"] = {} }, ["param2"] = 0, ["y"] = 10, ["param1"] = 0, ["z"] = 10, ["name"] = "default:tree" },
{["x"] = 5, ["meta"] = { ["fields"] = {}, ["inventory"] = {} }, ["param2"] = 3, ["y"] = 11, ["param1"] = 0, ["z"] = 6, ["name"] = "default:tree" },
{["x"] = 5, ["meta"] = { ["fields"] = {}, ["inventory"] = {} }, ["param2"] = 0, ["y"] = 11, ["param1"] = 187, ["z"] = 7, ["name"] = "lottother:air" },
