return {
{["x"] = 0, ["meta"] = { ["fields"] = {}, ["inventory"] = {} }, ["param2"] = 0, ["y"] = 0, ["param1"] = 13, ["z"] = 0, ["name"] = "lottother:snow" },
{["x"] = 0, ["meta"] = { ["fields"] = {}, ["inventory"] = {} }, ["param2"] = 0, ["y"] = 0, ["param1"] = 13, ["z"] = 1, ["name"] = "lottother:snow" },
{["x"] = 0, ["meta"] = { ["fields"] = {}, ["inventory"] = {} }, ["param2"] = 0, ["y"] = 0, ["param1"] = 13, ["z"] = 2, ["name"] = "lottother:snow" },
{["x"] = 0, ["meta"] = { ["fields"] = {}, ["inventory"] = {} }, ["param2"] = 0, ["y"] = 0, ["param1"] = 13, ["z"] = 3, ["name"] = "lottother:snow" },
{["x"] = 0, ["meta"] = { ["fields"] = {}, ["inventory"] = {} }, ["param2"] = 0, ["y"] = 0, ["param1"] = 13, ["z"] = 4, ["name"] = "lottother:snow" },
{["x"] = 0, ["meta"] = { ["fields"] = {}, ["inventory"] = {} }, ["param2"] = 0, ["y"] = 0, ["param1"] = 15, ["z"] = 5, ["name"] = "lottother:snow" },
{["x"] = 0, ["meta"] = { ["fields"] = {}, ["inventory"] = {} }, ["param2"] = 0, ["y"] = 0, ["param1"] = 15, ["z"] = 6, ["name"] = "lottother:snow" },
{["x"] = 0, ["meta"] = { ["fields"] = {}, ["inventory"] = {} }, ["param2"] = 0, ["y"] = 0, ["param1"] = 15, ["z"] = 7, ["name"] = "lottother:snow" },
{["x"] = 0, ["meta"] = { ["fields"] = {}, ["inventory"] = {} }, ["param2"] = 0, ["y"] = 0, ["param1"] = 15, ["z"] = 8, ["name"] = "lottother:snow" },
{["x"] = 0, ["meta"] = { ["fields"] = {}, ["inventory"] = {} }, ["param2"] = 0, ["y"] = 0, ["param1"] = 15, ["z"] = 9, ["name"] = "lottother:snow" },
{["x"] = 0, ["meta"] = { ["fields"] = {}, ["inventory"] = {} }, ["param2"] = 0, ["y"] = 0, ["param1"] = 15, ["z"] = 10, ["name"] = "lottother:snow" },
{["x"] = 0, ["meta"] = { ["fields"] = {}, ["inventory"] = {} }, ["param2"] = 0, ["y"] = 0, ["param1"] = 15, ["z"] = 11, ["name"] = "lottother:snow" },
{["x"] = 0, ["meta"] = { ["fields"] = {}, ["inventory"] = {} }, ["param2"] = 0, ["y"] = 0, ["param1"] = 15, ["z"] = 12, ["name"] = "lottother:snow" },
{["x"] = 0, ["meta"] = { ["fields"] = {}, ["inventory"] = {} }, ["param2"] = 0, ["y"] = 0, ["param1"] = 15, ["z"] = 13, ["name"] = "lottother:snow" },
{["x"] = 0, ["meta"] = { ["fields"] = {}, ["inventory"] = {} }, ["param2"] = 0, ["y"] = 0, ["param1"] = 13, ["z"] = 14, ["name"] = "lottother:snow" },
{["x"] = 0, ["meta"] = { ["fields"] = {}, ["inventory"] = {} }, ["param2"] = 0, ["y"] = 0, ["param1"] = 13, ["z"] = 15, ["name"] = "lottother:snow" },
{["x"] = 0, ["meta"] = { ["fields"] = {}, ["inventory"] = {} }, ["param2"] = 0, ["y"] = 0, ["param1"] = 13, ["z"] = 16, ["name"] = "lottother:snow" },
{["x"] = 0, ["meta"] = { ["fields"] = {}, ["inventory"] = {} }, ["param2"] = 0, ["y"] = 0, ["param1"] = 13, ["z"] = 17, ["name"] = "lottother:snow" },
{["x"] = 0, ["meta"] = { ["fields"] = {}, ["inventory"] = {} }, ["param2"] = 0, ["y"] = 0, ["param1"] = 13, ["z"] = 18, ["name"] = "lottother:snow" },
{["x"] = 0, ["meta"] = { ["fields"] = {}, ["inventory"] = {} }, ["param2"] = 0, ["y"] = 9, ["param1"] = 0, ["z"] = 1, ["name"] = "default:cobble" },
{["x"] = 0, ["meta"] = { ["fields"] = {}, ["inventory"] = {} }, ["param2"] = 0, ["y"] = 9, ["param1"] = 0, ["z"] = 3, ["name"] = "default:cobble" },
{["x"] = 0, ["meta"] = { ["fields"] = {}, ["inventory"] = {} }, ["param2"] = 0, ["y"] = 9, ["param1"] = 0, ["z"] = 15, ["name"] = "default:cobble" },
{["x"] = 0, ["meta"] = { ["fields"] = {}, ["inventory"] = {} }, ["param2"] = 0, ["y"] = 9, ["param1"] = 0, ["z"] = 17, ["name"] = "default:cobble" },
{["x"] = 0, ["meta"] = { ["fields"] = {}, ["inventory"] = {} }, ["param2"] = 0, ["y"] = 10, ["param1"] = 0, ["z"] = 0, ["name"] = "default:cobble" },
{["x"] = 0, ["meta"] = { ["fields"] = {}, ["inventory"] = {} }, ["param2"] = 0, ["y"] = 10, ["param1"] = 0, ["z"] = 2, ["name"] = "default:cobble" },
{["x"] = 0, ["meta"] = { ["fields"] = {}, ["inventory"] = {} }, ["param2"] = 0, ["y"] = 10, ["param1"] = 0, ["z"] = 4, ["name"] = "default:cobble" },
{["x"] = 0, ["meta"] = { ["fields"] = {}, ["inventory"] = {} }, ["param2"] = 0, ["y"] = 10, ["param1"] = 0, ["z"] = 14, ["name"] = "default:cobble" },
{["x"] = 0, ["meta"] = { ["fields"] = {}, ["inventory"] = {} }, ["param2"] = 0, ["y"] = 10, ["param1"] = 0, ["z"] = 16, ["name"] = "default:cobble" },
{["x"] = 0, ["meta"] = { ["fields"] = {}, ["inventory"] = {} }, ["param2"] = 0, ["y"] = 10, ["param1"] = 0, ["z"] = 18, ["name"] = "default:cobble" },
{["x"] = 1, ["meta"] = { ["fields"] = {}, ["inventory"] = {} }, ["param2"] = 0, ["y"] = 0, ["param1"] = 13, ["z"] = 0, ["name"] = "lottother:snow" },
{["x"] = 1, ["meta"] = { ["fields"] = {}, ["inventory"] = {} }, ["param2"] = 0, ["y"] = 0, ["param1"] = 12, ["z"] = 1, ["name"] = "lottother:snow" },
{["x"] = 1, ["meta"] = { ["fields"] = {}, ["inventory"] = {} }, ["param2"] = 0, ["y"] = 0, ["param1"] = 12, ["z"] = 2, ["name"] = "lottother:snow" },
{["x"] = 1, ["meta"] = { ["fields"] = {}, ["inventory"] = {} }, ["param2"] = 0, ["y"] = 0, ["param1"] = 12, ["z"] = 3, ["name"] = "lottother:snow" },
{["x"] = 1, ["meta"] = { ["fields"] = {}, ["inventory"] = {} }, ["param2"] = 0, ["y"] = 0, ["param1"] = 12, ["z"] = 4, ["name"] = "lottother:snow" },
{["x"] = 1, ["meta"] = { ["fields"] = {}, ["inventory"] = {} }, ["param2"] = 0, ["y"] = 0, ["param1"] = 13, ["z"] = 5, ["name"] = "lottother:snow" },
{["x"] = 1, ["meta"] = { ["fields"] = {}, ["inventory"] = {} }, ["param2"] = 0, ["y"] = 0, ["param1"] = 13, ["z"] = 6, ["name"] = "lottother:snow" },
{["x"] = 1, ["meta"] = { ["fields"] = {}, ["inventory"] = {} }, ["param2"] = 0, ["y"] = 0, ["param1"] = 13, ["z"] = 7, ["name"] = "lottother:snow" },
{["x"] = 1, ["meta"] = { ["fields"] = {}, ["inventory"] = {} }, ["param2"] = 0, ["y"] = 0, ["param1"] = 13, ["z"] = 8, ["name"] = "lottother:snow" },
{["x"] = 1, ["meta"] = { ["fields"] = {}, ["inventory"] = {} }, ["param2"] = 0, ["y"] = 0, ["param1"] = 13, ["z"] = 9, ["name"] = "lottother:snow" },
{["x"] = 1, ["meta"] = { ["fields"] = {}, ["inventory"] = {} }, ["param2"] = 0, ["y"] = 0, ["param1"] = 13, ["z"] = 10, ["name"] = "lottother:snow" },
{["x"] = 1, ["meta"] = { ["fields"] = {}, ["inventory"] = {} }, ["param2"] = 0, ["y"] = 0, ["param1"] = 13, ["z"] = 11, ["name"] = "lottother:snow" },
{["x"] = 1, ["meta"] = { ["fields"] = {}, ["inventory"] = {} }, ["param2"] = 0, ["y"] = 0, ["param1"] = 13, ["z"] = 12, ["name"] = "lottother:snow" },
{["x"] = 1, ["meta"] = { ["fields"] = {}, ["inventory"] = {} }, ["param2"] = 0, ["y"] = 0, ["param1"] = 13, ["z"] = 13, ["name"] = "lottother:snow" },
{["x"] = 1, ["meta"] = { ["fields"] = {}, ["inventory"] = {} }, ["param2"] = 0, ["y"] = 0, ["param1"] = 12, ["z"] = 14, ["name"] = "lottother:snow" },
{["x"] = 1, ["meta"] = { ["fields"] = {}, ["inventory"] = {} }, ["param2"] = 0, ["y"] = 0, ["param1"] = 12, ["z"] = 15, ["name"] = "lottother:snow" },
{["x"] = 1, ["meta"] = { ["fields"] = {}, ["inventory"] = {} }, ["param2"] = 0, ["y"] = 0, ["param1"] = 12, ["z"] = 16, ["name"] = "lottother:snow" },
{["x"] = 1, ["meta"] = { ["fields"] = {}, ["inventory"] = {} }, ["param2"] = 0, ["y"] = 0, ["param1"] = 12, ["z"] = 17, ["name"] = "lottother:snow" },
{["x"] = 1, ["meta"] = { ["fields"] = {}, ["inventory"] = {} }, ["param2"] = 0, ["y"] = 0, ["param1"] = 13, ["z"] = 18, ["name"] = "lottother:snow" },
{["x"] = 1, ["meta"] = { ["fields"] = {}, ["inventory"] = {} }, ["param2"] = 0, ["y"] = 1, ["param1"] = 0, ["z"] = 1, ["name"] = "lottother:snow" },
{["x"] = 1, ["meta"] = { ["fields"] = {}, ["inventory"] = {} }, ["param2"] = 0, ["y"] = 1, ["param1"] = 0, ["z"] = 2, ["name"] = "lottother:snow" },
{["x"] = 1, ["meta"] = { ["fields"] = {}, ["inventory"] = {} }, ["param2"] = 0, ["y"] = 1, ["param1"] = 0, ["z"] = 3, ["name"] = "lottother:snow" },
{["x"] = 1, ["meta"] = { ["fields"] = {}, ["inventory"] = {} }, ["param2"] = 0, ["y"] = 1, ["param1"] = 0, ["z"] = 4, ["name"] = "lottother:snow" },
{["x"] = 1, ["meta"] = { ["fields"] = {}, ["inventory"] = {} }, ["param2"] = 0, ["y"] = 1, ["param1"] = 0, ["z"] = 5, ["name"] = "lottother:snow" },
{["x"] = 1, ["meta"] = { ["fields"] = {}, ["inventory"] = {} }, ["param2"] = 0, ["y"] = 1, ["param1"] = 0, ["z"] = 6, ["name"] = "lottother:snow" },
{["x"] = 1, ["meta"] = { ["fields"] = {}, ["inventory"] = {} }, ["param2"] = 0, ["y"] = 1, ["param1"] = 0, ["z"] = 12, ["name"] = "lottother:snow" },
{["x"] = 1, ["meta"] = { ["fields"] = {}, ["inventory"] = {} }, ["param2"] = 0, ["y"] = 1, ["param1"] = 0, ["z"] = 13, ["name"] = "lottother:snow" },
{["x"] = 1, ["meta"] = { ["fields"] = {}, ["inventory"] = {} }, ["param2"] = 0, ["y"] = 1, ["param1"] = 0, ["z"] = 14, ["name"] = "lottother:snow" },
{["x"] = 1, ["meta"] = { ["fields"] = {}, ["inventory"] = {} }, ["param2"] = 0, ["y"] = 1, ["param1"] = 0, ["z"] = 15, ["name"] = "lottother:snow" },
{["x"] = 1, ["meta"] = { ["fields"] = {}, ["inventory"] = {} }, ["param2"] = 0, ["y"] = 1, ["param1"] = 0, ["z"] = 16, ["name"] = "lottother:snow" },
{["x"] = 1, ["meta"] = { ["fields"] = {}, ["inventory"] = {} }, ["param2"] = 0, ["y"] = 1, ["param1"] = 0, ["z"] = 17, ["name"] = "lottother:snow" },
{["x"] = 1, ["meta"] = { ["fields"] = {}, ["inventory"] = {} }, ["param2"] = 0, ["y"] = 9, ["param1"] = 0, ["z"] = 0, ["name"] = "default:cobble" },
{["x"] = 1, ["meta"] = { ["fields"] = {}, ["inventory"] = {} }, ["param2"] = 0, ["y"] = 9, ["param1"] = 0, ["z"] = 1, ["name"] = "default:cobble" },
{["x"] = 1, ["meta"] = { ["fields"] = {}, ["inventory"] = {} }, ["param2"] = 0, ["y"] = 9, ["param1"] = 0, ["z"] = 2, ["name"] = "default:cobble" },
{["x"] = 1, ["meta"] = { ["fields"] = {}, ["inventory"] = {} }, ["param2"] = 0, ["y"] = 9, ["param1"] = 0, ["z"] = 3, ["name"] = "default:cobble" },
{["x"] = 1, ["meta"] = { ["fields"] = {}, ["inventory"] = {} }, ["param2"] = 0, ["y"] = 9, ["param1"] = 0, ["z"] = 4, ["name"] = "default:cobble" },
{["x"] = 1, ["meta"] = { ["fields"] = {}, ["inventory"] = {} }, ["param2"] = 0, ["y"] = 9, ["param1"] = 0, ["z"] = 14, ["name"] = "default:cobble" },
{["x"] = 1, ["meta"] = { ["fields"] = {}, ["inventory"] = {} }, ["param2"] = 0, ["y"] = 9, ["param1"] = 0, ["z"] = 15, ["name"] = "default:cobble" },
{["x"] = 1, ["meta"] = { ["fields"] = {}, ["inventory"] = {} }, ["param2"] = 0, ["y"] = 9, ["param1"] = 0, ["z"] = 16, ["name"] = "default:cobble" },
{["x"] = 1, ["meta"] = { ["fields"] = {}, ["inventory"] = {} }, ["param2"] = 0, ["y"] = 9, ["param1"] = 0, ["z"] = 17, ["name"] = "default:cobble" },
{["x"] = 1, ["meta"] = { ["fields"] = {}, ["inventory"] = {} }, ["param2"] = 0, ["y"] = 9, ["param1"] = 0, ["z"] = 18, ["name"] = "default:cobble" },
{["x"] = 2, ["meta"] = { ["fields"] = {}, ["inventory"] = {} }, ["param2"] = 0, ["y"] = 0, ["param1"] = 13, ["z"] = 0, ["name"] = "lottother:snow" },
{["x"] = 2, ["meta"] = { ["fields"] = {}, ["inventory"] = {} }, ["param2"] = 0, ["y"] = 0, ["param1"] = 28, ["z"] = 1, ["name"] = "lottother:snow" },
{["x"] = 2, ["meta"] = { ["fields"] = {}, ["inventory"] = {} }, ["param2"] = 0, ["y"] = 0, ["param1"] = 11, ["z"] = 2, ["name"] = "lottother:snow" },
{["x"] = 2, ["meta"] = { ["fields"] = {}, ["inventory"] = {} }, ["param2"] = 0, ["y"] = 0, ["param1"] = 11, ["z"] = 3, ["name"] = "lottother:snow" },
{["x"] = 2, ["meta"] = { ["fields"] = {}, ["inventory"] = {} }, ["param2"] = 0, ["y"] = 0, ["param1"] = 11, ["z"] = 4, ["name"] = "lottother:snow" },
{["x"] = 2, ["meta"] = { ["fields"] = {}, ["inventory"] = {} }, ["param2"] = 0, ["y"] = 0, ["param1"] = 12, ["z"] = 5, ["name"] = "lottother:snow" },
{["x"] = 2, ["meta"] = { ["fields"] = {}, ["inventory"] = {} }, ["param2"] = 0, ["y"] = 0, ["param1"] = 12, ["z"] = 6, ["name"] = "lottother:snow" },
{["x"] = 2, ["meta"] = { ["fields"] = {}, ["inventory"] = {} }, ["param2"] = 0, ["y"] = 0, ["param1"] = 12, ["z"] = 7, ["name"] = "lottother:snow" },
{["x"] = 2, ["meta"] = { ["fields"] = {}, ["inventory"] = {} }, ["param2"] = 0, ["y"] = 0, ["param1"] = 12, ["z"] = 8, ["name"] = "lottother:snow" },
{["x"] = 2, ["meta"] = { ["fields"] = {}, ["inventory"] = {} }, ["param2"] = 0, ["y"] = 0, ["param1"] = 12, ["z"] = 9, ["name"] = "lottother:snow" },
{["x"] = 2, ["meta"] = { ["fields"] = {}, ["inventory"] = {} }, ["param2"] = 0, ["y"] = 0, ["param1"] = 12, ["z"] = 10, ["name"] = "lottother:snow" },
{["x"] = 2, ["meta"] = { ["fields"] = {}, ["inventory"] = {} }, ["param2"] = 0, ["y"] = 0, ["param1"] = 12, ["z"] = 11, ["name"] = "lottother:snow" },
{["x"] = 2, ["meta"] = { ["fields"] = {}, ["inventory"] = {} }, ["param2"] = 0, ["y"] = 0, ["param1"] = 12, ["z"] = 12, ["name"] = "lottother:snow" },
{["x"] = 2, ["meta"] = { ["fields"] = {}, ["inventory"] = {} }, ["param2"] = 0, ["y"] = 0, ["param1"] = 12, ["z"] = 13, ["name"] = "lottother:snow" },
{["x"] = 2, ["meta"] = { ["fields"] = {}, ["inventory"] = {} }, ["param2"] = 0, ["y"] = 0, ["param1"] = 11, ["z"] = 14, ["name"] = "lottother:snow" },
{["x"] = 2, ["meta"] = { ["fields"] = {}, ["inventory"] = {} }, ["param2"] = 0, ["y"] = 0, ["param1"] = 11, ["z"] = 15, ["name"] = "lottother:snow" },
{["x"] = 2, ["meta"] = { ["fields"] = {}, ["inventory"] = {} }, ["param2"] = 0, ["y"] = 0, ["param1"] = 11, ["z"] = 16, ["name"] = "lottother:snow" },
{["x"] = 2, ["meta"] = { ["fields"] = {}, ["inventory"] = {} }, ["param2"] = 0, ["y"] = 0, ["param1"] = 12, ["z"] = 17, ["name"] = "lottother:snow" },
{["x"] = 2, ["meta"] = { ["fields"] = {}, ["inventory"] = {} }, ["param2"] = 0, ["y"] = 0, ["param1"] = 13, ["z"] = 18, ["name"] = "lottother:snow" },
{["x"] = 2, ["meta"] = { ["fields"] = {}, ["inventory"] = {} }, ["param2"] = 0, ["y"] = 1, ["param1"] = 0, ["z"] = 1, ["name"] = "lottother:snow" },
{["x"] = 2, ["meta"] = { ["fields"] = {}, ["inventory"] = {} }, ["param2"] = 0, ["y"] = 1, ["param1"] = 59, ["z"] = 2, ["name"] = "lottother:snow" },
{["x"] = 2, ["meta"] = { ["fields"] = {}, ["inventory"] = {} }, ["param2"] = 0, ["y"] = 1, ["param1"] = 43, ["z"] = 3, ["name"] = "lottother:snow" },
{["x"] = 2, ["meta"] = { ["fields"] = {}, ["inventory"] = {} }, ["param2"] = 0, ["y"] = 1, ["param1"] = 28, ["z"] = 4, ["name"] = "lottother:snow" },
{["x"] = 2, ["meta"] = { ["fields"] = {}, ["inventory"] = {} }, ["param2"] = 0, ["y"] = 1, ["param1"] = 13, ["z"] = 5, ["name"] = "lottother:snow" },
{["x"] = 2, ["meta"] = { ["fields"] = {}, ["inventory"] = {} }, ["param2"] = 0, ["y"] = 1, ["param1"] = 13, ["z"] = 6, ["name"] = "lottother:snow" },
{["x"] = 2, ["meta"] = { ["fields"] = {}, ["inventory"] = {} }, ["param2"] = 0, ["y"] = 1, ["param1"] = 13, ["z"] = 7, ["name"] = "lottother:snow" },
{["x"] = 2, ["meta"] = { ["fields"] = {}, ["inventory"] = {} }, ["param2"] = 0, ["y"] = 1, ["param1"] = 13, ["z"] = 8, ["name"] = "lottother:snow" },
{["x"] = 2, ["meta"] = { ["fields"] = {}, ["inventory"] = {} }, ["param2"] = 0, ["y"] = 1, ["param1"] = 13, ["z"] = 9, ["name"] = "lottother:snow" },
{["x"] = 2, ["meta"] = { ["fields"] = {}, ["inventory"] = {} }, ["param2"] = 0, ["y"] = 1, ["param1"] = 13, ["z"] = 10, ["name"] = "lottother:snow" },
{["x"] = 2, ["meta"] = { ["fields"] = {}, ["inventory"] = {} }, ["param2"] = 0, ["y"] = 1, ["param1"] = 13, ["z"] = 11, ["name"] = "lottother:snow" },
{["x"] = 2, ["meta"] = { ["fields"] = {}, ["inventory"] = {} }, ["param2"] = 0, ["y"] = 1, ["param1"] = 13, ["z"] = 12, ["name"] = "lottother:snow" },
{["x"] = 2, ["meta"] = { ["fields"] = {}, ["inventory"] = {} }, ["param2"] = 0, ["y"] = 1, ["param1"] = 13, ["z"] = 13, ["name"] = "lottother:snow" },
{["x"] = 2, ["meta"] = { ["fields"] = {}, ["inventory"] = {} }, ["param2"] = 0, ["y"] = 1, ["param1"] = 28, ["z"] = 14, ["name"] = "lottother:snow" },
{["x"] = 2, ["meta"] = { ["fields"] = {}, ["inventory"] = {} }, ["param2"] = 0, ["y"] = 1, ["param1"] = 43, ["z"] = 15, ["name"] = "lottother:snow" },
{["x"] = 2, ["meta"] = { ["fields"] = {}, ["inventory"] = {} }, ["param2"] = 0, ["y"] = 1, ["param1"] = 59, ["z"] = 16, ["name"] = "lottother:snow" },
{["x"] = 2, ["meta"] = { ["fields"] = {}, ["inventory"] = {} }, ["param2"] = 0, ["y"] = 1, ["param1"] = 0, ["z"] = 17, ["name"] = "lottother:snow" },
{["x"] = 2, ["meta"] = { ["fields"] = {}, ["inventory"] = {} }, ["param2"] = 0, ["y"] = 2, ["param1"] = 0, ["z"] = 2, ["name"] = "default:cobble" },
{["x"] = 2, ["meta"] = { ["fields"] = {}, ["inventory"] = {} }, ["param2"] = 0, ["y"] = 2, ["param1"] = 0, ["z"] = 3, ["name"] = "default:cobble" },
{["x"] = 2, ["meta"] = { ["fields"] = {}, ["inventory"] = {} }, ["param2"] = 0, ["y"] = 2, ["param1"] = 0, ["z"] = 4, ["name"] = "default:cobble" },
{["x"] = 2, ["meta"] = { ["fields"] = {}, ["inventory"] = {} }, ["param2"] = 0, ["y"] = 2, ["param1"] = 0, ["z"] = 5, ["name"] = "default:cobble" },
{["x"] = 2, ["meta"] = { ["fields"] = {}, ["inventory"] = {} }, ["param2"] = 0, ["y"] = 2, ["param1"] = 0, ["z"] = 13, ["name"] = "default:cobble" },
{["x"] = 2, ["meta"] = { ["fields"] = {}, ["inventory"] = {} }, ["param2"] = 0, ["y"] = 2, ["param1"] = 0, ["z"] = 14, ["name"] = "default:cobble" },
{["x"] = 2, ["meta"] = { ["fields"] = {}, ["inventory"] = {} }, ["param2"] = 0, ["y"] = 2, ["param1"] = 0, ["z"] = 15, ["name"] = "default:cobble" },
{["x"] = 2, ["meta"] = { ["fields"] = {}, ["inventory"] = {} }, ["param2"] = 0, ["y"] = 2, ["param1"] = 0, ["z"] = 16, ["name"] = "default:cobble" },
{["x"] = 2, ["meta"] = { ["fields"] = {}, ["inventory"] = {} }, ["param2"] = 0, ["y"] = 3, ["param1"] = 0, ["z"] = 2, ["name"] = "default:cobble" },
{["x"] = 2, ["meta"] = { ["fields"] = {}, ["inventory"] = {} }, ["param2"] = 0, ["y"] = 3, ["param1"] = 0, ["z"] = 3, ["name"] = "default:cobble" },
{["x"] = 2, ["meta"] = { ["fields"] = {}, ["inventory"] = {} }, ["param2"] = 0, ["y"] = 3, ["param1"] = 0, ["z"] = 4, ["name"] = "default:cobble" },
{["x"] = 2, ["meta"] = { ["fields"] = {}, ["inventory"] = {} }, ["param2"] = 0, ["y"] = 3, ["param1"] = 0, ["z"] = 5, ["name"] = "default:cobble" },
{["x"] = 2, ["meta"] = { ["fields"] = {}, ["inventory"] = {} }, ["param2"] = 0, ["y"] = 3, ["param1"] = 0, ["z"] = 13, ["name"] = "default:cobble" },
{["x"] = 2, ["meta"] = { ["fields"] = {}, ["inventory"] = {} }, ["param2"] = 0, ["y"] = 3, ["param1"] = 0, ["z"] = 14, ["name"] = "default:cobble" },
{["x"] = 2, ["meta"] = { ["fields"] = {}, ["inventory"] = {} }, ["param2"] = 0, ["y"] = 3, ["param1"] = 0, ["z"] = 15, ["name"] = "default:cobble" },
{["x"] = 2, ["meta"] = { ["fields"] = {}, ["inventory"] = {} }, ["param2"] = 0, ["y"] = 3, ["param1"] = 0, ["z"] = 16, ["name"] = "default:cobble" },
{["x"] = 2, ["meta"] = { ["fields"] = {}, ["inventory"] = {} }, ["param2"] = 0, ["y"] = 4, ["param1"] = 0, ["z"] = 2, ["name"] = "default:cobble" },
{["x"] = 2, ["meta"] = { ["fields"] = {}, ["inventory"] = {} }, ["param2"] = 0, ["y"] = 4, ["param1"] = 0, ["z"] = 3, ["name"] = "default:cobble" },
{["x"] = 2, ["meta"] = { ["fields"] = {}, ["inventory"] = {} }, ["param2"] = 0, ["y"] = 4, ["param1"] = 0, ["z"] = 4, ["name"] = "default:cobble" },
{["x"] = 2, ["meta"] = { ["fields"] = {}, ["inventory"] = {} }, ["param2"] = 0, ["y"] = 4, ["param1"] = 0, ["z"] = 5, ["name"] = "default:cobble" },
{["x"] = 2, ["meta"] = { ["fields"] = {}, ["inventory"] = {} }, ["param2"] = 0, ["y"] = 4, ["param1"] = 0, ["z"] = 13, ["name"] = "default:cobble" },
{["x"] = 2, ["meta"] = { ["fields"] = {}, ["inventory"] = {} }, ["param2"] = 0, ["y"] = 4, ["param1"] = 0, ["z"] = 14, ["name"] = "default:cobble" },
{["x"] = 2, ["meta"] = { ["fields"] = {}, ["inventory"] = {} }, ["param2"] = 0, ["y"] = 4, ["param1"] = 0, ["z"] = 15, ["name"] = "default:cobble" },
{["x"] = 2, ["meta"] = { ["fields"] = {}, ["inventory"] = {} }, ["param2"] = 0, ["y"] = 4, ["param1"] = 0, ["z"] = 16, ["name"] = "default:cobble" },
{["x"] = 2, ["meta"] = { ["fields"] = {}, ["inventory"] = {} }, ["param2"] = 0, ["y"] = 5, ["param1"] = 0, ["z"] = 2, ["name"] = "default:cobble" },
{["x"] = 2, ["meta"] = { ["fields"] = {}, ["inventory"] = {} }, ["param2"] = 0, ["y"] = 5, ["param1"] = 0, ["z"] = 3, ["name"] = "default:cobble" },
{["x"] = 2, ["meta"] = { ["fields"] = {}, ["inventory"] = {} }, ["param2"] = 0, ["y"] = 5, ["param1"] = 0, ["z"] = 4, ["name"] = "default:cobble" },
{["x"] = 2, ["meta"] = { ["fields"] = {}, ["inventory"] = {} }, ["param2"] = 0, ["y"] = 5, ["param1"] = 0, ["z"] = 5, ["name"] = "default:cobble" },
{["x"] = 2, ["meta"] = { ["fields"] = {}, ["inventory"] = {} }, ["param2"] = 0, ["y"] = 5, ["param1"] = 0, ["z"] = 6, ["name"] = "default:cobble" },
{["x"] = 2, ["meta"] = { ["fields"] = {}, ["inventory"] = {} }, ["param2"] = 0, ["y"] = 5, ["param1"] = 0, ["z"] = 7, ["name"] = "default:cobble" },
{["x"] = 2, ["meta"] = { ["fields"] = {}, ["inventory"] = {} }, ["param2"] = 0, ["y"] = 5, ["param1"] = 0, ["z"] = 9, ["name"] = "default:cobble" },
{["x"] = 2, ["meta"] = { ["fields"] = {}, ["inventory"] = {} }, ["param2"] = 0, ["y"] = 5, ["param1"] = 0, ["z"] = 11, ["name"] = "default:cobble" },
{["x"] = 2, ["meta"] = { ["fields"] = {}, ["inventory"] = {} }, ["param2"] = 0, ["y"] = 5, ["param1"] = 0, ["z"] = 13, ["name"] = "default:cobble" },
{["x"] = 2, ["meta"] = { ["fields"] = {}, ["inventory"] = {} }, ["param2"] = 0, ["y"] = 5, ["param1"] = 0, ["z"] = 14, ["name"] = "default:cobble" },
{["x"] = 2, ["meta"] = { ["fields"] = {}, ["inventory"] = {} }, ["param2"] = 0, ["y"] = 5, ["param1"] = 0, ["z"] = 15, ["name"] = "default:cobble" },
{["x"] = 2, ["meta"] = { ["fields"] = {}, ["inventory"] = {} }, ["param2"] = 0, ["y"] = 5, ["param1"] = 0, ["z"] = 16, ["name"] = "default:cobble" },
{["x"] = 2, ["meta"] = { ["fields"] = {}, ["inventory"] = {} }, ["param2"] = 0, ["y"] = 6, ["param1"] = 0, ["z"] = 2, ["name"] = "default:cobble" },
{["x"] = 2, ["meta"] = { ["fields"] = {}, ["inventory"] = {} }, ["param2"] = 0, ["y"] = 6, ["param1"] = 0, ["z"] = 3, ["name"] = "default:cobble" },
{["x"] = 2, ["meta"] = { ["fields"] = {}, ["inventory"] = {} }, ["param2"] = 0, ["y"] = 6, ["param1"] = 0, ["z"] = 4, ["name"] = "default:cobble" },
{["x"] = 2, ["meta"] = { ["fields"] = {}, ["inventory"] = {} }, ["param2"] = 0, ["y"] = 6, ["param1"] = 15, ["z"] = 5, ["name"] = "lottother:air" },
{["x"] = 2, ["meta"] = { ["fields"] = {}, ["inventory"] = {} }, ["param2"] = 0, ["y"] = 6, ["param1"] = 0, ["z"] = 6, ["name"] = "default:cobble" },
{["x"] = 2, ["meta"] = { ["fields"] = {}, ["inventory"] = {} }, ["param2"] = 0, ["y"] = 6, ["param1"] = 15, ["z"] = 7, ["name"] = "lottother:air" },
{["x"] = 2, ["meta"] = { ["fields"] = {}, ["inventory"] = {} }, ["param2"] = 0, ["y"] = 6, ["param1"] = 0, ["z"] = 8, ["name"] = "default:cobble" },
{["x"] = 2, ["meta"] = { ["fields"] = {}, ["inventory"] = {} }, ["param2"] = 0, ["y"] = 6, ["param1"] = 15, ["z"] = 9, ["name"] = "lottother:air" },
{["x"] = 2, ["meta"] = { ["fields"] = {}, ["inventory"] = {} }, ["param2"] = 0, ["y"] = 6, ["param1"] = 0, ["z"] = 10, ["name"] = "default:cobble" },
{["x"] = 2, ["meta"] = { ["fields"] = {}, ["inventory"] = {} }, ["param2"] = 0, ["y"] = 6, ["param1"] = 15, ["z"] = 11, ["name"] = "lottother:air" },
{["x"] = 2, ["meta"] = { ["fields"] = {}, ["inventory"] = {} }, ["param2"] = 0, ["y"] = 6, ["param1"] = 0, ["z"] = 12, ["name"] = "default:cobble" },
{["x"] = 2, ["meta"] = { ["fields"] = {}, ["inventory"] = {} }, ["param2"] = 0, ["y"] = 6, ["param1"] = 15, ["z"] = 13, ["name"] = "lottother:air" },
{["x"] = 2, ["meta"] = { ["fields"] = {}, ["inventory"] = {} }, ["param2"] = 0, ["y"] = 6, ["param1"] = 0, ["z"] = 14, ["name"] = "default:cobble" },
{["x"] = 2, ["meta"] = { ["fields"] = {}, ["inventory"] = {} }, ["param2"] = 0, ["y"] = 6, ["param1"] = 0, ["z"] = 15, ["name"] = "default:cobble" },
{["x"] = 2, ["meta"] = { ["fields"] = {}, ["inventory"] = {} }, ["param2"] = 0, ["y"] = 6, ["param1"] = 0, ["z"] = 16, ["name"] = "default:cobble" },
{["x"] = 2, ["meta"] = { ["fields"] = {}, ["inventory"] = {} }, ["param2"] = 0, ["y"] = 7, ["param1"] = 0, ["z"] = 2, ["name"] = "default:cobble" },
{["x"] = 2, ["meta"] = { ["fields"] = {}, ["inventory"] = {} }, ["param2"] = 0, ["y"] = 7, ["param1"] = 0, ["z"] = 3, ["name"] = "default:cobble" },
{["x"] = 2, ["meta"] = { ["fields"] = {}, ["inventory"] = {} }, ["param2"] = 0, ["y"] = 7, ["param1"] = 0, ["z"] = 4, ["name"] = "default:cobble" },
{["x"] = 2, ["meta"] = { ["fields"] = {}, ["inventory"] = {} }, ["param2"] = 0, ["y"] = 7, ["param1"] = 0, ["z"] = 14, ["name"] = "default:cobble" },
{["x"] = 2, ["meta"] = { ["fields"] = {}, ["inventory"] = {} }, ["param2"] = 0, ["y"] = 7, ["param1"] = 0, ["z"] = 15, ["name"] = "default:cobble" },
{["x"] = 2, ["meta"] = { ["fields"] = {}, ["inventory"] = {} }, ["param2"] = 0, ["y"] = 7, ["param1"] = 0, ["z"] = 16, ["name"] = "default:cobble" },
{["x"] = 2, ["meta"] = { ["fields"] = {}, ["inventory"] = {} }, ["param2"] = 0, ["y"] = 8, ["param1"] = 0, ["z"] = 2, ["name"] = "default:cobble" },
{["x"] = 2, ["meta"] = { ["fields"] = {}, ["inventory"] = {} }, ["param2"] = 0, ["y"] = 8, ["param1"] = 0, ["z"] = 3, ["name"] = "default:cobble" },
{["x"] = 2, ["meta"] = { ["fields"] = {}, ["inventory"] = {} }, ["param2"] = 0, ["y"] = 8, ["param1"] = 0, ["z"] = 4, ["name"] = "default:cobble" },
{["x"] = 2, ["meta"] = { ["fields"] = {}, ["inventory"] = {} }, ["param2"] = 0, ["y"] = 8, ["param1"] = 0, ["z"] = 14, ["name"] = "default:cobble" },
{["x"] = 2, ["meta"] = { ["fields"] = {}, ["inventory"] = {} }, ["param2"] = 0, ["y"] = 8, ["param1"] = 0, ["z"] = 15, ["name"] = "default:cobble" },
{["x"] = 2, ["meta"] = { ["fields"] = {}, ["inventory"] = {} }, ["param2"] = 0, ["y"] = 8, ["param1"] = 0, ["z"] = 16, ["name"] = "default:cobble" },
{["x"] = 2, ["meta"] = { ["fields"] = {}, ["inventory"] = {} }, ["param2"] = 0, ["y"] = 9, ["param1"] = 0, ["z"] = 1, ["name"] = "default:cobble" },
{["x"] = 2, ["meta"] = { ["fields"] = {}, ["inventory"] = {} }, ["param2"] = 0, ["y"] = 9, ["param1"] = 0, ["z"] = 2, ["name"] = "default:cobble" },
{["x"] = 2, ["meta"] = { ["fields"] = {}, ["inventory"] = {} }, ["param2"] = 0, ["y"] = 9, ["param1"] = 0, ["z"] = 3, ["name"] = "default:cobble" },
{["x"] = 2, ["meta"] = { ["fields"] = {}, ["inventory"] = {} }, ["param2"] = 0, ["y"] = 9, ["param1"] = 0, ["z"] = 4, ["name"] = "default:cobble" },
{["x"] = 2, ["meta"] = { ["fields"] = {}, ["inventory"] = {} }, ["param2"] = 0, ["y"] = 9, ["param1"] = 0, ["z"] = 14, ["name"] = "default:cobble" },
{["x"] = 2, ["meta"] = { ["fields"] = {}, ["inventory"] = {} }, ["param2"] = 0, ["y"] = 9, ["param1"] = 0, ["z"] = 15, ["name"] = "default:cobble" },
{["x"] = 2, ["meta"] = { ["fields"] = {}, ["inventory"] = {} }, ["param2"] = 0, ["y"] = 9, ["param1"] = 0, ["z"] = 16, ["name"] = "default:cobble" },
{["x"] = 2, ["meta"] = { ["fields"] = {}, ["inventory"] = {} }, ["param2"] = 0, ["y"] = 9, ["param1"] = 0, ["z"] = 17, ["name"] = "default:cobble" },
{["x"] = 2, ["meta"] = { ["fields"] = {}, ["inventory"] = {} }, ["param2"] = 0, ["y"] = 10, ["param1"] = 0, ["z"] = 0, ["name"] = "default:cobble" },
{["x"] = 2, ["meta"] = { ["fields"] = {}, ["inventory"] = {} }, ["param2"] = 0, ["y"] = 10, ["param1"] = 0, ["z"] = 4, ["name"] = "default:cobble" },
{["x"] = 2, ["meta"] = { ["fields"] = {}, ["inventory"] = {} }, ["param2"] = 0, ["y"] = 10, ["param1"] = 0, ["z"] = 14, ["name"] = "default:cobble" },
{["x"] = 2, ["meta"] = { ["fields"] = {}, ["inventory"] = {} }, ["param2"] = 0, ["y"] = 10, ["param1"] = 0, ["z"] = 18, ["name"] = "default:cobble" },
{["x"] = 3, ["meta"] = { ["fields"] = {}, ["inventory"] = {} }, ["param2"] = 0, ["y"] = 0, ["param1"] = 29, ["z"] = 0, ["name"] = "lottother:snow" },
{["x"] = 3, ["meta"] = { ["fields"] = {}, ["inventory"] = {} }, ["param2"] = 0, ["y"] = 0, ["param1"] = 44, ["z"] = 1, ["name"] = "lottother:snow" },
{["x"] = 3, ["meta"] = { ["fields"] = {}, ["inventory"] = {} }, ["param2"] = 0, ["y"] = 0, ["param1"] = 27, ["z"] = 2, ["name"] = "lottother:snow" },
{["x"] = 3, ["meta"] = { ["fields"] = {}, ["inventory"] = {} }, ["param2"] = 0, ["y"] = 0, ["param1"] = 10, ["z"] = 3, ["name"] = "lottother:snow" },
{["x"] = 3, ["meta"] = { ["fields"] = {}, ["inventory"] = {} }, ["param2"] = 0, ["y"] = 0, ["param1"] = 10, ["z"] = 4, ["name"] = "lottother:snow" },
{["x"] = 3, ["meta"] = { ["fields"] = {}, ["inventory"] = {} }, ["param2"] = 0, ["y"] = 0, ["param1"] = 11, ["z"] = 5, ["name"] = "lottother:snow" },
{["x"] = 3, ["meta"] = { ["fields"] = {}, ["inventory"] = {} }, ["param2"] = 0, ["y"] = 0, ["param1"] = 11, ["z"] = 6, ["name"] = "lottother:snow" },
{["x"] = 3, ["meta"] = { ["fields"] = {}, ["inventory"] = {} }, ["param2"] = 0, ["y"] = 0, ["param1"] = 11, ["z"] = 7, ["name"] = "lottother:snow" },
{["x"] = 3, ["meta"] = { ["fields"] = {}, ["inventory"] = {} }, ["param2"] = 0, ["y"] = 0, ["param1"] = 11, ["z"] = 8, ["name"] = "lottother:snow" },
{["x"] = 3, ["meta"] = { ["fields"] = {}, ["inventory"] = {} }, ["param2"] = 0, ["y"] = 0, ["param1"] = 11, ["z"] = 9, ["name"] = "lottother:snow" },
{["x"] = 3, ["meta"] = { ["fields"] = {}, ["inventory"] = {} }, ["param2"] = 0, ["y"] = 0, ["param1"] = 11, ["z"] = 10, ["name"] = "lottother:snow" },
{["x"] = 3, ["meta"] = { ["fields"] = {}, ["inventory"] = {} }, ["param2"] = 0, ["y"] = 0, ["param1"] = 11, ["z"] = 11, ["name"] = "lottother:snow" },
{["x"] = 3, ["meta"] = { ["fields"] = {}, ["inventory"] = {} }, ["param2"] = 0, ["y"] = 0, ["param1"] = 11, ["z"] = 12, ["name"] = "lottother:snow" },
{["x"] = 3, ["meta"] = { ["fields"] = {}, ["inventory"] = {} }, ["param2"] = 0, ["y"] = 0, ["param1"] = 11, ["z"] = 13, ["name"] = "lottother:snow" },
{["x"] = 3, ["meta"] = { ["fields"] = {}, ["inventory"] = {} }, ["param2"] = 0, ["y"] = 0, ["param1"] = 10, ["z"] = 14, ["name"] = "lottother:snow" },
{["x"] = 3, ["meta"] = { ["fields"] = {}, ["inventory"] = {} }, ["param2"] = 0, ["y"] = 0, ["param1"] = 10, ["z"] = 15, ["name"] = "lottother:snow" },
{["x"] = 3, ["meta"] = { ["fields"] = {}, ["inventory"] = {} }, ["param2"] = 0, ["y"] = 0, ["param1"] = 11, ["z"] = 16, ["name"] = "lottother:snow" },
{["x"] = 3, ["meta"] = { ["fields"] = {}, ["inventory"] = {} }, ["param2"] = 0, ["y"] = 0, ["param1"] = 12, ["z"] = 17, ["name"] = "lottother:snow" },
{["x"] = 3, ["meta"] = { ["fields"] = {}, ["inventory"] = {} }, ["param2"] = 0, ["y"] = 0, ["param1"] = 29, ["z"] = 18, ["name"] = "lottother:snow" },
{["x"] = 3, ["meta"] = { ["fields"] = {}, ["inventory"] = {} }, ["param2"] = 0, ["y"] = 1, ["param1"] = 0, ["z"] = 1, ["name"] = "lottother:snow" },
{["x"] = 3, ["meta"] = { ["fields"] = {}, ["inventory"] = {} }, ["param2"] = 0, ["y"] = 1, ["param1"] = 75, ["z"] = 2, ["name"] = "lottother:snow" },
{["x"] = 3, ["meta"] = { ["fields"] = {}, ["inventory"] = {} }, ["param2"] = 0, ["y"] = 1, ["param1"] = 58, ["z"] = 3, ["name"] = "lottother:snow" },
{["x"] = 3, ["meta"] = { ["fields"] = {}, ["inventory"] = {} }, ["param2"] = 0, ["y"] = 1, ["param1"] = 43, ["z"] = 4, ["name"] = "lottother:snow" },
{["x"] = 3, ["meta"] = { ["fields"] = {}, ["inventory"] = {} }, ["param2"] = 0, ["y"] = 1, ["param1"] = 28, ["z"] = 5, ["name"] = "lottother:snow" },
{["x"] = 3, ["meta"] = { ["fields"] = {}, ["inventory"] = {} }, ["param2"] = 0, ["y"] = 1, ["param1"] = 12, ["z"] = 6, ["name"] = "lottother:snow" },
{["x"] = 3, ["meta"] = { ["fields"] = {}, ["inventory"] = {} }, ["param2"] = 0, ["y"] = 1, ["param1"] = 12, ["z"] = 7, ["name"] = "lottother:snow" },
{["x"] = 3, ["meta"] = { ["fields"] = {}, ["inventory"] = {} }, ["param2"] = 0, ["y"] = 1, ["param1"] = 12, ["z"] = 8, ["name"] = "lottother:snow" },
{["x"] = 3, ["meta"] = { ["fields"] = {}, ["inventory"] = {} }, ["param2"] = 0, ["y"] = 1, ["param1"] = 12, ["z"] = 9, ["name"] = "lottother:snow" },
{["x"] = 3, ["meta"] = { ["fields"] = {}, ["inventory"] = {} }, ["param2"] = 0, ["y"] = 1, ["param1"] = 12, ["z"] = 10, ["name"] = "lottother:snow" },
{["x"] = 3, ["meta"] = { ["fields"] = {}, ["inventory"] = {} }, ["param2"] = 0, ["y"] = 1, ["param1"] = 12, ["z"] = 11, ["name"] = "lottother:snow" },
{["x"] = 3, ["meta"] = { ["fields"] = {}, ["inventory"] = {} }, ["param2"] = 0, ["y"] = 1, ["param1"] = 12, ["z"] = 12, ["name"] = "lottother:snow" },
{["x"] = 3, ["meta"] = { ["fields"] = {}, ["inventory"] = {} }, ["param2"] = 0, ["y"] = 1, ["param1"] = 28, ["z"] = 13, ["name"] = "lottother:snow" },
{["x"] = 3, ["meta"] = { ["fields"] = {}, ["inventory"] = {} }, ["param2"] = 0, ["y"] = 1, ["param1"] = 43, ["z"] = 14, ["name"] = "lottother:snow" },
{["x"] = 3, ["meta"] = { ["fields"] = {}, ["inventory"] = {} }, ["param2"] = 0, ["y"] = 1, ["param1"] = 58, ["z"] = 15, ["name"] = "lottother:snow" },
{["x"] = 3, ["meta"] = { ["fields"] = {}, ["inventory"] = {} }, ["param2"] = 0, ["y"] = 1, ["param1"] = 75, ["z"] = 16, ["name"] = "lottother:snow" },
{["x"] = 3, ["meta"] = { ["fields"] = {}, ["inventory"] = {} }, ["param2"] = 0, ["y"] = 1, ["param1"] = 0, ["z"] = 17, ["name"] = "lottother:snow" },
{["x"] = 3, ["meta"] = { ["fields"] = {}, ["inventory"] = {} }, ["param2"] = 0, ["y"] = 2, ["param1"] = 0, ["z"] = 2, ["name"] = "default:cobble" },
{["x"] = 3, ["meta"] = { ["fields"] = {}, ["inventory"] = {} }, ["param2"] = 0, ["y"] = 2, ["param1"] = 0, ["z"] = 3, ["name"] = "lottblocks:orc_brick" },
{["x"] = 3, ["meta"] = { ["fields"] = {}, ["inventory"] = {} }, ["param2"] = 0, ["y"] = 2, ["param1"] = 0, ["z"] = 4, ["name"] = "lottblocks:orc_brick" },
{["x"] = 3, ["meta"] = { ["fields"] = {}, ["inventory"] = {} }, ["param2"] = 0, ["y"] = 2, ["param1"] = 0, ["z"] = 5, ["name"] = "default:cobble" },
{["x"] = 3, ["meta"] = { ["fields"] = {}, ["inventory"] = {} }, ["param2"] = 0, ["y"] = 2, ["param1"] = 0, ["z"] = 6, ["name"] = "default:cobble" },
{["x"] = 3, ["meta"] = { ["fields"] = {}, ["inventory"] = {} }, ["param2"] = 0, ["y"] = 2, ["param1"] = 0, ["z"] = 7, ["name"] = "default:cobble" },
{["x"] = 3, ["meta"] = { ["fields"] = {}, ["inventory"] = {} }, ["param2"] = 0, ["y"] = 2, ["param1"] = 0, ["z"] = 8, ["name"] = "default:cobble" },
{["x"] = 3, ["meta"] = { ["fields"] = {}, ["inventory"] = {} }, ["param2"] = 0, ["y"] = 2, ["param1"] = 0, ["z"] = 9, ["name"] = "default:cobble" },
{["x"] = 3, ["meta"] = { ["fields"] = {}, ["inventory"] = {} }, ["param2"] = 0, ["y"] = 2, ["param1"] = 0, ["z"] = 10, ["name"] = "default:cobble" },
{["x"] = 3, ["meta"] = { ["fields"] = {}, ["inventory"] = {} }, ["param2"] = 0, ["y"] = 2, ["param1"] = 0, ["z"] = 11, ["name"] = "default:cobble" },
{["x"] = 3, ["meta"] = { ["fields"] = {}, ["inventory"] = {} }, ["param2"] = 0, ["y"] = 2, ["param1"] = 0, ["z"] = 12, ["name"] = "default:cobble" },
{["x"] = 3, ["meta"] = { ["fields"] = {}, ["inventory"] = {} }, ["param2"] = 0, ["y"] = 2, ["param1"] = 0, ["z"] = 13, ["name"] = "default:cobble" },
{["x"] = 3, ["meta"] = { ["fields"] = {}, ["inventory"] = {} }, ["param2"] = 0, ["y"] = 2, ["param1"] = 0, ["z"] = 14, ["name"] = "lottblocks:orc_brick" },
{["x"] = 3, ["meta"] = { ["fields"] = {}, ["inventory"] = {} }, ["param2"] = 0, ["y"] = 2, ["param1"] = 0, ["z"] = 15, ["name"] = "lottblocks:orc_brick" },
{["x"] = 3, ["meta"] = { ["fields"] = {}, ["inventory"] = {} }, ["param2"] = 0, ["y"] = 2, ["param1"] = 0, ["z"] = 16, ["name"] = "default:cobble" },
{["x"] = 3, ["meta"] = { ["fields"] = {}, ["inventory"] = {} }, ["param2"] = 0, ["y"] = 3, ["param1"] = 0, ["z"] = 2, ["name"] = "default:cobble" },
{["x"] = 3, ["meta"] = { ["fields"] = {}, ["inventory"] = {} }, ["param2"] = 5, ["y"] = 3, ["param1"] = 153, ["z"] = 3, ["name"] = "default:ladder" },
{["x"] = 3, ["meta"] = { ["fields"] = {}, ["inventory"] = {} }, ["param2"] = 0, ["y"] = 3, ["param1"] = 170, ["z"] = 4, ["name"] = "lottother:air" },
{["x"] = 3, ["meta"] = { ["fields"] = {}, ["inventory"] = {} }, ["param2"] = 0, ["y"] = 3, ["param1"] = 0, ["z"] = 5, ["name"] = "default:cobble" },
{["x"] = 3, ["meta"] = { ["fields"] = {}, ["inventory"] = {} }, ["param2"] = 0, ["y"] = 3, ["param1"] = 0, ["z"] = 6, ["name"] = "default:cobble" },
{["x"] = 3, ["meta"] = { ["fields"] = {}, ["inventory"] = {} }, ["param2"] = 0, ["y"] = 3, ["param1"] = 0, ["z"] = 7, ["name"] = "default:cobble" },
{["x"] = 3, ["meta"] = { ["fields"] = {}, ["inventory"] = {} }, ["param2"] = 0, ["y"] = 3, ["param1"] = 0, ["z"] = 8, ["name"] = "default:cobble" },
{["x"] = 3, ["meta"] = { ["fields"] = {}, ["inventory"] = {} }, ["param2"] = 0, ["y"] = 3, ["param1"] = 0, ["z"] = 9, ["name"] = "default:cobble" },
{["x"] = 3, ["meta"] = { ["fields"] = {}, ["inventory"] = {} }, ["param2"] = 0, ["y"] = 3, ["param1"] = 0, ["z"] = 10, ["name"] = "default:cobble" },
{["x"] = 3, ["meta"] = { ["fields"] = {}, ["inventory"] = {} }, ["param2"] = 0, ["y"] = 3, ["param1"] = 0, ["z"] = 11, ["name"] = "default:cobble" },
{["x"] = 3, ["meta"] = { ["fields"] = {}, ["inventory"] = {} }, ["param2"] = 0, ["y"] = 3, ["param1"] = 0, ["z"] = 12, ["name"] = "default:cobble" },
{["x"] = 3, ["meta"] = { ["fields"] = {}, ["inventory"] = {} }, ["param2"] = 0, ["y"] = 3, ["param1"] = 0, ["z"] = 13, ["name"] = "default:cobble" },
{["x"] = 3, ["meta"] = { ["fields"] = {}, ["inventory"] = {} }, ["param2"] = 0, ["y"] = 3, ["param1"] = 170, ["z"] = 14, ["name"] = "lottother:air" },
{["x"] = 3, ["meta"] = { ["fields"] = {}, ["inventory"] = {} }, ["param2"] = 4, ["y"] = 3, ["param1"] = 153, ["z"] = 15, ["name"] = "default:ladder" },
{["x"] = 3, ["meta"] = { ["fields"] = {}, ["inventory"] = {} }, ["param2"] = 0, ["y"] = 3, ["param1"] = 0, ["z"] = 16, ["name"] = "default:cobble" },
{["x"] = 3, ["meta"] = { ["fields"] = {}, ["inventory"] = {} }, ["param2"] = 0, ["y"] = 4, ["param1"] = 0, ["z"] = 2, ["name"] = "default:cobble" },
{["x"] = 3, ["meta"] = { ["fields"] = {}, ["inventory"] = {} }, ["param2"] = 5, ["y"] = 4, ["param1"] = 170, ["z"] = 3, ["name"] = "default:ladder" },
{["x"] = 3, ["meta"] = { ["fields"] = {}, ["inventory"] = {} }, ["param2"] = 4, ["y"] = 4, ["param1"] = 0, ["z"] = 4, ["name"] = "lottother:orc_torch" },
{["x"] = 3, ["meta"] = { ["fields"] = {}, ["inventory"] = {} }, ["param2"] = 0, ["y"] = 4, ["param1"] = 0, ["z"] = 5, ["name"] = "default:cobble" },
{["x"] = 3, ["meta"] = { ["fields"] = {}, ["inventory"] = {} }, ["param2"] = 0, ["y"] = 4, ["param1"] = 0, ["z"] = 6, ["name"] = "default:cobble" },
{["x"] = 3, ["meta"] = { ["fields"] = {}, ["inventory"] = {} }, ["param2"] = 0, ["y"] = 4, ["param1"] = 0, ["z"] = 7, ["name"] = "default:cobble" },
{["x"] = 3, ["meta"] = { ["fields"] = {}, ["inventory"] = {} }, ["param2"] = 0, ["y"] = 4, ["param1"] = 0, ["z"] = 8, ["name"] = "default:cobble" },
{["x"] = 3, ["meta"] = { ["fields"] = {}, ["inventory"] = {} }, ["param2"] = 0, ["y"] = 4, ["param1"] = 0, ["z"] = 9, ["name"] = "default:cobble" },
{["x"] = 3, ["meta"] = { ["fields"] = {}, ["inventory"] = {} }, ["param2"] = 0, ["y"] = 4, ["param1"] = 0, ["z"] = 10, ["name"] = "default:cobble" },
{["x"] = 3, ["meta"] = { ["fields"] = {}, ["inventory"] = {} }, ["param2"] = 0, ["y"] = 4, ["param1"] = 0, ["z"] = 11, ["name"] = "default:cobble" },
{["x"] = 3, ["meta"] = { ["fields"] = {}, ["inventory"] = {} }, ["param2"] = 0, ["y"] = 4, ["param1"] = 0, ["z"] = 12, ["name"] = "default:cobble" },
{["x"] = 3, ["meta"] = { ["fields"] = {}, ["inventory"] = {} }, ["param2"] = 0, ["y"] = 4, ["param1"] = 0, ["z"] = 13, ["name"] = "default:cobble" },
{["x"] = 3, ["meta"] = { ["fields"] = {}, ["inventory"] = {} }, ["param2"] = 5, ["y"] = 4, ["param1"] = 0, ["z"] = 14, ["name"] = "lottother:orc_torch" },
{["x"] = 3, ["meta"] = { ["fields"] = {}, ["inventory"] = {} }, ["param2"] = 4, ["y"] = 4, ["param1"] = 170, ["z"] = 15, ["name"] = "default:ladder" },
{["x"] = 3, ["meta"] = { ["fields"] = {}, ["inventory"] = {} }, ["param2"] = 0, ["y"] = 4, ["param1"] = 0, ["z"] = 16, ["name"] = "default:cobble" },
{["x"] = 3, ["meta"] = { ["fields"] = {}, ["inventory"] = {} }, ["param2"] = 0, ["y"] = 5, ["param1"] = 0, ["z"] = 2, ["name"] = "default:cobble" },
{["x"] = 3, ["meta"] = { ["fields"] = {}, ["inventory"] = {} }, ["param2"] = 5, ["y"] = 5, ["param1"] = 153, ["z"] = 3, ["name"] = "default:ladder" },
{["x"] = 3, ["meta"] = { ["fields"] = {}, ["inventory"] = {} }, ["param2"] = 0, ["y"] = 5, ["param1"] = 0, ["z"] = 4, ["name"] = "default:cobble" },
{["x"] = 3, ["meta"] = { ["fields"] = {}, ["inventory"] = {} }, ["param2"] = 0, ["y"] = 5, ["param1"] = 0, ["z"] = 5, ["name"] = "default:cobble" },
{["x"] = 3, ["meta"] = { ["fields"] = {}, ["inventory"] = {} }, ["param2"] = 0, ["y"] = 5, ["param1"] = 0, ["z"] = 6, ["name"] = "default:cobble" },
{["x"] = 3, ["meta"] = { ["fields"] = {}, ["inventory"] = {} }, ["param2"] = 0, ["y"] = 5, ["param1"] = 0, ["z"] = 7, ["name"] = "default:cobble" },
{["x"] = 3, ["meta"] = { ["fields"] = {}, ["inventory"] = {} }, ["param2"] = 0, ["y"] = 5, ["param1"] = 0, ["z"] = 8, ["name"] = "default:cobble" },
{["x"] = 3, ["meta"] = { ["fields"] = {}, ["inventory"] = {} }, ["param2"] = 0, ["y"] = 5, ["param1"] = 0, ["z"] = 9, ["name"] = "default:cobble" },
{["x"] = 3, ["meta"] = { ["fields"] = {}, ["inventory"] = {} }, ["param2"] = 0, ["y"] = 5, ["param1"] = 0, ["z"] = 10, ["name"] = "default:cobble" },
{["x"] = 3, ["meta"] = { ["fields"] = {}, ["inventory"] = {} }, ["param2"] = 0, ["y"] = 5, ["param1"] = 0, ["z"] = 11, ["name"] = "default:cobble" },
{["x"] = 3, ["meta"] = { ["fields"] = {}, ["inventory"] = {} }, ["param2"] = 0, ["y"] = 5, ["param1"] = 0, ["z"] = 12, ["name"] = "default:cobble" },
{["x"] = 3, ["meta"] = { ["fields"] = {}, ["inventory"] = {} }, ["param2"] = 0, ["y"] = 5, ["param1"] = 0, ["z"] = 13, ["name"] = "default:cobble" },
{["x"] = 3, ["meta"] = { ["fields"] = {}, ["inventory"] = {} }, ["param2"] = 0, ["y"] = 5, ["param1"] = 0, ["z"] = 14, ["name"] = "default:cobble" },
{["x"] = 3, ["meta"] = { ["fields"] = {}, ["inventory"] = {} }, ["param2"] = 4, ["y"] = 5, ["param1"] = 153, ["z"] = 15, ["name"] = "default:ladder" },
{["x"] = 3, ["meta"] = { ["fields"] = {}, ["inventory"] = {} }, ["param2"] = 0, ["y"] = 5, ["param1"] = 0, ["z"] = 16, ["name"] = "default:cobble" },
{["x"] = 3, ["meta"] = { ["fields"] = {}, ["inventory"] = {} }, ["param2"] = 0, ["y"] = 6, ["param1"] = 0, ["z"] = 2, ["name"] = "default:cobble" },
{["x"] = 3, ["meta"] = { ["fields"] = {}, ["inventory"] = {} }, ["param2"] = 5, ["y"] = 6, ["param1"] = 138, ["z"] = 3, ["name"] = "default:ladder" },
{["x"] = 3, ["meta"] = { ["fields"] = {}, ["inventory"] = {} }, ["param2"] = 0, ["y"] = 6, ["param1"] = 0, ["z"] = 4, ["name"] = "default:cobble" },
{["x"] = 3, ["meta"] = { ["fields"] = {}, ["inventory"] = {} }, ["param2"] = 0, ["y"] = 6, ["param1"] = 0, ["z"] = 14, ["name"] = "default:cobble" },
{["x"] = 3, ["meta"] = { ["fields"] = {}, ["inventory"] = {} }, ["param2"] = 4, ["y"] = 6, ["param1"] = 138, ["z"] = 15, ["name"] = "default:ladder" },
{["x"] = 3, ["meta"] = { ["fields"] = {}, ["inventory"] = {} }, ["param2"] = 0, ["y"] = 6, ["param1"] = 0, ["z"] = 16, ["name"] = "default:cobble" },
{["x"] = 3, ["meta"] = { ["fields"] = {}, ["inventory"] = {} }, ["param2"] = 0, ["y"] = 7, ["param1"] = 0, ["z"] = 2, ["name"] = "default:cobble" },
{["x"] = 3, ["meta"] = { ["fields"] = {}, ["inventory"] = {} }, ["param2"] = 5, ["y"] = 7, ["param1"] = 123, ["z"] = 3, ["name"] = "default:ladder" },
{["x"] = 3, ["meta"] = { ["fields"] = {}, ["inventory"] = {} }, ["param2"] = 0, ["y"] = 7, ["param1"] = 0, ["z"] = 4, ["name"] = "default:cobble" },
{["x"] = 3, ["meta"] = { ["fields"] = {}, ["inventory"] = {} }, ["param2"] = 0, ["y"] = 7, ["param1"] = 0, ["z"] = 14, ["name"] = "default:cobble" },
{["x"] = 3, ["meta"] = { ["fields"] = {}, ["inventory"] = {} }, ["param2"] = 4, ["y"] = 7, ["param1"] = 123, ["z"] = 15, ["name"] = "default:ladder" },
{["x"] = 3, ["meta"] = { ["fields"] = {}, ["inventory"] = {} }, ["param2"] = 0, ["y"] = 7, ["param1"] = 0, ["z"] = 16, ["name"] = "default:cobble" },
{["x"] = 3, ["meta"] = { ["fields"] = {}, ["inventory"] = {} }, ["param2"] = 0, ["y"] = 8, ["param1"] = 0, ["z"] = 2, ["name"] = "default:cobble" },
{["x"] = 3, ["meta"] = { ["fields"] = {}, ["inventory"] = {} }, ["param2"] = 5, ["y"] = 8, ["param1"] = 108, ["z"] = 3, ["name"] = "default:ladder" },
{["x"] = 3, ["meta"] = { ["fields"] = {}, ["inventory"] = {} }, ["param2"] = 0, ["y"] = 8, ["param1"] = 0, ["z"] = 4, ["name"] = "default:cobble" },
{["x"] = 3, ["meta"] = { ["fields"] = {}, ["inventory"] = {} }, ["param2"] = 0, ["y"] = 8, ["param1"] = 0, ["z"] = 14, ["name"] = "default:cobble" },
{["x"] = 3, ["meta"] = { ["fields"] = {}, ["inventory"] = {} }, ["param2"] = 4, ["y"] = 8, ["param1"] = 108, ["z"] = 15, ["name"] = "default:ladder" },
{["x"] = 3, ["meta"] = { ["fields"] = {}, ["inventory"] = {} }, ["param2"] = 0, ["y"] = 8, ["param1"] = 0, ["z"] = 16, ["name"] = "default:cobble" },
{["x"] = 3, ["meta"] = { ["fields"] = {}, ["inventory"] = {} }, ["param2"] = 0, ["y"] = 9, ["param1"] = 0, ["z"] = 0, ["name"] = "default:cobble" },
{["x"] = 3, ["meta"] = { ["fields"] = {}, ["inventory"] = {} }, ["param2"] = 0, ["y"] = 9, ["param1"] = 0, ["z"] = 1, ["name"] = "default:cobble" },
{["x"] = 3, ["meta"] = { ["fields"] = {}, ["inventory"] = {} }, ["param2"] = 0, ["y"] = 9, ["param1"] = 0, ["z"] = 2, ["name"] = "default:cobble" },
{["x"] = 3, ["meta"] = { ["fields"] = {}, ["inventory"] = {} }, ["param2"] = 5, ["y"] = 9, ["param1"] = 93, ["z"] = 3, ["name"] = "default:ladder" },
{["x"] = 3, ["meta"] = { ["fields"] = {}, ["inventory"] = {} }, ["param2"] = 0, ["y"] = 9, ["param1"] = 0, ["z"] = 4, ["name"] = "default:cobble" },
{["x"] = 3, ["meta"] = { ["fields"] = {}, ["inventory"] = {} }, ["param2"] = 0, ["y"] = 9, ["param1"] = 0, ["z"] = 14, ["name"] = "default:cobble" },
{["x"] = 3, ["meta"] = { ["fields"] = {}, ["inventory"] = {} }, ["param2"] = 4, ["y"] = 9, ["param1"] = 93, ["z"] = 15, ["name"] = "default:ladder" },
{["x"] = 3, ["meta"] = { ["fields"] = {}, ["inventory"] = {} }, ["param2"] = 0, ["y"] = 9, ["param1"] = 0, ["z"] = 16, ["name"] = "default:cobble" },
{["x"] = 3, ["meta"] = { ["fields"] = {}, ["inventory"] = {} }, ["param2"] = 0, ["y"] = 9, ["param1"] = 0, ["z"] = 17, ["name"] = "default:cobble" },
{["x"] = 3, ["meta"] = { ["fields"] = {}, ["inventory"] = {} }, ["param2"] = 0, ["y"] = 9, ["param1"] = 0, ["z"] = 18, ["name"] = "default:cobble" },
{["x"] = 4, ["meta"] = { ["fields"] = {}, ["inventory"] = {} }, ["param2"] = 0, ["y"] = 0, ["param1"] = 45, ["z"] = 0, ["name"] = "lottother:snow" },
{["x"] = 4, ["meta"] = { ["fields"] = {}, ["inventory"] = {} }, ["param2"] = 0, ["y"] = 0, ["param1"] = 60, ["z"] = 1, ["name"] = "lottother:snow" },
{["x"] = 4, ["meta"] = { ["fields"] = {}, ["inventory"] = {} }, ["param2"] = 0, ["y"] = 0, ["param1"] = 43, ["z"] = 2, ["name"] = "lottother:snow" },
{["x"] = 4, ["meta"] = { ["fields"] = {}, ["inventory"] = {} }, ["param2"] = 0, ["y"] = 0, ["param1"] = 26, ["z"] = 3, ["name"] = "lottother:snow" },
{["x"] = 4, ["meta"] = { ["fields"] = {}, ["inventory"] = {} }, ["param2"] = 0, ["y"] = 0, ["param1"] = 9, ["z"] = 4, ["name"] = "lottother:snow" },
{["x"] = 4, ["meta"] = { ["fields"] = {}, ["inventory"] = {} }, ["param2"] = 0, ["y"] = 0, ["param1"] = 10, ["z"] = 5, ["name"] = "lottother:snow" },
{["x"] = 4, ["meta"] = { ["fields"] = {}, ["inventory"] = {} }, ["param2"] = 0, ["y"] = 0, ["param1"] = 10, ["z"] = 6, ["name"] = "lottother:snow" },
{["x"] = 4, ["meta"] = { ["fields"] = {}, ["inventory"] = {} }, ["param2"] = 0, ["y"] = 0, ["param1"] = 10, ["z"] = 7, ["name"] = "lottother:snow" },
{["x"] = 4, ["meta"] = { ["fields"] = {}, ["inventory"] = {} }, ["param2"] = 0, ["y"] = 0, ["param1"] = 10, ["z"] = 8, ["name"] = "lottother:snow" },
{["x"] = 4, ["meta"] = { ["fields"] = {}, ["inventory"] = {} }, ["param2"] = 0, ["y"] = 0, ["param1"] = 10, ["z"] = 9, ["name"] = "lottother:snow" },
{["x"] = 4, ["meta"] = { ["fields"] = {}, ["inventory"] = {} }, ["param2"] = 0, ["y"] = 0, ["param1"] = 10, ["z"] = 10, ["name"] = "lottother:snow" },
{["x"] = 4, ["meta"] = { ["fields"] = {}, ["inventory"] = {} }, ["param2"] = 0, ["y"] = 0, ["param1"] = 10, ["z"] = 11, ["name"] = "lottother:snow" },
{["x"] = 4, ["meta"] = { ["fields"] = {}, ["inventory"] = {} }, ["param2"] = 0, ["y"] = 0, ["param1"] = 10, ["z"] = 12, ["name"] = "lottother:snow" },
{["x"] = 4, ["meta"] = { ["fields"] = {}, ["inventory"] = {} }, ["param2"] = 0, ["y"] = 0, ["param1"] = 10, ["z"] = 13, ["name"] = "lottother:snow" },
{["x"] = 4, ["meta"] = { ["fields"] = {}, ["inventory"] = {} }, ["param2"] = 0, ["y"] = 0, ["param1"] = 9, ["z"] = 14, ["name"] = "lottother:snow" },
{["x"] = 4, ["meta"] = { ["fields"] = {}, ["inventory"] = {} }, ["param2"] = 0, ["y"] = 0, ["param1"] = 10, ["z"] = 15, ["name"] = "lottother:snow" },
{["x"] = 4, ["meta"] = { ["fields"] = {}, ["inventory"] = {} }, ["param2"] = 0, ["y"] = 0, ["param1"] = 11, ["z"] = 16, ["name"] = "lottother:snow" },
{["x"] = 4, ["meta"] = { ["fields"] = {}, ["inventory"] = {} }, ["param2"] = 0, ["y"] = 0, ["param1"] = 28, ["z"] = 17, ["name"] = "lottother:snow" },
{["x"] = 4, ["meta"] = { ["fields"] = {}, ["inventory"] = {} }, ["param2"] = 0, ["y"] = 0, ["param1"] = 45, ["z"] = 18, ["name"] = "lottother:snow" },
{["x"] = 4, ["meta"] = { ["fields"] = {}, ["inventory"] = {} }, ["param2"] = 0, ["y"] = 1, ["param1"] = 0, ["z"] = 1, ["name"] = "lottother:snow" },
{["x"] = 4, ["meta"] = { ["fields"] = {}, ["inventory"] = {} }, ["param2"] = 0, ["y"] = 1, ["param1"] = 92, ["z"] = 2, ["name"] = "lottother:snow" },
{["x"] = 4, ["meta"] = { ["fields"] = {}, ["inventory"] = {} }, ["param2"] = 0, ["y"] = 1, ["param1"] = 75, ["z"] = 3, ["name"] = "lottother:snow" },
{["x"] = 4, ["meta"] = { ["fields"] = {}, ["inventory"] = {} }, ["param2"] = 0, ["y"] = 1, ["param1"] = 58, ["z"] = 4, ["name"] = "lottother:snow" },
{["x"] = 4, ["meta"] = { ["fields"] = {}, ["inventory"] = {} }, ["param2"] = 0, ["y"] = 1, ["param1"] = 43, ["z"] = 5, ["name"] = "lottother:snow" },
{["x"] = 4, ["meta"] = { ["fields"] = {}, ["inventory"] = {} }, ["param2"] = 0, ["y"] = 1, ["param1"] = 27, ["z"] = 6, ["name"] = "lottother:snow" },
{["x"] = 4, ["meta"] = { ["fields"] = {}, ["inventory"] = {} }, ["param2"] = 0, ["y"] = 1, ["param1"] = 11, ["z"] = 7, ["name"] = "lottother:snow" },
{["x"] = 4, ["meta"] = { ["fields"] = {}, ["inventory"] = {} }, ["param2"] = 0, ["y"] = 1, ["param1"] = 11, ["z"] = 8, ["name"] = "lottother:snow" },
{["x"] = 4, ["meta"] = { ["fields"] = {}, ["inventory"] = {} }, ["param2"] = 0, ["y"] = 1, ["param1"] = 11, ["z"] = 9, ["name"] = "lottother:snow" },
{["x"] = 4, ["meta"] = { ["fields"] = {}, ["inventory"] = {} }, ["param2"] = 0, ["y"] = 1, ["param1"] = 11, ["z"] = 10, ["name"] = "lottother:snow" },
{["x"] = 4, ["meta"] = { ["fields"] = {}, ["inventory"] = {} }, ["param2"] = 0, ["y"] = 1, ["param1"] = 11, ["z"] = 11, ["name"] = "lottother:snow" },
{["x"] = 4, ["meta"] = { ["fields"] = {}, ["inventory"] = {} }, ["param2"] = 0, ["y"] = 1, ["param1"] = 27, ["z"] = 12, ["name"] = "lottother:snow" },
{["x"] = 4, ["meta"] = { ["fields"] = {}, ["inventory"] = {} }, ["param2"] = 0, ["y"] = 1, ["param1"] = 43, ["z"] = 13, ["name"] = "lottother:snow" },
{["x"] = 4, ["meta"] = { ["fields"] = {}, ["inventory"] = {} }, ["param2"] = 0, ["y"] = 1, ["param1"] = 58, ["z"] = 14, ["name"] = "lottother:snow" },
{["x"] = 4, ["meta"] = { ["fields"] = {}, ["inventory"] = {} }, ["param2"] = 0, ["y"] = 1, ["param1"] = 75, ["z"] = 15, ["name"] = "lottother:snow" },
{["x"] = 4, ["meta"] = { ["fields"] = {}, ["inventory"] = {} }, ["param2"] = 0, ["y"] = 1, ["param1"] = 92, ["z"] = 16, ["name"] = "lottother:snow" },
{["x"] = 4, ["meta"] = { ["fields"] = {}, ["inventory"] = {} }, ["param2"] = 0, ["y"] = 1, ["param1"] = 0, ["z"] = 17, ["name"] = "lottother:snow" },
{["x"] = 4, ["meta"] = { ["fields"] = {}, ["inventory"] = {} }, ["param2"] = 0, ["y"] = 2, ["param1"] = 0, ["z"] = 2, ["name"] = "default:cobble" },
{["x"] = 4, ["meta"] = { ["fields"] = {}, ["inventory"] = {} }, ["param2"] = 0, ["y"] = 2, ["param1"] = 0, ["z"] = 3, ["name"] = "default:cobble" },
{["x"] = 4, ["meta"] = { ["fields"] = {}, ["inventory"] = {} }, ["param2"] = 0, ["y"] = 2, ["param1"] = 0, ["z"] = 4, ["name"] = "lottblocks:orc_brick" },
{["x"] = 4, ["meta"] = { ["fields"] = {}, ["inventory"] = {} }, ["param2"] = 0, ["y"] = 2, ["param1"] = 0, ["z"] = 5, ["name"] = "default:cobble" },
{["x"] = 4, ["meta"] = { ["fields"] = {}, ["inventory"] = {} }, ["param2"] = 0, ["y"] = 2, ["param1"] = 0, ["z"] = 6, ["name"] = "default:cobble" },
{["x"] = 4, ["meta"] = { ["fields"] = {}, ["inventory"] = {} }, ["param2"] = 0, ["y"] = 2, ["param1"] = 0, ["z"] = 7, ["name"] = "default:cobble" },
{["x"] = 4, ["meta"] = { ["fields"] = {}, ["inventory"] = {} }, ["param2"] = 0, ["y"] = 2, ["param1"] = 0, ["z"] = 8, ["name"] = "default:cobble" },
{["x"] = 4, ["meta"] = { ["fields"] = {}, ["inventory"] = {} }, ["param2"] = 0, ["y"] = 2, ["param1"] = 0, ["z"] = 9, ["name"] = "default:cobble" },
{["x"] = 4, ["meta"] = { ["fields"] = {}, ["inventory"] = {} }, ["param2"] = 0, ["y"] = 2, ["param1"] = 0, ["z"] = 10, ["name"] = "default:cobble" },
{["x"] = 4, ["meta"] = { ["fields"] = {}, ["inventory"] = {} }, ["param2"] = 0, ["y"] = 2, ["param1"] = 0, ["z"] = 11, ["name"] = "default:cobble" },
{["x"] = 4, ["meta"] = { ["fields"] = {}, ["inventory"] = {} }, ["param2"] = 0, ["y"] = 2, ["param1"] = 0, ["z"] = 12, ["name"] = "default:cobble" },
{["x"] = 4, ["meta"] = { ["fields"] = {}, ["inventory"] = {} }, ["param2"] = 0, ["y"] = 2, ["param1"] = 0, ["z"] = 13, ["name"] = "default:cobble" },
{["x"] = 4, ["meta"] = { ["fields"] = {}, ["inventory"] = {} }, ["param2"] = 0, ["y"] = 2, ["param1"] = 0, ["z"] = 14, ["name"] = "lottblocks:orc_brick" },
{["x"] = 4, ["meta"] = { ["fields"] = {}, ["inventory"] = {} }, ["param2"] = 0, ["y"] = 2, ["param1"] = 0, ["z"] = 15, ["name"] = "default:cobble" },
{["x"] = 4, ["meta"] = { ["fields"] = {}, ["inventory"] = {} }, ["param2"] = 0, ["y"] = 2, ["param1"] = 0, ["z"] = 16, ["name"] = "default:cobble" },
{["x"] = 4, ["meta"] = { ["fields"] = {}, ["inventory"] = {} }, ["param2"] = 0, ["y"] = 3, ["param1"] = 0, ["z"] = 2, ["name"] = "default:cobble" },
{["x"] = 4, ["meta"] = { ["fields"] = {}, ["inventory"] = {} }, ["param2"] = 0, ["y"] = 3, ["param1"] = 0, ["z"] = 3, ["name"] = "default:cobble" },
{["x"] = 4, ["meta"] = { ["fields"] = {}, ["inventory"] = {} }, ["param2"] = 0, ["y"] = 3, ["param1"] = 153, ["z"] = 4, ["name"] = "lottother:air" },
{["x"] = 4, ["meta"] = { ["fields"] = {}, ["inventory"] = {} }, ["param2"] = 0, ["y"] = 3, ["param1"] = 0, ["z"] = 5, ["name"] = "default:cobble" },
{["x"] = 4, ["meta"] = { ["fields"] = {}, ["inventory"] = {} }, ["param2"] = 0, ["y"] = 3, ["param1"] = 0, ["z"] = 6, ["name"] = "default:cobble" },
{["x"] = 4, ["meta"] = { ["fields"] = {}, ["inventory"] = {} }, ["param2"] = 0, ["y"] = 3, ["param1"] = 0, ["z"] = 7, ["name"] = "default:cobble" },
{["x"] = 4, ["meta"] = { ["fields"] = {}, ["inventory"] = {} }, ["param2"] = 0, ["y"] = 3, ["param1"] = 0, ["z"] = 8, ["name"] = "default:cobble" },
{["x"] = 4, ["meta"] = { ["fields"] = {}, ["inventory"] = {} }, ["param2"] = 0, ["y"] = 3, ["param1"] = 0, ["z"] = 9, ["name"] = "default:cobble" },
{["x"] = 4, ["meta"] = { ["fields"] = {}, ["inventory"] = {} }, ["param2"] = 0, ["y"] = 3, ["param1"] = 0, ["z"] = 10, ["name"] = "default:cobble" },
{["x"] = 4, ["meta"] = { ["fields"] = {}, ["inventory"] = {} }, ["param2"] = 0, ["y"] = 3, ["param1"] = 0, ["z"] = 11, ["name"] = "default:cobble" },
{["x"] = 4, ["meta"] = { ["fields"] = {}, ["inventory"] = {} }, ["param2"] = 0, ["y"] = 3, ["param1"] = 0, ["z"] = 12, ["name"] = "default:cobble" },
{["x"] = 4, ["meta"] = { ["fields"] = {}, ["inventory"] = {} }, ["param2"] = 0, ["y"] = 3, ["param1"] = 0, ["z"] = 13, ["name"] = "default:cobble" },
{["x"] = 4, ["meta"] = { ["fields"] = {}, ["inventory"] = {} }, ["param2"] = 0, ["y"] = 3, ["param1"] = 153, ["z"] = 14, ["name"] = "lottother:air" },
{["x"] = 4, ["meta"] = { ["fields"] = {}, ["inventory"] = {} }, ["param2"] = 0, ["y"] = 3, ["param1"] = 0, ["z"] = 15, ["name"] = "default:cobble" },
{["x"] = 4, ["meta"] = { ["fields"] = {}, ["inventory"] = {} }, ["param2"] = 0, ["y"] = 3, ["param1"] = 0, ["z"] = 16, ["name"] = "default:cobble" },
{["x"] = 4, ["meta"] = { ["fields"] = {}, ["inventory"] = {} }, ["param2"] = 0, ["y"] = 4, ["param1"] = 0, ["z"] = 2, ["name"] = "default:cobble" },
{["x"] = 4, ["meta"] = { ["fields"] = {}, ["inventory"] = {} }, ["param2"] = 0, ["y"] = 4, ["param1"] = 0, ["z"] = 3, ["name"] = "default:cobble" },
{["x"] = 4, ["meta"] = { ["fields"] = {}, ["inventory"] = {} }, ["param2"] = 0, ["y"] = 4, ["param1"] = 170, ["z"] = 4, ["name"] = "lottother:air" },
{["x"] = 4, ["meta"] = { ["fields"] = {}, ["inventory"] = {} }, ["param2"] = 0, ["y"] = 4, ["param1"] = 0, ["z"] = 5, ["name"] = "default:cobble" },
{["x"] = 4, ["meta"] = { ["fields"] = {}, ["inventory"] = {} }, ["param2"] = 0, ["y"] = 4, ["param1"] = 0, ["z"] = 6, ["name"] = "default:cobble" },
{["x"] = 4, ["meta"] = { ["fields"] = {}, ["inventory"] = {} }, ["param2"] = 0, ["y"] = 4, ["param1"] = 0, ["z"] = 7, ["name"] = "default:cobble" },
{["x"] = 4, ["meta"] = { ["fields"] = {}, ["inventory"] = {} }, ["param2"] = 0, ["y"] = 4, ["param1"] = 0, ["z"] = 8, ["name"] = "default:cobble" },
{["x"] = 4, ["meta"] = { ["fields"] = {}, ["inventory"] = {} }, ["param2"] = 0, ["y"] = 4, ["param1"] = 0, ["z"] = 9, ["name"] = "default:cobble" },
{["x"] = 4, ["meta"] = { ["fields"] = {}, ["inventory"] = {} }, ["param2"] = 0, ["y"] = 4, ["param1"] = 0, ["z"] = 10, ["name"] = "default:cobble" },
{["x"] = 4, ["meta"] = { ["fields"] = {}, ["inventory"] = {} }, ["param2"] = 0, ["y"] = 4, ["param1"] = 0, ["z"] = 11, ["name"] = "default:cobble" },
{["x"] = 4, ["meta"] = { ["fields"] = {}, ["inventory"] = {} }, ["param2"] = 0, ["y"] = 4, ["param1"] = 0, ["z"] = 12, ["name"] = "default:cobble" },
{["x"] = 4, ["meta"] = { ["fields"] = {}, ["inventory"] = {} }, ["param2"] = 0, ["y"] = 4, ["param1"] = 0, ["z"] = 13, ["name"] = "default:cobble" },
{["x"] = 4, ["meta"] = { ["fields"] = {}, ["inventory"] = {} }, ["param2"] = 0, ["y"] = 4, ["param1"] = 170, ["z"] = 14, ["name"] = "lottother:air" },
{["x"] = 4, ["meta"] = { ["fields"] = {}, ["inventory"] = {} }, ["param2"] = 0, ["y"] = 4, ["param1"] = 0, ["z"] = 15, ["name"] = "default:cobble" },
{["x"] = 4, ["meta"] = { ["fields"] = {}, ["inventory"] = {} }, ["param2"] = 0, ["y"] = 4, ["param1"] = 0, ["z"] = 16, ["name"] = "default:cobble" },
{["x"] = 4, ["meta"] = { ["fields"] = {}, ["inventory"] = {} }, ["param2"] = 0, ["y"] = 5, ["param1"] = 0, ["z"] = 2, ["name"] = "default:cobble" },
{["x"] = 4, ["meta"] = { ["fields"] = {}, ["inventory"] = {} }, ["param2"] = 0, ["y"] = 5, ["param1"] = 0, ["z"] = 3, ["name"] = "default:cobble" },
{["x"] = 4, ["meta"] = { ["fields"] = {}, ["inventory"] = {} }, ["param2"] = 0, ["y"] = 5, ["param1"] = 0, ["z"] = 4, ["name"] = "default:cobble" },
{["x"] = 4, ["meta"] = { ["fields"] = {}, ["inventory"] = {} }, ["param2"] = 0, ["y"] = 5, ["param1"] = 0, ["z"] = 5, ["name"] = "default:cobble" },
{["x"] = 4, ["meta"] = { ["fields"] = {}, ["inventory"] = {} }, ["param2"] = 0, ["y"] = 5, ["param1"] = 0, ["z"] = 6, ["name"] = "default:cobble" },
{["x"] = 4, ["meta"] = { ["fields"] = {}, ["inventory"] = {} }, ["param2"] = 0, ["y"] = 5, ["param1"] = 0, ["z"] = 7, ["name"] = "default:cobble" },
{["x"] = 4, ["meta"] = { ["fields"] = {}, ["inventory"] = {} }, ["param2"] = 0, ["y"] = 5, ["param1"] = 0, ["z"] = 8, ["name"] = "default:cobble" },
{["x"] = 4, ["meta"] = { ["fields"] = {}, ["inventory"] = {} }, ["param2"] = 0, ["y"] = 5, ["param1"] = 0, ["z"] = 9, ["name"] = "default:cobble" },
{["x"] = 4, ["meta"] = { ["fields"] = {}, ["inventory"] = {} }, ["param2"] = 0, ["y"] = 5, ["param1"] = 0, ["z"] = 10, ["name"] = "default:cobble" },
{["x"] = 4, ["meta"] = { ["fields"] = {}, ["inventory"] = {} }, ["param2"] = 0, ["y"] = 5, ["param1"] = 0, ["z"] = 11, ["name"] = "default:cobble" },
{["x"] = 4, ["meta"] = { ["fields"] = {}, ["inventory"] = {} }, ["param2"] = 0, ["y"] = 5, ["param1"] = 0, ["z"] = 12, ["name"] = "default:cobble" },
{["x"] = 4, ["meta"] = { ["fields"] = {}, ["inventory"] = {} }, ["param2"] = 0, ["y"] = 5, ["param1"] = 0, ["z"] = 13, ["name"] = "default:cobble" },
{["x"] = 4, ["meta"] = { ["fields"] = {}, ["inventory"] = {} }, ["param2"] = 0, ["y"] = 5, ["param1"] = 0, ["z"] = 14, ["name"] = "default:cobble" },
{["x"] = 4, ["meta"] = { ["fields"] = {}, ["inventory"] = {} }, ["param2"] = 0, ["y"] = 5, ["param1"] = 0, ["z"] = 15, ["name"] = "default:cobble" },
{["x"] = 4, ["meta"] = { ["fields"] = {}, ["inventory"] = {} }, ["param2"] = 0, ["y"] = 5, ["param1"] = 0, ["z"] = 16, ["name"] = "default:cobble" },
{["x"] = 4, ["meta"] = { ["fields"] = {}, ["inventory"] = {} }, ["param2"] = 0, ["y"] = 6, ["param1"] = 0, ["z"] = 2, ["name"] = "default:cobble" },
{["x"] = 4, ["meta"] = { ["fields"] = {}, ["inventory"] = {} }, ["param2"] = 0, ["y"] = 6, ["param1"] = 0, ["z"] = 3, ["name"] = "default:cobble" },
{["x"] = 4, ["meta"] = { ["fields"] = {}, ["inventory"] = {} }, ["param2"] = 0, ["y"] = 6, ["param1"] = 0, ["z"] = 4, ["name"] = "default:cobble" },
{["x"] = 4, ["meta"] = { ["fields"] = {}, ["inventory"] = {} }, ["param2"] = 0, ["y"] = 6, ["param1"] = 0, ["z"] = 14, ["name"] = "default:cobble" },
{["x"] = 4, ["meta"] = { ["fields"] = {}, ["inventory"] = {} }, ["param2"] = 0, ["y"] = 6, ["param1"] = 0, ["z"] = 15, ["name"] = "default:cobble" },
{["x"] = 4, ["meta"] = { ["fields"] = {}, ["inventory"] = {} }, ["param2"] = 0, ["y"] = 6, ["param1"] = 0, ["z"] = 16, ["name"] = "default:cobble" },
{["x"] = 4, ["meta"] = { ["fields"] = {}, ["inventory"] = {} }, ["param2"] = 0, ["y"] = 7, ["param1"] = 0, ["z"] = 2, ["name"] = "default:cobble" },
{["x"] = 4, ["meta"] = { ["fields"] = {}, ["inventory"] = {} }, ["param2"] = 0, ["y"] = 7, ["param1"] = 0, ["z"] = 3, ["name"] = "default:cobble" },
{["x"] = 4, ["meta"] = { ["fields"] = {}, ["inventory"] = {} }, ["param2"] = 0, ["y"] = 7, ["param1"] = 0, ["z"] = 4, ["name"] = "default:cobble" },
{["x"] = 4, ["meta"] = { ["fields"] = {}, ["inventory"] = {} }, ["param2"] = 0, ["y"] = 7, ["param1"] = 0, ["z"] = 14, ["name"] = "default:cobble" },
{["x"] = 4, ["meta"] = { ["fields"] = {}, ["inventory"] = {} }, ["param2"] = 0, ["y"] = 7, ["param1"] = 0, ["z"] = 15, ["name"] = "default:cobble" },
{["x"] = 4, ["meta"] = { ["fields"] = {}, ["inventory"] = {} }, ["param2"] = 0, ["y"] = 7, ["param1"] = 0, ["z"] = 16, ["name"] = "default:cobble" },
{["x"] = 4, ["meta"] = { ["fields"] = {}, ["inventory"] = {} }, ["param2"] = 0, ["y"] = 8, ["param1"] = 0, ["z"] = 2, ["name"] = "default:cobble" },
{["x"] = 4, ["meta"] = { ["fields"] = {}, ["inventory"] = {} }, ["param2"] = 0, ["y"] = 8, ["param1"] = 0, ["z"] = 3, ["name"] = "default:cobble" },
{["x"] = 4, ["meta"] = { ["fields"] = {}, ["inventory"] = {} }, ["param2"] = 0, ["y"] = 8, ["param1"] = 0, ["z"] = 4, ["name"] = "default:cobble" },
{["x"] = 4, ["meta"] = { ["fields"] = {}, ["inventory"] = {} }, ["param2"] = 0, ["y"] = 8, ["param1"] = 0, ["z"] = 14, ["name"] = "default:cobble" },
{["x"] = 4, ["meta"] = { ["fields"] = {}, ["inventory"] = {} }, ["param2"] = 0, ["y"] = 8, ["param1"] = 0, ["z"] = 15, ["name"] = "default:cobble" },
{["x"] = 4, ["meta"] = { ["fields"] = {}, ["inventory"] = {} }, ["param2"] = 0, ["y"] = 8, ["param1"] = 0, ["z"] = 16, ["name"] = "default:cobble" },
{["x"] = 4, ["meta"] = { ["fields"] = {}, ["inventory"] = {} }, ["param2"] = 0, ["y"] = 9, ["param1"] = 0, ["z"] = 1, ["name"] = "default:cobble" },
{["x"] = 4, ["meta"] = { ["fields"] = {}, ["inventory"] = {} }, ["param2"] = 0, ["y"] = 9, ["param1"] = 0, ["z"] = 2, ["name"] = "default:cobble" },
{["x"] = 4, ["meta"] = { ["fields"] = {}, ["inventory"] = {} }, ["param2"] = 0, ["y"] = 9, ["param1"] = 0, ["z"] = 3, ["name"] = "default:cobble" },
{["x"] = 4, ["meta"] = { ["fields"] = {}, ["inventory"] = {} }, ["param2"] = 0, ["y"] = 9, ["param1"] = 0, ["z"] = 4, ["name"] = "default:cobble" },
{["x"] = 4, ["meta"] = { ["fields"] = {}, ["inventory"] = {} }, ["param2"] = 0, ["y"] = 9, ["param1"] = 0, ["z"] = 14, ["name"] = "default:cobble" },
{["x"] = 4, ["meta"] = { ["fields"] = {}, ["inventory"] = {} }, ["param2"] = 0, ["y"] = 9, ["param1"] = 0, ["z"] = 15, ["name"] = "default:cobble" },
{["x"] = 4, ["meta"] = { ["fields"] = {}, ["inventory"] = {} }, ["param2"] = 0, ["y"] = 9, ["param1"] = 0, ["z"] = 16, ["name"] = "default:cobble" },
{["x"] = 4, ["meta"] = { ["fields"] = {}, ["inventory"] = {} }, ["param2"] = 0, ["y"] = 9, ["param1"] = 0, ["z"] = 17, ["name"] = "default:cobble" },
{["x"] = 4, ["meta"] = { ["fields"] = {}, ["inventory"] = {} }, ["param2"] = 0, ["y"] = 10, ["param1"] = 0, ["z"] = 0, ["name"] = "default:cobble" },
{["x"] = 4, ["meta"] = { ["fields"] = {}, ["inventory"] = {} }, ["param2"] = 0, ["y"] = 10, ["param1"] = 0, ["z"] = 2, ["name"] = "default:cobble" },
{["x"] = 4, ["meta"] = { ["fields"] = {}, ["inventory"] = {} }, ["param2"] = 0, ["y"] = 10, ["param1"] = 0, ["z"] = 4, ["name"] = "default:cobble" },
{["x"] = 4, ["meta"] = { ["fields"] = {}, ["inventory"] = {} }, ["param2"] = 0, ["y"] = 10, ["param1"] = 0, ["z"] = 14, ["name"] = "default:cobble" },
{["x"] = 4, ["meta"] = { ["fields"] = {}, ["inventory"] = {} }, ["param2"] = 0, ["y"] = 10, ["param1"] = 0, ["z"] = 16, ["name"] = "default:cobble" },
{["x"] = 4, ["meta"] = { ["fields"] = {}, ["inventory"] = {} }, ["param2"] = 0, ["y"] = 10, ["param1"] = 0, ["z"] = 18, ["name"] = "default:cobble" },
{["x"] = 5, ["meta"] = { ["fields"] = {}, ["inventory"] = {} }, ["param2"] = 0, ["y"] = 0, ["param1"] = 63, ["z"] = 0, ["name"] = "lottother:snow" },
{["x"] = 5, ["meta"] = { ["fields"] = {}, ["inventory"] = {} }, ["param2"] = 0, ["y"] = 0, ["param1"] = 77, ["z"] = 1, ["name"] = "lottother:snow" },
{["x"] = 5, ["meta"] = { ["fields"] = {}, ["inventory"] = {} }, ["param2"] = 0, ["y"] = 0, ["param1"] = 60, ["z"] = 2, ["name"] = "lottother:snow" },
{["x"] = 5, ["meta"] = { ["fields"] = {}, ["inventory"] = {} }, ["param2"] = 0, ["y"] = 0, ["param1"] = 43, ["z"] = 3, ["name"] = "lottother:snow" },
{["x"] = 5, ["meta"] = { ["fields"] = {}, ["inventory"] = {} }, ["param2"] = 0, ["y"] = 0, ["param1"] = 26, ["z"] = 4, ["name"] = "lottother:snow" },
{["x"] = 5, ["meta"] = { ["fields"] = {}, ["inventory"] = {} }, ["param2"] = 0, ["y"] = 0, ["param1"] = 9, ["z"] = 5, ["name"] = "lottother:snow" },
{["x"] = 5, ["meta"] = { ["fields"] = {}, ["inventory"] = {} }, ["param2"] = 0, ["y"] = 0, ["param1"] = 9, ["z"] = 6, ["name"] = "lottother:snow" },
{["x"] = 5, ["meta"] = { ["fields"] = {}, ["inventory"] = {} }, ["param2"] = 0, ["y"] = 0, ["param1"] = 9, ["z"] = 7, ["name"] = "lottother:snow" },
{["x"] = 5, ["meta"] = { ["fields"] = {}, ["inventory"] = {} }, ["param2"] = 0, ["y"] = 0, ["param1"] = 9, ["z"] = 8, ["name"] = "lottother:snow" },
{["x"] = 5, ["meta"] = { ["fields"] = {}, ["inventory"] = {} }, ["param2"] = 0, ["y"] = 0, ["param1"] = 9, ["z"] = 9, ["name"] = "lottother:snow" },
{["x"] = 5, ["meta"] = { ["fields"] = {}, ["inventory"] = {} }, ["param2"] = 0, ["y"] = 0, ["param1"] = 9, ["z"] = 10, ["name"] = "lottother:snow" },
{["x"] = 5, ["meta"] = { ["fields"] = {}, ["inventory"] = {} }, ["param2"] = 0, ["y"] = 0, ["param1"] = 9, ["z"] = 11, ["name"] = "lottother:snow" },
{["x"] = 5, ["meta"] = { ["fields"] = {}, ["inventory"] = {} }, ["param2"] = 0, ["y"] = 0, ["param1"] = 9, ["z"] = 12, ["name"] = "lottother:snow" },
{["x"] = 5, ["meta"] = { ["fields"] = {}, ["inventory"] = {} }, ["param2"] = 0, ["y"] = 0, ["param1"] = 9, ["z"] = 13, ["name"] = "lottother:snow" },
{["x"] = 5, ["meta"] = { ["fields"] = {}, ["inventory"] = {} }, ["param2"] = 0, ["y"] = 0, ["param1"] = 10, ["z"] = 14, ["name"] = "lottother:snow" },
{["x"] = 5, ["meta"] = { ["fields"] = {}, ["inventory"] = {} }, ["param2"] = 0, ["y"] = 0, ["param1"] = 11, ["z"] = 15, ["name"] = "lottother:snow" },
{["x"] = 5, ["meta"] = { ["fields"] = {}, ["inventory"] = {} }, ["param2"] = 0, ["y"] = 0, ["param1"] = 28, ["z"] = 16, ["name"] = "lottother:snow" },
{["x"] = 5, ["meta"] = { ["fields"] = {}, ["inventory"] = {} }, ["param2"] = 0, ["y"] = 0, ["param1"] = 45, ["z"] = 17, ["name"] = "lottother:snow" },
{["x"] = 5, ["meta"] = { ["fields"] = {}, ["inventory"] = {} }, ["param2"] = 0, ["y"] = 0, ["param1"] = 63, ["z"] = 18, ["name"] = "lottother:snow" },
{["x"] = 5, ["meta"] = { ["fields"] = {}, ["inventory"] = {} }, ["param2"] = 0, ["y"] = 1, ["param1"] = 0, ["z"] = 1, ["name"] = "lottother:snow" },
{["x"] = 5, ["meta"] = { ["fields"] = {}, ["inventory"] = {} }, ["param2"] = 0, ["y"] = 1, ["param1"] = 109, ["z"] = 2, ["name"] = "lottother:snow" },
{["x"] = 5, ["meta"] = { ["fields"] = {}, ["inventory"] = {} }, ["param2"] = 0, ["y"] = 1, ["param1"] = 92, ["z"] = 3, ["name"] = "lottother:snow" },
{["x"] = 5, ["meta"] = { ["fields"] = {}, ["inventory"] = {} }, ["param2"] = 0, ["y"] = 1, ["param1"] = 75, ["z"] = 4, ["name"] = "lottother:snow" },
{["x"] = 5, ["meta"] = { ["fields"] = {}, ["inventory"] = {} }, ["param2"] = 0, ["y"] = 1, ["param1"] = 58, ["z"] = 5, ["name"] = "lottother:snow" },
{["x"] = 5, ["meta"] = { ["fields"] = {}, ["inventory"] = {} }, ["param2"] = 0, ["y"] = 1, ["param1"] = 42, ["z"] = 6, ["name"] = "lottother:snow" },
{["x"] = 5, ["meta"] = { ["fields"] = {}, ["inventory"] = {} }, ["param2"] = 0, ["y"] = 1, ["param1"] = 26, ["z"] = 7, ["name"] = "lottother:snow" },
{["x"] = 5, ["meta"] = { ["fields"] = {}, ["inventory"] = {} }, ["param2"] = 0, ["y"] = 1, ["param1"] = 10, ["z"] = 8, ["name"] = "lottother:snow" },
{["x"] = 5, ["meta"] = { ["fields"] = {}, ["inventory"] = {} }, ["param2"] = 0, ["y"] = 1, ["param1"] = 10, ["z"] = 9, ["name"] = "lottother:snow" },
{["x"] = 5, ["meta"] = { ["fields"] = {}, ["inventory"] = {} }, ["param2"] = 0, ["y"] = 1, ["param1"] = 10, ["z"] = 10, ["name"] = "lottother:snow" },
{["x"] = 5, ["meta"] = { ["fields"] = {}, ["inventory"] = {} }, ["param2"] = 0, ["y"] = 1, ["param1"] = 26, ["z"] = 11, ["name"] = "lottother:snow" },
{["x"] = 5, ["meta"] = { ["fields"] = {}, ["inventory"] = {} }, ["param2"] = 0, ["y"] = 1, ["param1"] = 42, ["z"] = 12, ["name"] = "lottother:snow" },
{["x"] = 5, ["meta"] = { ["fields"] = {}, ["inventory"] = {} }, ["param2"] = 0, ["y"] = 1, ["param1"] = 58, ["z"] = 13, ["name"] = "lottother:snow" },
{["x"] = 5, ["meta"] = { ["fields"] = {}, ["inventory"] = {} }, ["param2"] = 0, ["y"] = 1, ["param1"] = 75, ["z"] = 14, ["name"] = "lottother:snow" },
{["x"] = 5, ["meta"] = { ["fields"] = {}, ["inventory"] = {} }, ["param2"] = 0, ["y"] = 1, ["param1"] = 92, ["z"] = 15, ["name"] = "lottother:snow" },
{["x"] = 5, ["meta"] = { ["fields"] = {}, ["inventory"] = {} }, ["param2"] = 0, ["y"] = 1, ["param1"] = 109, ["z"] = 16, ["name"] = "lottother:snow" },
{["x"] = 5, ["meta"] = { ["fields"] = {}, ["inventory"] = {} }, ["param2"] = 0, ["y"] = 1, ["param1"] = 0, ["z"] = 17, ["name"] = "lottother:snow" },
{["x"] = 5, ["meta"] = { ["fields"] = {}, ["inventory"] = {} }, ["param2"] = 0, ["y"] = 2, ["param1"] = 0, ["z"] = 2, ["name"] = "default:cobble" },
{["x"] = 5, ["meta"] = { ["fields"] = {}, ["inventory"] = {} }, ["param2"] = 0, ["y"] = 2, ["param1"] = 0, ["z"] = 3, ["name"] = "default:cobble" },
{["x"] = 5, ["meta"] = { ["fields"] = {}, ["inventory"] = {} }, ["param2"] = 0, ["y"] = 2, ["param1"] = 0, ["z"] = 4, ["name"] = "lottblocks:orc_brick" },
{["x"] = 5, ["meta"] = { ["fields"] = {}, ["inventory"] = {} }, ["param2"] = 0, ["y"] = 2, ["param1"] = 0, ["z"] = 5, ["name"] = "lottblocks:orc_brick" },
{["x"] = 5, ["meta"] = { ["fields"] = {}, ["inventory"] = {} }, ["param2"] = 0, ["y"] = 2, ["param1"] = 0, ["z"] = 6, ["name"] = "lottblocks:orc_brick" },
{["x"] = 5, ["meta"] = { ["fields"] = {}, ["inventory"] = {} }, ["param2"] = 0, ["y"] = 2, ["param1"] = 0, ["z"] = 7, ["name"] = "lottblocks:orc_brick" },
{["x"] = 5, ["meta"] = { ["fields"] = {}, ["inventory"] = {} }, ["param2"] = 0, ["y"] = 2, ["param1"] = 0, ["z"] = 8, ["name"] = "lottblocks:orc_brick" },
{["x"] = 5, ["meta"] = { ["fields"] = {}, ["inventory"] = {} }, ["param2"] = 0, ["y"] = 2, ["param1"] = 0, ["z"] = 9, ["name"] = "lottblocks:orc_brick" },
{["x"] = 5, ["meta"] = { ["fields"] = {}, ["inventory"] = {} }, ["param2"] = 0, ["y"] = 2, ["param1"] = 0, ["z"] = 10, ["name"] = "lottblocks:orc_brick" },
{["x"] = 5, ["meta"] = { ["fields"] = {}, ["inventory"] = {} }, ["param2"] = 0, ["y"] = 2, ["param1"] = 0, ["z"] = 11, ["name"] = "lottblocks:orc_brick" },
{["x"] = 5, ["meta"] = { ["fields"] = {}, ["inventory"] = {} }, ["param2"] = 0, ["y"] = 2, ["param1"] = 0, ["z"] = 12, ["name"] = "lottblocks:orc_brick" },
{["x"] = 5, ["meta"] = { ["fields"] = {}, ["inventory"] = {} }, ["param2"] = 0, ["y"] = 2, ["param1"] = 0, ["z"] = 13, ["name"] = "lottblocks:orc_brick" },
{["x"] = 5, ["meta"] = { ["fields"] = {}, ["inventory"] = {} }, ["param2"] = 0, ["y"] = 2, ["param1"] = 0, ["z"] = 14, ["name"] = "lottblocks:orc_brick" },
{["x"] = 5, ["meta"] = { ["fields"] = {}, ["inventory"] = {} }, ["param2"] = 0, ["y"] = 2, ["param1"] = 0, ["z"] = 15, ["name"] = "default:cobble" },
{["x"] = 5, ["meta"] = { ["fields"] = {}, ["inventory"] = {} }, ["param2"] = 0, ["y"] = 2, ["param1"] = 0, ["z"] = 16, ["name"] = "default:cobble" },
{["x"] = 5, ["meta"] = { ["fields"] = {}, ["inventory"] = {} }, ["param2"] = 0, ["y"] = 3, ["param1"] = 0, ["z"] = 2, ["name"] = "default:cobble" },
{["x"] = 5, ["meta"] = { ["fields"] = {}, ["inventory"] = {} }, ["param2"] = 0, ["y"] = 3, ["param1"] = 0, ["z"] = 3, ["name"] = "default:cobble" },
{["x"] = 5, ["meta"] = { ["fields"] = {}, ["inventory"] = {} }, ["param2"] = 0, ["y"] = 3, ["param1"] = 136, ["z"] = 4, ["name"] = "lottother:air" },
{["x"] = 5, ["meta"] = { ["fields"] = {}, ["inventory"] = {} }, ["param2"] = 0, ["y"] = 3, ["param1"] = 119, ["z"] = 5, ["name"] = "lottother:air" },
{["x"] = 5, ["meta"] = { ["fields"] = {}, ["inventory"] = {} }, ["param2"] = 0, ["y"] = 3, ["param1"] = 102, ["z"] = 6, ["name"] = "lottother:air" },
{["x"] = 5, ["meta"] = { ["fields"] = {}, ["inventory"] = {} }, ["param2"] = 0, ["y"] = 3, ["param1"] = 85, ["z"] = 7, ["name"] = "lottother:air" },
{["x"] = 5, ["meta"] = { ["fields"] = {}, ["inventory"] = {} }, ["param2"] = 0, ["y"] = 3, ["param1"] = 85, ["z"] = 8, ["name"] = "lottother:air" },
{["x"] = 5, ["meta"] = { ["fields"] = {}, ["inventory"] = {} }, ["param2"] = 0, ["y"] = 3, ["param1"] = 102, ["z"] = 9, ["name"] = "lottother:air" },
{["x"] = 5, ["meta"] = { ["fields"] = {}, ["inventory"] = {} }, ["param2"] = 0, ["y"] = 3, ["param1"] = 85, ["z"] = 10, ["name"] = "lottother:air" },
{["x"] = 5, ["meta"] = { ["fields"] = {}, ["inventory"] = {} }, ["param2"] = 0, ["y"] = 3, ["param1"] = 85, ["z"] = 11, ["name"] = "lottother:air" },
{["x"] = 5, ["meta"] = { ["fields"] = {}, ["inventory"] = {} }, ["param2"] = 0, ["y"] = 3, ["param1"] = 102, ["z"] = 12, ["name"] = "lottother:air" },
{["x"] = 5, ["meta"] = { ["fields"] = {}, ["inventory"] = {} }, ["param2"] = 0, ["y"] = 3, ["param1"] = 119, ["z"] = 13, ["name"] = "lottother:air" },
{["x"] = 5, ["meta"] = { ["fields"] = {}, ["inventory"] = {} }, ["param2"] = 0, ["y"] = 3, ["param1"] = 136, ["z"] = 14, ["name"] = "lottother:air" },
{["x"] = 5, ["meta"] = { ["fields"] = {}, ["inventory"] = {} }, ["param2"] = 0, ["y"] = 3, ["param1"] = 0, ["z"] = 15, ["name"] = "default:cobble" },
{["x"] = 5, ["meta"] = { ["fields"] = {}, ["inventory"] = {} }, ["param2"] = 0, ["y"] = 3, ["param1"] = 0, ["z"] = 16, ["name"] = "default:cobble" },
{["x"] = 5, ["meta"] = { ["fields"] = {}, ["inventory"] = {} }, ["param2"] = 0, ["y"] = 4, ["param1"] = 0, ["z"] = 2, ["name"] = "default:cobble" },
{["x"] = 5, ["meta"] = { ["fields"] = {}, ["inventory"] = {} }, ["param2"] = 0, ["y"] = 4, ["param1"] = 0, ["z"] = 3, ["name"] = "default:cobble" },
{["x"] = 5, ["meta"] = { ["fields"] = {}, ["inventory"] = {} }, ["param2"] = 0, ["y"] = 4, ["param1"] = 153, ["z"] = 4, ["name"] = "lottother:air" },
{["x"] = 5, ["meta"] = { ["fields"] = {}, ["inventory"] = {} }, ["param2"] = 0, ["y"] = 4, ["param1"] = 136, ["z"] = 5, ["name"] = "lottother:air" },
{["x"] = 5, ["meta"] = { ["fields"] = {}, ["inventory"] = {} }, ["param2"] = 0, ["y"] = 4, ["param1"] = 119, ["z"] = 6, ["name"] = "lottother:air" },
{["x"] = 5, ["meta"] = { ["fields"] = {}, ["inventory"] = {} }, ["param2"] = 0, ["y"] = 4, ["param1"] = 102, ["z"] = 7, ["name"] = "lottother:air" },
{["x"] = 5, ["meta"] = { ["fields"] = {}, ["inventory"] = {} }, ["param2"] = 0, ["y"] = 4, ["param1"] = 102, ["z"] = 8, ["name"] = "lottother:air" },
{["x"] = 5, ["meta"] = { ["fields"] = {}, ["inventory"] = {} }, ["param2"] = 0, ["y"] = 4, ["param1"] = 119, ["z"] = 9, ["name"] = "lottother:air" },
{["x"] = 5, ["meta"] = { ["fields"] = {}, ["inventory"] = {} }, ["param2"] = 0, ["y"] = 4, ["param1"] = 102, ["z"] = 10, ["name"] = "lottother:air" },
{["x"] = 5, ["meta"] = { ["fields"] = {}, ["inventory"] = {} }, ["param2"] = 0, ["y"] = 4, ["param1"] = 102, ["z"] = 11, ["name"] = "lottother:air" },
{["x"] = 5, ["meta"] = { ["fields"] = {}, ["inventory"] = {} }, ["param2"] = 0, ["y"] = 4, ["param1"] = 119, ["z"] = 12, ["name"] = "lottother:air" },
{["x"] = 5, ["meta"] = { ["fields"] = {}, ["inventory"] = {} }, ["param2"] = 0, ["y"] = 4, ["param1"] = 136, ["z"] = 13, ["name"] = "lottother:air" },
{["x"] = 5, ["meta"] = { ["fields"] = {}, ["inventory"] = {} }, ["param2"] = 0, ["y"] = 4, ["param1"] = 153, ["z"] = 14, ["name"] = "lottother:air" },
{["x"] = 5, ["meta"] = { ["fields"] = {}, ["inventory"] = {} }, ["param2"] = 0, ["y"] = 4, ["param1"] = 0, ["z"] = 15, ["name"] = "default:cobble" },
{["x"] = 5, ["meta"] = { ["fields"] = {}, ["inventory"] = {} }, ["param2"] = 0, ["y"] = 4, ["param1"] = 0, ["z"] = 16, ["name"] = "default:cobble" },
{["x"] = 5, ["meta"] = { ["fields"] = {}, ["inventory"] = {} }, ["param2"] = 0, ["y"] = 5, ["param1"] = 0, ["z"] = 2, ["name"] = "default:cobble" },
{["x"] = 5, ["meta"] = { ["fields"] = {}, ["inventory"] = {} }, ["param2"] = 0, ["y"] = 5, ["param1"] = 0, ["z"] = 3, ["name"] = "default:cobble" },
{["x"] = 5, ["meta"] = { ["fields"] = {}, ["inventory"] = {} }, ["param2"] = 0, ["y"] = 5, ["param1"] = 0, ["z"] = 4, ["name"] = "default:cobble" },
{["x"] = 5, ["meta"] = { ["fields"] = {}, ["inventory"] = {} }, ["param2"] = 0, ["y"] = 5, ["param1"] = 0, ["z"] = 5, ["name"] = "default:cobble" },
{["x"] = 5, ["meta"] = { ["fields"] = {}, ["inventory"] = {} }, ["param2"] = 0, ["y"] = 5, ["param1"] = 102, ["z"] = 6, ["name"] = "lottother:air" },
{["x"] = 5, ["meta"] = { ["fields"] = {}, ["inventory"] = {} }, ["param2"] = 0, ["y"] = 5, ["param1"] = 85, ["z"] = 7, ["name"] = "lottother:air" },
{["x"] = 5, ["meta"] = { ["fields"] = {}, ["inventory"] = {} }, ["param2"] = 0, ["y"] = 5, ["param1"] = 85, ["z"] = 8, ["name"] = "lottother:air" },
{["x"] = 5, ["meta"] = { ["fields"] = {}, ["inventory"] = {} }, ["param2"] = 0, ["y"] = 5, ["param1"] = 102, ["z"] = 9, ["name"] = "lottother:air" },
{["x"] = 5, ["meta"] = { ["fields"] = {}, ["inventory"] = {} }, ["param2"] = 0, ["y"] = 5, ["param1"] = 85, ["z"] = 10, ["name"] = "lottother:air" },
{["x"] = 5, ["meta"] = { ["fields"] = {}, ["inventory"] = {} }, ["param2"] = 0, ["y"] = 5, ["param1"] = 85, ["z"] = 11, ["name"] = "lottother:air" },
{["x"] = 5, ["meta"] = { ["fields"] = {}, ["inventory"] = {} }, ["param2"] = 0, ["y"] = 5, ["param1"] = 102, ["z"] = 12, ["name"] = "lottother:air" },
{["x"] = 5, ["meta"] = { ["fields"] = {}, ["inventory"] = {} }, ["param2"] = 0, ["y"] = 5, ["param1"] = 0, ["z"] = 13, ["name"] = "default:cobble" },
{["x"] = 5, ["meta"] = { ["fields"] = {}, ["inventory"] = {} }, ["param2"] = 0, ["y"] = 5, ["param1"] = 0, ["z"] = 14, ["name"] = "default:cobble" },
{["x"] = 5, ["meta"] = { ["fields"] = {}, ["inventory"] = {} }, ["param2"] = 0, ["y"] = 5, ["param1"] = 0, ["z"] = 15, ["name"] = "default:cobble" },
{["x"] = 5, ["meta"] = { ["fields"] = {}, ["inventory"] = {} }, ["param2"] = 0, ["y"] = 5, ["param1"] = 0, ["z"] = 16, ["name"] = "default:cobble" },
{["x"] = 5, ["meta"] = { ["fields"] = {}, ["inventory"] = {} }, ["param2"] = 0, ["y"] = 6, ["param1"] = 95, ["z"] = 2, ["name"] = "lottother:air" },
{["x"] = 5, ["meta"] = { ["fields"] = {}, ["inventory"] = {} }, ["param2"] = 0, ["y"] = 6, ["param1"] = 0, ["z"] = 6, ["name"] = "default:cobble" },
{["x"] = 5, ["meta"] = { ["fields"] = {}, ["inventory"] = {} }, ["param2"] = 0, ["y"] = 6, ["param1"] = 0, ["z"] = 7, ["name"] = "default:cobble" },
{["x"] = 5, ["meta"] = { ["fields"] = {}, ["inventory"] = {} }, ["param2"] = 0, ["y"] = 6, ["param1"] = 0, ["z"] = 8, ["name"] = "default:cobble" },
{["x"] = 5, ["meta"] = { ["fields"] = {}, ["inventory"] = {} }, ["param2"] = 0, ["y"] = 6, ["param1"] = 0, ["z"] = 9, ["name"] = "default:cobble" },
{["x"] = 5, ["meta"] = { ["fields"] = {}, ["inventory"] = {} }, ["param2"] = 0, ["y"] = 6, ["param1"] = 0, ["z"] = 10, ["name"] = "default:cobble" },
{["x"] = 5, ["meta"] = { ["fields"] = {}, ["inventory"] = {} }, ["param2"] = 0, ["y"] = 6, ["param1"] = 0, ["z"] = 11, ["name"] = "default:cobble" },
{["x"] = 5, ["meta"] = { ["fields"] = {}, ["inventory"] = {} }, ["param2"] = 0, ["y"] = 6, ["param1"] = 0, ["z"] = 12, ["name"] = "default:cobble" },
{["x"] = 5, ["meta"] = { ["fields"] = {}, ["inventory"] = {} }, ["param2"] = 0, ["y"] = 6, ["param1"] = 95, ["z"] = 16, ["name"] = "lottother:air" },
{["x"] = 6, ["meta"] = { ["fields"] = {}, ["inventory"] = {} }, ["param2"] = 0, ["y"] = 0, ["param1"] = 79, ["z"] = 0, ["name"] = "lottother:snow" },
{["x"] = 6, ["meta"] = { ["fields"] = {}, ["inventory"] = {} }, ["param2"] = 0, ["y"] = 0, ["param1"] = 93, ["z"] = 1, ["name"] = "lottother:snow" },
{["x"] = 6, ["meta"] = { ["fields"] = {}, ["inventory"] = {} }, ["param2"] = 0, ["y"] = 0, ["param1"] = 76, ["z"] = 2, ["name"] = "lottother:snow" },
{["x"] = 6, ["meta"] = { ["fields"] = {}, ["inventory"] = {} }, ["param2"] = 0, ["y"] = 0, ["param1"] = 59, ["z"] = 3, ["name"] = "lottother:snow" },
{["x"] = 6, ["meta"] = { ["fields"] = {}, ["inventory"] = {} }, ["param2"] = 0, ["y"] = 0, ["param1"] = 42, ["z"] = 4, ["name"] = "lottother:snow" },
{["x"] = 6, ["meta"] = { ["fields"] = {}, ["inventory"] = {} }, ["param2"] = 0, ["y"] = 0, ["param1"] = 25, ["z"] = 5, ["name"] = "lottother:snow" },
{["x"] = 6, ["meta"] = { ["fields"] = {}, ["inventory"] = {} }, ["param2"] = 0, ["y"] = 0, ["param1"] = 8, ["z"] = 6, ["name"] = "lottother:snow" },
{["x"] = 6, ["meta"] = { ["fields"] = {}, ["inventory"] = {} }, ["param2"] = 0, ["y"] = 0, ["param1"] = 8, ["z"] = 7, ["name"] = "lottother:snow" },
{["x"] = 6, ["meta"] = { ["fields"] = {}, ["inventory"] = {} }, ["param2"] = 0, ["y"] = 0, ["param1"] = 8, ["z"] = 8, ["name"] = "lottother:snow" },
{["x"] = 6, ["meta"] = { ["fields"] = {}, ["inventory"] = {} }, ["param2"] = 0, ["y"] = 0, ["param1"] = 8, ["z"] = 9, ["name"] = "lottother:snow" },
{["x"] = 6, ["meta"] = { ["fields"] = {}, ["inventory"] = {} }, ["param2"] = 0, ["y"] = 0, ["param1"] = 8, ["z"] = 10, ["name"] = "lottother:snow" },
{["x"] = 6, ["meta"] = { ["fields"] = {}, ["inventory"] = {} }, ["param2"] = 0, ["y"] = 0, ["param1"] = 8, ["z"] = 11, ["name"] = "lottother:snow" },
{["x"] = 6, ["meta"] = { ["fields"] = {}, ["inventory"] = {} }, ["param2"] = 0, ["y"] = 0, ["param1"] = 8, ["z"] = 12, ["name"] = "lottother:snow" },
{["x"] = 6, ["meta"] = { ["fields"] = {}, ["inventory"] = {} }, ["param2"] = 0, ["y"] = 0, ["param1"] = 9, ["z"] = 13, ["name"] = "lottother:snow" },
{["x"] = 6, ["meta"] = { ["fields"] = {}, ["inventory"] = {} }, ["param2"] = 0, ["y"] = 0, ["param1"] = 10, ["z"] = 14, ["name"] = "lottother:snow" },
{["x"] = 6, ["meta"] = { ["fields"] = {}, ["inventory"] = {} }, ["param2"] = 0, ["y"] = 0, ["param1"] = 27, ["z"] = 15, ["name"] = "lottother:snow" },
{["x"] = 6, ["meta"] = { ["fields"] = {}, ["inventory"] = {} }, ["param2"] = 0, ["y"] = 0, ["param1"] = 44, ["z"] = 16, ["name"] = "lottother:snow" },
{["x"] = 6, ["meta"] = { ["fields"] = {}, ["inventory"] = {} }, ["param2"] = 0, ["y"] = 0, ["param1"] = 61, ["z"] = 17, ["name"] = "lottother:snow" },
{["x"] = 6, ["meta"] = { ["fields"] = {}, ["inventory"] = {} }, ["param2"] = 0, ["y"] = 0, ["param1"] = 79, ["z"] = 18, ["name"] = "lottother:snow" },
{["x"] = 6, ["meta"] = { ["fields"] = {}, ["inventory"] = {} }, ["param2"] = 0, ["y"] = 1, ["param1"] = 0, ["z"] = 1, ["name"] = "lottother:snow" },
{["x"] = 6, ["meta"] = { ["fields"] = {}, ["inventory"] = {} }, ["param2"] = 0, ["y"] = 1, ["param1"] = 125, ["z"] = 2, ["name"] = "lottother:snow" },
{["x"] = 6, ["meta"] = { ["fields"] = {}, ["inventory"] = {} }, ["param2"] = 0, ["y"] = 1, ["param1"] = 108, ["z"] = 3, ["name"] = "lottother:snow" },
{["x"] = 6, ["meta"] = { ["fields"] = {}, ["inventory"] = {} }, ["param2"] = 0, ["y"] = 1, ["param1"] = 91, ["z"] = 4, ["name"] = "lottother:snow" },
{["x"] = 6, ["meta"] = { ["fields"] = {}, ["inventory"] = {} }, ["param2"] = 0, ["y"] = 1, ["param1"] = 74, ["z"] = 5, ["name"] = "lottother:snow" },
{["x"] = 6, ["meta"] = { ["fields"] = {}, ["inventory"] = {} }, ["param2"] = 0, ["y"] = 1, ["param1"] = 57, ["z"] = 6, ["name"] = "lottother:snow" },
{["x"] = 6, ["meta"] = { ["fields"] = {}, ["inventory"] = {} }, ["param2"] = 0, ["y"] = 1, ["param1"] = 41, ["z"] = 7, ["name"] = "lottother:snow" },
{["x"] = 6, ["meta"] = { ["fields"] = {}, ["inventory"] = {} }, ["param2"] = 0, ["y"] = 1, ["param1"] = 25, ["z"] = 8, ["name"] = "lottother:snow" },
{["x"] = 6, ["meta"] = { ["fields"] = {}, ["inventory"] = {} }, ["param2"] = 0, ["y"] = 1, ["param1"] = 9, ["z"] = 9, ["name"] = "lottother:snow" },
{["x"] = 6, ["meta"] = { ["fields"] = {}, ["inventory"] = {} }, ["param2"] = 0, ["y"] = 1, ["param1"] = 25, ["z"] = 10, ["name"] = "lottother:snow" },
{["x"] = 6, ["meta"] = { ["fields"] = {}, ["inventory"] = {} }, ["param2"] = 0, ["y"] = 1, ["param1"] = 41, ["z"] = 11, ["name"] = "lottother:snow" },
{["x"] = 6, ["meta"] = { ["fields"] = {}, ["inventory"] = {} }, ["param2"] = 0, ["y"] = 1, ["param1"] = 57, ["z"] = 12, ["name"] = "lottother:snow" },
{["x"] = 6, ["meta"] = { ["fields"] = {}, ["inventory"] = {} }, ["param2"] = 0, ["y"] = 1, ["param1"] = 74, ["z"] = 13, ["name"] = "lottother:snow" },
{["x"] = 6, ["meta"] = { ["fields"] = {}, ["inventory"] = {} }, ["param2"] = 0, ["y"] = 1, ["param1"] = 91, ["z"] = 14, ["name"] = "lottother:snow" },
{["x"] = 6, ["meta"] = { ["fields"] = {}, ["inventory"] = {} }, ["param2"] = 0, ["y"] = 1, ["param1"] = 108, ["z"] = 15, ["name"] = "lottother:snow" },
{["x"] = 6, ["meta"] = { ["fields"] = {}, ["inventory"] = {} }, ["param2"] = 0, ["y"] = 1, ["param1"] = 125, ["z"] = 16, ["name"] = "lottother:snow" },
{["x"] = 6, ["meta"] = { ["fields"] = {}, ["inventory"] = {} }, ["param2"] = 0, ["y"] = 1, ["param1"] = 0, ["z"] = 17, ["name"] = "lottother:snow" },
{["x"] = 6, ["meta"] = { ["fields"] = {}, ["inventory"] = {} }, ["param2"] = 0, ["y"] = 2, ["param1"] = 0, ["z"] = 3, ["name"] = "default:cobble" },
{["x"] = 6, ["meta"] = { ["fields"] = {}, ["inventory"] = {} }, ["param2"] = 0, ["y"] = 2, ["param1"] = 0, ["z"] = 4, ["name"] = "default:cobble" },
{["x"] = 6, ["meta"] = { ["fields"] = {}, ["inventory"] = {} }, ["param2"] = 0, ["y"] = 2, ["param1"] = 0, ["z"] = 5, ["name"] = "lottblocks:orc_brick" },
{["x"] = 6, ["meta"] = { ["fields"] = {}, ["inventory"] = {} }, ["param2"] = 0, ["y"] = 2, ["param1"] = 0, ["z"] = 6, ["name"] = "lottblocks:orc_brick" },
{["x"] = 6, ["meta"] = { ["fields"] = {}, ["inventory"] = {} }, ["param2"] = 0, ["y"] = 2, ["param1"] = 0, ["z"] = 7, ["name"] = "lottblocks:orc_brick" },
{["x"] = 6, ["meta"] = { ["fields"] = {}, ["inventory"] = {} }, ["param2"] = 0, ["y"] = 2, ["param1"] = 0, ["z"] = 8, ["name"] = "lottblocks:orc_brick" },
{["x"] = 6, ["meta"] = { ["fields"] = {}, ["inventory"] = {} }, ["param2"] = 0, ["y"] = 2, ["param1"] = 0, ["z"] = 9, ["name"] = "lottblocks:orc_brick" },
{["x"] = 6, ["meta"] = { ["fields"] = {}, ["inventory"] = {} }, ["param2"] = 0, ["y"] = 2, ["param1"] = 0, ["z"] = 10, ["name"] = "lottblocks:orc_brick" },
{["x"] = 6, ["meta"] = { ["fields"] = {}, ["inventory"] = {} }, ["param2"] = 0, ["y"] = 2, ["param1"] = 0, ["z"] = 11, ["name"] = "lottblocks:orc_brick" },
{["x"] = 6, ["meta"] = { ["fields"] = {}, ["inventory"] = {} }, ["param2"] = 0, ["y"] = 2, ["param1"] = 0, ["z"] = 12, ["name"] = "lottblocks:orc_brick" },
{["x"] = 6, ["meta"] = { ["fields"] = {}, ["inventory"] = {} }, ["param2"] = 0, ["y"] = 2, ["param1"] = 0, ["z"] = 13, ["name"] = "lottblocks:orc_brick" },
{["x"] = 6, ["meta"] = { ["fields"] = {}, ["inventory"] = {} }, ["param2"] = 0, ["y"] = 2, ["param1"] = 0, ["z"] = 14, ["name"] = "default:cobble" },
{["x"] = 6, ["meta"] = { ["fields"] = {}, ["inventory"] = {} }, ["param2"] = 0, ["y"] = 2, ["param1"] = 0, ["z"] = 15, ["name"] = "default:cobble" },
{["x"] = 6, ["meta"] = { ["fields"] = {}, ["inventory"] = {} }, ["param2"] = 0, ["y"] = 3, ["param1"] = 0, ["z"] = 3, ["name"] = "default:cobble" },
{["x"] = 6, ["meta"] = { ["fields"] = {}, ["inventory"] = {} }, ["param2"] = 0, ["y"] = 3, ["param1"] = 0, ["z"] = 4, ["name"] = "default:cobble" },
{["x"] = 6, ["meta"] = { ["fields"] = {}, ["inventory"] = {} }, ["param2"] = 0, ["y"] = 3, ["param1"] = 104, ["z"] = 5, ["name"] = "lottother:air" },
{["x"] = 6, ["meta"] = { ["fields"] = {}, ["inventory"] = {} }, ["param2"] = 0, ["y"] = 3, ["param1"] = 87, ["z"] = 6, ["name"] = "lottother:air" },
{["x"] = 6, ["meta"] = { ["fields"] = {}, ["inventory"] = {} }, ["param2"] = 0, ["y"] = 3, ["param1"] = 86, ["z"] = 7, ["name"] = "lottother:air" },
{["x"] = 6, ["meta"] = { ["fields"] = {}, ["inventory"] = {} }, ["param2"] = 0, ["y"] = 3, ["param1"] = 102, ["z"] = 8, ["name"] = "lottother:air" },
{["x"] = 6, ["meta"] = { ["fields"] = {}, ["inventory"] = {} }, ["param2"] = 0, ["y"] = 3, ["param1"] = 119, ["z"] = 9, ["name"] = "lottother:air" },
{["x"] = 6, ["meta"] = { ["fields"] = {}, ["inventory"] = {} }, ["param2"] = 0, ["y"] = 3, ["param1"] = 102, ["z"] = 10, ["name"] = "lottother:air" },
{["x"] = 6, ["meta"] = { ["fields"] = {}, ["inventory"] = {} }, ["param2"] = 0, ["y"] = 3, ["param1"] = 86, ["z"] = 11, ["name"] = "lottother:air" },
{["x"] = 6, ["meta"] = { ["fields"] = {}, ["inventory"] = {} }, ["param2"] = 0, ["y"] = 3, ["param1"] = 87, ["z"] = 12, ["name"] = "lottother:air" },
{["x"] = 6, ["meta"] = { ["fields"] = {}, ["inventory"] = {} }, ["param2"] = 0, ["y"] = 3, ["param1"] = 104, ["z"] = 13, ["name"] = "lottother:air" },
{["x"] = 6, ["meta"] = { ["fields"] = {}, ["inventory"] = {} }, ["param2"] = 0, ["y"] = 3, ["param1"] = 0, ["z"] = 14, ["name"] = "default:cobble" },
{["x"] = 6, ["meta"] = { ["fields"] = {}, ["inventory"] = {} }, ["param2"] = 0, ["y"] = 3, ["param1"] = 0, ["z"] = 15, ["name"] = "default:cobble" },
{["x"] = 6, ["meta"] = { ["fields"] = {}, ["inventory"] = {} }, ["param2"] = 0, ["y"] = 4, ["param1"] = 0, ["z"] = 3, ["name"] = "default:cobble" },
{["x"] = 6, ["meta"] = { ["fields"] = {}, ["inventory"] = {} }, ["param2"] = 0, ["y"] = 4, ["param1"] = 0, ["z"] = 4, ["name"] = "default:cobble" },
{["x"] = 6, ["meta"] = { ["fields"] = {}, ["inventory"] = {} }, ["param2"] = 0, ["y"] = 4, ["param1"] = 120, ["z"] = 5, ["name"] = "lottother:air" },
{["x"] = 6, ["meta"] = { ["fields"] = {}, ["inventory"] = {} }, ["param2"] = 0, ["y"] = 4, ["param1"] = 103, ["z"] = 6, ["name"] = "lottother:air" },
{["x"] = 6, ["meta"] = { ["fields"] = {}, ["inventory"] = {} }, ["param2"] = 0, ["y"] = 4, ["param1"] = 102, ["z"] = 7, ["name"] = "lottother:air" },
{["x"] = 6, ["meta"] = { ["fields"] = {}, ["inventory"] = {} }, ["param2"] = 0, ["y"] = 4, ["param1"] = 119, ["z"] = 8, ["name"] = "lottother:air" },
{["x"] = 6, ["meta"] = { ["fields"] = {}, ["inventory"] = {} }, ["param2"] = 0, ["y"] = 4, ["param1"] = 136, ["z"] = 9, ["name"] = "lottother:air" },
{["x"] = 6, ["meta"] = { ["fields"] = {}, ["inventory"] = {} }, ["param2"] = 0, ["y"] = 4, ["param1"] = 119, ["z"] = 10, ["name"] = "lottother:air" },
{["x"] = 6, ["meta"] = { ["fields"] = {}, ["inventory"] = {} }, ["param2"] = 0, ["y"] = 4, ["param1"] = 102, ["z"] = 11, ["name"] = "lottother:air" },
{["x"] = 6, ["meta"] = { ["fields"] = {}, ["inventory"] = {} }, ["param2"] = 0, ["y"] = 4, ["param1"] = 103, ["z"] = 12, ["name"] = "lottother:air" },
{["x"] = 6, ["meta"] = { ["fields"] = {}, ["inventory"] = {} }, ["param2"] = 0, ["y"] = 4, ["param1"] = 120, ["z"] = 13, ["name"] = "lottother:air" },
{["x"] = 6, ["meta"] = { ["fields"] = {}, ["inventory"] = {} }, ["param2"] = 0, ["y"] = 4, ["param1"] = 0, ["z"] = 14, ["name"] = "default:cobble" },
{["x"] = 6, ["meta"] = { ["fields"] = {}, ["inventory"] = {} }, ["param2"] = 0, ["y"] = 4, ["param1"] = 0, ["z"] = 15, ["name"] = "default:cobble" },
{["x"] = 6, ["meta"] = { ["fields"] = {}, ["inventory"] = {} }, ["param2"] = 0, ["y"] = 5, ["param1"] = 0, ["z"] = 3, ["name"] = "default:cobble" },
{["x"] = 6, ["meta"] = { ["fields"] = {}, ["inventory"] = {} }, ["param2"] = 0, ["y"] = 5, ["param1"] = 0, ["z"] = 4, ["name"] = "default:cobble" },
{["x"] = 6, ["meta"] = { ["fields"] = {}, ["inventory"] = {} }, ["param2"] = 0, ["y"] = 5, ["param1"] = 103, ["z"] = 5, ["name"] = "lottother:air" },
{["x"] = 6, ["meta"] = { ["fields"] = {}, ["inventory"] = {} }, ["param2"] = 0, ["y"] = 5, ["param1"] = 86, ["z"] = 6, ["name"] = "lottother:air" },
{["x"] = 6, ["meta"] = { ["fields"] = {}, ["inventory"] = {} }, ["param2"] = 0, ["y"] = 5, ["param1"] = 85, ["z"] = 7, ["name"] = "lottother:air" },
{["x"] = 6, ["meta"] = { ["fields"] = {}, ["inventory"] = {} }, ["param2"] = 0, ["y"] = 5, ["param1"] = 102, ["z"] = 8, ["name"] = "lottother:air" },
{["x"] = 6, ["meta"] = { ["fields"] = {}, ["inventory"] = {} }, ["param2"] = 0, ["y"] = 5, ["param1"] = 119, ["z"] = 9, ["name"] = "lottother:air" },
{["x"] = 6, ["meta"] = { ["fields"] = {}, ["inventory"] = {} }, ["param2"] = 0, ["y"] = 5, ["param1"] = 102, ["z"] = 10, ["name"] = "lottother:air" },
{["x"] = 6, ["meta"] = { ["fields"] = {}, ["inventory"] = {} }, ["param2"] = 0, ["y"] = 5, ["param1"] = 85, ["z"] = 11, ["name"] = "lottother:air" },
{["x"] = 6, ["meta"] = { ["fields"] = {}, ["inventory"] = {} }, ["param2"] = 0, ["y"] = 5, ["param1"] = 86, ["z"] = 12, ["name"] = "lottother:air" },
{["x"] = 6, ["meta"] = { ["fields"] = {}, ["inventory"] = {} }, ["param2"] = 0, ["y"] = 5, ["param1"] = 103, ["z"] = 13, ["name"] = "lottother:air" },
{["x"] = 6, ["meta"] = { ["fields"] = {}, ["inventory"] = {} }, ["param2"] = 0, ["y"] = 5, ["param1"] = 0, ["z"] = 14, ["name"] = "default:cobble" },
{["x"] = 6, ["meta"] = { ["fields"] = {}, ["inventory"] = {} }, ["param2"] = 0, ["y"] = 5, ["param1"] = 0, ["z"] = 15, ["name"] = "default:cobble" },
{["x"] = 6, ["meta"] = { ["fields"] = {}, ["inventory"] = {} }, ["param2"] = 0, ["y"] = 6, ["param1"] = 0, ["z"] = 2, ["name"] = "default:cobble" },
{["x"] = 6, ["meta"] = { ["fields"] = {}, ["inventory"] = {} }, ["param2"] = 0, ["y"] = 6, ["param1"] = 0, ["z"] = 5, ["name"] = "default:cobble" },
{["x"] = 6, ["meta"] = { ["fields"] = {}, ["inventory"] = {} }, ["param2"] = 0, ["y"] = 6, ["param1"] = 0, ["z"] = 6, ["name"] = "default:cobble" },
{["x"] = 6, ["meta"] = { ["fields"] = {}, ["inventory"] = {} }, ["param2"] = 0, ["y"] = 6, ["param1"] = 0, ["z"] = 7, ["name"] = "default:cobble" },
{["x"] = 6, ["meta"] = { ["fields"] = {}, ["inventory"] = {} }, ["param2"] = 0, ["y"] = 6, ["param1"] = 0, ["z"] = 8, ["name"] = "default:cobble" },
{["x"] = 6, ["meta"] = { ["fields"] = {}, ["inventory"] = {} }, ["param2"] = 0, ["y"] = 6, ["param1"] = 0, ["z"] = 9, ["name"] = "default:cobble" },
{["x"] = 6, ["meta"] = { ["fields"] = {}, ["inventory"] = {} }, ["param2"] = 0, ["y"] = 6, ["param1"] = 0, ["z"] = 10, ["name"] = "default:cobble" },
{["x"] = 6, ["meta"] = { ["fields"] = {}, ["inventory"] = {} }, ["param2"] = 0, ["y"] = 6, ["param1"] = 0, ["z"] = 11, ["name"] = "default:cobble" },
{["x"] = 6, ["meta"] = { ["fields"] = {}, ["inventory"] = {} }, ["param2"] = 0, ["y"] = 6, ["param1"] = 0, ["z"] = 12, ["name"] = "default:cobble" },
{["x"] = 6, ["meta"] = { ["fields"] = {}, ["inventory"] = {} }, ["param2"] = 0, ["y"] = 6, ["param1"] = 0, ["z"] = 13, ["name"] = "default:cobble" },
{["x"] = 6, ["meta"] = { ["fields"] = {}, ["inventory"] = {} }, ["param2"] = 0, ["y"] = 6, ["param1"] = 0, ["z"] = 16, ["name"] = "default:cobble" },
{["x"] = 6, ["meta"] = { ["fields"] = {}, ["inventory"] = {} }, ["param2"] = 0, ["y"] = 7, ["param1"] = 0, ["z"] = 6, ["name"] = "default:cobble" },
{["x"] = 6, ["meta"] = { ["fields"] = {}, ["inventory"] = {} }, ["param2"] = 0, ["y"] = 7, ["param1"] = 0, ["z"] = 7, ["name"] = "default:cobble" },
{["x"] = 6, ["meta"] = { ["fields"] = {}, ["inventory"] = {} }, ["param2"] = 0, ["y"] = 7, ["param1"] = 0, ["z"] = 8, ["name"] = "default:cobble" },
{["x"] = 6, ["meta"] = { ["fields"] = {}, ["inventory"] = {} }, ["param2"] = 0, ["y"] = 7, ["param1"] = 0, ["z"] = 9, ["name"] = "default:cobble" },
{["x"] = 6, ["meta"] = { ["fields"] = {}, ["inventory"] = {} }, ["param2"] = 0, ["y"] = 7, ["param1"] = 0, ["z"] = 10, ["name"] = "default:cobble" },
{["x"] = 6, ["meta"] = { ["fields"] = {}, ["inventory"] = {} }, ["param2"] = 0, ["y"] = 7, ["param1"] = 0, ["z"] = 11, ["name"] = "default:cobble" },
{["x"] = 6, ["meta"] = { ["fields"] = {}, ["inventory"] = {} }, ["param2"] = 0, ["y"] = 7, ["param1"] = 0, ["z"] = 12, ["name"] = "default:cobble" },
{["x"] = 6, ["meta"] = { ["fields"] = {}, ["inventory"] = {} }, ["param2"] = 0, ["y"] = 8, ["param1"] = 0, ["z"] = 6, ["name"] = "default:cobble" },
{["x"] = 6, ["meta"] = { ["fields"] = {}, ["inventory"] = {} }, ["param2"] = 0, ["y"] = 8, ["param1"] = 0, ["z"] = 7, ["name"] = "default:cobble" },
{["x"] = 6, ["meta"] = { ["fields"] = {}, ["inventory"] = {} }, ["param2"] = 0, ["y"] = 8, ["param1"] = 0, ["z"] = 8, ["name"] = "default:cobble" },
{["x"] = 6, ["meta"] = { ["fields"] = {}, ["inventory"] = {} }, ["param2"] = 0, ["y"] = 8, ["param1"] = 0, ["z"] = 9, ["name"] = "default:cobble" },
{["x"] = 6, ["meta"] = { ["fields"] = {}, ["inventory"] = {} }, ["param2"] = 0, ["y"] = 8, ["param1"] = 0, ["z"] = 10, ["name"] = "default:cobble" },
{["x"] = 6, ["meta"] = { ["fields"] = {}, ["inventory"] = {} }, ["param2"] = 0, ["y"] = 8, ["param1"] = 0, ["z"] = 11, ["name"] = "default:cobble" },
{["x"] = 6, ["meta"] = { ["fields"] = {}, ["inventory"] = {} }, ["param2"] = 0, ["y"] = 8, ["param1"] = 0, ["z"] = 12, ["name"] = "default:cobble" },
{["x"] = 6, ["meta"] = { ["fields"] = {}, ["inventory"] = {} }, ["param2"] = 0, ["y"] = 9, ["param1"] = 0, ["z"] = 6, ["name"] = "default:cobble" },
{["x"] = 6, ["meta"] = { ["fields"] = {}, ["inventory"] = {} }, ["param2"] = 0, ["y"] = 9, ["param1"] = 0, ["z"] = 7, ["name"] = "default:cobble" },
{["x"] = 6, ["meta"] = { ["fields"] = {}, ["inventory"] = {} }, ["param2"] = 0, ["y"] = 9, ["param1"] = 0, ["z"] = 8, ["name"] = "default:cobble" },
{["x"] = 6, ["meta"] = { ["fields"] = {}, ["inventory"] = {} }, ["param2"] = 0, ["y"] = 9, ["param1"] = 0, ["z"] = 9, ["name"] = "default:cobble" },
{["x"] = 6, ["meta"] = { ["fields"] = {}, ["inventory"] = {} }, ["param2"] = 0, ["y"] = 9, ["param1"] = 0, ["z"] = 10, ["name"] = "default:cobble" },
{["x"] = 6, ["meta"] = { ["fields"] = {}, ["inventory"] = {} }, ["param2"] = 0, ["y"] = 9, ["param1"] = 0, ["z"] = 11, ["name"] = "default:cobble" },
{["x"] = 6, ["meta"] = { ["fields"] = {}, ["inventory"] = {} }, ["param2"] = 0, ["y"] = 9, ["param1"] = 0, ["z"] = 12, ["name"] = "default:cobble" },
{["x"] = 7, ["meta"] = { ["fields"] = {}, ["inventory"] = {} }, ["param2"] = 0, ["y"] = 0, ["param1"] = 95, ["z"] = 0, ["name"] = "lottother:snow" },
{["x"] = 7, ["meta"] = { ["fields"] = {}, ["inventory"] = {} }, ["param2"] = 0, ["y"] = 0, ["param1"] = 111, ["z"] = 1, ["name"] = "lottother:snow" },
{["x"] = 7, ["meta"] = { ["fields"] = {}, ["inventory"] = {} }, ["param2"] = 0, ["y"] = 0, ["param1"] = 93, ["z"] = 2, ["name"] = "lottother:snow" },
{["x"] = 7, ["meta"] = { ["fields"] = {}, ["inventory"] = {} }, ["param2"] = 0, ["y"] = 0, ["param1"] = 76, ["z"] = 3, ["name"] = "lottother:snow" },
{["x"] = 7, ["meta"] = { ["fields"] = {}, ["inventory"] = {} }, ["param2"] = 0, ["y"] = 0, ["param1"] = 59, ["z"] = 4, ["name"] = "lottother:snow" },
{["x"] = 7, ["meta"] = { ["fields"] = {}, ["inventory"] = {} }, ["param2"] = 0, ["y"] = 0, ["param1"] = 42, ["z"] = 5, ["name"] = "lottother:snow" },
{["x"] = 7, ["meta"] = { ["fields"] = {}, ["inventory"] = {} }, ["param2"] = 0, ["y"] = 0, ["param1"] = 25, ["z"] = 6, ["name"] = "lottother:snow" },
